{
  "version": 8,
  "blockIdVersion": 11,
  "anchorX": 0,
  "anchorY": 1,
  "anchorZ": 0,
  "blocks": [
    {
      "x": -11,
      "y": 15,
      "z": -4,
      "name": "*Rock_Aqua_Cobble_Roof_Hollow_State_Definitions_Inverted_Corner_Right",
      "rotation": 3
    },
    {
      "x": -11,
      "y": 16,
      "z": -3,
      "name": "*Rock_Aqua_Cobble_Roof_Hollow_State_Definitions_Corner_Left",
      "rotation": 2
    },
    {
      "x": -11,
      "y": 16,
      "z": -2,
      "name": "Rock_Aqua_Cobble_Roof_Hollow",
      "rotation": 3
    },
    {
      "x": -11,
      "y": 5,
      "z": -1,
      "name": "Rock_Aqua_Brick_Smooth_Half",
      "rotation": 7
    },
    {
      "x": -11,
      "y": 16,
      "z": -1,
      "name": "Rock_Aqua_Cobble_Roof_Hollow",
      "rotation": 3
    },
    {
      "x": -11,
      "y": 6,
      "z": 0,
      "name": "Rock_Aqua_Brick_Smooth_Half",
      "rotation": 7
    },
    {
      "x": -11,
      "y": 16,
      "z": 0,
      "name": "Rock_Aqua_Cobble_Roof_Hollow",
      "rotation": 3
    },
    {
      "x": -11,
      "y": 5,
      "z": 1,
      "name": "Rock_Aqua_Brick_Smooth_Half",
      "rotation": 7
    },
    {
      "x": -11,
      "y": 16,
      "z": 1,
      "name": "Rock_Aqua_Cobble_Roof_Hollow",
      "rotation": 3
    },
    {
      "x": -11,
      "y": 16,
      "z": 2,
      "name": "Rock_Aqua_Cobble_Roof_Hollow",
      "rotation": 3
    },
    {
      "x": -11,
      "y": 16,
      "z": 3,
      "name": "*Rock_Aqua_Cobble_Roof_Hollow_State_Definitions_Corner_Right"
    },
    {
      "x": -11,
      "y": 15,
      "z": 4,
      "name": "*Rock_Aqua_Cobble_Roof_Hollow_State_Definitions_Inverted_Corner_Right"
    },
    {
      "x": -10,
      "y": 15,
      "z": -7,
      "name": "*Rock_Aqua_Cobble_Roof_Hollow_State_Definitions_Inverted_Corner_Right",
      "rotation": 3
    },
    {
      "x": -10,
      "y": 0,
      "z": -6,
      "name": "Rock_Aqua_Brick_Ornate",
      "rotation": 1
    },
    {
      "x": -10,
      "y": 1,
      "z": -6,
      "name": "Rock_Aqua_Brick_Decorative",
      "rotation": 1
    },
    {
      "x": -10,
      "y": 2,
      "z": -6,
      "name": "*Rock_Aqua_Brick_Wall_State_Definitions_Corner",
      "rotation": 1
    },
    {
      "x": -10,
      "y": 3,
      "z": -6,
      "name": "Rock_Aqua_Brick_Beam",
      "rotation": 1
    },
    {
      "x": -10,
      "y": 4,
      "z": -6,
      "name": "Rock_Aqua_Brick_Beam",
      "rotation": 1
    },
    {
      "x": -10,
      "y": 5,
      "z": -6,
      "name": "*Rock_Aqua_Cobble_Roof_State_Definitions_Corner_Left",
      "rotation": 2
    },
    {
      "x": -10,
      "y": 16,
      "z": -6,
      "name": "*Rock_Aqua_Cobble_Roof_Hollow_State_Definitions_Corner_Left",
      "rotation": 2
    },
    {
      "x": -10,
      "y": 0,
      "z": -5,
      "name": "Rock_Aqua_Brick_Smooth",
      "rotation": 1
    },
    {
      "x": -10,
      "y": 1,
      "z": -5,
      "name": "Rock_Aqua_Brick_Decorative",
      "rotation": 1
    },
    {
      "x": -10,
      "y": 2,
      "z": -5,
      "name": "Rock_Aqua_Brick_Wall",
      "rotation": 1
    },
    {
      "x": -10,
      "y": 5,
      "z": -5,
      "name": "Rock_Aqua_Cobble_Roof_Hollow",
      "rotation": 3
    },
    {
      "x": -10,
      "y": 16,
      "z": -5,
      "name": "Rock_Aqua_Cobble_Roof_Hollow",
      "rotation": 3
    },
    {
      "x": -10,
      "y": 0,
      "z": -4,
      "name": "Rock_Aqua_Brick_Ornate",
      "rotation": 1
    },
    {
      "x": -10,
      "y": 1,
      "z": -4,
      "name": "Rock_Aqua_Brick_Decorative",
      "rotation": 1
    },
    {
      "x": -10,
      "y": 2,
      "z": -4,
      "name": "Rock_Aqua_Brick_Wall",
      "rotation": 1
    },
    {
      "x": -10,
      "y": 5,
      "z": -4,
      "name": "Rock_Aqua_Cobble_Roof_Hollow",
      "rotation": 3
    },
    {
      "x": -10,
      "y": 6,
      "z": -4,
      "name": "Rock_Aqua_Brick_Smooth_Half",
      "rotation": 7
    },
    {
      "x": -10,
      "y": 7,
      "z": -4,
      "name": "Rock_Aqua_Brick_Smooth_Half",
      "rotation": 7
    },
    {
      "x": -10,
      "y": 11,
      "z": -4,
      "name": "Rock_Aqua_Brick_Smooth_Half",
      "rotation": 7
    },
    {
      "x": -10,
      "y": 12,
      "z": -4,
      "name": "Rock_Aqua_Brick_Smooth_Half",
      "rotation": 7
    },
    {
      "x": -10,
      "y": 16,
      "z": -4,
      "name": "Rock_Aqua_Cobble_Roof_Hollow",
      "rotation": 3
    },
    {
      "x": -10,
      "y": 0,
      "z": -3,
      "name": "Rock_Aqua_Brick_Smooth",
      "rotation": 1
    },
    {
      "x": -10,
      "y": 1,
      "z": -3,
      "name": "Rock_Aqua_Brick_Decorative",
      "rotation": 1
    },
    {
      "x": -10,
      "y": 2,
      "z": -3,
      "name": "Rock_Aqua_Brick_Wall",
      "rotation": 1
    },
    {
      "x": -10,
      "y": 3,
      "z": -3,
      "name": "Furniture_Temple_Dark_Stool",
      "rotation": 2
    },
    {
      "x": -10,
      "y": 5,
      "z": -3,
      "name": "Rock_Aqua_Cobble_Roof_Hollow",
      "rotation": 3
    },
    {
      "x": -10,
      "y": 6,
      "z": -3,
      "name": "Rock_Aqua_Brick_Smooth_Half",
      "rotation": 7
    },
    {
      "x": -10,
      "y": 7,
      "z": -3,
      "name": "Rock_Aqua_Brick_Smooth_Half",
      "rotation": 7
    },
    {
      "x": -10,
      "y": 11,
      "z": -3,
      "name": "Rock_Aqua_Brick_Smooth_Half",
      "rotation": 7
    },
    {
      "x": -10,
      "y": 12,
      "z": -3,
      "name": "Rock_Aqua_Brick_Smooth_Half",
      "rotation": 7
    },
    {
      "x": -10,
      "y": 16,
      "z": -3,
      "name": "*Rock_Aqua_Cobble_Roof_Hollow_State_Definitions_Inverted_Corner_Right",
      "rotation": 3
    },
    {
      "x": -10,
      "y": 0,
      "z": -2,
      "name": "Rock_Aqua_Brick_Ornate",
      "rotation": 1
    },
    {
      "x": -10,
      "y": 1,
      "z": -2,
      "name": "Rock_Aqua_Brick_Smooth",
      "rotation": 1
    },
    {
      "x": -10,
      "y": 2,
      "z": -2,
      "name": "Rock_Aqua_Brick_Smooth",
      "rotation": 1
    },
    {
      "x": -10,
      "y": 3,
      "z": -2,
      "name": "Rock_Aqua_Brick_Smooth",
      "rotation": 1
    },
    {
      "x": -10,
      "y": 4,
      "z": -2,
      "name": "Rock_Aqua_Brick_Smooth",
      "rotation": 1
    },
    {
      "x": -10,
      "y": 5,
      "z": -2,
      "name": "Rock_Aqua_Brick_Smooth",
      "rotation": 1
    },
    {
      "x": -10,
      "y": 6,
      "z": -2,
      "name": "Rock_Aqua_Brick_Smooth",
      "rotation": 1
    },
    {
      "x": -10,
      "y": 7,
      "z": -2,
      "name": "Rock_Aqua_Brick_Smooth",
      "rotation": 1
    },
    {
      "x": -10,
      "y": 8,
      "z": -2,
      "name": "Rock_Aqua_Brick_Smooth",
      "rotation": 1
    },
    {
      "x": -10,
      "y": 9,
      "z": -2,
      "name": "Rock_Aqua_Brick_Smooth",
      "rotation": 1
    },
    {
      "x": -10,
      "y": 10,
      "z": -2,
      "name": "Rock_Aqua_Brick_Smooth",
      "rotation": 1
    },
    {
      "x": -10,
      "y": 11,
      "z": -2,
      "name": "Rock_Aqua_Brick_Smooth",
      "rotation": 1
    },
    {
      "x": -10,
      "y": 12,
      "z": -2,
      "name": "Rock_Aqua_Brick_Smooth",
      "rotation": 1
    },
    {
      "x": -10,
      "y": 13,
      "z": -2,
      "name": "Rock_Aqua_Brick_Smooth",
      "rotation": 1
    },
    {
      "x": -10,
      "y": 14,
      "z": -2,
      "name": "Rock_Aqua_Brick_Smooth",
      "rotation": 1
    },
    {
      "x": -10,
      "y": 15,
      "z": -2,
      "name": "Rock_Aqua_Brick_Smooth",
      "rotation": 1
    },
    {
      "x": -10,
      "y": 16,
      "z": -2,
      "name": "Rock_Aqua_Brick_Smooth",
      "rotation": 3
    },
    {
      "x": -10,
      "y": 17,
      "z": -2,
      "name": "*Rock_Aqua_Cobble_Roof_State_Definitions_Corner_Right",
      "rotation": 3
    },
    {
      "x": -10,
      "y": 0,
      "z": -1,
      "name": "Rock_Aqua_Brick_Smooth"
    },
    {
      "x": -10,
      "y": 3,
      "z": -1,
      "name": "Rock_Aqua_Brick_Smooth_Half",
      "rotation": 4
    },
    {
      "x": -10,
      "y": 4,
      "z": -1,
      "name": "Rock_Aqua_Brick_Smooth"
    },
    {
      "x": -10,
      "y": 5,
      "z": -1,
      "name": "Rock_Aqua_Brick_Smooth"
    },
    {
      "x": -10,
      "y": 6,
      "z": -1,
      "name": "Rock_Aqua_Brick_Smooth"
    },
    {
      "x": -10,
      "y": 7,
      "z": -1,
      "name": "Rock_Aqua_Brick_Smooth"
    },
    {
      "x": -10,
      "y": 8,
      "z": -1,
      "name": "Rock_Aqua_Brick_Smooth"
    },
    {
      "x": -10,
      "y": 9,
      "z": -1,
      "name": "Rock_Aqua_Brick_Smooth"
    },
    {
      "x": -10,
      "y": 12,
      "z": -1,
      "name": "Rock_Aqua_Brick_Smooth_Half",
      "rotation": 4
    },
    {
      "x": -10,
      "y": 13,
      "z": -1,
      "name": "Rock_Aqua_Brick_Smooth"
    },
    {
      "x": -10,
      "y": 14,
      "z": -1,
      "name": "Rock_Aqua_Brick_Smooth"
    },
    {
      "x": -10,
      "y": 15,
      "z": -1,
      "name": "Rock_Aqua_Brick_Smooth"
    },
    {
      "x": -10,
      "y": 16,
      "z": -1,
      "name": "Rock_Aqua_Brick_Smooth",
      "rotation": 3
    },
    {
      "x": -10,
      "y": 17,
      "z": -1,
      "name": "Rock_Aqua_Cobble_Roof",
      "rotation": 3
    },
    {
      "x": -10,
      "y": 0,
      "z": 0,
      "name": "Rock_Aqua_Brick_Smooth"
    },
    {
      "x": -10,
      "y": 4,
      "z": 0,
      "name": "Rock_Aqua_Brick_Smooth_Half",
      "rotation": 8
    },
    {
      "x": -10,
      "y": 5,
      "z": 0,
      "name": "Rock_Aqua_Brick_Ornate"
    },
    {
      "x": -10,
      "y": 6,
      "z": 0,
      "name": "Rock_Aqua_Brick_Smooth"
    },
    {
      "x": -10,
      "y": 7,
      "z": 0,
      "name": "Rock_Aqua_Brick_Smooth"
    },
    {
      "x": -10,
      "y": 8,
      "z": 0,
      "name": "Rock_Aqua_Brick_Smooth"
    },
    {
      "x": -10,
      "y": 9,
      "z": 0,
      "name": "Rock_Aqua_Brick_Ornate"
    },
    {
      "x": -10,
      "y": 13,
      "z": 0,
      "name": "Rock_Aqua_Brick_Smooth_Half",
      "rotation": 8
    },
    {
      "x": -10,
      "y": 14,
      "z": 0,
      "name": "Rock_Aqua_Brick_Smooth"
    },
    {
      "x": -10,
      "y": 15,
      "z": 0,
      "name": "Rock_Aqua_Brick_Smooth"
    },
    {
      "x": -10,
      "y": 16,
      "z": 0,
      "name": "Rock_Aqua_Brick_Smooth",
      "rotation": 3
    },
    {
      "x": -10,
      "y": 17,
      "z": 0,
      "name": "Rock_Aqua_Cobble_Roof",
      "rotation": 3
    },
    {
      "x": -10,
      "y": 0,
      "z": 1,
      "name": "Rock_Aqua_Brick_Smooth"
    },
    {
      "x": -10,
      "y": 3,
      "z": 1,
      "name": "Rock_Aqua_Brick_Smooth_Half",
      "rotation": 6
    },
    {
      "x": -10,
      "y": 4,
      "z": 1,
      "name": "Rock_Aqua_Brick_Smooth"
    },
    {
      "x": -10,
      "y": 5,
      "z": 1,
      "name": "Rock_Aqua_Brick_Smooth"
    },
    {
      "x": -10,
      "y": 6,
      "z": 1,
      "name": "Rock_Aqua_Brick_Smooth"
    },
    {
      "x": -10,
      "y": 7,
      "z": 1,
      "name": "Rock_Aqua_Brick_Smooth"
    },
    {
      "x": -10,
      "y": 8,
      "z": 1,
      "name": "Rock_Aqua_Brick_Smooth"
    },
    {
      "x": -10,
      "y": 9,
      "z": 1,
      "name": "Rock_Aqua_Brick_Smooth"
    },
    {
      "x": -10,
      "y": 10,
      "z": 1,
      "name": "Plant_Moss_Short_Blue",
      "support": 15
    },
    {
      "x": -10,
      "y": 12,
      "z": 1,
      "name": "Rock_Aqua_Brick_Smooth_Half",
      "rotation": 6
    },
    {
      "x": -10,
      "y": 13,
      "z": 1,
      "name": "Rock_Aqua_Brick_Smooth"
    },
    {
      "x": -10,
      "y": 14,
      "z": 1,
      "name": "Rock_Aqua_Brick_Smooth"
    },
    {
      "x": -10,
      "y": 15,
      "z": 1,
      "name": "Rock_Aqua_Brick_Smooth"
    },
    {
      "x": -10,
      "y": 16,
      "z": 1,
      "name": "Rock_Aqua_Brick_Smooth"
    },
    {
      "x": -10,
      "y": 17,
      "z": 1,
      "name": "Rock_Aqua_Cobble_Roof",
      "rotation": 3
    },
    {
      "x": -10,
      "y": 0,
      "z": 2,
      "name": "Rock_Aqua_Brick_Ornate",
      "rotation": 2
    },
    {
      "x": -10,
      "y": 1,
      "z": 2,
      "name": "Rock_Aqua_Brick_Smooth",
      "rotation": 2
    },
    {
      "x": -10,
      "y": 2,
      "z": 2,
      "name": "Rock_Aqua_Brick_Smooth",
      "rotation": 2
    },
    {
      "x": -10,
      "y": 3,
      "z": 2,
      "name": "Rock_Aqua_Brick_Smooth",
      "rotation": 2
    },
    {
      "x": -10,
      "y": 4,
      "z": 2,
      "name": "Rock_Aqua_Brick_Smooth",
      "rotation": 2
    },
    {
      "x": -10,
      "y": 5,
      "z": 2,
      "name": "Rock_Aqua_Brick_Smooth",
      "rotation": 2
    },
    {
      "x": -10,
      "y": 6,
      "z": 2,
      "name": "Rock_Aqua_Brick_Smooth",
      "rotation": 2
    },
    {
      "x": -10,
      "y": 7,
      "z": 2,
      "name": "Rock_Aqua_Brick_Smooth",
      "rotation": 2
    },
    {
      "x": -10,
      "y": 8,
      "z": 2,
      "name": "Rock_Aqua_Brick_Smooth",
      "rotation": 2
    },
    {
      "x": -10,
      "y": 9,
      "z": 2,
      "name": "Rock_Aqua_Brick_Smooth",
      "rotation": 2
    },
    {
      "x": -10,
      "y": 10,
      "z": 2,
      "name": "Rock_Aqua_Brick_Smooth",
      "rotation": 2
    },
    {
      "x": -10,
      "y": 11,
      "z": 2,
      "name": "Rock_Aqua_Brick_Smooth",
      "rotation": 2
    },
    {
      "x": -10,
      "y": 12,
      "z": 2,
      "name": "Rock_Aqua_Brick_Smooth",
      "rotation": 2
    },
    {
      "x": -10,
      "y": 13,
      "z": 2,
      "name": "Rock_Aqua_Brick_Smooth",
      "rotation": 2
    },
    {
      "x": -10,
      "y": 14,
      "z": 2,
      "name": "Rock_Aqua_Brick_Smooth",
      "rotation": 2
    },
    {
      "x": -10,
      "y": 15,
      "z": 2,
      "name": "Rock_Aqua_Brick_Smooth",
      "rotation": 2
    },
    {
      "x": -10,
      "y": 16,
      "z": 2,
      "name": "Rock_Aqua_Brick_Smooth"
    },
    {
      "x": -10,
      "y": 17,
      "z": 2,
      "name": "*Rock_Aqua_Cobble_Roof_State_Definitions_Corner_Left",
      "rotation": 3
    },
    {
      "x": -10,
      "y": 0,
      "z": 3,
      "name": "Rock_Aqua_Brick_Smooth",
      "rotation": 2
    },
    {
      "x": -10,
      "y": 1,
      "z": 3,
      "name": "Rock_Aqua_Brick_Decorative",
      "rotation": 2
    },
    {
      "x": -10,
      "y": 2,
      "z": 3,
      "name": "Rock_Aqua_Brick_Wall",
      "rotation": 3
    },
    {
      "x": -10,
      "y": 3,
      "z": 3,
      "name": "Furniture_Temple_Dark_Stool",
      "rotation": 3
    },
    {
      "x": -10,
      "y": 5,
      "z": 3,
      "name": "Rock_Aqua_Cobble_Roof_Hollow",
      "rotation": 3
    },
    {
      "x": -10,
      "y": 6,
      "z": 3,
      "name": "Rock_Aqua_Brick_Smooth_Half",
      "rotation": 7
    },
    {
      "x": -10,
      "y": 7,
      "z": 3,
      "name": "Rock_Aqua_Brick_Smooth_Half",
      "rotation": 7
    },
    {
      "x": -10,
      "y": 11,
      "z": 3,
      "name": "Rock_Aqua_Brick_Smooth_Half",
      "rotation": 7
    },
    {
      "x": -10,
      "y": 12,
      "z": 3,
      "name": "Rock_Aqua_Brick_Smooth_Half",
      "rotation": 7
    },
    {
      "x": -10,
      "y": 16,
      "z": 3,
      "name": "*Rock_Aqua_Cobble_Roof_Hollow_State_Definitions_Inverted_Corner_Left",
      "rotation": 3
    },
    {
      "x": -10,
      "y": 0,
      "z": 4,
      "name": "Rock_Aqua_Brick_Ornate",
      "rotation": 2
    },
    {
      "x": -10,
      "y": 1,
      "z": 4,
      "name": "Rock_Aqua_Brick_Decorative",
      "rotation": 2
    },
    {
      "x": -10,
      "y": 2,
      "z": 4,
      "name": "Rock_Aqua_Brick_Wall",
      "rotation": 3
    },
    {
      "x": -10,
      "y": 5,
      "z": 4,
      "name": "Rock_Aqua_Cobble_Roof_Hollow",
      "rotation": 3
    },
    {
      "x": -10,
      "y": 6,
      "z": 4,
      "name": "Rock_Aqua_Brick_Smooth_Half",
      "rotation": 7
    },
    {
      "x": -10,
      "y": 7,
      "z": 4,
      "name": "Rock_Aqua_Brick_Smooth_Half",
      "rotation": 7
    },
    {
      "x": -10,
      "y": 11,
      "z": 4,
      "name": "Rock_Aqua_Brick_Smooth_Half",
      "rotation": 7
    },
    {
      "x": -10,
      "y": 12,
      "z": 4,
      "name": "Rock_Aqua_Brick_Smooth_Half",
      "rotation": 7
    },
    {
      "x": -10,
      "y": 16,
      "z": 4,
      "name": "Rock_Aqua_Cobble_Roof_Hollow",
      "rotation": 3
    },
    {
      "x": -10,
      "y": 0,
      "z": 5,
      "name": "Rock_Aqua_Brick_Smooth",
      "rotation": 2
    },
    {
      "x": -10,
      "y": 1,
      "z": 5,
      "name": "Rock_Aqua_Brick_Decorative",
      "rotation": 2
    },
    {
      "x": -10,
      "y": 2,
      "z": 5,
      "name": "Rock_Aqua_Brick_Wall",
      "rotation": 3
    },
    {
      "x": -10,
      "y": 5,
      "z": 5,
      "name": "Rock_Aqua_Cobble_Roof_Hollow",
      "rotation": 3
    },
    {
      "x": -10,
      "y": 16,
      "z": 5,
      "name": "Rock_Aqua_Cobble_Roof_Hollow",
      "rotation": 3
    },
    {
      "x": -10,
      "y": 0,
      "z": 6,
      "name": "Rock_Aqua_Brick_Ornate",
      "rotation": 2
    },
    {
      "x": -10,
      "y": 1,
      "z": 6,
      "name": "Rock_Aqua_Brick_Decorative",
      "rotation": 2
    },
    {
      "x": -10,
      "y": 2,
      "z": 6,
      "name": "*Rock_Aqua_Brick_Wall_State_Definitions_Corner",
      "rotation": 2
    },
    {
      "x": -10,
      "y": 3,
      "z": 6,
      "name": "Rock_Aqua_Brick_Beam",
      "rotation": 2
    },
    {
      "x": -10,
      "y": 4,
      "z": 6,
      "name": "Rock_Aqua_Brick_Beam",
      "rotation": 2
    },
    {
      "x": -10,
      "y": 5,
      "z": 6,
      "name": "*Rock_Aqua_Cobble_Roof_State_Definitions_Corner_Left",
      "rotation": 3
    },
    {
      "x": -10,
      "y": 16,
      "z": 6,
      "name": "*Rock_Aqua_Cobble_Roof_Hollow_State_Definitions_Corner_Right"
    },
    {
      "x": -10,
      "y": 15,
      "z": 7,
      "name": "*Rock_Aqua_Cobble_Roof_Hollow_State_Definitions_Inverted_Corner_Right"
    },
    {
      "x": -9,
      "y": 15,
      "z": -9,
      "name": "*Rock_Aqua_Cobble_Roof_Hollow_State_Definitions_Inverted_Corner_Right",
      "rotation": 3
    },
    {
      "x": -9,
      "y": 0,
      "z": -8,
      "name": "Rock_Aqua_Brick_Smooth",
      "rotation": 1
    },
    {
      "x": -9,
      "y": 1,
      "z": -8,
      "name": "Rock_Aqua_Brick_Decorative",
      "rotation": 1
    },
    {
      "x": -9,
      "y": 2,
      "z": -8,
      "name": "*Rock_Aqua_Brick_Wall_State_Definitions_Corner",
      "rotation": 1
    },
    {
      "x": -9,
      "y": 13,
      "z": -8,
      "name": "*Rock_Aqua_Cobble_Roof_Hollow_State_Definitions_Corner_Left",
      "rotation": 2
    },
    {
      "x": -9,
      "y": 16,
      "z": -8,
      "name": "*Rock_Aqua_Cobble_Roof_Hollow_State_Definitions_Corner_Left",
      "rotation": 2
    },
    {
      "x": -9,
      "y": 0,
      "z": -7,
      "name": "Rock_Aqua_Brick_Ornate",
      "rotation": 1
    },
    {
      "x": -9,
      "y": 1,
      "z": -7,
      "name": "Rock_Aqua_Brick_Decorative",
      "rotation": 1
    },
    {
      "x": -9,
      "y": 2,
      "z": -7,
      "name": "Rock_Aqua_Brick_Wall",
      "rotation": 1
    },
    {
      "x": -9,
      "y": 6,
      "z": -7,
      "name": "Rock_Aqua_Brick_Smooth_Half",
      "rotation": 7
    },
    {
      "x": -9,
      "y": 7,
      "z": -7,
      "name": "Rock_Aqua_Brick_Smooth_Half",
      "rotation": 7
    },
    {
      "x": -9,
      "y": 10,
      "z": -7,
      "name": "Rock_Aqua_Brick_Half",
      "rotation": 7
    },
    {
      "x": -9,
      "y": 13,
      "z": -7,
      "name": "Rock_Aqua_Cobble_Roof_Hollow",
      "rotation": 3
    },
    {
      "x": -9,
      "y": 16,
      "z": -7,
      "name": "Rock_Aqua_Cobble_Roof_Hollow",
      "rotation": 3
    },
    {
      "x": -9,
      "y": 0,
      "z": -6,
      "name": "Rock_Aqua_Brick_Smooth",
      "rotation": 1
    },
    {
      "x": -9,
      "y": 1,
      "z": -6,
      "name": "Rock_Aqua_Brick_Decorative",
      "rotation": 1
    },
    {
      "x": -9,
      "y": 2,
      "z": -6,
      "name": "*Rock_Aqua_Brick_Wall_State_Definitions_Corner",
      "rotation": 3
    },
    {
      "x": -9,
      "y": 3,
      "z": -6,
      "name": "Furniture_Temple_Dark_Stool",
      "rotation": 3
    },
    {
      "x": -9,
      "y": 5,
      "z": -6,
      "name": "Rock_Aqua_Cobble_Roof_Hollow",
      "rotation": 2
    },
    {
      "x": -9,
      "y": 6,
      "z": -6,
      "name": "Rock_Aqua_Brick_Smooth_Half",
      "rotation": 7
    },
    {
      "x": -9,
      "y": 7,
      "z": -6,
      "name": "Rock_Aqua_Brick_Smooth_Half",
      "rotation": 7
    },
    {
      "x": -9,
      "y": 10,
      "z": -6,
      "name": "Rock_Aqua_Brick_Half",
      "rotation": 7
    },
    {
      "x": -9,
      "y": 13,
      "z": -6,
      "name": "Rock_Aqua_Cobble_Roof_Hollow",
      "rotation": 3
    },
    {
      "x": -9,
      "y": 16,
      "z": -6,
      "name": "*Rock_Aqua_Cobble_Roof_Hollow_State_Definitions_Inverted_Corner_Left",
      "rotation": 2
    },
    {
      "x": -9,
      "y": 0,
      "z": -5,
      "name": "Rock_Aqua_Brick_Smooth",
      "rotation": 1
    },
    {
      "x": -9,
      "y": 1,
      "z": -5,
      "name": "Rock_Aqua_Brick_Smooth",
      "rotation": 1
    },
    {
      "x": -9,
      "y": 2,
      "z": -5,
      "name": "Rock_Aqua_Brick_Smooth",
      "rotation": 1
    },
    {
      "x": -9,
      "y": 3,
      "z": -5,
      "name": "Rock_Aqua_Brick_Smooth",
      "rotation": 1
    },
    {
      "x": -9,
      "y": 4,
      "z": -5,
      "name": "Rock_Aqua_Brick_Smooth",
      "rotation": 1
    },
    {
      "x": -9,
      "y": 5,
      "z": -5,
      "name": "Rock_Aqua_Brick_Smooth",
      "rotation": 1
    },
    {
      "x": -9,
      "y": 6,
      "z": -5,
      "name": "Rock_Aqua_Brick_Smooth",
      "rotation": 1
    },
    {
      "x": -9,
      "y": 7,
      "z": -5,
      "name": "Rock_Aqua_Brick_Smooth",
      "rotation": 1
    },
    {
      "x": -9,
      "y": 8,
      "z": -5,
      "name": "Rock_Aqua_Brick_Smooth",
      "rotation": 1
    },
    {
      "x": -9,
      "y": 9,
      "z": -5,
      "name": "Rock_Aqua_Brick_Smooth",
      "rotation": 1
    },
    {
      "x": -9,
      "y": 10,
      "z": -5,
      "name": "Rock_Aqua_Brick_Smooth",
      "rotation": 1
    },
    {
      "x": -9,
      "y": 11,
      "z": -5,
      "name": "Rock_Aqua_Brick_Smooth",
      "rotation": 1
    },
    {
      "x": -9,
      "y": 12,
      "z": -5,
      "name": "Rock_Aqua_Brick_Smooth",
      "rotation": 1
    },
    {
      "x": -9,
      "y": 13,
      "z": -5,
      "name": "Rock_Aqua_Brick_Smooth",
      "rotation": 1
    },
    {
      "x": -9,
      "y": 14,
      "z": -5,
      "name": "Rock_Aqua_Brick_Smooth",
      "rotation": 1
    },
    {
      "x": -9,
      "y": 15,
      "z": -5,
      "name": "Rock_Aqua_Brick_Smooth",
      "rotation": 1
    },
    {
      "x": -9,
      "y": 16,
      "z": -5,
      "name": "Rock_Aqua_Brick_Smooth",
      "rotation": 3
    },
    {
      "x": -9,
      "y": 17,
      "z": -5,
      "name": "*Rock_Aqua_Cobble_Roof_State_Definitions_Corner_Left",
      "rotation": 2
    },
    {
      "x": -9,
      "y": 0,
      "z": -4,
      "name": "Rock_Aqua_Brick_Smooth",
      "rotation": 1
    },
    {
      "x": -9,
      "y": 1,
      "z": -4,
      "name": "Rock_Aqua_Brick_Smooth",
      "rotation": 1
    },
    {
      "x": -9,
      "y": 2,
      "z": -4,
      "name": "Rock_Aqua_Brick_Smooth",
      "rotation": 1
    },
    {
      "x": -9,
      "y": 3,
      "z": -4,
      "name": "Rock_Aqua_Brick_Smooth",
      "rotation": 1
    },
    {
      "x": -9,
      "y": 4,
      "z": -4,
      "name": "Rock_Aqua_Brick_Smooth",
      "rotation": 1
    },
    {
      "x": -9,
      "y": 5,
      "z": -4,
      "name": "Rock_Aqua_Brick_Smooth",
      "rotation": 1
    },
    {
      "x": -9,
      "y": 6,
      "z": -4,
      "name": "Rock_Aqua_Brick_Smooth",
      "rotation": 1
    },
    {
      "x": -9,
      "y": 7,
      "z": -4,
      "name": "Rock_Aqua_Brick_Smooth",
      "rotation": 1
    },
    {
      "x": -9,
      "y": 8,
      "z": -4,
      "name": "Rock_Aqua_Brick_Smooth",
      "rotation": 1
    },
    {
      "x": -9,
      "y": 9,
      "z": -4,
      "name": "Rock_Aqua_Brick_Smooth",
      "rotation": 1
    },
    {
      "x": -9,
      "y": 10,
      "z": -4,
      "name": "Rock_Aqua_Brick_Smooth",
      "rotation": 1
    },
    {
      "x": -9,
      "y": 11,
      "z": -4,
      "name": "Rock_Aqua_Brick_Smooth",
      "rotation": 1
    },
    {
      "x": -9,
      "y": 12,
      "z": -4,
      "name": "Rock_Aqua_Brick_Smooth",
      "rotation": 1
    },
    {
      "x": -9,
      "y": 13,
      "z": -4,
      "name": "Rock_Aqua_Brick_Smooth",
      "rotation": 1
    },
    {
      "x": -9,
      "y": 14,
      "z": -4,
      "name": "Rock_Aqua_Brick_Smooth",
      "rotation": 1
    },
    {
      "x": -9,
      "y": 15,
      "z": -4,
      "name": "Rock_Aqua_Brick_Smooth",
      "rotation": 1
    },
    {
      "x": -9,
      "y": 16,
      "z": -4,
      "name": "Rock_Aqua_Brick_Smooth",
      "rotation": 3
    },
    {
      "x": -9,
      "y": 17,
      "z": -4,
      "name": "Rock_Aqua_Cobble_Roof",
      "rotation": 3
    },
    {
      "x": -9,
      "y": 0,
      "z": -3,
      "name": "Rock_Aqua_Brick_Smooth",
      "rotation": 1
    },
    {
      "x": -9,
      "y": 1,
      "z": -3,
      "name": "Rock_Aqua_Brick_Smooth",
      "rotation": 1
    },
    {
      "x": -9,
      "y": 2,
      "z": -3,
      "name": "Rock_Aqua_Brick_Smooth",
      "rotation": 1
    },
    {
      "x": -9,
      "y": 3,
      "z": -3,
      "name": "Rock_Aqua_Brick_Smooth",
      "rotation": 1
    },
    {
      "x": -9,
      "y": 4,
      "z": -3,
      "name": "Rock_Aqua_Brick_Smooth",
      "rotation": 1
    },
    {
      "x": -9,
      "y": 5,
      "z": -3,
      "name": "Rock_Aqua_Brick_Smooth",
      "rotation": 1
    },
    {
      "x": -9,
      "y": 6,
      "z": -3,
      "name": "Rock_Aqua_Brick_Smooth",
      "rotation": 1
    },
    {
      "x": -9,
      "y": 7,
      "z": -3,
      "name": "Rock_Aqua_Brick_Smooth",
      "rotation": 1
    },
    {
      "x": -9,
      "y": 8,
      "z": -3,
      "name": "Rock_Aqua_Brick_Smooth",
      "rotation": 1
    },
    {
      "x": -9,
      "y": 9,
      "z": -3,
      "name": "Rock_Aqua_Brick_Smooth",
      "rotation": 1
    },
    {
      "x": -9,
      "y": 10,
      "z": -3,
      "name": "Rock_Aqua_Brick_Smooth",
      "rotation": 1
    },
    {
      "x": -9,
      "y": 11,
      "z": -3,
      "name": "Rock_Aqua_Brick_Smooth",
      "rotation": 1
    },
    {
      "x": -9,
      "y": 12,
      "z": -3,
      "name": "Rock_Aqua_Brick_Smooth",
      "rotation": 1
    },
    {
      "x": -9,
      "y": 13,
      "z": -3,
      "name": "Rock_Aqua_Brick_Smooth",
      "rotation": 1
    },
    {
      "x": -9,
      "y": 14,
      "z": -3,
      "name": "Rock_Aqua_Brick_Smooth",
      "rotation": 1
    },
    {
      "x": -9,
      "y": 15,
      "z": -3,
      "name": "Rock_Aqua_Brick_Smooth",
      "rotation": 1
    },
    {
      "x": -9,
      "y": 16,
      "z": -3,
      "name": "Rock_Aqua_Brick_Smooth",
      "rotation": 3
    },
    {
      "x": -9,
      "y": 17,
      "z": -3,
      "name": "Rock_Aqua_Cobble_Roof",
      "rotation": 3
    },
    {
      "x": -9,
      "y": 0,
      "z": -2,
      "name": "Rock_Aqua_Brick",
      "rotation": 1
    },
    {
      "x": -9,
      "y": 1,
      "z": -2,
      "name": "Rock_Aqua_Brick_Beam"
    },
    {
      "x": -9,
      "y": 2,
      "z": -2,
      "name": "Rock_Aqua_Brick_Beam"
    },
    {
      "x": -9,
      "y": 3,
      "z": -2,
      "name": "Rock_Aqua_Brick_Beam"
    },
    {
      "x": -9,
      "y": 4,
      "z": -2,
      "name": "Rock_Aqua_Brick_Beam"
    },
    {
      "x": -9,
      "y": 5,
      "z": -2,
      "name": "Rock_Aqua_Brick_Beam"
    },
    {
      "x": -9,
      "y": 6,
      "z": -2,
      "name": "Rock_Aqua_Brick_Beam"
    },
    {
      "x": -9,
      "y": 7,
      "z": -2,
      "name": "Rock_Aqua_Brick_Pillar_Base",
      "rotation": 8
    },
    {
      "x": -9,
      "y": 8,
      "z": -2,
      "name": "Rock_Aqua_Brick",
      "rotation": 1
    },
    {
      "x": -9,
      "y": 9,
      "z": -2,
      "name": "Rock_Aqua_Brick",
      "rotation": 1
    },
    {
      "x": -9,
      "y": 14,
      "z": -2,
      "name": "Rock_Aqua_Brick_Stairs",
      "rotation": 11
    },
    {
      "x": -9,
      "y": 15,
      "z": -2,
      "name": "Rock_Aqua_Brick_Pillar_Base",
      "rotation": 4
    },
    {
      "x": -9,
      "y": 16,
      "z": -2,
      "name": "Rock_Aqua_Brick_Stairs",
      "rotation": 1
    },
    {
      "x": -9,
      "y": 17,
      "z": -2,
      "name": "*Rock_Aqua_Cobble_Roof_Hollow_State_Definitions_Inverted_Corner_Left",
      "rotation": 2
    },
    {
      "x": -9,
      "y": 0,
      "z": -1,
      "name": "Rock_Aqua_Brick"
    },
    {
      "x": -9,
      "y": 5,
      "z": -1,
      "name": "Rock_Aqua_Brick_Smooth_Half",
      "rotation": 5
    },
    {
      "x": -9,
      "y": 7,
      "z": -1,
      "name": "Rock_Aqua_Brick_Half",
      "rotation": 8
    },
    {
      "x": -9,
      "y": 8,
      "z": -1,
      "name": "Rock_Aqua_Brick"
    },
    {
      "x": -9,
      "y": 9,
      "z": -1,
      "name": "Rock_Aqua_Brick"
    },
    {
      "x": -9,
      "y": 14,
      "z": -1,
      "name": "Rock_Aqua_Brick_Stairs",
      "rotation": 11
    },
    {
      "x": -9,
      "y": 15,
      "z": -1,
      "name": "Rock_Aqua_Brick_Pillar_Middle",
      "rotation": 4
    },
    {
      "x": -9,
      "y": 16,
      "z": -1,
      "name": "Rock_Aqua_Brick_Stairs",
      "rotation": 1
    },
    {
      "x": -9,
      "y": 18,
      "z": -1,
      "name": "*Rock_Aqua_Cobble_Roof_Hollow_State_Definitions_Corner_Left",
      "rotation": 2
    },
    {
      "x": -9,
      "y": 0,
      "z": 0,
      "name": "Rock_Aqua_Brick"
    },
    {
      "x": -9,
      "y": 6,
      "z": 0,
      "name": "Rock_Aqua_Brick_Smooth_Half",
      "rotation": 5
    },
    {
      "x": -9,
      "y": 7,
      "z": 0,
      "name": "Rock_Aqua_Brick_Half",
      "rotation": 8
    },
    {
      "x": -9,
      "y": 8,
      "z": 0,
      "name": "Rock_Aqua_Brick"
    },
    {
      "x": -9,
      "y": 9,
      "z": 0,
      "name": "Rock_Aqua_Brick"
    },
    {
      "x": -9,
      "y": 14,
      "z": 0,
      "name": "Rock_Aqua_Brick_Stairs",
      "rotation": 11
    },
    {
      "x": -9,
      "y": 15,
      "z": 0,
      "name": "Rock_Aqua_Brick_Pillar_Middle",
      "rotation": 4
    },
    {
      "x": -9,
      "y": 16,
      "z": 0,
      "name": "Rock_Aqua_Brick_Stairs",
      "rotation": 1
    },
    {
      "x": -9,
      "y": 18,
      "z": 0,
      "name": "Rock_Aqua_Cobble_Roof_Hollow",
      "rotation": 3
    },
    {
      "x": -9,
      "y": 0,
      "z": 1,
      "name": "Rock_Aqua_Brick"
    },
    {
      "x": -9,
      "y": 5,
      "z": 1,
      "name": "Rock_Aqua_Brick_Smooth_Half",
      "rotation": 5
    },
    {
      "x": -9,
      "y": 7,
      "z": 1,
      "name": "Rock_Aqua_Brick_Half",
      "rotation": 8
    },
    {
      "x": -9,
      "y": 8,
      "z": 1,
      "name": "Rock_Aqua_Brick"
    },
    {
      "x": -9,
      "y": 9,
      "z": 1,
      "name": "Rock_Aqua_Brick"
    },
    {
      "x": -9,
      "y": 14,
      "z": 1,
      "name": "Rock_Aqua_Brick_Stairs",
      "rotation": 11
    },
    {
      "x": -9,
      "y": 15,
      "z": 1,
      "name": "Rock_Aqua_Brick_Pillar_Middle",
      "rotation": 6
    },
    {
      "x": -9,
      "y": 16,
      "z": 1,
      "name": "Rock_Aqua_Brick_Stairs",
      "rotation": 1
    },
    {
      "x": -9,
      "y": 18,
      "z": 1,
      "name": "*Rock_Aqua_Cobble_Roof_Hollow_State_Definitions_Corner_Left",
      "rotation": 3
    },
    {
      "x": -9,
      "y": 0,
      "z": 2,
      "name": "Rock_Aqua_Brick",
      "rotation": 2
    },
    {
      "x": -9,
      "y": 1,
      "z": 2,
      "name": "Rock_Aqua_Brick_Beam"
    },
    {
      "x": -9,
      "y": 2,
      "z": 2,
      "name": "Rock_Aqua_Brick_Beam"
    },
    {
      "x": -9,
      "y": 3,
      "z": 2,
      "name": "Rock_Aqua_Brick_Beam"
    },
    {
      "x": -9,
      "y": 4,
      "z": 2,
      "name": "Rock_Aqua_Brick_Beam"
    },
    {
      "x": -9,
      "y": 5,
      "z": 2,
      "name": "Rock_Aqua_Brick_Beam"
    },
    {
      "x": -9,
      "y": 6,
      "z": 2,
      "name": "Rock_Aqua_Brick_Beam"
    },
    {
      "x": -9,
      "y": 7,
      "z": 2,
      "name": "Rock_Aqua_Brick_Pillar_Base",
      "rotation": 8
    },
    {
      "x": -9,
      "y": 8,
      "z": 2,
      "name": "Rock_Aqua_Brick",
      "rotation": 2
    },
    {
      "x": -9,
      "y": 9,
      "z": 2,
      "name": "Rock_Aqua_Brick",
      "rotation": 2
    },
    {
      "x": -9,
      "y": 10,
      "z": 2,
      "name": "Plant_Moss_Short_Blue",
      "support": 15
    },
    {
      "x": -9,
      "y": 14,
      "z": 2,
      "name": "Rock_Aqua_Brick_Stairs",
      "rotation": 11
    },
    {
      "x": -9,
      "y": 15,
      "z": 2,
      "name": "Rock_Aqua_Brick_Pillar_Base",
      "rotation": 6
    },
    {
      "x": -9,
      "y": 16,
      "z": 2,
      "name": "Rock_Aqua_Brick_Stairs",
      "rotation": 1
    },
    {
      "x": -9,
      "y": 17,
      "z": 2,
      "name": "*Rock_Aqua_Cobble_Roof_Hollow_State_Definitions_Inverted_Corner_Right"
    },
    {
      "x": -9,
      "y": 0,
      "z": 3,
      "name": "Rock_Aqua_Brick_Smooth",
      "rotation": 2
    },
    {
      "x": -9,
      "y": 1,
      "z": 3,
      "name": "Rock_Aqua_Brick_Smooth",
      "rotation": 2
    },
    {
      "x": -9,
      "y": 2,
      "z": 3,
      "name": "Rock_Aqua_Brick_Smooth",
      "rotation": 2
    },
    {
      "x": -9,
      "y": 3,
      "z": 3,
      "name": "Rock_Aqua_Brick_Smooth",
      "rotation": 2
    },
    {
      "x": -9,
      "y": 4,
      "z": 3,
      "name": "Rock_Aqua_Brick_Smooth",
      "rotation": 2
    },
    {
      "x": -9,
      "y": 5,
      "z": 3,
      "name": "Rock_Aqua_Brick_Smooth",
      "rotation": 2
    },
    {
      "x": -9,
      "y": 6,
      "z": 3,
      "name": "Rock_Aqua_Brick_Smooth",
      "rotation": 2
    },
    {
      "x": -9,
      "y": 7,
      "z": 3,
      "name": "Rock_Aqua_Brick_Smooth",
      "rotation": 2
    },
    {
      "x": -9,
      "y": 8,
      "z": 3,
      "name": "Rock_Aqua_Brick_Smooth",
      "rotation": 2
    },
    {
      "x": -9,
      "y": 9,
      "z": 3,
      "name": "Rock_Aqua_Brick_Smooth",
      "rotation": 2
    },
    {
      "x": -9,
      "y": 10,
      "z": 3,
      "name": "Rock_Aqua_Brick_Smooth",
      "rotation": 2
    },
    {
      "x": -9,
      "y": 11,
      "z": 3,
      "name": "Rock_Aqua_Brick_Smooth",
      "rotation": 2
    },
    {
      "x": -9,
      "y": 12,
      "z": 3,
      "name": "Rock_Aqua_Brick_Smooth",
      "rotation": 2
    },
    {
      "x": -9,
      "y": 13,
      "z": 3,
      "name": "Rock_Aqua_Brick_Smooth"
    },
    {
      "x": -9,
      "y": 14,
      "z": 3,
      "name": "Rock_Aqua_Brick_Smooth",
      "rotation": 2
    },
    {
      "x": -9,
      "y": 15,
      "z": 3,
      "name": "Rock_Aqua_Brick_Smooth",
      "rotation": 2
    },
    {
      "x": -9,
      "y": 16,
      "z": 3,
      "name": "Rock_Aqua_Brick_Smooth"
    },
    {
      "x": -9,
      "y": 17,
      "z": 3,
      "name": "Rock_Aqua_Cobble_Roof",
      "rotation": 3
    },
    {
      "x": -9,
      "y": 0,
      "z": 4,
      "name": "Rock_Aqua_Brick_Smooth",
      "rotation": 2
    },
    {
      "x": -9,
      "y": 1,
      "z": 4,
      "name": "Rock_Aqua_Brick_Smooth",
      "rotation": 2
    },
    {
      "x": -9,
      "y": 2,
      "z": 4,
      "name": "Rock_Aqua_Brick_Smooth",
      "rotation": 2
    },
    {
      "x": -9,
      "y": 3,
      "z": 4,
      "name": "Rock_Aqua_Brick_Smooth",
      "rotation": 2
    },
    {
      "x": -9,
      "y": 4,
      "z": 4,
      "name": "Rock_Aqua_Brick_Smooth",
      "rotation": 2
    },
    {
      "x": -9,
      "y": 5,
      "z": 4,
      "name": "Rock_Aqua_Brick_Smooth",
      "rotation": 2
    },
    {
      "x": -9,
      "y": 6,
      "z": 4,
      "name": "Rock_Aqua_Brick_Smooth",
      "rotation": 2
    },
    {
      "x": -9,
      "y": 7,
      "z": 4,
      "name": "Rock_Aqua_Brick_Smooth",
      "rotation": 2
    },
    {
      "x": -9,
      "y": 8,
      "z": 4,
      "name": "Rock_Aqua_Brick_Smooth",
      "rotation": 2
    },
    {
      "x": -9,
      "y": 9,
      "z": 4,
      "name": "Rock_Aqua_Brick_Smooth",
      "rotation": 2
    },
    {
      "x": -9,
      "y": 10,
      "z": 4,
      "name": "Rock_Aqua_Brick_Smooth",
      "rotation": 2
    },
    {
      "x": -9,
      "y": 11,
      "z": 4,
      "name": "Rock_Aqua_Brick_Smooth",
      "rotation": 2
    },
    {
      "x": -9,
      "y": 12,
      "z": 4,
      "name": "Rock_Aqua_Brick_Smooth",
      "rotation": 2
    },
    {
      "x": -9,
      "y": 13,
      "z": 4,
      "name": "Rock_Aqua_Brick_Smooth",
      "rotation": 2
    },
    {
      "x": -9,
      "y": 14,
      "z": 4,
      "name": "Rock_Aqua_Brick_Smooth",
      "rotation": 2
    },
    {
      "x": -9,
      "y": 15,
      "z": 4,
      "name": "Rock_Aqua_Brick_Smooth",
      "rotation": 2
    },
    {
      "x": -9,
      "y": 16,
      "z": 4,
      "name": "Rock_Aqua_Brick_Smooth"
    },
    {
      "x": -9,
      "y": 17,
      "z": 4,
      "name": "Rock_Aqua_Cobble_Roof",
      "rotation": 3
    },
    {
      "x": -9,
      "y": 0,
      "z": 5,
      "name": "Rock_Aqua_Brick_Smooth",
      "rotation": 2
    },
    {
      "x": -9,
      "y": 1,
      "z": 5,
      "name": "Rock_Aqua_Brick_Smooth",
      "rotation": 2
    },
    {
      "x": -9,
      "y": 2,
      "z": 5,
      "name": "Rock_Aqua_Brick_Smooth",
      "rotation": 2
    },
    {
      "x": -9,
      "y": 3,
      "z": 5,
      "name": "Rock_Aqua_Brick_Smooth",
      "rotation": 2
    },
    {
      "x": -9,
      "y": 4,
      "z": 5,
      "name": "Rock_Aqua_Brick_Smooth",
      "rotation": 2
    },
    {
      "x": -9,
      "y": 5,
      "z": 5,
      "name": "Rock_Aqua_Brick_Smooth",
      "rotation": 2
    },
    {
      "x": -9,
      "y": 6,
      "z": 5,
      "name": "Rock_Aqua_Brick_Smooth",
      "rotation": 2
    },
    {
      "x": -9,
      "y": 7,
      "z": 5,
      "name": "Rock_Aqua_Brick_Smooth",
      "rotation": 2
    },
    {
      "x": -9,
      "y": 8,
      "z": 5,
      "name": "Rock_Aqua_Brick_Smooth",
      "rotation": 2
    },
    {
      "x": -9,
      "y": 9,
      "z": 5,
      "name": "Rock_Aqua_Brick_Smooth",
      "rotation": 2
    },
    {
      "x": -9,
      "y": 10,
      "z": 5,
      "name": "Rock_Aqua_Brick_Smooth",
      "rotation": 2
    },
    {
      "x": -9,
      "y": 11,
      "z": 5,
      "name": "Rock_Aqua_Brick_Smooth",
      "rotation": 2
    },
    {
      "x": -9,
      "y": 12,
      "z": 5,
      "name": "Rock_Aqua_Brick_Smooth",
      "rotation": 2
    },
    {
      "x": -9,
      "y": 13,
      "z": 5,
      "name": "Rock_Aqua_Brick_Smooth",
      "rotation": 2
    },
    {
      "x": -9,
      "y": 14,
      "z": 5,
      "name": "Rock_Aqua_Brick_Smooth",
      "rotation": 2
    },
    {
      "x": -9,
      "y": 15,
      "z": 5,
      "name": "Rock_Aqua_Brick_Smooth",
      "rotation": 2
    },
    {
      "x": -9,
      "y": 16,
      "z": 5,
      "name": "Rock_Aqua_Brick_Smooth"
    },
    {
      "x": -9,
      "y": 17,
      "z": 5,
      "name": "*Rock_Aqua_Cobble_Roof_State_Definitions_Corner_Left",
      "rotation": 3
    },
    {
      "x": -9,
      "y": 0,
      "z": 6,
      "name": "Rock_Aqua_Brick_Smooth",
      "rotation": 2
    },
    {
      "x": -9,
      "y": 1,
      "z": 6,
      "name": "Rock_Aqua_Brick_Decorative",
      "rotation": 2
    },
    {
      "x": -9,
      "y": 2,
      "z": 6,
      "name": "*Rock_Aqua_Brick_Wall_State_Definitions_Corner"
    },
    {
      "x": -9,
      "y": 3,
      "z": 6,
      "name": "Furniture_Temple_Dark_Stool",
      "rotation": 3
    },
    {
      "x": -9,
      "y": 5,
      "z": 6,
      "name": "Rock_Aqua_Cobble_Roof_Hollow"
    },
    {
      "x": -9,
      "y": 6,
      "z": 6,
      "name": "Rock_Aqua_Brick_Smooth_Half",
      "rotation": 7
    },
    {
      "x": -9,
      "y": 7,
      "z": 6,
      "name": "Rock_Aqua_Brick_Smooth_Half",
      "rotation": 7
    },
    {
      "x": -9,
      "y": 10,
      "z": 6,
      "name": "Rock_Aqua_Brick_Half",
      "rotation": 7
    },
    {
      "x": -9,
      "y": 13,
      "z": 6,
      "name": "Rock_Aqua_Cobble_Roof_Hollow",
      "rotation": 3
    },
    {
      "x": -9,
      "y": 16,
      "z": 6,
      "name": "*Rock_Aqua_Cobble_Roof_Hollow_State_Definitions_Inverted_Corner_Left",
      "rotation": 3
    },
    {
      "x": -9,
      "y": 0,
      "z": 7,
      "name": "Rock_Aqua_Brick_Ornate",
      "rotation": 2
    },
    {
      "x": -9,
      "y": 1,
      "z": 7,
      "name": "Rock_Aqua_Brick_Decorative",
      "rotation": 2
    },
    {
      "x": -9,
      "y": 2,
      "z": 7,
      "name": "Rock_Aqua_Brick_Wall",
      "rotation": 3
    },
    {
      "x": -9,
      "y": 6,
      "z": 7,
      "name": "Rock_Aqua_Brick_Smooth_Half",
      "rotation": 7
    },
    {
      "x": -9,
      "y": 7,
      "z": 7,
      "name": "Rock_Aqua_Brick_Smooth_Half",
      "rotation": 7
    },
    {
      "x": -9,
      "y": 10,
      "z": 7,
      "name": "Rock_Aqua_Brick_Half",
      "rotation": 7
    },
    {
      "x": -9,
      "y": 13,
      "z": 7,
      "name": "Rock_Aqua_Cobble_Roof_Hollow",
      "rotation": 3
    },
    {
      "x": -9,
      "y": 16,
      "z": 7,
      "name": "Rock_Aqua_Cobble_Roof_Hollow",
      "rotation": 3
    },
    {
      "x": -9,
      "y": 0,
      "z": 8,
      "name": "Rock_Aqua_Brick_Smooth",
      "rotation": 2
    },
    {
      "x": -9,
      "y": 1,
      "z": 8,
      "name": "Rock_Aqua_Brick_Decorative",
      "rotation": 2
    },
    {
      "x": -9,
      "y": 2,
      "z": 8,
      "name": "*Rock_Aqua_Brick_Wall_State_Definitions_Corner",
      "rotation": 2
    },
    {
      "x": -9,
      "y": 13,
      "z": 8,
      "name": "*Rock_Aqua_Cobble_Roof_Hollow_State_Definitions_Corner_Left",
      "rotation": 3
    },
    {
      "x": -9,
      "y": 16,
      "z": 8,
      "name": "*Rock_Aqua_Cobble_Roof_Hollow_State_Definitions_Corner_Right"
    },
    {
      "x": -9,
      "y": 15,
      "z": 9,
      "name": "*Rock_Aqua_Cobble_Roof_Hollow_State_Definitions_Inverted_Corner_Right"
    },
    {
      "x": -8,
      "y": 0,
      "z": -9,
      "name": "Rock_Aqua_Brick_Smooth",
      "rotation": 1
    },
    {
      "x": -8,
      "y": 1,
      "z": -9,
      "name": "Rock_Aqua_Brick_Decorative",
      "rotation": 1
    },
    {
      "x": -8,
      "y": 2,
      "z": -9,
      "name": "*Rock_Aqua_Brick_Wall_State_Definitions_Corner",
      "rotation": 1
    },
    {
      "x": -8,
      "y": 13,
      "z": -9,
      "name": "*Rock_Aqua_Cobble_Roof_Hollow_State_Definitions_Corner_Left",
      "rotation": 2
    },
    {
      "x": -8,
      "y": 16,
      "z": -9,
      "name": "*Rock_Aqua_Cobble_Roof_Hollow_State_Definitions_Corner_Right",
      "rotation": 3
    },
    {
      "x": -8,
      "y": 0,
      "z": -8,
      "name": "Rock_Aqua_Brick_Ornate",
      "rotation": 1
    },
    {
      "x": -8,
      "y": 1,
      "z": -8,
      "name": "Rock_Aqua_Brick_Decorative",
      "rotation": 1
    },
    {
      "x": -8,
      "y": 2,
      "z": -8,
      "name": "*Rock_Aqua_Brick_Wall_State_Definitions_Corner",
      "rotation": 3
    },
    {
      "x": -8,
      "y": 3,
      "z": -8,
      "name": "Furniture_Temple_Dark_Stool",
      "rotation": 2
    },
    {
      "x": -8,
      "y": 6,
      "z": -8,
      "name": "Rock_Aqua_Brick",
      "rotation": 1
    },
    {
      "x": -8,
      "y": 7,
      "z": -8,
      "name": "Rock_Aqua_Brick",
      "rotation": 1
    },
    {
      "x": -8,
      "y": 10,
      "z": -8,
      "name": "Rock_Aqua_Brick_Ornate",
      "rotation": 1
    },
    {
      "x": -8,
      "y": 13,
      "z": -8,
      "name": "*Rock_Aqua_Cobble_Roof_Hollow_State_Definitions_Inverted_Corner_Right",
      "rotation": 3
    },
    {
      "x": -8,
      "y": 16,
      "z": -8,
      "name": "*Rock_Aqua_Cobble_Roof_Hollow_State_Definitions_Inverted_Corner_Left",
      "rotation": 2
    },
    {
      "x": -8,
      "y": 0,
      "z": -7,
      "name": "Rock_Aqua_Brick_Smooth",
      "rotation": 1
    },
    {
      "x": -8,
      "y": 1,
      "z": -7,
      "name": "Rock_Aqua_Brick_Smooth",
      "rotation": 1
    },
    {
      "x": -8,
      "y": 2,
      "z": -7,
      "name": "Rock_Aqua_Brick_Smooth",
      "rotation": 1
    },
    {
      "x": -8,
      "y": 3,
      "z": -7,
      "name": "Rock_Aqua_Brick_Smooth",
      "rotation": 1
    },
    {
      "x": -8,
      "y": 4,
      "z": -7,
      "name": "Rock_Aqua_Brick_Smooth",
      "rotation": 1
    },
    {
      "x": -8,
      "y": 5,
      "z": -7,
      "name": "Rock_Aqua_Brick_Smooth",
      "rotation": 1
    },
    {
      "x": -8,
      "y": 6,
      "z": -7,
      "name": "Rock_Aqua_Brick_Smooth",
      "rotation": 1
    },
    {
      "x": -8,
      "y": 7,
      "z": -7,
      "name": "Rock_Aqua_Brick_Smooth",
      "rotation": 1
    },
    {
      "x": -8,
      "y": 8,
      "z": -7,
      "name": "Rock_Aqua_Brick_Smooth",
      "rotation": 1
    },
    {
      "x": -8,
      "y": 9,
      "z": -7,
      "name": "Rock_Aqua_Brick_Smooth",
      "rotation": 1
    },
    {
      "x": -8,
      "y": 10,
      "z": -7,
      "name": "Rock_Aqua_Brick_Smooth",
      "rotation": 1
    },
    {
      "x": -8,
      "y": 13,
      "z": -7,
      "name": "Rock_Aqua_Brick_Smooth",
      "rotation": 1
    },
    {
      "x": -8,
      "y": 14,
      "z": -7,
      "name": "Rock_Aqua_Brick_Smooth",
      "rotation": 1
    },
    {
      "x": -8,
      "y": 15,
      "z": -7,
      "name": "Rock_Aqua_Brick_Smooth",
      "rotation": 1
    },
    {
      "x": -8,
      "y": 16,
      "z": -7,
      "name": "Rock_Aqua_Brick_Smooth",
      "rotation": 3
    },
    {
      "x": -8,
      "y": 17,
      "z": -7,
      "name": "*Rock_Aqua_Cobble_Roof_State_Definitions_Corner_Left",
      "rotation": 2
    },
    {
      "x": -8,
      "y": 0,
      "z": -6,
      "name": "Rock_Aqua_Brick_Smooth",
      "rotation": 1
    },
    {
      "x": -8,
      "y": 1,
      "z": -6,
      "name": "Rock_Aqua_Brick_Smooth",
      "rotation": 1
    },
    {
      "x": -8,
      "y": 2,
      "z": -6,
      "name": "Rock_Aqua_Brick_Smooth",
      "rotation": 1
    },
    {
      "x": -8,
      "y": 3,
      "z": -6,
      "name": "Rock_Aqua_Brick_Smooth",
      "rotation": 1
    },
    {
      "x": -8,
      "y": 4,
      "z": -6,
      "name": "Rock_Aqua_Brick_Smooth",
      "rotation": 1
    },
    {
      "x": -8,
      "y": 5,
      "z": -6,
      "name": "Rock_Aqua_Brick_Smooth",
      "rotation": 1
    },
    {
      "x": -8,
      "y": 6,
      "z": -6,
      "name": "Rock_Aqua_Brick_Smooth",
      "rotation": 1
    },
    {
      "x": -8,
      "y": 7,
      "z": -6,
      "name": "Rock_Aqua_Brick_Smooth",
      "rotation": 1
    },
    {
      "x": -8,
      "y": 8,
      "z": -6,
      "name": "Rock_Aqua_Brick_Smooth",
      "rotation": 1
    },
    {
      "x": -8,
      "y": 9,
      "z": -6,
      "name": "Rock_Aqua_Brick_Smooth",
      "rotation": 1
    },
    {
      "x": -8,
      "y": 10,
      "z": -6,
      "name": "Rock_Aqua_Brick_Smooth",
      "rotation": 1
    },
    {
      "x": -8,
      "y": 11,
      "z": -6,
      "name": "Rock_Aqua_Brick_Half",
      "rotation": 6
    },
    {
      "x": -8,
      "y": 12,
      "z": -6,
      "name": "Rock_Aqua_Brick_Half",
      "rotation": 6
    },
    {
      "x": -8,
      "y": 13,
      "z": -6,
      "name": "Rock_Aqua_Brick_Smooth",
      "rotation": 1
    },
    {
      "x": -8,
      "y": 14,
      "z": -6,
      "name": "Rock_Aqua_Brick_Smooth",
      "rotation": 1
    },
    {
      "x": -8,
      "y": 15,
      "z": -6,
      "name": "Rock_Aqua_Brick_Smooth",
      "rotation": 1
    },
    {
      "x": -8,
      "y": 16,
      "z": -6,
      "name": "Rock_Aqua_Brick_Smooth",
      "rotation": 3
    },
    {
      "x": -8,
      "y": 17,
      "z": -6,
      "name": "Rock_Aqua_Cobble_Roof",
      "rotation": 3
    },
    {
      "x": -8,
      "y": 0,
      "z": -5,
      "name": "Rock_Aqua_Brick",
      "rotation": 1
    },
    {
      "x": -8,
      "y": 1,
      "z": -5,
      "name": "Rock_Aqua_Brick_Pillar_Base"
    },
    {
      "x": -8,
      "y": 2,
      "z": -5,
      "name": "Rock_Aqua_Brick_Pillar_Middle"
    },
    {
      "x": -8,
      "y": 3,
      "z": -5,
      "name": "Rock_Aqua_Stalactite_Small"
    },
    {
      "x": -8,
      "y": 5,
      "z": -5,
      "name": "Rock_Aqua_Stalactite_Small",
      "rotation": 8
    },
    {
      "x": -8,
      "y": 6,
      "z": -5,
      "name": "Rock_Aqua_Brick_Pillar_Middle",
      "rotation": 8
    },
    {
      "x": -8,
      "y": 7,
      "z": -5,
      "name": "Rock_Aqua_Brick_Pillar_Base",
      "rotation": 8
    },
    {
      "x": -8,
      "y": 8,
      "z": -5,
      "name": "Rock_Aqua_Brick",
      "rotation": 1
    },
    {
      "x": -8,
      "y": 9,
      "z": -5,
      "name": "Rock_Aqua_Brick",
      "rotation": 1
    },
    {
      "x": -8,
      "y": 10,
      "z": -5,
      "name": "Rock_Aqua_Brick_Stairs"
    },
    {
      "x": -8,
      "y": 11,
      "z": -5,
      "name": "Rock_Aqua_Brick_Half",
      "rotation": 4
    },
    {
      "x": -8,
      "y": 12,
      "z": -5,
      "name": "Rock_Aqua_Brick_Half",
      "rotation": 4
    },
    {
      "x": -8,
      "y": 13,
      "z": -5,
      "name": "Rock_Aqua_Brick_Stairs",
      "rotation": 10
    },
    {
      "x": -8,
      "y": 14,
      "z": -5,
      "name": "Rock_Aqua_Brick_Stairs"
    },
    {
      "x": -8,
      "y": 17,
      "z": -5,
      "name": "*Rock_Aqua_Cobble_Roof_Hollow_State_Definitions_Inverted_Corner_Right",
      "rotation": 3
    },
    {
      "x": -8,
      "y": 0,
      "z": -4,
      "name": "Rock_Aqua_Brick",
      "rotation": 1
    },
    {
      "x": -8,
      "y": 1,
      "z": -4,
      "name": "Rubble_Aqua",
      "support": 15
    },
    {
      "x": -8,
      "y": 7,
      "z": -4,
      "name": "Rock_Aqua_Brick_Half",
      "rotation": 8
    },
    {
      "x": -8,
      "y": 8,
      "z": -4,
      "name": "Rock_Aqua_Brick",
      "rotation": 1
    },
    {
      "x": -8,
      "y": 9,
      "z": -4,
      "name": "Rock_Aqua_Brick",
      "rotation": 1
    },
    {
      "x": -8,
      "y": 18,
      "z": -4,
      "name": "*Rock_Aqua_Cobble_Roof_Hollow_State_Definitions_Corner_Left",
      "rotation": 2
    },
    {
      "x": -8,
      "y": 0,
      "z": -3,
      "name": "Rock_Aqua_Brick",
      "rotation": 1
    },
    {
      "x": -8,
      "y": 7,
      "z": -3,
      "name": "Rock_Aqua_Brick_Half",
      "rotation": 8
    },
    {
      "x": -8,
      "y": 8,
      "z": -3,
      "name": "Rock_Aqua_Brick",
      "rotation": 1
    },
    {
      "x": -8,
      "y": 9,
      "z": -3,
      "name": "Rock_Aqua_Brick",
      "rotation": 1
    },
    {
      "x": -8,
      "y": 10,
      "z": -3,
      "name": "Rubble_Aqua",
      "support": 15
    },
    {
      "x": -8,
      "y": 18,
      "z": -3,
      "name": "Rock_Aqua_Cobble_Roof_Hollow",
      "rotation": 3
    },
    {
      "x": -8,
      "y": 0,
      "z": -2,
      "name": "Rock_Aqua_Brick",
      "rotation": 1
    },
    {
      "x": -8,
      "y": 8,
      "z": -2,
      "name": "Rock_Aqua_Brick",
      "rotation": 1
    },
    {
      "x": -8,
      "y": 9,
      "z": -2,
      "name": "Rock_Aqua_Brick",
      "rotation": 1
    },
    {
      "x": -8,
      "y": 18,
      "z": -2,
      "name": "Rock_Aqua_Cobble_Roof_Hollow",
      "rotation": 3
    },
    {
      "x": -8,
      "y": 0,
      "z": -1,
      "name": "Rock_Aqua_Brick"
    },
    {
      "x": -8,
      "y": 8,
      "z": -1,
      "name": "Rock_Aqua_Brick"
    },
    {
      "x": -8,
      "y": 9,
      "z": -1,
      "name": "Rock_Aqua_Brick"
    },
    {
      "x": -8,
      "y": 18,
      "z": -1,
      "name": "*Rock_Aqua_Cobble_Roof_Hollow_State_Definitions_Inverted_Corner_Right",
      "rotation": 3
    },
    {
      "x": -8,
      "y": 0,
      "z": 0,
      "name": "Rock_Aqua_Brick"
    },
    {
      "x": -8,
      "y": 8,
      "z": 0,
      "name": "Rock_Aqua_Brick"
    },
    {
      "x": -8,
      "y": 9,
      "z": 0,
      "name": "Rock_Aqua_Brick_Pillar_Base",
      "rotation": 8
    },
    {
      "x": -8,
      "y": 19,
      "z": 0,
      "name": "Rock_Aqua_Cobble_Roof_Flat",
      "rotation": 3
    },
    {
      "x": -8,
      "y": 0,
      "z": 1,
      "name": "Rock_Aqua_Brick"
    },
    {
      "x": -8,
      "y": 8,
      "z": 1,
      "name": "Rock_Aqua_Brick"
    },
    {
      "x": -8,
      "y": 9,
      "z": 1,
      "name": "Rock_Aqua_Brick"
    },
    {
      "x": -8,
      "y": 18,
      "z": 1,
      "name": "*Rock_Aqua_Cobble_Roof_Hollow_State_Definitions_Inverted_Corner_Right"
    },
    {
      "x": -8,
      "y": 0,
      "z": 2,
      "name": "Rock_Aqua_Brick",
      "rotation": 2
    },
    {
      "x": -8,
      "y": 8,
      "z": 2,
      "name": "Rock_Aqua_Brick",
      "rotation": 2
    },
    {
      "x": -8,
      "y": 9,
      "z": 2,
      "name": "Rock_Aqua_Brick",
      "rotation": 2
    },
    {
      "x": -8,
      "y": 18,
      "z": 2,
      "name": "Rock_Aqua_Cobble_Roof_Hollow",
      "rotation": 3
    },
    {
      "x": -8,
      "y": 0,
      "z": 3,
      "name": "Rock_Aqua_Brick",
      "rotation": 2
    },
    {
      "x": -8,
      "y": 7,
      "z": 3,
      "name": "Rock_Aqua_Brick_Half",
      "rotation": 8
    },
    {
      "x": -8,
      "y": 8,
      "z": 3,
      "name": "Rock_Aqua_Brick",
      "rotation": 2
    },
    {
      "x": -8,
      "y": 9,
      "z": 3,
      "name": "Rock_Aqua_Brick",
      "rotation": 2
    },
    {
      "x": -8,
      "y": 10,
      "z": 3,
      "name": "Plant_Moss_Rug_Blue",
      "support": 15
    },
    {
      "x": -8,
      "y": 11,
      "z": 3,
      "name": "Plant_Moss_Wall_Blue",
      "support": 15,
      "rotation": 1
    },
    {
      "x": -8,
      "y": 18,
      "z": 3,
      "name": "Rock_Aqua_Cobble_Roof_Hollow",
      "rotation": 3
    },
    {
      "x": -8,
      "y": 0,
      "z": 4,
      "name": "Rock_Aqua_Brick",
      "rotation": 2
    },
    {
      "x": -8,
      "y": 1,
      "z": 4,
      "name": "Rock_Aqua_Brick_Beam"
    },
    {
      "x": -8,
      "y": 2,
      "z": 4,
      "name": "Furniture_Human_Ruins_Lantern"
    },
    {
      "x": -8,
      "y": 7,
      "z": 4,
      "name": "Rock_Aqua_Brick_Half",
      "rotation": 8
    },
    {
      "x": -8,
      "y": 8,
      "z": 4,
      "name": "Rock_Aqua_Brick",
      "rotation": 2
    },
    {
      "x": -8,
      "y": 9,
      "z": 4,
      "name": "Rock_Aqua_Brick",
      "rotation": 2
    },
    {
      "x": -8,
      "y": 10,
      "z": 4,
      "name": "Plant_Moss_Blue",
      "support": 15
    },
    {
      "x": -8,
      "y": 12,
      "z": 4,
      "name": "Plant_Moss_Wall_Blue",
      "support": 15,
      "rotation": 1
    },
    {
      "x": -8,
      "y": 18,
      "z": 4,
      "name": "*Rock_Aqua_Cobble_Roof_Hollow_State_Definitions_Corner_Left",
      "rotation": 3
    },
    {
      "x": -8,
      "y": 0,
      "z": 5,
      "name": "Rock_Aqua_Brick",
      "rotation": 2
    },
    {
      "x": -8,
      "y": 1,
      "z": 5,
      "name": "Rock_Aqua_Brick_Pillar_Base"
    },
    {
      "x": -8,
      "y": 2,
      "z": 5,
      "name": "Rock_Aqua_Brick_Pillar_Middle"
    },
    {
      "x": -8,
      "y": 3,
      "z": 5,
      "name": "Rock_Aqua_Brick_Pillar_Middle"
    },
    {
      "x": -8,
      "y": 4,
      "z": 5,
      "name": "Rock_Aqua_Brick_Pillar_Middle"
    },
    {
      "x": -8,
      "y": 5,
      "z": 5,
      "name": "Rock_Aqua_Brick_Pillar_Middle",
      "rotation": 8
    },
    {
      "x": -8,
      "y": 6,
      "z": 5,
      "name": "Rock_Aqua_Brick_Pillar_Middle",
      "rotation": 8
    },
    {
      "x": -8,
      "y": 7,
      "z": 5,
      "name": "Rock_Aqua_Brick_Pillar_Base",
      "rotation": 8
    },
    {
      "x": -8,
      "y": 8,
      "z": 5,
      "name": "Rock_Aqua_Brick",
      "rotation": 2
    },
    {
      "x": -8,
      "y": 9,
      "z": 5,
      "name": "Rock_Aqua_Brick",
      "rotation": 2
    },
    {
      "x": -8,
      "y": 10,
      "z": 5,
      "name": "Rock_Aqua_Brick_Stairs",
      "rotation": 2
    },
    {
      "x": -8,
      "y": 11,
      "z": 5,
      "name": "Rock_Aqua_Brick_Half",
      "rotation": 6
    },
    {
      "x": -8,
      "y": 12,
      "z": 5,
      "name": "Rock_Aqua_Brick_Half",
      "rotation": 6
    },
    {
      "x": -8,
      "y": 13,
      "z": 5,
      "name": "Rock_Aqua_Brick_Stairs",
      "rotation": 8
    },
    {
      "x": -8,
      "y": 14,
      "z": 5,
      "name": "Rock_Aqua_Brick_Stairs",
      "rotation": 2
    },
    {
      "x": -8,
      "y": 17,
      "z": 5,
      "name": "*Rock_Aqua_Cobble_Roof_Hollow_State_Definitions_Inverted_Corner_Right"
    },
    {
      "x": -8,
      "y": 0,
      "z": 6,
      "name": "Rock_Aqua_Brick_Smooth",
      "rotation": 2
    },
    {
      "x": -8,
      "y": 1,
      "z": 6,
      "name": "Rock_Aqua_Brick_Smooth",
      "rotation": 2
    },
    {
      "x": -8,
      "y": 2,
      "z": 6,
      "name": "Rock_Aqua_Brick_Smooth",
      "rotation": 2
    },
    {
      "x": -8,
      "y": 3,
      "z": 6,
      "name": "Rock_Aqua_Brick_Smooth",
      "rotation": 2
    },
    {
      "x": -8,
      "y": 4,
      "z": 6,
      "name": "Rock_Aqua_Brick_Smooth",
      "rotation": 2
    },
    {
      "x": -8,
      "y": 5,
      "z": 6,
      "name": "Rock_Aqua_Brick_Smooth",
      "rotation": 2
    },
    {
      "x": -8,
      "y": 6,
      "z": 6,
      "name": "Rock_Aqua_Brick_Smooth",
      "rotation": 2
    },
    {
      "x": -8,
      "y": 7,
      "z": 6,
      "name": "Rock_Aqua_Brick_Smooth",
      "rotation": 2
    },
    {
      "x": -8,
      "y": 8,
      "z": 6,
      "name": "Rock_Aqua_Brick_Smooth",
      "rotation": 2
    },
    {
      "x": -8,
      "y": 9,
      "z": 6,
      "name": "Rock_Aqua_Brick_Smooth",
      "rotation": 2
    },
    {
      "x": -8,
      "y": 10,
      "z": 6,
      "name": "Rock_Aqua_Brick_Smooth",
      "rotation": 2
    },
    {
      "x": -8,
      "y": 11,
      "z": 6,
      "name": "Rock_Aqua_Brick_Half",
      "rotation": 4
    },
    {
      "x": -8,
      "y": 12,
      "z": 6,
      "name": "Rock_Aqua_Brick_Half",
      "rotation": 4
    },
    {
      "x": -8,
      "y": 13,
      "z": 6,
      "name": "Rock_Aqua_Brick_Smooth",
      "rotation": 2
    },
    {
      "x": -8,
      "y": 14,
      "z": 6,
      "name": "Rock_Aqua_Brick_Smooth",
      "rotation": 2
    },
    {
      "x": -8,
      "y": 15,
      "z": 6,
      "name": "Rock_Aqua_Brick_Smooth",
      "rotation": 2
    },
    {
      "x": -8,
      "y": 16,
      "z": 6,
      "name": "Rock_Aqua_Brick_Smooth"
    },
    {
      "x": -8,
      "y": 17,
      "z": 6,
      "name": "Rock_Aqua_Cobble_Roof",
      "rotation": 3
    },
    {
      "x": -8,
      "y": 0,
      "z": 7,
      "name": "Rock_Aqua_Brick_Smooth",
      "rotation": 2
    },
    {
      "x": -8,
      "y": 1,
      "z": 7,
      "name": "Rock_Aqua_Brick_Smooth",
      "rotation": 2
    },
    {
      "x": -8,
      "y": 2,
      "z": 7,
      "name": "Rock_Aqua_Brick_Smooth",
      "rotation": 2
    },
    {
      "x": -8,
      "y": 3,
      "z": 7,
      "name": "Rock_Aqua_Brick_Smooth",
      "rotation": 2
    },
    {
      "x": -8,
      "y": 4,
      "z": 7,
      "name": "Rock_Aqua_Brick_Smooth",
      "rotation": 2
    },
    {
      "x": -8,
      "y": 5,
      "z": 7,
      "name": "Rock_Aqua_Brick_Smooth",
      "rotation": 2
    },
    {
      "x": -8,
      "y": 6,
      "z": 7,
      "name": "Rock_Aqua_Brick_Smooth",
      "rotation": 2
    },
    {
      "x": -8,
      "y": 7,
      "z": 7,
      "name": "Rock_Aqua_Brick_Smooth",
      "rotation": 2
    },
    {
      "x": -8,
      "y": 8,
      "z": 7,
      "name": "Rock_Aqua_Brick_Smooth",
      "rotation": 2
    },
    {
      "x": -8,
      "y": 9,
      "z": 7,
      "name": "Rock_Aqua_Brick_Smooth",
      "rotation": 2
    },
    {
      "x": -8,
      "y": 10,
      "z": 7,
      "name": "Rock_Aqua_Brick_Smooth",
      "rotation": 2
    },
    {
      "x": -8,
      "y": 13,
      "z": 7,
      "name": "Rock_Aqua_Brick_Smooth",
      "rotation": 2
    },
    {
      "x": -8,
      "y": 14,
      "z": 7,
      "name": "Rock_Aqua_Brick_Smooth",
      "rotation": 2
    },
    {
      "x": -8,
      "y": 15,
      "z": 7,
      "name": "Rock_Aqua_Brick_Smooth",
      "rotation": 2
    },
    {
      "x": -8,
      "y": 16,
      "z": 7,
      "name": "Rock_Aqua_Brick_Smooth"
    },
    {
      "x": -8,
      "y": 17,
      "z": 7,
      "name": "*Rock_Aqua_Cobble_Roof_State_Definitions_Corner_Right"
    },
    {
      "x": -8,
      "y": 0,
      "z": 8,
      "name": "Rock_Aqua_Brick_Ornate",
      "rotation": 2
    },
    {
      "x": -8,
      "y": 1,
      "z": 8,
      "name": "Rock_Aqua_Brick_Decorative",
      "rotation": 2
    },
    {
      "x": -8,
      "y": 2,
      "z": 8,
      "name": "*Rock_Aqua_Brick_Wall_State_Definitions_Corner"
    },
    {
      "x": -8,
      "y": 3,
      "z": 8,
      "name": "Furniture_Temple_Dark_Stool",
      "rotation": 3
    },
    {
      "x": -8,
      "y": 6,
      "z": 8,
      "name": "Rock_Aqua_Brick",
      "rotation": 2
    },
    {
      "x": -8,
      "y": 7,
      "z": 8,
      "name": "Rock_Aqua_Brick",
      "rotation": 2
    },
    {
      "x": -8,
      "y": 10,
      "z": 8,
      "name": "Rock_Aqua_Brick_Ornate",
      "rotation": 2
    },
    {
      "x": -8,
      "y": 13,
      "z": 8,
      "name": "*Rock_Aqua_Cobble_Roof_Hollow_State_Definitions_Inverted_Corner_Right"
    },
    {
      "x": -8,
      "y": 16,
      "z": 8,
      "name": "*Rock_Aqua_Cobble_Roof_Hollow_State_Definitions_Inverted_Corner_Left",
      "rotation": 3
    },
    {
      "x": -8,
      "y": 0,
      "z": 9,
      "name": "Rock_Aqua_Brick_Smooth",
      "rotation": 2
    },
    {
      "x": -8,
      "y": 1,
      "z": 9,
      "name": "Rock_Aqua_Brick_Decorative",
      "rotation": 2
    },
    {
      "x": -8,
      "y": 2,
      "z": 9,
      "name": "*Rock_Aqua_Brick_Wall_State_Definitions_Corner",
      "rotation": 2
    },
    {
      "x": -8,
      "y": 13,
      "z": 9,
      "name": "*Rock_Aqua_Cobble_Roof_Hollow_State_Definitions_Corner_Left",
      "rotation": 3
    },
    {
      "x": -8,
      "y": 16,
      "z": 9,
      "name": "*Rock_Aqua_Cobble_Roof_Hollow_State_Definitions_Corner_Left",
      "rotation": 3
    },
    {
      "x": -7,
      "y": 15,
      "z": -10,
      "name": "*Rock_Aqua_Cobble_Roof_Hollow_State_Definitions_Inverted_Corner_Right",
      "rotation": 3
    },
    {
      "x": -7,
      "y": 0,
      "z": -9,
      "name": "Rock_Aqua_Brick_Ornate",
      "rotation": 1
    },
    {
      "x": -7,
      "y": 1,
      "z": -9,
      "name": "Rock_Aqua_Brick_Decorative",
      "rotation": 1
    },
    {
      "x": -7,
      "y": 2,
      "z": -9,
      "name": "Rock_Aqua_Brick_Wall",
      "rotation": 2
    },
    {
      "x": -7,
      "y": 6,
      "z": -9,
      "name": "Rock_Aqua_Brick_Smooth_Half",
      "rotation": 6
    },
    {
      "x": -7,
      "y": 7,
      "z": -9,
      "name": "Rock_Aqua_Brick_Smooth_Half",
      "rotation": 6
    },
    {
      "x": -7,
      "y": 10,
      "z": -9,
      "name": "Rock_Aqua_Brick_Half",
      "rotation": 6
    },
    {
      "x": -7,
      "y": 13,
      "z": -9,
      "name": "Rock_Aqua_Cobble_Roof_Hollow",
      "rotation": 2
    },
    {
      "x": -7,
      "y": 16,
      "z": -9,
      "name": "Rock_Aqua_Cobble_Roof_Hollow",
      "rotation": 2
    },
    {
      "x": -7,
      "y": 0,
      "z": -8,
      "name": "Rock_Aqua_Brick_Smooth",
      "rotation": 1
    },
    {
      "x": -7,
      "y": 1,
      "z": -8,
      "name": "Rock_Aqua_Brick_Smooth",
      "rotation": 1
    },
    {
      "x": -7,
      "y": 2,
      "z": -8,
      "name": "Rock_Aqua_Brick_Smooth",
      "rotation": 1
    },
    {
      "x": -7,
      "y": 3,
      "z": -8,
      "name": "Rock_Aqua_Brick_Smooth",
      "rotation": 1
    },
    {
      "x": -7,
      "y": 4,
      "z": -8,
      "name": "Rock_Aqua_Brick_Smooth",
      "rotation": 1
    },
    {
      "x": -7,
      "y": 5,
      "z": -8,
      "name": "Rock_Aqua_Brick_Smooth",
      "rotation": 1
    },
    {
      "x": -7,
      "y": 6,
      "z": -8,
      "name": "Rock_Aqua_Brick_Smooth",
      "rotation": 1
    },
    {
      "x": -7,
      "y": 7,
      "z": -8,
      "name": "Rock_Aqua_Brick_Smooth",
      "rotation": 1
    },
    {
      "x": -7,
      "y": 8,
      "z": -8,
      "name": "Rock_Aqua_Brick_Smooth",
      "rotation": 1
    },
    {
      "x": -7,
      "y": 9,
      "z": -8,
      "name": "Rock_Aqua_Brick_Smooth",
      "rotation": 1
    },
    {
      "x": -7,
      "y": 10,
      "z": -8,
      "name": "Rock_Aqua_Brick_Smooth",
      "rotation": 1
    },
    {
      "x": -7,
      "y": 13,
      "z": -8,
      "name": "Rock_Aqua_Brick_Smooth",
      "rotation": 1
    },
    {
      "x": -7,
      "y": 14,
      "z": -8,
      "name": "Rock_Aqua_Brick_Smooth",
      "rotation": 1
    },
    {
      "x": -7,
      "y": 15,
      "z": -8,
      "name": "Rock_Aqua_Brick_Smooth",
      "rotation": 1
    },
    {
      "x": -7,
      "y": 16,
      "z": -8,
      "name": "Rock_Aqua_Brick_Smooth",
      "rotation": 3
    },
    {
      "x": -7,
      "y": 17,
      "z": -8,
      "name": "*Rock_Aqua_Cobble_Roof_State_Definitions_Corner_Right",
      "rotation": 3
    },
    {
      "x": -7,
      "y": 0,
      "z": -7,
      "name": "Rock_Aqua_Brick",
      "rotation": 1
    },
    {
      "x": -7,
      "y": 7,
      "z": -7,
      "name": "Rock_Aqua_Brick_Pillar_Base",
      "rotation": 8
    },
    {
      "x": -7,
      "y": 8,
      "z": -7,
      "name": "Rock_Aqua_Brick",
      "rotation": 1
    },
    {
      "x": -7,
      "y": 9,
      "z": -7,
      "name": "Rock_Aqua_Brick",
      "rotation": 1
    },
    {
      "x": -7,
      "y": 13,
      "z": -7,
      "name": "*Rock_Aqua_Brick_Stairs_State_Definitions_Inverted_Corner_Left",
      "rotation": 11
    },
    {
      "x": -7,
      "y": 14,
      "z": -7,
      "name": "*Rock_Aqua_Brick_Stairs_State_Definitions_Inverted_Corner_Left"
    },
    {
      "x": -7,
      "y": 17,
      "z": -7,
      "name": "*Rock_Aqua_Cobble_Roof_Hollow_State_Definitions_Inverted_Corner_Right",
      "rotation": 3
    },
    {
      "x": -7,
      "y": 0,
      "z": -6,
      "name": "Rock_Aqua_Brick",
      "rotation": 1
    },
    {
      "x": -7,
      "y": 7,
      "z": -6,
      "name": "Rock_Aqua_Brick_Half",
      "rotation": 8
    },
    {
      "x": -7,
      "y": 8,
      "z": -6,
      "name": "Rock_Aqua_Brick",
      "rotation": 1
    },
    {
      "x": -7,
      "y": 9,
      "z": -6,
      "name": "Rock_Aqua_Brick",
      "rotation": 1
    },
    {
      "x": -7,
      "y": 10,
      "z": -6,
      "name": "Rubble_Aqua",
      "support": 15
    },
    {
      "x": -7,
      "y": 13,
      "z": -6,
      "name": "Rock_Aqua_Brick_Stairs",
      "rotation": 11
    },
    {
      "x": -7,
      "y": 14,
      "z": -6,
      "name": "Rock_Aqua_Brick_Stairs",
      "rotation": 1
    },
    {
      "x": -7,
      "y": 18,
      "z": -6,
      "name": "*Rock_Aqua_Cobble_Roof_Hollow_State_Definitions_Corner_Left",
      "rotation": 2
    },
    {
      "x": -7,
      "y": 0,
      "z": -5,
      "name": "Rock_Aqua_Brick",
      "rotation": 1
    },
    {
      "x": -7,
      "y": 8,
      "z": -5,
      "name": "Rock_Aqua_Brick",
      "rotation": 1
    },
    {
      "x": -7,
      "y": 9,
      "z": -5,
      "name": "Rock_Aqua_Brick",
      "rotation": 1
    },
    {
      "x": -7,
      "y": 13,
      "z": -5,
      "name": "*Rock_Aqua_Brick_Stairs_State_Definitions_Corner_Left",
      "rotation": 11
    },
    {
      "x": -7,
      "y": 14,
      "z": -5,
      "name": "*Rock_Aqua_Brick_Stairs_State_Definitions_Corner_Left"
    },
    {
      "x": -7,
      "y": 18,
      "z": -5,
      "name": "Rock_Aqua_Cobble_Roof_Hollow",
      "rotation": 3
    },
    {
      "x": -7,
      "y": 0,
      "z": -4,
      "name": "Rock_Aqua_Brick",
      "rotation": 1
    },
    {
      "x": -7,
      "y": 8,
      "z": -4,
      "name": "Rock_Aqua_Brick",
      "rotation": 1
    },
    {
      "x": -7,
      "y": 9,
      "z": -4,
      "name": "Rock_Aqua"
    },
    {
      "x": -7,
      "y": 10,
      "z": -4,
      "name": "Rubble_Aqua_Medium",
      "support": 15
    },
    {
      "x": -7,
      "y": 18,
      "z": -4,
      "name": "*Rock_Aqua_Cobble_Roof_Hollow_State_Definitions_Inverted_Corner_Right",
      "rotation": 3
    },
    {
      "x": -7,
      "y": 0,
      "z": -3,
      "name": "Rock_Aqua_Brick",
      "rotation": 1
    },
    {
      "x": -7,
      "y": 8,
      "z": -3,
      "name": "Rock_Aqua_Brick",
      "rotation": 1
    },
    {
      "x": -7,
      "y": 9,
      "z": -3,
      "name": "Rock_Aqua_Brick",
      "rotation": 1
    },
    {
      "x": -7,
      "y": 18,
      "z": -3,
      "name": "Rock_Aqua_Cobble_Half",
      "rotation": 8
    },
    {
      "x": -7,
      "y": 19,
      "z": -3,
      "name": "Rock_Aqua_Cobble_Roof_Shallow",
      "rotation": 3
    },
    {
      "x": -7,
      "y": 0,
      "z": -2,
      "name": "Rock_Aqua_Brick",
      "rotation": 1
    },
    {
      "x": -7,
      "y": 8,
      "z": -2,
      "name": "Rock_Aqua_Brick",
      "rotation": 1
    },
    {
      "x": -7,
      "y": 9,
      "z": -2,
      "name": "Rock_Aqua_Brick",
      "rotation": 1
    },
    {
      "x": -7,
      "y": 18,
      "z": -2,
      "name": "Rock_Aqua_Cobble_Half",
      "rotation": 8
    },
    {
      "x": -7,
      "y": 19,
      "z": -2,
      "name": "Rock_Aqua_Cobble_Roof_Shallow",
      "rotation": 3
    },
    {
      "x": -7,
      "y": 0,
      "z": -1,
      "name": "Rock_Aqua_Brick"
    },
    {
      "x": -7,
      "y": 8,
      "z": -1,
      "name": "Rock_Aqua_Brick"
    },
    {
      "x": -7,
      "y": 9,
      "z": -1,
      "name": "Rock_Aqua_Brick_Pillar_Base",
      "rotation": 8
    },
    {
      "x": -7,
      "y": 18,
      "z": -1,
      "name": "Rock_Aqua_Cobble_Half",
      "rotation": 8
    },
    {
      "x": -7,
      "y": 19,
      "z": -1,
      "name": "Rock_Aqua_Cobble_Roof_Shallow",
      "rotation": 3
    },
    {
      "x": -7,
      "y": 0,
      "z": 0,
      "name": "Rock_Aqua_Brick"
    },
    {
      "x": -7,
      "y": 8,
      "z": 0,
      "name": "Rock_Aqua_Brick"
    },
    {
      "x": -7,
      "y": 9,
      "z": 0,
      "name": "Rock_Aqua_Brick_Pillar_Base",
      "rotation": 8
    },
    {
      "x": -7,
      "y": 18,
      "z": 0,
      "name": "Rock_Aqua_Cobble_Half",
      "rotation": 8
    },
    {
      "x": -7,
      "y": 19,
      "z": 0,
      "name": "Rock_Aqua_Cobble_Roof_Shallow",
      "rotation": 3
    },
    {
      "x": -7,
      "y": 0,
      "z": 1,
      "name": "Rock_Aqua_Brick"
    },
    {
      "x": -7,
      "y": 8,
      "z": 1,
      "name": "Rock_Aqua_Brick"
    },
    {
      "x": -7,
      "y": 9,
      "z": 1,
      "name": "Rock_Aqua_Brick_Pillar_Base",
      "rotation": 8
    },
    {
      "x": -7,
      "y": 18,
      "z": 1,
      "name": "Rock_Aqua_Cobble_Half",
      "rotation": 8
    },
    {
      "x": -7,
      "y": 19,
      "z": 1,
      "name": "Rock_Aqua_Cobble_Roof_Shallow",
      "rotation": 3
    },
    {
      "x": -7,
      "y": 0,
      "z": 2,
      "name": "Rock_Aqua_Brick",
      "rotation": 2
    },
    {
      "x": -7,
      "y": 1,
      "z": 2,
      "name": "Plant_Seaweed_Grass",
      "support": 15
    },
    {
      "x": -7,
      "y": 8,
      "z": 2,
      "name": "Rock_Aqua_Brick",
      "rotation": 2
    },
    {
      "x": -7,
      "y": 9,
      "z": 2,
      "name": "Rock_Aqua_Brick",
      "rotation": 2
    },
    {
      "x": -7,
      "y": 10,
      "z": 2,
      "name": "Plant_Moss_Blue",
      "support": 15
    },
    {
      "x": -7,
      "y": 18,
      "z": 2,
      "name": "Rock_Aqua_Cobble_Half",
      "rotation": 8
    },
    {
      "x": -7,
      "y": 19,
      "z": 2,
      "name": "Rock_Aqua_Cobble_Roof_Shallow",
      "rotation": 3
    },
    {
      "x": -7,
      "y": 0,
      "z": 3,
      "name": "Rock_Aqua_Brick",
      "rotation": 2
    },
    {
      "x": -7,
      "y": 8,
      "z": 3,
      "name": "Rock_Aqua_Brick",
      "rotation": 2
    },
    {
      "x": -7,
      "y": 9,
      "z": 3,
      "name": "Rock_Aqua_Brick",
      "rotation": 2
    },
    {
      "x": -7,
      "y": 18,
      "z": 3,
      "name": "Rock_Aqua_Cobble_Half",
      "rotation": 8
    },
    {
      "x": -7,
      "y": 19,
      "z": 3,
      "name": "Rock_Aqua_Cobble_Roof_Shallow",
      "rotation": 3
    },
    {
      "x": -7,
      "y": 0,
      "z": 4,
      "name": "Rock_Aqua_Brick",
      "rotation": 2
    },
    {
      "x": -7,
      "y": 8,
      "z": 4,
      "name": "Rock_Aqua_Brick",
      "rotation": 2
    },
    {
      "x": -7,
      "y": 9,
      "z": 4,
      "name": "Rock_Aqua_Brick",
      "rotation": 2
    },
    {
      "x": -7,
      "y": 10,
      "z": 4,
      "name": "Plant_Moss_Rug_Blue",
      "support": 15
    },
    {
      "x": -7,
      "y": 18,
      "z": 4,
      "name": "*Rock_Aqua_Cobble_Roof_Hollow_State_Definitions_Inverted_Corner_Right"
    },
    {
      "x": -7,
      "y": 0,
      "z": 5,
      "name": "Rock_Aqua_Brick",
      "rotation": 2
    },
    {
      "x": -7,
      "y": 8,
      "z": 5,
      "name": "Rock_Aqua_Brick",
      "rotation": 2
    },
    {
      "x": -7,
      "y": 9,
      "z": 5,
      "name": "Rock_Aqua_Brick",
      "rotation": 2
    },
    {
      "x": -7,
      "y": 10,
      "z": 5,
      "name": "Plant_Moss_Short_Blue",
      "support": 15
    },
    {
      "x": -7,
      "y": 13,
      "z": 5,
      "name": "*Rock_Aqua_Brick_Stairs_State_Definitions_Corner_Left",
      "rotation": 8
    },
    {
      "x": -7,
      "y": 14,
      "z": 5,
      "name": "*Rock_Aqua_Brick_Stairs_State_Definitions_Corner_Right",
      "rotation": 2
    },
    {
      "x": -7,
      "y": 18,
      "z": 5,
      "name": "Rock_Aqua_Cobble_Roof_Hollow",
      "rotation": 3
    },
    {
      "x": -7,
      "y": 0,
      "z": 6,
      "name": "Rock_Aqua_Brick",
      "rotation": 2
    },
    {
      "x": -7,
      "y": 7,
      "z": 6,
      "name": "Rock_Aqua_Brick_Half",
      "rotation": 8
    },
    {
      "x": -7,
      "y": 8,
      "z": 6,
      "name": "Rock_Aqua_Brick",
      "rotation": 2
    },
    {
      "x": -7,
      "y": 9,
      "z": 6,
      "name": "Rock_Aqua_Brick",
      "rotation": 2
    },
    {
      "x": -7,
      "y": 10,
      "z": 6,
      "name": "Plant_Moss_Blue",
      "support": 15
    },
    {
      "x": -7,
      "y": 13,
      "z": 6,
      "name": "Rock_Aqua_Brick_Stairs",
      "rotation": 11
    },
    {
      "x": -7,
      "y": 14,
      "z": 6,
      "name": "Rock_Aqua_Brick_Stairs",
      "rotation": 1
    },
    {
      "x": -7,
      "y": 18,
      "z": 6,
      "name": "*Rock_Aqua_Cobble_Roof_Hollow_State_Definitions_Corner_Left",
      "rotation": 3
    },
    {
      "x": -7,
      "y": 0,
      "z": 7,
      "name": "Rock_Aqua_Brick",
      "rotation": 2
    },
    {
      "x": -7,
      "y": 7,
      "z": 7,
      "name": "Rock_Aqua_Brick_Pillar_Base",
      "rotation": 8
    },
    {
      "x": -7,
      "y": 8,
      "z": 7,
      "name": "Rock_Aqua_Brick",
      "rotation": 2
    },
    {
      "x": -7,
      "y": 9,
      "z": 7,
      "name": "Rock_Aqua_Brick",
      "rotation": 2
    },
    {
      "x": -7,
      "y": 10,
      "z": 7,
      "name": "Plant_Moss_Wall_Blue",
      "support": 15,
      "rotation": 1
    },
    {
      "x": -7,
      "y": 13,
      "z": 7,
      "name": "*Rock_Aqua_Brick_Stairs_State_Definitions_Inverted_Corner_Right",
      "rotation": 11
    },
    {
      "x": -7,
      "y": 14,
      "z": 7,
      "name": "*Rock_Aqua_Brick_Stairs_State_Definitions_Inverted_Corner_Right",
      "rotation": 2
    },
    {
      "x": -7,
      "y": 17,
      "z": 7,
      "name": "*Rock_Aqua_Cobble_Roof_Hollow_State_Definitions_Inverted_Corner_Right"
    },
    {
      "x": -7,
      "y": 0,
      "z": 8,
      "name": "Rock_Aqua_Brick_Smooth",
      "rotation": 2
    },
    {
      "x": -7,
      "y": 1,
      "z": 8,
      "name": "Rock_Aqua_Brick_Smooth",
      "rotation": 2
    },
    {
      "x": -7,
      "y": 2,
      "z": 8,
      "name": "Rock_Aqua_Brick_Smooth",
      "rotation": 2
    },
    {
      "x": -7,
      "y": 3,
      "z": 8,
      "name": "Rock_Aqua_Brick_Smooth",
      "rotation": 2
    },
    {
      "x": -7,
      "y": 4,
      "z": 8,
      "name": "Rock_Aqua_Brick_Smooth",
      "rotation": 2
    },
    {
      "x": -7,
      "y": 5,
      "z": 8,
      "name": "Rock_Aqua_Brick_Smooth",
      "rotation": 2
    },
    {
      "x": -7,
      "y": 6,
      "z": 8,
      "name": "Rock_Aqua_Brick_Smooth",
      "rotation": 2
    },
    {
      "x": -7,
      "y": 7,
      "z": 8,
      "name": "Rock_Aqua_Brick_Smooth",
      "rotation": 2
    },
    {
      "x": -7,
      "y": 8,
      "z": 8,
      "name": "Rock_Aqua_Brick_Smooth",
      "rotation": 2
    },
    {
      "x": -7,
      "y": 9,
      "z": 8,
      "name": "Rock_Aqua_Brick_Smooth",
      "rotation": 2
    },
    {
      "x": -7,
      "y": 10,
      "z": 8,
      "name": "Rock_Aqua_Brick_Smooth",
      "rotation": 2
    },
    {
      "x": -7,
      "y": 13,
      "z": 8,
      "name": "Rock_Aqua_Brick_Smooth",
      "rotation": 2
    },
    {
      "x": -7,
      "y": 14,
      "z": 8,
      "name": "Rock_Aqua_Brick_Smooth",
      "rotation": 2
    },
    {
      "x": -7,
      "y": 15,
      "z": 8,
      "name": "Rock_Aqua_Brick_Smooth",
      "rotation": 2
    },
    {
      "x": -7,
      "y": 16,
      "z": 8,
      "name": "Rock_Aqua_Brick_Smooth"
    },
    {
      "x": -7,
      "y": 17,
      "z": 8,
      "name": "*Rock_Aqua_Cobble_Roof_State_Definitions_Corner_Left",
      "rotation": 3
    },
    {
      "x": -7,
      "y": 0,
      "z": 9,
      "name": "Rock_Aqua_Brick_Ornate",
      "rotation": 2
    },
    {
      "x": -7,
      "y": 1,
      "z": 9,
      "name": "Rock_Aqua_Brick_Decorative",
      "rotation": 2
    },
    {
      "x": -7,
      "y": 2,
      "z": 9,
      "name": "Rock_Aqua_Brick_Wall",
      "rotation": 2
    },
    {
      "x": -7,
      "y": 6,
      "z": 9,
      "name": "Rock_Aqua_Brick_Smooth_Half",
      "rotation": 4
    },
    {
      "x": -7,
      "y": 7,
      "z": 9,
      "name": "Rock_Aqua_Brick_Smooth_Half",
      "rotation": 4
    },
    {
      "x": -7,
      "y": 10,
      "z": 9,
      "name": "Rock_Aqua_Brick_Half",
      "rotation": 4
    },
    {
      "x": -7,
      "y": 13,
      "z": 9,
      "name": "Rock_Aqua_Cobble_Roof_Hollow"
    },
    {
      "x": -7,
      "y": 16,
      "z": 9,
      "name": "Rock_Aqua_Cobble_Roof_Hollow"
    },
    {
      "x": -7,
      "y": 15,
      "z": 10,
      "name": "*Rock_Aqua_Cobble_Roof_Hollow_State_Definitions_Inverted_Corner_Right"
    },
    {
      "x": -6,
      "y": 0,
      "z": -10,
      "name": "Rock_Aqua_Brick_Ornate",
      "rotation": 1
    },
    {
      "x": -6,
      "y": 1,
      "z": -10,
      "name": "Rock_Aqua_Brick_Decorative",
      "rotation": 1
    },
    {
      "x": -6,
      "y": 2,
      "z": -10,
      "name": "*Rock_Aqua_Brick_Wall_State_Definitions_Corner",
      "rotation": 1
    },
    {
      "x": -6,
      "y": 3,
      "z": -10,
      "name": "Rock_Aqua_Brick_Beam",
      "rotation": 1
    },
    {
      "x": -6,
      "y": 4,
      "z": -10,
      "name": "Rock_Aqua_Brick_Beam",
      "rotation": 1
    },
    {
      "x": -6,
      "y": 5,
      "z": -10,
      "name": "*Rock_Aqua_Cobble_Roof_State_Definitions_Corner_Left",
      "rotation": 2
    },
    {
      "x": -6,
      "y": 16,
      "z": -10,
      "name": "*Rock_Aqua_Cobble_Roof_Hollow_State_Definitions_Corner_Right",
      "rotation": 3
    },
    {
      "x": -6,
      "y": 0,
      "z": -9,
      "name": "Rock_Aqua_Brick_Smooth",
      "rotation": 1
    },
    {
      "x": -6,
      "y": 1,
      "z": -9,
      "name": "Rock_Aqua_Brick_Decorative",
      "rotation": 1
    },
    {
      "x": -6,
      "y": 2,
      "z": -9,
      "name": "*Rock_Aqua_Brick_Wall_State_Definitions_Corner",
      "rotation": 3
    },
    {
      "x": -6,
      "y": 3,
      "z": -9,
      "name": "Furniture_Temple_Dark_Stool",
      "rotation": 2
    },
    {
      "x": -6,
      "y": 5,
      "z": -9,
      "name": "Rock_Aqua_Cobble_Roof_Hollow",
      "rotation": 3
    },
    {
      "x": -6,
      "y": 6,
      "z": -9,
      "name": "Rock_Aqua_Brick_Smooth_Half",
      "rotation": 6
    },
    {
      "x": -6,
      "y": 7,
      "z": -9,
      "name": "Rock_Aqua_Brick_Smooth_Half",
      "rotation": 6
    },
    {
      "x": -6,
      "y": 10,
      "z": -9,
      "name": "Rock_Aqua_Brick_Half",
      "rotation": 6
    },
    {
      "x": -6,
      "y": 13,
      "z": -9,
      "name": "Rock_Aqua_Cobble_Roof_Hollow",
      "rotation": 2
    },
    {
      "x": -6,
      "y": 16,
      "z": -9,
      "name": "*Rock_Aqua_Cobble_Roof_Hollow_State_Definitions_Inverted_Corner_Left",
      "rotation": 2
    },
    {
      "x": -6,
      "y": 0,
      "z": -8,
      "name": "Rock_Aqua_Brick_Smooth",
      "rotation": 1
    },
    {
      "x": -6,
      "y": 1,
      "z": -8,
      "name": "Rock_Aqua_Brick_Smooth",
      "rotation": 1
    },
    {
      "x": -6,
      "y": 2,
      "z": -8,
      "name": "Rock_Aqua_Brick_Smooth",
      "rotation": 1
    },
    {
      "x": -6,
      "y": 3,
      "z": -8,
      "name": "Rock_Aqua_Brick_Smooth",
      "rotation": 1
    },
    {
      "x": -6,
      "y": 4,
      "z": -8,
      "name": "Rock_Aqua_Brick_Smooth",
      "rotation": 1
    },
    {
      "x": -6,
      "y": 5,
      "z": -8,
      "name": "Rock_Aqua_Brick_Smooth",
      "rotation": 1
    },
    {
      "x": -6,
      "y": 6,
      "z": -8,
      "name": "Rock_Aqua_Brick_Smooth",
      "rotation": 1
    },
    {
      "x": -6,
      "y": 7,
      "z": -8,
      "name": "Rock_Aqua_Brick_Smooth",
      "rotation": 1
    },
    {
      "x": -6,
      "y": 8,
      "z": -8,
      "name": "Rock_Aqua_Brick_Smooth",
      "rotation": 1
    },
    {
      "x": -6,
      "y": 9,
      "z": -8,
      "name": "Rock_Aqua_Brick_Smooth",
      "rotation": 1
    },
    {
      "x": -6,
      "y": 10,
      "z": -8,
      "name": "Rock_Aqua_Brick_Smooth",
      "rotation": 1
    },
    {
      "x": -6,
      "y": 11,
      "z": -8,
      "name": "Rock_Aqua_Brick_Half",
      "rotation": 7
    },
    {
      "x": -6,
      "y": 12,
      "z": -8,
      "name": "Rock_Aqua_Brick_Half",
      "rotation": 7
    },
    {
      "x": -6,
      "y": 13,
      "z": -8,
      "name": "Rock_Aqua_Brick_Smooth",
      "rotation": 1
    },
    {
      "x": -6,
      "y": 14,
      "z": -8,
      "name": "Rock_Aqua_Brick_Smooth",
      "rotation": 1
    },
    {
      "x": -6,
      "y": 15,
      "z": -8,
      "name": "Rock_Aqua_Brick_Smooth",
      "rotation": 1
    },
    {
      "x": -6,
      "y": 16,
      "z": -8,
      "name": "Rock_Aqua_Brick_Smooth",
      "rotation": 3
    },
    {
      "x": -6,
      "y": 17,
      "z": -8,
      "name": "Rock_Aqua_Cobble_Roof",
      "rotation": 2
    },
    {
      "x": -6,
      "y": 0,
      "z": -7,
      "name": "Rock_Aqua_Brick",
      "rotation": 1
    },
    {
      "x": -6,
      "y": 7,
      "z": -7,
      "name": "Rock_Aqua_Brick_Half",
      "rotation": 8
    },
    {
      "x": -6,
      "y": 8,
      "z": -7,
      "name": "Rock_Aqua_Brick",
      "rotation": 1
    },
    {
      "x": -6,
      "y": 9,
      "z": -7,
      "name": "Rock_Aqua_Brick",
      "rotation": 1
    },
    {
      "x": -6,
      "y": 13,
      "z": -7,
      "name": "Rock_Aqua_Brick_Stairs",
      "rotation": 10
    },
    {
      "x": -6,
      "y": 14,
      "z": -7,
      "name": "Rock_Aqua_Brick_Stairs"
    },
    {
      "x": -6,
      "y": 18,
      "z": -7,
      "name": "*Rock_Aqua_Cobble_Roof_Hollow_State_Definitions_Corner_Left",
      "rotation": 2
    },
    {
      "x": -6,
      "y": 0,
      "z": -6,
      "name": "Rock_Aqua_Brick",
      "rotation": 1
    },
    {
      "x": -6,
      "y": 8,
      "z": -6,
      "name": "Rock_Aqua_Brick",
      "rotation": 1
    },
    {
      "x": -6,
      "y": 9,
      "z": -6,
      "name": "Rock_Aqua_Brick",
      "rotation": 1
    },
    {
      "x": -6,
      "y": 18,
      "z": -6,
      "name": "*Rock_Aqua_Cobble_Roof_Hollow_State_Definitions_Inverted_Corner_Right",
      "rotation": 3
    },
    {
      "x": -6,
      "y": 0,
      "z": -5,
      "name": "Rock_Aqua_Brick",
      "rotation": 1
    },
    {
      "x": -6,
      "y": 8,
      "z": -5,
      "name": "Rock_Aqua_Brick",
      "rotation": 1
    },
    {
      "x": -6,
      "y": 9,
      "z": -5,
      "name": "Rock_Aqua_Brick",
      "rotation": 1
    },
    {
      "x": -6,
      "y": 18,
      "z": -5,
      "name": "Rock_Aqua_Cobble_Half",
      "rotation": 8
    },
    {
      "x": -6,
      "y": 19,
      "z": -5,
      "name": "*Rock_Aqua_Cobble_Roof_State_Definitions_Corner_Left",
      "rotation": 2
    },
    {
      "x": -6,
      "y": 0,
      "z": -4,
      "name": "Rock_Aqua_Brick",
      "rotation": 1
    },
    {
      "x": -6,
      "y": 8,
      "z": -4,
      "name": "Rock_Aqua_Brick",
      "rotation": 1
    },
    {
      "x": -6,
      "y": 9,
      "z": -4,
      "name": "Rock_Aqua_Brick",
      "rotation": 1
    },
    {
      "x": -6,
      "y": 18,
      "z": -4,
      "name": "Rock_Aqua_Cobble_Half",
      "rotation": 8
    },
    {
      "x": -6,
      "y": 19,
      "z": -4,
      "name": "Rock_Aqua_Cobble_Roof",
      "rotation": 3
    },
    {
      "x": -6,
      "y": 0,
      "z": -3,
      "name": "Rock_Aqua_Brick",
      "rotation": 1
    },
    {
      "x": -6,
      "y": 8,
      "z": -3,
      "name": "Rock_Aqua_Brick",
      "rotation": 1
    },
    {
      "x": -6,
      "y": 9,
      "z": -3,
      "name": "Rock_Aqua_Brick",
      "rotation": 1
    },
    {
      "x": -6,
      "y": 19,
      "z": -3,
      "name": "Rock_Aqua_Cobble_Roof_Shallow",
      "filler": 1,
      "rotation": 3
    },
    {
      "x": -6,
      "y": 0,
      "z": -2,
      "name": "Rock_Aqua_Brick",
      "rotation": 1
    },
    {
      "x": -6,
      "y": 8,
      "z": -2,
      "name": "Rock_Aqua_Brick",
      "rotation": 1
    },
    {
      "x": -6,
      "y": 9,
      "z": -2,
      "name": "Rock_Aqua_Brick",
      "rotation": 1
    },
    {
      "x": -6,
      "y": 19,
      "z": -2,
      "name": "Rock_Aqua_Cobble_Roof_Shallow",
      "filler": 1,
      "rotation": 3
    },
    {
      "x": -6,
      "y": 0,
      "z": -1,
      "name": "Rock_Aqua_Brick"
    },
    {
      "x": -6,
      "y": 8,
      "z": -1,
      "name": "Rock_Aqua_Brick"
    },
    {
      "x": -6,
      "y": 9,
      "z": -1,
      "name": "Rock_Aqua_Brick"
    },
    {
      "x": -6,
      "y": 19,
      "z": -1,
      "name": "Rock_Aqua_Cobble_Roof_Shallow",
      "filler": 1,
      "rotation": 3
    },
    {
      "x": -6,
      "y": 0,
      "z": 0,
      "name": "Rock_Aqua_Brick"
    },
    {
      "x": -6,
      "y": 8,
      "z": 0,
      "name": "Rock_Aqua_Brick"
    },
    {
      "x": -6,
      "y": 9,
      "z": 0,
      "name": "Rock_Aqua_Brick_Pillar_Base",
      "rotation": 8
    },
    {
      "x": -6,
      "y": 10,
      "z": 0,
      "name": "Plant_Moss_Short_Blue",
      "support": 15
    },
    {
      "x": -6,
      "y": 19,
      "z": 0,
      "name": "Rock_Aqua_Cobble_Roof_Shallow",
      "filler": 1,
      "rotation": 3
    },
    {
      "x": -6,
      "y": 0,
      "z": 1,
      "name": "Rock_Aqua_Brick"
    },
    {
      "x": -6,
      "y": 8,
      "z": 1,
      "name": "Rock_Aqua_Brick"
    },
    {
      "x": -6,
      "y": 9,
      "z": 1,
      "name": "Rock_Aqua_Brick"
    },
    {
      "x": -6,
      "y": 18,
      "z": 1,
      "name": "Plant_Moss_Cave_Blue",
      "support": 15,
      "rotation": 8
    },
    {
      "x": -6,
      "y": 19,
      "z": 1,
      "name": "Rock_Aqua_Cobble_Roof_Shallow",
      "filler": 1,
      "rotation": 3
    },
    {
      "x": -6,
      "y": 0,
      "z": 2,
      "name": "Rock_Aqua_Brick",
      "rotation": 2
    },
    {
      "x": -6,
      "y": 8,
      "z": 2,
      "name": "Rock_Aqua_Brick",
      "rotation": 2
    },
    {
      "x": -6,
      "y": 9,
      "z": 2,
      "name": "Rock_Aqua_Brick",
      "rotation": 2
    },
    {
      "x": -6,
      "y": 19,
      "z": 2,
      "name": "Rock_Aqua_Cobble_Roof_Shallow",
      "filler": 1,
      "rotation": 3
    },
    {
      "x": -6,
      "y": 0,
      "z": 3,
      "name": "Rock_Aqua_Brick",
      "rotation": 2
    },
    {
      "x": -6,
      "y": 8,
      "z": 3,
      "name": "Rock_Aqua_Brick",
      "rotation": 2
    },
    {
      "x": -6,
      "y": 9,
      "z": 3,
      "name": "Rock_Aqua_Brick",
      "rotation": 2
    },
    {
      "x": -6,
      "y": 10,
      "z": 3,
      "name": "Plant_Moss_Rug_Blue",
      "support": 15
    },
    {
      "x": -6,
      "y": 18,
      "z": 3,
      "name": "Plant_Moss_Cave_Blue",
      "support": 15,
      "rotation": 8
    },
    {
      "x": -6,
      "y": 19,
      "z": 3,
      "name": "Rock_Aqua_Cobble_Roof_Shallow",
      "filler": 1,
      "rotation": 3
    },
    {
      "x": -6,
      "y": 0,
      "z": 4,
      "name": "Rock_Aqua_Brick",
      "rotation": 2
    },
    {
      "x": -6,
      "y": 1,
      "z": 4,
      "name": "Plant_Seaweed_Grass",
      "support": 15
    },
    {
      "x": -6,
      "y": 8,
      "z": 4,
      "name": "Rock_Aqua_Brick",
      "rotation": 2
    },
    {
      "x": -6,
      "y": 9,
      "z": 4,
      "name": "Rock_Aqua_Brick",
      "rotation": 2
    },
    {
      "x": -6,
      "y": 10,
      "z": 4,
      "name": "Plant_Moss_Blue",
      "support": 15
    },
    {
      "x": -6,
      "y": 18,
      "z": 4,
      "name": "Rock_Aqua_Cobble_Half",
      "rotation": 8
    },
    {
      "x": -6,
      "y": 19,
      "z": 4,
      "name": "Rock_Aqua_Cobble_Roof",
      "rotation": 3
    },
    {
      "x": -6,
      "y": 0,
      "z": 5,
      "name": "Rock_Aqua_Brick",
      "rotation": 2
    },
    {
      "x": -6,
      "y": 8,
      "z": 5,
      "name": "Rock_Aqua_Brick",
      "rotation": 2
    },
    {
      "x": -6,
      "y": 9,
      "z": 5,
      "name": "Rock_Aqua_Brick",
      "rotation": 2
    },
    {
      "x": -6,
      "y": 10,
      "z": 5,
      "name": "Rubble_Aqua",
      "support": 15
    },
    {
      "x": -6,
      "y": 18,
      "z": 5,
      "name": "Rock_Aqua_Cobble_Half",
      "rotation": 8
    },
    {
      "x": -6,
      "y": 19,
      "z": 5,
      "name": "*Rock_Aqua_Cobble_Roof_State_Definitions_Corner_Left",
      "rotation": 3
    },
    {
      "x": -6,
      "y": 0,
      "z": 6,
      "name": "Rock_Aqua_Brick",
      "rotation": 2
    },
    {
      "x": -6,
      "y": 8,
      "z": 6,
      "name": "Rock_Aqua_Brick",
      "rotation": 2
    },
    {
      "x": -6,
      "y": 9,
      "z": 6,
      "name": "Rock_Aqua_Brick",
      "rotation": 2
    },
    {
      "x": -6,
      "y": 10,
      "z": 6,
      "name": "Plant_Moss_Blue",
      "support": 15
    },
    {
      "x": -6,
      "y": 18,
      "z": 6,
      "name": "*Rock_Aqua_Cobble_Roof_Hollow_State_Definitions_Inverted_Corner_Right"
    },
    {
      "x": -6,
      "y": 0,
      "z": 7,
      "name": "Rock_Aqua_Brick",
      "rotation": 2
    },
    {
      "x": -6,
      "y": 7,
      "z": 7,
      "name": "Rock_Aqua_Brick_Half",
      "rotation": 8
    },
    {
      "x": -6,
      "y": 8,
      "z": 7,
      "name": "Rock_Aqua_Brick",
      "rotation": 2
    },
    {
      "x": -6,
      "y": 9,
      "z": 7,
      "name": "Rock_Aqua_Brick",
      "rotation": 2
    },
    {
      "x": -6,
      "y": 10,
      "z": 7,
      "name": "Plant_Moss_Rug_Blue",
      "support": 15
    },
    {
      "x": -6,
      "y": 13,
      "z": 7,
      "name": "Rock_Aqua_Brick_Stairs",
      "rotation": 8
    },
    {
      "x": -6,
      "y": 14,
      "z": 7,
      "name": "Rock_Aqua_Brick_Stairs",
      "rotation": 2
    },
    {
      "x": -6,
      "y": 18,
      "z": 7,
      "name": "*Rock_Aqua_Cobble_Roof_Hollow_State_Definitions_Corner_Left",
      "rotation": 3
    },
    {
      "x": -6,
      "y": 0,
      "z": 8,
      "name": "Rock_Aqua_Brick_Smooth",
      "rotation": 2
    },
    {
      "x": -6,
      "y": 1,
      "z": 8,
      "name": "Rock_Aqua_Brick_Smooth",
      "rotation": 2
    },
    {
      "x": -6,
      "y": 2,
      "z": 8,
      "name": "Rock_Aqua_Brick_Smooth",
      "rotation": 2
    },
    {
      "x": -6,
      "y": 3,
      "z": 8,
      "name": "Rock_Aqua_Brick_Smooth",
      "rotation": 2
    },
    {
      "x": -6,
      "y": 4,
      "z": 8,
      "name": "Rock_Aqua_Brick_Smooth",
      "rotation": 2
    },
    {
      "x": -6,
      "y": 5,
      "z": 8,
      "name": "Rock_Aqua_Brick_Smooth",
      "rotation": 2
    },
    {
      "x": -6,
      "y": 6,
      "z": 8,
      "name": "Rock_Aqua_Brick_Smooth",
      "rotation": 2
    },
    {
      "x": -6,
      "y": 7,
      "z": 8,
      "name": "Rock_Aqua_Brick_Smooth",
      "rotation": 2
    },
    {
      "x": -6,
      "y": 8,
      "z": 8,
      "name": "Rock_Aqua_Brick_Smooth",
      "rotation": 2
    },
    {
      "x": -6,
      "y": 9,
      "z": 8,
      "name": "Rock_Aqua_Brick_Smooth",
      "rotation": 2
    },
    {
      "x": -6,
      "y": 10,
      "z": 8,
      "name": "Rock_Aqua_Brick_Smooth",
      "rotation": 2
    },
    {
      "x": -6,
      "y": 11,
      "z": 8,
      "name": "Rock_Aqua_Brick_Half",
      "rotation": 7
    },
    {
      "x": -6,
      "y": 12,
      "z": 8,
      "name": "Rock_Aqua_Brick_Half",
      "rotation": 7
    },
    {
      "x": -6,
      "y": 13,
      "z": 8,
      "name": "Rock_Aqua_Brick_Smooth",
      "rotation": 2
    },
    {
      "x": -6,
      "y": 14,
      "z": 8,
      "name": "Rock_Aqua_Brick_Smooth",
      "rotation": 2
    },
    {
      "x": -6,
      "y": 15,
      "z": 8,
      "name": "Rock_Aqua_Brick_Smooth",
      "rotation": 2
    },
    {
      "x": -6,
      "y": 16,
      "z": 8,
      "name": "Rock_Aqua_Brick_Smooth"
    },
    {
      "x": -6,
      "y": 17,
      "z": 8,
      "name": "Rock_Aqua_Cobble_Roof"
    },
    {
      "x": -6,
      "y": 0,
      "z": 9,
      "name": "Rock_Aqua_Brick_Smooth",
      "rotation": 2
    },
    {
      "x": -6,
      "y": 1,
      "z": 9,
      "name": "Rock_Aqua_Brick_Decorative",
      "rotation": 2
    },
    {
      "x": -6,
      "y": 2,
      "z": 9,
      "name": "*Rock_Aqua_Brick_Wall_State_Definitions_Corner"
    },
    {
      "x": -6,
      "y": 3,
      "z": 9,
      "name": "Furniture_Temple_Dark_Stool"
    },
    {
      "x": -6,
      "y": 5,
      "z": 9,
      "name": "Rock_Aqua_Cobble_Roof_Hollow",
      "rotation": 3
    },
    {
      "x": -6,
      "y": 6,
      "z": 9,
      "name": "Rock_Aqua_Brick_Smooth_Half",
      "rotation": 4
    },
    {
      "x": -6,
      "y": 7,
      "z": 9,
      "name": "Rock_Aqua_Brick_Smooth_Half",
      "rotation": 4
    },
    {
      "x": -6,
      "y": 10,
      "z": 9,
      "name": "Rock_Aqua_Brick_Half",
      "rotation": 4
    },
    {
      "x": -6,
      "y": 13,
      "z": 9,
      "name": "Rock_Aqua_Cobble_Roof_Hollow"
    },
    {
      "x": -6,
      "y": 16,
      "z": 9,
      "name": "*Rock_Aqua_Cobble_Roof_Hollow_State_Definitions_Inverted_Corner_Left",
      "rotation": 3
    },
    {
      "x": -6,
      "y": 0,
      "z": 10,
      "name": "Rock_Aqua_Brick_Ornate",
      "rotation": 2
    },
    {
      "x": -6,
      "y": 1,
      "z": 10,
      "name": "Rock_Aqua_Brick_Decorative",
      "rotation": 2
    },
    {
      "x": -6,
      "y": 2,
      "z": 10,
      "name": "*Rock_Aqua_Brick_Wall_State_Definitions_Corner",
      "rotation": 2
    },
    {
      "x": -6,
      "y": 3,
      "z": 10,
      "name": "Rock_Aqua_Brick_Beam",
      "rotation": 2
    },
    {
      "x": -6,
      "y": 4,
      "z": 10,
      "name": "Rock_Aqua_Brick_Beam",
      "rotation": 2
    },
    {
      "x": -6,
      "y": 5,
      "z": 10,
      "name": "*Rock_Aqua_Cobble_Roof_State_Definitions_Corner_Left",
      "rotation": 3
    },
    {
      "x": -6,
      "y": 16,
      "z": 10,
      "name": "*Rock_Aqua_Cobble_Roof_Hollow_State_Definitions_Corner_Left",
      "rotation": 3
    },
    {
      "x": -5,
      "y": 0,
      "z": -10,
      "name": "Rock_Aqua_Brick_Smooth",
      "rotation": 1
    },
    {
      "x": -5,
      "y": 1,
      "z": -10,
      "name": "Rock_Aqua_Brick_Decorative",
      "rotation": 1
    },
    {
      "x": -5,
      "y": 2,
      "z": -10,
      "name": "Rock_Aqua_Brick_Wall",
      "rotation": 2
    },
    {
      "x": -5,
      "y": 5,
      "z": -10,
      "name": "Rock_Aqua_Cobble_Roof_Hollow",
      "rotation": 2
    },
    {
      "x": -5,
      "y": 16,
      "z": -10,
      "name": "Rock_Aqua_Cobble_Roof_Hollow",
      "rotation": 2
    },
    {
      "x": -5,
      "y": 0,
      "z": -9,
      "name": "Rock_Aqua_Brick_Smooth",
      "rotation": 1
    },
    {
      "x": -5,
      "y": 1,
      "z": -9,
      "name": "Rock_Aqua_Brick_Smooth",
      "rotation": 1
    },
    {
      "x": -5,
      "y": 2,
      "z": -9,
      "name": "Rock_Aqua_Brick_Smooth",
      "rotation": 1
    },
    {
      "x": -5,
      "y": 3,
      "z": -9,
      "name": "Rock_Aqua_Brick_Smooth",
      "rotation": 1
    },
    {
      "x": -5,
      "y": 4,
      "z": -9,
      "name": "Rock_Aqua_Brick_Smooth",
      "rotation": 1
    },
    {
      "x": -5,
      "y": 5,
      "z": -9,
      "name": "Rock_Aqua_Brick_Smooth",
      "rotation": 1
    },
    {
      "x": -5,
      "y": 6,
      "z": -9,
      "name": "Rock_Aqua_Brick_Smooth",
      "rotation": 1
    },
    {
      "x": -5,
      "y": 7,
      "z": -9,
      "name": "Rock_Aqua_Brick_Smooth",
      "rotation": 1
    },
    {
      "x": -5,
      "y": 8,
      "z": -9,
      "name": "Rock_Aqua_Brick_Smooth",
      "rotation": 1
    },
    {
      "x": -5,
      "y": 9,
      "z": -9,
      "name": "Rock_Aqua_Brick_Smooth",
      "rotation": 1
    },
    {
      "x": -5,
      "y": 10,
      "z": -9,
      "name": "Rock_Aqua_Brick_Smooth",
      "rotation": 1
    },
    {
      "x": -5,
      "y": 11,
      "z": -9,
      "name": "Rock_Aqua_Brick_Smooth",
      "rotation": 1
    },
    {
      "x": -5,
      "y": 12,
      "z": -9,
      "name": "Rock_Aqua_Brick_Smooth",
