{
  "version": 8,
  "blockIdVersion": 11,
  "anchorX": 0,
  "anchorY": 1,
  "anchorZ": 0,
  "blocks": [
    {
      "x": -10,
      "y": 0,
      "z": -2,
      "name": "Rock_Aqua_Brick_Smooth"
    },
    {
      "x": -10,
      "y": 1,
      "z": -2,
      "name": "Rock_Aqua_Brick_Smooth"
    },
    {
      "x": -10,
      "y": 2,
      "z": -2,
      "name": "Rock_Aqua_Brick_Smooth"
    },
    {
      "x": -10,
      "y": 3,
      "z": -2,
      "name": "Rock_Aqua_Brick_Smooth"
    },
    {
      "x": -10,
      "y": 4,
      "z": -2,
      "name": "Rock_Aqua_Brick_Smooth"
    },
    {
      "x": -10,
      "y": 5,
      "z": -2,
      "name": "Rock_Aqua_Brick_Smooth"
    },
    {
      "x": -10,
      "y": 6,
      "z": -2,
      "name": "Rock_Aqua_Brick_Smooth"
    },
    {
      "x": -10,
      "y": 7,
      "z": -2,
      "name": "Rock_Aqua_Brick_Smooth"
    },
    {
      "x": -10,
      "y": 8,
      "z": -2,
      "name": "Rock_Aqua_Brick_Smooth"
    },
    {
      "x": -10,
      "y": 9,
      "z": -2,
      "name": "Rock_Aqua_Brick_Smooth"
    },
    {
      "x": -10,
      "y": 10,
      "z": -2,
      "name": "Rock_Aqua_Brick_Smooth"
    },
    {
      "x": -10,
      "y": 11,
      "z": -2,
      "name": "Rock_Aqua_Brick_Smooth"
    },
    {
      "x": -10,
      "y": 12,
      "z": -2,
      "name": "Rock_Aqua_Brick_Smooth"
    },
    {
      "x": -10,
      "y": 13,
      "z": -2,
      "name": "Rock_Aqua_Brick_Smooth"
    },
    {
      "x": -10,
      "y": 14,
      "z": -2,
      "name": "Rock_Aqua_Brick_Smooth"
    },
    {
      "x": -10,
      "y": 15,
      "z": -2,
      "name": "Rock_Aqua_Brick_Smooth"
    },
    {
      "x": -10,
      "y": 16,
      "z": -2,
      "name": "Rock_Aqua_Brick_Smooth"
    },
    {
      "x": -10,
      "y": 0,
      "z": -1,
      "name": "Rock_Aqua_Brick_Smooth"
    },
    {
      "x": -10,
      "y": 3,
      "z": -1,
      "name": "Rock_Aqua_Brick_Smooth_Half",
      "rotation": 4
    },
    {
      "x": -10,
      "y": 4,
      "z": -1,
      "name": "Rock_Aqua_Brick_Smooth"
    },
    {
      "x": -10,
      "y": 5,
      "z": -1,
      "name": "Rock_Aqua_Brick_Smooth"
    },
    {
      "x": -10,
      "y": 6,
      "z": -1,
      "name": "Rock_Aqua_Brick_Smooth"
    },
    {
      "x": -10,
      "y": 7,
      "z": -1,
      "name": "Rock_Aqua_Brick_Smooth"
    },
    {
      "x": -10,
      "y": 8,
      "z": -1,
      "name": "Rock_Aqua_Brick_Smooth"
    },
    {
      "x": -10,
      "y": 9,
      "z": -1,
      "name": "Rock_Aqua_Brick_Smooth"
    },
    {
      "x": -10,
      "y": 12,
      "z": -1,
      "name": "Rock_Aqua_Brick_Smooth_Half",
      "rotation": 4
    },
    {
      "x": -10,
      "y": 13,
      "z": -1,
      "name": "Rock_Aqua_Brick_Smooth"
    },
    {
      "x": -10,
      "y": 14,
      "z": -1,
      "name": "Rock_Aqua_Brick_Smooth"
    },
    {
      "x": -10,
      "y": 15,
      "z": -1,
      "name": "Rock_Aqua_Brick_Smooth"
    },
    {
      "x": -10,
      "y": 16,
      "z": -1,
      "name": "Rock_Aqua_Brick_Smooth"
    },
    {
      "x": -10,
      "y": 0,
      "z": 0,
      "name": "Rock_Aqua_Brick_Smooth"
    },
    {
      "x": -10,
      "y": 4,
      "z": 0,
      "name": "Rock_Aqua_Brick_Smooth_Half",
      "rotation": 8
    },
    {
      "x": -10,
      "y": 5,
      "z": 0,
      "name": "Rock_Aqua_Brick_Smooth"
    },
    {
      "x": -10,
      "y": 6,
      "z": 0,
      "name": "Rock_Aqua_Brick_Smooth"
    },
    {
      "x": -10,
      "y": 7,
      "z": 0,
      "name": "Rock_Aqua_Brick_Smooth"
    },
    {
      "x": -10,
      "y": 8,
      "z": 0,
      "name": "Rock_Aqua_Brick_Smooth"
    },
    {
      "x": -10,
      "y": 9,
      "z": 0,
      "name": "Rock_Aqua_Brick_Smooth"
    },
    {
      "x": -10,
      "y": 13,
      "z": 0,
      "name": "Rock_Aqua_Brick_Smooth_Half",
      "rotation": 8
    },
    {
      "x": -10,
      "y": 14,
      "z": 0,
      "name": "Rock_Aqua_Brick_Smooth"
    },
    {
      "x": -10,
      "y": 15,
      "z": 0,
      "name": "Rock_Aqua_Brick_Smooth"
    },
    {
      "x": -10,
      "y": 16,
      "z": 0,
      "name": "Rock_Aqua_Brick_Smooth"
    },
    {
      "x": -10,
      "y": 0,
      "z": 1,
      "name": "Rock_Aqua_Brick_Smooth"
    },
    {
      "x": -10,
      "y": 3,
      "z": 1,
      "name": "Rock_Aqua_Brick_Smooth_Half",
      "rotation": 6
    },
    {
      "x": -10,
      "y": 4,
      "z": 1,
      "name": "Rock_Aqua_Brick_Smooth"
    },
    {
      "x": -10,
      "y": 5,
      "z": 1,
      "name": "Rock_Aqua_Brick_Smooth"
    },
    {
      "x": -10,
      "y": 6,
      "z": 1,
      "name": "Rock_Aqua_Brick_Smooth"
    },
    {
      "x": -10,
      "y": 7,
      "z": 1,
      "name": "Rock_Aqua_Brick_Smooth"
    },
    {
      "x": -10,
      "y": 8,
      "z": 1,
      "name": "Rock_Aqua_Brick_Smooth"
    },
    {
      "x": -10,
      "y": 9,
      "z": 1,
      "name": "Rock_Aqua_Brick_Smooth"
    },
    {
      "x": -10,
      "y": 12,
      "z": 1,
      "name": "Rock_Aqua_Brick_Smooth_Half",
      "rotation": 6
    },
    {
      "x": -10,
      "y": 13,
      "z": 1,
      "name": "Rock_Aqua_Brick_Smooth"
    },
    {
      "x": -10,
      "y": 14,
      "z": 1,
      "name": "Rock_Aqua_Brick_Smooth"
    },
    {
      "x": -10,
      "y": 15,
      "z": 1,
      "name": "Rock_Aqua_Brick_Smooth"
    },
    {
      "x": -10,
      "y": 16,
      "z": 1,
      "name": "Rock_Aqua_Brick_Smooth"
    },
    {
      "x": -10,
      "y": 0,
      "z": 2,
      "name": "Rock_Aqua_Brick_Smooth"
    },
    {
      "x": -10,
      "y": 1,
      "z": 2,
      "name": "Rock_Aqua_Brick_Smooth"
    },
    {
      "x": -10,
      "y": 2,
      "z": 2,
      "name": "Rock_Aqua_Brick_Smooth"
    },
    {
      "x": -10,
      "y": 3,
      "z": 2,
      "name": "Rock_Aqua_Brick_Smooth"
    },
    {
      "x": -10,
      "y": 4,
      "z": 2,
      "name": "Rock_Aqua_Brick_Smooth"
    },
    {
      "x": -10,
      "y": 5,
      "z": 2,
      "name": "Rock_Aqua_Brick_Smooth"
    },
    {
      "x": -10,
      "y": 6,
      "z": 2,
      "name": "Rock_Aqua_Brick_Smooth"
    },
    {
      "x": -10,
      "y": 7,
      "z": 2,
      "name": "Rock_Aqua_Brick_Smooth"
    },
    {
      "x": -10,
      "y": 8,
      "z": 2,
      "name": "Rock_Aqua_Brick_Smooth"
    },
    {
      "x": -10,
      "y": 9,
      "z": 2,
      "name": "Rock_Aqua_Brick_Smooth"
    },
    {
      "x": -10,
      "y": 10,
      "z": 2,
      "name": "Rock_Aqua_Brick_Smooth"
    },
    {
      "x": -10,
      "y": 11,
      "z": 2,
      "name": "Rock_Aqua_Brick_Smooth"
    },
    {
      "x": -10,
      "y": 12,
      "z": 2,
      "name": "Rock_Aqua_Brick_Smooth"
    },
    {
      "x": -10,
      "y": 13,
      "z": 2,
      "name": "Rock_Aqua_Brick_Smooth"
    },
    {
      "x": -10,
      "y": 14,
      "z": 2,
      "name": "Rock_Aqua_Brick_Smooth"
    },
    {
      "x": -10,
      "y": 15,
      "z": 2,
      "name": "Rock_Aqua_Brick_Smooth"
    },
    {
      "x": -10,
      "y": 16,
      "z": 2,
      "name": "Rock_Aqua_Brick_Smooth"
    },
    {
      "x": -9,
      "y": 0,
      "z": -5,
      "name": "Rock_Aqua_Brick_Smooth"
    },
    {
      "x": -9,
      "y": 1,
      "z": -5,
      "name": "Rock_Aqua_Brick_Smooth"
    },
    {
      "x": -9,
      "y": 2,
      "z": -5,
      "name": "Rock_Aqua_Brick_Smooth"
    },
    {
      "x": -9,
      "y": 3,
      "z": -5,
      "name": "Rock_Aqua_Brick_Smooth"
    },
    {
      "x": -9,
      "y": 4,
      "z": -5,
      "name": "Rock_Aqua_Brick_Smooth"
    },
    {
      "x": -9,
      "y": 5,
      "z": -5,
      "name": "Rock_Aqua_Brick_Smooth"
    },
    {
      "x": -9,
      "y": 6,
      "z": -5,
      "name": "Rock_Aqua_Brick_Smooth"
    },
    {
      "x": -9,
      "y": 7,
      "z": -5,
      "name": "Rock_Aqua_Brick_Smooth"
    },
    {
      "x": -9,
      "y": 8,
      "z": -5,
      "name": "Rock_Aqua_Brick_Smooth"
    },
    {
      "x": -9,
      "y": 9,
      "z": -5,
      "name": "Rock_Aqua_Brick_Smooth"
    },
    {
      "x": -9,
      "y": 10,
      "z": -5,
      "name": "Rock_Aqua_Brick_Smooth"
    },
    {
      "x": -9,
      "y": 11,
      "z": -5,
      "name": "Rock_Aqua_Brick_Smooth"
    },
    {
      "x": -9,
      "y": 12,
      "z": -5,
      "name": "Rock_Aqua_Brick_Smooth"
    },
    {
      "x": -9,
      "y": 13,
      "z": -5,
      "name": "Rock_Aqua_Brick_Smooth"
    },
    {
      "x": -9,
      "y": 14,
      "z": -5,
      "name": "Rock_Aqua_Brick_Smooth"
    },
    {
      "x": -9,
      "y": 15,
      "z": -5,
      "name": "Rock_Aqua_Brick_Smooth"
    },
    {
      "x": -9,
      "y": 16,
      "z": -5,
      "name": "Rock_Aqua_Brick_Smooth"
    },
    {
      "x": -9,
      "y": 0,
      "z": -4,
      "name": "Rock_Aqua_Brick_Smooth"
    },
    {
      "x": -9,
      "y": 1,
      "z": -4,
      "name": "Rock_Aqua_Brick_Smooth"
    },
    {
      "x": -9,
      "y": 2,
      "z": -4,
      "name": "Rock_Aqua_Brick_Smooth"
    },
    {
      "x": -9,
      "y": 3,
      "z": -4,
      "name": "Rock_Aqua_Brick_Smooth"
    },
    {
      "x": -9,
      "y": 4,
      "z": -4,
      "name": "Rock_Aqua_Brick_Smooth"
    },
    {
      "x": -9,
      "y": 5,
      "z": -4,
      "name": "Rock_Aqua_Brick_Smooth"
    },
    {
      "x": -9,
      "y": 6,
      "z": -4,
      "name": "Rock_Aqua_Brick_Smooth"
    },
    {
      "x": -9,
      "y": 7,
      "z": -4,
      "name": "Rock_Aqua_Brick_Smooth"
    },
    {
      "x": -9,
      "y": 8,
      "z": -4,
      "name": "Rock_Aqua_Brick_Smooth"
    },
    {
      "x": -9,
      "y": 9,
      "z": -4,
      "name": "Rock_Aqua_Brick_Smooth"
    },
    {
      "x": -9,
      "y": 10,
      "z": -4,
      "name": "Rock_Aqua_Brick_Smooth"
    },
    {
      "x": -9,
      "y": 11,
      "z": -4,
      "name": "Rock_Aqua_Brick_Smooth"
    },
    {
      "x": -9,
      "y": 12,
      "z": -4,
      "name": "Rock_Aqua_Brick_Smooth"
    },
    {
      "x": -9,
      "y": 13,
      "z": -4,
      "name": "Rock_Aqua_Brick_Smooth"
    },
    {
      "x": -9,
      "y": 14,
      "z": -4,
      "name": "Rock_Aqua_Brick_Smooth"
    },
    {
      "x": -9,
      "y": 15,
      "z": -4,
      "name": "Rock_Aqua_Brick_Smooth"
    },
    {
      "x": -9,
      "y": 16,
      "z": -4,
      "name": "Rock_Aqua_Brick_Smooth"
    },
    {
      "x": -9,
      "y": 0,
      "z": -3,
      "name": "Rock_Aqua_Brick_Smooth"
    },
    {
      "x": -9,
      "y": 1,
      "z": -3,
      "name": "Rock_Aqua_Brick_Smooth"
    },
    {
      "x": -9,
      "y": 2,
      "z": -3,
      "name": "Rock_Aqua_Brick_Smooth"
    },
    {
      "x": -9,
      "y": 3,
      "z": -3,
      "name": "Rock_Aqua_Brick_Smooth"
    },
    {
      "x": -9,
      "y": 4,
      "z": -3,
      "name": "Rock_Aqua_Brick_Smooth"
    },
    {
      "x": -9,
      "y": 5,
      "z": -3,
      "name": "Rock_Aqua_Brick_Smooth"
    },
    {
      "x": -9,
      "y": 6,
      "z": -3,
      "name": "Rock_Aqua_Brick_Smooth"
    },
    {
      "x": -9,
      "y": 7,
      "z": -3,
      "name": "Rock_Aqua_Brick_Smooth"
    },
    {
      "x": -9,
      "y": 8,
      "z": -3,
      "name": "Rock_Aqua_Brick_Smooth"
    },
    {
      "x": -9,
      "y": 9,
      "z": -3,
      "name": "Rock_Aqua_Brick_Smooth"
    },
    {
      "x": -9,
      "y": 10,
      "z": -3,
      "name": "Rock_Aqua_Brick_Smooth"
    },
    {
      "x": -9,
      "y": 11,
      "z": -3,
      "name": "Rock_Aqua_Brick_Smooth"
    },
    {
      "x": -9,
      "y": 12,
      "z": -3,
      "name": "Rock_Aqua_Brick_Smooth"
    },
    {
      "x": -9,
      "y": 13,
      "z": -3,
      "name": "Rock_Aqua_Brick_Smooth"
    },
    {
      "x": -9,
      "y": 14,
      "z": -3,
      "name": "Rock_Aqua_Brick_Smooth"
    },
    {
      "x": -9,
      "y": 15,
      "z": -3,
      "name": "Rock_Aqua_Brick_Smooth"
    },
    {
      "x": -9,
      "y": 16,
      "z": -3,
      "name": "Rock_Aqua_Brick_Smooth"
    },
    {
      "x": -9,
      "y": 0,
      "z": -2,
      "name": "Rock_Aqua_Brick"
    },
    {
      "x": -9,
      "y": 8,
      "z": -2,
      "name": "Rock_Aqua_Brick"
    },
    {
      "x": -9,
      "y": 9,
      "z": -2,
      "name": "Rock_Aqua_Brick"
    },
    {
      "x": -9,
      "y": 0,
      "z": -1,
      "name": "Rock_Aqua_Brick"
    },
    {
      "x": -9,
      "y": 8,
      "z": -1,
      "name": "Rock_Aqua_Brick"
    },
    {
      "x": -9,
      "y": 9,
      "z": -1,
      "name": "Rock_Aqua_Brick"
    },
    {
      "x": -9,
      "y": 0,
      "z": 0,
      "name": "Rock_Aqua_Brick"
    },
    {
      "x": -9,
      "y": 8,
      "z": 0,
      "name": "Rock_Aqua_Brick"
    },
    {
      "x": -9,
      "y": 9,
      "z": 0,
      "name": "Rock_Aqua_Brick"
    },
    {
      "x": -9,
      "y": 0,
      "z": 1,
      "name": "Rock_Aqua_Brick"
    },
    {
      "x": -9,
      "y": 8,
      "z": 1,
      "name": "Rock_Aqua_Brick"
    },
    {
      "x": -9,
      "y": 9,
      "z": 1,
      "name": "Rock_Aqua_Brick"
    },
    {
      "x": -9,
      "y": 0,
      "z": 2,
      "name": "Rock_Aqua_Brick"
    },
    {
      "x": -9,
      "y": 8,
      "z": 2,
      "name": "Rock_Aqua_Brick"
    },
    {
      "x": -9,
      "y": 9,
      "z": 2,
      "name": "Rock_Aqua_Brick"
    },
    {
      "x": -9,
      "y": 0,
      "z": 3,
      "name": "Rock_Aqua_Brick_Smooth"
    },
    {
      "x": -9,
      "y": 1,
      "z": 3,
      "name": "Rock_Aqua_Brick_Smooth"
    },
    {
      "x": -9,
      "y": 2,
      "z": 3,
      "name": "Rock_Aqua_Brick_Smooth"
    },
    {
      "x": -9,
      "y": 3,
      "z": 3,
      "name": "Rock_Aqua_Brick_Smooth"
    },
    {
      "x": -9,
      "y": 4,
      "z": 3,
      "name": "Rock_Aqua_Brick_Smooth"
    },
    {
      "x": -9,
      "y": 5,
      "z": 3,
      "name": "Rock_Aqua_Brick_Smooth"
    },
    {
      "x": -9,
      "y": 6,
      "z": 3,
      "name": "Rock_Aqua_Brick_Smooth"
    },
    {
      "x": -9,
      "y": 7,
      "z": 3,
      "name": "Rock_Aqua_Brick_Smooth"
    },
    {
      "x": -9,
      "y": 8,
      "z": 3,
      "name": "Rock_Aqua_Brick_Smooth"
    },
    {
      "x": -9,
      "y": 9,
      "z": 3,
      "name": "Rock_Aqua_Brick_Smooth"
    },
    {
      "x": -9,
      "y": 10,
      "z": 3,
      "name": "Rock_Aqua_Brick_Smooth"
    },
    {
      "x": -9,
      "y": 11,
      "z": 3,
      "name": "Rock_Aqua_Brick_Smooth"
    },
    {
      "x": -9,
      "y": 12,
      "z": 3,
      "name": "Rock_Aqua_Brick_Smooth"
    },
    {
      "x": -9,
      "y": 13,
      "z": 3,
      "name": "Rock_Aqua_Brick_Smooth"
    },
    {
      "x": -9,
      "y": 14,
      "z": 3,
      "name": "Rock_Aqua_Brick_Smooth"
    },
    {
      "x": -9,
      "y": 15,
      "z": 3,
      "name": "Rock_Aqua_Brick_Smooth"
    },
    {
      "x": -9,
      "y": 16,
      "z": 3,
      "name": "Rock_Aqua_Brick_Smooth"
    },
    {
      "x": -9,
      "y": 0,
      "z": 4,
      "name": "Rock_Aqua_Brick_Smooth"
    },
    {
      "x": -9,
      "y": 1,
      "z": 4,
      "name": "Rock_Aqua_Brick_Smooth"
    },
    {
      "x": -9,
      "y": 2,
      "z": 4,
      "name": "Rock_Aqua_Brick_Smooth"
    },
    {
      "x": -9,
      "y": 3,
      "z": 4,
      "name": "Rock_Aqua_Brick_Smooth"
    },
    {
      "x": -9,
      "y": 4,
      "z": 4,
      "name": "Rock_Aqua_Brick_Smooth"
    },
    {
      "x": -9,
      "y": 5,
      "z": 4,
      "name": "Rock_Aqua_Brick_Smooth"
    },
    {
      "x": -9,
      "y": 6,
      "z": 4,
      "name": "Rock_Aqua_Brick_Smooth"
    },
    {
      "x": -9,
      "y": 7,
      "z": 4,
      "name": "Rock_Aqua_Brick_Smooth"
    },
    {
      "x": -9,
      "y": 8,
      "z": 4,
      "name": "Rock_Aqua_Brick_Smooth"
    },
    {
      "x": -9,
      "y": 9,
      "z": 4,
      "name": "Rock_Aqua_Brick_Smooth"
    },
    {
      "x": -9,
      "y": 10,
      "z": 4,
      "name": "Rock_Aqua_Brick_Smooth"
    },
    {
      "x": -9,
      "y": 11,
      "z": 4,
      "name": "Rock_Aqua_Brick_Smooth"
    },
    {
      "x": -9,
      "y": 12,
      "z": 4,
      "name": "Rock_Aqua_Brick_Smooth"
    },
    {
      "x": -9,
      "y": 13,
      "z": 4,
      "name": "Rock_Aqua_Brick_Smooth"
    },
    {
      "x": -9,
      "y": 14,
      "z": 4,
      "name": "Rock_Aqua_Brick_Smooth"
    },
    {
      "x": -9,
      "y": 15,
      "z": 4,
      "name": "Rock_Aqua_Brick_Smooth"
    },
    {
      "x": -9,
      "y": 16,
      "z": 4,
      "name": "Rock_Aqua_Brick_Smooth"
    },
    {
      "x": -9,
      "y": 0,
      "z": 5,
      "name": "Rock_Aqua_Brick_Smooth"
    },
    {
      "x": -9,
      "y": 1,
      "z": 5,
      "name": "Rock_Aqua_Brick_Smooth"
    },
    {
      "x": -9,
      "y": 2,
      "z": 5,
      "name": "Rock_Aqua_Brick_Smooth"
    },
    {
      "x": -9,
      "y": 3,
      "z": 5,
      "name": "Rock_Aqua_Brick_Smooth"
    },
    {
      "x": -9,
      "y": 4,
      "z": 5,
      "name": "Rock_Aqua_Brick_Smooth"
    },
    {
      "x": -9,
      "y": 5,
      "z": 5,
      "name": "Rock_Aqua_Brick_Smooth"
    },
    {
      "x": -9,
      "y": 6,
      "z": 5,
      "name": "Rock_Aqua_Brick_Smooth"
    },
    {
      "x": -9,
      "y": 7,
      "z": 5,
      "name": "Rock_Aqua_Brick_Smooth"
    },
    {
      "x": -9,
      "y": 8,
      "z": 5,
      "name": "Rock_Aqua_Brick_Smooth"
    },
    {
      "x": -9,
      "y": 9,
      "z": 5,
      "name": "Rock_Aqua_Brick_Smooth"
    },
    {
      "x": -9,
      "y": 10,
      "z": 5,
      "name": "Rock_Aqua_Brick_Smooth"
    },
    {
      "x": -9,
      "y": 11,
      "z": 5,
      "name": "Rock_Aqua_Brick_Smooth"
    },
    {
      "x": -9,
      "y": 12,
      "z": 5,
      "name": "Rock_Aqua_Brick_Smooth"
    },
    {
      "x": -9,
      "y": 13,
      "z": 5,
      "name": "Rock_Aqua_Brick_Smooth"
    },
    {
      "x": -9,
      "y": 14,
      "z": 5,
      "name": "Rock_Aqua_Brick_Smooth"
    },
    {
      "x": -9,
      "y": 15,
      "z": 5,
      "name": "Rock_Aqua_Brick_Smooth"
    },
    {
      "x": -9,
      "y": 16,
      "z": 5,
      "name": "Rock_Aqua_Brick_Smooth"
    },
    {
      "x": -8,
      "y": 0,
      "z": -7,
      "name": "Rock_Aqua_Brick_Smooth"
    },
    {
      "x": -8,
      "y": 1,
      "z": -7,
      "name": "Rock_Aqua_Brick_Smooth"
    },
    {
      "x": -8,
      "y": 2,
      "z": -7,
      "name": "Rock_Aqua_Brick_Smooth"
    },
    {
      "x": -8,
      "y": 3,
      "z": -7,
      "name": "Rock_Aqua_Brick_Smooth"
    },
    {
      "x": -8,
      "y": 4,
      "z": -7,
      "name": "Rock_Aqua_Brick_Smooth"
    },
    {
      "x": -8,
      "y": 5,
      "z": -7,
      "name": "Rock_Aqua_Brick_Smooth"
    },
    {
      "x": -8,
      "y": 6,
      "z": -7,
      "name": "Rock_Aqua_Brick_Smooth"
    },
    {
      "x": -8,
      "y": 7,
      "z": -7,
      "name": "Rock_Aqua_Brick_Smooth"
    },
    {
      "x": -8,
      "y": 8,
      "z": -7,
      "name": "Rock_Aqua_Brick_Smooth"
    },
    {
      "x": -8,
      "y": 9,
      "z": -7,
      "name": "Rock_Aqua_Brick_Smooth"
    },
    {
      "x": -8,
      "y": 10,
      "z": -7,
      "name": "Rock_Aqua_Brick_Smooth"
    },
    {
      "x": -8,
      "y": 11,
      "z": -7,
      "name": "Rock_Aqua_Brick_Smooth"
    },
    {
      "x": -8,
      "y": 12,
      "z": -7,
      "name": "Rock_Aqua_Brick_Smooth"
    },
    {
      "x": -8,
      "y": 13,
      "z": -7,
      "name": "Rock_Aqua_Brick_Smooth"
    },
    {
      "x": -8,
      "y": 14,
      "z": -7,
      "name": "Rock_Aqua_Brick_Smooth"
    },
    {
      "x": -8,
      "y": 15,
      "z": -7,
      "name": "Rock_Aqua_Brick_Smooth"
    },
    {
      "x": -8,
      "y": 16,
      "z": -7,
      "name": "Rock_Aqua_Brick_Smooth"
    },
    {
      "x": -8,
      "y": 0,
      "z": -6,
      "name": "Rock_Aqua_Brick_Smooth"
    },
    {
      "x": -8,
      "y": 1,
      "z": -6,
      "name": "Rock_Aqua_Brick_Smooth"
    },
    {
      "x": -8,
      "y": 2,
      "z": -6,
      "name": "Rock_Aqua_Brick_Smooth"
    },
    {
      "x": -8,
      "y": 3,
      "z": -6,
      "name": "Rock_Aqua_Brick_Smooth"
    },
    {
      "x": -8,
      "y": 4,
      "z": -6,
      "name": "Rock_Aqua_Brick_Smooth"
    },
    {
      "x": -8,
      "y": 5,
      "z": -6,
      "name": "Rock_Aqua_Brick_Smooth"
    },
    {
      "x": -8,
      "y": 6,
      "z": -6,
      "name": "Rock_Aqua_Brick_Smooth"
    },
    {
      "x": -8,
      "y": 7,
      "z": -6,
      "name": "Rock_Aqua_Brick_Smooth"
    },
    {
      "x": -8,
      "y": 8,
      "z": -6,
      "name": "Rock_Aqua_Brick_Smooth"
    },
    {
      "x": -8,
      "y": 9,
      "z": -6,
      "name": "Rock_Aqua_Brick_Smooth"
    },
    {
      "x": -8,
      "y": 10,
      "z": -6,
      "name": "Rock_Aqua_Brick_Smooth"
    },
    {
      "x": -8,
      "y": 11,
      "z": -6,
      "name": "Rock_Aqua_Brick_Smooth"
    },
    {
      "x": -8,
      "y": 12,
      "z": -6,
      "name": "Rock_Aqua_Brick_Smooth"
    },
    {
      "x": -8,
      "y": 13,
      "z": -6,
      "name": "Rock_Aqua_Brick_Smooth"
    },
    {
      "x": -8,
      "y": 14,
      "z": -6,
      "name": "Rock_Aqua_Brick_Smooth"
    },
    {
      "x": -8,
      "y": 15,
      "z": -6,
      "name": "Rock_Aqua_Brick_Smooth"
    },
    {
      "x": -8,
      "y": 16,
      "z": -6,
      "name": "Rock_Aqua_Brick_Smooth"
    },
    {
      "x": -8,
      "y": 0,
      "z": -5,
      "name": "Rock_Aqua_Brick"
    },
    {
      "x": -8,
      "y": 8,
      "z": -5,
      "name": "Rock_Aqua_Brick"
    },
    {
      "x": -8,
      "y": 9,
      "z": -5,
      "name": "Rock_Aqua_Brick"
    },
    {
      "x": -8,
      "y": 0,
      "z": -4,
      "name": "Rock_Aqua_Brick"
    },
    {
      "x": -8,
      "y": 8,
      "z": -4,
      "name": "Rock_Aqua_Brick"
    },
    {
      "x": -8,
      "y": 9,
      "z": -4,
      "name": "Rock_Aqua_Brick"
    },
    {
      "x": -8,
      "y": 0,
      "z": -3,
      "name": "Rock_Aqua_Brick"
    },
    {
      "x": -8,
      "y": 8,
      "z": -3,
      "name": "Rock_Aqua_Brick"
    },
    {
      "x": -8,
      "y": 9,
      "z": -3,
      "name": "Rock_Aqua_Brick"
    },
    {
      "x": -8,
      "y": 0,
      "z": -2,
      "name": "Rock_Aqua_Brick"
    },
    {
      "x": -8,
      "y": 8,
      "z": -2,
      "name": "Rock_Aqua_Brick"
    },
    {
      "x": -8,
      "y": 9,
      "z": -2,
      "name": "Rock_Aqua_Brick"
    },
    {
      "x": -8,
      "y": 0,
      "z": -1,
      "name": "Rock_Aqua_Brick"
    },
    {
      "x": -8,
      "y": 8,
      "z": -1,
      "name": "Rock_Aqua_Brick"
    },
    {
      "x": -8,
      "y": 9,
      "z": -1,
      "name": "Rock_Aqua_Brick"
    },
    {
      "x": -8,
      "y": 0,
      "z": 0,
      "name": "Rock_Aqua_Brick"
    },
    {
      "x": -8,
      "y": 8,
      "z": 0,
      "name": "Rock_Aqua_Brick"
    },
    {
      "x": -8,
      "y": 9,
      "z": 0,
      "name": "Rock_Aqua_Brick"
    },
    {
      "x": -8,
      "y": 0,
      "z": 1,
      "name": "Rock_Aqua_Brick"
    },
    {
      "x": -8,
      "y": 8,
      "z": 1,
      "name": "Rock_Aqua_Brick"
    },
    {
      "x": -8,
      "y": 9,
      "z": 1,
      "name": "Rock_Aqua_Brick"
    },
    {
      "x": -8,
      "y": 0,
      "z": 2,
      "name": "Rock_Aqua_Brick"
    },
    {
      "x": -8,
      "y": 8,
      "z": 2,
      "name": "Rock_Aqua_Brick"
    },
    {
      "x": -8,
      "y": 9,
      "z": 2,
      "name": "Rock_Aqua_Brick"
    },
    {
      "x": -8,
      "y": 0,
      "z": 3,
      "name": "Rock_Aqua_Brick"
    },
    {
      "x": -8,
      "y": 8,
      "z": 3,
      "name": "Rock_Aqua_Brick"
    },
    {
      "x": -8,
      "y": 9,
      "z": 3,
      "name": "Rock_Aqua_Brick"
    },
    {
      "x": -8,
      "y": 0,
      "z": 4,
      "name": "Rock_Aqua_Brick"
    },
    {
      "x": -8,
      "y": 8,
      "z": 4,
      "name": "Rock_Aqua_Brick"
    },
    {
      "x": -8,
      "y": 9,
      "z": 4,
      "name": "Rock_Aqua_Brick"
    },
    {
      "x": -8,
      "y": 0,
      "z": 5,
      "name": "Rock_Aqua_Brick"
    },
    {
      "x": -8,
      "y": 8,
      "z": 5,
      "name": "Rock_Aqua_Brick"
    },
    {
      "x": -8,
      "y": 9,
      "z": 5,
      "name": "Rock_Aqua_Brick"
    },
    {
      "x": -8,
      "y": 0,
      "z": 6,
      "name": "Rock_Aqua_Brick_Smooth"
    },
    {
      "x": -8,
      "y": 1,
      "z": 6,
      "name": "Rock_Aqua_Brick_Smooth"
    },
    {
      "x": -8,
      "y": 2,
      "z": 6,
      "name": "Rock_Aqua_Brick_Smooth"
    },
    {
      "x": -8,
      "y": 3,
      "z": 6,
      "name": "Rock_Aqua_Brick_Smooth"
    },
    {
      "x": -8,
      "y": 4,
      "z": 6,
      "name": "Rock_Aqua_Brick_Smooth"
    },
    {
      "x": -8,
      "y": 5,
      "z": 6,
      "name": "Rock_Aqua_Brick_Smooth"
    },
    {
      "x": -8,
      "y": 6,
      "z": 6,
      "name": "Rock_Aqua_Brick_Smooth"
    },
    {
      "x": -8,
      "y": 7,
      "z": 6,
      "name": "Rock_Aqua_Brick_Smooth"
    },
    {
      "x": -8,
      "y": 8,
      "z": 6,
      "name": "Rock_Aqua_Brick_Smooth"
    },
    {
      "x": -8,
      "y": 9,
      "z": 6,
      "name": "Rock_Aqua_Brick_Smooth"
    },
    {
      "x": -8,
      "y": 10,
      "z": 6,
      "name": "Rock_Aqua_Brick_Smooth"
    },
    {
      "x": -8,
      "y": 11,
      "z": 6,
      "name": "Rock_Aqua_Brick_Smooth"
    },
    {
      "x": -8,
      "y": 12,
      "z": 6,
      "name": "Rock_Aqua_Brick_Smooth"
    },
    {
      "x": -8,
      "y": 13,
      "z": 6,
      "name": "Rock_Aqua_Brick_Smooth"
    },
    {
      "x": -8,
      "y": 14,
      "z": 6,
      "name": "Rock_Aqua_Brick_Smooth"
    },
    {
      "x": -8,
      "y": 15,
      "z": 6,
      "name": "Rock_Aqua_Brick_Smooth"
    },
    {
      "x": -8,
      "y": 16,
      "z": 6,
      "name": "Rock_Aqua_Brick_Smooth"
    },
    {
      "x": -8,
      "y": 0,
      "z": 7,
      "name": "Rock_Aqua_Brick_Smooth"
    },
    {
      "x": -8,
      "y": 1,
      "z": 7,
      "name": "Rock_Aqua_Brick_Smooth"
    },
    {
      "x": -8,
      "y": 2,
      "z": 7,
      "name": "Rock_Aqua_Brick_Smooth"
    },
    {
      "x": -8,
      "y": 3,
      "z": 7,
      "name": "Rock_Aqua_Brick_Smooth"
    },
    {
      "x": -8,
      "y": 4,
      "z": 7,
      "name": "Rock_Aqua_Brick_Smooth"
    },
    {
      "x": -8,
      "y": 5,
      "z": 7,
      "name": "Rock_Aqua_Brick_Smooth"
    },
    {
      "x": -8,
      "y": 6,
      "z": 7,
      "name": "Rock_Aqua_Brick_Smooth"
    },
    {
      "x": -8,
      "y": 7,
      "z": 7,
      "name": "Rock_Aqua_Brick_Smooth"
    },
    {
      "x": -8,
      "y": 8,
      "z": 7,
      "name": "Rock_Aqua_Brick_Smooth"
    },
    {
      "x": -8,
      "y": 9,
      "z": 7,
      "name": "Rock_Aqua_Brick_Smooth"
    },
    {
      "x": -8,
      "y": 10,
      "z": 7,
      "name": "Rock_Aqua_Brick_Smooth"
    },
    {
      "x": -8,
      "y": 11,
      "z": 7,
      "name": "Rock_Aqua_Brick_Smooth"
    },
    {
      "x": -8,
      "y": 12,
      "z": 7,
      "name": "Rock_Aqua_Brick_Smooth"
    },
    {
      "x": -8,
      "y": 13,
      "z": 7,
      "name": "Rock_Aqua_Brick_Smooth"
    },
    {
      "x": -8,
      "y": 14,
      "z": 7,
      "name": "Rock_Aqua_Brick_Smooth"
    },
    {
      "x": -8,
      "y": 15,
      "z": 7,
      "name": "Rock_Aqua_Brick_Smooth"
    },
    {
      "x": -8,
      "y": 16,
      "z": 7,
      "name": "Rock_Aqua_Brick_Smooth"
    },
    {
      "x": -7,
      "y": 0,
      "z": -8,
      "name": "Rock_Aqua_Brick_Smooth"
    },
    {
      "x": -7,
      "y": 1,
      "z": -8,
      "name": "Rock_Aqua_Brick_Smooth"
    },
    {
      "x": -7,
      "y": 2,
      "z": -8,
      "name": "Rock_Aqua_Brick_Smooth"
    },
    {
      "x": -7,
      "y": 3,
      "z": -8,
      "name": "Rock_Aqua_Brick_Smooth"
    },
    {
      "x": -7,
      "y": 4,
      "z": -8,
      "name": "Rock_Aqua_Brick_Smooth"
    },
    {
      "x": -7,
      "y": 5,
      "z": -8,
      "name": "Rock_Aqua_Brick_Smooth"
    },
    {
      "x": -7,
      "y": 6,
      "z": -8,
      "name": "Rock_Aqua_Brick_Smooth"
    },
    {
      "x": -7,
      "y": 7,
      "z": -8,
      "name": "Rock_Aqua_Brick_Smooth"
    },
    {
      "x": -7,
      "y": 8,
      "z": -8,
      "name": "Rock_Aqua_Brick_Smooth"
    },
    {
      "x": -7,
      "y": 9,
      "z": -8,
      "name": "Rock_Aqua_Brick_Smooth"
    },
    {
      "x": -7,
      "y": 10,
      "z": -8,
      "name": "Rock_Aqua_Brick_Smooth"
    },
    {
      "x": -7,
      "y": 11,
      "z": -8,
      "name": "Rock_Aqua_Brick_Smooth"
    },
    {
      "x": -7,
      "y": 12,
      "z": -8,
      "name": "Rock_Aqua_Brick_Smooth"
    },
    {
      "x": -7,
      "y": 13,
      "z": -8,
      "name": "Rock_Aqua_Brick_Smooth"
    },
    {
      "x": -7,
      "y": 14,
      "z": -8,
      "name": "Rock_Aqua_Brick_Smooth"
    },
    {
      "x": -7,
      "y": 15,
      "z": -8,
      "name": "Rock_Aqua_Brick_Smooth"
    },
    {
      "x": -7,
      "y": 16,
      "z": -8,
      "name": "Rock_Aqua_Brick_Smooth"
    },
    {
      "x": -7,
      "y": 0,
      "z": -7,
      "name": "Rock_Aqua_Brick"
    },
    {
      "x": -7,
      "y": 8,
      "z": -7,
      "name": "Rock_Aqua_Brick"
    },
    {
      "x": -7,
      "y": 9,
      "z": -7,
      "name": "Rock_Aqua_Brick"
    },
    {
      "x": -7,
      "y": 0,
      "z": -6,
      "name": "Rock_Aqua_Brick"
    },
    {
      "x": -7,
      "y": 8,
      "z": -6,
      "name": "Rock_Aqua_Brick"
    },
    {
      "x": -7,
      "y": 9,
      "z": -6,
      "name": "Rock_Aqua_Brick"
    },
    {
      "x": -7,
      "y": 0,
      "z": -5,
      "name": "Rock_Aqua_Brick"
    },
    {
      "x": -7,
      "y": 8,
      "z": -5,
      "name": "Rock_Aqua_Brick"
    },
    {
      "x": -7,
      "y": 9,
      "z": -5,
      "name": "Rock_Aqua_Brick"
    },
    {
      "x": -7,
      "y": 0,
      "z": -4,
      "name": "Rock_Aqua_Brick"
    },
    {
      "x": -7,
      "y": 8,
      "z": -4,
      "name": "Rock_Aqua_Brick"
    },
    {
      "x": -7,
      "y": 9,
      "z": -4,
      "name": "Rock_Aqua_Brick"
    },
    {
      "x": -7,
      "y": 0,
      "z": -3,
      "name": "Rock_Aqua_Brick"
    },
    {
      "x": -7,
      "y": 8,
      "z": -3,
      "name": "Rock_Aqua_Brick"
    },
    {
      "x": -7,
      "y": 9,
      "z": -3,
      "name": "Rock_Aqua_Brick"
    },
    {
      "x": -7,
      "y": 0,
      "z": -2,
      "name": "Rock_Aqua_Brick"
    },
    {
      "x": -7,
      "y": 8,
      "z": -2,
      "name": "Rock_Aqua_Brick"
    },
    {
      "x": -7,
      "y": 9,
      "z": -2,
      "name": "Rock_Aqua_Brick"
    },
    {
      "x": -7,
      "y": 0,
      "z": -1,
      "name": "Rock_Aqua_Brick"
    },
    {
      "x": -7,
      "y": 8,
      "z": -1,
      "name": "Rock_Aqua_Brick"
    },
    {
      "x": -7,
      "y": 9,
      "z": -1,
      "name": "Rock_Aqua_Brick"
    },
    {
      "x": -7,
      "y": 0,
      "z": 0,
      "name": "Rock_Aqua_Brick"
    },
    {
      "x": -7,
      "y": 8,
      "z": 0,
      "name": "Rock_Aqua_Brick"
    },
    {
      "x": -7,
      "y": 9,
      "z": 0,
      "name": "Rock_Aqua_Brick"
    },
    {
      "x": -7,
      "y": 0,
      "z": 1,
      "name": "Rock_Aqua_Brick"
    },
    {
      "x": -7,
      "y": 8,
      "z": 1,
      "name": "Rock_Aqua_Brick"
    },
    {
      "x": -7,
      "y": 9,
      "z": 1,
      "name": "Rock_Aqua_Brick"
    },
    {
      "x": -7,
      "y": 0,
      "z": 2,
      "name": "Rock_Aqua_Brick"
    },
    {
      "x": -7,
      "y": 8,
      "z": 2,
      "name": "Rock_Aqua_Brick"
    },
    {
      "x": -7,
      "y": 9,
      "z": 2,
      "name": "Rock_Aqua_Brick"
    },
    {
      "x": -7,
      "y": 0,
      "z": 3,
      "name": "Rock_Aqua_Brick"
    },
    {
      "x": -7,
      "y": 8,
      "z": 3,
      "name": "Rock_Aqua_Brick"
    },
    {
      "x": -7,
      "y": 9,
      "z": 3,
      "name": "Rock_Aqua_Brick"
    },
    {
      "x": -7,
      "y": 0,
      "z": 4,
      "name": "Rock_Aqua_Brick"
    },
    {
      "x": -7,
      "y": 8,
      "z": 4,
      "name": "Rock_Aqua_Brick"
    },
    {
      "x": -7,
      "y": 9,
      "z": 4,
      "name": "Rock_Aqua_Brick"
    },
    {
      "x": -7,
      "y": 0,
      "z": 5,
      "name": "Rock_Aqua_Brick"
    },
    {
      "x": -7,
      "y": 8,
      "z": 5,
      "name": "Rock_Aqua_Brick"
    },
    {
      "x": -7,
      "y": 9,
      "z": 5,
      "name": "Rock_Aqua_Brick"
    },
    {
      "x": -7,
      "y": 0,
      "z": 6,
      "name": "Rock_Aqua_Brick"
    },
    {
      "x": -7,
      "y": 8,
      "z": 6,
      "name": "Rock_Aqua_Brick"
    },
    {
      "x": -7,
      "y": 9,
      "z": 6,
      "name": "Rock_Aqua_Brick"
    },
    {
      "x": -7,
      "y": 0,
      "z": 7,
      "name": "Rock_Aqua_Brick"
    },
    {
      "x": -7,
      "y": 8,
      "z": 7,
      "name": "Rock_Aqua_Brick"
    },
    {
      "x": -7,
      "y": 9,
      "z": 7,
      "name": "Rock_Aqua_Brick"
    },
    {
      "x": -7,
      "y": 0,
      "z": 8,
      "name": "Rock_Aqua_Brick_Smooth"
    },
    {
      "x": -7,
      "y": 1,
      "z": 8,
      "name": "Rock_Aqua_Brick_Smooth"
    },
    {
      "x": -7,
      "y": 2,
      "z": 8,
      "name": "Rock_Aqua_Brick_Smooth"
    },
    {
      "x": -7,
      "y": 3,
      "z": 8,
      "name": "Rock_Aqua_Brick_Smooth"
    },
    {
      "x": -7,
      "y": 4,
      "z": 8,
      "name": "Rock_Aqua_Brick_Smooth"
    },
    {
      "x": -7,
      "y": 5,
      "z": 8,
      "name": "Rock_Aqua_Brick_Smooth"
    },
    {
      "x": -7,
      "y": 6,
      "z": 8,
      "name": "Rock_Aqua_Brick_Smooth"
    },
    {
      "x": -7,
      "y": 7,
      "z": 8,
      "name": "Rock_Aqua_Brick_Smooth"
    },
    {
      "x": -7,
      "y": 8,
      "z": 8,
      "name": "Rock_Aqua_Brick_Smooth"
    },
    {
      "x": -7,
      "y": 9,
      "z": 8,
      "name": "Rock_Aqua_Brick_Smooth"
    },
    {
      "x": -7,
      "y": 10,
      "z": 8,
      "name": "Rock_Aqua_Brick_Smooth"
    },
    {
      "x": -7,
      "y": 11,
      "z": 8,
      "name": "Rock_Aqua_Brick_Smooth"
    },
    {
      "x": -7,
      "y": 12,
      "z": 8,
      "name": "Rock_Aqua_Brick_Smooth"
    },
    {
      "x": -7,
      "y": 13,
      "z": 8,
      "name": "Rock_Aqua_Brick_Smooth"
    },
    {
      "x": -7,
      "y": 14,
      "z": 8,
      "name": "Rock_Aqua_Brick_Smooth"
    },
    {
      "x": -7,
      "y": 15,
      "z": 8,
      "name": "Rock_Aqua_Brick_Smooth"
    },
    {
      "x": -7,
      "y": 16,
      "z": 8,
      "name": "Rock_Aqua_Brick_Smooth"
    },
    {
      "x": -6,
      "y": 0,
      "z": -8,
      "name": "Rock_Aqua_Brick_Smooth"
    },
    {
      "x": -6,
      "y": 1,
      "z": -8,
      "name": "Rock_Aqua_Brick_Smooth"
    },
    {
      "x": -6,
      "y": 2,
      "z": -8,
      "name": "Rock_Aqua_Brick_Smooth"
    },
    {
      "x": -6,
      "y": 3,
      "z": -8,
      "name": "Rock_Aqua_Brick_Smooth"
    },
    {
      "x": -6,
      "y": 4,
      "z": -8,
      "name": "Rock_Aqua_Brick_Smooth"
    },
    {
      "x": -6,
      "y": 5,
      "z": -8,
      "name": "Rock_Aqua_Brick_Smooth"
    },
    {
      "x": -6,
      "y": 6,
      "z": -8,
      "name": "Rock_Aqua_Brick_Smooth"
    },
    {
      "x": -6,
      "y": 7,
      "z": -8,
      "name": "Rock_Aqua_Brick_Smooth"
    },
    {
      "x": -6,
      "y": 8,
      "z": -8,
      "name": "Rock_Aqua_Brick_Smooth"
    },
    {
      "x": -6,
      "y": 9,
      "z": -8,
      "name": "Rock_Aqua_Brick_Smooth"
    },
    {
      "x": -6,
      "y": 10,
      "z": -8,
      "name": "Rock_Aqua_Brick_Smooth"
    },
    {
      "x": -6,
      "y": 11,
      "z": -8,
      "name": "Rock_Aqua_Brick_Smooth"
    },
    {
      "x": -6,
      "y": 12,
      "z": -8,
      "name": "Rock_Aqua_Brick_Smooth"
    },
    {
      "x": -6,
      "y": 13,
      "z": -8,
      "name": "Rock_Aqua_Brick_Smooth"
    },
    {
      "x": -6,
      "y": 14,
      "z": -8,
      "name": "Rock_Aqua_Brick_Smooth"
    },
    {
      "x": -6,
      "y": 15,
      "z": -8,
      "name": "Rock_Aqua_Brick_Smooth"
    },
    {
      "x": -6,
      "y": 16,
      "z": -8,
      "name": "Rock_Aqua_Brick_Smooth"
    },
    {
      "x": -6,
      "y": 0,
      "z": -7,
      "name": "Rock_Aqua_Brick"
    },
    {
      "x": -6,
      "y": 8,
      "z": -7,
      "name": "Rock_Aqua_Brick"
    },
    {
      "x": -6,
      "y": 9,
      "z": -7,
      "name": "Rock_Aqua_Brick"
    },
    {
      "x": -6,
      "y": 0,
      "z": -6,
      "name": "Rock_Aqua_Brick"
    },
    {
      "x": -6,
      "y": 8,
      "z": -6,
      "name": "Rock_Aqua_Brick"
    },
    {
      "x": -6,
      "y": 9,
      "z": -6,
      "name": "Rock_Aqua_Brick"
    },
    {
      "x": -6,
      "y": 0,
      "z": -5,
      "name": "Rock_Aqua_Brick"
    },
    {
      "x": -6,
      "y": 8,
      "z": -5,
      "name": "Rock_Aqua_Brick"
    },
    {
      "x": -6,
      "y": 9,
      "z": -5,
      "name": "Rock_Aqua_Brick"
    },
    {
      "x": -6,
      "y": 0,
      "z": -4,
      "name": "Rock_Aqua_Brick"
    },
    {
      "x": -6,
      "y": 8,
      "z": -4,
      "name": "Rock_Aqua_Brick"
    },
    {
      "x": -6,
      "y": 9,
      "z": -4,
      "name": "Rock_Aqua_Brick"
    },
    {
      "x": -6,
      "y": 0,
      "z": -3,
      "name": "Rock_Aqua_Brick"
    },
    {
      "x": -6,
      "y": 8,
      "z": -3,
      "name": "Rock_Aqua_Brick"
    },
    {
      "x": -6,
      "y": 9,
      "z": -3,
      "name": "Rock_Aqua_Brick"
    },
    {
      "x": -6,
      "y": 0,
      "z": -2,
      "name": "Rock_Aqua_Brick"
    },
    {
      "x": -6,
      "y": 8,
      "z": -2,
      "name": "Rock_Aqua_Brick"
    },
    {
      "x": -6,
      "y": 9,
      "z": -2,
      "name": "Rock_Aqua_Brick"
    },
    {
      "x": -6,
      "y": 0,
      "z": -1,
      "name": "Rock_Aqua_Brick"
    },
    {
      "x": -6,
      "y": 8,
      "z": -1,
      "name": "Rock_Aqua_Brick"
    },
    {
      "x": -6,
      "y": 9,
      "z": -1,
      "name": "Rock_Aqua_Brick"
    },
    {
      "x": -6,
      "y": 0,
      "z": 0,
      "name": "Rock_Aqua_Brick"
    },
    {
      "x": -6,
      "y": 8,
      "z": 0,
      "name": "Rock_Aqua_Brick"
    },
    {
      "x": -6,
      "y": 9,
      "z": 0,
      "name": "Rock_Aqua_Brick"
    },
    {
      "x": -6,
      "y": 0,
      "z": 1,
      "name": "Rock_Aqua_Brick"
    },
    {
      "x": -6,
      "y": 8,
      "z": 1,
      "name": "Rock_Aqua_Brick"
    },
    {
      "x": -6,
      "y": 9,
      "z": 1,
      "name": "Rock_Aqua_Brick"
    },
    {
      "x": -6,
      "y": 0,
      "z": 2,
      "name": "Rock_Aqua_Brick"
    },
    {
      "x": -6,
      "y": 8,
      "z": 2,
      "name": "Rock_Aqua_Brick"
    },
    {
      "x": -6,
      "y": 9,
      "z": 2,
      "name": "Rock_Aqua_Brick"
    },
    {
      "x": -6,
      "y": 0,
      "z": 3,
      "name": "Rock_Aqua_Brick"
    },
    {
      "x": -6,
      "y": 8,
      "z": 3,
      "name": "Rock_Aqua_Brick"
    },
    {
      "x": -6,
      "y": 9,
      "z": 3,
      "name": "Rock_Aqua_Brick"
    },
    {
      "x": -6,
      "y": 0,
      "z": 4,
      "name": "Rock_Aqua_Brick"
    },
    {
      "x": -6,
      "y": 8,
      "z": 4,
      "name": "Rock_Aqua_Brick"
    },
    {
      "x": -6,
      "y": 9,
      "z": 4,
      "name": "Rock_Aqua_Brick"
    },
    {
      "x": -6,
      "y": 0,
      "z": 5,
      "name": "Rock_Aqua_Brick"
    },
    {
      "x": -6,
      "y": 8,
      "z": 5,
      "name": "Rock_Aqua_Brick"
    },
    {
      "x": -6,
      "y": 9,
      "z": 5,
      "name": "Rock_Aqua_Brick"
    },
    {
      "x": -6,
      "y": 0,
      "z": 6,
      "name": "Rock_Aqua_Brick"
    },
    {
      "x": -6,
      "y": 8,
      "z": 6,
      "name": "Rock_Aqua_Brick"
    },
    {
      "x": -6,
      "y": 9,
      "z": 6,
      "name": "Rock_Aqua_Brick"
    },
    {
      "x": -6,
      "y": 0,
      "z": 7,
      "name": "Rock_Aqua_Brick"
    },
    {
      "x": -6,
      "y": 8,
      "z": 7,
      "name": "Rock_Aqua_Brick"
    },
    {
      "x": -6,
      "y": 9,
      "z": 7,
      "name": "Rock_Aqua_Brick"
    },
    {
      "x": -6,
      "y": 0,
      "z": 8,
      "name": "Rock_Aqua_Brick_Smooth"
    },
    {
      "x": -6,
      "y": 1,
      "z": 8,
      "name": "Rock_Aqua_Brick_Smooth"
    },
    {
      "x": -6,
      "y": 2,
      "z": 8,
      "name": "Rock_Aqua_Brick_Smooth"
    },
    {
      "x": -6,
      "y": 3,
      "z": 8,
      "name": "Rock_Aqua_Brick_Smooth"
    },
    {
      "x": -6,
      "y": 4,
      "z": 8,
      "name": "Rock_Aqua_Brick_Smooth"
    },
    {
      "x": -6,
      "y": 5,
      "z": 8,
      "name": "Rock_Aqua_Brick_Smooth"
    },
    {
      "x": -6,
      "y": 6,
      "z": 8,
      "name": "Rock_Aqua_Brick_Smooth"
    },
    {
      "x": -6,
      "y": 7,
      "z": 8,
      "name": "Rock_Aqua_Brick_Smooth"
    },
    {
      "x": -6,
      "y": 8,
      "z": 8,
      "name": "Rock_Aqua_Brick_Smooth"
    },
    {
      "x": -6,
      "y": 9,
      "z": 8,
      "name": "Rock_Aqua_Brick_Smooth"
    },
    {
      "x": -6,
      "y": 10,
      "z": 8,
      "name": "Rock_Aqua_Brick_Smooth"
    },
    {
      "x": -6,
      "y": 11,
      "z": 8,
      "name": "Rock_Aqua_Brick_Smooth"
    },
    {
      "x": -6,
      "y": 12,
      "z": 8,
      "name": "Rock_Aqua_Brick_Smooth"
    },
    {
      "x": -6,
      "y": 13,
      "z": 8,
      "name": "Rock_Aqua_Brick_Smooth"
    },
    {
      "x": -6,
      "y": 14,
      "z": 8,
      "name": "Rock_Aqua_Brick_Smooth"
    },
    {
      "x": -6,
      "y": 15,
      "z": 8,
      "name": "Rock_Aqua_Brick_Smooth"
    },
    {
      "x": -6,
      "y": 16,
      "z": 8,
      "name": "Rock_Aqua_Brick_Smooth"
    },
    {
      "x": -5,
      "y": 0,
      "z": -9,
      "name": "Rock_Aqua_Brick_Smooth"
    },
    {
      "x": -5,
      "y": 1,
      "z": -9,
      "name": "Rock_Aqua_Brick_Smooth"
    },
    {
      "x": -5,
      "y": 2,
      "z": -9,
      "name": "Rock_Aqua_Brick_Smooth"
    },
    {
      "x": -5,
      "y": 3,
      "z": -9,
      "name": "Rock_Aqua_Brick_Smooth"
    },
    {
      "x": -5,
      "y": 4,
      "z": -9,
      "name": "Rock_Aqua_Brick_Smooth"
    },
    {
      "x": -5,
      "y": 5,
      "z": -9,
      "name": "Rock_Aqua_Brick_Smooth"
    },
    {
      "x": -5,
      "y": 6,
      "z": -9,
      "name": "Rock_Aqua_Brick_Smooth"
    },
    {
      "x": -5,
      "y": 7,
      "z": -9,
      "name": "Rock_Aqua_Brick_Smooth"
    },
    {
      "x": -5,
      "y": 8,
      "z": -9,
      "name": "Rock_Aqua_Brick_Smooth"
    },
    {
      "x": -5,
      "y": 9,
      "z": -9,
      "name": "Rock_Aqua_Brick_Smooth"
    },
    {
      "x": -5,
      "y": 10,
      "z": -9,
      "name": "Rock_Aqua_Brick_Smooth"
    },
    {
      "x": -5,
      "y": 11,
      "z": -9,
      "name": "Rock_Aqua_Brick_Smooth"
    },
    {
      "x": -5,
      "y": 12,
      "z": -9,
      "name": "Rock_Aqua_Brick_Smooth"
    },
    {
      "x": -5,
      "y": 13,
      "z": -9,
      "name": "Rock_Aqua_Brick_Smooth"
    },
    {
      "x": -5,
      "y": 14,
      "z": -9,
      "name": "Rock_Aqua_Brick_Smooth"
    },
    {
      "x": -5,
      "y": 15,
      "z": -9,
      "name": "Rock_Aqua_Brick_Smooth"
    },
    {
      "x": -5,
      "y": 16,
      "z": -9,
      "name": "Rock_Aqua_Brick_Smooth"
    },
    {
      "x": -5,
      "y": 0,
      "z": -8,
      "name": "Rock_Aqua_Brick"
    },
    {
      "x": -5,
      "y": 8,
      "z": -8,
      "name": "Rock_Aqua_Brick"
    },
    {
      "x": -5,
      "y": 9,
      "z": -8,
      "name": "Rock_Aqua_Brick"
    },
    {
      "x": -5,
      "y": 0,
      "z": -7,
      "name": "Rock_Aqua_Brick"
    },
    {
      "x": -5,
      "y": 8,
      "z": -7,
      "name": "Rock_Aqua_Brick"
    },
    {
      "x": -5,
      "y": 9,
      "z": -7,
      "name": "Rock_Aqua_Brick"
    },
    {
      "x": -5,
      "y": 0,
      "z": -6,
      "name": "Rock_Aqua_Brick"
    },
    {
      "x": -5,
      "y": 8,
      "z": -6,
      "name": "Rock_Aqua_Brick"
    },
    {
      "x": -5,
      "y": 9,
      "z": -6,
      "name": "Rock_Aqua_Brick"
    },
    {
      "x": -5,
      "y": 0,
      "z": -5,
      "name": "Rock_Aqua_Brick"
    },
    {
      "x": -5,
      "y": 8,
      "z": -5,
      "name": "Rock_Aqua_Brick"
    },
    {
      "x": -5,
      "y": 9,
      "z": -5,
      "name": "Rock_Aqua_Brick"
    },
    {
      "x": -5,
      "y": 0,
      "z": -4,
      "name": "Rock_Aqua_Brick"
    },
    {
      "x": -5,
      "y": 8,
      "z": -4,
      "name": "Rock_Aqua_Brick"
    },
    {
      "x": -5,
      "y": 9,
      "z": -4,
      "name": "Rock_Aqua_Brick"
    },
    {
      "x": -5,
      "y": 0,
      "z": -3,
      "name": "Rock_Aqua_Brick"
    },
    {
      "x": -5,
      "y": 8,
      "z": -3,
      "name": "Rock_Aqua_Brick"
    },
    {
      "x": -5,
      "y": 9,
      "z": -3,
      "name": "Rock_Aqua_Brick"
    },
    {
      "x": -5,
      "y": 0,
      "z": -2,
      "name": "Rock_Aqua_Brick"
    },
    {
      "x": -5,
      "y": 8,
      "z": -2,
      "name": "Rock_Aqua_Brick"
    },
    {
      "x": -5,
      "y": 9,
      "z": -2,
      "name": "Rock_Aqua_Brick"
    },
    {
      "x": -5,
      "y": 0,
      "z": -1,
      "name": "Rock_Aqua_Brick"
    },
    {
      "x": -5,
      "y": 8,
      "z": -1,
      "name": "Rock_Aqua_Brick"
    },
    {
      "x": -5,
      "y": 9,
      "z": -1,
      "name": "Rock_Aqua_Brick"
    },
    {
      "x": -5,
      "y": 0,
      "z": 0,
      "name": "Rock_Aqua_Brick"
    },
    {
      "x": -5,
      "y": 8,
      "z": 0,
      "name": "Rock_Aqua_Brick"
    },
    {
      "x": -5,
      "y": 9,
      "z": 0,
      "name": "Rock_Aqua_Brick"
    },
    {
      "x": -5,
      "y": 0,
      "z": 1,
      "name": "Rock_Aqua_Brick"
    },
    {
      "x": -5,
      "y": 8,
      "z": 1,
      "name": "Rock_Aqua_Brick"
    },
    {
      "x": -5,
      "y": 9,
      "z": 1,
      "name": "Rock_Aqua_Brick"
    },
    {
      "x": -5,
      "y": 0,
      "z": 2,
      "name": "Rock_Aqua_Brick"
    },
    {
      "x": -5,
      "y": 8,
      "z": 2,
      "name": "Rock_Aqua_Brick"
    },
    {
      "x": -5,
      "y": 9,
      "z": 2,
      "name": "Rock_Aqua_Brick"
    },
    {
      "x": -5,
      "y": 0,
      "z": 3,
      "name": "Rock_Aqua_Brick"
    },
    {
      "x": -5,
      "y": 8,
      "z": 3,
      "name": "Rock_Aqua_Brick"
    },
    {
      "x": -5,
      "y": 9,
      "z": 3,
      "name": "Rock_Aqua_Brick"
    },
    {
      "x": -5,
      "y": 0,
      "z": 4,
      "name": "Rock_Aqua_Brick"
    },
    {
      "x": -5,
      "y": 8,
      "z": 4,
      "name": "Rock_Aqua_Brick"
    },
    {
      "x": -5,
      "y": 9,
      "z": 4,
      "name": "Rock_Aqua_Brick"
    },
    {
      "x": -5,
      "y": 0,
      "z": 5,
      "name": "Rock_Aqua_Brick"
    },
    {
      "x": -5,
      "y": 8,
      "z": 5,
      "name": "Rock_Aqua_Brick"
    },
    {
      "x": -5,
      "y": 9,
      "z": 5,
      "name": "Rock_Aqua_Brick"
    },
    {
      "x": -5,
      "y": 0,
      "z": 6,
      "name": "Rock_Aqua_Brick"
    },
    {
      "x": -5,
      "y": 8,
      "z": 6,
      "name": "Rock_Aqua_Brick"
    },
    {
      "x": -5,
      "y": 9,
      "z": 6,
      "name": "Rock_Aqua_Brick"
    },
    {
      "x": -5,
      "y": 0,
      "z": 7,
      "name": "Rock_Aqua_Brick"
    },
    {
      "x": -5,
      "y": 8,
      "z": 7,
      "name": "Rock_Aqua_Brick"
    },
    {
      "x": -5,
      "y": 9,
      "z": 7,
      "name": "Rock_Aqua_Brick"
    },
    {
      "x": -5,
      "y": 0,
      "z": 8,
      "name": "Rock_Aqua_Brick"
    },
    {
      "x": -5,
      "y": 8,
      "z": 8,
      "name": "Rock_Aqua_Brick"
    },
    {
      "x": -5,
      "y": 9,
      "z": 8,
      "name": "Rock_Aqua_Brick"
    },
    {
      "x": -5,
      "y": 0,
      "z": 9,
      "name": "Rock_Aqua_Brick_Smooth"
    },
    {
      "x": -5,
      "y": 1,
      "z": 9,
      "name": "Rock_Aqua_Brick_Smooth"
    },
    {
      "x": -5,
      "y": 2,
      "z": 9,
      "name": "Rock_Aqua_Brick_Smooth"
    },
    {
      "x": -5,
      "y": 3,
      "z": 9,
      "name": "Rock_Aqua_Brick_Smooth"
    },
    {
      "x": -5,
      "y": 4,
      "z": 9,
      "name": "Rock_Aqua_Brick_Smooth"
    },
    {
      "x": -5,
      "y": 5,
      "z": 9,
      "name": "Rock_Aqua_Brick_Smooth"
    },
    {
      "x": -5,
      "y": 6,
      "z": 9,
      "name": "Rock_Aqua_Brick_Smooth"
    },
    {
      "x": -5,
      "y": 7,
      "z": 9,
      "name": "Rock_Aqua_Brick_Smooth"
    },
    {
      "x": -5,
      "y": 8,
      "z": 9,
      "name": "Rock_Aqua_Brick_Smooth"
    },
    {
      "x": -5,
      "y": 9,
      "z": 9,
      "name": "Rock_Aqua_Brick_Smooth"
    },
    {
      "x": -5,
      "y": 10,
      "z": 9,
      "name": "Rock_Aqua_Brick_Smooth"
    },
    {
      "x": -5,
      "y": 11,
      "z": 9,
      "name": "Rock_Aqua_Brick_Smooth"
    },
    {
      "x": -5,
      "y": 12,
      "z": 9,
      "name": "Rock_Aqua_Brick_Smooth"
    },
    {
      "x": -5,
      "y": 13,
      "z": 9,
      "name": "Rock_Aqua_Brick_Smooth"
    },
    {
      "x": -5,
      "y": 14,
      "z": 9,
      "name": "Rock_Aqua_Brick_Smooth"
    },
    {
      "x": -5,
      "y": 15,
      "z": 9,
      "name": "Rock_Aqua_Brick_Smooth"
    },
    {
      "x": -5,
      "y": 16,
      "z": 9,
      "name": "Rock_Aqua_Brick_Smooth"
    },
    {
      "x": -4,
      "y": 0,
      "z": -9,
      "name": "Rock_Aqua_Brick_Smooth"
    },
    {
      "x": -4,
      "y": 1,
      "z": -9,
      "name": "Rock_Aqua_Brick_Smooth"
    },
    {
      "x": -4,
      "y": 2,
      "z": -9,
      "name": "Rock_Aqua_Brick_Smooth"
    },
    {
      "x": -4,
      "y": 3,
      "z": -9,
      "name": "Rock_Aqua_Brick_Smooth"
    },
    {
      "x": -4,
      "y": 4,
      "z": -9,
      "name": "Rock_Aqua_Brick_Smooth"
    },
    {
      "x": -4,
      "y": 5,
      "z": -9,
      "name": "Rock_Aqua_Brick_Smooth"
    },
    {
      "x": -4,
      "y": 6,
      "z": -9,
      "name": "Rock_Aqua_Brick_Smooth"
    },
    {
      "x": -4,
      "y": 7,
      "z": -9,
      "name": "Rock_Aqua_Brick_Smooth"
    },
    {
      "x": -4,
      "y": 8,
      "z": -9,
      "name": "Rock_Aqua_Brick_Smooth"
    },
    {
      "x": -4,
      "y": 9,
      "z": -9,
      "name": "Rock_Aqua_Brick_Smooth"
    },
    {
      "x": -4,
      "y": 10,
      "z": -9,
      "name": "Rock_Aqua_Brick_Smooth"
    },
    {
      "x": -4,
      "y": 11,
      "z": -9,
      "name": "Rock_Aqua_Brick_Smooth"
    },
    {
      "x": -4,
      "y": 12,
      "z": -9,
      "name": "Rock_Aqua_Brick_Smooth"
    },
    {
      "x": -4,
      "y": 13,
      "z": -9,
      "name": "Rock_Aqua_Brick_Smooth"
    },
    {
      "x": -4,
      "y": 14,
      "z": -9,
      "name": "Rock_Aqua_Brick_Smooth"
    },
    {
      "x": -4,
      "y": 15,
      "z": -9,
      "name": "Rock_Aqua_Brick_Smooth"
    },
    {
      "x": -4,
      "y": 16,
      "z": -9,
      "name": "Rock_Aqua_Brick_Smooth"
    },
    {
      "x": -4,
      "y": 0,
      "z": -8,
      "name": "Rock_Aqua_Brick"
    },
    {
      "x": -4,
      "y": 8,
      "z": -8,
      "name": "Rock_Aqua_Brick"
    },
    {
      "x": -4,
      "y": 9,
      "z": -8,
      "name": "Rock_Aqua_Brick"
    },
    {
      "x": -4,
      "y": 0,
      "z": -7,
      "name": "Rock_Aqua_Brick"
    },
    {
      "x": -4,
      "y": 8,
      "z": -7,
      "name": "Rock_Aqua_Brick"
    },
    {
      "x": -4,
      "y": 9,
      "z": -7,
      "name": "Rock_Aqua_Brick"
    },
    {
      "x": -4,
      "y": 0,
      "z": -6,
      "name": "Rock_Aqua_Brick"
    },
    {
      "x": -4,
      "y": 8,
      "z": -6,
      "name": "Rock_Aqua_Brick"
    },
    {
      "x": -4,
      "y": 9,
      "z": -6,
      "name": "Rock_Aqua_Brick"
    },
    {
      "x": -4,
      "y": 0,
      "z": -5,
      "name": "Rock_Aqua_Brick"
    },
    {
      "x": -4,
      "y": 8,
      "z": -5,
      "name": "Rock_Aqua_Brick"
    },
    {
      "x": -4,
      "y": 9,
      "z": -5,
      "name": "Rock_Aqua_Brick"
    },
    {
      "x": -4,
      "y": 0,
      "z": -4,
      "name": "Rock_Aqua_Brick"
    },
    {
      "x": -4,
      "y": 8,
      "z": -4,
      "name": "Rock_Aqua_Brick"
    },
    {
      "x": -4,
      "y": 9,
      "z": -4,
      "name": "Rock_Aqua_Brick"
    },
    {
      "x": -4,
      "y": 0,
      "z": -3,
      "name": "Rock_Aqua_Brick"
    },
    {
      "x": -4,
      "y": 8,
      "z": -3,
      "name": "Rock_Aqua_Brick"
    },
    {
      "x": -4,
      "y": 9,
      "z": -3,
      "name": "Rock_Aqua_Brick"
    },
    {
      "x": -4,
      "y": 0,
      "z": -2,
      "name": "Rock_Aqua_Brick"
    },
    {
      "x": -4,
      "y": 8,
      "z": -2,
      "name": "Rock_Aqua_Brick"
    },
    {
      "x": -4,
      "y": 9,
      "z": -2,
      "name": "Rock_Aqua_Brick"
    },
    {
      "x": -4,
      "y": 0,
      "z": -1,
      "name": "Rock_Aqua_Brick"
    },
    {
      "x": -4,
      "y": 0,
      "z": 0,
      "name": "Rock_Aqua_Brick"
    },
    {
      "x": -4,
      "y": 0,
      "z": 1,
      "name": "Rock_Aqua_Brick"
    },
    {
      "x": -4,
      "y": 0,
      "z": 2,
      "name": "Rock_Aqua_Brick"
    },
    {
      "x": -4,
      "y": 8,
      "z": 2,
      "name": "Rock_Aqua_Brick"
    },
    {
      "x": -4,
      "y": 9,
      "z": 2,
      "name": "Rock_Aqua_Brick"
    },
    {
      "x": -4,
      "y": 0,
      "z": 3,
      "name": "Rock_Aqua_Brick"
    },
    {
      "x": -4,
      "y": 8,
      "z": 3,
      "name": "Rock_Aqua_Brick"
    },
    {
      "x": -4,
      "y": 9,
      "z": 3,
      "name": "Rock_Aqua_Brick"
    },
    {
      "x": -4,
      "y": 0,
      "z": 4,
      "name": "Rock_Aqua_Brick"
    },
    {
      "x": -4,
      "y": 8,
      "z": 4,
      "name": "Rock_Aqua_Brick"
    },
    {
      "x": -4,
      "y": 9,
      "z": 4,
      "name": "Rock_Aqua_Brick"
    },
    {
      "x": -4,
      "y": 0,
      "z": 5,
      "name": "Rock_Aqua_Brick"
    },
    {
      "x": -4,
      "y": 8,
      "z": 5,
      "name": "Rock_Aqua_Brick"
    },
    {
      "x": -4,
      "y": 9,
      "z": 5,
      "name": "Rock_Aqua_Brick"
    },
    {
      "x": -4,
      "y": 0,
      "z": 6,
      "name": "Rock_Aqua_Brick"
    },
    {
      "x": -4,
      "y": 8,
      "z": 6,
      "name": "Rock_Aqua_Brick"
    },
    {
      "x": -4,
      "y": 9,
      "z": 6,
      "name": "Rock_Aqua_Brick"
    },
    {
      "x": -4,
      "y": 0,
      "z": 7,
      "name": "Rock_Aqua_Brick"
    },
    {
      "x": -4,
      "y": 8,
      "z": 7,
      "name": "Rock_Aqua_Brick"
    },
    {
      "x": -4,
      "y": 9,
      "z": 7,
      "name": "Rock_Aqua_Brick"
    },
    {
      "x": -4,
      "y": 0,
      "z": 8,
      "name": "Rock_Aqua_Brick"
    },
    {
      "x": -4,
      "y": 8,
      "z": 8,
      "name": "Rock_Aqua_Brick"
    },
    {
      "x": -4,
      "y": 9,
      "z": 8,
      "name": "Rock_Aqua_Brick"
    },
    {
      "x": -4,
      "y": 0,
      "z": 9,
      "name": "Rock_Aqua_Brick_Smooth"
    },
    {
      "x": -4,
      "y": 1,
      "z": 9,
      "name": "Rock_Aqua_Brick_Smooth"
    },
    {
      "x": -4,
      "y": 2,
      "z": 9,
      "name": "Rock_Aqua_Brick_Smooth"
    },
    {
      "x": -4,
      "y": 3,
      "z": 9,
      "name": "Rock_Aqua_Brick_Smooth"
    },
    {
      "x": -4,
      "y": 4,
      "z": 9,
      "name": "Rock_Aqua_Brick_Smooth"
    },
    {
      "x": -4,
      "y": 5,
      "z": 9,
      "name": "Rock_Aqua_Brick_Smooth"
    },
    {
      "x": -4,
      "y": 6,
      "z": 9,
      "name": "Rock_Aqua_Brick_Smooth"
    },
    {
      "x": -4,
      "y": 7,
      "z": 9,
      "name": "Rock_Aqua_Brick_Smooth"
    },
    {
      "x": -4,
      "y": 8,
      "z": 9,
      "name": "Rock_Aqua_Brick_Smooth"
    },
    {
      "x": -4,
      "y": 9,
      "z": 9,
      "name": "Rock_Aqua_Brick_Smooth"
    },
    {
      "x": -4,
      "y": 10,
      "z": 9,
      "name": "Rock_Aqua_Brick_Smooth"
    },
    {
      "x": -4,
      "y": 11,
      "z": 9,
      "name": "Rock_Aqua_Brick_Smooth"
    },
    {
      "x": -4,
      "y": 12,
      "z": 9,
      "name": "Rock_Aqua_Brick_Smooth"
    },
    {
      "x": -4,
      "y": 13,
      "z": 9,
      "name": "Rock_Aqua_Brick_Smooth"
    },
    {
      "x": -4,
      "y": 14,
      "z": 9,
      "name": "Rock_Aqua_Brick_Smooth"
    },
    {
      "x": -4,
      "y": 15,
      "z": 9,
      "name": "Rock_Aqua_Brick_Smooth"
    },
    {
      "x": -4,
      "y": 16,
      "z": 9,
      "name": "Rock_Aqua_Brick_Smooth"
    },
    {
      "x": -3,
      "y": 0,
      "z": -9,
      "name": "Rock_Aqua_Brick_Smooth"
    },
    {
      "x": -3,
      "y": 1,
      "z": -9,
      "name": "Rock_Aqua_Brick_Smooth"
    },
    {
      "x": -3,
      "y": 2,
      "z": -9,
      "name": "Rock_Aqua_Brick_Smooth"
    },
    {
      "x": -3,
      "y": 3,
      "z": -9,
      "name": "Rock_Aqua_Brick_Smooth"
    },
    {
      "x": -3,
      "y": 4,
      "z": -9,
      "name": "Rock_Aqua_Brick_Smooth"
    },
    {
      "x": -3,
      "y": 5,
      "z": -9,
      "name": "Rock_Aqua_Brick_Smooth"
    },
    {
      "x": -3,
      "y": 6,
      "z": -9,
      "name": "Rock_Aqua_Brick_Smooth"
    },
    {
      "x": -3,
      "y": 7,
      "z": -9,
      "name": "Rock_Aqua_Brick_Smooth"
    },
    {
      "x": -3,
      "y": 8,
      "z": -9,
      "name": "Rock_Aqua_Brick_Smooth"
    },
    {
      "x": -3,
      "y": 9,
      "z": -9,
      "name": "Rock_Aqua_Brick_Smooth"
    },
    {
      "x": -3,
      "y": 10,
      "z": -9,
      "name": "Rock_Aqua_Brick_Smooth"
    },
    {
      "x": -3,
      "y": 11,
      "z": -9,
      "name": "Rock_Aqua_Brick_Smooth"
    },
    {
      "x": -3,
      "y": 12,
      "z": -9,
      "name": "Rock_Aqua_Brick_Smooth"
    },
    {
      "x": -3,
      "y": 13,
      "z": -9,
      "name": "Rock_Aqua_Brick_Smooth"
    },
    {
      "x": -3,
      "y": 14,
      "z": -9,
      "name": "Rock_Aqua_Brick_Smooth"
    },
    {
      "x": -3,
      "y": 15,
      "z": -9,
      "name": "Rock_Aqua_Brick_Smooth"
    },
    {
      "x": -3,
      "y": 16,
      "z": -9,
      "name": "Rock_Aqua_Brick_Smooth"
    },
    {
      "x": -3,
      "y": 0,
      "z": -8,
      "name": "Rock_Aqua_Brick"
    },
    {
      "x": -3,
      "y": 8,
      "z": -8,
      "name": "Rock_Aqua_Brick"
    },
    {
      "x": -3,
      "y": 9,
      "z": -8,
      "name": "Rock_Aqua_Brick"
    },
    {
      "x": -3,
      "y": 0,
      "z": -7,
      "name": "Rock_Aqua_Brick"
    },
    {
      "x": -3,
      "y": 8,
      "z": -7,
      "name": "Rock_Aqua_Brick"
    },
    {
      "x": -3,
      "y": 9,
      "z": -7,
      "name": "Rock_Aqua_Brick"
    },
    {
      "x": -3,
      "y": 0,
      "z": -6,
      "name": "Rock_Aqua_Brick"
    },
    {
      "x": -3,
      "y": 8,
      "z": -6,
      "name": "Rock_Aqua_Brick"
    },
    {
      "x": -3,
      "y": 9,
      "z": -6,
      "name": "Rock_Aqua_Brick"
    },
    {
      "x": -3,
      "y": 0,
      "z": -5,
      "name": "Rock_Aqua_Brick"
    },
    {
      "x": -3,
      "y": 8,
      "z": -5,
      "name": "Rock_Aqua_Brick"
    },
    {
      "x": -3,
      "y": 9,
      "z": -5,
      "name": "Rock_Aqua_Brick"
    },
    {
      "x": -3,
      "y": 0,
      "z": -4,
      "name": "Rock_Aqua_Brick"
    },
    {
      "x": -3,
      "y": 8,
      "z": -4,
      "name": "Rock_Aqua_Brick"
    },
    {
      "x": -3,
      "y": 9,
      "z": -4,
      "name": "Rock_Aqua_Brick"
    },
    {
      "x": -3,
      "y": 0,
      "z": -3,
      "name": "Rock_Aqua_Brick"
    },
    {
      "x": -3,
      "y": 0,
      "z": -2,
      "name": "Rock_Aqua_Brick"
    },
    {
      "x": -3,
      "y": 0,
      "z": -1,
      "name": "Rock_Aqua_Brick"
    },
    {
      "x": -3,
      "y": 0,
      "z": 0,
      "name": "Rock_Aqua_Brick"
    },
    {
      "x": -3,
      "y": 0,
      "z": 1,
      "name": "Rock_Aqua_Brick"
    },
    {
      "x": -3,
      "y": 0,
      "z": 2,
      "name": "Rock_Aqua_Brick"
    },
    {
      "x": -3,
      "y": 0,
      "z": 3,
      "name": "Rock_Aqua_Brick"
    },
    {
      "x": -3,
      "y": 0,
      "z": 4,
      "name": "Rock_Aqua_Brick"
    },
    {
      "x": -3,
      "y": 8,
      "z": 4,
      "name": "Rock_Aqua_Brick"
    },
    {
      "x": -3,
      "y": 9,
      "z": 4,
      "name": "Rock_Aqua_Brick"
    },
    {
      "x": -3,
      "y": 0,
      "z": 5,
      "name": "Rock_Aqua_Brick"
    },
    {
      "x": -3,
      "y": 8,
      "z": 5,
      "name": "Rock_Aqua_Brick"
    },
    {
      "x": -3,
      "y": 9,
      "z": 5,
      "name": "Rock_Aqua_Brick"
    },
    {
      "x": -3,
      "y": 0,
      "z": 6,
      "name": "Rock_Aqua_Brick"
    },
    {
      "x": -3,
      "y": 8,
      "z": 6,
      "name": "Rock_Aqua_Brick"
    },
    {
      "x": -3,
      "y": 9,
      "z": 6,
      "name": "Rock_Aqua_Brick"
    },
    {
      "x": -3,
      "y": 0,
      "z": 7,
      "name": "Rock_Aqua_Brick"
    },
    {
      "x": -3,
      "y": 8,
      "z": 7,
      "name": "Rock_Aqua_Brick"
    },
    {
      "x": -3,
      "y": 9,
      "z": 7,
      "name": "Rock_Aqua_Brick"
    },
    {
      "x": -3,
      "y": 0,
      "z": 8,
      "name": "Rock_Aqua_Brick"
    },
    {
      "x": -3,
      "y": 8,
      "z": 8,
      "name": "Rock_Aqua_Brick"
    },
    {
      "x": -3,
      "y": 9,
      "z": 8,
      "name": "Rock_Aqua_Brick"
    },
    {
      "x": -3,
      "y": 0,
      "z": 9,
      "name": "Rock_Aqua_Brick_Smooth"
    },
    {
      "x": -3,
      "y": 1,
      "z": 9,
      "name": "Rock_Aqua_Brick_Smooth"
    },
    {
      "x": -3,
      "y": 2,
      "z": 9,
      "name": "Rock_Aqua_Brick_Smooth"
    },
    {
      "x": -3,
      "y": 3,
      "z": 9,
      "name": "Rock_Aqua_Brick_Smooth"
    },
    {
      "x": -3,
      "y": 4,
      "z": 9,
      "name": "Rock_Aqua_Brick_Smooth"
    },
    {
      "x": -3,
      "y": 5,
      "z": 9,
      "name": "Rock_Aqua_Brick_Smooth"
    },
    {
      "x": -3,
      "y": 6,
      "z": 9,
      "name": "Rock_Aqua_Brick_Smooth"
    },
    {
      "x": -3,
      "y": 7,
      "z": 9,
      "name": "Rock_Aqua_Brick_Smooth"
    },
    {
      "x": -3,
      "y": 8,
      "z": 9,
      "name": "Rock_Aqua_Brick_Smooth"
    },
    {
      "x": -3,
      "y": 9,
      "z": 9,
      "name": "Rock_Aqua_Brick_Smooth"
    },
    {
      "x": -3,
      "y": 10,
      "z": 9,
      "name": "Rock_Aqua_Brick_Smooth"
    },
    {
      "x": -3,
      "y": 11,
      "z": 9,
      "name": "Rock_Aqua_Brick_Smooth"
    },
    {
      "x": -3,
      "y": 12,
      "z": 9,
      "name": "Rock_Aqua_Brick_Smooth"
    },
    {
      "x": -3,
      "y": 13,
      "z": 9,
      "name": "Rock_Aqua_Brick_Smooth"
    },
    {
      "x": -3,
      "y": 14,
      "z": 9,
      "name": "Rock_Aqua_Brick_Smooth"
    },
    {
      "x": -3,
      "y": 15,
      "z": 9,
      "name": "Rock_Aqua_Brick_Smooth"
    },
    {
      "x": -3,
      "y": 16,
      "z": 9,
      "name": "Rock_Aqua_Brick_Smooth"
    },
    {
      "x": -2,
      "y": 0,
      "z": -10,
      "name": "Rock_Aqua_Brick_Smooth"
    },
    {
      "x": -2,
      "y": 1,
      "z": -10,
      "name": "Rock_Aqua_Brick_Smooth"
    },
    {
      "x": -2,
      "y": 2,
      "z": -10,
      "name": "Rock_Aqua_Brick_Smooth"
    },
    {
      "x": -2,
      "y": 3,
      "z": -10,
      "name": "Rock_Aqua_Brick_Smooth"
    },
    {
      "x": -2,
      "y": 4,
      "z": -10,
      "name": "Rock_Aqua_Brick_Smooth"
    },
    {
      "x": -2,
      "y": 5,
      "z": -10,
      "name": "Rock_Aqua_Brick_Smooth"
    },
    {
      "x": -2,
      "y": 6,
      "z": -10,
      "name": "Rock_Aqua_Brick_Smooth"
    },
    {
      "x": -2,
      "y": 7,
      "z": -10,
      "name": "Rock_Aqua_Brick_Smooth"
    },
    {
      "x": -2,
      "y": 8,
      "z": -10,
      "name": "Rock_Aqua_Brick_Smooth"
    },
    {
      "x": -2,
      "y": 9,
      "z": -10,
      "name": "Rock_Aqua_Brick_Smooth"
    },
    {
      "x": -2,
      "y": 10,
      "z": -10,
      "name": "Rock_Aqua_Brick_Smooth"
    },
    {
      "x": -2,
      "y": 11,
      "z": -10,
      "name": "Rock_Aqua_Brick_Smooth"
    },
    {
      "x": -2,
      "y": 12,
      "z": -10,
      "name": "Rock_Aqua_Brick_Smooth"
    },
    {
      "x": -2,
      "y": 13,
      "z": -10,
      "name": "Rock_Aqua_Brick_Smooth"
    },
    {
      "x": -2,
      "y": 14,
      "z": -10,
      "name": "Rock_Aqua_Brick_Smooth"
    },
    {
      "x": -2,
      "y": 15,
      "z": -10,
      "name": "Rock_Aqua_Brick_Smooth"
    },
    {
      "x": -2,
      "y": 16,
      "z": -10,
      "name": "Rock_Aqua_Brick_Smooth"
    },
    {
      "x": -2,
      "y": 0,
      "z": -9,
      "name": "Rock_Aqua_Brick"
    },
    {
      "x": -2,
      "y": 8,
      "z": -9,
      "name": "Rock_Aqua_Brick"
    },
    {
      "x": -2,
      "y": 9,
      "z": -9,
      "name": "Rock_Aqua_Brick"
    },
    {
      "x": -2,
      "y": 0,
      "z": -8,
      "name": "Rock_Aqua_Brick"
    },
    {
      "x": -2,
      "y": 8,
      "z": -8,
      "name": "Rock_Aqua_Brick"
    },
    {
      "x": -2,
      "y": 9,
      "z": -8,
      "name": "Rock_Aqua_Brick"
    },
    {
      "x": -2,
      "y": 0,
      "z": -7,
      "name": "Rock_Aqua_Brick"
    },
    {
      "x": -2,
      "y": 8,
      "z": -7,
      "name": "Rock_Aqua_Brick"
    },
    {
      "x": -2,
      "y": 9,
      "z": -7,
      "name": "Rock_Aqua_Brick"
    },
    {
      "x": -2,
      "y": 0,
      "z": -6,
      "name": "Rock_Aqua_Brick"
    },
    {
      "x": -2,
      "y": 8,
      "z": -6,
      "name": "Rock_Aqua_Brick"
    },
    {
      "x": -2,
      "y": 9,
      "z": -6,
      "name": "Rock_Aqua_Brick"
    },
    {
      "x": -2,
      "y": 0,
      "z": -5,
      "name": "Rock_Aqua_Brick"
    },
    {
      "x": -2,
      "y": 8,
      "z": -5,
      "name": "Rock_Aqua_Brick"
    },
    {
      "x": -2,
      "y": 9,
      "z": -5,
      "name": "Rock_Aqua_Brick"
    },
    {
      "x": -2,
      "y": 0,
      "z": -4,
      "name": "Rock_Aqua_Brick"
    },
    {
      "x": -2,
      "y": 8,
      "z": -4,
      "name": "Rock_Aqua_Brick"
    },
    {
      "x": -2,
      "y": 9,
      "z": -4,
      "name": "Rock_Aqua_Brick"
    },
    {
      "x": -2,
      "y": 0,
      "z": -3,
      "name": "Rock_Aqua_Brick"
    },
    {
      "x": -2,
      "y": 0,
      "z": -2,
      "name": "Rock_Aqua_Brick"
    },
    {
      "x": -2,
      "y": 0,
      "z": -1,
      "name": "Rock_Aqua_Brick"
    },
    {
      "x": -2,
      "y": 0,
      "z": 0,
      "name": "Rock_Aqua_Brick"
    },
    {
      "x": -2,
      "y": 0,
      "z": 1,
      "name": "Rock_Aqua_Brick"
    },
    {
      "x": -2,
      "y": 0,
      "z": 2,
      "name": "Rock_Aqua_Brick"
    },
    {
      "x": -2,
      "y": 0,
      "z": 3,
      "name": "Rock_Aqua_Brick"
    },
    {
      "x": -2,
      "y": 0,
      "z": 4,
      "name": "Rock_Aqua_Brick"
    },
    {
      "x": -2,
      "y": 8,
      "z": 4,
      "name": "Rock_Aqua_Brick"
    },
    {
      "x": -2,
      "y": 9,
      "z": 4,
      "name": "Rock_Aqua_Brick"
    },
    {
      "x": -2,
      "y": 0,
      "z": 5,
      "name": "Rock_Aqua_Brick"
    },
    {
      "x": -2,
      "y": 8,
      "z": 5,
      "name": "Rock_Aqua_Brick"
    },
    {
      "x": -2,
      "y": 9,
      "z": 5,
      "name": "Rock_Aqua_Brick"
    },
    {
      "x": -2,
      "y": 0,
      "z": 6,
      "name": "Rock_Aqua_Brick"
    },
    {
      "x": -2,
      "y": 8,
      "z": 6,
      "name": "Rock_Aqua_Brick"
    },
    {
      "x": -2,
      "y": 9,
      "z": 6,
      "name": "Rock_Aqua_Brick"
    },
    {
      "x": -2,
      "y": 0,
      "z": 7,
      "name": "Rock_Aqua_Brick"
    },
    {
      "x": -2,
      "y": 8,
      "z": 7,
      "name": "Rock_Aqua_Brick"
    },
    {
      "x": -2,
      "y": 9,
      "z": 7,
      "name": "Rock_Aqua_Brick"
    },
    {
      "x": -2,
      "y": 0,
      "z": 8,
      "name": "Rock_Aqua_Brick"
    },
    {
      "x": -2,
      "y": 8,
      "z": 8,
      "name": "Rock_Aqua_Brick"
    },
    {
      "x": -2,
      "y": 9,
      "z": 8,
      "name": "Rock_Aqua_Brick"
    },
    {
      "x": -2,
      "y": 0,
      "z": 9,
      "name": "Rock_Aqua_Brick_Smooth"
    },
    {
      "x": -2,
      "y": 8,
      "z": 9,
      "name": "Rock_Aqua_Brick_Smooth"
    },
    {
      "x": -2,
      "y": 9,
      "z": 9,
      "name": "Rock_Aqua_Brick_Smooth"
    },
    {
      "x": -2,
      "y": 0,
      "z": 10,
      "name": "Rock_Aqua_Brick_Smooth"
    },
    {
      "x": -2,
      "y": 1,
      "z": 10,
      "name": "Rock_Aqua_Brick_Smooth"
    },
    {
      "x": -2,
      "y": 2,
      "z": 10,
      "name": "Rock_Aqua_Brick_Smooth"
    },
    {
      "x": -2,
      "y": 3,
      "z": 10,
      "name": "Rock_Aqua_Brick_Smooth"
    },
    {
      "x": -2,
      "y": 4,
      "z": 10,
      "name": "Rock_Aqua_Brick_Smooth"
    },
    {
      "x": -2,
      "y": 5,
      "z": 10,
      "name": "Rock_Aqua_Brick_Smooth"
    },
    {
      "x": -2,
      "y": 6,
      "z": 10,
      "name": "Rock_Aqua_Brick_Smooth"
    },
    {
      "x": -2,
      "y": 7,
      "z": 10,
      "name": "Rock_Aqua_Brick_Smooth"
    },
    {
      "x": -2,
      "y": 8,
      "z": 10,
      "name": "Rock_Aqua_Brick_Smooth"
    },
    {
      "x": -2,
      "y": 9,
      "z": 10,
      "name": "Rock_Aqua_Brick_Smooth"
    },
    {
      "x": -2,
      "y": 10,
      "z": 10,
      "name": "Rock_Aqua_Brick_Smooth"
    },
    {
      "x": -2,
      "y": 11,
      "z": 10,
      "name": "Rock_Aqua_Brick_Smooth"
    },
    {
      "x": -2,
      "y": 12,
      "z": 10,
      "name": "Rock_Aqua_Brick_Smooth"
    },
    {
      "x": -2,
      "y": 13,
      "z": 10,
      "name": "Rock_Aqua_Brick_Smooth"
    },
    {
      "x": -2,
      "y": 14,
      "z": 10,
      "name": "Rock_Aqua_Brick_Smooth"
    },
    {
      "x": -2,
      "y": 15,
      "z": 10,
      "name": "Rock_Aqua_Brick_Smooth"
    },
    {
      "x": -2,
      "y": 16,
      "z": 10,
      "name": "Rock_Aqua_Brick_Smooth"
    },
    {
      "x": -1,
      "y": 0,
      "z": -10,
      "name": "Rock_Aqua_Brick_Smooth"
    },
    {
      "x": -1,
      "y": 1,
      "z": -10,
      "name": "Rock_Aqua_Brick_Smooth"
    },
    {
      "x": -1,
      "y": 2,
      "z": -10,
      "name": "Rock_Aqua_Brick_Smooth"
    },
    {
      "x": -1,
      "y": 3,
      "z": -10,
      "name": "Rock_Aqua_Brick_Smooth"
    },
    {
      "x": -1,
      "y": 4,
      "z": -10,
      "name": "Rock_Aqua_Brick_Smooth"
    },
    {
      "x": -1,
      "y": 5,
      "z": -10,
      "name": "Rock_Aqua_Brick_Smooth"
    },
    {
      "x": -1,
      "y": 6,
      "z": -10,
      "name": "Rock_Aqua_Brick_Smooth"
    },
    {
      "x": -1,
      "y": 7,
      "z": -10,
      "name": "Rock_Aqua_Brick_Smooth"
    },
    {
      "x": -1,
      "y": 8,
      "z": -10,
      "name": "Rock_Aqua_Brick_Smooth"
    },
    {
      "x": -1,
      "y": 9,
      "z": -10,
      "name": "Rock_Aqua_Brick_Smooth"
    },
    {
      "x": -1,
      "y": 12,
      "z": -10,
      "name": "Rock_Aqua_Brick_Smooth_Half",
      "rotation": 5
    },
    {
      "x": -1,
      "y": 13,
      "z": -10,
      "name": "Rock_Aqua_Brick_Smooth"
    },
    {
      "x": -1,
      "y": 14,
      "z": -10,
      "name": "Rock_Aqua_Brick_Smooth"
    },
    {
      "x": -1,
      "y": 15,
      "z": -10,
      "name": "Rock_Aqua_Brick_Smooth"
    },
    {
      "x": -1,
      "y": 16,
      "z": -10,
      "name": "Rock_Aqua_Brick_Smooth"
    },
    {
      "x": -1,
      "y": 0,
      "z": -9,
      "name": "Rock_Aqua_Brick"
    },
    {
      "x": -1,
      "y": 8,
      "z": -9,
      "name": "Rock_Aqua_Brick"
    },
    {
      "x": -1,
      "y": 9,
      "z": -9,
      "name": "Rock_Aqua_Brick"
    },
    {
      "x": -1,
      "y": 0,
      "z": -8,
      "name": "Rock_Aqua_Brick"
    },
    {
      "x": -1,
      "y": 8,
      "z": -8,
      "name": "Rock_Aqua_Brick"
    },
    {
      "x": -1,
      "y": 9,
      "z": -8,
      "name": "Rock_Aqua_Brick"
    },
    {
      "x": -1,
      "y": 0,
      "z": -7,
      "name": "Rock_Aqua_Brick"
    },
    {
      "x": -1,
      "y": 8,
      "z": -7,
      "name": "Rock_Aqua_Brick"
    },
    {
      "x": -1,
      "y": 9,
      "z": -7,
      "name": "Rock_Aqua_Brick"
    },
    {
      "x": -1,
      "y": 0,
      "z": -6,
      "name": "Rock_Aqua_Brick"
    },
    {
      "x": -1,
      "y": 8,
      "z": -6,
      "name": "Rock_Aqua_Brick"
    },
    {
      "x": -1,
      "y": 9,
      "z": -6,
      "name": "Rock_Aqua_Brick"
    },
    {
      "x": -1,
      "y": 0,
      "z": -5,
      "name": "Rock_Aqua_Brick"
    },
    {
      "x": -1,
      "y": 8,
      "z": -5,
      "name": "Rock_Aqua_Brick"
    },
    {
      "x": -1,
      "y": 9,
      "z": -5,
      "name": "Rock_Aqua_Brick"
    },
    {
      "x": -1,
      "y": 0,
      "z": -4,
      "name": "Rock_Aqua_Brick"
    },
    {
      "x": -1,
      "y": 0,
      "z": -3,
      "name": "Rock_Aqua_Brick"
    },
    {
      "x": -1,
      "y": 0,
      "z": -2,
      "name": "Rock_Aqua_Brick"
    },
    {
      "x": -1,
      "y": 0,
      "z": -1,
      "name": "Rock_Aqua_Brick"
    },
    {
      "x": -1,
      "y": 0,
      "z": 0,
      "name": "Rock_Aqua_Brick"
    },
    {
      "x": -1,
      "y": 0,
      "z": 1,
      "name": "Rock_Aqua_Brick"
    },
    {
      "x": -1,
      "y": 0,
      "z": 2,
      "name": "Rock_Aqua_Brick"
    },
    {
      "x": -1,
      "y": 0,
      "z": 3,
      "name": "Rock_Aqua_Brick"
    },
    {
      "x": -1,
      "y": 0,
      "z": 4,
      "name": "Rock_Aqua_Brick"
    },
    {
      "x": -1,
      "y": 0,
      "z": 5,
      "name": "Rock_Aqua_Brick"
    },
    {
      "x": -1,
      "y": 8,
      "z": 5,
      "name": "Rock_Aqua_Brick"
    },
    {
      "x": -1,
      "y": 9,
      "z": 5,
      "name": "Rock_Aqua_Brick"
    },
    {
      "x": -1,
      "y": 0,
      "z": 6,
      "name": "Rock_Aqua_Brick"
    },
    {
      "x": -1,
      "y": 8,
      "z": 6,
      "name": "Rock_Aqua_Brick"
    },
    {
      "x": -1,
      "y": 9,
      "z": 6,
      "name": "Rock_Aqua_Brick"
    },
    {
      "x": -1,
      "y": 0,
      "z": 7,
      "name": "Rock_Aqua_Brick"
    },
    {
      "x": -1,
      "y": 8,
      "z": 7,
      "name": "Rock_Aqua_Brick"
    },
    {
      "x": -1,
      "y": 9,
      "z": 7,
      "name": "Rock_Aqua_Brick"
    },
    {
      "x": -1,
      "y": 0,
      "z": 8,
      "name": "Rock_Aqua_Brick"
    },
    {
      "x": -1,
      "y": 8,
      "z": 8,
      "name": "Rock_Aqua_Brick"
    },
    {
      "x": -1,
      "y": 9,
      "z": 8,
      "name": "Rock_Aqua_Brick"
    },
    {
      "x": -1,
      "y": 0,
      "z": 9,
      "name": "Rock_Aqua_Brick_Smooth"
    },
    {
      "x": -1,
      "y": 8,
      "z": 9,
      "name": "Rock_Aqua_Brick_Smooth"
    },
    {
      "x": -1,
      "y": 9,
      "z": 9,
      "name": "Rock_Aqua_Brick_Smooth"
    },
    {
      "x": -1,
      "y": 0,
      "z": 10,
      "name": "Rock_Aqua_Brick_Smooth"
    },
    {
      "x": -1,
      "y": 1,
      "z": 10,
      "name": "Rock_Aqua_Brick_Smooth"
    },
    {
      "x": -1,
      "y": 2,
      "z": 10,
      "name": "Rock_Aqua_Brick_Smooth"
    },
    {
      "x": -1,
      "y": 3,
      "z": 10,
      "name": "Rock_Aqua_Brick_Smooth"
    },
    {
      "x": -1,
      "y": 4,
      "z": 10,
      "name": "Rock_Aqua_Brick_Smooth"
    },
    {
      "x": -1,
      "y": 5,
      "z": 10,
      "name": "Rock_Aqua_Brick_Smooth"
    },
    {
      "x": -1,
      "y": 6,
      "z": 10,
      "name": "Rock_Aqua_Brick_Smooth"
    },
    {
      "x": -1,
      "y": 7,
      "z": 10,
      "name": "Rock_Aqua_Brick_Smooth"
    },
    {
      "x": -1,
      "y": 8,
      "z": 10,
      "name": "Rock_Aqua_Brick_Smooth"
    },
    {
      "x": -1,
      "y": 9,
      "z": 10,
      "name": "Rock_Aqua_Brick_Smooth"
    },
    {
      "x": -1,
      "y": 12,
      "z": 10,
      "name": "Rock_Aqua_Brick_Smooth_Half",
      "rotation": 5
    },
    {
      "x": -1,
      "y": 13,
      "z": 10,
      "name": "Rock_Aqua_Brick_Smooth"
    },
    {
      "x": -1,
      "y": 14,
      "z": 10,
      "name": "Rock_Aqua_Brick_Smooth"
    },
    {
      "x": -1,
      "y": 15,
      "z": 10,
      "name": "Rock_Aqua_Brick_Smooth"
    },
    {
      "x": -1,
      "y": 16,
      "z": 10,
      "name": "Rock_Aqua_Brick_Smooth"
    },
    {
      "x": 0,
      "y": 0,
      "z": -10,
      "name": "Rock_Aqua_Brick_Smooth"
    },
    {
      "x": 0,
      "y": 1,
      "z": -10,
      "name": "Rock_Aqua_Brick_Smooth"
    },
    {
      "x": 0,
      "y": 2,
      "z": -10,
      "name": "Rock_Aqua_Brick_Smooth"
    },
    {
      "x": 0,
      "y": 3,
      "z": -10,
      "name": "Rock_Aqua_Brick_Smooth"
    },
    {
      "x": 0,
      "y": 4,
      "z": -10,
      "name": "Rock_Aqua_Brick_Smooth"
    },
    {
      "x": 0,
      "y": 5,
      "z": -10,
      "name": "Rock_Aqua_Brick_Smooth"
    },
    {
      "x": 0,
      "y": 6,
      "z": -10,
      "name": "Rock_Aqua_Brick_Smooth"
    },
    {
      "x": 0,
      "y": 7,
      "z": -10,
      "name": "Rock_Aqua_Brick_Smooth"
    },
    {
      "x": 0,
      "y": 8,
      "z": -10,
      "name": "Rock_Aqua_Brick_Smooth"
    },
    {
      "x": 0,
      "y": 9,
      "z": -10,
      "name": "Rock_Aqua_Brick_Smooth"
    },
    {
      "x": 0,
      "y": 13,
      "z": -10,
      "name": "Rock_Aqua_Brick_Smooth_Half",
      "rotation": 8
    },
    {
      "x": 0,
      "y": 14,
      "z": -10,
      "name": "Rock_Aqua_Brick_Smooth"
    },
    {
      "x": 0,
      "y": 15,
      "z": -10,
      "name": "Rock_Aqua_Brick_Smooth"
    },
    {
      "x": 0,
      "y": 16,
      "z": -10,
      "name": "Rock_Aqua_Brick_Smooth"
    },
    {
      "x": 0,
      "y": 0,
      "z": -9,
      "name": "Rock_Aqua_Brick"
    },
    {
      "x": 0,
      "y": 8,
      "z": -9,
      "name": "Rock_Aqua_Brick"
    },
    {
      "x": 0,
      "y": 9,
      "z": -9,
      "name": "Rock_Aqua_Brick"
    },
    {
      "x": 0,
      "y": 0,
      "z": -8,
      "name": "Rock_Aqua_Brick"
    },
    {
      "x": 0,
      "y": 8,
      "z": -8,
      "name": "Rock_Aqua_Brick"
    },
    {
      "x": 0,
      "y": 9,
      "z": -8,
      "name": "Rock_Aqua_Brick"
    },
    {
      "x": 0,
      "y": 0,
      "z": -7,
      "name": "Rock_Aqua_Brick"
    },
    {
      "x": 0,
      "y": 8,
      "z": -7,
      "name": "Rock_Aqua_Brick"
    },
    {
      "x": 0,
      "y": 9,
      "z": -7,
      "name": "Rock_Aqua_Brick"
    },
    {
      "x": 0,
      "y": 0,
      "z": -6,
      "name": "Rock_Aqua_Brick"
    },
    {
      "x": 0,
      "y": 8,
      "z": -6,
      "name": "Rock_Aqua_Brick"
    },
    {
      "x": 0,
      "y": 9,
      "z": -6,
      "name": "Rock_Aqua_Brick"
    },
    {
      "x": 0,
      "y": 0,
      "z": -5,
      "name": "Rock_Aqua_Brick"
    },
    {
      "x": 0,
      "y": 8,
      "z": -5,
      "name": "Rock_Aqua_Brick"
    },
    {
      "x": 0,
      "y": 9,
      "z": -5,
      "name": "Rock_Aqua_Brick"
    },
    {
      "x": 0,
      "y": 0,
      "z": -4,
      "name": "Rock_Aqua_Brick"
    },
    {
      "x": 0,
      "y": 0,
      "z": -3,
      "name": "Rock_Aqua_Brick"
    },
    {
      "x": 0,
      "y": 0,
      "z": -2,
      "name": "Rock_Aqua_Brick"
    },
    {
      "x": 0,
      "y": 0,
      "z": -1,
      "name": "Rock_Aqua_Brick"
    },
    {
      "x": 0,
      "y": 0,
      "z": 0,
      "name": "Rock_Aqua_Brick"
    },
    {
      "x": 0,
      "y": 0,
      "z": 1,
      "name": "Rock_Aqua_Brick"
    },
    {
      "x": 0,
      "y": 0,
      "z": 2,
      "name": "Rock_Aqua_Brick"
    },
    {
      "x": 0,
      "y": 0,
      "z": 3,
      "name": "Rock_Aqua_Brick"
    },
    {
      "x": 0,
      "y": 0,
      "z": 4,
      "name": "Rock_Aqua_Brick"
    },
    {
      "x": 0,
      "y": 0,
      "z": 5,
      "name": "Rock_Aqua_Brick"
    },
    {
      "x": 0,
      "y": 8,
      "z": 5,
      "name": "Rock_Aqua_Brick"
    },
    {
      "x": 0,
      "y": 9,
      "z": 5,
      "name": "Rock_Aqua_Brick"
    },
    {
      "x": 0,
      "y": 0,
      "z": 6,
      "name": "Rock_Aqua_Brick"
    },
    {
      "x": 0,
      "y": 8,
      "z": 6,
      "name": "Rock_Aqua_Brick"
    },
    {
      "x": 0,
      "y": 9,
      "z": 6,
      "name": "Rock_Aqua_Brick"
    },
    {
      "x": 0,
      "y": 0,
      "z": 7,
      "name": "Rock_Aqua_Brick"
    },
    {
      "x": 0,
      "y": 8,
      "z": 7,
      "name": "Rock_Aqua_Brick"
    },
    {
      "x": 0,
      "y": 9,
      "z": 7,
      "name": "Rock_Aqua_Brick"
    },
    {
      "x": 0,
      "y": 0,
      "z": 8,
      "name": "Rock_Aqua_Brick"
    },
    {
      "x": 0,
      "y": 8,
      "z": 8,
      "name": "Rock_Aqua_Brick"
    },
    {
      "x": 0,
      "y": 9,
      "z": 8,
      "name": "Rock_Aqua_Brick"
    },
    {
      "x": 0,
      "y": 0,
      "z": 9,
      "name": "Rock_Aqua_Brick_Smooth"
    },
    {
      "x": 0,
      "y": 8,
      "z": 9,
      "name": "Rock_Aqua_Brick_Smooth"
    },
    {
      "x": 0,
      "y": 9,
      "z": 9,
      "name": "Rock_Aqua_Brick_Smooth"
    },
    {
      "x": 0,
      "y": 0,
      "z": 10,
      "name": "Rock_Aqua_Brick_Smooth"
    },
    {
      "x": 0,
      "y": 1,
      "z": 10,
      "name": "Rock_Aqua_Brick_Smooth"
    },
    {
      "x": 0,
      "y": 2,
      "z": 10,
      "name": "Rock_Aqua_Brick_Smooth"
    },
    {
      "x": 0,
      "y": 3,
      "z": 10,
      "name": "Rock_Aqua_Brick_Smooth"
    },
    {
      "x": 0,
      "y": 4,
      "z": 10,
      "name": "Rock_Aqua_Brick_Smooth"
    },
    {
      "x": 0,
      "y": 5,
      "z": 10,
      "name": "Rock_Aqua_Brick_Smooth"
    },
    {
      "x": 0,
      "y": 6,
      "z": 10,
      "name": "Rock_Aqua_Brick_Smooth"
    },
    {
      "x": 0,
      "y": 7,
      "z": 10,
      "name": "Rock_Aqua_Brick_Smooth"
    },
    {
      "x": 0,
      "y": 8,
      "z": 10,
      "name": "Rock_Aqua_Brick_Smooth"
    },
    {
      "x": 0,
      "y": 9,
      "z": 10,
      "name": "Rock_Aqua_Brick_Smooth"
    },
    {
      "x": 0,
      "y": 13,
      "z": 10,
      "name": "Rock_Aqua_Brick_Smooth_Half",
      "rotation": 8
    },
    {
      "x": 0,
      "y": 14,
      "z": 10,
      "name": "Rock_Aqua_Brick_Smooth"
    },
    {
      "x": 0,
      "y": 15,
      "z": 10,
      "name": "Rock_Aqua_Brick_Smooth"
    },
    {
      "x": 0,
      "y": 16,
      "z": 10,
      "name": "Rock_Aqua_Brick_Smooth"
    },
    {
      "x": 1,
      "y": 0,
      "z": -10,
      "name": "Rock_Aqua_Brick_Smooth"
    },
    {
      "x": 1,
      "y": 1,
      "z": -10,
      "name": "Rock_Aqua_Brick_Smooth"
    },
    {
      "x": 1,
      "y": 2,
      "z": -10,
      "name": "Rock_Aqua_Brick_Smooth"
    },
    {
      "x": 1,
      "y": 3,
      "z": -10,
      "name": "Rock_Aqua_Brick_Smooth"
    },
    {
      "x": 1,
      "y": 4,
      "z": -10,
      "name": "Rock_Aqua_Brick_Smooth"
    },
    {
      "x": 1,
      "y": 5,
      "z": -10,
      "name": "Rock_Aqua_Brick_Smooth"
    },
    {
      "x": 1,
      "y": 6,
      "z": -10,
      "name": "Rock_Aqua_Brick_Smooth"
    },
    {
      "x": 1,
      "y": 7,
      "z": -10,
      "name": "Rock_Aqua_Brick_Smooth"
    },
    {
      "x": 1,
      "y": 8,
      "z": -10,
      "name": "Rock_Aqua_Brick_Smooth"
    },
    {
      "x": 1,
      "y": 9,
      "z": -10,
      "name": "Rock_Aqua_Brick_Smooth"
    },
    {
      "x": 1,
      "y": 12,
      "z": -10,
      "name": "Rock_Aqua_Brick_Smooth_Half",
      "rotation": 7
    },
    {
      "x": 1,
      "y": 13,
      "z": -10,
      "name": "Rock_Aqua_Brick_Smooth"
    },
    {
      "x": 1,
      "y": 14,
      "z": -10,
      "name": "Rock_Aqua_Brick_Smooth"
    },
    {
      "x": 1,
      "y": 15,
      "z": -10,
      "name": "Rock_Aqua_Brick_Smooth"
    },
    {
      "x": 1,
      "y": 16,
      "z": -10,
      "name": "Rock_Aqua_Brick_Smooth"
    },
    {
      "x": 1,
      "y": 0,
      "z": -9,
      "name": "Rock_Aqua_Brick"
    },
    {
      "x": 1,
      "y": 8,
      "z": -9,
      "name": "Rock_Aqua_Brick"
    },
    {
      "x": 1,
      "y": 9,
      "z": -9,
      "name": "Rock_Aqua_Brick"
    },
    {
      "x": 1,
      "y": 0,
      "z": -8,
      "name": "Rock_Aqua_Brick"
    },
    {
      "x": 1,
      "y": 8,
      "z": -8,
      "name": "Rock_Aqua_Brick"
    },
    {
      "x": 1,
      "y": 9,
      "z": -8,
      "name": "Rock_Aqua_Brick"
    },
    {
      "x": 1,
      "y": 0,
      "z": -7,
      "name": "Rock_Aqua_Brick"
    },
    {
      "x": 1,
      "y": 8,
      "z": -7,
      "name": "Rock_Aqua_Brick"
    },
    {
      "x": 1,
      "y": 9,
      "z": -7,
      "name": "Rock_Aqua_Brick"
    },
    {
      "x": 1,
      "y": 0,
      "z": -6,
      "name": "Rock_Aqua_Brick"
    },
    {
      "x": 1,
      "y": 8,
      "z": -6,
      "name": "Rock_Aqua_Brick"
    },
    {
      "x": 1,
      "y": 9,
      "z": -6,
      "name": "Rock_Aqua_Brick"
    },
    {
      "x": 1,
      "y": 0,
      "z": -5,
      "name": "Rock_Aqua_Brick"
    },
    {
      "x": 1,
      "y": 8,
      "z": -5,
      "name": "Rock_Aqua_Brick"
    },
    {
      "x": 1,
      "y": 9,
      "z": -5,
      "name": "Rock_Aqua_Brick"
    },
    {
      "x": 1,
      "y": 0,
      "z": -4,
      "name": "Rock_Aqua_Brick"
    },
    {
      "x": 1,
      "y": 0,
      "z": -3,
      "name": "Rock_Aqua_Brick"
    },
    {
      "x": 1,
      "y": 0,
      "z": -2,
      "name": "Rock_Aqua_Brick"
    },
    {
      "x": 1,
      "y": 0,
      "z": -1,
      "name": "Rock_Aqua_Brick"
    },
    {
      "x": 1,
      "y": 0,
      "z": 0,
      "name": "Rock_Aqua_Brick"
    },
    {
      "x": 1,
      "y": 0,
      "z": 1,
      "name": "Rock_Aqua_Brick"
    },
    {
      "x": 1,
      "y": 0,
      "z": 2,
      "name": "Rock_Aqua_Brick"
    },
    {
      "x": 1,
      "y": 0,
      "z": 3,
      "name": "Rock_Aqua_Brick"
    },
    {
      "x": 1,
      "y": 0,
      "z": 4,
      "name": "Rock_Aqua_Brick"
    },
    {
      "x": 1,
      "y": 0,
      "z": 5,
      "name": "Rock_Aqua_Brick"
    },
    {
      "x": 1,
      "y": 8,
      "z": 5,
      "name": "Rock_Aqua_Brick"
    },
    {
      "x": 1,
      "y": 9,
      "z": 5,
      "name": "Rock_Aqua_Brick"
    },
    {
      "x": 1,
      "y": 0,
      "z": 6,
      "name": "Rock_Aqua_Brick"
    },
    {
      "x": 1,
      "y": 8,
      "z": 6,
      "name": "Rock_Aqua_Brick"
    },
    {
      "x": 1,
      "y": 9,
      "z": 6,
      "name": "Rock_Aqua_Brick"
    },
    {
      "x": 1,
      "y": 0,
      "z": 7,
      "name": "Rock_Aqua_Brick"
    },
    {
      "x": 1,
      "y": 8,
      "z": 7,
      "name": "Rock_Aqua_Brick"
    },
    {
      "x": 1,
      "y": 9,
      "z": 7,
      "name": "Rock_Aqua_Brick"
    },
    {
      "x": 1,
      "y": 0,
      "z": 8,
      "name": "Rock_Aqua_Brick"
    },
    {
      "x": 1,
      "y": 8,
      "z": 8,
      "name": "Rock_Aqua_Brick"
    },
    {
      "x": 1,
      "y": 9,
      "z": 8,
      "name": "Rock_Aqua_Brick"
    },
    {
      "x": 1,
      "y": 0,
      "z": 9,
      "name": "Rock_Aqua_Brick_Smooth"
    },
    {
      "x": 1,
      "y": 8,
      "z": 9,
      "name": "Rock_Aqua_Brick_Smooth"
    },
    {
      "x": 1,
      "y": 9,
      "z": 9,
      "name": "Rock_Aqua_Brick_Smooth"
    },
    {
      "x": 1,
      "y": 0,
      "z": 10,
      "name": "Rock_Aqua_Brick_Smooth"
    },
    {
      "x": 1,
      "y": 1,
      "z": 10,
      "name": "Rock_Aqua_Brick_Smooth"
    },
    {
      "x": 1,
      "y": 2,
      "z": 10,
      "name": "Rock_Aqua_Brick_Smooth"
    },
    {
      "x": 1,
      "y": 3,
      "z": 10,
      "name": "Rock_Aqua_Brick_Smooth"
    },
    {
      "x": 1,
      "y": 4,
      "z": 10,
      "name": "Rock_Aqua_Brick_Smooth"
    },
    {
      "x": 1,
      "y": 5,
      "z": 10,
      "name": "Rock_Aqua_Brick_Smooth"
    },
    {
      "x": 1,
      "y": 6,
      "z": 10,
      "name": "Rock_Aqua_Brick_Smooth"
    },
    {
      "x": 1,
      "y": 7,
      "z": 10,
      "name": "Rock_Aqua_Brick_Smooth"
    },
    {
      "x": 1,
      "y": 8,
      "z": 10,
      "name": "Rock_Aqua_Brick_Smooth"
    },
    {
      "x": 1,
      "y": 9,
      "z": 10,
      "name": "Rock_Aqua_Brick_Smooth"
    },
    {
      "x": 1,
      "y": 12,
      "z": 10,
      "name": "Rock_Aqua_Brick_Smooth_Half",
      "rotation": 7
    },
    {
      "x": 1,
      "y": 13,
      "z": 10,
      "name": "Rock_Aqua_Brick_Smooth"
    },
    {
      "x": 1,
      "y": 14,
      "z": 10,
      "name": "Rock_Aqua_Brick_Smooth"
    },
    {
      "x": 1,
      "y": 15,
      "z": 10,
      "name": "Rock_Aqua_Brick_Smooth"
    },
    {
      "x": 1,
      "y": 16,
      "z": 10,
      "name": "Rock_Aqua_Brick_Smooth"
    },
    {
      "x": 2,
      "y": 0,
      "z": -10,
      "name": "Rock_Aqua_Brick_Smooth"
    },
    {
      "x": 2,
      "y": 1,
      "z": -10,
      "name": "Rock_Aqua_Brick_Smooth"
    },
    {
      "x": 2,
      "y": 2,
      "z": -10,
      "name": "Rock_Aqua_Brick_Smooth"
    },
    {
      "x": 2,
      "y": 3,
      "z": -10,
      "name": "Rock_Aqua_Brick_Smooth"
    },
    {
      "x": 2,
      "y": 4,
      "z": -10,
      "name": "Rock_Aqua_Brick_Smooth"
    },
    {
      "x": 2,
      "y": 5,
      "z": -10,
      "name": "Rock_Aqua_Brick_Smooth"
    },
    {
      "x": 2,
      "y": 6,
      "z": -10,
      "name": "Rock_Aqua_Brick_Smooth"
    },
    {
      "x": 2,
      "y": 7,
      "z": -10,
      "name": "Rock_Aqua_Brick_Smooth"
    },
    {
      "x": 2,
      "y": 8,
      "z": -10,
      "name": "Rock_Aqua_Brick_Smooth"
    },
    {
      "x": 2,
      "y": 9,
      "z": -10,
      "name": "Rock_Aqua_Brick_Smooth"
    },
    {
      "x": 2,
      "y": 10,
      "z": -10,
      "name": "Rock_Aqua_Brick_Smooth"
    },
    {
      "x": 2,
      "y": 11,
      "z": -10,
      "name": "Rock_Aqua_Brick_Smooth"
    },
    {
      "x": 2,
      "y": 12,
      "z": -10,
      "name": "Rock_Aqua_Brick_Smooth"
    },
    {
      "x": 2,
      "y": 13,
      "z": -10,
      "name": "Rock_Aqua_Brick_Smooth"
    },
    {
      "x": 2,
      "y": 14,
      "z": -10,
      "name": "Rock_Aqua_Brick_Smooth"
    },
    {
      "x": 2,
      "y": 15,
      "z": -10,
      "name": "Rock_Aqua_Brick_Smooth"
    },
    {
      "x": 2,
      "y": 16,
      "z": -10,
      "name": "Rock_Aqua_Brick_Smooth"
    },
    {
      "x": 2,
      "y": 0,
      "z": -9,
      "name": "Rock_Aqua_Brick"
    },
    {
      "x": 2,
      "y": 8,
      "z": -9,
      "name": "Rock_Aqua_Brick"
    },
    {
      "x": 2,
      "y": 9,
      "z": -9,
      "name": "Rock_Aqua_Brick"
    },
    {
      "x": 2,
      "y": 0,
      "z": -8,
      "name": "Rock_Aqua_Brick"
    },
    {
      "x": 2,
      "y": 8,
      "z": -8,
      "name": "Rock_Aqua_Brick"
    },
    {
      "x": 2,
      "y": 9,
      "z": -8,
      "name": "Rock_Aqua_Brick"
    },
    {
      "x": 2,
      "y": 0,
      "z": -7,
      "name": "Rock_Aqua_Brick"
    },
    {
      "x": 2,
      "y": 8,
      "z": -7,
      "name": "Rock_Aqua_Brick"
    },
    {
      "x": 2,
      "y": 9,
      "z": -7,
      "name": "Rock_Aqua_Brick"
    },
    {
      "x": 2,
      "y": 0,
      "z": -6,
      "name": "Rock_Aqua_Brick"
    },
    {
      "x": 2,
      "y": 8,
      "z": -6,
      "name": "Rock_Aqua_Brick"
    },
    {
      "x": 2,
      "y": 9,
      "z": -6,
      "name": "Rock_Aqua_Brick"
    },
    {
      "x": 2,
      "y": 0,
      "z": -5,
      "name": "Rock_Aqua_Brick"
    },
    {
      "x": 2,
      "y": 8,
      "z": -5,
      "name": "Rock_Aqua_Brick"
    },
    {
      "x": 2,
      "y": 9,
      "z": -5,
      "name": "Rock_Aqua_Brick"
    },
    {
      "x": 2,
      "y": 0,
      "z": -4,
      "name": "Rock_Aqua_Brick"
    },
    {
      "x": 2,
      "y": 8,
      "z": -4,
      "name": "Rock_Aqua_Brick"
    },
    {
      "x": 2,
      "y": 9,
      "z": -4,
      "name": "Rock_Aqua_Brick"
    },
    {
      "x": 2,
      "y": 0,
      "z": -3,
      "name": "Rock_Aqua_Brick"
    },
    {
      "x": 2,
      "y": 0,
      "z": -2,
      "name": "Rock_Aqua_Brick"
    },
    {
      "x": 2,
      "y": 0,
      "z": -1,
      "name": "Rock_Aqua_Brick"
    },
    {
      "x": 2,
      "y": 0,
      "z": 0,
      "name": "Rock_Aqua_Brick"
    },
    {
      "x": 2,
      "y": 0,
      "z": 1,
      "name": "Rock_Aqua_Brick"
    },
    {
      "x": 2,
      "y": 0,
      "z": 2,
      "name": "Rock_Aqua_Brick"
    },
    {
      "x": 2,
      "y": 0,
      "z": 3,
      "name": "Rock_Aqua_Brick"
    },
    {
      "x": 2,
      "y": 0,
      "z": 4,
      "name": "Rock_Aqua_Brick"
    },
    {
      "x": 2,
      "y": 8,
      "z": 4,
      "name": "Rock_Aqua_Brick"
    },
    {
      "x": 2,
      "y": 9,
      "z": 4,
      "name": "Rock_Aqua_Brick"
    },
    {
      "x": 2,
      "y": 0,
      "z": 5,
      "name": "Rock_Aqua_Brick"
    },
    {
      "x": 2,
      "y": 8,
      "z": 5,
      "name": "Rock_Aqua_Brick"
    },
    {
      "x": 2,
      "y": 9,
      "z": 5,
      "name": "Rock_Aqua_Brick"
    },
    {
      "x": 2,
      "y": 0,
      "z": 6,
      "name": "Rock_Aqua_Brick"
    },
    {
      "x": 2,
      "y": 8,
      "z": 6,
      "name": "Rock_Aqua_Brick"
    },
    {
      "x": 2,
      "y": 9,
      "z": 6,
      "name": "Rock_Aqua_Brick"
    },
    {
      "x": 2,
      "y": 0,
      "z": 7,
      "name": "Rock_Aqua_Brick"
    },
    {
      "x": 2,
      "y": 8,
      "z": 7,
      "name": "Rock_Aqua_Brick"
    },
    {
      "x": 2,
      "y": 9,
      "z": 7,
      "name": "Rock_Aqua_Brick"
    },
    {
      "x": 2,
      "y": 0,
      "z": 8,
      "name": "Rock_Aqua_Brick"
    },
    {
      "x": 2,
      "y": 8,
      "z": 8,
      "name": "Rock_Aqua_Brick"
    },
    {
      "x": 2,
      "y": 9,
      "z": 8,
      "name": "Rock_Aqua_Brick"
    },
    {
      "x": 2,
      "y": 0,
      "z": 9,
      "name": "Rock_Aqua_Brick_Smooth"
    },
    {
      "x": 2,
      "y": 8,
      "z": 9,
      "name": "Rock_Aqua_Brick_Smooth"
    },
    {
      "x": 2,
      "y": 9,
      "z": 9,
      "name": "Rock_Aqua_Brick_Smooth"
    },
    {
      "x": 2,
      "y": 0,
      "z": 10,
      "name": "Rock_Aqua_Brick_Smooth"
    },
    {
      "x": 2,
      "y": 1,
      "z": 10,
      "name": "Rock_Aqua_Brick_Smooth"
    },
    {
      "x": 2,
      "y": 2,
      "z": 10,
      "name": "Rock_Aqua_Brick_Smooth"
    },
    {
      "x": 2,
      "y": 3,
      "z": 10,
      "name": "Rock_Aqua_Brick_Smooth"
    },
    {
      "x": 2,
      "y": 4,
      "z": 10,
      "name": "Rock_Aqua_Brick_Smooth"
    },
    {
      "x": 2,
      "y": 5,
      "z": 10,
      "name": "Rock_Aqua_Brick_Smooth"
    },
    {
      "x": 2,
      "y": 6,
      "z": 10,
      "name": "Rock_Aqua_Brick_Smooth"
    },
    {
      "x": 2,
      "y": 7,
      "z": 10,
      "name": "Rock_Aqua_Brick_Smooth"
    },
    {
      "x": 2,
      "y": 8,
      "z": 10,
      "name": "Rock_Aqua_Brick_Smooth"
    },
    {
      "x": 2,
      "y": 9,
      "z": 10,
      "name": "Rock_Aqua_Brick_Smooth"
    },
    {
      "x": 2,
      "y": 10,
      "z": 10,
      "name": "Rock_Aqua_Brick_Smooth"
    },
    {
      "x": 2,
      "y": 11,
      "z": 10,
      "name": "Rock_Aqua_Brick_Smooth"
    },
    {
      "x": 2,
      "y": 12,
      "z": 10,
      "name": "Rock_Aqua_Brick_Smooth"
    },
    {
      "x": 2,
      "y": 13,
      "z": 10,
      "name": "Rock_Aqua_Brick_Smooth"
    },
    {
      "x": 2,
      "y": 14,
      "z": 10,
      "name": "Rock_Aqua_Brick_Smooth"
    },
    {
      "x": 2,
      "y": 15,
      "z": 10,
      "name": "Rock_Aqua_Brick_Smooth"
    },
    {
      "x": 2,
      "y": 16,
      "z": 10,
      "name": "Rock_Aqua_Brick_Smooth"
    },
    {
      "x": 3,
      "y": 0,
      "z": -9,
      "name": "Rock_Aqua_Brick_Smooth"
    },
    {
      "x": 3,
      "y": 1,
      "z": -9,
      "name": "Rock_Aqua_Brick_Smooth"
    },
    {
      "x": 3,
      "y": 2,
      "z": -9,
      "name": "Rock_Aqua_Brick_Smooth"
    },
    {
      "x": 3,
      "y": 3,
      "z": -9,
      "name": "Rock_Aqua_Brick_Smooth"
    },
    {
      "x": 3,
      "y": 4,
      "z": -9,
      "name": "Rock_Aqua_Brick_Smooth"
    },
    {
      "x": 3,
      "y": 5,
      "z": -9,
      "name": "Rock_Aqua_Brick_Smooth"
    },
    {
      "x": 3,
      "y": 6,
      "z": -9,
      "name": "Rock_Aqua_Brick_Smooth"
    },
    {
      "x": 3,
      "y": 7,
      "z": -9,
      "name": "Rock_Aqua_Brick_Smooth"
    },
    {
      "x": 3,
      "y": 8,
      "z": -9,
      "name": "Rock_Aqua_Brick_Smooth"
    },
    {
      "x": 3,
      "y": 9,
      "z": -9,
      "name": "Rock_Aqua_Brick_Smooth"
    },
    {
      "x": 3,
      "y": 10,
      "z": -9,
      "name": "Rock_Aqua_Brick_Smooth"
    },
    {
      "x": 3,
      "y": 11,
      "z": -9,
      "name": "Rock_Aqua_Brick_Smooth"
    },
    {
      "x": 3,
      "y": 12,
      "z": -9,
      "name": "Rock_Aqua_Brick_Smooth"
    },
    {
      "x": 3,
      "y": 13,
      "z": -9,
      "name": "Rock_Aqua_Brick_Smooth"
    },
    {
      "x": 3,
      "y": 14,
      "z": -9,
      "name": "Rock_Aqua_Brick_Smooth"
    },
    {
      "x": 3,
      "y": 15,
      "z": -9,
      "name": "Rock_Aqua_Brick_Smooth"
    },
    {
      "x": 3,
      "y": 16,
      "z": -9,
      "name": "Rock_Aqua_Brick_Smooth"
    },
    {
      "x": 3,
      "y": 0,
      "z": -8,
      "name": "Rock_Aqua_Brick"
    },
    {
      "x": 3,
      "y": 8,
      "z": -8,
      "name": "Rock_Aqua_Brick"
    },
    {
      "x": 3,
      "y": 9,
      "z": -8,
      "name": "Rock_Aqua_Brick"
    },
    {
      "x": 3,
      "y": 0,
      "z": -7,
      "name": "Rock_Aqua_Brick"
    },
    {
      "x": 3,
      "y": 8,
      "z": -7,
      "name": "Rock_Aqua_Brick"
    },
    {
      "x": 3,
      "y": 9,
      "z": -7,
      "name": "Rock_Aqua_Brick"
    },
    {
      "x": 3,
      "y": 0,
      "z": -6,
      "name": "Rock_Aqua_Brick"
    },
    {
      "x": 3,
      "y": 8,
      "z": -6,
      "name": "Rock_Aqua_Brick"
    },
    {
      "x": 3,
      "y": 9,
      "z": -6,
      "name": "Rock_Aqua_Brick"
    },
    {
      "x": 3,
      "y": 0,
      "z": -5,
      "name": "Rock_Aqua_Brick"
    },
    {
      "x": 3,
      "y": 8,
      "z": -5,
      "name": "Rock_Aqua_Brick"
    },
    {
      "x": 3,
      "y": 9,
      "z": -5,
      "name": "Rock_Aqua_Brick"
    },
    {
      "x": 3,
      "y": 0,
      "z": -4,
      "name": "Rock_Aqua_Brick"
    },
    {
      "x": 3,
      "y": 8,
      "z": -4,
      "name": "Rock_Aqua_Brick"
    },
    {
      "x": 3,
      "y": 9,
      "z": -4,
      "name": "Rock_Aqua_Brick"
    },
    {
      "x": 3,
      "y": 0,
      "z": -3,
      "name": "Rock_Aqua_Brick"
    },
    {
      "x": 3,
      "y": 0,
      "z": -2,
      "name": "Rock_Aqua_Brick"
    },
    {
      "x": 3,
      "y": 0,
