{
  "version": 8,
  "blockIdVersion": 11,
  "anchorX": 0,
  "anchorY": 1,
  "anchorZ": 0,
  "blocks": [
    {
      "x": -11,
      "y": 16,
      "z": -3,
      "name": "*Rock_Aqua_Cobble_Roof_Hollow_State_Definitions_Corner_Left",
      "rotation": 2
    },
    {
      "x": -11,
      "y": 16,
      "z": -2,
      "name": "Rock_Aqua_Cobble_Roof_Hollow",
      "rotation": 3
    },
    {
      "x": -11,
      "y": 16,
      "z": -1,
      "name": "Rock_Aqua_Cobble_Roof_Hollow",
      "rotation": 3
    },
    {
      "x": -11,
      "y": 16,
      "z": 0,
      "name": "Rock_Aqua_Cobble_Roof_Hollow",
      "rotation": 3
    },
    {
      "x": -11,
      "y": 16,
      "z": 1,
      "name": "Rock_Aqua_Cobble_Roof_Hollow",
      "rotation": 3
    },
    {
      "x": -11,
      "y": 16,
      "z": 2,
      "name": "Rock_Aqua_Cobble_Roof_Hollow",
      "rotation": 3
    },
    {
      "x": -11,
      "y": 16,
      "z": 3,
      "name": "*Rock_Aqua_Cobble_Roof_Hollow_State_Definitions_Corner_Right"
    },
    {
      "x": -10,
      "y": 16,
      "z": -6,
      "name": "*Rock_Aqua_Cobble_Roof_Hollow_State_Definitions_Corner_Left",
      "rotation": 2
    },
    {
      "x": -10,
      "y": 16,
      "z": -5,
      "name": "Rock_Aqua_Cobble_Roof_Hollow",
      "rotation": 3
    },
    {
      "x": -10,
      "y": 16,
      "z": -4,
      "name": "Rock_Aqua_Cobble_Roof_Hollow",
      "rotation": 3
    },
    {
      "x": -10,
      "y": 16,
      "z": -3,
      "name": "*Rock_Aqua_Cobble_Roof_Hollow_State_Definitions_Inverted_Corner_Right",
      "rotation": 3
    },
    {
      "x": -10,
      "y": 0,
      "z": -2,
      "name": "Rock_Aqua_Brick_Smooth"
    },
    {
      "x": -10,
      "y": 1,
      "z": -2,
      "name": "Rock_Aqua_Brick_Smooth"
    },
    {
      "x": -10,
      "y": 2,
      "z": -2,
      "name": "Rock_Aqua_Brick_Smooth"
    },
    {
      "x": -10,
      "y": 3,
      "z": -2,
      "name": "Rock_Aqua_Brick_Smooth"
    },
    {
      "x": -10,
      "y": 4,
      "z": -2,
      "name": "Rock_Aqua_Brick_Smooth"
    },
    {
      "x": -10,
      "y": 5,
      "z": -2,
      "name": "Rock_Aqua_Brick_Smooth"
    },
    {
      "x": -10,
      "y": 6,
      "z": -2,
      "name": "Rock_Aqua_Brick_Smooth"
    },
    {
      "x": -10,
      "y": 7,
      "z": -2,
      "name": "Rock_Aqua_Brick_Smooth"
    },
    {
      "x": -10,
      "y": 8,
      "z": -2,
      "name": "Rock_Aqua_Brick_Smooth"
    },
    {
      "x": -10,
      "y": 9,
      "z": -2,
      "name": "Rock_Aqua_Brick_Smooth"
    },
    {
      "x": -10,
      "y": 10,
      "z": -2,
      "name": "Rock_Aqua_Brick_Smooth"
    },
    {
      "x": -10,
      "y": 11,
      "z": -2,
      "name": "Rock_Aqua_Brick_Smooth"
    },
    {
      "x": -10,
      "y": 12,
      "z": -2,
      "name": "Rock_Aqua_Brick_Smooth"
    },
    {
      "x": -10,
      "y": 13,
      "z": -2,
      "name": "Rock_Aqua_Brick_Smooth"
    },
    {
      "x": -10,
      "y": 14,
      "z": -2,
      "name": "Rock_Aqua_Brick_Smooth"
    },
    {
      "x": -10,
      "y": 15,
      "z": -2,
      "name": "Rock_Aqua_Brick_Smooth"
    },
    {
      "x": -10,
      "y": 16,
      "z": -2,
      "name": "Rock_Aqua_Brick_Smooth",
      "rotation": 3
    },
    {
      "x": -10,
      "y": 17,
      "z": -2,
      "name": "*Rock_Aqua_Cobble_Roof_State_Definitions_Corner_Right",
      "rotation": 3
    },
    {
      "x": -10,
      "y": 0,
      "z": -1,
      "name": "Rock_Aqua_Brick_Smooth"
    },
    {
      "x": -10,
      "y": 3,
      "z": -1,
      "name": "Rock_Aqua_Brick_Smooth_Half",
      "rotation": 4
    },
    {
      "x": -10,
      "y": 4,
      "z": -1,
      "name": "Rock_Aqua_Brick_Smooth"
    },
    {
      "x": -10,
      "y": 5,
      "z": -1,
      "name": "Rock_Aqua_Brick_Smooth"
    },
    {
      "x": -10,
      "y": 6,
      "z": -1,
      "name": "Rock_Aqua_Brick_Smooth"
    },
    {
      "x": -10,
      "y": 7,
      "z": -1,
      "name": "Rock_Aqua_Brick_Smooth"
    },
    {
      "x": -10,
      "y": 8,
      "z": -1,
      "name": "Rock_Aqua_Brick_Smooth"
    },
    {
      "x": -10,
      "y": 9,
      "z": -1,
      "name": "Rock_Aqua_Brick_Smooth"
    },
    {
      "x": -10,
      "y": 12,
      "z": -1,
      "name": "Rock_Aqua_Brick_Smooth_Half",
      "rotation": 4
    },
    {
      "x": -10,
      "y": 13,
      "z": -1,
      "name": "Rock_Aqua_Brick_Smooth"
    },
    {
      "x": -10,
      "y": 14,
      "z": -1,
      "name": "Rock_Aqua_Brick_Smooth"
    },
    {
      "x": -10,
      "y": 15,
      "z": -1,
      "name": "Rock_Aqua_Brick_Smooth"
    },
    {
      "x": -10,
      "y": 16,
      "z": -1,
      "name": "Rock_Aqua_Brick_Smooth",
      "rotation": 3
    },
    {
      "x": -10,
      "y": 17,
      "z": -1,
      "name": "Rock_Aqua_Cobble_Roof",
      "rotation": 3
    },
    {
      "x": -10,
      "y": 0,
      "z": 0,
      "name": "Rock_Aqua_Brick_Smooth"
    },
    {
      "x": -10,
      "y": 4,
      "z": 0,
      "name": "Rock_Aqua_Brick_Smooth_Half",
      "rotation": 8
    },
    {
      "x": -10,
      "y": 5,
      "z": 0,
      "name": "Rock_Aqua_Brick_Smooth"
    },
    {
      "x": -10,
      "y": 6,
      "z": 0,
      "name": "Rock_Aqua_Brick_Smooth"
    },
    {
      "x": -10,
      "y": 7,
      "z": 0,
      "name": "Rock_Aqua_Brick_Smooth"
    },
    {
      "x": -10,
      "y": 8,
      "z": 0,
      "name": "Rock_Aqua_Brick_Smooth"
    },
    {
      "x": -10,
      "y": 9,
      "z": 0,
      "name": "Rock_Aqua_Brick_Smooth"
    },
    {
      "x": -10,
      "y": 13,
      "z": 0,
      "name": "Rock_Aqua_Brick_Smooth_Half",
      "rotation": 8
    },
    {
      "x": -10,
      "y": 14,
      "z": 0,
      "name": "Rock_Aqua_Brick_Smooth"
    },
    {
      "x": -10,
      "y": 15,
      "z": 0,
      "name": "Rock_Aqua_Brick_Smooth"
    },
    {
      "x": -10,
      "y": 16,
      "z": 0,
      "name": "Rock_Aqua_Brick_Smooth",
      "rotation": 3
    },
    {
      "x": -10,
      "y": 17,
      "z": 0,
      "name": "Rock_Aqua_Cobble_Roof",
      "rotation": 3
    },
    {
      "x": -10,
      "y": 0,
      "z": 1,
      "name": "Rock_Aqua_Brick_Smooth"
    },
    {
      "x": -10,
      "y": 3,
      "z": 1,
      "name": "Rock_Aqua_Brick_Smooth_Half",
      "rotation": 6
    },
    {
      "x": -10,
      "y": 4,
      "z": 1,
      "name": "Rock_Aqua_Brick_Smooth"
    },
    {
      "x": -10,
      "y": 5,
      "z": 1,
      "name": "Rock_Aqua_Brick_Smooth"
    },
    {
      "x": -10,
      "y": 6,
      "z": 1,
      "name": "Rock_Aqua_Brick_Smooth"
    },
    {
      "x": -10,
      "y": 7,
      "z": 1,
      "name": "Rock_Aqua_Brick_Smooth"
    },
    {
      "x": -10,
      "y": 8,
      "z": 1,
      "name": "Rock_Aqua_Brick_Smooth"
    },
    {
      "x": -10,
      "y": 9,
      "z": 1,
      "name": "Rock_Aqua_Brick_Smooth"
    },
    {
      "x": -10,
      "y": 12,
      "z": 1,
      "name": "Rock_Aqua_Brick_Smooth_Half",
      "rotation": 6
    },
    {
      "x": -10,
      "y": 13,
      "z": 1,
      "name": "Rock_Aqua_Brick_Smooth"
    },
    {
      "x": -10,
      "y": 14,
      "z": 1,
      "name": "Rock_Aqua_Brick_Smooth"
    },
    {
      "x": -10,
      "y": 15,
      "z": 1,
      "name": "Rock_Aqua_Brick_Smooth"
    },
    {
      "x": -10,
      "y": 16,
      "z": 1,
      "name": "Rock_Aqua_Brick_Smooth"
    },
    {
      "x": -10,
      "y": 17,
      "z": 1,
      "name": "Rock_Aqua_Cobble_Roof",
      "rotation": 3
    },
    {
      "x": -10,
      "y": 0,
      "z": 2,
      "name": "Rock_Aqua_Brick_Smooth"
    },
    {
      "x": -10,
      "y": 1,
      "z": 2,
      "name": "Rock_Aqua_Brick_Smooth"
    },
    {
      "x": -10,
      "y": 2,
      "z": 2,
      "name": "Rock_Aqua_Brick_Smooth"
    },
    {
      "x": -10,
      "y": 3,
      "z": 2,
      "name": "Rock_Aqua_Brick_Smooth"
    },
    {
      "x": -10,
      "y": 4,
      "z": 2,
      "name": "Rock_Aqua_Brick_Smooth"
    },
    {
      "x": -10,
      "y": 5,
      "z": 2,
      "name": "Rock_Aqua_Brick_Smooth"
    },
    {
      "x": -10,
      "y": 6,
      "z": 2,
      "name": "Rock_Aqua_Brick_Smooth"
    },
    {
      "x": -10,
      "y": 7,
      "z": 2,
      "name": "Rock_Aqua_Brick_Smooth"
    },
    {
      "x": -10,
      "y": 8,
      "z": 2,
      "name": "Rock_Aqua_Brick_Smooth"
    },
    {
      "x": -10,
      "y": 9,
      "z": 2,
      "name": "Rock_Aqua_Brick_Smooth"
    },
    {
      "x": -10,
      "y": 10,
      "z": 2,
      "name": "Rock_Aqua_Brick_Smooth"
    },
    {
      "x": -10,
      "y": 11,
      "z": 2,
      "name": "Rock_Aqua_Brick_Smooth"
    },
    {
      "x": -10,
      "y": 12,
      "z": 2,
      "name": "Rock_Aqua_Brick_Smooth"
    },
    {
      "x": -10,
      "y": 13,
      "z": 2,
      "name": "Rock_Aqua_Brick_Smooth"
    },
    {
      "x": -10,
      "y": 14,
      "z": 2,
      "name": "Rock_Aqua_Brick_Smooth"
    },
    {
      "x": -10,
      "y": 15,
      "z": 2,
      "name": "Rock_Aqua_Brick_Smooth"
    },
    {
      "x": -10,
      "y": 16,
      "z": 2,
      "name": "Rock_Aqua_Brick_Smooth"
    },
    {
      "x": -10,
      "y": 17,
      "z": 2,
      "name": "*Rock_Aqua_Cobble_Roof_State_Definitions_Corner_Left",
      "rotation": 3
    },
    {
      "x": -10,
      "y": 16,
      "z": 3,
      "name": "*Rock_Aqua_Cobble_Roof_Hollow_State_Definitions_Inverted_Corner_Left",
      "rotation": 3
    },
    {
      "x": -10,
      "y": 16,
      "z": 4,
      "name": "Rock_Aqua_Cobble_Roof_Hollow",
      "rotation": 3
    },
    {
      "x": -10,
      "y": 16,
      "z": 5,
      "name": "Rock_Aqua_Cobble_Roof_Hollow",
      "rotation": 3
    },
    {
      "x": -10,
      "y": 16,
      "z": 6,
      "name": "*Rock_Aqua_Cobble_Roof_Hollow_State_Definitions_Corner_Right"
    },
    {
      "x": -9,
      "y": 16,
      "z": -8,
      "name": "*Rock_Aqua_Cobble_Roof_Hollow_State_Definitions_Corner_Left",
      "rotation": 2
    },
    {
      "x": -9,
      "y": 16,
      "z": -7,
      "name": "Rock_Aqua_Cobble_Roof_Hollow",
      "rotation": 3
    },
    {
      "x": -9,
      "y": 16,
      "z": -6,
      "name": "*Rock_Aqua_Cobble_Roof_Hollow_State_Definitions_Inverted_Corner_Left",
      "rotation": 2
    },
    {
      "x": -9,
      "y": 0,
      "z": -5,
      "name": "Rock_Aqua_Brick_Smooth"
    },
    {
      "x": -9,
      "y": 1,
      "z": -5,
      "name": "Rock_Aqua_Brick_Smooth"
    },
    {
      "x": -9,
      "y": 2,
      "z": -5,
      "name": "Rock_Aqua_Brick_Smooth"
    },
    {
      "x": -9,
      "y": 3,
      "z": -5,
      "name": "Rock_Aqua_Brick_Smooth"
    },
    {
      "x": -9,
      "y": 4,
      "z": -5,
      "name": "Rock_Aqua_Brick_Smooth"
    },
    {
      "x": -9,
      "y": 5,
      "z": -5,
      "name": "Rock_Aqua_Brick_Smooth"
    },
    {
      "x": -9,
      "y": 6,
      "z": -5,
      "name": "Rock_Aqua_Brick_Smooth"
    },
    {
      "x": -9,
      "y": 7,
      "z": -5,
      "name": "Rock_Aqua_Brick_Smooth"
    },
    {
      "x": -9,
      "y": 8,
      "z": -5,
      "name": "Rock_Aqua_Brick_Smooth"
    },
    {
      "x": -9,
      "y": 9,
      "z": -5,
      "name": "Rock_Aqua_Brick_Smooth"
    },
    {
      "x": -9,
      "y": 10,
      "z": -5,
      "name": "Rock_Aqua_Brick_Smooth"
    },
    {
      "x": -9,
      "y": 11,
      "z": -5,
      "name": "Rock_Aqua_Brick_Smooth"
    },
    {
      "x": -9,
      "y": 12,
      "z": -5,
      "name": "Rock_Aqua_Brick_Smooth"
    },
    {
      "x": -9,
      "y": 13,
      "z": -5,
      "name": "Rock_Aqua_Brick_Smooth"
    },
    {
      "x": -9,
      "y": 14,
      "z": -5,
      "name": "Rock_Aqua_Brick_Smooth"
    },
    {
      "x": -9,
      "y": 15,
      "z": -5,
      "name": "Rock_Aqua_Brick_Smooth"
    },
    {
      "x": -9,
      "y": 16,
      "z": -5,
      "name": "Rock_Aqua_Brick_Smooth",
      "rotation": 3
    },
    {
      "x": -9,
      "y": 17,
      "z": -5,
      "name": "*Rock_Aqua_Cobble_Roof_State_Definitions_Corner_Left",
      "rotation": 2
    },
    {
      "x": -9,
      "y": 0,
      "z": -4,
      "name": "Rock_Aqua_Brick_Smooth"
    },
    {
      "x": -9,
      "y": 1,
      "z": -4,
      "name": "Rock_Aqua_Brick_Smooth"
    },
    {
      "x": -9,
      "y": 2,
      "z": -4,
      "name": "Rock_Aqua_Brick_Smooth"
    },
    {
      "x": -9,
      "y": 3,
      "z": -4,
      "name": "Rock_Aqua_Brick_Smooth"
    },
    {
      "x": -9,
      "y": 4,
      "z": -4,
      "name": "Rock_Aqua_Brick_Smooth"
    },
    {
      "x": -9,
      "y": 5,
      "z": -4,
      "name": "Rock_Aqua_Brick_Smooth"
    },
    {
      "x": -9,
      "y": 6,
      "z": -4,
      "name": "Rock_Aqua_Brick_Smooth"
    },
    {
      "x": -9,
      "y": 7,
      "z": -4,
      "name": "Rock_Aqua_Brick_Smooth"
    },
    {
      "x": -9,
      "y": 8,
      "z": -4,
      "name": "Rock_Aqua_Brick_Smooth"
    },
    {
      "x": -9,
      "y": 9,
      "z": -4,
      "name": "Rock_Aqua_Brick_Smooth"
    },
    {
      "x": -9,
      "y": 10,
      "z": -4,
      "name": "Rock_Aqua_Brick_Smooth"
    },
    {
      "x": -9,
      "y": 11,
      "z": -4,
      "name": "Rock_Aqua_Brick_Smooth"
    },
    {
      "x": -9,
      "y": 12,
      "z": -4,
      "name": "Rock_Aqua_Brick_Smooth"
    },
    {
      "x": -9,
      "y": 13,
      "z": -4,
      "name": "Rock_Aqua_Brick_Smooth"
    },
    {
      "x": -9,
      "y": 14,
      "z": -4,
      "name": "Rock_Aqua_Brick_Smooth"
    },
    {
      "x": -9,
      "y": 15,
      "z": -4,
      "name": "Rock_Aqua_Brick_Smooth"
    },
    {
      "x": -9,
      "y": 16,
      "z": -4,
      "name": "Rock_Aqua_Brick_Smooth",
      "rotation": 3
    },
    {
      "x": -9,
      "y": 17,
      "z": -4,
      "name": "Rock_Aqua_Cobble_Roof",
      "rotation": 3
    },
    {
      "x": -9,
      "y": 0,
      "z": -3,
      "name": "Rock_Aqua_Brick_Smooth"
    },
    {
      "x": -9,
      "y": 1,
      "z": -3,
      "name": "Rock_Aqua_Brick_Smooth"
    },
    {
      "x": -9,
      "y": 2,
      "z": -3,
      "name": "Rock_Aqua_Brick_Smooth"
    },
    {
      "x": -9,
      "y": 3,
      "z": -3,
      "name": "Rock_Aqua_Brick_Smooth"
    },
    {
      "x": -9,
      "y": 4,
      "z": -3,
      "name": "Rock_Aqua_Brick_Smooth"
    },
    {
      "x": -9,
      "y": 5,
      "z": -3,
      "name": "Rock_Aqua_Brick_Smooth"
    },
    {
      "x": -9,
      "y": 6,
      "z": -3,
      "name": "Rock_Aqua_Brick_Smooth"
    },
    {
      "x": -9,
      "y": 7,
      "z": -3,
      "name": "Rock_Aqua_Brick_Smooth"
    },
    {
      "x": -9,
      "y": 8,
      "z": -3,
      "name": "Rock_Aqua_Brick_Smooth"
    },
    {
      "x": -9,
      "y": 9,
      "z": -3,
      "name": "Rock_Aqua_Brick_Smooth"
    },
    {
      "x": -9,
      "y": 10,
      "z": -3,
      "name": "Rock_Aqua_Brick_Smooth"
    },
    {
      "x": -9,
      "y": 11,
      "z": -3,
      "name": "Rock_Aqua_Brick_Smooth"
    },
    {
      "x": -9,
      "y": 12,
      "z": -3,
      "name": "Rock_Aqua_Brick_Smooth"
    },
    {
      "x": -9,
      "y": 13,
      "z": -3,
      "name": "Rock_Aqua_Brick_Smooth"
    },
    {
      "x": -9,
      "y": 14,
      "z": -3,
      "name": "Rock_Aqua_Brick_Smooth"
    },
    {
      "x": -9,
      "y": 15,
      "z": -3,
      "name": "Rock_Aqua_Brick_Smooth"
    },
    {
      "x": -9,
      "y": 16,
      "z": -3,
      "name": "Rock_Aqua_Brick_Smooth",
      "rotation": 3
    },
    {
      "x": -9,
      "y": 17,
      "z": -3,
      "name": "Rock_Aqua_Cobble_Roof",
      "rotation": 3
    },
    {
      "x": -9,
      "y": 0,
      "z": -2,
      "name": "Rock_Aqua_Brick"
    },
    {
      "x": -9,
      "y": 8,
      "z": -2,
      "name": "Rock_Aqua_Brick"
    },
    {
      "x": -9,
      "y": 9,
      "z": -2,
      "name": "Rock_Aqua_Brick"
    },
    {
      "x": -9,
      "y": 17,
      "z": -2,
      "name": "*Rock_Aqua_Cobble_Roof_Hollow_State_Definitions_Inverted_Corner_Left",
      "rotation": 2
    },
    {
      "x": -9,
      "y": 0,
      "z": -1,
      "name": "Rock_Aqua_Brick"
    },
    {
      "x": -9,
      "y": 8,
      "z": -1,
      "name": "Rock_Aqua_Brick"
    },
    {
      "x": -9,
      "y": 9,
      "z": -1,
      "name": "Rock_Aqua_Brick"
    },
    {
      "x": -9,
      "y": 18,
      "z": -1,
      "name": "*Rock_Aqua_Cobble_Roof_Hollow_State_Definitions_Corner_Left",
      "rotation": 2
    },
    {
      "x": -9,
      "y": 0,
      "z": 0,
      "name": "Rock_Aqua_Brick"
    },
    {
      "x": -9,
      "y": 8,
      "z": 0,
      "name": "Rock_Aqua_Brick"
    },
    {
      "x": -9,
      "y": 9,
      "z": 0,
      "name": "Rock_Aqua_Brick"
    },
    {
      "x": -9,
      "y": 18,
      "z": 0,
      "name": "Rock_Aqua_Cobble_Roof_Hollow",
      "rotation": 3
    },
    {
      "x": -9,
      "y": 0,
      "z": 1,
      "name": "Rock_Aqua_Brick"
    },
    {
      "x": -9,
      "y": 8,
      "z": 1,
      "name": "Rock_Aqua_Brick"
    },
    {
      "x": -9,
      "y": 9,
      "z": 1,
      "name": "Rock_Aqua_Brick"
    },
    {
      "x": -9,
      "y": 18,
      "z": 1,
      "name": "*Rock_Aqua_Cobble_Roof_Hollow_State_Definitions_Corner_Left",
      "rotation": 3
    },
    {
      "x": -9,
      "y": 0,
      "z": 2,
      "name": "Rock_Aqua_Brick"
    },
    {
      "x": -9,
      "y": 8,
      "z": 2,
      "name": "Rock_Aqua_Brick"
    },
    {
      "x": -9,
      "y": 9,
      "z": 2,
      "name": "Rock_Aqua_Brick"
    },
    {
      "x": -9,
      "y": 17,
      "z": 2,
      "name": "*Rock_Aqua_Cobble_Roof_Hollow_State_Definitions_Inverted_Corner_Right"
    },
    {
      "x": -9,
      "y": 0,
      "z": 3,
      "name": "Rock_Aqua_Brick_Smooth"
    },
    {
      "x": -9,
      "y": 1,
      "z": 3,
      "name": "Rock_Aqua_Brick_Smooth"
    },
    {
      "x": -9,
      "y": 2,
      "z": 3,
      "name": "Rock_Aqua_Brick_Smooth"
    },
    {
      "x": -9,
      "y": 3,
      "z": 3,
      "name": "Rock_Aqua_Brick_Smooth"
    },
    {
      "x": -9,
      "y": 4,
      "z": 3,
      "name": "Rock_Aqua_Brick_Smooth"
    },
    {
      "x": -9,
      "y": 5,
      "z": 3,
      "name": "Rock_Aqua_Brick_Smooth"
    },
    {
      "x": -9,
      "y": 6,
      "z": 3,
      "name": "Rock_Aqua_Brick_Smooth"
    },
    {
      "x": -9,
      "y": 7,
      "z": 3,
      "name": "Rock_Aqua_Brick_Smooth"
    },
    {
      "x": -9,
      "y": 8,
      "z": 3,
      "name": "Rock_Aqua_Brick_Smooth"
    },
    {
      "x": -9,
      "y": 9,
      "z": 3,
      "name": "Rock_Aqua_Brick_Smooth"
    },
    {
      "x": -9,
      "y": 10,
      "z": 3,
      "name": "Rock_Aqua_Brick_Smooth"
    },
    {
      "x": -9,
      "y": 11,
      "z": 3,
      "name": "Rock_Aqua_Brick_Smooth"
    },
    {
      "x": -9,
      "y": 12,
      "z": 3,
      "name": "Rock_Aqua_Brick_Smooth"
    },
    {
      "x": -9,
      "y": 13,
      "z": 3,
      "name": "Rock_Aqua_Brick_Smooth"
    },
    {
      "x": -9,
      "y": 14,
      "z": 3,
      "name": "Rock_Aqua_Brick_Smooth"
    },
    {
      "x": -9,
      "y": 15,
      "z": 3,
      "name": "Rock_Aqua_Brick_Smooth"
    },
    {
      "x": -9,
      "y": 16,
      "z": 3,
      "name": "Rock_Aqua_Brick_Smooth"
    },
    {
      "x": -9,
      "y": 17,
      "z": 3,
      "name": "Rock_Aqua_Cobble_Roof",
      "rotation": 3
    },
    {
      "x": -9,
      "y": 0,
      "z": 4,
      "name": "Rock_Aqua_Brick_Smooth"
    },
    {
      "x": -9,
      "y": 1,
      "z": 4,
      "name": "Rock_Aqua_Brick_Smooth"
    },
    {
      "x": -9,
      "y": 2,
      "z": 4,
      "name": "Rock_Aqua_Brick_Smooth"
    },
    {
      "x": -9,
      "y": 3,
      "z": 4,
      "name": "Rock_Aqua_Brick_Smooth"
    },
    {
      "x": -9,
      "y": 4,
      "z": 4,
      "name": "Rock_Aqua_Brick_Smooth"
    },
    {
      "x": -9,
      "y": 5,
      "z": 4,
      "name": "Rock_Aqua_Brick_Smooth"
    },
    {
      "x": -9,
      "y": 6,
      "z": 4,
      "name": "Rock_Aqua_Brick_Smooth"
    },
    {
      "x": -9,
      "y": 7,
      "z": 4,
      "name": "Rock_Aqua_Brick_Smooth"
    },
    {
      "x": -9,
      "y": 8,
      "z": 4,
      "name": "Rock_Aqua_Brick_Smooth"
    },
    {
      "x": -9,
      "y": 9,
      "z": 4,
      "name": "Rock_Aqua_Brick_Smooth"
    },
    {
      "x": -9,
      "y": 10,
      "z": 4,
      "name": "Rock_Aqua_Brick_Smooth"
    },
    {
      "x": -9,
      "y": 11,
      "z": 4,
      "name": "Rock_Aqua_Brick_Smooth"
    },
    {
      "x": -9,
      "y": 12,
      "z": 4,
      "name": "Rock_Aqua_Brick_Smooth"
    },
    {
      "x": -9,
      "y": 13,
      "z": 4,
      "name": "Rock_Aqua_Brick_Smooth"
    },
    {
      "x": -9,
      "y": 14,
      "z": 4,
      "name": "Rock_Aqua_Brick_Smooth"
    },
    {
      "x": -9,
      "y": 15,
      "z": 4,
      "name": "Rock_Aqua_Brick_Smooth"
    },
    {
      "x": -9,
      "y": 16,
      "z": 4,
      "name": "Rock_Aqua_Brick_Smooth"
    },
    {
      "x": -9,
      "y": 17,
      "z": 4,
      "name": "Rock_Aqua_Cobble_Roof",
      "rotation": 3
    },
    {
      "x": -9,
      "y": 0,
      "z": 5,
      "name": "Rock_Aqua_Brick_Smooth"
    },
    {
      "x": -9,
      "y": 1,
      "z": 5,
      "name": "Rock_Aqua_Brick_Smooth"
    },
    {
      "x": -9,
      "y": 2,
      "z": 5,
      "name": "Rock_Aqua_Brick_Smooth"
    },
    {
      "x": -9,
      "y": 3,
      "z": 5,
      "name": "Rock_Aqua_Brick_Smooth"
    },
    {
      "x": -9,
      "y": 4,
      "z": 5,
      "name": "Rock_Aqua_Brick_Smooth"
    },
    {
      "x": -9,
      "y": 5,
      "z": 5,
      "name": "Rock_Aqua_Brick_Smooth"
    },
    {
      "x": -9,
      "y": 6,
      "z": 5,
      "name": "Rock_Aqua_Brick_Smooth"
    },
    {
      "x": -9,
      "y": 7,
      "z": 5,
      "name": "Rock_Aqua_Brick_Smooth"
    },
    {
      "x": -9,
      "y": 8,
      "z": 5,
      "name": "Rock_Aqua_Brick_Smooth"
    },
    {
      "x": -9,
      "y": 9,
      "z": 5,
      "name": "Rock_Aqua_Brick_Smooth"
    },
    {
      "x": -9,
      "y": 10,
      "z": 5,
      "name": "Rock_Aqua_Brick_Smooth"
    },
    {
      "x": -9,
      "y": 11,
      "z": 5,
      "name": "Rock_Aqua_Brick_Smooth"
    },
    {
      "x": -9,
      "y": 12,
      "z": 5,
      "name": "Rock_Aqua_Brick_Smooth"
    },
    {
      "x": -9,
      "y": 13,
      "z": 5,
      "name": "Rock_Aqua_Brick_Smooth"
    },
    {
      "x": -9,
      "y": 14,
      "z": 5,
      "name": "Rock_Aqua_Brick_Smooth"
    },
    {
      "x": -9,
      "y": 15,
      "z": 5,
      "name": "Rock_Aqua_Brick_Smooth"
    },
    {
      "x": -9,
      "y": 16,
      "z": 5,
      "name": "Rock_Aqua_Brick_Smooth"
    },
    {
      "x": -9,
      "y": 17,
      "z": 5,
      "name": "*Rock_Aqua_Cobble_Roof_State_Definitions_Corner_Left",
      "rotation": 3
    },
    {
      "x": -9,
      "y": 16,
      "z": 6,
      "name": "*Rock_Aqua_Cobble_Roof_Hollow_State_Definitions_Inverted_Corner_Left",
      "rotation": 3
    },
    {
      "x": -9,
      "y": 16,
      "z": 7,
      "name": "Rock_Aqua_Cobble_Roof_Hollow",
      "rotation": 3
    },
    {
      "x": -9,
      "y": 16,
      "z": 8,
      "name": "*Rock_Aqua_Cobble_Roof_Hollow_State_Definitions_Corner_Right"
    },
    {
      "x": -8,
      "y": 16,
      "z": -9,
      "name": "*Rock_Aqua_Cobble_Roof_Hollow_State_Definitions_Corner_Right",
      "rotation": 3
    },
    {
      "x": -8,
      "y": 16,
      "z": -8,
      "name": "*Rock_Aqua_Cobble_Roof_Hollow_State_Definitions_Inverted_Corner_Left",
      "rotation": 2
    },
    {
      "x": -8,
      "y": 0,
      "z": -7,
      "name": "Rock_Aqua_Brick_Smooth"
    },
    {
      "x": -8,
      "y": 1,
      "z": -7,
      "name": "Rock_Aqua_Brick_Smooth"
    },
    {
      "x": -8,
      "y": 2,
      "z": -7,
      "name": "Rock_Aqua_Brick_Smooth"
    },
    {
      "x": -8,
      "y": 3,
      "z": -7,
      "name": "Rock_Aqua_Brick_Smooth"
    },
    {
      "x": -8,
      "y": 4,
      "z": -7,
      "name": "Rock_Aqua_Brick_Smooth"
    },
    {
      "x": -8,
      "y": 5,
      "z": -7,
      "name": "Rock_Aqua_Brick_Smooth"
    },
    {
      "x": -8,
      "y": 6,
      "z": -7,
      "name": "Rock_Aqua_Brick_Smooth"
    },
    {
      "x": -8,
      "y": 7,
      "z": -7,
      "name": "Rock_Aqua_Brick_Smooth"
    },
    {
      "x": -8,
      "y": 8,
      "z": -7,
      "name": "Rock_Aqua_Brick_Smooth"
    },
    {
      "x": -8,
      "y": 9,
      "z": -7,
      "name": "Rock_Aqua_Brick_Smooth"
    },
    {
      "x": -8,
      "y": 10,
      "z": -7,
      "name": "Rock_Aqua_Brick_Smooth"
    },
    {
      "x": -8,
      "y": 11,
      "z": -7,
      "name": "Rock_Aqua_Brick_Smooth"
    },
    {
      "x": -8,
      "y": 12,
      "z": -7,
      "name": "Rock_Aqua_Brick_Smooth"
    },
    {
      "x": -8,
      "y": 13,
      "z": -7,
      "name": "Rock_Aqua_Brick_Smooth"
    },
    {
      "x": -8,
      "y": 14,
      "z": -7,
      "name": "Rock_Aqua_Brick_Smooth"
    },
    {
      "x": -8,
      "y": 15,
      "z": -7,
      "name": "Rock_Aqua_Brick_Smooth"
    },
    {
      "x": -8,
      "y": 16,
      "z": -7,
      "name": "Rock_Aqua_Brick_Smooth",
      "rotation": 3
    },
    {
      "x": -8,
      "y": 17,
      "z": -7,
      "name": "*Rock_Aqua_Cobble_Roof_State_Definitions_Corner_Left",
      "rotation": 2
    },
    {
      "x": -8,
      "y": 0,
      "z": -6,
      "name": "Rock_Aqua_Brick_Smooth"
    },
    {
      "x": -8,
      "y": 1,
      "z": -6,
      "name": "Rock_Aqua_Brick_Smooth"
    },
    {
      "x": -8,
      "y": 2,
      "z": -6,
      "name": "Rock_Aqua_Brick_Smooth"
    },
    {
      "x": -8,
      "y": 3,
      "z": -6,
      "name": "Rock_Aqua_Brick_Smooth"
    },
    {
      "x": -8,
      "y": 4,
      "z": -6,
      "name": "Rock_Aqua_Brick_Smooth"
    },
    {
      "x": -8,
      "y": 5,
      "z": -6,
      "name": "Rock_Aqua_Brick_Smooth"
    },
    {
      "x": -8,
      "y": 6,
      "z": -6,
      "name": "Rock_Aqua_Brick_Smooth"
    },
    {
      "x": -8,
      "y": 7,
      "z": -6,
      "name": "Rock_Aqua_Brick_Smooth"
    },
    {
      "x": -8,
      "y": 8,
      "z": -6,
      "name": "Rock_Aqua_Brick_Smooth"
    },
    {
      "x": -8,
      "y": 9,
      "z": -6,
      "name": "Rock_Aqua_Brick_Smooth"
    },
    {
      "x": -8,
      "y": 10,
      "z": -6,
      "name": "Rock_Aqua_Brick_Smooth"
    },
    {
      "x": -8,
      "y": 11,
      "z": -6,
      "name": "Rock_Aqua_Brick_Smooth"
    },
    {
      "x": -8,
      "y": 12,
      "z": -6,
      "name": "Rock_Aqua_Brick_Smooth"
    },
    {
      "x": -8,
      "y": 13,
      "z": -6,
      "name": "Rock_Aqua_Brick_Smooth"
    },
    {
      "x": -8,
      "y": 14,
      "z": -6,
      "name": "Rock_Aqua_Brick_Smooth"
    },
    {
      "x": -8,
      "y": 15,
      "z": -6,
      "name": "Rock_Aqua_Brick_Smooth"
    },
    {
      "x": -8,
      "y": 16,
      "z": -6,
      "name": "Rock_Aqua_Brick_Smooth",
      "rotation": 3
    },
    {
      "x": -8,
      "y": 17,
      "z": -6,
      "name": "Rock_Aqua_Cobble_Roof",
      "rotation": 3
    },
    {
      "x": -8,
      "y": 0,
      "z": -5,
      "name": "Rock_Aqua_Brick"
    },
    {
      "x": -8,
      "y": 8,
      "z": -5,
      "name": "Rock_Aqua_Brick"
    },
    {
      "x": -8,
      "y": 9,
      "z": -5,
      "name": "Rock_Aqua_Brick"
    },
    {
      "x": -8,
      "y": 17,
      "z": -5,
      "name": "*Rock_Aqua_Cobble_Roof_Hollow_State_Definitions_Inverted_Corner_Right",
      "rotation": 3
    },
    {
      "x": -8,
      "y": 0,
      "z": -4,
      "name": "Rock_Aqua_Brick"
    },
    {
      "x": -8,
      "y": 8,
      "z": -4,
      "name": "Rock_Aqua_Brick"
    },
    {
      "x": -8,
      "y": 9,
      "z": -4,
      "name": "Rock_Aqua_Brick"
    },
    {
      "x": -8,
      "y": 18,
      "z": -4,
      "name": "*Rock_Aqua_Cobble_Roof_Hollow_State_Definitions_Corner_Left",
      "rotation": 2
    },
    {
      "x": -8,
      "y": 0,
      "z": -3,
      "name": "Rock_Aqua_Brick"
    },
    {
      "x": -8,
      "y": 8,
      "z": -3,
      "name": "Rock_Aqua_Brick"
    },
    {
      "x": -8,
      "y": 9,
      "z": -3,
      "name": "Rock_Aqua_Brick"
    },
    {
      "x": -8,
      "y": 18,
      "z": -3,
      "name": "Rock_Aqua_Cobble_Roof_Hollow",
      "rotation": 3
    },
    {
      "x": -8,
      "y": 0,
      "z": -2,
      "name": "Rock_Aqua_Brick"
    },
    {
      "x": -8,
      "y": 8,
      "z": -2,
      "name": "Rock_Aqua_Brick"
    },
    {
      "x": -8,
      "y": 9,
      "z": -2,
      "name": "Rock_Aqua_Brick"
    },
    {
      "x": -8,
      "y": 18,
      "z": -2,
      "name": "Rock_Aqua_Cobble_Roof_Hollow",
      "rotation": 3
    },
    {
      "x": -8,
      "y": 0,
      "z": -1,
      "name": "Rock_Aqua_Brick"
    },
    {
      "x": -8,
      "y": 8,
      "z": -1,
      "name": "Rock_Aqua_Brick"
    },
    {
      "x": -8,
      "y": 9,
      "z": -1,
      "name": "Rock_Aqua_Brick"
    },
    {
      "x": -8,
      "y": 18,
      "z": -1,
      "name": "*Rock_Aqua_Cobble_Roof_Hollow_State_Definitions_Inverted_Corner_Right",
      "rotation": 3
    },
    {
      "x": -8,
      "y": 0,
      "z": 0,
      "name": "Rock_Aqua_Brick"
    },
    {
      "x": -8,
      "y": 8,
      "z": 0,
      "name": "Rock_Aqua_Brick"
    },
    {
      "x": -8,
      "y": 9,
      "z": 0,
      "name": "Rock_Aqua_Brick"
    },
    {
      "x": -8,
      "y": 19,
      "z": 0,
      "name": "Rock_Aqua_Cobble_Roof_Flat",
      "rotation": 3
    },
    {
      "x": -8,
      "y": 0,
      "z": 1,
      "name": "Rock_Aqua_Brick"
    },
    {
      "x": -8,
      "y": 8,
      "z": 1,
      "name": "Rock_Aqua_Brick"
    },
    {
      "x": -8,
      "y": 9,
      "z": 1,
      "name": "Rock_Aqua_Brick"
    },
    {
      "x": -8,
      "y": 18,
      "z": 1,
      "name": "*Rock_Aqua_Cobble_Roof_Hollow_State_Definitions_Inverted_Corner_Right"
    },
    {
      "x": -8,
      "y": 0,
      "z": 2,
      "name": "Rock_Aqua_Brick"
    },
    {
      "x": -8,
      "y": 8,
      "z": 2,
      "name": "Rock_Aqua_Brick"
    },
    {
      "x": -8,
      "y": 9,
      "z": 2,
      "name": "Rock_Aqua_Brick"
    },
    {
      "x": -8,
      "y": 18,
      "z": 2,
      "name": "Rock_Aqua_Cobble_Roof_Hollow",
      "rotation": 3
    },
    {
      "x": -8,
      "y": 0,
      "z": 3,
      "name": "Rock_Aqua_Brick"
    },
    {
      "x": -8,
      "y": 8,
      "z": 3,
      "name": "Rock_Aqua_Brick"
    },
    {
      "x": -8,
      "y": 9,
      "z": 3,
      "name": "Rock_Aqua_Brick"
    },
    {
      "x": -8,
      "y": 18,
      "z": 3,
      "name": "Rock_Aqua_Cobble_Roof_Hollow",
      "rotation": 3
    },
    {
      "x": -8,
      "y": 0,
      "z": 4,
      "name": "Rock_Aqua_Brick"
    },
    {
      "x": -8,
      "y": 8,
      "z": 4,
      "name": "Rock_Aqua_Brick"
    },
    {
      "x": -8,
      "y": 9,
      "z": 4,
      "name": "Rock_Aqua_Brick"
    },
    {
      "x": -8,
      "y": 18,
      "z": 4,
      "name": "*Rock_Aqua_Cobble_Roof_Hollow_State_Definitions_Corner_Left",
      "rotation": 3
    },
    {
      "x": -8,
      "y": 0,
      "z": 5,
      "name": "Rock_Aqua_Brick"
    },
    {
      "x": -8,
      "y": 8,
      "z": 5,
      "name": "Rock_Aqua_Brick"
    },
    {
      "x": -8,
      "y": 9,
      "z": 5,
      "name": "Rock_Aqua_Brick"
    },
    {
      "x": -8,
      "y": 17,
      "z": 5,
      "name": "*Rock_Aqua_Cobble_Roof_Hollow_State_Definitions_Inverted_Corner_Right"
    },
    {
      "x": -8,
      "y": 0,
      "z": 6,
      "name": "Rock_Aqua_Brick_Smooth"
    },
    {
      "x": -8,
      "y": 1,
      "z": 6,
      "name": "Rock_Aqua_Brick_Smooth"
    },
    {
      "x": -8,
      "y": 2,
      "z": 6,
      "name": "Rock_Aqua_Brick_Smooth"
    },
    {
      "x": -8,
      "y": 3,
      "z": 6,
      "name": "Rock_Aqua_Brick_Smooth"
    },
    {
      "x": -8,
      "y": 4,
      "z": 6,
      "name": "Rock_Aqua_Brick_Smooth"
    },
    {
      "x": -8,
      "y": 5,
      "z": 6,
      "name": "Rock_Aqua_Brick_Smooth"
    },
    {
      "x": -8,
      "y": 6,
      "z": 6,
      "name": "Rock_Aqua_Brick_Smooth"
    },
    {
      "x": -8,
      "y": 7,
      "z": 6,
      "name": "Rock_Aqua_Brick_Smooth"
    },
    {
      "x": -8,
      "y": 8,
      "z": 6,
      "name": "Rock_Aqua_Brick_Smooth"
    },
    {
      "x": -8,
      "y": 9,
      "z": 6,
      "name": "Rock_Aqua_Brick_Smooth"
    },
    {
      "x": -8,
      "y": 10,
      "z": 6,
      "name": "Rock_Aqua_Brick_Smooth"
    },
    {
      "x": -8,
      "y": 11,
      "z": 6,
      "name": "Rock_Aqua_Brick_Smooth"
    },
    {
      "x": -8,
      "y": 12,
      "z": 6,
      "name": "Rock_Aqua_Brick_Smooth"
    },
    {
      "x": -8,
      "y": 13,
      "z": 6,
      "name": "Rock_Aqua_Brick_Smooth"
    },
    {
      "x": -8,
      "y": 14,
      "z": 6,
      "name": "Rock_Aqua_Brick_Smooth"
    },
    {
      "x": -8,
      "y": 15,
      "z": 6,
      "name": "Rock_Aqua_Brick_Smooth"
    },
    {
      "x": -8,
      "y": 16,
      "z": 6,
      "name": "Rock_Aqua_Brick_Smooth"
    },
    {
      "x": -8,
      "y": 17,
      "z": 6,
      "name": "Rock_Aqua_Cobble_Roof",
      "rotation": 3
    },
    {
      "x": -8,
      "y": 0,
      "z": 7,
      "name": "Rock_Aqua_Brick_Smooth"
    },
    {
      "x": -8,
      "y": 1,
      "z": 7,
      "name": "Rock_Aqua_Brick_Smooth"
    },
    {
      "x": -8,
      "y": 2,
      "z": 7,
      "name": "Rock_Aqua_Brick_Smooth"
    },
    {
      "x": -8,
      "y": 3,
      "z": 7,
      "name": "Rock_Aqua_Brick_Smooth"
    },
    {
      "x": -8,
      "y": 4,
      "z": 7,
      "name": "Rock_Aqua_Brick_Smooth"
    },
    {
      "x": -8,
      "y": 5,
      "z": 7,
      "name": "Rock_Aqua_Brick_Smooth"
    },
    {
      "x": -8,
      "y": 6,
      "z": 7,
      "name": "Rock_Aqua_Brick_Smooth"
    },
    {
      "x": -8,
      "y": 7,
      "z": 7,
      "name": "Rock_Aqua_Brick_Smooth"
    },
    {
      "x": -8,
      "y": 8,
      "z": 7,
      "name": "Rock_Aqua_Brick_Smooth"
    },
    {
      "x": -8,
      "y": 9,
      "z": 7,
      "name": "Rock_Aqua_Brick_Smooth"
    },
    {
      "x": -8,
      "y": 10,
      "z": 7,
      "name": "Rock_Aqua_Brick_Smooth"
    },
    {
      "x": -8,
      "y": 11,
      "z": 7,
      "name": "Rock_Aqua_Brick_Smooth"
    },
    {
      "x": -8,
      "y": 12,
      "z": 7,
      "name": "Rock_Aqua_Brick_Smooth"
    },
    {
      "x": -8,
      "y": 13,
      "z": 7,
      "name": "Rock_Aqua_Brick_Smooth"
    },
    {
      "x": -8,
      "y": 14,
      "z": 7,
      "name": "Rock_Aqua_Brick_Smooth"
    },
    {
      "x": -8,
      "y": 15,
      "z": 7,
      "name": "Rock_Aqua_Brick_Smooth"
    },
    {
      "x": -8,
      "y": 16,
      "z": 7,
      "name": "Rock_Aqua_Brick_Smooth"
    },
    {
      "x": -8,
      "y": 17,
      "z": 7,
      "name": "*Rock_Aqua_Cobble_Roof_State_Definitions_Corner_Right"
    },
    {
      "x": -8,
      "y": 16,
      "z": 8,
      "name": "*Rock_Aqua_Cobble_Roof_Hollow_State_Definitions_Inverted_Corner_Left",
      "rotation": 3
    },
    {
      "x": -8,
      "y": 16,
      "z": 9,
      "name": "*Rock_Aqua_Cobble_Roof_Hollow_State_Definitions_Corner_Left",
      "rotation": 3
    },
    {
      "x": -7,
      "y": 16,
      "z": -9,
      "name": "Rock_Aqua_Cobble_Roof_Hollow",
      "rotation": 2
    },
    {
      "x": -7,
      "y": 0,
      "z": -8,
      "name": "Rock_Aqua_Brick_Smooth"
    },
    {
      "x": -7,
      "y": 1,
      "z": -8,
      "name": "Rock_Aqua_Brick_Smooth"
    },
    {
      "x": -7,
      "y": 2,
      "z": -8,
      "name": "Rock_Aqua_Brick_Smooth"
    },
    {
      "x": -7,
      "y": 3,
      "z": -8,
      "name": "Rock_Aqua_Brick_Smooth"
    },
    {
      "x": -7,
      "y": 4,
      "z": -8,
      "name": "Rock_Aqua_Brick_Smooth"
    },
    {
      "x": -7,
      "y": 5,
      "z": -8,
      "name": "Rock_Aqua_Brick_Smooth"
    },
    {
      "x": -7,
      "y": 6,
      "z": -8,
      "name": "Rock_Aqua_Brick_Smooth"
    },
    {
      "x": -7,
      "y": 7,
      "z": -8,
      "name": "Rock_Aqua_Brick_Smooth"
    },
    {
      "x": -7,
      "y": 8,
      "z": -8,
      "name": "Rock_Aqua_Brick_Smooth"
    },
    {
      "x": -7,
      "y": 9,
      "z": -8,
      "name": "Rock_Aqua_Brick_Smooth"
    },
    {
      "x": -7,
      "y": 10,
      "z": -8,
      "name": "Rock_Aqua_Brick_Smooth"
    },
    {
      "x": -7,
      "y": 11,
      "z": -8,
      "name": "Rock_Aqua_Brick_Smooth"
    },
    {
      "x": -7,
      "y": 12,
      "z": -8,
      "name": "Rock_Aqua_Brick_Smooth"
    },
    {
      "x": -7,
      "y": 13,
      "z": -8,
      "name": "Rock_Aqua_Brick_Smooth"
    },
    {
      "x": -7,
      "y": 14,
      "z": -8,
      "name": "Rock_Aqua_Brick_Smooth"
    },
    {
      "x": -7,
      "y": 15,
      "z": -8,
      "name": "Rock_Aqua_Brick_Smooth"
    },
    {
      "x": -7,
      "y": 16,
      "z": -8,
      "name": "Rock_Aqua_Brick_Smooth",
      "rotation": 3
    },
    {
      "x": -7,
      "y": 17,
      "z": -8,
      "name": "*Rock_Aqua_Cobble_Roof_State_Definitions_Corner_Right",
      "rotation": 3
    },
    {
      "x": -7,
      "y": 0,
      "z": -7,
      "name": "Rock_Aqua_Brick"
    },
    {
      "x": -7,
      "y": 8,
      "z": -7,
      "name": "Rock_Aqua_Brick"
    },
    {
      "x": -7,
      "y": 9,
      "z": -7,
      "name": "Rock_Aqua_Brick"
    },
    {
      "x": -7,
      "y": 17,
      "z": -7,
      "name": "*Rock_Aqua_Cobble_Roof_Hollow_State_Definitions_Inverted_Corner_Right",
      "rotation": 3
    },
    {
      "x": -7,
      "y": 0,
      "z": -6,
      "name": "Rock_Aqua_Brick"
    },
    {
      "x": -7,
      "y": 8,
      "z": -6,
      "name": "Rock_Aqua_Brick"
    },
    {
      "x": -7,
      "y": 9,
      "z": -6,
      "name": "Rock_Aqua_Brick"
    },
    {
      "x": -7,
      "y": 18,
      "z": -6,
      "name": "*Rock_Aqua_Cobble_Roof_Hollow_State_Definitions_Corner_Left",
      "rotation": 2
    },
    {
      "x": -7,
      "y": 0,
      "z": -5,
      "name": "Rock_Aqua_Brick"
    },
    {
      "x": -7,
      "y": 8,
      "z": -5,
      "name": "Rock_Aqua_Brick"
    },
    {
      "x": -7,
      "y": 9,
      "z": -5,
      "name": "Rock_Aqua_Brick"
    },
    {
      "x": -7,
      "y": 18,
      "z": -5,
      "name": "Rock_Aqua_Cobble_Roof_Hollow",
      "rotation": 3
    },
    {
      "x": -7,
      "y": 0,
      "z": -4,
      "name": "Rock_Aqua_Brick"
    },
    {
      "x": -7,
      "y": 8,
      "z": -4,
      "name": "Rock_Aqua_Brick"
    },
    {
      "x": -7,
      "y": 9,
      "z": -4,
      "name": "Rock_Aqua_Brick"
    },
    {
      "x": -7,
      "y": 18,
      "z": -4,
      "name": "*Rock_Aqua_Cobble_Roof_Hollow_State_Definitions_Inverted_Corner_Right",
      "rotation": 3
    },
    {
      "x": -7,
      "y": 0,
      "z": -3,
      "name": "Rock_Aqua_Brick"
    },
    {
      "x": -7,
      "y": 8,
      "z": -3,
      "name": "Rock_Aqua_Brick"
    },
    {
      "x": -7,
      "y": 9,
      "z": -3,
      "name": "Rock_Aqua_Brick"
    },
    {
      "x": -7,
      "y": 19,
      "z": -3,
      "name": "Rock_Aqua_Cobble_Roof_Shallow",
      "rotation": 3
    },
    {
      "x": -7,
      "y": 0,
      "z": -2,
      "name": "Rock_Aqua_Brick"
    },
    {
      "x": -7,
      "y": 8,
      "z": -2,
      "name": "Rock_Aqua_Brick"
    },
    {
      "x": -7,
      "y": 9,
      "z": -2,
      "name": "Rock_Aqua_Brick"
    },
    {
      "x": -7,
      "y": 19,
      "z": -2,
      "name": "Rock_Aqua_Cobble_Roof_Shallow",
      "rotation": 3
    },
    {
      "x": -7,
      "y": 0,
      "z": -1,
      "name": "Rock_Aqua_Brick"
    },
    {
      "x": -7,
      "y": 8,
      "z": -1,
      "name": "Rock_Aqua_Brick"
    },
    {
      "x": -7,
      "y": 9,
      "z": -1,
      "name": "Rock_Aqua_Brick"
    },
    {
      "x": -7,
      "y": 19,
      "z": -1,
      "name": "Rock_Aqua_Cobble_Roof_Shallow",
      "rotation": 3
    },
    {
      "x": -7,
      "y": 0,
      "z": 0,
      "name": "Rock_Aqua_Brick"
    },
    {
      "x": -7,
      "y": 8,
      "z": 0,
      "name": "Rock_Aqua_Brick"
    },
    {
      "x": -7,
      "y": 9,
      "z": 0,
      "name": "Rock_Aqua_Brick"
    },
    {
      "x": -7,
      "y": 19,
      "z": 0,
      "name": "Rock_Aqua_Cobble_Roof_Shallow",
      "rotation": 3
    },
    {
      "x": -7,
      "y": 0,
      "z": 1,
      "name": "Rock_Aqua_Brick"
    },
    {
      "x": -7,
      "y": 8,
      "z": 1,
      "name": "Rock_Aqua_Brick"
    },
    {
      "x": -7,
      "y": 9,
      "z": 1,
      "name": "Rock_Aqua_Brick"
    },
    {
      "x": -7,
      "y": 19,
      "z": 1,
      "name": "Rock_Aqua_Cobble_Roof_Shallow",
      "rotation": 3
    },
    {
      "x": -7,
      "y": 0,
      "z": 2,
      "name": "Rock_Aqua_Brick"
    },
    {
      "x": -7,
      "y": 8,
      "z": 2,
      "name": "Rock_Aqua_Brick"
    },
    {
      "x": -7,
      "y": 9,
      "z": 2,
      "name": "Rock_Aqua_Brick"
    },
    {
      "x": -7,
      "y": 19,
      "z": 2,
      "name": "Rock_Aqua_Cobble_Roof_Shallow",
      "rotation": 3
    },
    {
      "x": -7,
      "y": 0,
      "z": 3,
      "name": "Rock_Aqua_Brick"
    },
    {
      "x": -7,
      "y": 8,
      "z": 3,
      "name": "Rock_Aqua_Brick"
    },
    {
      "x": -7,
      "y": 9,
      "z": 3,
      "name": "Rock_Aqua_Brick"
    },
    {
      "x": -7,
      "y": 19,
      "z": 3,
      "name": "Rock_Aqua_Cobble_Roof_Shallow",
      "rotation": 3
    },
    {
      "x": -7,
      "y": 0,
      "z": 4,
      "name": "Rock_Aqua_Brick"
    },
    {
      "x": -7,
      "y": 8,
      "z": 4,
      "name": "Rock_Aqua_Brick"
    },
    {
      "x": -7,
      "y": 9,
      "z": 4,
      "name": "Rock_Aqua_Brick"
    },
    {
      "x": -7,
      "y": 18,
      "z": 4,
      "name": "*Rock_Aqua_Cobble_Roof_Hollow_State_Definitions_Inverted_Corner_Right"
    },
    {
      "x": -7,
      "y": 0,
      "z": 5,
      "name": "Rock_Aqua_Brick"
    },
    {
      "x": -7,
      "y": 8,
      "z": 5,
      "name": "Rock_Aqua_Brick"
    },
    {
      "x": -7,
      "y": 9,
      "z": 5,
      "name": "Rock_Aqua_Brick"
    },
    {
      "x": -7,
      "y": 18,
      "z": 5,
      "name": "Rock_Aqua_Cobble_Roof_Hollow",
      "rotation": 3
    },
    {
      "x": -7,
      "y": 0,
      "z": 6,
      "name": "Rock_Aqua_Brick"
    },
    {
      "x": -7,
      "y": 8,
      "z": 6,
      "name": "Rock_Aqua_Brick"
    },
    {
      "x": -7,
      "y": 9,
      "z": 6,
      "name": "Rock_Aqua_Brick"
    },
    {
      "x": -7,
      "y": 18,
      "z": 6,
      "name": "*Rock_Aqua_Cobble_Roof_Hollow_State_Definitions_Corner_Left",
      "rotation": 3
    },
    {
      "x": -7,
      "y": 0,
      "z": 7,
      "name": "Rock_Aqua_Brick"
    },
    {
      "x": -7,
      "y": 8,
      "z": 7,
      "name": "Rock_Aqua_Brick"
    },
    {
      "x": -7,
      "y": 9,
      "z": 7,
      "name": "Rock_Aqua_Brick"
    },
    {
      "x": -7,
      "y": 17,
      "z": 7,
      "name": "*Rock_Aqua_Cobble_Roof_Hollow_State_Definitions_Inverted_Corner_Right"
    },
    {
      "x": -7,
      "y": 0,
      "z": 8,
      "name": "Rock_Aqua_Brick_Smooth"
    },
    {
      "x": -7,
      "y": 1,
      "z": 8,
      "name": "Rock_Aqua_Brick_Smooth"
    },
    {
      "x": -7,
      "y": 2,
      "z": 8,
      "name": "Rock_Aqua_Brick_Smooth"
    },
    {
      "x": -7,
      "y": 3,
      "z": 8,
      "name": "Rock_Aqua_Brick_Smooth"
    },
    {
      "x": -7,
      "y": 4,
      "z": 8,
      "name": "Rock_Aqua_Brick_Smooth"
    },
    {
      "x": -7,
      "y": 5,
      "z": 8,
      "name": "Rock_Aqua_Brick_Smooth"
    },
    {
      "x": -7,
      "y": 6,
      "z": 8,
      "name": "Rock_Aqua_Brick_Smooth"
    },
    {
      "x": -7,
      "y": 7,
      "z": 8,
      "name": "Rock_Aqua_Brick_Smooth"
    },
    {
      "x": -7,
      "y": 8,
      "z": 8,
      "name": "Rock_Aqua_Brick_Smooth"
    },
    {
      "x": -7,
      "y": 9,
      "z": 8,
      "name": "Rock_Aqua_Brick_Smooth"
    },
    {
      "x": -7,
      "y": 10,
      "z": 8,
      "name": "Rock_Aqua_Brick_Smooth"
    },
    {
      "x": -7,
      "y": 11,
      "z": 8,
      "name": "Rock_Aqua_Brick_Smooth"
    },
    {
      "x": -7,
      "y": 12,
      "z": 8,
      "name": "Rock_Aqua_Brick_Smooth"
    },
    {
      "x": -7,
      "y": 13,
      "z": 8,
      "name": "Rock_Aqua_Brick_Smooth"
    },
    {
      "x": -7,
      "y": 14,
      "z": 8,
      "name": "Rock_Aqua_Brick_Smooth"
    },
    {
      "x": -7,
      "y": 15,
      "z": 8,
      "name": "Rock_Aqua_Brick_Smooth"
    },
    {
      "x": -7,
      "y": 16,
      "z": 8,
      "name": "Rock_Aqua_Brick_Smooth"
    },
    {
      "x": -7,
      "y": 17,
      "z": 8,
      "name": "*Rock_Aqua_Cobble_Roof_State_Definitions_Corner_Left",
      "rotation": 3
    },
    {
      "x": -7,
      "y": 16,
      "z": 9,
      "name": "Rock_Aqua_Cobble_Roof_Hollow"
    },
    {
      "x": -6,
      "y": 16,
      "z": -10,
      "name": "*Rock_Aqua_Cobble_Roof_Hollow_State_Definitions_Corner_Right",
      "rotation": 3
    },
    {
      "x": -6,
      "y": 16,
      "z": -9,
      "name": "*Rock_Aqua_Cobble_Roof_Hollow_State_Definitions_Inverted_Corner_Left",
      "rotation": 2
    },
    {
      "x": -6,
      "y": 0,
      "z": -8,
      "name": "Rock_Aqua_Brick_Smooth"
    },
    {
      "x": -6,
      "y": 1,
      "z": -8,
      "name": "Rock_Aqua_Brick_Smooth"
    },
    {
      "x": -6,
      "y": 2,
      "z": -8,
      "name": "Rock_Aqua_Brick_Smooth"
    },
    {
      "x": -6,
      "y": 3,
      "z": -8,
      "name": "Rock_Aqua_Brick_Smooth"
    },
    {
      "x": -6,
      "y": 4,
      "z": -8,
      "name": "Rock_Aqua_Brick_Smooth"
    },
    {
      "x": -6,
      "y": 5,
      "z": -8,
      "name": "Rock_Aqua_Brick_Smooth"
    },
    {
      "x": -6,
      "y": 6,
      "z": -8,
      "name": "Rock_Aqua_Brick_Smooth"
    },
    {
      "x": -6,
      "y": 7,
      "z": -8,
      "name": "Rock_Aqua_Brick_Smooth"
    },
    {
      "x": -6,
      "y": 8,
      "z": -8,
      "name": "Rock_Aqua_Brick_Smooth"
    },
    {
      "x": -6,
      "y": 9,
      "z": -8,
      "name": "Rock_Aqua_Brick_Smooth"
    },
    {
      "x": -6,
      "y": 10,
      "z": -8,
      "name": "Rock_Aqua_Brick_Smooth"
    },
    {
      "x": -6,
      "y": 11,
      "z": -8,
      "name": "Rock_Aqua_Brick_Smooth"
    },
    {
      "x": -6,
      "y": 12,
      "z": -8,
      "name": "Rock_Aqua_Brick_Smooth"
    },
    {
      "x": -6,
      "y": 13,
      "z": -8,
      "name": "Rock_Aqua_Brick_Smooth"
    },
    {
      "x": -6,
      "y": 14,
      "z": -8,
      "name": "Rock_Aqua_Brick_Smooth"
    },
    {
      "x": -6,
      "y": 15,
      "z": -8,
      "name": "Rock_Aqua_Brick_Smooth"
    },
    {
      "x": -6,
      "y": 16,
      "z": -8,
      "name": "Rock_Aqua_Brick_Smooth",
      "rotation": 3
    },
    {
      "x": -6,
      "y": 17,
      "z": -8,
      "name": "Rock_Aqua_Cobble_Roof",
      "rotation": 2
    },
    {
      "x": -6,
      "y": 0,
      "z": -7,
      "name": "Rock_Aqua_Brick"
    },
    {
      "x": -6,
      "y": 8,
      "z": -7,
      "name": "Rock_Aqua_Brick"
    },
    {
      "x": -6,
      "y": 9,
      "z": -7,
      "name": "Rock_Aqua_Brick"
    },
    {
      "x": -6,
      "y": 18,
      "z": -7,
      "name": "*Rock_Aqua_Cobble_Roof_Hollow_State_Definitions_Corner_Left",
      "rotation": 2
    },
    {
      "x": -6,
      "y": 0,
      "z": -6,
      "name": "Rock_Aqua_Brick"
    },
    {
      "x": -6,
      "y": 8,
      "z": -6,
      "name": "Rock_Aqua_Brick"
    },
    {
      "x": -6,
      "y": 9,
      "z": -6,
      "name": "Rock_Aqua_Brick"
    },
    {
      "x": -6,
      "y": 18,
      "z": -6,
      "name": "*Rock_Aqua_Cobble_Roof_Hollow_State_Definitions_Inverted_Corner_Right",
      "rotation": 3
    },
    {
      "x": -6,
      "y": 0,
      "z": -5,
      "name": "Rock_Aqua_Brick"
    },
    {
      "x": -6,
      "y": 8,
      "z": -5,
      "name": "Rock_Aqua_Brick"
    },
    {
      "x": -6,
      "y": 9,
      "z": -5,
      "name": "Rock_Aqua_Brick"
    },
    {
      "x": -6,
      "y": 19,
      "z": -5,
      "name": "*Rock_Aqua_Cobble_Roof_Hollow_State_Definitions_Corner_Left",
      "rotation": 2
    },
    {
      "x": -6,
      "y": 0,
      "z": -4,
      "name": "Rock_Aqua_Brick"
    },
    {
      "x": -6,
      "y": 8,
      "z": -4,
      "name": "Rock_Aqua_Brick"
    },
    {
      "x": -6,
      "y": 9,
      "z": -4,
      "name": "Rock_Aqua_Brick"
    },
    {
      "x": -6,
      "y": 19,
      "z": -4,
      "name": "Rock_Aqua_Cobble_Roof_Hollow",
      "rotation": 3
    },
    {
      "x": -6,
      "y": 0,
      "z": -3,
      "name": "Rock_Aqua_Brick"
    },
    {
      "x": -6,
      "y": 8,
      "z": -3,
      "name": "Rock_Aqua_Brick"
    },
    {
      "x": -6,
      "y": 9,
      "z": -3,
      "name": "Rock_Aqua_Brick"
    },
    {
      "x": -6,
      "y": 19,
      "z": -3,
      "name": "Rock_Aqua_Cobble_Roof_Shallow",
      "filler": 1,
      "rotation": 3
    },
    {
      "x": -6,
      "y": 0,
      "z": -2,
      "name": "Rock_Aqua_Brick"
    },
    {
      "x": -6,
      "y": 8,
      "z": -2,
      "name": "Rock_Aqua_Brick"
    },
    {
      "x": -6,
      "y": 9,
      "z": -2,
      "name": "Rock_Aqua_Brick"
    },
    {
      "x": -6,
      "y": 19,
      "z": -2,
      "name": "Rock_Aqua_Cobble_Roof_Shallow",
      "filler": 1,
      "rotation": 3
    },
    {
      "x": -6,
      "y": 0,
      "z": -1,
      "name": "Rock_Aqua_Brick"
    },
    {
      "x": -6,
      "y": 8,
      "z": -1,
      "name": "Rock_Aqua_Brick"
    },
    {
      "x": -6,
      "y": 9,
      "z": -1,
      "name": "Rock_Aqua_Brick"
    },
    {
      "x": -6,
      "y": 19,
      "z": -1,
      "name": "Rock_Aqua_Cobble_Roof_Shallow",
      "filler": 1,
      "rotation": 3
    },
    {
      "x": -6,
      "y": 0,
      "z": 0,
      "name": "Rock_Aqua_Brick"
    },
    {
      "x": -6,
      "y": 8,
      "z": 0,
      "name": "Rock_Aqua_Brick"
    },
    {
      "x": -6,
      "y": 9,
      "z": 0,
      "name": "Rock_Aqua_Brick"
    },
    {
      "x": -6,
      "y": 19,
      "z": 0,
      "name": "Rock_Aqua_Cobble_Roof_Shallow",
      "filler": 1,
      "rotation": 3
    },
    {
      "x": -6,
      "y": 0,
      "z": 1,
      "name": "Rock_Aqua_Brick"
    },
    {
      "x": -6,
      "y": 8,
      "z": 1,
      "name": "Rock_Aqua_Brick"
    },
    {
      "x": -6,
      "y": 9,
      "z": 1,
      "name": "Rock_Aqua_Brick"
    },
    {
      "x": -6,
      "y": 19,
      "z": 1,
      "name": "Rock_Aqua_Cobble_Roof_Shallow",
      "filler": 1,
      "rotation": 3
    },
    {
      "x": -6,
      "y": 0,
      "z": 2,
      "name": "Rock_Aqua_Brick"
    },
    {
      "x": -6,
      "y": 8,
      "z": 2,
      "name": "Rock_Aqua_Brick"
    },
    {
      "x": -6,
      "y": 9,
      "z": 2,
      "name": "Rock_Aqua_Brick"
    },
    {
      "x": -6,
      "y": 19,
      "z": 2,
      "name": "Rock_Aqua_Cobble_Roof_Shallow",
      "filler": 1,
      "rotation": 3
    },
    {
      "x": -6,
      "y": 0,
      "z": 3,
      "name": "Rock_Aqua_Brick"
    },
    {
      "x": -6,
      "y": 8,
      "z": 3,
      "name": "Rock_Aqua_Brick"
    },
    {
      "x": -6,
      "y": 9,
      "z": 3,
      "name": "Rock_Aqua_Brick"
    },
    {
      "x": -6,
      "y": 19,
      "z": 3,
      "name": "Rock_Aqua_Cobble_Roof_Shallow",
      "filler": 1,
      "rotation": 3
    },
    {
      "x": -6,
      "y": 0,
      "z": 4,
      "name": "Rock_Aqua_Brick"
    },
    {
      "x": -6,
      "y": 8,
      "z": 4,
      "name": "Rock_Aqua_Brick"
    },
    {
      "x": -6,
      "y": 9,
      "z": 4,
      "name": "Rock_Aqua_Brick"
    },
    {
      "x": -6,
      "y": 19,
      "z": 4,
      "name": "Rock_Aqua_Cobble_Roof_Hollow",
      "rotation": 3
    },
    {
      "x": -6,
      "y": 0,
      "z": 5,
      "name": "Rock_Aqua_Brick"
    },
    {
      "x": -6,
      "y": 8,
      "z": 5,
      "name": "Rock_Aqua_Brick"
    },
    {
      "x": -6,
      "y": 9,
      "z": 5,
      "name": "Rock_Aqua_Brick"
    },
    {
      "x": -6,
      "y": 19,
      "z": 5,
      "name": "*Rock_Aqua_Cobble_Roof_Hollow_State_Definitions_Corner_Left",
      "rotation": 3
    },
    {
      "x": -6,
      "y": 0,
      "z": 6,
      "name": "Rock_Aqua_Brick"
    },
    {
      "x": -6,
      "y": 8,
      "z": 6,
      "name": "Rock_Aqua_Brick"
    },
    {
      "x": -6,
      "y": 9,
      "z": 6,
      "name": "Rock_Aqua_Brick"
    },
    {
      "x": -6,
      "y": 18,
      "z": 6,
      "name": "*Rock_Aqua_Cobble_Roof_Hollow_State_Definitions_Inverted_Corner_Right"
    },
    {
      "x": -6,
      "y": 0,
      "z": 7,
      "name": "Rock_Aqua_Brick"
    },
    {
      "x": -6,
      "y": 8,
      "z": 7,
      "name": "Rock_Aqua_Brick"
    },
    {
      "x": -6,
      "y": 9,
      "z": 7,
      "name": "Rock_Aqua_Brick"
    },
    {
      "x": -6,
      "y": 18,
      "z": 7,
      "name": "*Rock_Aqua_Cobble_Roof_Hollow_State_Definitions_Corner_Left",
      "rotation": 3
    },
    {
      "x": -6,
      "y": 0,
      "z": 8,
      "name": "Rock_Aqua_Brick_Smooth"
    },
    {
      "x": -6,
      "y": 1,
      "z": 8,
      "name": "Rock_Aqua_Brick_Smooth"
    },
    {
      "x": -6,
      "y": 2,
      "z": 8,
      "name": "Rock_Aqua_Brick_Smooth"
    },
    {
      "x": -6,
      "y": 3,
      "z": 8,
      "name": "Rock_Aqua_Brick_Smooth"
    },
    {
      "x": -6,
      "y": 4,
      "z": 8,
      "name": "Rock_Aqua_Brick_Smooth"
    },
    {
      "x": -6,
      "y": 5,
      "z": 8,
      "name": "Rock_Aqua_Brick_Smooth"
    },
    {
      "x": -6,
      "y": 6,
      "z": 8,
      "name": "Rock_Aqua_Brick_Smooth"
    },
    {
      "x": -6,
      "y": 7,
      "z": 8,
      "name": "Rock_Aqua_Brick_Smooth"
    },
    {
      "x": -6,
      "y": 8,
      "z": 8,
      "name": "Rock_Aqua_Brick_Smooth"
    },
    {
      "x": -6,
      "y": 9,
      "z": 8,
      "name": "Rock_Aqua_Brick_Smooth"
    },
    {
      "x": -6,
      "y": 10,
      "z": 8,
      "name": "Rock_Aqua_Brick_Smooth"
    },
    {
      "x": -6,
      "y": 11,
      "z": 8,
      "name": "Rock_Aqua_Brick_Smooth"
    },
    {
      "x": -6,
      "y": 12,
      "z": 8,
      "name": "Rock_Aqua_Brick_Smooth"
    },
    {
      "x": -6,
      "y": 13,
      "z": 8,
      "name": "Rock_Aqua_Brick_Smooth"
    },
    {
      "x": -6,
      "y": 14,
      "z": 8,
      "name": "Rock_Aqua_Brick_Smooth"
    },
    {
      "x": -6,
      "y": 15,
      "z": 8,
      "name": "Rock_Aqua_Brick_Smooth"
    },
    {
      "x": -6,
      "y": 16,
      "z": 8,
      "name": "Rock_Aqua_Brick_Smooth"
    },
    {
      "x": -6,
      "y": 17,
      "z": 8,
      "name": "Rock_Aqua_Cobble_Roof"
    },
    {
      "x": -6,
      "y": 16,
      "z": 9,
      "name": "*Rock_Aqua_Cobble_Roof_Hollow_State_Definitions_Inverted_Corner_Left",
      "rotation": 3
    },
    {
      "x": -6,
      "y": 16,
      "z": 10,
      "name": "*Rock_Aqua_Cobble_Roof_Hollow_State_Definitions_Corner_Left",
      "rotation": 3
    },
    {
      "x": -5,
      "y": 16,
      "z": -10,
      "name": "Rock_Aqua_Cobble_Roof_Hollow",
      "rotation": 2
    },
    {
      "x": -5,
      "y": 0,
      "z": -9,
      "name": "Rock_Aqua_Brick_Smooth"
    },
    {
      "x": -5,
      "y": 1,
      "z": -9,
      "name": "Rock_Aqua_Brick_Smooth"
    },
    {
      "x": -5,
      "y": 2,
      "z": -9,
      "name": "Rock_Aqua_Brick_Smooth"
    },
    {
      "x": -5,
      "y": 3,
      "z": -9,
      "name": "Rock_Aqua_Brick_Smooth"
    },
    {
      "x": -5,
      "y": 4,
      "z": -9,
      "name": "Rock_Aqua_Brick_Smooth"
    },
    {
      "x": -5,
      "y": 5,
      "z": -9,
      "name": "Rock_Aqua_Brick_Smooth"
    },
    {
      "x": -5,
      "y": 6,
      "z": -9,
      "name": "Rock_Aqua_Brick_Smooth"
    },
    {
      "x": -5,
      "y": 7,
      "z": -9,
      "name": "Rock_Aqua_Brick_Smooth"
    },
    {
      "x": -5,
      "y": 8,
      "z": -9,
      "name": "Rock_Aqua_Brick_Smooth"
    },
    {
      "x": -5,
      "y": 9,
      "z": -9,
      "name": "Rock_Aqua_Brick_Smooth"
    },
    {
      "x": -5,
      "y": 10,
      "z": -9,
      "name": "Rock_Aqua_Brick_Smooth"
    },
    {
      "x": -5,
      "y": 11,
      "z": -9,
      "name": "Rock_Aqua_Brick_Smooth"
    },
    {
      "x": -5,
      "y": 12,
      "z": -9,
      "name": "Rock_Aqua_Brick_Smooth"
    },
    {
      "x": -5,
      "y": 13,
      "z": -9,
      "name": "Rock_Aqua_Brick_Smooth"
    },
    {
      "x": -5,
      "y": 14,
      "z": -9,
      "name": "Rock_Aqua_Brick_Smooth"
    },
    {
      "x": -5,
      "y": 15,
      "z": -9,
      "name": "Rock_Aqua_Brick_Smooth"
    },
    {
      "x": -5,
      "y": 16,
      "z": -9,
      "name": "Rock_Aqua_Brick_Smooth",
      "rotation": 3
    },
    {
      "x": -5,
      "y": 17,
      "z": -9,
      "name": "*Rock_Aqua_Cobble_Roof_State_Definitions_Corner_Left",
      "rotation": 2
    },
    {
      "x": -5,
      "y": 0,
      "z": -8,
      "name": "Rock_Aqua_Brick"
    },
    {
      "x": -5,
      "y": 8,
      "z": -8,
      "name": "Rock_Aqua_Brick"
    },
    {
      "x": -5,
      "y": 9,
      "z": -8,
      "name": "Rock_Aqua_Brick"
    },
    {
      "x": -5,
      "y": 17,
      "z": -8,
      "name": "*Rock_Aqua_Cobble_Roof_Hollow_State_Definitions_Inverted_Corner_Right",
      "rotation": 3
    },
    {
      "x": -5,
      "y": 0,
      "z": -7,
      "name": "Rock_Aqua_Brick"
    },
    {
      "x": -5,
      "y": 8,
      "z": -7,
      "name": "Rock_Aqua_Brick"
    },
    {
      "x": -5,
      "y": 9,
      "z": -7,
      "name": "Rock_Aqua_Brick"
    },
    {
      "x": -5,
      "y": 18,
      "z": -7,
      "name": "Rock_Aqua_Cobble_Roof_Hollow",
      "rotation": 2
    },
    {
      "x": -5,
      "y": 0,
      "z": -6,
      "name": "Rock_Aqua_Brick"
    },
    {
      "x": -5,
      "y": 8,
      "z": -6,
      "name": "Rock_Aqua_Brick"
    },
    {
      "x": -5,
      "y": 9,
      "z": -6,
      "name": "Rock_Aqua_Brick"
    },
    {
      "x": -5,
      "y": 19,
      "z": -6,
      "name": "*Rock_Aqua_Cobble_Roof_Hollow_State_Definitions_Corner_Left",
      "rotation": 2
    },
    {
      "x": -5,
      "y": 0,
      "z": -5,
      "name": "Rock_Aqua_Brick"
    },
    {
      "x": -5,
      "y": 8,
      "z": -5,
      "name": "Rock_Aqua_Brick"
    },
    {
      "x": -5,
      "y": 9,
      "z": -5,
      "name": "Rock_Aqua_Brick"
    },
    {
      "x": -5,
      "y": 19,
      "z": -5,
      "name": "*Rock_Aqua_Cobble_Roof_Hollow_State_Definitions_Inverted_Corner_Right",
      "rotation": 3
    },
    {
      "x": -5,
      "y": 0,
      "z": -4,
      "name": "Rock_Aqua_Brick"
    },
    {
      "x": -5,
      "y": 8,
      "z": -4,
      "name": "Rock_Aqua_Brick"
    },
    {
      "x": -5,
      "y": 9,
      "z": -4,
      "name": "Rock_Aqua_Brick"
    },
    {
      "x": -5,
      "y": 20,
      "z": -4,
      "name": "Rock_Aqua_Cobble_Roof_Flat",
      "rotation": 3
    },
    {
      "x": -5,
      "y": 0,
      "z": -3,
      "name": "Rock_Aqua_Brick"
    },
    {
      "x": -5,
      "y": 8,
      "z": -3,
      "name": "Rock_Aqua_Brick"
    },
    {
      "x": -5,
      "y": 9,
      "z": -3,
      "name": "Rock_Aqua_Brick"
    },
    {
      "x": -5,
      "y": 20,
      "z": -3,
      "name": "Rock_Aqua_Cobble_Roof_Flat",
      "rotation": 3
    },
    {
      "x": -5,
      "y": 0,
      "z": -2,
      "name": "Rock_Aqua_Brick"
    },
    {
      "x": -5,
      "y": 8,
      "z": -2,
      "name": "Rock_Aqua_Brick"
    },
    {
      "x": -5,
      "y": 9,
      "z": -2,
      "name": "Rock_Aqua_Brick"
    },
    {
      "x": -5,
      "y": 20,
      "z": -2,
      "name": "Rock_Aqua_Cobble_Roof_Flat",
      "rotation": 3
    },
    {
      "x": -5,
      "y": 0,
      "z": -1,
      "name": "Rock_Aqua_Brick"
    },
    {
      "x": -5,
      "y": 8,
      "z": -1,
      "name": "Rock_Aqua_Brick"
    },
    {
      "x": -5,
      "y": 9,
      "z": -1,
      "name": "Rock_Aqua_Brick"
    },
    {
      "x": -5,
      "y": 19,
      "z": -1,
      "name": "Rock_Aqua_Brick",
      "rotation": 3
    },
    {
      "x": -5,
      "y": 20,
      "z": -1,
      "name": "Rock_Aqua_Brick_Decorative"
    },
    {
      "x": -5,
      "y": 21,
      "z": -1,
      "name": "Rock_Aqua_Brick"
    },
    {
      "x": -5,
      "y": 24,
      "z": -1,
      "name": "Rock_Aqua_Brick_Smooth"
    },
    {
      "x": -5,
      "y": 25,
      "z": -1,
      "name": "*Rock_Aqua_Cobble_Roof_State_Definitions_Corner_Right",
      "rotation": 3
    },
    {
      "x": -5,
      "y": 0,
      "z": 0,
      "name": "Rock_Aqua_Brick"
    },
    {
      "x": -5,
      "y": 8,
      "z": 0,
      "name": "Rock_Aqua_Brick"
    },
    {
      "x": -5,
      "y": 9,
      "z": 0,
      "name": "Rock_Aqua_Brick"
    },
    {
      "x": -5,
      "y": 19,
      "z": 0,
      "name": "Rock_Aqua_Brick",
      "rotation": 3
    },
    {
      "x": -5,
      "y": 20,
      "z": 0,
      "name": "Rock_Aqua_Brick_Decorative"
    },
    {
      "x": -5,
      "y": 21,
      "z": 0,
      "name": "Rock_Aqua_Brick_Ornate"
    },
    {
      "x": -5,
      "y": 24,
      "z": 0,
      "name": "Rock_Aqua_Brick_Ornate"
    },
    {
      "x": -5,
      "y": 25,
      "z": 0,
      "name": "Rock_Aqua_Cobble_Roof",
      "rotation": 3
    },
    {
      "x": -5,
      "y": 0,
      "z": 1,
      "name": "Rock_Aqua_Brick"
    },
    {
      "x": -5,
      "y": 8,
      "z": 1,
      "name": "Rock_Aqua_Brick"
    },
    {
      "x": -5,
      "y": 9,
      "z": 1,
      "name": "Rock_Aqua_Brick"
    },
    {
      "x": -5,
      "y": 19,
      "z": 1,
      "name": "Rock_Aqua_Brick"
    },
    {
      "x": -5,
      "y": 20,
      "z": 1,
      "name": "Rock_Aqua_Brick_Decorative"
    },
    {
      "x": -5,
      "y": 21,
      "z": 1,
      "name": "Rock_Aqua_Brick"
    },
    {
      "x": -5,
      "y": 24,
      "z": 1,
      "name": "Rock_Aqua_Brick_Smooth"
    },
    {
      "x": -5,
      "y": 25,
      "z": 1,
      "name": "*Rock_Aqua_Cobble_Roof_State_Definitions_Corner_Right"
    },
    {
      "x": -5,
      "y": 0,
      "z": 2,
      "name": "Rock_Aqua_Brick"
    },
    {
      "x": -5,
      "y": 8,
      "z": 2,
      "name": "Rock_Aqua_Brick"
    },
    {
      "x": -5,
      "y": 9,
      "z": 2,
      "name": "Rock_Aqua_Brick"
    },
    {
      "x": -5,
      "y": 20,
      "z": 2,
      "name": "Rock_Aqua_Cobble_Roof_Flat"
    },
    {
      "x": -5,
      "y": 0,
      "z": 3,
      "name": "Rock_Aqua_Brick"
    },
    {
      "x": -5,
      "y": 8,
      "z": 3,
      "name": "Rock_Aqua_Brick"
    },
    {
      "x": -5,
      "y": 9,
      "z": 3,
      "name": "Rock_Aqua_Brick"
    },
    {
      "x": -5,
      "y": 20,
      "z": 3,
      "name": "Rock_Aqua_Cobble_Roof_Flat"
    },
    {
      "x": -5,
      "y": 0,
      "z": 4,
      "name": "Rock_Aqua_Brick"
    },
    {
      "x": -5,
      "y": 8,
      "z": 4,
      "name": "Rock_Aqua_Brick"
    },
    {
      "x": -5,
      "y": 9,
      "z": 4,
      "name": "Rock_Aqua_Brick"
    },
    {
      "x": -5,
      "y": 20,
      "z": 4,
      "name": "Rock_Aqua_Cobble_Roof_Flat"
    },
    {
      "x": -5,
      "y": 0,
      "z": 5,
      "name": "Rock_Aqua_Brick"
    },
    {
      "x": -5,
      "y": 8,
      "z": 5,
      "name": "Rock_Aqua_Brick"
    },
    {
      "x": -5,
      "y": 9,
      "z": 5,
      "name": "Rock_Aqua_Brick"
    },
    {
      "x": -5,
      "y": 19,
      "z": 5,
      "name": "*Rock_Aqua_Cobble_Roof_Hollow_State_Definitions_Inverted_Corner_Right"
    },
    {
      "x": -5,
      "y": 0,
      "z": 6,
      "name": "Rock_Aqua_Brick"
    },
    {
      "x": -5,
      "y": 8,
      "z": 6,
      "name": "Rock_Aqua_Brick"
    },
    {
      "x": -5,
      "y": 9,
      "z": 6,
      "name": "Rock_Aqua_Brick"
    },
    {
      "x": -5,
      "y": 19,
      "z": 6,
      "name": "*Rock_Aqua_Cobble_Roof_Hollow_State_Definitions_Corner_Left",
      "rotation": 3
    },
    {
      "x": -5,
      "y": 0,
      "z": 7,
      "name": "Rock_Aqua_Brick"
    },
    {
      "x": -5,
      "y": 8,
      "z": 7,
      "name": "Rock_Aqua_Brick"
    },
    {
      "x": -5,
      "y": 9,
      "z": 7,
      "name": "Rock_Aqua_Brick"
    },
    {
      "x": -5,
      "y": 18,
      "z": 7,
      "name": "Rock_Aqua_Cobble_Roof_Hollow"
    },
    {
      "x": -5,
      "y": 0,
      "z": 8,
      "name": "Rock_Aqua_Brick"
    },
    {
      "x": -5,
      "y": 8,
      "z": 8,
      "name": "Rock_Aqua_Brick"
    },
    {
      "x": -5,
      "y": 9,
      "z": 8,
      "name": "Rock_Aqua_Brick"
    },
    {
      "x": -5,
      "y": 17,
      "z": 8,
      "name": "*Rock_Aqua_Cobble_Roof_Hollow_State_Definitions_Inverted_Corner_Right"
    },
    {
      "x": -5,
      "y": 0,
      "z": 9,
      "name": "Rock_Aqua_Brick_Smooth"
    },
    {
      "x": -5,
      "y": 1,
      "z": 9,
      "name": "Rock_Aqua_Brick_Smooth"
    },
    {
      "x": -5,
      "y": 2,
      "z": 9,
      "name": "Rock_Aqua_Brick_Smooth"
    },
    {
      "x": -5,
      "y": 3,
      "z": 9,
      "name": "Rock_Aqua_Brick_Smooth"
    },
    {
      "x": -5,
      "y": 4,
      "z": 9,
      "name": "Rock_Aqua_Brick_Smooth"
    },
    {
      "x": -5,
      "y": 5,
      "z": 9,
      "name": "Rock_Aqua_Brick_Smooth"
    },
    {
      "x": -5,
      "y": 6,
      "z": 9,
      "name": "Rock_Aqua_Brick_Smooth"
    },
    {
      "x": -5,
      "y": 7,
      "z": 9,
      "name": "Rock_Aqua_Brick_Smooth"
    },
    {
      "x": -5,
      "y": 8,
      "z": 9,
      "name": "Rock_Aqua_Brick_Smooth"
    },
    {
      "x": -5,
      "y": 9,
      "z": 9,
      "name": "Rock_Aqua_Brick_Smooth"
    },
    {
      "x": -5,
      "y": 10,
      "z": 9,
      "name": "Rock_Aqua_Brick_Smooth"
    },
    {
      "x": -5,
      "y": 11,
      "z": 9,
      "name": "Rock_Aqua_Brick_Smooth"
    },
    {
      "x": -5,
      "y": 12,
      "z": 9,
      "name": "Rock_Aqua_Brick_Smooth"
    },
    {
      "x": -5,
      "y": 13,
      "z": 9,
      "name": "Rock_Aqua_Brick_Smooth"
    },
    {
      "x": -5,
      "y": 14,
      "z": 9,
      "name": "Rock_Aqua_Brick_Smooth"
    },
    {
      "x": -5,
      "y": 15,
      "z": 9,
      "name": "Rock_Aqua_Brick_Smooth"
    },
    {
      "x": -5,
      "y": 16,
      "z": 9,
      "name": "Rock_Aqua_Brick_Smooth"
    },
    {
      "x": -5,
      "y": 17,
      "z": 9,
      "name": "*Rock_Aqua_Cobble_Roof_State_Definitions_Corner_Left",
      "rotation": 3
    },
    {
      "x": -5,
      "y": 16,
      "z": 10,
      "name": "Rock_Aqua_Cobble_Roof_Hollow"
    },
    {
      "x": -4,
      "y": 16,
      "z": -10,
      "name": "Rock_Aqua_Cobble_Roof_Hollow",
      "rotation": 2
    },
    {
      "x": -4,
      "y": 0,
      "z": -9,
      "name": "Rock_Aqua_Brick_Smooth"
    },
    {
      "x": -4,
      "y": 1,
      "z": -9,
      "name": "Rock_Aqua_Brick_Smooth"
    },
    {
      "x": -4,
      "y": 2,
      "z": -9,
      "name": "Rock_Aqua_Brick_Smooth"
    },
    {
      "x": -4,
      "y": 3,
      "z": -9,
      "name": "Rock_Aqua_Brick_Smooth"
    },
    {
      "x": -4,
      "y": 4,
      "z": -9,
      "name": "Rock_Aqua_Brick_Smooth"
    },
    {
      "x": -4,
      "y": 5,
      "z": -9,
      "name": "Rock_Aqua_Brick_Smooth"
    },
    {
      "x": -4,
      "y": 6,
      "z": -9,
      "name": "Rock_Aqua_Brick_Smooth"
    },
    {
      "x": -4,
      "y": 7,
      "z": -9,
      "name": "Rock_Aqua_Brick_Smooth"
    },
    {
      "x": -4,
      "y": 8,
      "z": -9,
      "name": "Rock_Aqua_Brick_Smooth"
    },
    {
      "x": -4,
      "y": 9,
      "z": -9,
      "name": "Rock_Aqua_Brick_Smooth"
    },
    {
      "x": -4,
      "y": 10,
      "z": -9,
      "name": "Rock_Aqua_Brick_Smooth"
    },
    {
      "x": -4,
      "y": 11,
      "z": -9,
      "name": "Rock_Aqua_Brick_Smooth"
    },
    {
      "x": -4,
      "y": 12,
      "z": -9,
      "name": "Rock_Aqua_Brick_Smooth"
    },
    {
      "x": -4,
      "y": 13,
      "z": -9,
      "name": "Rock_Aqua_Brick_Smooth"
    },
    {
      "x": -4,
      "y": 14,
      "z": -9,
      "name": "Rock_Aqua_Brick_Smooth"
    },
    {
      "x": -4,
      "y": 15,
      "z": -9,
      "name": "Rock_Aqua_Brick_Smooth"
    },
    {
      "x": -4,
      "y": 16,
      "z": -9,
      "name": "Rock_Aqua_Brick_Smooth",
      "rotation": 3
    },
    {
      "x": -4,
      "y": 17,
      "z": -9,
      "name": "Rock_Aqua_Cobble_Roof",
      "rotation": 2
    },
    {
      "x": -4,
      "y": 0,
      "z": -8,
      "name": "Rock_Aqua_Brick"
    },
    {
      "x": -4,
      "y": 8,
      "z": -8,
      "name": "Rock_Aqua_Brick"
    },
    {
      "x": -4,
      "y": 9,
      "z": -8,
      "name": "Rock_Aqua_Brick"
    },
    {
      "x": -4,
      "y": 18,
      "z": -8,
      "name": "*Rock_Aqua_Cobble_Roof_Hollow_State_Definitions_Corner_Left",
      "rotation": 2
    },
    {
      "x": -4,
      "y": 0,
      "z": -7,
      "name": "Rock_Aqua_Brick"
    },
    {
      "x": -4,
      "y": 8,
      "z": -7,
      "name": "Rock_Aqua_Brick"
    },
    {
      "x": -4,
      "y": 9,
      "z": -7,
      "name": "Rock_Aqua_Brick"
    },
    {
      "x": -4,
      "y": 18,
      "z": -7,
      "name": "*Rock_Aqua_Cobble_Roof_Hollow_State_Definitions_Inverted_Corner_Right",
      "rotation": 3
    },
    {
      "x": -4,
      "y": 0,
      "z": -6,
      "name": "Rock_Aqua_Brick"
    },
    {
      "x": -4,
      "y": 8,
      "z": -6,
      "name": "Rock_Aqua_Brick"
    },
    {
      "x": -4,
      "y": 9,
      "z": -6,
      "name": "Rock_Aqua_Brick"
    },
    {
      "x": -4,
      "y": 19,
      "z": -6,
      "name": "Rock_Aqua_Cobble_Roof_Hollow",
      "rotation": 2
    },
    {
      "x": -4,
      "y": 0,
      "z": -5,
      "name": "Rock_Aqua_Brick"
    },
    {
      "x": -4,
      "y": 8,
      "z": -5,
      "name": "Rock_Aqua_Brick"
    },
    {
      "x": -4,
      "y": 9,
      "z": -5,
      "name": "Rock_Aqua_Brick"
    },
    {
      "x": -4,
      "y": 20,
      "z": -5,
      "name": "Rock_Aqua_Cobble_Roof_Flat",
      "rotation": 3
    },
    {
      "x": -4,
      "y": 0,
      "z": -4,
      "name": "Rock_Aqua_Brick"
    },
    {
      "x": -4,
      "y": 8,
      "z": -4,
      "name": "Rock_Aqua_Brick"
    },
    {
      "x": -4,
      "y": 9,
      "z": -4,
      "name": "Rock_Aqua_Brick"
    },
    {
      "x": -4,
      "y": 20,
      "z": -4,
      "name": "Rock_Aqua_Cobble_Roof_Flat",
      "rotation": 1
    },
    {
      "x": -4,
      "y": 0,
      "z": -3,
      "name": "Rock_Aqua_Brick"
    },
    {
      "x": -4,
      "y": 8,
      "z": -3,
      "name": "Rock_Aqua_Brick"
    },
    {
      "x": -4,
      "y": 9,
      "z": -3,
      "name": "Rock_Aqua_Brick"
    },
    {
      "x": -4,
      "y": 19,
      "z": -3,
      "name": "Rock_Aqua_Brick",
      "rotation": 3
    },
    {
      "x": -4,
      "y": 20,
      "z": -3,
      "name": "Rock_Aqua_Brick_Decorative"
    },
    {
      "x": -4,
      "y": 24,
      "z": -3,
      "name": "Rock_Aqua_Brick_Smooth"
    },
    {
      "x": -4,
      "y": 25,
      "z": -3,
      "name": "*Rock_Aqua_Cobble_Roof_State_Definitions_Corner_Right",
      "rotation": 3
    },
    {
      "x": -4,
      "y": 0,
      "z": -2,
      "name": "Rock_Aqua_Brick"
    },
    {
      "x": -4,
      "y": 8,
      "z": -2,
      "name": "Rock_Aqua_Brick"
    },
    {
      "x": -4,
      "y": 9,
      "z": -2,
      "name": "Rock_Aqua_Brick"
    },
    {
      "x": -4,
      "y": 19,
      "z": -2,
      "name": "Rock_Aqua_Brick",
      "rotation": 3
    },
    {
      "x": -4,
      "y": 20,
      "z": -2,
      "name": "Rock_Aqua_Brick_Decorative"
    },
    {
      "x": -4,
      "y": 21,
      "z": -2,
      "name": "Rock_Aqua_Brick_Pillar_Base"
    },
    {
      "x": -4,
      "y": 22,
      "z": -2,
      "name": "Rock_Aqua_Brick_Pillar_Middle"
    },
    {
      "x": -4,
      "y": 23,
      "z": -2,
      "name": "Rock_Aqua_Brick_Pillar_Base",
      "rotation": 8
    },
    {
      "x": -4,
      "y": 24,
      "z": -2,
      "name": "Rock_Aqua_Brick_Ornate"
    },
    {
      "x": -4,
      "y": 25,
      "z": -2,
      "name": "Rock_Aqua_Cobble_Roof",
      "rotation": 3
    },
    {
      "x": -4,
      "y": 0,
      "z": -1,
      "name": "Rock_Aqua_Brick"
    },
    {
      "x": -4,
      "y": 25,
      "z": -1,
      "name": "*Rock_Aqua_Cobble_Roof_Hollow_State_Definitions_Inverted_Corner_Left",
      "rotation": 2
    },
    {
      "x": -4,
      "y": 0,
      "z": 0,
      "name": "Rock_Aqua_Brick"
    },
    {
      "x": -4,
      "y": 26,
      "z": 0,
      "name": "Rock_Aqua_Cobble_Roof_Flat",
      "rotation": 1
    },
    {
      "x": -4,
      "y": 0,
      "z": 1,
      "name": "Rock_Aqua_Brick"
    },
    {
      "x": -4,
      "y": 25,
      "z": 1,
      "name": "*Rock_Aqua_Cobble_Roof_Hollow_State_Definitions_Inverted_Corner_Left",
      "rotation": 3
    },
    {
      "x": -4,
      "y": 0,
      "z": 2,
      "name": "Rock_Aqua_Brick"
    },
    {
      "x": -4,
      "y": 8,
      "z": 2,
      "name": "Rock_Aqua_Brick"
    },
    {
      "x": -4,
      "y": 9,
      "z": 2,
      "name": "Rock_Aqua_Brick"
    },
    {
      "x": -4,
      "y": 19,
      "z": 2,
      "name": "Rock_Aqua_Brick"
    },
    {
      "x": -4,
      "y": 20,
      "z": 2,
      "name": "Rock_Aqua_Brick_Decorative"
    },
    {
      "x": -4,
      "y": 21,
      "z": 2,
      "name": "Rock_Aqua_Brick_Pillar_Base"
    },
    {
      "x": -4,
      "y": 22,
      "z": 2,
      "name": "Rock_Aqua_Brick_Pillar_Middle"
    },
    {
      "x": -4,
      "y": 23,
      "z": 2,
      "name": "Rock_Aqua_Brick_Pillar_Base",
      "rotation": 8
    },
    {
      "x": -4,
      "y": 24,
      "z": 2,
      "name": "Rock_Aqua_Brick_Ornate"
    },
    {
      "x": -4,
      "y": 25,
      "z": 2,
      "name": "Rock_Aqua_Cobble_Roof",
      "rotation": 3
    },
    {
      "x": -4,
      "y": 0,
      "z": 3,
      "name": "Rock_Aqua_Brick"
    },
    {
      "x": -4,
      "y": 8,
      "z": 3,
      "name": "Rock_Aqua_Brick"
    },
    {
      "x": -4,
      "y": 9,
      "z": 3,
      "name": "Rock_Aqua_Brick"
    },
    {
      "x": -4,
      "y": 19,
      "z": 3,
      "name": "Rock_Aqua_Brick"
    },
    {
      "x": -4,
      "y": 20,
      "z": 3,
      "name": "Rock_Aqua_Brick_Decorative"
    },
    {
      "x": -4,
      "y": 24,
      "z": 3,
      "name": "Rock_Aqua_Brick_Smooth"
    },
    {
      "x": -4,
      "y": 25,
      "z": 3,
      "name": "*Rock_Aqua_Cobble_Roof_State_Definitions_Corner_Right"
    },
    {
      "x": -4,
      "y": 0,
      "z": 4,
      "name": "Rock_Aqua_Brick"
    },
    {
      "x": -4,
      "y": 8,
      "z": 4,
      "name": "Rock_Aqua_Brick"
    },
    {
      "x": -4,
      "y": 9,
      "z": 4,
      "name": "Rock_Aqua_Brick"
    },
    {
      "x": -4,
      "y": 20,
      "z": 4,
      "name": "Rock_Aqua_Cobble_Roof_Flat",
      "rotation": 2
    },
    {
      "x": -4,
      "y": 0,
      "z": 5,
      "name": "Rock_Aqua_Brick"
    },
    {
      "x": -4,
      "y": 8,
      "z": 5,
      "name": "Rock_Aqua_Brick"
    },
    {
      "x": -4,
      "y": 9,
      "z": 5,
      "name": "Rock_Aqua_Brick"
    },
    {
      "x": -4,
      "y": 20,
      "z": 5,
      "name": "Rock_Aqua_Cobble_Roof_Flat"
    },
    {
      "x": -4,
      "y": 0,
      "z": 6,
      "name": "Rock_Aqua_Brick"
    },
    {
      "x": -4,
      "y": 8,
      "z": 6,
      "name": "Rock_Aqua_Brick"
    },
    {
      "x": -4,
      "y": 9,
      "z": 6,
      "name": "Rock_Aqua_Brick"
    },
    {
      "x": -4,
      "y": 19,
      "z": 6,
      "name": "Rock_Aqua_Cobble_Roof_Hollow"
    },
    {
      "x": -4,
      "y": 0,
      "z": 7,
      "name": "Rock_Aqua_Brick"
    },
    {
      "x": -4,
      "y": 8,
      "z": 7,
      "name": "Rock_Aqua_Brick"
    },
    {
      "x": -4,
      "y": 9,
      "z": 7,
      "name": "Rock_Aqua_Brick"
    },
    {
      "x": -4,
      "y": 18,
      "z": 7,
      "name": "*Rock_Aqua_Cobble_Roof_Hollow_State_Definitions_Inverted_Corner_Right"
    },
    {
      "x": -4,
      "y": 0,
      "z": 8,
      "name": "Rock_Aqua_Brick"
    },
    {
      "x": -4,
      "y": 8,
      "z": 8,
      "name": "Rock_Aqua_Brick"
    },
    {
      "x": -4,
      "y": 9,
      "z": 8,
      "name": "Rock_Aqua_Brick"
    },
    {
      "x": -4,
      "y": 18,
      "z": 8,
      "name": "*Rock_Aqua_Cobble_Roof_Hollow_State_Definitions_Corner_Left",
      "rotation": 3
    },
    {
      "x": -4,
      "y": 0,
      "z": 9,
      "name": "Rock_Aqua_Brick_Smooth"
    },
    {
      "x": -4,
      "y": 1,
      "z": 9,
      "name": "Rock_Aqua_Brick_Smooth"
    },
    {
      "x": -4,
      "y": 2,
      "z": 9,
      "name": "Rock_Aqua_Brick_Smooth"
    },
    {
      "x": -4,
      "y": 3,
      "z": 9,
      "name": "Rock_Aqua_Brick_Smooth"
    },
    {
      "x": -4,
      "y": 4,
      "z": 9,
      "name": "Rock_Aqua_Brick_Smooth"
    },
    {
      "x": -4,
      "y": 5,
      "z": 9,
      "name": "Rock_Aqua_Brick_Smooth"
    },
    {
      "x": -4,
      "y": 6,
      "z": 9,
      "name": "Rock_Aqua_Brick_Smooth"
    },
    {
      "x": -4,
      "y": 7,
      "z": 9,
      "name": "Rock_Aqua_Brick_Smooth"
    },
    {
      "x": -4,
      "y": 8,
      "z": 9,
      "name": "Rock_Aqua_Brick_Smooth"
    },
    {
      "x": -4,
      "y": 9,
      "z": 9,
      "name": "Rock_Aqua_Brick_Smooth"
    },
    {
      "x": -4,
      "y": 10,
      "z": 9,
      "name": "Rock_Aqua_Brick_Smooth"
    },
    {
      "x": -4,
      "y": 11,
      "z": 9,
      "name": "Rock_Aqua_Brick_Smooth"
    },
    {
      "x": -4,
      "y": 12,
      "z": 9,
      "name": "Rock_Aqua_Brick_Smooth"
    },
    {
      "x": -4,
      "y": 13,
      "z": 9,
      "name": "Rock_Aqua_Brick_Smooth"
    },
    {
      "x": -4,
      "y": 14,
      "z": 9,
      "name": "Rock_Aqua_Brick_Smooth"
    },
    {
      "x": -4,
      "y": 15,
      "z": 9,
      "name": "Rock_Aqua_Brick_Smooth"
    },
    {
      "x": -4,
      "y": 16,
      "z": 9,
      "name": "Rock_Aqua_Brick_Smooth"
    },
    {
      "x": -4,
      "y": 17,
      "z": 9,
      "name": "Rock_Aqua_Cobble_Roof"
    },
    {
      "x": -4,
      "y": 16,
      "z": 10,
      "name": "Rock_Aqua_Cobble_Roof_Hollow"
    },
    {
      "x": -3,
      "y": 16,
      "z": -11,
      "name": "*Rock_Aqua_Cobble_Roof_Hollow_State_Definitions_Corner_Right",
      "rotation": 3
    },
    {
      "x": -3,
      "y": 16,
      "z": -10,
      "name": "*Rock_Aqua_Cobble_Roof_Hollow_State_Definitions_Inverted_Corner_Left",
      "rotation": 2
    },
    {
      "x": -3,
      "y": 0,
      "z": -9,
      "name": "Rock_Aqua_Brick_Smooth"
    },
    {
      "x": -3,
      "y": 1,
      "z": -9,
      "name": "Rock_Aqua_Brick_Smooth"
    },
    {
      "x": -3,
      "y": 2,
      "z": -9,
      "name": "Rock_Aqua_Brick_Smooth"
    },
    {
      "x": -3,
      "y": 3,
      "z": -9,
      "name": "Rock_Aqua_Brick_Smooth"
    },
    {
      "x": -3,
      "y": 4,
      "z": -9,
      "name": "Rock_Aqua_Brick_Smooth"
    },
    {
      "x": -3,
      "y": 5,
      "z": -9,
      "name": "Rock_Aqua_Brick_Smooth"
    },
    {
      "x": -3,
      "y": 6,
      "z": -9,
      "name": "Rock_Aqua_Brick_Smooth"
    },
    {
      "x": -3,
      "y": 7,
      "z": -9,
      "name": "Rock_Aqua_Brick_Smooth"
    },
    {
      "x": -3,
      "y": 8,
      "z": -9,
      "name": "Rock_Aqua_Brick_Smooth"
    },
    {
      "x": -3,
      "y": 9,
      "z": -9,
      "name": "Rock_Aqua_Brick_Smooth"
    },
    {
      "x": -3,
      "y": 10,
      "z": -9,
      "name": "Rock_Aqua_Brick_Smooth"
    },
    {
      "x": -3,
      "y": 11,
      "z": -9,
      "name": "Rock_Aqua_Brick_Smooth"
    },
    {
      "x": -3,
      "y": 12,
      "z": -9,
      "name": "Rock_Aqua_Brick_Smooth"
    },
    {
      "x": -3,
      "y": 13,
      "z": -9,
      "name": "Rock_Aqua_Brick_Smooth"
    },
    {
      "x": -3,
      "y": 14,
      "z": -9,
      "name": "Rock_Aqua_Brick_Smooth"
    },
    {
      "x": -3,
      "y": 15,
      "z": -9,
      "name": "Rock_Aqua_Brick_Smooth"
    },
    {
      "x": -3,
      "y": 16,
      "z": -9,
      "name": "Rock_Aqua_Brick_Smooth",
      "rotation": 3
    },
    {
      "x": -3,
      "y": 17,
      "z": -9,
      "name": "Rock_Aqua_Cobble_Roof",
      "rotation": 2
    },
    {
      "x": -3,
      "y": 0,
      "z": -8,
      "name": "Rock_Aqua_Brick"
    },
    {
      "x": -3,
      "y": 8,
      "z": -8,
      "name": "Rock_Aqua_Brick"
    },
    {
      "x": -3,
      "y": 9,
      "z": -8,
      "name": "Rock_Aqua_Brick"
    },
    {
      "x": -3,
      "y": 18,
      "z": -8,
      "name": "Rock_Aqua_Cobble_Roof_Hollow",
      "rotation": 2
    },
    {
      "x": -3,
      "y": 0,
      "z": -7,
      "name": "Rock_Aqua_Brick"
    },
    {
      "x": -3,
      "y": 8,
      "z": -7,
      "name": "Rock_Aqua_Brick"
    },
    {
      "x": -3,
      "y": 9,
      "z": -7,
      "name": "Rock_Aqua_Brick"
    },
    {
      "x": -3,
      "y": 19,
      "z": -7,
      "name": "Rock_Aqua_Cobble_Roof_Shallow",
      "rotation": 2
    },
    {
      "x": -3,
      "y": 0,
      "z": -6,
      "name": "Rock_Aqua_Brick"
    },
    {
      "x": -3,
      "y": 8,
      "z": -6,
      "name": "Rock_Aqua_Brick"
    },
    {
      "x": -3,
      "y": 9,
      "z": -6,
      "name": "Rock_Aqua_Brick"
    },
    {
      "x": -3,
      "y": 19,
      "z": -6,
      "name": "Rock_Aqua_Cobble_Roof_Shallow",
      "filler": 32,
      "rotation": 2
    },
    {
      "x": -3,
      "y": 0,
      "z": -5,
      "name": "Rock_Aqua_Brick"
    },
    {
      "x": -3,
      "y": 8,
      "z": -5,
      "name": "Rock_Aqua_Brick"
    },
    {
      "x": -3,
      "y": 9,
      "z": -5,
      "name": "Rock_Aqua_Brick"
    },
    {
      "x": -3,
      "y": 20,
      "z": -5,
      "name": "Rock_Aqua_Cobble_Roof_Flat",
      "rotation": 3
    },
    {
      "x": -3,
      "y": 0,
      "z": -4,
      "name": "Rock_Aqua_Brick"
    },
    {
      "x": -3,
      "y": 8,
      "z": -4,
      "name": "Rock_Aqua_Brick"
    },
    {
      "x": -3,
      "y": 9,
      "z": -4,
      "name": "Rock_Aqua_Brick"
    },
    {
      "x": -3,
      "y": 19,
      "z": -4,
      "name": "Rock_Aqua_Brick",
      "rotation": 3
    },
    {
      "x": -3,
      "y": 20,
      "z": -4,
      "name": "Rock_Aqua_Brick_Decorative"
    },
    {
      "x": -3,
      "y": 24,
      "z": -4,
      "name": "Rock_Aqua_Brick_Smooth"
    },
    {
      "x": -3,
      "y": 25,
      "z": -4,
      "name": "*Rock_Aqua_Cobble_Roof_State_Definitions_Corner_Right",
      "rotation": 3
    },
    {
      "x": -3,
      "y": 0,
      "z": -3,
      "name": "Rock_Aqua_Brick"
    },
    {
      "x": -3,
      "y": 25,
      "z": -3,
      "name": "*Rock_Aqua_Cobble_Roof_Hollow_State_Definitions_Inverted_Corner_Left",
      "rotation": 2
    },
    {
      "x": -3,
      "y": 0,
      "z": -2,
      "name": "Rock_Aqua_Brick"
    },
    {
      "x": -3,
      "y": 26,
      "z": -2,
      "name": "*Rock_Aqua_Cobble_Roof_Hollow_State_Definitions_Corner_Right",
      "rotation": 3
    },
    {
      "x": -3,
      "y": 0,
      "z": -1,
      "name": "Rock_Aqua_Brick"
    },
    {
      "x": -3,
      "y": 26,
      "z": -1,
      "name": "Rock_Aqua_Cobble_Roof_Hollow",
      "rotation": 3
    },
    {
      "x": -3,
      "y": 0,
      "z": 0,
      "name": "Rock_Aqua_Brick"
    },
    {
      "x": -3,
      "y": 26,
      "z": 0,
      "name": "Rock_Aqua_Cobble_Roof_Hollow",
      "rotation": 3
    },
    {
      "x": -3,
      "y": 0,
      "z": 1,
      "name": "Rock_Aqua_Brick"
    },
    {
      "x": -3,
      "y": 26,
      "z": 1,
      "name": "Rock_Aqua_Cobble_Roof_Hollow",
      "rotation": 3
    },
    {
      "x": -3,
      "y": 0,
      "z": 2,
      "name": "Rock_Aqua_Brick"
    },
    {
      "x": -3,
      "y": 26,
      "z": 2,
      "name": "*Rock_Aqua_Cobble_Roof_Hollow_State_Definitions_Corner_Right"
    },
    {
      "x": -3,
      "y": 0,
      "z": 3,
      "name": "Rock_Aqua_Brick"
    },
    {
      "x": -3,
      "y": 25,
      "z": 3,
      "name": "*Rock_Aqua_Cobble_Roof_Hollow_State_Definitions_Inverted_Corner_Left",
      "rotation": 3
    },
    {
      "x": -3,
      "y": 0,
      "z": 4,
      "name": "Rock_Aqua_Brick"
    },
    {
      "x": -3,
      "y": 8,
      "z": 4,
      "name": "Rock_Aqua_Brick"
    },
    {
      "x": -3,
      "y": 9,
      "z": 4,
      "name": "Rock_Aqua_Brick"
    },
    {
      "x": -3,
      "y": 19,
      "z": 4,
      "name": "Rock_Aqua_Brick"
    },
    {
      "x": -3,
      "y": 20,
      "z": 4,
      "name": "Rock_Aqua_Brick_Decorative"
    },
    {
      "x": -3,
      "y": 24,
      "z": 4,
      "name": "Rock_Aqua_Brick_Smooth"
    },
    {
      "x": -3,
      "y": 25,
      "z": 4,
      "name": "*Rock_Aqua_Cobble_Roof_State_Definitions_Corner_Right"
    },
    {
      "x": -3,
      "y": 0,
      "z": 5,
      "name": "Rock_Aqua_Brick"
    },
    {
      "x": -3,
      "y": 8,
      "z": 5,
      "name": "Rock_Aqua_Brick"
    },
    {
      "x": -3,
      "y": 9,
      "z": 5,
      "name": "Rock_Aqua_Brick"
    },
    {
      "x": -3,
      "y": 20,
      "z": 5,
      "name": "Rock_Aqua_Cobble_Roof_Flat"
    },
    {
      "x": -3,
      "y": 0,
      "z": 6,
      "name": "Rock_Aqua_Brick"
    },
    {
      "x": -3,
      "y": 8,
      "z": 6,
      "name": "Rock_Aqua_Brick"
    },
    {
      "x": -3,
      "y": 9,
      "z": 6,
      "name": "Rock_Aqua_Brick"
    },
    {
      "x": -3,
      "y": 19,
      "z": 6,
      "name": "Rock_Aqua_Cobble_Roof_Shallow",
      "filler": 992
    },
    {
      "x": -3,
      "y": 0,
      "z": 7,
      "name": "Rock_Aqua_Brick"
    },
    {
      "x": -3,
      "y": 8,
      "z": 7,
      "name": "Rock_Aqua_Brick"
    },
    {
      "x": -3,
      "y": 9,
      "z": 7,
      "name": "Rock_Aqua_Brick"
    },
    {
      "x": -3,
      "y": 19,
      "z": 7,
      "name": "Rock_Aqua_Cobble_Roof_Shallow"
    },
    {
      "x": -3,
      "y": 0,
      "z": 8,
      "name": "Rock_Aqua_Brick"
    },
    {
      "x": -3,
      "y": 8,
      "z": 8,
      "name": "Rock_Aqua_Brick"
    },
    {
      "x": -3,
      "y": 9,
      "z": 8,
      "name": "Rock_Aqua_Brick"
    },
    {
      "x": -3,
      "y": 18,
      "z": 8,
      "name": "Rock_Aqua_Cobble_Roof_Hollow"
    },
    {
      "x": -3,
      "y": 0,
      "z": 9,
      "name": "Rock_Aqua_Brick_Smooth"
    },
    {
      "x": -3,
      "y": 1,
      "z": 9,
      "name": "Rock_Aqua_Brick_Smooth"
    },
    {
      "x": -3,
      "y": 2,
      "z": 9,
      "name": "Rock_Aqua_Brick_Smooth"
    },
    {
      "x": -3,
      "y": 3,
      "z": 9,
      "name": "Rock_Aqua_Brick_Smooth"
    },
    {
      "x": -3,
      "y": 4,
      "z": 9,
      "name": "Rock_Aqua_Brick_Smooth"
    },
    {
      "x": -3,
      "y": 5,
      "z": 9,
      "name": "Rock_Aqua_Brick_Smooth"
    },
    {
      "x": -3,
      "y": 6,
      "z": 9,
      "name": "Rock_Aqua_Brick_Smooth"
    },
    {
      "x": -3,
      "y": 7,
      "z": 9,
      "name": "Rock_Aqua_Brick_Smooth"
    },
    {
      "x": -3,
      "y": 8,
      "z": 9,
      "name": "Rock_Aqua_Brick_Smooth"
    },
    {
      "x": -3,
      "y": 9,
      "z": 9,
      "name": "Rock_Aqua_Brick_Smooth"
    },
    {
      "x": -3,
      "y": 10,
      "z": 9,
      "name": "Rock_Aqua_Brick_Smooth"
    },
    {
      "x": -3,
      "y": 11,
      "z": 9,
      "name": "Rock_Aqua_Brick_Smooth"
    },
    {
      "x": -3,
      "y": 12,
      "z": 9,
      "name": "Rock_Aqua_Brick_Smooth"
    },
    {
      "x": -3,
      "y": 13,
      "z": 9,
      "name": "Rock_Aqua_Brick_Smooth"
    },
    {
      "x": -3,
      "y": 14,
      "z": 9,
      "name": "Rock_Aqua_Brick_Smooth"
    },
    {
      "x": -3,
      "y": 15,
      "z": 9,
      "name": "Rock_Aqua_Brick_Smooth"
    },
    {
      "x": -3,
      "y": 16,
      "z": 9,
      "name": "Rock_Aqua_Brick_Smooth"
    },
    {
      "x": -3,
      "y": 17,
      "z": 9,
      "name": "Rock_Aqua_Cobble_Roof"
    },
    {
      "x": -3,
      "y": 16,
      "z": 10,
      "name": "*Rock_Aqua_Cobble_Roof_Hollow_State_Definitions_Inverted_Corner_Right"
    },
    {
      "x": -3,
      "y": 16,
      "z": 11,
      "name": "*Rock_Aqua_Cobble_Roof_Hollow_State_Definitions_Corner_Left",
      "rotation": 3
    },
    {
      "x": -2,
      "y": 16,
      "z": -11,
      "name": "Rock_Aqua_Cobble_Roof_Hollow",
      "rotation": 2
    },
    {
      "x": -2,
      "y": 0,
      "z": -10,
      "name": "Rock_Aqua_Brick_Smooth"
    },
    {
      "x": -2,
      "y": 1,
      "z": -10,
      "name": "Rock_Aqua_Brick_Smooth"
    },
    {
      "x": -2,
      "y": 2,
      "z": -10,
      "name": "Rock_Aqua_Brick_Smooth"
    },
    {
      "x": -2,
      "y": 3,
      "z": -10,
      "name": "Rock_Aqua_Brick_Smooth"
    },
    {
      "x": -2,
      "y": 4,
      "z": -10,
      "name": "Rock_Aqua_Brick_Smooth"
    },
    {
      "x": -2,
      "y": 5,
      "z": -10,
      "name": "Rock_Aqua_Brick_Smooth"
    },
    {
      "x": -2,
      "y": 6,
      "z": -10,
      "name": "Rock_Aqua_Brick_Smooth"
    },
    {
      "x": -2,
      "y": 7,
      "z": -10,
      "name": "Rock_Aqua_Brick_Smooth"
    },
    {
      "x": -2,
      "y": 8,
      "z": -10,
      "name": "Rock_Aqua_Brick_Smooth"
    },
    {
      "x": -2,
      "y": 9,
      "z": -10,
      "name": "Rock_Aqua_Brick_Smooth"
    },
    {
      "x": -2,
      "y": 10,
      "z": -10,
      "name": "Rock_Aqua_Brick_Smooth"
    },
    {
      "x": -2,
      "y": 11,
      "z": -10,
      "name": "Rock_Aqua_Brick_Smooth"
    },
    {
      "x": -2,
      "y": 12,
      "z": -10,
      "name": "Rock_Aqua_Brick_Smooth"
    },
    {
      "x": -2,
      "y": 13,
      "z": -10,
      "name": "Rock_Aqua_Brick_Smooth"
    },
    {
      "x": -2,
      "y": 14,
      "z": -10,
      "name": "Rock_Aqua_Brick_Smooth"
    },
    {
      "x": -2,
      "y": 15,
      "z": -10,
      "name": "Rock_Aqua_Brick_Smooth"
    },
    {
      "x": -2,
      "y": 16,
      "z": -10,
      "name": "Rock_Aqua_Brick_Smooth",
      "rotation": 3
    },
    {
      "x": -2,
      "y": 17,
      "z": -10,
      "name": "*Rock_Aqua_Cobble_Roof_State_Definitions_Corner_Left",
      "rotation": 2
    },
    {
      "x": -2,
      "y": 0,
      "z": -9,
      "name": "Rock_Aqua_Brick"
    },
    {
      "x": -2,
      "y": 8,
      "z": -9,
      "name": "Rock_Aqua_Brick"
    },
    {
      "x": -2,
      "y": 9,
      "z": -9,
      "name": "Rock_Aqua_Brick"
    },
    {
      "x": -2,
      "y": 17,
      "z": -9,
      "name": "*Rock_Aqua_Cobble_Roof_Hollow_State_Definitions_Inverted_Corner_Right",
      "rotation": 3
    },
    {
      "x": -2,
      "y": 0,
      "z": -8,
      "name": "Rock_Aqua_Brick"
    },
    {
      "x": -2,
      "y": 8,
      "z": -8,
      "name": "Rock_Aqua_Brick"
    },
    {
      "x": -2,
      "y": 9,
      "z": -8,
      "name": "Rock_Aqua_Brick"
    },
    {
      "x": -2,
      "y": 18,
      "z": -8,
      "name": "Rock_Aqua_Cobble_Roof_Hollow",
      "rotation": 2
    },
    {
      "x": -2,
      "y": 0,
      "z": -7,
      "name": "Rock_Aqua_Brick"
    },
    {
      "x": -2,
      "y": 8,
      "z": -7,
      "name": "Rock_Aqua_Brick"
    },
    {
      "x": -2,
      "y": 9,
      "z": -7,
      "name": "Rock_Aqua_Brick"
    },
    {
      "x": -2,
      "y": 19,
      "z": -7,
      "name": "Rock_Aqua_Cobble_Roof_Shallow",
      "rotation": 2
    },
    {
      "x": -2,
      "y": 0,
      "z": -6,
      "name": "Rock_Aqua_Brick"
    },
    {
      "x": -2,
      "y": 8,
      "z": -6,
      "name": "Rock_Aqua_Brick"
    },
    {
      "x": -2,
      "y": 9,
      "z": -6,
      "name": "Rock_Aqua_Brick"
    },
    {
      "x": -2,
      "y": 19,
      "z": -6,
      "name": "Rock_Aqua_Cobble_Roof_Shallow",
      "filler": 32,
      "rotation": 2
    },
    {
      "x": -2,
      "y": 0,
      "z": -5,
      "name": "Rock_Aqua_Brick"
    },
    {
      "x": -2,
      "y": 8,
      "z": -5,
      "name": "Rock_Aqua_Brick"
    },
    {
      "x": -2,
      "y": 9,
      "z": -5,
      "name": "Rock_Aqua_Brick"
    },
    {
      "x": -2,
      "y": 20,
      "z": -5,
      "name": "Rock_Aqua_Cobble_Roof_Flat",
      "rotation": 3
    },
    {
      "x": -2,
      "y": 0,
      "z": -4,
      "name": "Rock_Aqua_Brick"
    },
    {
      "x": -2,
      "y": 8,
      "z": -4,
      "name": "Rock_Aqua_Brick"
    },
    {
      "x": -2,
      "y": 9,
      "z": -4,
      "name": "Rock_Aqua_Brick"
    },
    {
      "x": -2,
      "y": 19,
      "z": -4,
      "name": "Rock_Aqua_Brick",
      "rotation": 3
    },
    {
      "x": -2,
      "y": 20,
      "z": -4,
      "name": "Rock_Aqua_Brick_Decorative"
    },
    {
      "x": -2,
      "y": 21,
      "z": -4,
      "name": "Rock_Aqua_Brick_Pillar_Base"
    },
    {
      "x": -2,
      "y": 22,
      "z": -4,
      "name": "Rock_Aqua_Brick_Pillar_Middle"
    },
    {
      "x": -2,
      "y": 23,
      "z": -4,
      "name": "Rock_Aqua_Brick_Pillar_Base",
      "rotation": 8
    },
    {
      "x": -2,
      "y": 24,
      "z": -4,
      "name": "Rock_Aqua_Brick_Ornate"
    },
    {
      "x": -2,
      "y": 25,
      "z": -4,
      "name": "Rock_Aqua_Cobble_Roof",
      "rotation": 2
    },
    {
      "x": -2,
      "y": 0,
      "z": -3,
      "name": "Rock_Aqua_Brick"
    },
    {
      "x": -2,
      "y": 26,
      "z": -3,
      "name": "*Rock_Aqua_Cobble_Roof_Hollow_State_Definitions_Corner_Right",
      "rotation": 3
    },
    {
      "x": -2,
      "y": 0,
      "z": -2,
      "name": "Rock_Aqua_Brick"
    },
    {
      "x": -2,
      "y": 26,
      "z": -2,
      "name": "*Rock_Aqua_Cobble_Roof_Hollow_State_Definitions_Inverted_Corner_Left",
      "rotation": 2
    },
    {
      "x": -2,
      "y": 0,
      "z": -1,
      "name": "Rock_Aqua_Brick"
    },
    {
      "x": -2,
      "y": 27,
      "z": -1,
      "name": "*Rock_Aqua_Cobble_Roof_Steep_State_Definitions_Corner_Right",
      "rotation": 3
    },
    {
      "x": -2,
      "y": 28,
      "z": -1,
      "name": "*Rock_Aqua_Cobble_Roof_Steep_State_Definitions_Corner_Right",
      "filler": 1024,
      "rotation": 3
    },
    {
      "x": -2,
      "y": 0,
      "z": 0,
      "name": "Rock_Aqua_Brick"
    },
    {
      "x": -2,
      "y": 27,
      "z": 0,
      "name": "Rock_Aqua_Cobble_Roof_Steep",
      "rotation": 3
    },
    {
      "x": -2,
      "y": 28,
      "z": 0,
      "name": "Rock_Aqua_Cobble_Roof_Steep",
      "filler": 1024,
      "rotation": 3
    },
    {
      "x": -2,
      "y": 0,
      "z": 1,
      "name": "Rock_Aqua_Brick"
    },
    {
      "x": -2,
      "y": 27,
      "z": 1,
      "name": "*Rock_Aqua_Cobble_Roof_Steep_State_Definitions_Corner_Right"
    },
    {
      "x": -2,
      "y": 28,
      "z": 1,
      "name": "*Rock_Aqua_Cobble_Roof_Steep_State_Definitions_Corner_Right",
      "filler": 1024
    },
    {
      "x": -2,
      "y": 0,
      "z": 2,
      "name": "Rock_Aqua_Brick"
    },
    {
      "x": -2,
      "y": 26,
      "z": 2,
      "name": "*Rock_Aqua_Cobble_Roof_Hollow_State_Definitions_Inverted_Corner_Left",
      "rotation": 3
    },
    {
      "x": -2,
      "y": 0,
      "z": 3,
      "name": "Rock_Aqua_Brick"
    },
    {
      "x": -2,
      "y": 26,
      "z": 3,
      "name": "*Rock_Aqua_Cobble_Roof_Hollow_State_Definitions_Corner_Right"
    },
    {
      "x": -2,
      "y": 0,
      "z": 4,
      "name": "Rock_Aqua_Brick"
    },
    {
      "x": -2,
      "y": 8,
      "z": 4,
      "name": "Rock_Aqua_Brick"
    },
    {
      "x": -2,
      "y": 9,
      "z": 4,
      "name": "Rock_Aqua_Brick"
    },
    {
      "x": -2,
      "y": 19,
      "z": 4,
      "name": "Rock_Aqua_Brick"
    },
    {
      "x": -2,
      "y": 20,
      "z": 4,
      "name": "Rock_Aqua_Brick_Decorative"
    },
    {
      "x": -2,
      "y": 21,
      "z": 4,
      "name": "Rock_Aqua_Brick_Pillar_Base"
    },
    {
      "x": -2,
      "y": 22,
      "z": 4,
      "name": "Rock_Aqua_Brick_Pillar_Middle"
    },
    {
      "x": -2,
      "y": 23,
      "z": 4,
      "name": "Rock_Aqua_Brick_Pillar_Base",
      "rotation": 8
    },
    {
      "x": -2,
      "y": 24,
      "z": 4,
      "name": "Rock_Aqua_Brick_Ornate"
    },
    {
      "x": -2,
      "y": 25,
      "z": 4,
      "name": "Rock_Aqua_Cobble_Roof"
    },
    {
      "x": -2,
      "y": 0,
      "z": 5,
      "name": "Rock_Aqua_Brick"
    },
    {
      "x": -2,
      "y": 8,
      "z": 5,
      "name": "Rock_Aqua_Brick"
    },
    {
      "x": -2,
      "y": 9,
      "z": 5,
      "name": "Rock_Aqua_Brick"
    },
    {
      "x": -2,
      "y": 20,
      "z": 5,
      "name": "Rock_Aqua_Cobble_Roof_Flat"
    },
    {
      "x": -2,
      "y": 0,
      "z": 6,
      "name": "Rock_Aqua_Brick"
    },
    {
      "x": -2,
      "y": 8,
      "z": 6,
      "name": "Rock_Aqua_Brick"
    },
    {
      "x": -2,
      "y": 9,
      "z": 6,
      "name": "Rock_Aqua_Brick"
    },
    {
      "x": -2,
      "y": 19,
      "z": 6,
      "name": "Rock_Aqua_Cobble_Roof_Shallow",
      "filler": 992
    },
    {
      "x": -2,
      "y": 0,
      "z": 7,
      "name": "Rock_Aqua_Brick"
    },
    {
      "x": -2,
      "y": 8,
      "z": 7,
      "name": "Rock_Aqua_Brick"
    },
    {
      "x": -2,
      "y": 9,
      "z": 7,
      "name": "Rock_Aqua_Brick"
    },
    {
      "x": -2,
      "y": 19,
      "z": 7,
      "name": "Rock_Aqua_Cobble_Roof_Shallow"
    },
    {
      "x": -2,
      "y": 0,
      "z": 8,
      "name": "Rock_Aqua_Brick"
    },
    {
      "x": -2,
      "y": 8,
      "z": 8,
      "name": "Rock_Aqua_Brick"
    },
    {
      "x": -2,
      "y": 9,
      "z": 8,
      "name": "Rock_Aqua_Brick"
    },
    {
      "x": -2,
      "y": 18,
      "z": 8,
      "name": "Rock_Aqua_Cobble_Roof_Hollow"
    },
    {
      "x": -2,
      "y": 0,
      "z": 9,
      "name": "Rock_Aqua_Brick_Smooth"
    },
    {
      "x": -2,
      "y": 8,
      "z": 9,
      "name": "Rock_Aqua_Brick_Smooth"
    },
    {
      "x": -2,
      "y": 9,
      "z": 9,
      "name": "Rock_Aqua_Brick_Smooth"
    },
    {
      "x": -2,
      "y": 17,
      "z": 9,
      "name": "*Rock_Aqua_Cobble_Roof_Hollow_State_Definitions_Inverted_Corner_Left",
      "rotation": 3
    },
    {
      "x": -2,
      "y": 0,
      "z": 10,
      "name": "Rock_Aqua_Brick_Smooth"
    },
    {
      "x": -2,
      "y": 1,
      "z": 10,
      "name": "Rock_Aqua_Brick_Smooth"
    },
    {
      "x": -2,
      "y": 2,
      "z": 10,
      "name": "Rock_Aqua_Brick_Smooth"
    },
    {
      "x": -2,
      "y": 3,
      "z": 10,
      "name": "Rock_Aqua_Brick_Smooth"
    },
    {
      "x": -2,
      "y": 4,
      "z": 10,
      "name": "Rock_Aqua_Brick_Smooth"
    },
    {
      "x": -2,
      "y": 5,
      "z": 10,
      "name": "Rock_Aqua_Brick_Smooth"
    },
