{
  "version": 8,
  "blockIdVersion": 11,
  "anchorX": 0,
  "anchorY": 3,
  "anchorZ": 0,
  "blocks": [
    {
      "x": -6,
      "y": 14,
      "z": -5,
      "name": "Plant_Coral_Block_Blue"
    },
    {
      "x": -6,
      "y": 14,
      "z": -4,
      "name": "Plant_Coral_Block_Blue"
    },
    {
      "x": -6,
      "y": 14,
      "z": -3,
      "name": "Plant_Coral_Block_Blue"
    },
    {
      "x": -6,
      "y": 14,
      "z": -1,
      "name": "Plant_Coral_Block_Blue"
    },
    {
      "x": -6,
      "y": 14,
      "z": 0,
      "name": "Plant_Coral_Block_Blue"
    },
    {
      "x": -5,
      "y": 14,
      "z": -5,
      "name": "Plant_Coral_Block_Blue"
    },
    {
      "x": -5,
      "y": 13,
      "z": -4,
      "name": "Plant_Crop_Mushroom_Block_Blue_Mycelium"
    },
    {
      "x": -5,
      "y": 14,
      "z": -4,
      "name": "Plant_Coral_Block_Cyan"
    },
    {
      "x": -5,
      "y": 14,
      "z": -3,
      "name": "Plant_Coral_Block_Cyan"
    },
    {
      "x": -5,
      "y": 14,
      "z": -2,
      "name": "Plant_Coral_Block_Cyan"
    },
    {
      "x": -5,
      "y": 14,
      "z": -1,
      "name": "Plant_Coral_Block_Cyan"
    },
    {
      "x": -5,
      "y": 14,
      "z": 0,
      "name": "Plant_Coral_Block_Cyan"
    },
    {
      "x": -5,
      "y": 14,
      "z": 1,
      "name": "Plant_Coral_Block_Blue"
    },
    {
      "x": -4,
      "y": 14,
      "z": -6,
      "name": "Plant_Coral_Block_Blue"
    },
    {
      "x": -4,
      "y": 14,
      "z": -5,
      "name": "Plant_Coral_Block_Cyan"
    },
    {
      "x": -4,
      "y": 15,
      "z": -5,
      "name": "Plant_Coral_Bush_Cyan"
    },
    {
      "x": -4,
      "y": 14,
      "z": -4,
      "name": "Plant_Coral_Block_Cyan"
    },
    {
      "x": -4,
      "y": 14,
      "z": -3,
      "name": "Plant_Coral_Block_Cyan"
    },
    {
      "x": -4,
      "y": 14,
      "z": -2,
      "name": "Plant_Coral_Block_Cyan"
    },
    {
      "x": -4,
      "y": 13,
      "z": -1,
      "name": "Plant_Crop_Mushroom_Block_Blue_Mycelium"
    },
    {
      "x": -4,
      "y": 14,
      "z": -1,
      "name": "Plant_Coral_Block_Cyan"
    },
    {
      "x": -4,
      "y": 14,
      "z": 0,
      "name": "Plant_Coral_Block_Cyan"
    },
    {
      "x": -4,
      "y": 14,
      "z": 1,
      "name": "Plant_Coral_Block_Cyan"
    },
    {
      "x": -4,
      "y": 14,
      "z": 3,
      "name": "Plant_Coral_Block_Blue"
    },
    {
      "x": -3,
      "y": 13,
      "z": -6,
      "name": "Plant_Crop_Mushroom_Block_Blue_Mycelium"
    },
    {
      "x": -3,
      "y": 14,
      "z": -6,
      "name": "Plant_Coral_Block_Cyan"
    },
    {
      "x": -3,
      "y": 14,
      "z": -5,
      "name": "Plant_Coral_Block_Cyan"
    },
    {
      "x": -3,
      "y": 14,
      "z": -4,
      "name": "Plant_Coral_Block_Cyan"
    },
    {
      "x": -3,
      "y": 14,
      "z": -3,
      "name": "Plant_Coral_Block_Cyan"
    },
    {
      "x": -3,
      "y": 15,
      "z": -3,
      "name": "Plant_Coral_Bush_Cyan"
    },
    {
      "x": -3,
      "y": 8,
      "z": -2,
      "name": "Plant_Coral_Block_Blue"
    },
    {
      "x": -3,
      "y": 9,
      "z": -2,
      "name": "Plant_Coral_Block_Blue"
    },
    {
      "x": -3,
      "y": 10,
      "z": -2,
      "name": "Plant_Coral_Block_Blue"
    },
    {
      "x": -3,
      "y": 14,
      "z": -2,
      "name": "Plant_Coral_Block_Cyan"
    },
    {
      "x": -3,
      "y": 1,
      "z": -1,
      "name": "Plant_Coral_Block_Blue"
    },
    {
      "x": -3,
      "y": 2,
      "z": -1,
      "name": "Plant_Coral_Block_Blue"
    },
    {
      "x": -3,
      "y": 3,
      "z": -1,
      "name": "Plant_Coral_Block_Cyan"
    },
    {
      "x": -3,
      "y": 4,
      "z": -1,
      "name": "Plant_Coral_Block_Cyan"
    },
    {
      "x": -3,
      "y": 5,
      "z": -1,
      "name": "Plant_Coral_Block_Cyan"
    },
    {
      "x": -3,
      "y": 6,
      "z": -1,
      "name": "Plant_Coral_Block_Cyan"
    },
    {
      "x": -3,
      "y": 7,
      "z": -1,
      "name": "Plant_Coral_Block_Cyan"
    },
    {
      "x": -3,
      "y": 8,
      "z": -1,
      "name": "Plant_Coral_Block_Blue"
    },
    {
      "x": -3,
      "y": 9,
      "z": -1,
      "name": "Plant_Coral_Block_Blue"
    },
    {
      "x": -3,
      "y": 10,
      "z": -1,
      "name": "Plant_Coral_Block_Blue"
    },
    {
      "x": -3,
      "y": 11,
      "z": -1,
      "name": "Plant_Coral_Block_Blue"
    },
    {
      "x": -3,
      "y": 12,
      "z": -1,
      "name": "Plant_Coral_Block_Blue"
    },
    {
      "x": -3,
      "y": 13,
      "z": -1,
      "name": "Plant_Coral_Block_Blue"
    },
    {
      "x": -3,
      "y": 14,
      "z": -1,
      "name": "Plant_Coral_Block_Blue"
    },
    {
      "x": -3,
      "y": 15,
      "z": -1,
      "name": "Plant_Coral_Model_Cyan"
    },
    {
      "x": -3,
      "y": 1,
      "z": 0,
      "name": "Plant_Coral_Block_Blue"
    },
    {
      "x": -3,
      "y": 2,
      "z": 0,
      "name": "Plant_Coral_Block_Blue"
    },
    {
      "x": -3,
      "y": 3,
      "z": 0,
      "name": "Plant_Coral_Block_Cyan"
    },
    {
      "x": -3,
      "y": 4,
      "z": 0,
      "name": "Plant_Coral_Block_Cyan"
    },
    {
      "x": -3,
      "y": 5,
      "z": 0,
      "name": "Plant_Coral_Block_Cyan"
    },
    {
      "x": -3,
      "y": 6,
      "z": 0,
      "name": "Plant_Coral_Block_Cyan"
    },
    {
      "x": -3,
      "y": 7,
      "z": 0,
      "name": "Plant_Coral_Block_Cyan"
    },
    {
      "x": -3,
      "y": 8,
      "z": 0,
      "name": "Plant_Coral_Block_Blue"
    },
    {
      "x": -3,
      "y": 9,
      "z": 0,
      "name": "Plant_Coral_Block_Blue"
    },
    {
      "x": -3,
      "y": 10,
      "z": 0,
      "name": "Plant_Coral_Block_Blue"
    },
    {
      "x": -3,
      "y": 11,
      "z": 0,
      "name": "Plant_Coral_Block_Blue"
    },
    {
      "x": -3,
      "y": 12,
      "z": 0,
      "name": "Plant_Coral_Block_Blue"
    },
    {
      "x": -3,
      "y": 13,
      "z": 0,
      "name": "Plant_Coral_Block_Blue"
    },
    {
      "x": -3,
      "y": 14,
      "z": 0,
      "name": "Plant_Coral_Block_Blue"
    },
    {
      "x": -3,
      "y": 1,
      "z": 1,
      "name": "Plant_Coral_Block_Blue"
    },
    {
      "x": -3,
      "y": 2,
      "z": 1,
      "name": "Plant_Coral_Block_Blue"
    },
    {
      "x": -3,
      "y": 3,
      "z": 1,
      "name": "Plant_Coral_Block_Blue"
    },
    {
      "x": -3,
      "y": 4,
      "z": 1,
      "name": "Plant_Coral_Block_Cyan"
    },
    {
      "x": -3,
      "y": 5,
      "z": 1,
      "name": "Plant_Coral_Block_Cyan"
    },
    {
      "x": -3,
      "y": 6,
      "z": 1,
      "name": "Plant_Coral_Block_Cyan"
    },
    {
      "x": -3,
      "y": 7,
      "z": 1,
      "name": "Plant_Coral_Block_Blue"
    },
    {
      "x": -3,
      "y": 11,
      "z": 1,
      "name": "Plant_Coral_Block_Blue"
    },
    {
      "x": -3,
      "y": 12,
      "z": 1,
      "name": "Plant_Coral_Block_Blue"
    },
    {
      "x": -3,
      "y": 13,
      "z": 1,
      "name": "Plant_Coral_Block_Blue"
    },
    {
      "x": -3,
      "y": 14,
      "z": 1,
      "name": "Plant_Coral_Block_Blue"
    },
    {
      "x": -3,
      "y": 13,
      "z": 2,
      "name": "Plant_Crop_Mushroom_Block_Blue_Mycelium"
    },
    {
      "x": -3,
      "y": 14,
      "z": 2,
      "name": "Plant_Coral_Block_Cyan"
    },
    {
      "x": -3,
      "y": 11,
      "z": 3,
      "name": "Plant_Coral_Block_Blue"
    },
    {
      "x": -3,
      "y": 12,
      "z": 3,
      "name": "Plant_Coral_Model_Blue"
    },
    {
      "x": -3,
      "y": 14,
      "z": 3,
      "name": "Plant_Coral_Block_Blue"
    },
    {
      "x": -3,
      "y": 11,
      "z": 4,
      "name": "Plant_Coral_Block_Blue"
    },
    {
      "x": -2,
      "y": 14,
      "z": -7,
      "name": "Plant_Coral_Block_Blue"
    },
    {
      "x": -2,
      "y": 14,
      "z": -6,
      "name": "Plant_Coral_Block_Cyan"
    },
    {
      "x": -2,
      "y": 14,
      "z": -5,
      "name": "Plant_Coral_Block_Cyan"
    },
    {
      "x": -2,
      "y": 15,
      "z": -5,
      "name": "Plant_Coral_Bush_Cyan"
    },
    {
      "x": -2,
      "y": 14,
      "z": -4,
      "name": "Plant_Coral_Block_Cyan"
    },
    {
      "x": -2,
      "y": 15,
      "z": -4,
      "name": "Rock_Crystal_Cyan_Small"
    },
    {
      "x": -2,
      "y": 7,
      "z": -3,
      "name": "Rock_Crystal_Blue_Small",
      "rotation": 6
    },
    {
      "x": -2,
      "y": 8,
      "z": -3,
      "name": "Plant_Coral_Block_Cyan"
    },
    {
      "x": -2,
      "y": 9,
      "z": -3,
      "name": "Plant_Coral_Block_Cyan"
    },
    {
      "x": -2,
      "y": 10,
      "z": -3,
      "name": "Plant_Coral_Block_Blue"
    },
    {
      "x": -2,
      "y": 11,
      "z": -3,
      "name": "Plant_Coral_Block_Blue"
    },
    {
      "x": -2,
      "y": 12,
      "z": -3,
      "name": "Plant_Coral_Model_Blue"
    },
    {
      "x": -2,
      "y": 14,
      "z": -3,
      "name": "Plant_Coral_Block_Cyan"
    },
    {
      "x": -2,
      "y": 1,
      "z": -2,
      "name": "Plant_Coral_Block_Blue"
    },
    {
      "x": -2,
      "y": 2,
      "z": -2,
      "name": "Plant_Coral_Block_Blue"
    },
    {
      "x": -2,
      "y": 3,
      "z": -2,
      "name": "Plant_Coral_Block_Cyan"
    },
    {
      "x": -2,
      "y": 4,
      "z": -2,
      "name": "Plant_Coral_Block_Cyan"
    },
    {
      "x": -2,
      "y": 5,
      "z": -2,
      "name": "Plant_Coral_Block_Cyan"
    },
    {
      "x": -2,
      "y": 6,
      "z": -2,
      "name": "Plant_Coral_Block_Cyan"
    },
    {
      "x": -2,
      "y": 7,
      "z": -2,
      "name": "Plant_Coral_Block_Cyan"
    },
    {
      "x": -2,
      "y": 8,
      "z": -2,
      "name": "Plant_Coral_Bush_Cyan"
    },
    {
      "x": -2,
      "y": 11,
      "z": -2,
      "name": "Plant_Coral_Block_Blue"
    },
    {
      "x": -2,
      "y": 12,
      "z": -2,
      "name": "Plant_Coral_Block_Blue"
    },
    {
      "x": -2,
      "y": 13,
      "z": -2,
      "name": "Plant_Coral_Block_Blue"
    },
    {
      "x": -2,
      "y": 14,
      "z": -2,
      "name": "Plant_Coral_Block_Blue"
    },
    {
      "x": -2,
      "y": 0,
      "z": -1,
      "name": "Plant_Coral_Block_Blue"
    },
    {
      "x": -2,
      "y": 3,
      "z": -1,
      "name": "Rock_Crystal_Cyan_Large",
      "rotation": 4
    },
    {
      "x": -2,
      "y": 5,
      "z": -1,
      "name": "Plant_Coral_Bush_Cyan"
    },
    {
      "x": -2,
      "y": 7,
      "z": -1,
      "name": "Plant_Coral_Bush_Cyan"
    },
    {
      "x": -2,
      "y": 13,
      "z": -1,
      "name": "Plant_Coral_Bush_Blue"
    },
    {
      "x": -2,
      "y": 14,
      "z": -1,
      "name": "Plant_Coral_Block_Blue"
    },
    {
      "x": -2,
      "y": 15,
      "z": -1,
      "name": "Plant_Coral_Block_Blue"
    },
    {
      "x": -2,
      "y": 16,
      "z": -1,
      "name": "Plant_Coral_Block_Blue"
    },
    {
      "x": -2,
      "y": 17,
      "z": -1,
      "name": "Plant_Coral_Block_Blue"
    },
    {
      "x": -2,
      "y": 0,
      "z": 0,
      "name": "Plant_Coral_Block_Blue"
    },
    {
      "x": -2,
      "y": 1,
      "z": 0,
      "name": "Plant_Coral_Bush_Blue"
    },
    {
      "x": -2,
      "y": 4,
      "z": 0,
      "name": "Plant_Coral_Bush_Cyan"
    },
    {
      "x": -2,
      "y": 5,
      "z": 0,
      "name": "Plant_Coral_Bush_Cyan"
    },
    {
      "x": -2,
      "y": 7,
      "z": 0,
      "name": "Plant_Coral_Bush_Cyan"
    },
    {
      "x": -2,
      "y": 10,
      "z": 0,
      "name": "Plant_Coral_Bush_Blue"
    },
    {
      "x": -2,
      "y": 11,
      "z": 0,
      "name": "Plant_Coral_Bush_Blue"
    },
    {
      "x": -2,
      "y": 12,
      "z": 0,
      "name": "Plant_Coral_Bush_Blue"
    },
    {
      "x": -2,
      "y": 14,
      "z": 0,
      "name": "Plant_Coral_Block_Blue"
    },
    {
      "x": -2,
      "y": 15,
      "z": 0,
      "name": "Plant_Coral_Block_Blue"
    },
    {
      "x": -2,
      "y": 16,
      "z": 0,
      "name": "Plant_Coral_Block_Blue"
    },
    {
      "x": -2,
      "y": 17,
      "z": 0,
      "name": "Plant_Coral_Block_Blue"
    },
    {
      "x": -2,
      "y": 0,
      "z": 1,
      "name": "Plant_Coral_Block_Blue"
    },
    {
      "x": -2,
      "y": 3,
      "z": 1,
      "name": "Plant_Coral_Bush_Blue"
    },
    {
      "x": -2,
      "y": 5,
      "z": 1,
      "name": "Plant_Coral_Bush_Blue"
    },
    {
      "x": -2,
      "y": 8,
      "z": 1,
      "name": "Plant_Coral_Block_Blue"
    },
    {
      "x": -2,
      "y": 9,
      "z": 1,
      "name": "Plant_Coral_Block_Blue"
    },
    {
      "x": -2,
      "y": 10,
      "z": 1,
      "name": "Plant_Coral_Block_Blue"
    },
    {
      "x": -2,
      "y": 13,
      "z": 1,
      "name": "Plant_Coral_Bush_Blue"
    },
    {
      "x": -2,
      "y": 14,
      "z": 1,
      "name": "Plant_Coral_Block_Blue"
    },
    {
      "x": -2,
      "y": 15,
      "z": 1,
      "name": "Plant_Coral_Block_Blue"
    },
    {
      "x": -2,
      "y": 16,
      "z": 1,
      "name": "Plant_Coral_Block_Blue"
    },
    {
      "x": -2,
      "y": 17,
      "z": 1,
      "name": "Plant_Coral_Block_Blue"
    },
    {
      "x": -2,
      "y": 1,
      "z": 2,
      "name": "Plant_Coral_Block_Blue"
    },
    {
      "x": -2,
      "y": 2,
      "z": 2,
      "name": "Plant_Coral_Block_Blue"
    },
    {
      "x": -2,
      "y": 3,
      "z": 2,
      "name": "Plant_Coral_Block_Blue"
    },
    {
      "x": -2,
      "y": 4,
      "z": 2,
      "name": "Plant_Coral_Block_Blue"
    },
    {
      "x": -2,
      "y": 5,
      "z": 2,
      "name": "Plant_Coral_Block_Blue"
    },
    {
      "x": -2,
      "y": 6,
      "z": 2,
      "name": "Plant_Coral_Block_Blue"
    },
    {
      "x": -2,
      "y": 7,
      "z": 2,
      "name": "Plant_Coral_Block_Blue"
    },
    {
      "x": -2,
      "y": 8,
      "z": 2,
      "name": "Plant_Coral_Block_Blue"
    },
    {
      "x": -2,
      "y": 9,
      "z": 2,
      "name": "Plant_Coral_Model_Blue"
    },
    {
      "x": -2,
      "y": 10,
      "z": 2,
      "name": "Plant_Coral_Block_Blue"
    },
    {
      "x": -2,
      "y": 11,
      "z": 2,
      "name": "Plant_Coral_Block_Blue"
    },
    {
      "x": -2,
      "y": 12,
      "z": 2,
      "name": "Plant_Coral_Block_Blue"
    },
    {
      "x": -2,
      "y": 13,
      "z": 2,
      "name": "Plant_Coral_Block_Blue"
    },
    {
      "x": -2,
      "y": 14,
      "z": 2,
      "name": "Plant_Coral_Block_Blue"
    },
    {
      "x": -2,
      "y": 15,
      "z": 2,
      "name": "Plant_Coral_Model_Blue"
    },
    {
      "x": -2,
      "y": 11,
      "z": 3,
      "name": "Plant_Coral_Block_Cyan"
    },
    {
      "x": -2,
      "y": 14,
      "z": 3,
      "name": "Plant_Coral_Block_Blue"
    },
    {
      "x": -2,
      "y": 11,
      "z": 4,
      "name": "Plant_Coral_Block_Cyan"
    },
    {
      "x": -2,
      "y": 11,
      "z": 5,
      "name": "Plant_Coral_Block_Blue"
    },
    {
      "x": -1,
      "y": 14,
      "z": -7,
      "name": "Plant_Coral_Block_Blue"
    },
    {
      "x": -1,
      "y": 14,
      "z": -6,
      "name": "Plant_Coral_Block_Cyan"
    },
    {
      "x": -1,
      "y": 14,
      "z": -5,
      "name": "Plant_Coral_Block_Cyan"
    },
    {
      "x": -1,
      "y": 8,
      "z": -4,
      "name": "Plant_Coral_Block_Cyan"
    },
    {
      "x": -1,
      "y": 9,
      "z": -4,
      "name": "Plant_Coral_Block_Cyan"
    },
    {
      "x": -1,
      "y": 10,
      "z": -4,
      "name": "Plant_Coral_Block_Blue"
    },
    {
      "x": -1,
      "y": 11,
      "z": -4,
      "name": "Plant_Coral_Block_Blue"
    },
    {
      "x": -1,
      "y": 14,
      "z": -4,
      "name": "Plant_Coral_Block_Cyan"
    },
    {
      "x": -1,
      "y": 1,
      "z": -3,
      "name": "Plant_Coral_Block_Blue"
    },
    {
      "x": -1,
      "y": 2,
      "z": -3,
      "name": "Plant_Coral_Block_Blue"
    },
    {
      "x": -1,
      "y": 3,
      "z": -3,
      "name": "Plant_Coral_Block_Blue"
    },
    {
      "x": -1,
      "y": 4,
      "z": -3,
      "name": "Plant_Coral_Block_Cyan"
    },
    {
      "x": -1,
      "y": 5,
      "z": -3,
      "name": "Plant_Coral_Block_Cyan"
    },
    {
      "x": -1,
      "y": 6,
      "z": -3,
      "name": "Plant_Coral_Block_Cyan"
    },
    {
      "x": -1,
      "y": 7,
      "z": -3,
      "name": "Plant_Coral_Block_Cyan"
    },
    {
      "x": -1,
      "y": 8,
      "z": -3,
      "name": "Plant_Coral_Bush_Cyan"
    },
    {
      "x": -1,
      "y": 9,
      "z": -3,
      "name": "Plant_Coral_Bush_Cyan"
    },
    {
      "x": -1,
      "y": 11,
      "z": -3,
      "name": "Plant_Coral_Block_Blue"
    },
    {
      "x": -1,
      "y": 12,
      "z": -3,
      "name": "Plant_Coral_Block_Blue"
    },
    {
      "x": -1,
      "y": 13,
      "z": -3,
      "name": "Plant_Coral_Block_Blue"
    },
    {
      "x": -1,
      "y": 14,
      "z": -3,
      "name": "Plant_Coral_Block_Cyan"
    },
    {
      "x": -1,
      "y": 15,
      "z": -3,
      "name": "Plant_Coral_Model_Cyan"
    },
    {
      "x": -1,
      "y": 0,
      "z": -2,
      "name": "Plant_Coral_Block_Blue"
    },
    {
      "x": -1,
      "y": 3,
      "z": -2,
      "name": "Plant_Coral_Bush_Cyan"
    },
    {
      "x": -1,
      "y": 5,
      "z": -2,
      "name": "Plant_Coral_Bush_Cyan"
    },
    {
      "x": -1,
      "y": 7,
      "z": -2,
      "name": "Plant_Coral_Bush_Cyan"
    },
    {
      "x": -1,
      "y": 11,
      "z": -2,
      "name": "Plant_Coral_Bush_Blue"
    },
    {
      "x": -1,
      "y": 12,
      "z": -2,
      "name": "Plant_Coral_Bush_Blue"
    },
    {
      "x": -1,
      "y": 13,
      "z": -2,
      "name": "Plant_Coral_Bush_Blue"
    },
    {
      "x": -1,
      "y": 14,
      "z": -2,
      "name": "Plant_Coral_Block_Blue"
    },
    {
      "x": -1,
      "y": 15,
      "z": -2,
      "name": "Plant_Coral_Block_Blue"
    },
    {
      "x": -1,
      "y": 16,
      "z": -2,
      "name": "Plant_Coral_Block_Blue"
    },
    {
      "x": -1,
      "y": 17,
      "z": -2,
      "name": "Plant_Coral_Block_Blue"
    },
    {
      "x": -1,
      "y": 0,
      "z": -1,
      "name": "Plant_Coral_Block_Blue"
    },
    {
      "x": -1,
      "y": 1,
      "z": -1,
      "name": "Plant_Coral_Bush_Blue"
    },
    {
      "x": -1,
      "y": 14,
      "z": -1,
      "name": "Plant_Coral_Bush_Blue"
    },
    {
      "x": -1,
      "y": 0,
      "z": 0,
      "name": "Plant_Coral_Block_Blue"
    },
    {
      "x": -1,
      "y": 15,
      "z": 0,
      "name": "Plant_Coral_Bush_Blue"
    },
    {
      "x": -1,
      "y": 0,
      "z": 1,
      "name": "Plant_Coral_Block_Blue"
    },
    {
      "x": -1,
      "y": 1,
      "z": 1,
      "name": "Plant_Coral_Bush_Blue"
    },
    {
      "x": -1,
      "y": 9,
      "z": 1,
      "name": "Plant_Coral_Bush_Blue"
    },
    {
      "x": -1,
      "y": 15,
      "z": 1,
      "name": "Plant_Coral_Bush_Blue"
    },
    {
      "x": -1,
      "y": 0,
      "z": 2,
      "name": "Plant_Coral_Block_Blue"
    },
    {
      "x": -1,
      "y": 6,
      "z": 2,
      "name": "Plant_Coral_Bush_Blue"
    },
    {
      "x": -1,
      "y": 7,
      "z": 2,
      "name": "Plant_Coral_Bush_Blue"
    },
    {
      "x": -1,
      "y": 8,
      "z": 2,
      "name": "Plant_Coral_Block_Blue"
    },
    {
      "x": -1,
      "y": 9,
      "z": 2,
      "name": "Plant_Coral_Block_Blue"
    },
    {
      "x": -1,
      "y": 10,
      "z": 2,
      "name": "Plant_Coral_Block_Blue"
    },
    {
      "x": -1,
      "y": 11,
      "z": 2,
      "name": "Plant_Coral_Bush_Blue"
    },
    {
      "x": -1,
      "y": 14,
      "z": 2,
      "name": "Plant_Coral_Block_Blue"
    },
    {
      "x": -1,
      "y": 15,
      "z": 2,
      "name": "Plant_Coral_Block_Blue"
    },
    {
      "x": -1,
      "y": 16,
      "z": 2,
      "name": "Plant_Coral_Block_Blue"
    },
    {
      "x": -1,
      "y": 1,
      "z": 3,
      "name": "Plant_Coral_Block_Blue"
    },
    {
      "x": -1,
      "y": 2,
      "z": 3,
      "name": "Plant_Coral_Block_Blue"
    },
    {
      "x": -1,
      "y": 3,
      "z": 3,
      "name": "Plant_Coral_Block_Blue"
    },
    {
      "x": -1,
      "y": 4,
      "z": 3,
      "name": "Plant_Coral_Block_Blue"
    },
    {
      "x": -1,
      "y": 5,
      "z": 3,
      "name": "Plant_Coral_Block_Blue"
    },
    {
      "x": -1,
      "y": 6,
      "z": 3,
      "name": "Plant_Coral_Block_Blue"
    },
    {
      "x": -1,
      "y": 7,
      "z": 3,
      "name": "Plant_Coral_Block_Blue"
    },
    {
      "x": -1,
      "y": 8,
      "z": 3,
      "name": "Plant_Coral_Block_Blue"
    },
    {
      "x": -1,
      "y": 9,
      "z": 3,
      "name": "Plant_Coral_Block_Blue"
    },
    {
      "x": -1,
      "y": 10,
      "z": 3,
      "name": "Plant_Coral_Block_Blue"
    },
    {
      "x": -1,
      "y": 11,
      "z": 3,
      "name": "Plant_Coral_Block_Blue"
    },
    {
      "x": -1,
      "y": 12,
      "z": 3,
      "name": "Plant_Coral_Block_Blue"
    },
    {
      "x": -1,
      "y": 13,
      "z": 3,
      "name": "Plant_Coral_Block_Blue"
    },
    {
      "x": -1,
      "y": 11,
      "z": 4,
      "name": "Plant_Coral_Block_Cyan"
    },
    {
      "x": -1,
      "y": 11,
      "z": 5,
      "name": "Plant_Coral_Block_Cyan"
    },
    {
      "x": -1,
      "y": 11,
      "z": 7,
      "name": "Plant_Coral_Block_Blue"
    },
    {
      "x": 0,
      "y": 14,
      "z": -7,
      "name": "Plant_Coral_Block_Blue"
    },
    {
      "x": 0,
      "y": 14,
      "z": -6,
      "name": "Plant_Coral_Block_Cyan"
    },
    {
      "x": 0,
      "y": 15,
      "z": -6,
      "name": "Plant_Coral_Model_Cyan"
    },
    {
      "x": 0,
      "y": 13,
      "z": -5,
      "name": "Plant_Crop_Mushroom_Block_Blue_Mycelium"
    },
    {
      "x": 0,
      "y": 14,
      "z": -5,
      "name": "Plant_Coral_Block_Cyan"
    },
    {
      "x": 0,
      "y": 8,
      "z": -4,
      "name": "Plant_Coral_Block_Cyan"
    },
    {
      "x": 0,
      "y": 9,
      "z": -4,
      "name": "Plant_Coral_Block_Blue"
    },
    {
      "x": 0,
      "y": 10,
      "z": -4,
      "name": "Plant_Coral_Block_Blue"
    },
    {
      "x": 0,
      "y": 11,
      "z": -4,
      "name": "Plant_Coral_Block_Blue"
    },
    {
      "x": 0,
      "y": 14,
      "z": -4,
      "name": "Plant_Coral_Block_Cyan"
    },
    {
      "x": 0,
      "y": 15,
      "z": -4,
      "name": "Plant_Coral_Bush_Cyan"
    },
    {
      "x": 0,
      "y": 1,
      "z": -3,
      "name": "Plant_Coral_Block_Blue"
    },
    {
      "x": 0,
      "y": 2,
      "z": -3,
      "name": "Plant_Coral_Block_Blue"
    },
    {
      "x": 0,
      "y": 3,
      "z": -3,
      "name": "Plant_Coral_Block_Blue"
    },
    {
      "x": 0,
      "y": 4,
      "z": -3,
      "name": "Plant_Coral_Block_Cyan"
    },
    {
      "x": 0,
      "y": 5,
      "z": -3,
      "name": "Plant_Coral_Block_Cyan"
    },
    {
      "x": 0,
      "y": 6,
      "z": -3,
      "name": "Plant_Coral_Block_Cyan"
    },
    {
      "x": 0,
      "y": 7,
      "z": -3,
      "name": "Plant_Coral_Block_Cyan"
    },
    {
      "x": 0,
      "y": 10,
      "z": -3,
      "name": "Plant_Coral_Bush_Blue"
    },
    {
      "x": 0,
      "y": 11,
      "z": -3,
      "name": "Plant_Coral_Block_Blue"
    },
    {
      "x": 0,
      "y": 12,
      "z": -3,
      "name": "Plant_Coral_Block_Blue"
    },
    {
      "x": 0,
      "y": 13,
      "z": -3,
      "name": "Plant_Coral_Block_Blue"
    },
    {
      "x": 0,
      "y": 14,
      "z": -3,
      "name": "Plant_Coral_Block_Blue"
    },
    {
      "x": 0,
      "y": 15,
      "z": -3,
      "name": "Plant_Coral_Block_Blue"
    },
    {
      "x": 0,
      "y": 16,
      "z": -3,
      "name": "Plant_Coral_Block_Blue"
    },
    {
      "x": 0,
      "y": 17,
      "z": -3,
      "name": "Plant_Coral_Block_Blue"
    },
    {
      "x": 0,
      "y": 0,
      "z": -2,
      "name": "Plant_Coral_Block_Blue"
    },
    {
      "x": 0,
      "y": 5,
      "z": -2,
      "name": "Plant_Coral_Bush_Cyan"
    },
    {
      "x": 0,
      "y": 7,
      "z": -2,
      "name": "Plant_Coral_Bush_Cyan"
    },
    {
      "x": 0,
      "y": 14,
      "z": -2,
      "name": "Plant_Coral_Bush_Blue"
    },
    {
      "x": 0,
      "y": 15,
      "z": -2,
      "name": "Plant_Coral_Bush_Blue"
    },
    {
      "x": 0,
      "y": 16,
      "z": -2,
      "name": "Plant_Coral_Bush_Blue"
    },
    {
      "x": 0,
      "y": 0,
      "z": -1,
      "name": "Plant_Coral_Block_Blue"
    },
    {
      "x": 0,
      "y": 14,
      "z": -1,
      "name": "Plant_Coral_Bush_Blue"
    },
    {
      "x": 0,
      "y": 0,
      "z": 0,
      "name": "Plant_Coral_Block_Blue"
    },
    {
      "x": 0,
      "y": 0,
      "z": 1,
      "name": "Plant_Coral_Block_Blue"
    },
    {
      "x": 0,
      "y": 15,
      "z": 1,
      "name": "Plant_Coral_Bush_Blue"
    },
    {
      "x": 0,
      "y": 0,
      "z": 2,
      "name": "Plant_Coral_Block_Blue"
    },
    {
      "x": 0,
      "y": 3,
      "z": 2,
      "name": "Plant_Coral_Bush_Blue"
    },
    {
      "x": 0,
      "y": 4,
      "z": 2,
      "name": "Plant_Coral_Bush_Blue"
    },
    {
      "x": 0,
      "y": 7,
      "z": 2,
      "name": "Plant_Coral_Bush_Blue"
    },
    {
      "x": 0,
      "y": 8,
      "z": 2,
      "name": "Plant_Coral_Block_Blue"
    },
    {
      "x": 0,
      "y": 9,
      "z": 2,
      "name": "Plant_Coral_Block_Blue"
    },
    {
      "x": 0,
      "y": 10,
      "z": 2,
      "name": "Plant_Coral_Block_Blue"
    },
    {
      "x": 0,
      "y": 15,
      "z": 2,
      "name": "Plant_Coral_Bush_Blue"
    },
    {
      "x": 0,
      "y": 1,
      "z": 3,
      "name": "Plant_Coral_Block_Blue"
    },
    {
      "x": 0,
      "y": 2,
      "z": 3,
      "name": "Plant_Coral_Block_Blue"
    },
    {
      "x": 0,
      "y": 3,
      "z": 3,
      "name": "Plant_Coral_Block_Blue"
    },
    {
      "x": 0,
      "y": 4,
      "z": 3,
      "name": "Plant_Coral_Block_Blue"
    },
    {
      "x": 0,
      "y": 5,
      "z": 3,
      "name": "Plant_Coral_Block_Blue"
    },
    {
      "x": 0,
      "y": 6,
      "z": 3,
      "name": "Plant_Coral_Block_Blue"
    },
    {
      "x": 0,
      "y": 7,
      "z": 3,
      "name": "Plant_Coral_Block_Blue"
    },
    {
      "x": 0,
      "y": 8,
      "z": 3,
      "name": "Plant_Coral_Block_Blue"
    },
    {
      "x": 0,
      "y": 9,
      "z": 3,
      "name": "Plant_Coral_Block_Blue"
    },
    {
      "x": 0,
      "y": 10,
      "z": 3,
      "name": "Plant_Coral_Block_Blue"
    },
    {
      "x": 0,
      "y": 11,
      "z": 3,
      "name": "Plant_Coral_Block_Blue"
    },
    {
      "x": 0,
      "y": 12,
      "z": 3,
      "name": "Plant_Coral_Block_Blue"
    },
    {
      "x": 0,
      "y": 13,
      "z": 3,
      "name": "Plant_Coral_Block_Blue"
    },
    {
      "x": 0,
      "y": 14,
      "z": 3,
      "name": "Plant_Coral_Block_Blue"
    },
    {
      "x": 0,
      "y": 15,
      "z": 3,
      "name": "Plant_Coral_Block_Blue"
    },
    {
      "x": 0,
      "y": 10,
      "z": 4,
      "name": "Plant_Crop_Mushroom_Block_Blue_Mycelium"
    },
    {
      "x": 0,
      "y": 11,
      "z": 4,
      "name": "Plant_Coral_Block_Cyan"
    },
    {
      "x": 0,
      "y": 11,
      "z": 5,
      "name": "Plant_Coral_Block_Cyan"
    },
    {
      "x": 0,
      "y": 11,
      "z": 6,
      "name": "Plant_Coral_Block_Cyan"
    },
    {
      "x": 0,
      "y": 11,
      "z": 7,
      "name": "Plant_Coral_Block_Blue"
    },
    {
      "x": 1,
      "y": 14,
      "z": -6,
      "name": "Plant_Coral_Block_Cyan"
    },
    {
      "x": 1,
      "y": 14,
      "z": -5,
      "name": "Plant_Coral_Block_Cyan"
    },
    {
      "x": 1,
      "y": 15,
      "z": -5,
      "name": "Plant_Coral_Bush_Cyan"
    },
    {
      "x": 1,
      "y": 8,
      "z": -4,
      "name": "Plant_Coral_Block_Blue"
    },
    {
      "x": 1,
      "y": 9,
      "z": -4,
      "name": "Plant_Coral_Block_Blue"
    },
    {
      "x": 1,
      "y": 10,
      "z": -4,
      "name": "Plant_Coral_Block_Blue"
    },
    {
      "x": 1,
      "y": 11,
      "z": -4,
      "name": "Plant_Coral_Block_Blue"
    },
    {
      "x": 1,
      "y": 12,
      "z": -4,
      "name": "Plant_Coral_Model_Blue"
    },
    {
      "x": 1,
      "y": 14,
      "z": -4,
      "name": "Plant_Coral_Block_Cyan"
    },
    {
      "x": 1,
      "y": 1,
      "z": -3,
      "name": "Plant_Coral_Block_Blue"
    },
    {
      "x": 1,
      "y": 2,
      "z": -3,
      "name": "Plant_Coral_Block_Blue"
    },
    {
      "x": 1,
      "y": 3,
      "z": -3,
      "name": "Plant_Coral_Block_Blue"
    },
    {
      "x": 1,
      "y": 4,
      "z": -3,
      "name": "Plant_Coral_Block_Blue"
    },
    {
      "x": 1,
      "y": 5,
      "z": -3,
      "name": "Plant_Coral_Block_Cyan"
    },
    {
      "x": 1,
      "y": 6,
      "z": -3,
      "name": "Plant_Coral_Block_Cyan"
    },
    {
      "x": 1,
      "y": 7,
      "z": -3,
      "name": "Plant_Coral_Block_Cyan"
    },
    {
      "x": 1,
      "y": 8,
      "z": -3,
      "name": "Plant_Coral_Bush_Cyan"
    },
    {
      "x": 1,
      "y": 9,
      "z": -3,
      "name": "Plant_Coral_Bush_Blue"
    },
    {
      "x": 1,
      "y": 11,
      "z": -3,
      "name": "Plant_Coral_Block_Blue"
    },
    {
      "x": 1,
      "y": 12,
      "z": -3,
      "name": "Plant_Coral_Block_Blue"
    },
    {
      "x": 1,
      "y": 13,
      "z": -3,
      "name": "Plant_Coral_Block_Blue"
    },
    {
      "x": 1,
      "y": 14,
      "z": -3,
      "name": "Plant_Coral_Block_Blue"
    },
    {
      "x": 1,
      "y": 15,
      "z": -3,
      "name": "Plant_Coral_Block_Blue"
    },
    {
      "x": 1,
      "y": 16,
      "z": -3,
      "name": "Plant_Coral_Block_Blue"
    },
    {
      "x": 1,
      "y": 17,
      "z": -3,
      "name": "Plant_Coral_Block_Blue"
    },
    {
      "x": 1,
      "y": 0,
      "z": -2,
      "name": "Plant_Coral_Block_Blue"
    },
    {
      "x": 1,
      "y": 1,
      "z": -2,
      "name": "Plant_Coral_Bush_Blue"
    },
    {
      "x": 1,
      "y": 3,
      "z": -2,
      "name": "Plant_Coral_Bush_Blue"
    },
    {
      "x": 1,
      "y": 6,
      "z": -2,
      "name": "Plant_Coral_Bush_Cyan"
    },
    {
      "x": 1,
      "y": 12,
      "z": -2,
      "name": "Plant_Coral_Bush_Blue"
    },
    {
      "x": 1,
      "y": 14,
      "z": -2,
      "name": "Plant_Coral_Bush_Blue"
    },
    {
      "x": 1,
      "y": 0,
      "z": -1,
      "name": "Plant_Coral_Block_Blue"
    },
    {
      "x": 1,
      "y": 3,
      "z": -1,
      "name": "Plant_Coral_Bush_Blue"
    },
    {
      "x": 1,
      "y": 11,
      "z": -1,
      "name": "Plant_Coral_Bush_Blue"
    },
    {
      "x": 1,
      "y": 0,
      "z": 0,
      "name": "Plant_Coral_Block_Blue"
    },
    {
      "x": 1,
      "y": 0,
      "z": 1,
      "name": "Plant_Coral_Block_Blue"
    },
    {
      "x": 1,
      "y": 1,
      "z": 1,
      "name": "Plant_Coral_Bush_Blue"
    },
    {
      "x": 1,
      "y": 9,
      "z": 1,
      "name": "Plant_Coral_Bush_Blue"
    },
    {
      "x": 1,
      "y": 0,
      "z": 2,
      "name": "Plant_Coral_Block_Blue"
    },
    {
      "x": 1,
      "y": 3,
      "z": 2,
      "name": "Plant_Coral_Bush_Blue"
    },
    {
      "x": 1,
      "y": 5,
      "z": 2,
      "name": "Plant_Coral_Bush_Blue"
    },
    {
      "x": 1,
      "y": 6,
      "z": 2,
      "name": "Plant_Coral_Bush_Blue"
    },
    {
      "x": 1,
      "y": 8,
      "z": 2,
      "name": "Plant_Coral_Block_Blue"
    },
    {
      "x": 1,
      "y": 9,
      "z": 2,
      "name": "Plant_Coral_Block_Blue"
    },
    {
      "x": 1,
      "y": 10,
      "z": 2,
      "name": "Plant_Coral_Block_Blue"
    },
    {
      "x": 1,
      "y": 11,
      "z": 2,
      "name": "Rock_Crystal_Blue_Medium"
    },
    {
      "x": 1,
      "y": 12,
      "z": 2,
      "name": "Plant_Coral_Bush_Blue"
    },
    {
      "x": 1,
      "y": 13,
      "z": 2,
      "name": "Plant_Coral_Bush_Blue"
    },
    {
      "x": 1,
      "y": 14,
      "z": 2,
      "name": "Plant_Coral_Bush_Blue"
    },
    {
      "x": 1,
      "y": 1,
      "z": 3,
      "name": "Plant_Coral_Block_Blue"
    },
    {
      "x": 1,
      "y": 2,
      "z": 3,
      "name": "Plant_Coral_Block_Blue"
    },
    {
      "x": 1,
      "y": 3,
      "z": 3,
      "name": "Plant_Coral_Block_Blue"
    },
    {
      "x": 1,
      "y": 4,
      "z": 3,
      "name": "Plant_Coral_Block_Blue"
    },
    {
      "x": 1,
      "y": 5,
      "z": 3,
      "name": "Plant_Coral_Block_Blue"
    },
    {
      "x": 1,
      "y": 6,
      "z": 3,
      "name": "Plant_Coral_Block_Blue"
    },
    {
      "x": 1,
      "y": 7,
      "z": 3,
      "name": "Plant_Coral_Block_Blue"
    },
    {
      "x": 1,
      "y": 8,
      "z": 3,
      "name": "Plant_Coral_Block_Blue"
    },
    {
      "x": 1,
      "y": 9,
      "z": 3,
      "name": "Plant_Coral_Block_Blue"
    },
    {
      "x": 1,
      "y": 10,
      "z": 3,
      "name": "Plant_Coral_Block_Blue"
    },
    {
      "x": 1,
      "y": 11,
      "z": 3,
      "name": "Plant_Coral_Block_Blue"
    },
    {
      "x": 1,
      "y": 12,
      "z": 3,
      "name": "Plant_Coral_Block_Blue"
    },
    {
      "x": 1,
      "y": 13,
      "z": 3,
      "name": "Plant_Coral_Block_Blue"
    },
    {
      "x": 1,
      "y": 14,
      "z": 3,
      "name": "Plant_Coral_Block_Blue"
    },
    {
      "x": 1,
      "y": 15,
      "z": 3,
      "name": "Plant_Coral_Block_Blue"
    },
    {
      "x": 1,
      "y": 11,
      "z": 4,
      "name": "Plant_Coral_Block_Cyan"
    },
    {
      "x": 1,
      "y": 12,
      "z": 4,
      "name": "Plant_Coral_Bush_Cyan"
    },
    {
      "x": 1,
      "y": 11,
      "z": 5,
      "name": "Plant_Coral_Block_Cyan"
    },
    {
      "x": 1,
      "y": 11,
      "z": 6,
      "name": "Plant_Coral_Block_Cyan"
    },
    {
      "x": 1,
      "y": 11,
      "z": 7,
      "name": "Plant_Coral_Block_Blue"
    },
    {
      "x": 2,
      "y": 14,
      "z": -7,
      "name": "Plant_Coral_Block_Blue"
    },
    {
      "x": 2,
      "y": 14,
      "z": -6,
      "name": "Plant_Coral_Block_Blue"
    },
    {
      "x": 2,
      "y": 14,
      "z": -5,
      "name": "Plant_Coral_Block_Cyan"
    },
    {
      "x": 2,
      "y": 14,
      "z": -4,
      "name": "Plant_Coral_Block_Cyan"
    },
    {
      "x": 2,
      "y": 8,
      "z": -3,
      "name": "Plant_Coral_Block_Blue"
    },
    {
      "x": 2,
      "y": 9,
      "z": -3,
      "name": "Plant_Coral_Block_Blue"
    },
    {
      "x": 2,
      "y": 10,
      "z": -3,
      "name": "Plant_Coral_Block_Blue"
    },
    {
      "x": 2,
      "y": 11,
      "z": -3,
      "name": "Plant_Coral_Block_Blue"
    },
    {
      "x": 2,
      "y": 14,
      "z": -3,
      "name": "Plant_Coral_Block_Blue"
    },
    {
      "x": 2,
      "y": 15,
      "z": -3,
      "name": "Plant_Coral_Block_Blue"
    },
    {
      "x": 2,
      "y": 16,
      "z": -3,
      "name": "Plant_Coral_Block_Blue"
    },
    {
      "x": 2,
      "y": 17,
      "z": -3,
      "name": "Plant_Coral_Block_Blue"
    },
    {
      "x": 2,
      "y": 1,
      "z": -2,
      "name": "Plant_Coral_Block_Blue"
    },
    {
      "x": 2,
      "y": 2,
      "z": -2,
      "name": "Plant_Coral_Block_Blue"
    },
    {
      "x": 2,
      "y": 3,
      "z": -2,
      "name": "Plant_Coral_Block_Blue"
    },
    {
      "x": 2,
      "y": 4,
      "z": -2,
      "name": "Plant_Coral_Block_Blue"
    },
    {
      "x": 2,
      "y": 5,
      "z": -2,
      "name": "Plant_Coral_Block_Blue"
    },
    {
      "x": 2,
      "y": 6,
      "z": -2,
      "name": "Plant_Coral_Block_Blue"
    },
    {
      "x": 2,
      "y": 7,
      "z": -2,
      "name": "Plant_Coral_Block_Blue"
    },
    {
      "x": 2,
      "y": 10,
      "z": -2,
      "name": "Plant_Coral_Bush_Blue"
    },
    {
      "x": 2,
      "y": 11,
      "z": -2,
      "name": "Plant_Coral_Block_Blue"
    },
    {
      "x": 2,
      "y": 12,
      "z": -2,
      "name": "Plant_Coral_Block_Blue"
    },
    {
      "x": 2,
      "y": 13,
      "z": -2,
      "name": "Plant_Coral_Block_Blue"
    },
    {
      "x": 2,
      "y": 0,
      "z": -1,
      "name": "Plant_Coral_Block_Blue"
    },
    {
      "x": 2,
      "y": 1,
      "z": -1,
      "name": "Plant_Coral_Bush_Blue"
    },
    {
      "x": 2,
      "y": 6,
      "z": -1,
      "name": "Plant_Coral_Bush_Blue"
    },
    {
      "x": 2,
      "y": 9,
      "z": -1,
      "name": "Plant_Coral_Bush_Blue"
    },
    {
      "x": 2,
      "y": 11,
      "z": -1,
      "name": "Plant_Coral_Bush_Blue"
    },
    {
      "x": 2,
      "y": 13,
      "z": -1,
      "name": "Plant_Coral_Bush_Blue"
    },
    {
      "x": 2,
      "y": 0,
      "z": 0,
      "name": "Plant_Coral_Block_Blue"
    },
    {
      "x": 2,
      "y": 3,
      "z": 0,
      "name": "Plant_Coral_Bush_Blue"
    },
    {
      "x": 2,
      "y": 4,
      "z": 0,
      "name": "Plant_Coral_Bush_Blue"
    },
    {
      "x": 2,
      "y": 5,
      "z": 0,
      "name": "Plant_Coral_Bush_Blue"
    },
    {
      "x": 2,
      "y": 9,
      "z": 0,
      "name": "Plant_Coral_Bush_Blue"
    },
    {
      "x": 2,
      "y": 11,
      "z": 0,
      "name": "Plant_Coral_Bush_Blue"
    },
    {
      "x": 2,
      "y": 12,
      "z": 0,
      "name": "Plant_Coral_Bush_Blue"
    },
    {
      "x": 2,
      "y": 13,
      "z": 0,
      "name": "Plant_Coral_Bush_Blue"
    },
    {
      "x": 2,
      "y": 0,
      "z": 1,
      "name": "Plant_Coral_Block_Blue"
    },
    {
      "x": 2,
      "y": 1,
      "z": 1,
      "name": "Plant_Coral_Bush_Blue"
    },
    {
      "x": 2,
      "y": 3,
      "z": 1,
      "name": "Plant_Coral_Bush_Blue"
    },
    {
      "x": 2,
      "y": 5,
      "z": 1,
      "name": "Plant_Coral_Bush_Blue"
    },
    {
      "x": 2,
      "y": 6,
      "z": 1,
      "name": "Plant_Coral_Bush_Blue"
    },
    {
      "x": 2,
      "y": 8,
      "z": 1,
      "name": "Plant_Coral_Block_Blue"
    },
    {
      "x": 2,
      "y": 9,
      "z": 1,
      "name": "Plant_Coral_Block_Blue"
    },
    {
      "x": 2,
      "y": 10,
      "z": 1,
      "name": "Plant_Coral_Block_Blue"
    },
    {
      "x": 2,
      "y": 12,
      "z": 1,
      "name": "Plant_Coral_Bush_Blue"
    },
    {
      "x": 2,
      "y": 14,
      "z": 1,
      "name": "Plant_Coral_Bush_Blue"
    },
    {
      "x": 2,
      "y": 1,
      "z": 2,
      "name": "Plant_Coral_Block_Blue"
    },
    {
      "x": 2,
      "y": 2,
      "z": 2,
      "name": "Plant_Coral_Block_Blue"
    },
    {
      "x": 2,
      "y": 3,
      "z": 2,
      "name": "Plant_Coral_Block_Blue"
    },
    {
      "x": 2,
      "y": 4,
      "z": 2,
      "name": "Plant_Coral_Block_Blue"
    },
    {
      "x": 2,
      "y": 5,
      "z": 2,
      "name": "Plant_Coral_Block_Blue"
    },
    {
      "x": 2,
      "y": 6,
      "z": 2,
      "name": "Plant_Coral_Block_Blue"
    },
    {
      "x": 2,
      "y": 7,
      "z": 2,
      "name": "Plant_Coral_Block_Blue"
    },
    {
      "x": 2,
      "y": 8,
      "z": 2,
      "name": "Plant_Coral_Block_Blue"
    },
    {
      "x": 2,
      "y": 10,
      "z": 2,
      "name": "Plant_Coral_Block_Blue"
    },
    {
      "x": 2,
      "y": 11,
      "z": 2,
      "name": "Plant_Coral_Block_Blue"
    },
    {
      "x": 2,
      "y": 12,
      "z": 2,
      "name": "Plant_Coral_Block_Blue"
    },
    {
      "x": 2,
      "y": 13,
      "z": 2,
      "name": "Plant_Coral_Block_Blue"
    },
    {
      "x": 2,
      "y": 11,
      "z": 3,
      "name": "Plant_Coral_Block_Cyan"
    },
    {
      "x": 2,
      "y": 12,
      "z": 3,
      "name": "Rock_Crystal_Cyan_Small"
    },
    {
      "x": 2,
      "y": 14,
      "z": 3,
      "name": "Plant_Coral_Block_Blue"
    },
    {
      "x": 2,
      "y": 15,
      "z": 3,
      "name": "Plant_Coral_Block_Blue"
    },
    {
      "x": 2,
      "y": 11,
      "z": 4,
      "name": "Plant_Coral_Block_Cyan"
    },
    {
      "x": 2,
      "y": 11,
      "z": 5,
      "name": "Plant_Coral_Block_Cyan"
    },
    {
      "x": 2,
      "y": 12,
      "z": 5,
      "name": "Plant_Coral_Bush_Cyan"
    },
    {
      "x": 2,
      "y": 11,
      "z": 6,
      "name": "Plant_Coral_Block_Cyan"
    },
    {
      "x": 3,
      "y": 14,
      "z": -6,
      "name": "Plant_Coral_Block_Blue"
    },
    {
      "x": 3,
      "y": 14,
      "z": -4,
      "name": "Plant_Coral_Block_Cyan"
    },
    {
      "x": 3,
      "y": 11,
      "z": -3,
      "name": "Plant_Coral_Block_Blue"
    },
    {
      "x": 3,
      "y": 13,
      "z": -3,
      "name": "Plant_Crop_Mushroom_Block_Blue_Mycelium"
    },
    {
      "x": 3,
      "y": 14,
      "z": -3,
      "name": "Plant_Coral_Block_Cyan"
    },
    {
      "x": 3,
      "y": 8,
      "z": -2,
      "name": "Plant_Coral_Block_Blue"
    },
    {
      "x": 3,
      "y": 9,
      "z": -2,
      "name": "Plant_Coral_Block_Blue"
    },
    {
      "x": 3,
      "y": 10,
      "z": -2,
      "name": "Plant_Coral_Block_Blue"
    },
    {
      "x": 3,
      "y": 11,
      "z": -2,
      "name": "Plant_Coral_Block_Cyan"
    },
    {
      "x": 3,
      "y": 13,
      "z": -2,
      "name": "Plant_Coral_Block_Blue"
    },
    {
      "x": 3,
      "y": 14,
      "z": -2,
      "name": "Plant_Coral_Block_Blue"
    },
    {
      "x": 3,
      "y": 15,
      "z": -2,
      "name": "Plant_Coral_Block_Blue"
    },
    {
      "x": 3,
      "y": 16,
      "z": -2,
      "name": "Plant_Coral_Block_Blue"
    },
    {
      "x": 3,
      "y": 1,
      "z": -1,
      "name": "Plant_Coral_Block_Blue"
    },
    {
      "x": 3,
      "y": 2,
      "z": -1,
      "name": "Plant_Coral_Block_Blue"
    },
    {
      "x": 3,
      "y": 3,
      "z": -1,
      "name": "Plant_Coral_Block_Blue"
    },
    {
      "x": 3,
      "y": 4,
      "z": -1,
      "name": "Plant_Coral_Block_Blue"
    },
    {
      "x": 3,
      "y": 5,
      "z": -1,
      "name": "Plant_Coral_Block_Blue"
    },
    {
      "x": 3,
      "y": 6,
      "z": -1,
      "name": "Plant_Coral_Block_Blue"
    },
    {
      "x": 3,
      "y": 7,
      "z": -1,
      "name": "Plant_Coral_Block_Blue"
    },
    {
      "x": 3,
      "y": 8,
      "z": -1,
      "name": "Plant_Coral_Block_Blue"
    },
    {
      "x": 3,
      "y": 9,
      "z": -1,
      "name": "Plant_Coral_Block_Blue"
    },
    {
      "x": 3,
      "y": 10,
      "z": -1,
      "name": "Plant_Coral_Block_Blue"
    },
    {
      "x": 3,
      "y": 11,
      "z": -1,
      "name": "Plant_Coral_Block_Blue"
    },
    {
      "x": 3,
      "y": 12,
      "z": -1,
      "name": "Plant_Coral_Block_Blue"
    },
    {
      "x": 3,
      "y": 13,
      "z": -1,
      "name": "Plant_Coral_Block_Blue"
    },
    {
      "x": 3,
      "y": 15,
      "z": -1,
      "name": "Plant_Coral_Bush_Blue"
    },
    {
      "x": 3,
      "y": 1,
      "z": 0,
      "name": "Plant_Coral_Block_Blue"
    },
    {
      "x": 3,
      "y": 2,
      "z": 0,
      "name": "Plant_Coral_Block_Blue"
    },
    {
      "x": 3,
      "y": 3,
      "z": 0,
      "name": "Plant_Coral_Block_Blue"
    },
    {
      "x": 3,
      "y": 4,
      "z": 0,
      "name": "Plant_Coral_Block_Blue"
    },
    {
      "x": 3,
      "y": 5,
      "z": 0,
      "name": "Plant_Coral_Block_Blue"
    },
    {
      "x": 3,
      "y": 6,
      "z": 0,
      "name": "Plant_Coral_Block_Blue"
    },
    {
      "x": 3,
      "y": 7,
      "z": 0,
      "name": "Plant_Coral_Block_Blue"
    },
    {
      "x": 3,
      "y": 8,
      "z": 0,
      "name": "Plant_Coral_Block_Blue"
    },
    {
      "x": 3,
      "y": 9,
      "z": 0,
      "name": "Plant_Coral_Block_Blue"
    },
    {
      "x": 3,
      "y": 10,
      "z": 0,
      "name": "Plant_Coral_Block_Blue"
    },
    {
      "x": 3,
      "y": 11,
      "z": 0,
      "name": "Plant_Coral_Block_Blue"
    },
    {
      "x": 3,
      "y": 12,
      "z": 0,
      "name": "Plant_Coral_Block_Blue"
    },
    {
      "x": 3,
      "y": 13,
      "z": 0,
      "name": "Plant_Coral_Block_Blue"
    },
    {
      "x": 3,
      "y": 14,
      "z": 0,
      "name": "Plant_Coral_Bush_Blue"
    },
    {
      "x": 3,
      "y": 1,
      "z": 1,
      "name": "Plant_Coral_Block_Blue"
    },
    {
      "x": 3,
      "y": 2,
      "z": 1,
      "name": "Plant_Coral_Block_Blue"
    },
    {
      "x": 3,
      "y": 3,
      "z": 1,
      "name": "Plant_Coral_Block_Blue"
    },
    {
      "x": 3,
      "y": 4,
      "z": 1,
      "name": "Plant_Coral_Block_Blue"
    },
    {
      "x": 3,
      "y": 5,
      "z": 1,
      "name": "Plant_Coral_Block_Blue"
    },
    {
      "x": 3,
      "y": 6,
      "z": 1,
      "name": "Plant_Coral_Block_Blue"
    },
    {
      "x": 3,
      "y": 7,
      "z": 1,
      "name": "Plant_Coral_Block_Blue"
    },
    {
      "x": 3,
      "y": 11,
      "z": 1,
      "name": "Plant_Coral_Block_Blue"
    },
    {
      "x": 3,
      "y": 12,
      "z": 1,
      "name": "Plant_Coral_Block_Blue"
    },
    {
      "x": 3,
      "y": 13,
      "z": 1,
      "name": "Plant_Coral_Block_Blue"
    },
    {
      "x": 3,
      "y": 14,
      "z": 1,
      "name": "Plant_Coral_Bush_Blue"
    },
    {
      "x": 3,
      "y": 11,
      "z": 2,
      "name": "Plant_Coral_Block_Cyan"
    },
    {
      "x": 3,
      "y": 13,
      "z": 2,
      "name": "Plant_Coral_Block_Blue"
    },
    {
      "x": 3,
      "y": 14,
      "z": 2,
      "name": "Plant_Coral_Block_Blue"
    },
    {
      "x": 3,
      "y": 15,
      "z": 2,
      "name": "Plant_Coral_Block_Blue"
    },
    {
      "x": 3,
      "y": 10,
      "z": 3,
      "name": "Plant_Crop_Mushroom_Block_Blue_Mycelium"
    },
    {
      "x": 3,
      "y": 11,
      "z": 3,
      "name": "Plant_Coral_Block_Cyan"
    },
    {
      "x": 3,
      "y": 12,
      "z": 3,
      "name": "Plant_Coral_Model_Cyan"
    },
    {
      "x": 3,
      "y": 11,
      "z": 4,
      "name": "Plant_Coral_Block_Cyan"
    },
    {
      "x": 3,
      "y": 12,
      "z": 4,
      "name": "Plant_Coral_Bush_Cyan"
    },
    {
      "x": 3,
      "y": 11,
      "z": 5,
      "name": "Plant_Coral_Block_Cyan"
    },
    {
      "x": 3,
      "y": 10,
      "z": 6,
      "name": "Plant_Crop_Mushroom_Block_Blue_Mycelium"
    },
    {
      "x": 3,
      "y": 11,
      "z": 6,
      "name": "Plant_Coral_Block_Cyan"
    },
    {
      "x": 3,
      "y": 11,
      "z": 7,
      "name": "Plant_Coral_Block_Blue"
    },
    {
      "x": 4,
      "y": 14,
      "z": -4,
      "name": "Plant_Coral_Block_Blue"
    },
    {
      "x": 4,
      "y": 14,
      "z": -3,
      "name": "Plant_Coral_Block_Blue"
    },
    {
      "x": 4,
      "y": 10,
      "z": -2,
      "name": "Plant_Crop_Mushroom_Block_Blue_Mycelium"
    },
    {
      "x": 4,
      "y": 11,
      "z": -2,
      "name": "Plant_Coral_Block_Cyan"
    },
    {
      "x": 4,
      "y": 11,
      "z": -1,
      "name": "Plant_Coral_Block_Cyan"
    },
    {
      "x": 4,
      "y": 13,
      "z": -1,
      "name": "Plant_Coral_Block_Blue"
    },
    {
      "x": 4,
      "y": 14,
      "z": -1,
      "name": "Plant_Coral_Block_Blue"
    },
    {
      "x": 4,
      "y": 15,
      "z": -1,
      "name": "Plant_Coral_Block_Blue"
    },
    {
      "x": 4,
      "y": 16,
      "z": -1,
      "name": "Plant_Coral_Block_Blue"
    },
    {
      "x": 4,
      "y": 11,
      "z": 0,
      "name": "Plant_Coral_Block_Cyan"
    },
    {
      "x": 4,
      "y": 12,
      "z": 0,
      "name": "Plant_Coral_Bush_Cyan"
    },
    {
      "x": 4,
      "y": 13,
      "z": 0,
      "name": "Plant_Coral_Block_Blue"
    },
    {
      "x": 4,
      "y": 14,
      "z": 0,
      "name": "Plant_Coral_Block_Blue"
    },
    {
      "x": 4,
      "y": 15,
      "z": 0,
      "name": "Plant_Coral_Block_Blue"
    },
    {
      "x": 4,
      "y": 16,
      "z": 0,
      "name": "Plant_Coral_Block_Blue"
    },
    {
      "x": 4,
      "y": 11,
      "z": 1,
      "name": "Plant_Coral_Block_Cyan"
    },
    {
      "x": 4,
      "y": 13,
      "z": 1,
      "name": "Plant_Coral_Block_Blue"
    },
    {
      "x": 4,
      "y": 14,
      "z": 1,
      "name": "Plant_Coral_Block_Blue"
    },
    {
      "x": 4,
      "y": 15,
      "z": 1,
      "name": "Plant_Coral_Block_Blue"
    },
    {
      "x": 4,
      "y": 16,
      "z": 1,
      "name": "Plant_Coral_Model_Blue"
    },
    {
      "x": 4,
      "y": 11,
      "z": 2,
      "name": "Plant_Coral_Block_Cyan"
    },
    {
      "x": 4,
      "y": 12,
      "z": 2,
      "name": "Plant_Coral_Bush_Cyan"
    },
    {
      "x": 4,
      "y": 11,
      "z": 3,
      "name": "Plant_Coral_Block_Cyan"
    },
    {
      "x": 4,
      "y": 12,
      "z": 3,
      "name": "Plant_Coral_Bush_Cyan"
    },
    {
      "x": 4,
      "y": 11,
      "z": 4,
      "name": "Plant_Coral_Block_Cyan"
    },
    {
      "x": 4,
      "y": 12,
      "z": 4,
      "name": "Plant_Coral_Model_Cyan"
    },
    {
      "x": 4,
      "y": 11,
      "z": 5,
      "name": "Plant_Coral_Block_Cyan"
    },
    {
      "x": 4,
      "y": 11,
      "z": 6,
      "name": "Plant_Coral_Block_Cyan"
    },
    {
      "x": 4,
      "y": 11,
      "z": 7,
      "name": "Plant_Coral_Block_Blue"
    },
    {
      "x": 5,
      "y": 11,
      "z": -3,
      "name": "Plant_Coral_Block_Blue"
    },
    {
      "x": 5,
      "y": 11,
      "z": -2,
      "name": "Plant_Coral_Block_Blue"
    },
    {
      "x": 5,
      "y": 11,
      "z": -1,
      "name": "Plant_Coral_Block_Cyan"
    },
    {
      "x": 5,
      "y": 11,
      "z": 0,
      "name": "Plant_Coral_Block_Cyan"
    },
    {
      "x": 5,
      "y": 11,
      "z": 1,
      "name": "Plant_Coral_Block_Cyan"
    },
    {
      "x": 5,
      "y": 11,
      "z": 2,
      "name": "Plant_Coral_Block_Cyan"
    },
    {
      "x": 5,
      "y": 12,
      "z": 2,
      "name": "Plant_Coral_Model_Cyan"
    },
    {
      "x": 5,
      "y": 11,
      "z": 3,
      "name": "Plant_Coral_Block_Cyan"
    },
    {
      "x": 5,
      "y": 11,
      "z": 4,
      "name": "Plant_Coral_Block_Cyan"
    },
    {
      "x": 5,
      "y": 11,
      "z": 5,
      "name": "Plant_Coral_Block_Cyan"
    },
    {
      "x": 5,
      "y": 11,
      "z": 6,
      "name": "Plant_Coral_Block_Blue"
    },
    {
      "x": 5,
      "y": 11,
      "z": 7,
      "name": "Plant_Coral_Block_Blue"
    },
    {
      "x": 6,
      "y": 11,
      "z": -2,
      "name": "Plant_Coral_Block_Blue"
    },
    {
      "x": 6,
      "y": 11,
      "z": 0,
      "name": "Plant_Coral_Block_Cyan"
    },
    {
      "x": 6,
      "y": 10,
      "z": 1,
      "name": "Plant_Crop_Mushroom_Block_Blue_Mycelium"
    },
    {
      "x": 6,
      "y": 11,
      "z": 1,
      "name": "Plant_Coral_Block_Cyan"
    },
    {
      "x": 6,
      "y": 11,
      "z": 2,
      "name": "Plant_Coral_Block_Cyan"
    },
    {
      "x": 6,
      "y": 11,
      "z": 3,
      "name": "Plant_Coral_Block_Cyan"
    },
    {
      "x": 6,
      "y": 10,
      "z": 4,
      "name": "Plant_Crop_Mushroom_Block_Blue_Mycelium"
    },
    {
      "x": 6,
      "y": 11,
      "z": 4,
      "name": "Plant_Coral_Block_Cyan"
    },
    {
      "x": 7,
      "y": 11,
      "z": 0,
      "name": "Plant_Coral_Block_Blue"
    },
    {
      "x": 7,
      "y": 11,
      "z": 1,
      "name": "Plant_Coral_Block_Blue"
    },
    {
      "x": 7,
      "y": 11,
      "z": 3,
      "name": "Plant_Coral_Block_Blue"
    },
    {
      "x": 7,
      "y": 11,
      "z": 4,
      "name": "Plant_Coral_Block_Blue"
    },
    {
      "x": 7,
      "y": 11,
      "z": 5,
      "name": "Plant_Coral_Block_Blue"
    }
  ],
  "fluids": [
    {
      "x": -5,
      "y": 13,
      "z": -4,
      "name": "Water_Source",
      "level": 1
    },
    {
      "x": -4,
      "y": 15,
      "z": -5,
      "name": "Water_Source",
      "level": 1
    },
    {
      "x": -4,
      "y": 13,
      "z": -1,
      "name": "Water_Source",
      "level": 1
    },
    {
      "x": -3,
      "y": 13,
      "z": -6,
      "name": "Water_Source",
      "level": 1
    },
    {
      "x": -3,
      "y": 15,
      "z": -3,
      "name": "Water_Source",
      "level": 1
    },
    {
      "x": -3,
      "y": 15,
      "z": -1,
      "name": "Water_Source",
      "level": 1
    },
    {
      "x": -3,
      "y": 13,
      "z": 2,
      "name": "Water_Source",
      "level": 1
    },
    {
      "x": -3,
      "y": 12,
      "z": 3,
      "name": "Water_Source",
      "level": 1
    },
    {
      "x": -2,
      "y": 15,
      "z": -5,
      "name": "Water_Source",
      "level": 1
    },
    {
      "x": -2,
      "y": 15,
      "z": -4,
      "name": "Water_Source",
      "level": 1
    },
    {
      "x": -2,
      "y": 7,
      "z": -3,
      "name": "Water_Source",
      "level": 1
    },
    {
      "x": -2,
      "y": 12,
      "z": -3,
      "name": "Water_Source",
      "level": 1
    },
    {
      "x": -2,
      "y": 8,
      "z": -2,
      "name": "Water_Source",
      "level": 1
    },
    {
      "x": -2,
      "y": 9,
      "z": -2,
      "name": "Water_Source",
      "level": 1
    },
    {
      "x": -2,
      "y": 10,
      "z": -2,
      "name": "Water_Source",
      "level": 1
    },
    {
      "x": -2,
      "y": 1,
      "z": -1,
      "name": "Water_Source",
      "level": 1
    },
    {
      "x": -2,
      "y": 2,
      "z": -1,
      "name": "Water_Source",
      "level": 1
    },
    {
      "x": -2,
      "y": 3,
      "z": -1,
      "name": "Water_Source",
      "level": 1
    },
    {
      "x": -2,
      "y": 4,
      "z": -1,
      "name": "Water_Source",
      "level": 1
    },
    {
      "x": -2,
      "y": 5,
      "z": -1,
      "name": "Water_Source",
      "level": 1
    },
    {
      "x": -2,
      "y": 6,
      "z": -1,
      "name": "Water_Source",
      "level": 1
    },
    {
      "x": -2,
      "y": 7,
      "z": -1,
      "name": "Water_Source",
      "level": 1
    },
    {
      "x": -2,
      "y": 8,
      "z": -1,
      "name": "Water_Source",
      "level": 1
    },
    {
      "x": -2,
      "y": 9,
      "z": -1,
      "name": "Water_Source",
      "level": 1
    },
    {
      "x": -2,
      "y": 10,
      "z": -1,
      "name": "Water_Source",
      "level": 1
    },
    {
      "x": -2,
      "y": 11,
      "z": -1,
      "name": "Water_Source",
      "level": 1
    },
    {
      "x": -2,
      "y": 12,
      "z": -1,
      "name": "Water_Source",
      "level": 1
    },
    {
      "x": -2,
      "y": 13,
      "z": -1,
      "name": "Water_Source",
      "level": 1
    },
    {
      "x": -2,
      "y": 1,
      "z": 0,
      "name": "Water_Source",
      "level": 1
    },
    {
      "x": -2,
      "y": 2,
      "z": 0,
      "name": "Water_Source",
      "level": 1
    },
    {
      "x": -2,
      "y": 3,
      "z": 0,
      "name": "Water_Source",
      "level": 1
    },
    {
      "x": -2,
      "y": 4,
      "z": 0,
      "name": "Water_Source",
      "level": 1
    },
    {
      "x": -2,
      "y": 5,
      "z": 0,
      "name": "Water_Source",
      "level": 1
    },
    {
      "x": -2,
      "y": 6,
      "z": 0,
      "name": "Water_Source",
      "level": 1
    },
    {
      "x": -2,
      "y": 7,
      "z": 0,
      "name": "Water_Source",
      "level": 1
    },
    {
      "x": -2,
      "y": 8,
      "z": 0,
      "name": "Water_Source",
      "level": 1
    },
    {
      "x": -2,
      "y": 9,
      "z": 0,
      "name": "Water_Source",
      "level": 1
    },
    {
      "x": -2,
      "y": 10,
      "z": 0,
      "name": "Water_Source",
      "level": 1
    },
    {
      "x": -2,
      "y": 11,
      "z": 0,
      "name": "Water_Source",
      "level": 1
    },
    {
      "x": -2,
      "y": 12,
      "z": 0,
      "name": "Water_Source",
      "level": 1
    },
    {
      "x": -2,
      "y": 13,
      "z": 0,
      "name": "Water_Source",
      "level": 1
    },
    {
      "x": -2,
      "y": 1,
      "z": 1,
      "name": "Water_Source",
      "level": 1
    },
    {
      "x": -2,
      "y": 2,
      "z": 1,
      "name": "Water_Source",
      "level": 1
    },
    {
      "x": -2,
      "y": 3,
      "z": 1,
      "name": "Water_Source",
      "level": 1
    },
    {
      "x": -2,
      "y": 4,
      "z": 1,
      "name": "Water_Source",
      "level": 1
    },
    {
      "x": -2,
      "y": 5,
      "z": 1,
      "name": "Water_Source",
      "level": 1
    },
    {
      "x": -2,
      "y": 6,
      "z": 1,
      "name": "Water_Source",
      "level": 1
    },
    {
      "x": -2,
      "y": 7,
      "z": 1,
      "name": "Water_Source",
      "level": 1
    },
    {
      "x": -2,
      "y": 11,
      "z": 1,
      "name": "Water_Source",
      "level": 1
    },
    {
      "x": -2,
      "y": 12,
      "z": 1,
      "name": "Water_Source",
      "level": 1
    },
    {
      "x": -2,
      "y": 13,
      "z": 1,
      "name": "Water_Source",
      "level": 1
    },
    {
      "x": -2,
      "y": 9,
      "z": 2,
      "name": "Water_Source",
      "level": 1
    },
    {
      "x": -1,
      "y": 8,
      "z": -3,
      "name": "Water_Source",
      "level": 1
    },
    {
      "x": -1,
      "y": 9,
      "z": -3,
      "name": "Water_Source",
      "level": 1
    },
    {
      "x": -1,
      "y": 10,
      "z": -3,
      "name": "Water_Source",
      "level": 1
    },
    {
      "x": -1,
      "y": 15,
      "z": -3,
      "name": "Water_Source",
      "level": 1
    },
    {
      "x": -1,
      "y": 1,
      "z": -2,
      "name": "Water_Source",
      "level": 1
    },
    {
      "x": -1,
      "y": 2,
      "z": -2,
      "name": "Water_Source",
      "level": 1
    },
    {
      "x": -1,
      "y": 3,
      "z": -2,
      "name": "Water_Source",
      "level": 1
    },
    {
      "x": -1,
      "y": 4,
      "z": -2,
      "name": "Water_Source",
      "level": 1
    },
    {
      "x": -1,
      "y": 5,
      "z": -2,
      "name": "Water_Source",
      "level": 1
    },
    {
      "x": -1,
      "y": 6,
      "z": -2,
      "name": "Water_Source",
      "level": 1
    },
    {
      "x": -1,
      "y": 7,
      "z": -2,
      "name": "Water_Source",
      "level": 1
    },
    {
      "x": -1,
      "y": 8,
      "z": -2,
      "name": "Water_Source",
      "level": 1
    },
    {
      "x": -1,
      "y": 9,
      "z": -2,
      "name": "Water_Source",
      "level": 1
    },
    {
      "x": -1,
      "y": 10,
      "z": -2,
      "name": "Water_Source",
      "level": 1
    },
    {
      "x": -1,
      "y": 11,
      "z": -2,
      "name": "Water_Source",
      "level": 1
    },
    {
      "x": -1,
      "y": 12,
      "z": -2,
      "name": "Water_Source",
      "level": 1
    },
    {
      "x": -1,
      "y": 13,
      "z": -2,
      "name": "Water_Source",
      "level": 1
    },
    {
      "x": -1,
      "y": 1,
      "z": -1,
      "name": "Water_Source",
      "level": 1
    },
    {
      "x": -1,
      "y": 2,
      "z": -1,
      "name": "Water_Source",
      "level": 1
    },
    {
      "x": -1,
      "y": 3,
      "z": -1,
      "name": "Water_Source",
      "level": 1
    },
    {
      "x": -1,
      "y": 4,
      "z": -1,
      "name": "Water_Source",
      "level": 1
    },
    {
      "x": -1,
      "y": 5,
      "z": -1,
      "name": "Water_Source",
      "level": 1
    },
    {
      "x": -1,
      "y": 6,
      "z": -1,
      "name": "Water_Source",
      "level": 1
    },
    {
      "x": -1,
      "y": 7,
      "z": -1,
      "name": "Water_Source",
      "level": 1
    },
    {
      "x": -1,
      "y": 8,
      "z": -1,
      "name": "Water_Source",
      "level": 1
    },
    {
      "x": -1,
      "y": 9,
      "z": -1,
      "name": "Water_Source",
      "level": 1
    },
    {
      "x": -1,
      "y": 10,
      "z": -1,
      "name": "Water_Source",
      "level": 1
    },
    {
      "x": -1,
      "y": 11,
      "z": -1,
      "name": "Water_Source",
      "level": 1
    },
    {
      "x": -1,
      "y": 12,
      "z": -1,
      "name": "Water_Source",
      "level": 1
    },
    {
      "x": -1,
      "y": 13,
      "z": -1,
      "name": "Water_Source",
      "level": 1
    },
    {
      "x": -1,
      "y": 14,
      "z": -1,
      "name": "Water_Source",
      "level": 1
    },
    {
      "x": -1,
      "y": 15,
      "z": -1,
      "name": "Water_Source",
      "level": 1
    },
    {
      "x": -1,
      "y": 16,
      "z": -1,
      "name": "Water_Source",
      "level": 1
    },
    {
      "x": -1,
      "y": 1,
      "z": 0,
      "name": "Water_Source",
      "level": 1
    },
    {
      "x": -1,
      "y": 2,
      "z": 0,
      "name": "Water_Source",
      "level": 1
    },
    {
      "x": -1,
      "y": 3,
      "z": 0,
      "name": "Water_Source",
      "level": 1
    },
    {
      "x": -1,
      "y": 4,
      "z": 0,
      "name": "Water_Source",
      "level": 1
    },
    {
      "x": -1,
      "y": 5,
      "z": 0,
      "name": "Water_Source",
      "level": 1
    },
    {
      "x": -1,
      "y": 6,
      "z": 0,
      "name": "Water_Source",
      "level": 1
    },
    {
      "x": -1,
      "y": 7,
      "z": 0,
      "name": "Water_Source",
      "level": 1
    },
    {
      "x": -1,
      "y": 8,
      "z": 0,
      "name": "Water_Source",
      "level": 1
    },
    {
      "x": -1,
      "y": 9,
      "z": 0,
      "name": "Water_Source",
      "level": 1
    },
    {
      "x": -1,
      "y": 10,
      "z": 0,
      "name": "Water_Source",
      "level": 1
    },
    {
      "x": -1,
      "y": 11,
      "z": 0,
      "name": "Water_Source",
      "level": 1
    },
    {
      "x": -1,
      "y": 12,
      "z": 0,
      "name": "Water_Source",
      "level": 1
    },
    {
      "x": -1,
      "y": 13,
      "z": 0,
      "name": "Water_Source",
      "level": 1
    },
    {
      "x": -1,
      "y": 14,
      "z": 0,
      "name": "Water_Source",
      "level": 1
    },
    {
      "x": -1,
      "y": 15,
      "z": 0,
      "name": "Water_Source",
      "level": 1
    },
    {
      "x": -1,
      "y": 16,
      "z": 0,
      "name": "Water_Source",
      "level": 1
    },
    {
      "x": -1,
      "y": 1,
      "z": 1,
      "name": "Water_Source",
      "level": 1
    },
    {
      "x": -1,
      "y": 2,
      "z": 1,
      "name": "Water_Source",
      "level": 1
    },
    {
      "x": -1,
      "y": 3,
      "z": 1,
      "name": "Water_Source",
      "level": 1
    },
    {
      "x": -1,
      "y": 4,
      "z": 1,
      "name": "Water_Source",
      "level": 1
    },
    {
      "x": -1,
      "y": 5,
      "z": 1,
      "name": "Water_Source",
      "level": 1
    },
    {
      "x": -1,
      "y": 6,
      "z": 1,
      "name": "Water_Source",
      "level": 1
    },
    {
      "x": -1,
      "y": 7,
      "z": 1,
      "name": "Water_Source",
      "level": 1
    },
    {
      "x": -1,
      "y": 8,
      "z": 1,
      "name": "Water_Source",
      "level": 1
    },
    {
      "x": -1,
      "y": 9,
      "z": 1,
      "name": "Water_Source",
      "level": 1
    },
    {
      "x": -1,
      "y": 10,
      "z": 1,
      "name": "Water_Source",
      "level": 1
    },
    {
      "x": -1,
      "y": 11,
      "z": 1,
      "name": "Water_Source",
      "level": 1
    },
    {
      "x": -1,
      "y": 12,
      "z": 1,
      "name": "Water_Source",
      "level": 1
    },
    {
      "x": -1,
      "y": 13,
      "z": 1,
      "name": "Water_Source",
      "level": 1
    },
    {
      "x": -1,
      "y": 14,
      "z": 1,
      "name": "Water_Source",
      "level": 1
    },
    {
      "x": -1,
      "y": 15,
      "z": 1,
      "name": "Water_Source",
      "level": 1
    },
    {
      "x": -1,
      "y": 1,
      "z": 2,
      "name": "Water_Source",
      "level": 1
    },
    {
      "x": -1,
      "y": 2,
      "z": 2,
      "name": "Water_Source",
      "level": 1
    },
    {
      "x": -1,
      "y": 3,
      "z": 2,
      "name": "Water_Source",
      "level": 1
    },
    {
      "x": -1,
      "y": 4,
      "z": 2,
      "name": "Water_Source",
      "level": 1
    },
    {
      "x": -1,
      "y": 5,
      "z": 2,
      "name": "Water_Source",
      "level": 1
    },
    {
      "x": -1,
      "y": 6,
      "z": 2,
      "name": "Water_Source",
      "level": 1
    },
    {
      "x": -1,
      "y": 7,
      "z": 2,
      "name": "Water_Source",
      "level": 1
    },
    {
      "x": -1,
      "y": 11,
      "z": 2,
      "name": "Water_Source",
      "level": 1
    },
    {
      "x": -1,
      "y": 12,
      "z": 2,
      "name": "Water_Source",
      "level": 1
    },
    {
      "x": -1,
      "y": 13,
      "z": 2,
      "name": "Water_Source",
      "level": 1
    },
    {
      "x": 0,
      "y": 15,
      "z": -6,
      "name": "Water_Source",
      "level": 1
    },
    {
      "x": 0,
      "y": 13,
      "z": -5,
      "name": "Water_Source",
      "level": 1
    },
    {
      "x": 0,
      "y": 15,
      "z": -4,
      "name": "Water_Source",
      "level": 1
    },
    {
      "x": 0,
      "y": 8,
      "z": -3,
      "name": "Water_Source",
      "level": 1
    },
    {
      "x": 0,
      "y": 9,
      "z": -3,
      "name": "Water_Source",
      "level": 1
    },
    {
      "x": 0,
      "y": 10,
      "z": -3,
      "name": "Water_Source",
      "level": 1
    },
    {
      "x": 0,
      "y": 1,
      "z": -2,
      "name": "Water_Source",
      "level": 1
    },
    {
      "x": 0,
      "y": 2,
      "z": -2,
      "name": "Water_Source",
      "level": 1
    },
    {
      "x": 0,
      "y": 3,
      "z": -2,
      "name": "Water_Source",
      "level": 1
    },
    {
      "x": 0,
      "y": 4,
      "z": -2,
      "name": "Water_Source",
      "level": 1
    },
    {
      "x": 0,
      "y": 5,
      "z": -2,
      "name": "Water_Source",
      "level": 1
    },
    {
      "x": 0,
      "y": 6,
      "z": -2,
      "name": "Water_Source",
      "level": 1
    },
    {
      "x": 0,
      "y": 7,
      "z": -2,
      "name": "Water_Source",
      "level": 1
    },
    {
      "x": 0,
      "y": 8,
      "z": -2,
      "name": "Water_Source",
      "level": 1
    },
    {
      "x": 0,
      "y": 9,
      "z": -2,
      "name": "Water_Source",
      "level": 1
    },
    {
      "x": 0,
      "y": 10,
      "z": -2,
      "name": "Water_Source",
      "level": 1
    },
    {
      "x": 0,
      "y": 11,
      "z": -2,
      "name": "Water_Source",
      "level": 1
    },
    {
      "x": 0,
      "y": 12,
      "z": -2,
      "name": "Water_Source",
      "level": 1
    },
    {
      "x": 0,
      "y": 13,
      "z": -2,
      "name": "Water_Source",
      "level": 1
    },
    {
      "x": 0,
      "y": 14,
      "z": -2,
      "name": "Water_Source",
      "level": 1
    },
    {
      "x": 0,
      "y": 15,
      "z": -2,
      "name": "Water_Source",
      "level": 1
    },
    {
      "x": 0,
      "y": 16,
      "z": -2,
      "name": "Water_Source",
      "level": 1
    },
    {
      "x": 0,
      "y": 1,
      "z": -1,
      "name": "Water_Source",
      "level": 1
    },
    {
      "x": 0,
      "y": 2,
      "z": -1,
      "name": "Water_Source",
      "level": 1
    },
    {
      "x": 0,
      "y": 3,
      "z": -1,
      "name": "Water_Source",
      "level": 1
    },
    {
      "x": 0,
      "y": 4,
      "z": -1,
      "name": "Water_Source",
      "level": 1
    },
    {
      "x": 0,
      "y": 5,
      "z": -1,
      "name": "Water_Source",
      "level": 1
    },
    {
      "x": 0,
      "y": 6,
      "z": -1,
      "name": "Water_Source",
      "level": 1
    },
    {
      "x": 0,
      "y": 7,
      "z": -1,
      "name": "Water_Source",
      "level": 1
    },
    {
      "x": 0,
      "y": 8,
      "z": -1,
      "name": "Water_Source",
      "level": 1
    },
    {
      "x": 0,
      "y": 9,
      "z": -1,
      "name": "Water_Source",
      "level": 1
    },
    {
      "x": 0,
      "y": 10,
      "z": -1,
      "name": "Water_Source",
      "level": 1
    },
    {
      "x": 0,
      "y": 11,
      "z": -1,
      "name": "Water_Source",
      "level": 1
    },
    {
      "x": 0,
      "y": 12,
      "z": -1,
      "name": "Water_Source",
      "level": 1
    },
    {
      "x": 0,
      "y": 13,
      "z": -1,
      "name": "Water_Source",
      "level": 1
    },
    {
      "x": 0,
      "y": 14,
      "z": -1,
      "name": "Water_Source",
      "level": 1
    },
    {
      "x": 0,
      "y": 15,
      "z": -1,
      "name": "Water_Source",
      "level": 1
    },
    {
      "x": 0,
      "y": 16,
      "z": -1,
      "name": "Water_Source",
      "level": 1
    },
    {
      "x": 0,
      "y": 1,
      "z": 0,
      "name": "Water_Source",
      "level": 1
    },
    {
      "x": 0,
      "y": 2,
      "z": 0,
      "name": "Water_Source",
      "level": 1
    },
    {
      "x": 0,
      "y": 3,
      "z": 0,
      "name": "Water_Source",
      "level": 1
    },
    {
      "x": 0,
      "y": 4,
      "z": 0,
      "name": "Water_Source",
      "level": 1
    },
    {
      "x": 0,
      "y": 5,
      "z": 0,
      "name": "Water_Source",
      "level": 1
    },
    {
      "x": 0,
      "y": 6,
      "z": 0,
      "name": "Water_Source",
      "level": 1
    },
    {
      "x": 0,
      "y": 7,
      "z": 0,
      "name": "Water_Source",
      "level": 1
    },
    {
      "x": 0,
      "y": 8,
      "z": 0,
      "name": "Water_Source",
      "level": 1
    },
    {
      "x": 0,
      "y": 9,
      "z": 0,
      "name": "Water_Source",
      "level": 1
    },
    {
      "x": 0,
      "y": 10,
      "z": 0,
      "name": "Water_Source",
      "level": 1
    },
    {
      "x": 0,
      "y": 11,
      "z": 0,
      "name": "Water_Source",
      "level": 1
    },
    {
      "x": 0,
      "y": 12,
      "z": 0,
      "name": "Water_Source",
      "level": 1
    },
    {
      "x": 0,
      "y": 13,
      "z": 0,
      "name": "Water_Source",
      "level": 1
    },
    {
      "x": 0,
      "y": 14,
      "z": 0,
      "name": "Water_Source",
      "level": 1
    },
    {
      "x": 0,
      "y": 15,
      "z": 0,
      "name": "Water_Source",
      "level": 1
    },
    {
      "x": 0,
      "y": 1,
      "z": 1,
      "name": "Water_Source",
      "level": 1
    },
    {
      "x": 0,
      "y": 2,
      "z": 1,
      "name": "Water_Source",
      "level": 1
    },
    {
      "x": 0,
      "y": 3,
      "z": 1,
      "name": "Water_Source",
      "level": 1
    },
    {
      "x": 0,
      "y": 4,
      "z": 1,
      "name": "Water_Source",
      "level": 1
    },
    {
      "x": 0,
      "y": 5,
      "z": 1,
      "name": "Water_Source",
      "level": 1
    },
    {
      "x": 0,
      "y": 6,
      "z": 1,
      "name": "Water_Source",
      "level": 1
    },
    {
      "x": 0,
      "y": 7,
      "z": 1,
      "name": "Water_Source",
      "level": 1
    },
    {
      "x": 0,
      "y": 8,
      "z": 1,
      "name": "Water_Source",
      "level": 1
    },
    {
      "x": 0,
      "y": 9,
      "z": 1,
      "name": "Water_Source",
      "level": 1
    },
    {
      "x": 0,
      "y": 10,
      "z": 1,
      "name": "Water_Source",
      "level": 1
    },
    {
      "x": 0,
      "y": 11,
      "z": 1,
      "name": "Water_Source",
      "level": 1
    },
    {
      "x": 0,
      "y": 12,
      "z": 1,
      "name": "Water_Source",
      "level": 1
    },
    {
      "x": 0,
      "y": 13,
      "z": 1,
      "name": "Water_Source",
      "level": 1
    },
    {
      "x": 0,
      "y": 14,
      "z": 1,
      "name": "Water_Source",
      "level": 1
    },
    {
      "x": 0,
      "y": 15,
      "z": 1,
      "name": "Water_Source",
      "level": 1
    },
    {
      "x": 0,
      "y": 1,
      "z": 2,
      "name": "Water_Source",
      "level": 1
    },
    {
      "x": 0,
      "y": 2,
      "z": 2,
      "name": "Water_Source",
      "level": 1
    },
    {
      "x": 0,
      "y": 3,
      "z": 2,
      "name": "Water_Source",
      "level": 1
    },
    {
      "x": 0,
      "y": 4,
      "z": 2,
      "name": "Water_Source",
      "level": 1
    },
    {
      "x": 0,
      "y": 5,
      "z": 2,
      "name": "Water_Source",
      "level": 1
    },
    {
      "x": 0,
      "y": 6,
      "z": 2,
      "name": "Water_Source",
      "level": 1
    },
    {
      "x": 0,
      "y": 7,
      "z": 2,
      "name": "Water_Source",
      "level": 1
    },
    {
      "x": 0,
      "y": 11,
      "z": 2,
      "name": "Water_Source",
      "level": 1
    },
    {
      "x": 0,
      "y": 12,
      "z": 2,
      "name": "Water_Source",
      "level": 1
    },
    {
      "x": 0,
      "y": 13,
      "z": 2,
      "name": "Water_Source",
      "level": 1
    },
    {
      "x": 0,
      "y": 14,
      "z": 2,
      "name": "Water_Source",
      "level": 1
    },
    {
      "x": 0,
      "y": 15,
      "z": 2,
      "name": "Water_Source",
      "level": 1
    },
    {
      "x": 0,
      "y": 10,
      "z": 4,
      "name": "Water_Source",
      "level": 1
    },
    {
      "x": 1,
      "y": 15,
      "z": -5,
      "name": "Water_Source",
      "level": 1
    },
    {
      "x": 1,
      "y": 12,
      "z": -4,
      "name": "Water_Source",
      "level": 1
    },
    {
      "x": 1,
      "y": 8,
      "z": -3,
      "name": "Water_Source",
      "level": 1
    },
    {
      "x": 1,
      "y": 9,
      "z": -3,
      "name": "Water_Source",
      "level": 1
    },
    {
      "x": 1,
      "y": 10,
      "z": -3,
      "name": "Water_Source",
      "level": 1
    },
    {
      "x": 1,
      "y": 1,
      "z": -2,
      "name": "Water_Source",
      "level": 1
    },
    {
      "x": 1,
      "y": 2,
      "z": -2,
      "name": "Water_Source",
      "level": 1
    },
    {
      "x": 1,
      "y": 3,
      "z": -2,
      "name": "Water_Source",
      "level": 1
    },
    {
      "x": 1,
      "y": 4,
      "z": -2,
      "name": "Water_Source",
      "level": 1
    },
    {
      "x": 1,
      "y": 5,
      "z": -2,
      "name": "Water_Source",
      "level": 1
    },
    {
      "x": 1,
      "y": 6,
      "z": -2,
      "name": "Water_Source",
      "level": 1
    },
    {
      "x": 1,
      "y": 7,
      "z": -2,
      "name": "Water_Source",
      "level": 1
    },
    {
      "x": 1,
      "y": 8,
      "z": -2,
      "name": "Water_Source",
      "level": 1
    },
    {
      "x": 1,
      "y": 9,
      "z": -2,
      "name": "Water_Source",
      "level": 1
    },
    {
      "x": 1,
      "y": 10,
      "z": -2,
      "name": "Water_Source",
      "level": 1
    },
    {
      "x": 1,
      "y": 11,
      "z": -2,
      "name": "Water_Source",
      "level": 1
    },
    {
      "x": 1,
      "y": 12,
      "z": -2,
      "name": "Water_Source",
      "level": 1
    },
    {
      "x": 1,
      "y": 13,
      "z": -2,
      "name": "Water_Source",
      "level": 1
    },
    {
      "x": 1,
      "y": 14,
      "z": -2,
      "name": "Water_Source",
      "level": 1
    },
    {
      "x": 1,
      "y": 15,
      "z": -2,
      "name": "Water_Source",
      "level": 1
    },
    {
      "x": 1,
      "y": 16,
      "z": -2,
      "name": "Water_Source",
      "level": 1
    },
    {
      "x": 1,
      "y": 1,
      "z": -1,
      "name": "Water_Source",
      "level": 1
    },
    {
      "x": 1,
      "y": 2,
      "z": -1,
      "name": "Water_Source",
      "level": 1
    },
    {
      "x": 1,
      "y": 3,
      "z": -1,
      "name": "Water_Source",
      "level": 1
    },
    {
      "x": 1,
      "y": 4,
      "z": -1,
      "name": "Water_Source",
      "level": 1
    },
    {
      "x": 1,
      "y": 5,
      "z": -1,
      "name": "Water_Source",
      "level": 1
    },
    {
      "x": 1,
      "y": 6,
      "z": -1,
      "name": "Water_Source",
      "level": 1
    },
    {
      "x": 1,
      "y": 7,
      "z": -1,
      "name": "Water_Source",
      "level": 1
    },
    {
      "x": 1,
      "y": 8,
      "z": -1,
      "name": "Water_Source",
      "level": 1
    },
    {
      "x": 1,
      "y": 9,
      "z": -1,
      "name": "Water_Source",
      "level": 1
    },
    {
      "x": 1,
      "y": 10,
      "z": -1,
      "name": "Water_Source",
      "level": 1
    },
    {
      "x": 1,
      "y": 11,
      "z": -1,
      "name": "Water_Source",
      "level": 1
    },
    {
      "x": 1,
      "y": 12,
      "z": -1,
      "name": "Water_Source",
      "level": 1
    },
    {
      "x": 1,
      "y": 13,
      "z": -1,
      "name": "Water_Source",
      "level": 1
    },
    {
      "x": 1,
      "y": 14,
      "z": -1,
      "name": "Water_Source",
      "level": 1
    },
    {
      "x": 1,
      "y": 15,
      "z": -1,
      "name": "Water_Source",
      "level": 1
    },
    {
      "x": 1,
      "y": 16,
      "z": -1,
      "name": "Water_Source",
      "level": 1
    },
    {
      "x": 1,
      "y": 1,
      "z": 0,
      "name": "Water_Source",
      "level": 1
    },
    {
      "x": 1,
      "y": 2,
      "z": 0,
      "name": "Water_Source",
      "level": 1
    },
    {
      "x": 1,
      "y": 3,
      "z": 0,
      "name": "Water_Source",
      "level": 1
    },
    {
      "x": 1,
      "y": 4,
      "z": 0,
      "name": "Water_Source",
      "level": 1
    },
    {
      "x": 1,
      "y": 5,
      "z": 0,
      "name": "Water_Source",
      "level": 1
    },
    {
      "x": 1,
      "y": 6,
      "z": 0,
      "name": "Water_Source",
      "level": 1
    },
    {
      "x": 1,
      "y": 7,
      "z": 0,
      "name": "Water_Source",
      "level": 1
    },
    {
      "x": 1,
      "y": 8,
      "z": 0,
      "name": "Water_Source",
      "level": 1
    },
    {
      "x": 1,
      "y": 9,
      "z": 0,
      "name": "Water_Source",
      "level": 1
    },
    {
      "x": 1,
      "y": 10,
      "z": 0,
      "name": "Water_Source",
      "level": 1
    },
    {
      "x": 1,
      "y": 11,
      "z": 0,
      "name": "Water_Source",
      "level": 1
    },
    {
      "x": 1,
      "y": 12,
      "z": 0,
      "name": "Water_Source",
      "level": 1
    },
    {
      "x": 1,
      "y": 13,
      "z": 0,
      "name": "Water_Source",
      "level": 1
    },
    {
      "x": 1,
      "y": 14,
      "z": 0,
      "name": "Water_Source",
      "level": 1
    },
    {
      "x": 1,
      "y": 15,
      "z": 0,
      "name": "Water_Source",
      "level": 1
    },
    {
      "x": 1,
      "y": 1,
      "z": 1,
      "name": "Water_Source",
      "level": 1
    },
    {
      "x": 1,
      "y": 2,
      "z": 1,
      "name": "Water_Source",
      "level": 1
    },
    {
      "x": 1,
      "y": 3,
      "z": 1,
      "name": "Water_Source",
      "level": 1
    },
    {
      "x": 1,
      "y": 4,
      "z": 1,
      "name": "Water_Source",
      "level": 1
    },
    {
      "x": 1,
      "y": 5,
      "z": 1,
      "name": "Water_Source",
      "level": 1
    },
    {
      "x": 1,
      "y": 6,
      "z": 1,
      "name": "Water_Source",
      "level": 1
    },
    {
      "x": 1,
      "y": 7,
      "z": 1,
      "name": "Water_Source",
      "level": 1
    },
    {
      "x": 1,
      "y": 8,
      "z": 1,
      "name": "Water_Source",
      "level": 1
    },
    {
      "x": 1,
      "y": 9,
      "z": 1,
      "name": "Water_Source",
      "level": 1
    },
    {
      "x": 1,
      "y": 10,
      "z": 1,
      "name": "Water_Source",
      "level": 1
    },
    {
      "x": 1,
      "y": 11,
      "z": 1,
      "name": "Water_Source",
      "level": 1
    },
    {
      "x": 1,
      "y": 12,
      "z": 1,
      "name": "Water_Source",
      "level": 1
    },
    {
      "x": 1,
      "y": 13,
      "z": 1,
      "name": "Water_Source",
      "level": 1
    },
    {
      "x": 1,
      "y": 14,
      "z": 1,
      "name": "Water_Source",
      "level": 1
    },
    {
      "x": 1,
      "y": 15,
      "z": 1,
      "name": "Water_Source",
      "level": 1
    },
    {
      "x": 1,
      "y": 1,
      "z": 2,
      "name": "Water_Source",
      "level": 1
    },
    {
      "x": 1,
      "y": 2,
      "z": 2,
      "name": "Water_Source",
      "level": 1
    },
    {
      "x": 1,
      "y": 3,
      "z": 2,
      "name": "Water_Source",
      "level": 1
    },
    {
      "x": 1,
      "y": 4,
      "z": 2,
      "name": "Water_Source",
      "level": 1
    },
    {
      "x": 1,
      "y": 5,
      "z": 2,
      "name": "Water_Source",
      "level": 1
    },
    {
      "x": 1,
      "y": 6,
      "z": 2,
      "name": "Water_Source",
      "level": 1
    },
    {
      "x": 1,
      "y": 7,
      "z": 2,
      "name": "Water_Source",
      "level": 1
    },
    {
      "x": 1,
      "y": 11,
      "z": 2,
      "name": "Water_Source",
      "level": 1
    },
    {
      "x": 1,
      "y": 12,
      "z": 2,
      "name": "Water_Source",
      "level": 1
    },
    {
      "x": 1,
      "y": 13,
      "z": 2,
      "name": "Water_Source",
      "level": 1
    },
    {
      "x": 1,
      "y": 14,
      "z": 2,
      "name": "Water_Source",
      "level": 1
    },
    {
      "x": 1,
      "y": 15,
      "z": 2,
      "name": "Water_Source",
      "level": 1
    },
    {
      "x": 1,
      "y": 12,
      "z": 4,
      "name": "Water_Source",
      "level": 1
    },
    {
      "x": 2,
      "y": 8,
      "z": -2,
      "name": "Water_Source",
      "level": 1
    },
    {
      "x": 2,
      "y": 9,
      "z": -2,
      "name": "Water_Source",
      "level": 1
    },
    {
      "x": 2,
      "y": 10,
      "z": -2,
      "name": "Water_Source",
      "level": 1
    },
    {
      "x": 2,
      "y": 14,
      "z": -2,
      "name": "Water_Source",
      "level": 1
    },
    {
      "x": 2,
      "y": 15,
      "z": -2,
      "name": "Water_Source",
      "level": 1
    },
    {
      "x": 2,
      "y": 16,
      "z": -2,
      "name": "Water_Source",
      "level": 1
    },
    {
      "x": 2,
      "y": 1,
      "z": -1,
      "name": "Water_Source",
      "level": 1
    },
    {
      "x": 2,
      "y": 2,
      "z": -1,
      "name": "Water_Source",
      "level": 1
    },
    {
      "x": 2,
      "y": 3,
      "z": -1,
      "name": "Water_Source",
      "level": 1
    },
    {
      "x": 2,
      "y": 4,
      "z": -1,
      "name": "Water_Source",
      "level": 1
    },
    {
      "x": 2,
      "y": 5,
      "z": -1,
      "name": "Water_Source",
      "level": 1
    },
    {
      "x": 2,
      "y": 6,
      "z": -1,
      "name": "Water_Source",
      "level": 1
    },
    {
      "x": 2,
      "y": 7,
      "z": -1,
      "name": "Water_Source",
      "level": 1
    },
    {
      "x": 2,
      "y": 8,
      "z": -1,
      "name": "Water_Source",
      "level": 1
    },
    {
      "x": 2,
      "y": 9,
      "z": -1,
      "name": "Water_Source",
      "level": 1
    },
    {
      "x": 2,
      "y": 10,
      "z": -1,
      "name": "Water_Source",
      "level": 1
    },
    {
      "x": 2,
      "y": 11,
      "z": -1,
      "name": "Water_Source",
      "level": 1
    },
    {
      "x": 2,
      "y": 12,
      "z": -1,
      "name": "Water_Source",
      "level": 1
    },
    {
      "x": 2,
      "y": 13,
      "z": -1,
      "name": "Water_Source",
      "level": 1
    },
    {
      "x": 2,
      "y": 14,
      "z": -1,
      "name": "Water_Source",
      "level": 1
    },
    {
      "x": 2,
      "y": 15,
      "z": -1,
      "name": "Water_Source",
      "level": 1
    },
    {
      "x": 2,
      "y": 1,
      "z": 0,
      "name": "Water_Source",
      "level": 1
    },
    {
      "x": 2,
      "y": 2,
      "z": 0,
      "name": "Water_Source",
      "level": 1
    },
    {
      "x": 2,
      "y": 3,
      "z": 0,
      "name": "Water_Source",
      "level": 1
    },
    {
      "x": 2,
      "y": 4,
      "z": 0,
      "name": "Water_Source",
      "level": 1
    },
    {
      "x": 2,
      "y": 5,
      "z": 0,
      "name": "Water_Source",
      "level": 1
    },
    {
      "x": 2,
      "y": 6,
      "z": 0,
      "name": "Water_Source",
      "level": 1
    },
    {
      "x": 2,
      "y": 7,
      "z": 0,
      "name": "Water_Source",
      "level": 1
    },
    {
      "x": 2,
      "y": 8,
      "z": 0,
      "name": "Water_Source",
      "level": 1
    },
    {
      "x": 2,
      "y": 9,
      "z": 0,
      "name": "Water_Source",
      "level": 1
    },
    {
      "x": 2,
      "y": 10,
      "z": 0,
      "name": "Water_Source",
      "level": 1
    },
    {
      "x": 2,
      "y": 11,
      "z": 0,
      "name": "Water_Source",
      "level": 1
    },
    {
      "x": 2,
      "y": 12,
      "z": 0,
      "name": "Water_Source",
      "level": 1
    },
    {
      "x": 2,
      "y": 13,
      "z": 0,
      "name": "Water_Source",
      "level": 1
    },
    {
      "x": 2,
      "y": 14,
      "z": 0,
      "name": "Water_Source",
      "level": 1
    },
    {
      "x": 2,
      "y": 15,
      "z": 0,
      "name": "Water_Source",
      "level": 1
    },
    {
      "x": 2,
      "y": 1,
      "z": 1,
      "name": "Water_Source",
      "level": 1
    },
    {
      "x": 2,
      "y": 2,
      "z": 1,
      "name": "Water_Source",
      "level": 1
    },
    {
      "x": 2,
      "y": 3,
      "z": 1,
      "name": "Water_Source",
      "level": 1
    },
    {
      "x": 2,
      "y": 4,
      "z": 1,
      "name": "Water_Source",
      "level": 1
    },
    {
      "x": 2,
      "y": 5,
      "z": 1,
      "name": "Water_Source",
      "level": 1
    },
    {
      "x": 2,
      "y": 6,
      "z": 1,
      "name": "Water_Source",
      "level": 1
    },
    {
      "x": 2,
      "y": 7,
      "z": 1,
      "name": "Water_Source",
      "level": 1
    },
    {
      "x": 2,
      "y": 11,
      "z": 1,
      "name": "Water_Source",
      "level": 1
    },
    {
      "x": 2,
      "y": 12,
      "z": 1,
      "name": "Water_Source",
      "level": 1
    },
    {
      "x": 2,
      "y": 13,
      "z": 1,
      "name": "Water_Source",
      "level": 1
    },
    {
      "x": 2,
      "y": 14,
      "z": 1,
      "name": "Water_Source",
      "level": 1
    },
    {
      "x": 2,
      "y": 15,
      "z": 1,
      "name": "Water_Source",
      "level": 1
    },
    {
      "x": 2,
      "y": 14,
      "z": 2,
      "name": "Water_Source",
      "level": 1
    },
    {
      "x": 2,
      "y": 15,
      "z": 2,
      "name": "Water_Source",
      "level": 1
    },
    {
      "x": 2,
      "y": 12,
      "z": 3,
      "name": "Water_Source",
      "level": 1
    },
    {
      "x": 2,
      "y": 12,
      "z": 5,
      "name": "Water_Source",
      "level": 1
    },
    {
      "x": 3,
      "y": 13,
      "z": -3,
      "name": "Water_Source",
      "level": 1
    },
    {
      "x": 3,
      "y": 14,
      "z": -1,
      "name": "Water_Source",
      "level": 1
    },
    {
      "x": 3,
      "y": 15,
      "z": -1,
      "name": "Water_Source",
      "level": 1
    },
    {
      "x": 3,
      "y": 14,
      "z": 0,
      "name": "Water_Source",
      "level": 1
    },
    {
      "x": 3,
      "y": 15,
      "z": 0,
      "name": "Water_Source",
      "level": 1
    },
    {
      "x": 3,
      "y": 14,
      "z": 1,
      "name": "Water_Source",
      "level": 1
    },
    {
      "x": 3,
      "y": 15,
      "z": 1,
      "name": "Water_Source",
      "level": 1
    },
    {
      "x": 3,
      "y": 10,
      "z": 3,
      "name": "Water_Source",
      "level": 1
    },
    {
      "x": 3,
      "y": 12,
      "z": 3,
      "name": "Water_Source",
      "level": 1
    },
    {
      "x": 3,
      "y": 12,
      "z": 4,
      "name": "Water_Source",
      "level": 1
    },
    {
      "x": 3,
      "y": 10,
      "z": 6,
      "name": "Water_Source",
      "level": 1
    },
    {
      "x": 4,
      "y": 10,
      "z": -2,
      "name": "Water_Source",
      "level": 1
    },
    {
      "x": 4,
      "y": 12,
      "z": 0,
      "name": "Water_Source",
      "level": 1
    },
    {
      "x": 4,
      "y": 12,
      "z": 2,
      "name": "Water_Source",
      "level": 1
    },
    {
      "x": 4,
      "y": 12,
      "z": 3,
      "name": "Water_Source",
      "level": 1
    },
    {
      "x": 4,
      "y": 12,
      "z": 4,
      "name": "Water_Source",
      "level": 1
    },
    {
      "x": 5,
      "y": 12,
      "z": 2,
      "name": "Water_Source",
      "level": 1
    },
    {
      "x": 6,
      "y": 10,
      "z": 1,
      "name": "Water_Source",
      "level": 1
    },
    {
      "x": 6,
      "y": 10,
      "z": 4,
      "name": "Water_Source",
      "level": 1
    }
  ]
}