{
  "version": 8,
  "blockIdVersion": 11,
  "anchorX": 0,
  "anchorY": 16,
  "anchorZ": 3,
  "blocks": [
    {
      "x": -5,
      "y": 20,
      "z": -5,
      "name": "*Rock_Aqua_Cobble_Roof_Shallow_State_Definitions_Corner_Left",
      "rotation": 2
    },
    {
      "x": -5,
      "y": 20,
      "z": -4,
      "name": "*Rock_Aqua_Cobble_Roof_Shallow_State_Definitions_Corner_Left",
      "filler": 32,
      "rotation": 2
    },
    {
      "x": -5,
      "y": 20,
      "z": -3,
      "name": "Rock_Aqua_Cobble_Roof_Shallow",
      "rotation": 3
    },
    {
      "x": -5,
      "y": 20,
      "z": -2,
      "name": "Rock_Aqua_Cobble_Roof_Shallow",
      "rotation": 3
    },
    {
      "x": -5,
      "y": 20,
      "z": -1,
      "name": "Rock_Aqua_Cobble_Roof_Shallow",
      "rotation": 3
    },
    {
      "x": -5,
      "y": 20,
      "z": 0,
      "name": "Rock_Aqua_Cobble_Roof_Shallow",
      "rotation": 3
    },
    {
      "x": -5,
      "y": 20,
      "z": 1,
      "name": "Rock_Aqua_Cobble_Roof_Shallow",
      "rotation": 3
    },
    {
      "x": -5,
      "y": 20,
      "z": 2,
      "name": "Rock_Aqua_Cobble_Roof_Shallow",
      "rotation": 3
    },
    {
      "x": -5,
      "y": 20,
      "z": 3,
      "name": "Rock_Aqua_Cobble_Roof_Shallow",
      "rotation": 3
    },
    {
      "x": -5,
      "y": 20,
      "z": 4,
      "name": "*Rock_Aqua_Cobble_Roof_Shallow_State_Definitions_Corner_Left",
      "filler": 992,
      "rotation": 3
    },
    {
      "x": -5,
      "y": 20,
      "z": 5,
      "name": "*Rock_Aqua_Cobble_Roof_Shallow_State_Definitions_Corner_Left",
      "rotation": 3
    },
    {
      "x": -4,
      "y": 20,
      "z": -5,
      "name": "*Rock_Aqua_Cobble_Roof_Shallow_State_Definitions_Corner_Left",
      "filler": 1,
      "rotation": 2
    },
    {
      "x": -4,
      "y": 20,
      "z": -4,
      "name": "*Rock_Aqua_Cobble_Roof_Shallow_State_Definitions_Corner_Left",
      "filler": 33,
      "rotation": 2
    },
    {
      "x": -4,
      "y": -9,
      "z": -3,
      "name": "Rock_Aqua_Brick_Smooth"
    },
    {
      "x": -4,
      "y": -8,
      "z": -3,
      "name": "Rock_Aqua_Brick_Smooth"
    },
    {
      "x": -4,
      "y": -7,
      "z": -3,
      "name": "Rock_Aqua_Brick_Decorative"
    },
    {
      "x": -4,
      "y": -6,
      "z": -3,
      "name": "Rock_Aqua_Brick_Smooth"
    },
    {
      "x": -4,
      "y": -5,
      "z": -3,
      "name": "Rock_Aqua_Brick_Smooth"
    },
    {
      "x": -4,
      "y": -4,
      "z": -3,
      "name": "Rock_Aqua_Brick_Decorative"
    },
    {
      "x": -4,
      "y": -3,
      "z": -3,
      "name": "Rock_Aqua_Brick_Smooth"
    },
    {
      "x": -4,
      "y": -2,
      "z": -3,
      "name": "Rock_Aqua_Brick_Smooth"
    },
    {
      "x": -4,
      "y": -1,
      "z": -3,
      "name": "Rock_Aqua_Brick_Decorative"
    },
    {
      "x": -4,
      "y": 0,
      "z": -3,
      "name": "Rock_Aqua_Brick_Smooth"
    },
    {
      "x": -4,
      "y": 1,
      "z": -3,
      "name": "Rock_Aqua_Brick_Smooth"
    },
    {
      "x": -4,
      "y": 2,
      "z": -3,
      "name": "Rock_Aqua_Brick_Decorative"
    },
    {
      "x": -4,
      "y": 3,
      "z": -3,
      "name": "Rock_Aqua_Brick_Smooth"
    },
    {
      "x": -4,
      "y": 4,
      "z": -3,
      "name": "Rock_Aqua_Brick_Smooth"
    },
    {
      "x": -4,
      "y": 5,
      "z": -3,
      "name": "Rock_Aqua_Brick_Decorative"
    },
    {
      "x": -4,
      "y": 6,
      "z": -3,
      "name": "Rock_Aqua_Brick_Smooth"
    },
    {
      "x": -4,
      "y": 7,
      "z": -3,
      "name": "Rock_Aqua_Brick_Smooth"
    },
    {
      "x": -4,
      "y": 8,
      "z": -3,
      "name": "Rock_Aqua_Brick_Stairs",
      "rotation": 3
    },
    {
      "x": -4,
      "y": 20,
      "z": -3,
      "name": "Rock_Aqua_Cobble_Roof_Shallow",
      "filler": 1,
      "rotation": 3
    },
    {
      "x": -4,
      "y": 20,
      "z": -2,
      "name": "Rock_Aqua_Cobble_Roof_Shallow",
      "filler": 1,
      "rotation": 3
    },
    {
      "x": -4,
      "y": -9,
      "z": -1,
      "name": "Rock_Aqua_Brick_Smooth"
    },
    {
      "x": -4,
      "y": -8,
      "z": -1,
      "name": "Rock_Aqua_Brick_Smooth"
    },
    {
      "x": -4,
      "y": -7,
      "z": -1,
      "name": "Rock_Aqua_Brick_Decorative"
    },
    {
      "x": -4,
      "y": -6,
      "z": -1,
      "name": "Rock_Aqua_Brick_Smooth"
    },
    {
      "x": -4,
      "y": -5,
      "z": -1,
      "name": "Rock_Aqua_Brick_Smooth"
    },
    {
      "x": -4,
      "y": -4,
      "z": -1,
      "name": "Rock_Aqua_Brick_Decorative"
    },
    {
      "x": -4,
      "y": -3,
      "z": -1,
      "name": "Rock_Aqua_Brick_Smooth"
    },
    {
      "x": -4,
      "y": -2,
      "z": -1,
      "name": "Rock_Aqua_Brick_Smooth"
    },
    {
      "x": -4,
      "y": -1,
      "z": -1,
      "name": "Rock_Aqua_Brick_Decorative"
    },
    {
      "x": -4,
      "y": 0,
      "z": -1,
      "name": "Rock_Aqua_Brick_Smooth"
    },
    {
      "x": -4,
      "y": 1,
      "z": -1,
      "name": "Rock_Aqua_Brick_Smooth"
    },
    {
      "x": -4,
      "y": 2,
      "z": -1,
      "name": "Rock_Aqua_Brick_Decorative"
    },
    {
      "x": -4,
      "y": 3,
      "z": -1,
      "name": "Rock_Aqua_Brick_Smooth"
    },
    {
      "x": -4,
      "y": 4,
      "z": -1,
      "name": "Rock_Aqua_Brick_Smooth"
    },
    {
      "x": -4,
      "y": 5,
      "z": -1,
      "name": "Rock_Aqua_Brick_Decorative"
    },
    {
      "x": -4,
      "y": 6,
      "z": -1,
      "name": "Rock_Aqua_Brick_Smooth"
    },
    {
      "x": -4,
      "y": 7,
      "z": -1,
      "name": "Rock_Aqua_Brick_Smooth"
    },
    {
      "x": -4,
      "y": 8,
      "z": -1,
      "name": "Rock_Aqua_Brick_Stairs",
      "rotation": 3
    },
    {
      "x": -4,
      "y": 20,
      "z": -1,
      "name": "Rock_Aqua_Cobble_Roof_Shallow",
      "filler": 1,
      "rotation": 3
    },
    {
      "x": -4,
      "y": 20,
      "z": 0,
      "name": "Rock_Aqua_Cobble_Roof_Shallow",
      "filler": 1,
      "rotation": 3
    },
    {
      "x": -4,
      "y": -9,
      "z": 1,
      "name": "Rock_Aqua_Brick_Smooth"
    },
    {
      "x": -4,
      "y": -8,
      "z": 1,
      "name": "Rock_Aqua_Brick_Smooth"
    },
    {
      "x": -4,
      "y": -7,
      "z": 1,
      "name": "Rock_Aqua_Brick_Decorative"
    },
    {
      "x": -4,
      "y": -6,
      "z": 1,
      "name": "Rock_Aqua_Brick_Smooth"
    },
    {
      "x": -4,
      "y": -5,
      "z": 1,
      "name": "Rock_Aqua_Brick_Smooth"
    },
    {
      "x": -4,
      "y": -4,
      "z": 1,
      "name": "Rock_Aqua_Brick_Decorative"
    },
    {
      "x": -4,
      "y": -3,
      "z": 1,
      "name": "Rock_Aqua_Brick_Smooth"
    },
    {
      "x": -4,
      "y": -2,
      "z": 1,
      "name": "Rock_Aqua_Brick_Smooth"
    },
    {
      "x": -4,
      "y": -1,
      "z": 1,
      "name": "Rock_Aqua_Brick_Decorative"
    },
    {
      "x": -4,
      "y": 0,
      "z": 1,
      "name": "Rock_Aqua_Brick_Smooth"
    },
    {
      "x": -4,
      "y": 1,
      "z": 1,
      "name": "Rock_Aqua_Brick_Smooth"
    },
    {
      "x": -4,
      "y": 2,
      "z": 1,
      "name": "Rock_Aqua_Brick_Decorative"
    },
    {
      "x": -4,
      "y": 3,
      "z": 1,
      "name": "Rock_Aqua_Brick_Smooth"
    },
    {
      "x": -4,
      "y": 4,
      "z": 1,
      "name": "Rock_Aqua_Brick_Smooth"
    },
    {
      "x": -4,
      "y": 5,
      "z": 1,
      "name": "Rock_Aqua_Brick_Decorative"
    },
    {
      "x": -4,
      "y": 6,
      "z": 1,
      "name": "Rock_Aqua_Brick_Smooth"
    },
    {
      "x": -4,
      "y": 7,
      "z": 1,
      "name": "Rock_Aqua_Brick_Smooth"
    },
    {
      "x": -4,
      "y": 8,
      "z": 1,
      "name": "Rock_Aqua_Brick_Stairs",
      "rotation": 3
    },
    {
      "x": -4,
      "y": 20,
      "z": 1,
      "name": "Rock_Aqua_Cobble_Roof_Shallow",
      "filler": 1,
      "rotation": 3
    },
    {
      "x": -4,
      "y": 20,
      "z": 2,
      "name": "Rock_Aqua_Cobble_Roof_Shallow",
      "filler": 1,
      "rotation": 3
    },
    {
      "x": -4,
      "y": -9,
      "z": 3,
      "name": "Rock_Aqua_Brick_Smooth"
    },
    {
      "x": -4,
      "y": -8,
      "z": 3,
      "name": "Rock_Aqua_Brick_Smooth"
    },
    {
      "x": -4,
      "y": -7,
      "z": 3,
      "name": "Rock_Aqua_Brick_Decorative"
    },
    {
      "x": -4,
      "y": -6,
      "z": 3,
      "name": "Rock_Aqua_Brick_Smooth"
    },
    {
      "x": -4,
      "y": -5,
      "z": 3,
      "name": "Rock_Aqua_Brick_Smooth"
    },
    {
      "x": -4,
      "y": -4,
      "z": 3,
      "name": "Rock_Aqua_Brick_Decorative"
    },
    {
      "x": -4,
      "y": -3,
      "z": 3,
      "name": "Rock_Aqua_Brick_Smooth"
    },
    {
      "x": -4,
      "y": -2,
      "z": 3,
      "name": "Rock_Aqua_Brick_Smooth"
    },
    {
      "x": -4,
      "y": -1,
      "z": 3,
      "name": "Rock_Aqua_Brick_Decorative"
    },
    {
      "x": -4,
      "y": 0,
      "z": 3,
      "name": "Rock_Aqua_Brick_Smooth"
    },
    {
      "x": -4,
      "y": 1,
      "z": 3,
      "name": "Rock_Aqua_Brick_Smooth"
    },
    {
      "x": -4,
      "y": 2,
      "z": 3,
      "name": "Rock_Aqua_Brick_Decorative"
    },
    {
      "x": -4,
      "y": 3,
      "z": 3,
      "name": "Rock_Aqua_Brick_Smooth"
    },
    {
      "x": -4,
      "y": 4,
      "z": 3,
      "name": "Rock_Aqua_Brick_Smooth"
    },
    {
      "x": -4,
      "y": 5,
      "z": 3,
      "name": "Rock_Aqua_Brick_Decorative"
    },
    {
      "x": -4,
      "y": 6,
      "z": 3,
      "name": "Rock_Aqua_Brick_Smooth"
    },
    {
      "x": -4,
      "y": 7,
      "z": 3,
      "name": "Rock_Aqua_Brick_Smooth"
    },
    {
      "x": -4,
      "y": 8,
      "z": 3,
      "name": "Rock_Aqua_Brick_Stairs",
      "rotation": 3
    },
    {
      "x": -4,
      "y": 20,
      "z": 3,
      "name": "Rock_Aqua_Cobble_Roof_Shallow",
      "filler": 1,
      "rotation": 3
    },
    {
      "x": -4,
      "y": 20,
      "z": 4,
      "name": "*Rock_Aqua_Cobble_Roof_Shallow_State_Definitions_Corner_Left",
      "filler": 993,
      "rotation": 3
    },
    {
      "x": -4,
      "y": 20,
      "z": 5,
      "name": "*Rock_Aqua_Cobble_Roof_Shallow_State_Definitions_Corner_Left",
      "filler": 1,
      "rotation": 3
    },
    {
      "x": -3,
      "y": 20,
      "z": -5,
      "name": "Rock_Aqua_Cobble_Roof_Shallow",
      "rotation": 2
    },
    {
      "x": -3,
      "y": -9,
      "z": -4,
      "name": "Rock_Aqua_Brick_Smooth"
    },
    {
      "x": -3,
      "y": -8,
      "z": -4,
      "name": "Rock_Aqua_Brick_Smooth"
    },
    {
      "x": -3,
      "y": -7,
      "z": -4,
      "name": "Rock_Aqua_Brick_Decorative"
    },
    {
      "x": -3,
      "y": -6,
      "z": -4,
      "name": "Rock_Aqua_Brick_Smooth"
    },
    {
      "x": -3,
      "y": -5,
      "z": -4,
      "name": "Rock_Aqua_Brick_Smooth"
    },
    {
      "x": -3,
      "y": -4,
      "z": -4,
      "name": "Rock_Aqua_Brick_Decorative"
    },
    {
      "x": -3,
      "y": -3,
      "z": -4,
      "name": "Rock_Aqua_Brick_Smooth"
    },
    {
      "x": -3,
      "y": -2,
      "z": -4,
      "name": "Rock_Aqua_Brick_Smooth"
    },
    {
      "x": -3,
      "y": -1,
      "z": -4,
      "name": "Rock_Aqua_Brick_Decorative"
    },
    {
      "x": -3,
      "y": 0,
      "z": -4,
      "name": "Rock_Aqua_Brick_Smooth"
    },
    {
      "x": -3,
      "y": 1,
      "z": -4,
      "name": "Rock_Aqua_Brick_Smooth"
    },
    {
      "x": -3,
      "y": 2,
      "z": -4,
      "name": "Rock_Aqua_Brick_Decorative"
    },
    {
      "x": -3,
      "y": 3,
      "z": -4,
      "name": "Rock_Aqua_Brick_Smooth"
    },
    {
      "x": -3,
      "y": 4,
      "z": -4,
      "name": "Rock_Aqua_Brick_Smooth"
    },
    {
      "x": -3,
      "y": 5,
      "z": -4,
      "name": "Rock_Aqua_Brick_Decorative"
    },
    {
      "x": -3,
      "y": 6,
      "z": -4,
      "name": "Rock_Aqua_Brick_Smooth"
    },
    {
      "x": -3,
      "y": 7,
      "z": -4,
      "name": "Rock_Aqua_Brick_Smooth"
    },
    {
      "x": -3,
      "y": 8,
      "z": -4,
      "name": "Rock_Aqua_Brick_Stairs",
      "rotation": 2
    },
    {
      "x": -3,
      "y": 20,
      "z": -4,
      "name": "Rock_Aqua_Cobble_Roof_Shallow",
      "filler": 32,
      "rotation": 2
    },
    {
      "x": -3,
      "y": -9,
      "z": -3,
      "name": "Rock_Aqua_Brick_Smooth"
    },
    {
      "x": -3,
      "y": -8,
      "z": -3,
      "name": "Rock_Aqua_Brick_Smooth"
    },
    {
      "x": -3,
      "y": -7,
      "z": -3,
      "name": "Rock_Aqua_Brick_Smooth"
    },
    {
      "x": -3,
      "y": -6,
      "z": -3,
      "name": "Rock_Aqua_Brick_Smooth"
    },
    {
      "x": -3,
      "y": -5,
      "z": -3,
      "name": "Rock_Aqua_Brick_Smooth"
    },
    {
      "x": -3,
      "y": -4,
      "z": -3,
      "name": "Rock_Aqua_Brick_Smooth"
    },
    {
      "x": -3,
      "y": -3,
      "z": -3,
      "name": "Rock_Aqua_Brick_Smooth"
    },
    {
      "x": -3,
      "y": -2,
      "z": -3,
      "name": "Rock_Aqua_Brick_Smooth"
    },
    {
      "x": -3,
      "y": -1,
      "z": -3,
      "name": "Rock_Aqua_Brick_Smooth"
    },
    {
      "x": -3,
      "y": 0,
      "z": -3,
      "name": "Rock_Aqua_Brick_Smooth"
    },
    {
      "x": -3,
      "y": 1,
      "z": -3,
      "name": "Rock_Aqua_Brick_Smooth"
    },
    {
      "x": -3,
      "y": 2,
      "z": -3,
      "name": "Rock_Aqua_Brick_Smooth"
    },
    {
      "x": -3,
      "y": 3,
      "z": -3,
      "name": "Rock_Aqua_Brick_Smooth"
    },
    {
      "x": -3,
      "y": 4,
      "z": -3,
      "name": "Rock_Aqua_Brick_Smooth"
    },
    {
      "x": -3,
      "y": 5,
      "z": -3,
      "name": "Rock_Aqua_Brick_Smooth"
    },
    {
      "x": -3,
      "y": 6,
      "z": -3,
      "name": "Rock_Aqua_Brick_Smooth"
    },
    {
      "x": -3,
      "y": 7,
      "z": -3,
      "name": "Rock_Aqua_Brick_Smooth"
    },
    {
      "x": -3,
      "y": 8,
      "z": -3,
      "name": "Rock_Aqua_Brick_Decorative",
      "rotation": 3
    },
    {
      "x": -3,
      "y": 9,
      "z": -3,
      "name": "Rock_Aqua_Brick_Ornate",
      "rotation": 3
    },
    {
      "x": -3,
      "y": 10,
      "z": -3,
      "name": "Rock_Aqua_Brick_Smooth",
      "rotation": 3
    },
    {
      "x": -3,
      "y": 11,
      "z": -3,
      "name": "Rock_Aqua_Brick_Decorative",
      "rotation": 3
    },
    {
      "x": -3,
      "y": 12,
      "z": -3,
      "name": "Rock_Aqua_Brick_Ornate",
      "rotation": 3
    },
    {
      "x": -3,
      "y": 13,
      "z": -3,
      "name": "Rock_Aqua_Brick_Smooth",
      "rotation": 3
    },
    {
      "x": -3,
      "y": 14,
      "z": -3,
      "name": "Rock_Aqua_Brick_Decorative",
      "rotation": 3
    },
    {
      "x": -3,
      "y": 15,
      "z": -3,
      "name": "Rock_Aqua_Brick_Ornate",
      "rotation": 3
    },
    {
      "x": -3,
      "y": 16,
      "z": -3,
      "name": "Rock_Aqua_Brick_Smooth",
      "rotation": 3
    },
    {
      "x": -3,
      "y": 17,
      "z": -3,
      "name": "Rock_Aqua_Brick_Ornate"
    },
    {
      "x": -3,
      "y": 21,
      "z": -3,
      "name": "*Rock_Aqua_Cobble_Roof_Hollow_State_Definitions_Corner_Left",
      "rotation": 2
    },
    {
      "x": -3,
      "y": -9,
      "z": -2,
      "name": "Rock_Aqua_Brick_Smooth"
    },
    {
      "x": -3,
      "y": -8,
      "z": -2,
      "name": "Rock_Aqua_Brick_Smooth"
    },
    {
      "x": -3,
      "y": -7,
      "z": -2,
      "name": "Rock_Aqua_Brick_Decorative"
    },
    {
      "x": -3,
      "y": -6,
      "z": -2,
      "name": "Rock_Aqua_Brick_Smooth"
    },
    {
      "x": -3,
      "y": -5,
      "z": -2,
      "name": "Rock_Aqua_Brick_Smooth"
    },
    {
      "x": -3,
      "y": -4,
      "z": -2,
      "name": "Rock_Aqua_Brick_Decorative"
    },
    {
      "x": -3,
      "y": -3,
      "z": -2,
      "name": "Rock_Aqua_Brick_Smooth"
    },
    {
      "x": -3,
      "y": -2,
      "z": -2,
      "name": "Rock_Aqua_Brick_Smooth"
    },
    {
      "x": -3,
      "y": -1,
      "z": -2,
      "name": "Rock_Aqua_Brick_Decorative"
    },
    {
      "x": -3,
      "y": 0,
      "z": -2,
      "name": "Rock_Aqua_Brick_Smooth"
    },
    {
      "x": -3,
      "y": 1,
      "z": -2,
      "name": "Rock_Aqua_Brick_Smooth"
    },
    {
      "x": -3,
      "y": 2,
      "z": -2,
      "name": "Rock_Aqua_Brick_Decorative"
    },
    {
      "x": -3,
      "y": 3,
      "z": -2,
      "name": "Rock_Aqua_Brick_Smooth"
    },
    {
      "x": -3,
      "y": 4,
      "z": -2,
      "name": "Rock_Aqua_Brick_Smooth"
    },
    {
      "x": -3,
      "y": 5,
      "z": -2,
      "name": "Rock_Aqua_Brick_Decorative"
    },
    {
      "x": -3,
      "y": 6,
      "z": -2,
      "name": "Rock_Aqua_Brick_Smooth"
    },
    {
      "x": -3,
      "y": 7,
      "z": -2,
      "name": "Rock_Aqua_Brick_Smooth"
    },
    {
      "x": -3,
      "y": 8,
      "z": -2,
      "name": "Rock_Aqua_Brick_Decorative"
    },
    {
      "x": -3,
      "y": 9,
      "z": -2,
      "name": "Rock_Aqua_Brick_Stairs",
      "rotation": 3
    },
    {
      "x": -3,
      "y": 10,
      "z": -2,
      "name": "Rock_Aqua_Brick_Half",
      "rotation": 7
    },
    {
      "x": -3,
      "y": 11,
      "z": -2,
      "name": "Rock_Aqua_Brick_Half",
      "rotation": 7
    },
    {
      "x": -3,
      "y": 12,
      "z": -2,
      "name": "Rock_Aqua_Brick_Half",
      "rotation": 7
    },
    {
      "x": -3,
      "y": 13,
      "z": -2,
      "name": "Rock_Aqua_Brick_Half",
      "rotation": 7
    },
    {
      "x": -3,
      "y": 14,
      "z": -2,
      "name": "Rock_Aqua_Brick_Half",
      "rotation": 7
    },
    {
      "x": -3,
      "y": 15,
      "z": -2,
      "name": "Rock_Aqua_Brick_Half",
      "rotation": 7
    },
    {
      "x": -3,
      "y": 16,
      "z": -2,
      "name": "Rock_Aqua_Brick_Stairs",
      "rotation": 9
    },
    {
      "x": -3,
      "y": 17,
      "z": -2,
      "name": "Rock_Aqua_Brick_Pillar_Base"
    },
    {
      "x": -3,
      "y": 18,
      "z": -2,
      "name": "Rock_Aqua_Brick_Pillar_Middle"
    },
    {
      "x": -3,
      "y": 19,
      "z": -2,
      "name": "Rock_Aqua_Brick_Beam"
    },
    {
      "x": -3,
      "y": 20,
      "z": -2,
      "name": "Rock_Aqua_Brick_Pillar_Base",
      "rotation": 8
    },
    {
      "x": -3,
      "y": 21,
      "z": -2,
      "name": "Rock_Aqua_Cobble_Roof",
      "rotation": 3
    },
    {
      "x": -3,
      "y": -9,
      "z": -1,
      "name": "Rock_Aqua_Brick_Smooth"
    },
    {
      "x": -3,
      "y": -8,
      "z": -1,
      "name": "Rock_Aqua_Brick_Smooth"
    },
    {
      "x": -3,
      "y": -7,
      "z": -1,
      "name": "Rock_Aqua_Brick_Smooth"
    },
    {
      "x": -3,
      "y": -6,
      "z": -1,
      "name": "Rock_Aqua_Brick_Smooth"
    },
    {
      "x": -3,
      "y": -5,
      "z": -1,
      "name": "Rock_Aqua_Brick_Smooth"
    },
    {
      "x": -3,
      "y": -4,
      "z": -1,
      "name": "Rock_Aqua_Brick_Smooth"
    },
    {
      "x": -3,
      "y": -3,
      "z": -1,
      "name": "Rock_Aqua_Brick_Smooth"
    },
    {
      "x": -3,
      "y": -2,
      "z": -1,
      "name": "Rock_Aqua_Brick_Smooth"
    },
    {
      "x": -3,
      "y": -1,
      "z": -1,
      "name": "Rock_Aqua_Brick_Smooth"
    },
    {
      "x": -3,
      "y": 0,
      "z": -1,
      "name": "Rock_Aqua_Brick_Smooth"
    },
    {
      "x": -3,
      "y": 1,
      "z": -1,
      "name": "Rock_Aqua_Brick_Smooth"
    },
    {
      "x": -3,
      "y": 2,
      "z": -1,
      "name": "Rock_Aqua_Brick_Smooth"
    },
    {
      "x": -3,
      "y": 3,
      "z": -1,
      "name": "Rock_Aqua_Brick_Smooth"
    },
    {
      "x": -3,
      "y": 4,
      "z": -1,
      "name": "Rock_Aqua_Brick_Smooth"
    },
    {
      "x": -3,
      "y": 5,
      "z": -1,
      "name": "Rock_Aqua_Brick_Smooth"
    },
    {
      "x": -3,
      "y": 6,
      "z": -1,
      "name": "Rock_Aqua_Brick_Smooth"
    },
    {
      "x": -3,
      "y": 7,
      "z": -1,
      "name": "Rock_Aqua_Brick_Smooth"
    },
    {
      "x": -3,
      "y": 8,
      "z": -1,
      "name": "Rock_Aqua_Brick_Decorative",
      "rotation": 3
    },
    {
      "x": -3,
      "y": 9,
      "z": -1,
      "name": "Rock_Aqua_Brick_Smooth",
      "rotation": 3
    },
    {
      "x": -3,
      "y": 10,
      "z": -1,
      "name": "Rock_Aqua_Brick_Smooth",
      "rotation": 3
    },
    {
      "x": -3,
      "y": 11,
      "z": -1,
      "name": "Rock_Aqua_Brick_Decorative",
      "rotation": 3
    },
    {
      "x": -3,
      "y": 12,
      "z": -1,
      "name": "Rock_Aqua_Brick_Smooth",
      "rotation": 3
    },
    {
      "x": -3,
      "y": 13,
      "z": -1,
      "name": "Rock_Aqua_Brick_Smooth",
      "rotation": 3
    },
    {
      "x": -3,
      "y": 14,
      "z": -1,
      "name": "Rock_Aqua_Brick_Decorative",
      "rotation": 3
    },
    {
      "x": -3,
      "y": 15,
      "z": -1,
      "name": "Rock_Aqua_Brick_Smooth",
      "support": 15,
      "rotation": 3
    },
    {
      "x": -3,
      "y": 16,
      "z": -1,
      "name": "Rock_Aqua_Brick_Smooth",
      "rotation": 3
    },
    {
      "x": -3,
      "y": 17,
      "z": -1,
      "name": "Rock_Aqua_Brick_Wall",
      "rotation": 1
    },
    {
      "x": -3,
      "y": 20,
      "z": -1,
      "name": "Rock_Aqua_Brick_Wall",
      "rotation": 1
    },
    {
      "x": -3,
      "y": 21,
      "z": -1,
      "name": "Rock_Aqua_Cobble_Roof",
      "rotation": 3
    },
    {
      "x": -3,
      "y": -9,
      "z": 0,
      "name": "Rock_Aqua_Brick_Smooth"
    },
    {
      "x": -3,
      "y": -8,
      "z": 0,
      "name": "Rock_Aqua_Brick_Smooth"
    },
    {
      "x": -3,
      "y": -7,
      "z": 0,
      "name": "Rock_Aqua_Brick_Decorative"
    },
    {
      "x": -3,
      "y": -6,
      "z": 0,
      "name": "Rock_Aqua_Brick_Smooth"
    },
    {
      "x": -3,
      "y": -5,
      "z": 0,
      "name": "Rock_Aqua_Brick_Smooth"
    },
    {
      "x": -3,
      "y": -4,
      "z": 0,
      "name": "Rock_Aqua_Brick_Decorative"
    },
    {
      "x": -3,
      "y": -3,
      "z": 0,
      "name": "Rock_Aqua_Brick_Smooth"
    },
    {
      "x": -3,
      "y": -2,
      "z": 0,
      "name": "Rock_Aqua_Brick_Smooth"
    },
    {
      "x": -3,
      "y": -1,
      "z": 0,
      "name": "Rock_Aqua_Brick_Decorative"
    },
    {
      "x": -3,
      "y": 0,
      "z": 0,
      "name": "Rock_Aqua_Brick_Smooth"
    },
    {
      "x": -3,
      "y": 1,
      "z": 0,
      "name": "Rock_Aqua_Brick_Smooth"
    },
    {
      "x": -3,
      "y": 2,
      "z": 0,
      "name": "Rock_Aqua_Brick_Decorative"
    },
    {
      "x": -3,
      "y": 3,
      "z": 0,
      "name": "Rock_Aqua_Brick_Smooth"
    },
    {
      "x": -3,
      "y": 4,
      "z": 0,
      "name": "Rock_Aqua_Brick_Smooth"
    },
    {
      "x": -3,
      "y": 5,
      "z": 0,
      "name": "Rock_Aqua_Brick_Decorative"
    },
    {
      "x": -3,
      "y": 6,
      "z": 0,
      "name": "Rock_Aqua_Brick_Smooth"
    },
    {
      "x": -3,
      "y": 7,
      "z": 0,
      "name": "Rock_Aqua_Brick_Smooth"
    },
    {
      "x": -3,
      "y": 8,
      "z": 0,
      "name": "Rock_Aqua_Brick_Decorative"
    },
    {
      "x": -3,
      "y": 9,
      "z": 0,
      "name": "Rock_Aqua_Brick_Stairs",
      "rotation": 3
    },
    {
      "x": -3,
      "y": 10,
      "z": 0,
      "name": "Rock_Aqua_Brick_Half",
      "rotation": 7
    },
    {
      "x": -3,
      "y": 11,
      "z": 0,
      "name": "Rock_Aqua_Brick_Half",
      "rotation": 7
    },
    {
      "x": -3,
      "y": 12,
      "z": 0,
      "name": "Rock_Aqua_Brick_Half",
      "rotation": 7
    },
    {
      "x": -3,
      "y": 13,
      "z": 0,
      "name": "Rock_Aqua_Brick_Half",
      "rotation": 7
    },
    {
      "x": -3,
      "y": 14,
      "z": 0,
      "name": "Rock_Aqua_Brick_Half",
      "rotation": 7
    },
    {
      "x": -3,
      "y": 15,
      "z": 0,
      "name": "Rock_Aqua_Brick_Half",
      "rotation": 7
    },
    {
      "x": -3,
      "y": 16,
      "z": 0,
      "name": "Rock_Aqua_Brick_Stairs",
      "rotation": 9
    },
    {
      "x": -3,
      "y": 17,
      "z": 0,
      "name": "Rock_Aqua_Brick_Wall",
      "rotation": 1
    },
    {
      "x": -3,
      "y": 20,
      "z": 0,
      "name": "Rock_Aqua_Brick_Pillar_Base",
      "rotation": 8
    },
    {
      "x": -3,
      "y": 21,
      "z": 0,
      "name": "Rock_Aqua_Cobble_Roof",
      "rotation": 3
    },
    {
      "x": -3,
      "y": -9,
      "z": 1,
      "name": "Rock_Aqua_Brick_Smooth"
    },
    {
      "x": -3,
      "y": -8,
      "z": 1,
      "name": "Rock_Aqua_Brick_Smooth"
    },
    {
      "x": -3,
      "y": -7,
      "z": 1,
      "name": "Rock_Aqua_Brick_Smooth"
    },
    {
      "x": -3,
      "y": -6,
      "z": 1,
      "name": "Rock_Aqua_Brick_Smooth"
    },
    {
      "x": -3,
      "y": -5,
      "z": 1,
      "name": "Rock_Aqua_Brick_Smooth"
    },
    {
      "x": -3,
      "y": -4,
      "z": 1,
      "name": "Rock_Aqua_Brick_Smooth"
    },
    {
      "x": -3,
      "y": -3,
      "z": 1,
      "name": "Rock_Aqua_Brick_Smooth"
    },
    {
      "x": -3,
      "y": -2,
      "z": 1,
      "name": "Rock_Aqua_Brick_Smooth"
    },
    {
      "x": -3,
      "y": -1,
      "z": 1,
      "name": "Rock_Aqua_Brick_Smooth"
    },
    {
      "x": -3,
      "y": 0,
      "z": 1,
      "name": "Rock_Aqua_Brick_Smooth"
    },
    {
      "x": -3,
      "y": 1,
      "z": 1,
      "name": "Rock_Aqua_Brick_Smooth"
    },
    {
      "x": -3,
      "y": 2,
      "z": 1,
      "name": "Rock_Aqua_Brick_Smooth"
    },
    {
      "x": -3,
      "y": 3,
      "z": 1,
      "name": "Rock_Aqua_Brick_Smooth"
    },
    {
      "x": -3,
      "y": 4,
      "z": 1,
      "name": "Rock_Aqua_Brick_Smooth"
    },
    {
      "x": -3,
      "y": 5,
      "z": 1,
      "name": "Rock_Aqua_Brick_Smooth"
    },
    {
      "x": -3,
      "y": 6,
      "z": 1,
      "name": "Rock_Aqua_Brick_Smooth"
    },
    {
      "x": -3,
      "y": 7,
      "z": 1,
      "name": "Rock_Aqua_Brick_Smooth"
    },
    {
      "x": -3,
      "y": 8,
      "z": 1,
      "name": "Rock_Aqua_Brick_Decorative"
    },
    {
      "x": -3,
      "y": 9,
      "z": 1,
      "name": "Rock_Aqua_Brick_Smooth"
    },
    {
      "x": -3,
      "y": 10,
      "z": 1,
      "name": "Rock_Aqua_Brick_Smooth"
    },
    {
      "x": -3,
      "y": 11,
      "z": 1,
      "name": "Rock_Aqua_Brick_Decorative"
    },
    {
      "x": -3,
      "y": 12,
      "z": 1,
      "name": "Rock_Aqua_Brick_Smooth"
    },
    {
      "x": -3,
      "y": 13,
      "z": 1,
      "name": "Rock_Aqua_Brick_Smooth"
    },
    {
      "x": -3,
      "y": 14,
      "z": 1,
      "name": "Rock_Aqua_Brick_Decorative"
    },
    {
      "x": -3,
      "y": 15,
      "z": 1,
      "name": "Rock_Aqua_Brick_Smooth"
    },
    {
      "x": -3,
      "y": 16,
      "z": 1,
      "name": "Rock_Aqua_Brick_Smooth"
    },
    {
      "x": -3,
      "y": 17,
      "z": 1,
      "name": "Rock_Aqua_Brick_Wall",
      "rotation": 1
    },
    {
      "x": -3,
      "y": 20,
      "z": 1,
      "name": "Rock_Aqua_Brick_Wall",
      "rotation": 1
    },
    {
      "x": -3,
      "y": 21,
      "z": 1,
      "name": "Rock_Aqua_Cobble_Roof",
      "rotation": 3
    },
    {
      "x": -3,
      "y": -9,
      "z": 2,
      "name": "Rock_Aqua_Brick_Smooth"
    },
    {
      "x": -3,
      "y": -8,
      "z": 2,
      "name": "Rock_Aqua_Brick_Smooth"
    },
    {
      "x": -3,
      "y": -7,
      "z": 2,
      "name": "Rock_Aqua_Brick_Decorative"
    },
    {
      "x": -3,
      "y": -6,
      "z": 2,
      "name": "Rock_Aqua_Brick_Smooth"
    },
    {
      "x": -3,
      "y": -5,
      "z": 2,
      "name": "Rock_Aqua_Brick_Smooth"
    },
    {
      "x": -3,
      "y": -4,
      "z": 2,
      "name": "Rock_Aqua_Brick_Decorative"
    },
    {
      "x": -3,
      "y": -3,
      "z": 2,
      "name": "Rock_Aqua_Brick_Smooth"
    },
    {
      "x": -3,
      "y": -2,
      "z": 2,
      "name": "Rock_Aqua_Brick_Smooth"
    },
    {
      "x": -3,
      "y": -1,
      "z": 2,
      "name": "Rock_Aqua_Brick_Decorative"
    },
    {
      "x": -3,
      "y": 0,
      "z": 2,
      "name": "Rock_Aqua_Brick_Smooth"
    },
    {
      "x": -3,
      "y": 1,
      "z": 2,
      "name": "Rock_Aqua_Brick_Smooth"
    },
    {
      "x": -3,
      "y": 2,
      "z": 2,
      "name": "Rock_Aqua_Brick_Decorative"
    },
    {
      "x": -3,
      "y": 3,
      "z": 2,
      "name": "Rock_Aqua_Brick_Smooth"
    },
    {
      "x": -3,
      "y": 4,
      "z": 2,
      "name": "Rock_Aqua_Brick_Smooth"
    },
    {
      "x": -3,
      "y": 5,
      "z": 2,
      "name": "Rock_Aqua_Brick_Decorative"
    },
    {
      "x": -3,
      "y": 6,
      "z": 2,
      "name": "Rock_Aqua_Brick_Smooth"
    },
    {
      "x": -3,
      "y": 7,
      "z": 2,
      "name": "Rock_Aqua_Brick_Smooth"
    },
    {
      "x": -3,
      "y": 8,
      "z": 2,
      "name": "Rock_Aqua_Brick_Decorative"
    },
    {
      "x": -3,
      "y": 9,
      "z": 2,
      "name": "Rock_Aqua_Brick_Stairs",
      "rotation": 3
    },
    {
      "x": -3,
      "y": 10,
      "z": 2,
      "name": "Rock_Aqua_Brick_Half",
      "rotation": 7
    },
    {
      "x": -3,
      "y": 11,
      "z": 2,
      "name": "Rock_Aqua_Brick_Half",
      "rotation": 7
    },
    {
      "x": -3,
      "y": 12,
      "z": 2,
      "name": "Rock_Aqua_Brick_Half",
      "rotation": 7
    },
    {
      "x": -3,
      "y": 13,
      "z": 2,
      "name": "Rock_Aqua_Brick_Half",
      "rotation": 7
    },
    {
      "x": -3,
      "y": 14,
      "z": 2,
      "name": "Rock_Aqua_Brick_Half",
      "rotation": 7
    },
    {
      "x": -3,
      "y": 15,
      "z": 2,
      "name": "Rock_Aqua_Brick_Half",
      "rotation": 7
    },
    {
      "x": -3,
      "y": 16,
      "z": 2,
      "name": "Rock_Aqua_Brick_Stairs",
      "rotation": 9
    },
    {
      "x": -3,
      "y": 17,
      "z": 2,
      "name": "Rock_Aqua_Brick_Pillar_Base"
    },
    {
      "x": -3,
      "y": 18,
      "z": 2,
      "name": "Rock_Aqua_Brick_Pillar_Middle"
    },
    {
      "x": -3,
      "y": 19,
      "z": 2,
      "name": "Rock_Aqua_Brick_Beam"
    },
    {
      "x": -3,
      "y": 20,
      "z": 2,
      "name": "Rock_Aqua_Brick_Pillar_Base",
      "rotation": 8
    },
    {
      "x": -3,
      "y": 21,
      "z": 2,
      "name": "Rock_Aqua_Cobble_Roof",
      "rotation": 3
    },
    {
      "x": -3,
      "y": -9,
      "z": 3,
      "name": "Rock_Aqua_Brick_Smooth"
    },
    {
      "x": -3,
      "y": -8,
      "z": 3,
      "name": "Rock_Aqua_Brick_Smooth"
    },
    {
      "x": -3,
      "y": -7,
      "z": 3,
      "name": "Rock_Aqua_Brick_Smooth"
    },
    {
      "x": -3,
      "y": -6,
      "z": 3,
      "name": "Rock_Aqua_Brick_Smooth"
    },
    {
      "x": -3,
      "y": -5,
      "z": 3,
      "name": "Rock_Aqua_Brick_Smooth"
    },
    {
      "x": -3,
      "y": -4,
      "z": 3,
      "name": "Rock_Aqua_Brick_Smooth"
    },
    {
      "x": -3,
      "y": -3,
      "z": 3,
      "name": "Rock_Aqua_Brick_Smooth"
    },
    {
      "x": -3,
      "y": -2,
      "z": 3,
      "name": "Rock_Aqua_Brick_Smooth"
    },
    {
      "x": -3,
      "y": -1,
      "z": 3,
      "name": "Rock_Aqua_Brick_Smooth"
    },
    {
      "x": -3,
      "y": 0,
      "z": 3,
      "name": "Rock_Aqua_Brick_Smooth"
    },
    {
      "x": -3,
      "y": 1,
      "z": 3,
      "name": "Rock_Aqua_Brick_Smooth"
    },
    {
      "x": -3,
      "y": 2,
      "z": 3,
      "name": "Rock_Aqua_Brick_Smooth"
    },
    {
      "x": -3,
      "y": 3,
      "z": 3,
      "name": "Rock_Aqua_Brick_Smooth"
    },
    {
      "x": -3,
      "y": 4,
      "z": 3,
      "name": "Rock_Aqua_Brick_Smooth"
    },
    {
      "x": -3,
      "y": 5,
      "z": 3,
      "name": "Rock_Aqua_Brick_Smooth"
    },
    {
      "x": -3,
      "y": 6,
      "z": 3,
      "name": "Rock_Aqua_Brick_Smooth"
    },
    {
      "x": -3,
      "y": 7,
      "z": 3,
      "name": "Rock_Aqua_Brick_Smooth"
    },
    {
      "x": -3,
      "y": 8,
      "z": 3,
      "name": "Rock_Aqua_Brick_Decorative"
    },
    {
      "x": -3,
      "y": 9,
      "z": 3,
      "name": "Rock_Aqua_Brick_Ornate"
    },
    {
      "x": -3,
      "y": 10,
      "z": 3,
      "name": "Rock_Aqua_Brick_Smooth"
    },
    {
      "x": -3,
      "y": 11,
      "z": 3,
      "name": "Rock_Aqua_Brick_Decorative"
    },
    {
      "x": -3,
      "y": 12,
      "z": 3,
      "name": "Rock_Aqua_Brick_Ornate"
    },
    {
      "x": -3,
      "y": 13,
      "z": 3,
      "name": "Rock_Aqua_Brick_Smooth"
    },
    {
      "x": -3,
      "y": 14,
      "z": 3,
      "name": "Rock_Aqua_Brick_Decorative"
    },
    {
      "x": -3,
      "y": 15,
      "z": 3,
      "name": "Rock_Aqua_Brick_Ornate"
    },
    {
      "x": -3,
      "y": 16,
      "z": 3,
      "name": "Rock_Aqua_Brick_Smooth"
    },
    {
      "x": -3,
      "y": 17,
      "z": 3,
      "name": "Rock_Aqua_Brick_Ornate"
    },
    {
      "x": -3,
      "y": 21,
      "z": 3,
      "name": "*Rock_Aqua_Cobble_Roof_Hollow_State_Definitions_Corner_Left",
      "rotation": 3
    },
    {
      "x": -3,
      "y": -9,
      "z": 4,
      "name": "Rock_Aqua_Brick_Smooth"
    },
    {
      "x": -3,
      "y": -8,
      "z": 4,
      "name": "Rock_Aqua_Brick_Smooth"
    },
    {
      "x": -3,
      "y": -7,
      "z": 4,
      "name": "Rock_Aqua_Brick_Decorative"
    },
    {
      "x": -3,
      "y": -6,
      "z": 4,
      "name": "Rock_Aqua_Brick_Smooth"
    },
    {
      "x": -3,
      "y": -5,
      "z": 4,
      "name": "Rock_Aqua_Brick_Smooth"
    },
    {
      "x": -3,
      "y": -4,
      "z": 4,
      "name": "Rock_Aqua_Brick_Decorative"
    },
    {
      "x": -3,
      "y": -3,
      "z": 4,
      "name": "Rock_Aqua_Brick_Smooth"
    },
    {
      "x": -3,
      "y": -2,
      "z": 4,
      "name": "Rock_Aqua_Brick_Smooth"
    },
    {
      "x": -3,
      "y": -1,
      "z": 4,
      "name": "Rock_Aqua_Brick_Decorative"
    },
    {
      "x": -3,
      "y": 0,
      "z": 4,
      "name": "Rock_Aqua_Brick_Smooth"
    },
    {
      "x": -3,
      "y": 1,
      "z": 4,
      "name": "Rock_Aqua_Brick_Smooth"
    },
    {
      "x": -3,
      "y": 2,
      "z": 4,
      "name": "Rock_Aqua_Brick_Decorative"
    },
    {
      "x": -3,
      "y": 3,
      "z": 4,
      "name": "Rock_Aqua_Brick_Smooth"
    },
    {
      "x": -3,
      "y": 4,
      "z": 4,
      "name": "Rock_Aqua_Brick_Smooth"
    },
    {
      "x": -3,
      "y": 5,
      "z": 4,
      "name": "Rock_Aqua_Brick_Decorative"
    },
    {
      "x": -3,
      "y": 6,
      "z": 4,
      "name": "Rock_Aqua_Brick_Smooth"
    },
    {
      "x": -3,
      "y": 7,
      "z": 4,
      "name": "Rock_Aqua_Brick_Smooth"
    },
    {
      "x": -3,
      "y": 8,
      "z": 4,
      "name": "Rock_Aqua_Brick_Stairs"
    },
    {
      "x": -3,
      "y": 20,
      "z": 4,
      "name": "Rock_Aqua_Cobble_Roof_Shallow",
      "filler": 992
    },
    {
      "x": -3,
      "y": 20,
      "z": 5,
      "name": "Rock_Aqua_Cobble_Roof_Shallow"
    },
    {
      "x": -2,
      "y": 20,
      "z": -5,
      "name": "Rock_Aqua_Cobble_Roof_Shallow",
      "rotation": 2
    },
    {
      "x": -2,
      "y": 20,
      "z": -4,
      "name": "Rock_Aqua_Cobble_Roof_Shallow",
      "filler": 32,
      "rotation": 2
    },
    {
      "x": -2,
      "y": -9,
      "z": -3,
      "name": "Rock_Aqua_Brick_Smooth"
    },
    {
      "x": -2,
      "y": -8,
      "z": -3,
      "name": "Rock_Aqua_Brick_Smooth"
    },
    {
      "x": -2,
      "y": -7,
      "z": -3,
      "name": "Rock_Aqua_Brick_Decorative"
    },
    {
      "x": -2,
      "y": -6,
      "z": -3,
      "name": "Rock_Aqua_Brick_Smooth"
    },
    {
      "x": -2,
      "y": -5,
      "z": -3,
      "name": "Rock_Aqua_Brick_Smooth"
    },
    {
      "x": -2,
      "y": -4,
      "z": -3,
      "name": "Rock_Aqua_Brick_Decorative"
    },
    {
      "x": -2,
      "y": -3,
      "z": -3,
      "name": "Rock_Aqua_Brick_Smooth"
    },
    {
      "x": -2,
      "y": -2,
      "z": -3,
      "name": "Rock_Aqua_Brick_Smooth"
    },
    {
      "x": -2,
      "y": -1,
      "z": -3,
      "name": "Rock_Aqua_Brick_Decorative"
    },
    {
      "x": -2,
      "y": 0,
      "z": -3,
      "name": "Rock_Aqua_Brick_Smooth"
    },
    {
      "x": -2,
      "y": 1,
      "z": -3,
      "name": "Rock_Aqua_Brick_Smooth"
    },
    {
      "x": -2,
      "y": 2,
      "z": -3,
      "name": "Rock_Aqua_Brick_Decorative"
    },
    {
      "x": -2,
      "y": 3,
      "z": -3,
      "name": "Rock_Aqua_Brick_Smooth"
    },
    {
      "x": -2,
      "y": 4,
      "z": -3,
      "name": "Rock_Aqua_Brick_Smooth"
    },
    {
      "x": -2,
      "y": 5,
      "z": -3,
      "name": "Rock_Aqua_Brick_Decorative"
    },
    {
      "x": -2,
      "y": 6,
      "z": -3,
      "name": "Rock_Aqua_Brick_Smooth"
    },
    {
      "x": -2,
      "y": 7,
      "z": -3,
      "name": "Rock_Aqua_Brick_Smooth"
    },
    {
      "x": -2,
      "y": 8,
      "z": -3,
      "name": "Rock_Aqua_Brick_Decorative"
    },
    {
      "x": -2,
      "y": 9,
      "z": -3,
      "name": "Rock_Aqua_Brick_Stairs",
      "rotation": 2
    },
    {
      "x": -2,
      "y": 10,
      "z": -3,
      "name": "Rock_Aqua_Brick_Half",
      "rotation": 6
    },
    {
      "x": -2,
      "y": 11,
      "z": -3,
      "name": "Rock_Aqua_Brick_Half",
      "rotation": 6
    },
    {
      "x": -2,
      "y": 12,
      "z": -3,
      "name": "Rock_Aqua_Brick_Half",
      "rotation": 6
    },
    {
      "x": -2,
      "y": 13,
      "z": -3,
      "name": "Rock_Aqua_Brick_Half",
      "rotation": 6
    },
    {
      "x": -2,
      "y": 14,
      "z": -3,
      "name": "Rock_Aqua_Brick_Half",
      "rotation": 6
    },
    {
      "x": -2,
      "y": 15,
      "z": -3,
      "name": "Rock_Aqua_Brick_Half",
      "rotation": 6
    },
    {
      "x": -2,
      "y": 16,
      "z": -3,
      "name": "Rock_Aqua_Brick_Stairs",
      "rotation": 8
    },
    {
      "x": -2,
      "y": 17,
      "z": -3,
      "name": "Rock_Aqua_Brick_Pillar_Base"
    },
    {
      "x": -2,
      "y": 18,
      "z": -3,
      "name": "Rock_Aqua_Brick_Pillar_Middle"
    },
    {
      "x": -2,
      "y": 19,
      "z": -3,
      "name": "Rock_Aqua_Brick_Beam"
    },
    {
      "x": -2,
      "y": 20,
      "z": -3,
      "name": "Rock_Aqua_Brick_Pillar_Base",
      "rotation": 8
    },
    {
      "x": -2,
      "y": 21,
      "z": -3,
      "name": "Rock_Aqua_Cobble_Roof",
      "rotation": 2
    },
    {
      "x": -2,
      "y": -9,
      "z": -2,
      "name": "Rock_Aqua_Brick_Smooth"
    },
    {
      "x": -2,
      "y": -8,
      "z": -2,
      "name": "Rock_Aqua_Brick_Smooth"
    },
    {
      "x": -2,
      "y": -7,
      "z": -2,
      "name": "Rock_Aqua_Brick_Smooth"
    },
    {
      "x": -2,
      "y": -6,
      "z": -2,
      "name": "Rock_Aqua_Brick_Smooth"
    },
    {
      "x": -2,
      "y": -5,
      "z": -2,
      "name": "Rock_Aqua_Brick_Smooth"
    },
    {
      "x": -2,
      "y": -4,
      "z": -2,
      "name": "Rock_Aqua_Brick_Smooth"
    },
    {
      "x": -2,
      "y": -3,
      "z": -2,
      "name": "Rock_Aqua_Brick_Smooth"
    },
    {
      "x": -2,
      "y": -2,
      "z": -2,
      "name": "Rock_Aqua_Brick_Smooth"
    },
    {
      "x": -2,
      "y": -1,
      "z": -2,
      "name": "Rock_Aqua_Brick_Smooth"
    },
    {
      "x": -2,
      "y": 0,
      "z": -2,
      "name": "Rock_Aqua_Brick_Smooth"
    },
    {
      "x": -2,
      "y": 1,
      "z": -2,
      "name": "Rock_Aqua_Brick_Smooth"
    },
    {
      "x": -2,
      "y": 2,
      "z": -2,
      "name": "Rock_Aqua_Brick_Smooth"
    },
    {
      "x": -2,
      "y": 3,
      "z": -2,
      "name": "Rock_Aqua_Brick_Smooth"
    },
    {
      "x": -2,
      "y": 4,
      "z": -2,
      "name": "Rock_Aqua_Brick_Smooth"
    },
    {
      "x": -2,
      "y": 5,
      "z": -2,
      "name": "Rock_Aqua_Brick_Smooth"
    },
    {
      "x": -2,
      "y": 6,
      "z": -2,
      "name": "Rock_Aqua_Brick_Smooth"
    },
    {
      "x": -2,
      "y": 7,
      "z": -2,
      "name": "Rock_Aqua_Brick_Smooth"
    },
    {
      "x": -2,
      "y": 8,
      "z": -2,
      "name": "Rock_Aqua_Brick_Smooth"
    },
    {
      "x": -2,
      "y": 9,
      "z": -2,
      "name": "Rock_Aqua_Brick_Smooth"
    },
    {
      "x": -2,
      "y": 10,
      "z": -2,
      "name": "Rock_Aqua_Brick_Smooth"
    },
    {
      "x": -2,
      "y": 11,
      "z": -2,
      "name": "Rock_Runic_Brick"
    },
    {
      "x": -2,
      "y": 15,
      "z": -2,
      "name": "Rock_Runic_Blue_Brick_Half",
      "rotation": 8
    },
    {
      "x": -2,
      "y": 16,
      "z": -2,
      "name": "Rock_Runic_Blue_Brick"
    },
    {
      "x": -2,
      "y": 22,
      "z": -2,
      "name": "*Rock_Aqua_Cobble_Roof_Hollow_State_Definitions_Corner_Right",
      "rotation": 3
    },
    {
      "x": -2,
      "y": -9,
      "z": -1,
      "name": "Rock_Aqua_Brick_Smooth"
    },
    {
      "x": -2,
      "y": -8,
      "z": -1,
      "name": "Rock_Aqua_Brick_Smooth"
    },
    {
      "x": -2,
      "y": -7,
      "z": -1,
      "name": "Rock_Aqua_Brick_Smooth"
    },
    {
      "x": -2,
      "y": -6,
      "z": -1,
      "name": "Rock_Aqua_Brick_Smooth"
    },
    {
      "x": -2,
      "y": -5,
      "z": -1,
      "name": "Rock_Aqua_Brick_Smooth"
    },
    {
      "x": -2,
      "y": -4,
      "z": -1,
      "name": "Rock_Aqua_Brick_Smooth"
    },
    {
      "x": -2,
      "y": -3,
      "z": -1,
      "name": "Rock_Aqua_Brick_Smooth"
    },
    {
      "x": -2,
      "y": -2,
      "z": -1,
      "name": "Rock_Aqua_Brick_Smooth"
    },
    {
      "x": -2,
      "y": -1,
      "z": -1,
      "name": "Rock_Aqua_Brick_Smooth"
    },
    {
      "x": -2,
      "y": 0,
      "z": -1,
      "name": "Rock_Aqua_Brick_Smooth"
    },
    {
      "x": -2,
      "y": 1,
      "z": -1,
      "name": "Rock_Aqua_Brick_Smooth"
    },
    {
      "x": -2,
      "y": 2,
      "z": -1,
      "name": "Rock_Aqua_Brick_Smooth"
    },
    {
      "x": -2,
      "y": 3,
      "z": -1,
      "name": "Rock_Aqua_Brick_Smooth"
    },
    {
      "x": -2,
      "y": 4,
      "z": -1,
      "name": "Rock_Aqua_Brick_Smooth"
    },
    {
      "x": -2,
      "y": 5,
      "z": -1,
      "name": "Rock_Aqua_Brick_Smooth"
    },
    {
      "x": -2,
      "y": 6,
      "z": -1,
      "name": "Rock_Aqua_Brick_Smooth"
    },
    {
      "x": -2,
      "y": 7,
      "z": -1,
      "name": "Rock_Aqua_Brick_Smooth"
    },
    {
      "x": -2,
      "y": 8,
      "z": -1,
      "name": "Rock_Aqua_Brick_Smooth"
    },
    {
      "x": -2,
      "y": 9,
      "z": -1,
      "name": "Rock_Aqua_Brick_Smooth"
    },
    {
      "x": -2,
      "y": 10,
      "z": -1,
      "name": "Rock_Aqua_Brick_Smooth"
    },
    {
      "x": -2,
      "y": 11,
      "z": -1,
      "name": "Rock_Runic_Brick"
    },
    {
      "x": -2,
      "y": 15,
      "z": -1,
      "name": "Rock_Aqua_Brick_Smooth_Half",
      "rotation": 5
    },
    {
      "x": -2,
      "y": 16,
      "z": -1,
      "name": "Rock_Runic_Blue_Brick"
    },
    {
      "x": -2,
      "y": 22,
      "z": -1,
      "name": "Rock_Aqua_Cobble_Roof_Hollow",
      "rotation": 3
    },
    {
      "x": -2,
      "y": -9,
      "z": 0,
      "name": "Rock_Aqua_Brick_Smooth"
    },
    {
      "x": -2,
      "y": -8,
      "z": 0,
      "name": "Rock_Aqua_Brick_Smooth"
    },
    {
      "x": -2,
      "y": -7,
      "z": 0,
      "name": "Rock_Aqua_Brick_Smooth"
    },
    {
      "x": -2,
      "y": -6,
      "z": 0,
      "name": "Rock_Aqua_Brick_Smooth"
    },
    {
      "x": -2,
      "y": -5,
      "z": 0,
      "name": "Rock_Aqua_Brick_Smooth"
    },
    {
      "x": -2,
      "y": -4,
      "z": 0,
      "name": "Rock_Aqua_Brick_Smooth"
    },
    {
      "x": -2,
      "y": -3,
      "z": 0,
      "name": "Rock_Aqua_Brick_Smooth"
    },
    {
      "x": -2,
      "y": -2,
      "z": 0,
      "name": "Rock_Aqua_Brick_Smooth"
    },
    {
      "x": -2,
      "y": -1,
      "z": 0,
      "name": "Rock_Aqua_Brick_Smooth"
    },
    {
      "x": -2,
      "y": 0,
      "z": 0,
      "name": "Rock_Aqua_Brick_Smooth"
    },
    {
      "x": -2,
      "y": 1,
      "z": 0,
      "name": "Rock_Aqua_Brick_Smooth"
    },
    {
      "x": -2,
      "y": 2,
      "z": 0,
      "name": "Rock_Aqua_Brick_Smooth"
    },
    {
      "x": -2,
      "y": 3,
      "z": 0,
      "name": "Rock_Aqua_Brick_Smooth"
    },
    {
      "x": -2,
      "y": 4,
      "z": 0,
      "name": "Rock_Aqua_Brick_Smooth"
    },
    {
      "x": -2,
      "y": 5,
      "z": 0,
      "name": "Rock_Aqua_Brick_Smooth"
    },
    {
      "x": -2,
      "y": 6,
      "z": 0,
      "name": "Rock_Aqua_Brick_Smooth"
    },
    {
      "x": -2,
      "y": 7,
      "z": 0,
      "name": "Rock_Aqua_Brick_Smooth"
    },
    {
      "x": -2,
      "y": 8,
      "z": 0,
      "name": "Rock_Aqua_Brick_Smooth"
    },
    {
      "x": -2,
      "y": 9,
      "z": 0,
      "name": "Rock_Aqua_Brick_Smooth"
    },
    {
      "x": -2,
      "y": 10,
      "z": 0,
      "name": "Rock_Aqua_Brick_Smooth"
    },
    {
      "x": -2,
      "y": 11,
      "z": 0,
      "name": "Rock_Runic_Brick"
    },
    {
      "x": -2,
      "y": 12,
      "z": 0,
      "name": "Furniture_Ancient_Barrel"
    },
    {
      "x": -2,
      "y": 16,
      "z": 0,
      "name": "Rock_Runic_Blue_Brick"
    },
    {
      "x": -2,
      "y": 22,
      "z": 0,
      "name": "Rock_Aqua_Cobble_Roof_Hollow",
      "rotation": 3
    },
    {
      "x": -2,
      "y": -9,
      "z": 1,
      "name": "Rock_Aqua_Brick_Smooth"
    },
    {
      "x": -2,
      "y": -8,
      "z": 1,
      "name": "Rock_Aqua_Brick_Smooth"
    },
    {
      "x": -2,
      "y": -7,
      "z": 1,
      "name": "Rock_Aqua_Brick_Smooth"
    },
    {
      "x": -2,
      "y": -6,
      "z": 1,
      "name": "Rock_Aqua_Brick_Smooth"
    },
    {
      "x": -2,
      "y": -5,
      "z": 1,
      "name": "Rock_Aqua_Brick_Smooth"
    },
    {
      "x": -2,
      "y": -4,
      "z": 1,
      "name": "Rock_Aqua_Brick_Smooth"
    },
    {
      "x": -2,
      "y": -3,
      "z": 1,
      "name": "Rock_Aqua_Brick_Smooth"
    },
    {
      "x": -2,
      "y": -2,
      "z": 1,
      "name": "Rock_Aqua_Brick_Smooth"
    },
    {
      "x": -2,
      "y": -1,
      "z": 1,
      "name": "Rock_Aqua_Brick_Smooth"
    },
    {
      "x": -2,
      "y": 0,
      "z": 1,
      "name": "Rock_Aqua_Brick_Smooth"
    },
    {
      "x": -2,
      "y": 1,
      "z": 1,
      "name": "Rock_Aqua_Brick_Smooth"
    },
    {
      "x": -2,
      "y": 2,
      "z": 1,
      "name": "Rock_Aqua_Brick_Smooth"
    },
    {
      "x": -2,
      "y": 3,
      "z": 1,
      "name": "Rock_Aqua_Brick_Smooth"
    },
    {
      "x": -2,
      "y": 4,
      "z": 1,
      "name": "Rock_Aqua_Brick_Smooth"
    },
    {
      "x": -2,
      "y": 5,
      "z": 1,
      "name": "Rock_Aqua_Brick_Smooth"
    },
    {
      "x": -2,
      "y": 6,
      "z": 1,
      "name": "Rock_Aqua_Brick_Smooth"
    },
    {
      "x": -2,
      "y": 7,
      "z": 1,
      "name": "Rock_Aqua_Brick_Smooth"
    },
    {
      "x": -2,
      "y": 8,
      "z": 1,
      "name": "Rock_Aqua_Brick_Smooth"
    },
    {
      "x": -2,
      "y": 9,
      "z": 1,
      "name": "Rock_Aqua_Brick_Smooth"
    },
    {
      "x": -2,
      "y": 10,
      "z": 1,
      "name": "Rock_Aqua_Brick_Smooth"
    },
    {
      "x": -2,
      "y": 11,
      "z": 1,
      "name": "Rock_Runic_Brick"
    },
    {
      "x": -2,
      "y": 12,
      "z": 1,
      "name": "Rock_Aqua_Brick_Smooth_Half",
      "rotation": 5
    },
    {
      "x": -2,
      "y": 15,
      "z": 1,
      "name": "Rock_Aqua_Brick_Smooth_Half",
      "rotation": 5
    },
    {
      "x": -2,
      "y": 16,
      "z": 1,
      "name": "Rock_Runic_Blue_Brick"
    },
    {
      "x": -2,
      "y": 22,
      "z": 1,
      "name": "Rock_Aqua_Cobble_Roof_Hollow",
      "rotation": 3
    },
    {
      "x": -2,
      "y": -9,
      "z": 2,
      "name": "Rock_Aqua_Brick_Smooth"
    },
    {
      "x": -2,
      "y": -8,
      "z": 2,
      "name": "Rock_Aqua_Brick_Smooth"
    },
    {
      "x": -2,
      "y": -7,
      "z": 2,
      "name": "Rock_Aqua_Brick_Smooth"
    },
    {
      "x": -2,
      "y": -6,
      "z": 2,
      "name": "Rock_Aqua_Brick_Smooth"
    },
    {
      "x": -2,
      "y": -5,
      "z": 2,
      "name": "Rock_Aqua_Brick_Smooth"
    },
    {
      "x": -2,
      "y": -4,
      "z": 2,
      "name": "Rock_Aqua_Brick_Smooth"
    },
    {
      "x": -2,
      "y": -3,
      "z": 2,
      "name": "Rock_Aqua_Brick_Smooth"
    },
    {
      "x": -2,
      "y": -2,
      "z": 2,
      "name": "Rock_Aqua_Brick_Smooth"
    },
    {
      "x": -2,
      "y": -1,
      "z": 2,
      "name": "Rock_Aqua_Brick_Smooth"
    },
    {
      "x": -2,
      "y": 0,
      "z": 2,
      "name": "Rock_Aqua_Brick_Smooth"
    },
    {
      "x": -2,
      "y": 1,
      "z": 2,
      "name": "Rock_Aqua_Brick_Smooth"
    },
    {
      "x": -2,
      "y": 2,
      "z": 2,
      "name": "Rock_Aqua_Brick_Smooth"
    },
    {
      "x": -2,
      "y": 3,
      "z": 2,
      "name": "Rock_Aqua_Brick_Smooth"
    },
    {
      "x": -2,
      "y": 4,
      "z": 2,
      "name": "Rock_Aqua_Brick_Smooth"
    },
    {
      "x": -2,
      "y": 5,
      "z": 2,
      "name": "Rock_Aqua_Brick_Smooth"
    },
    {
      "x": -2,
      "y": 6,
      "z": 2,
      "name": "Rock_Aqua_Brick_Smooth"
    },
    {
      "x": -2,
      "y": 7,
      "z": 2,
      "name": "Rock_Aqua_Brick_Smooth"
    },
    {
      "x": -2,
      "y": 8,
      "z": 2,
      "name": "Rock_Aqua_Brick_Smooth"
    },
    {
      "x": -2,
      "y": 9,
      "z": 2,
      "name": "Rock_Aqua_Brick_Smooth"
    },
    {
      "x": -2,
      "y": 10,
      "z": 2,
      "name": "Rock_Aqua_Brick_Smooth"
    },
    {
      "x": -2,
      "y": 11,
      "z": 2,
      "name": "Rock_Runic_Brick"
    },
    {
      "x": -2,
      "y": 12,
      "z": 2,
      "name": "Furniture_Ancient_Barrel"
    },
    {
      "x": -2,
      "y": 15,
      "z": 2,
      "name": "Rock_Runic_Blue_Brick_Half",
      "rotation": 8
    },
    {
      "x": -2,
      "y": 16,
      "z": 2,
      "name": "Rock_Runic_Blue_Brick"
    },
    {
      "x": -2,
      "y": 22,
      "z": 2,
      "name": "*Rock_Aqua_Cobble_Roof_Hollow_State_Definitions_Corner_Right"
    },
    {
      "x": -2,
      "y": -9,
      "z": 3,
      "name": "Rock_Aqua_Brick_Smooth"
    },
    {
      "x": -2,
      "y": -8,
      "z": 3,
      "name": "Rock_Aqua_Brick_Smooth"
    },
    {
      "x": -2,
      "y": -7,
      "z": 3,
      "name": "Rock_Aqua_Brick_Decorative"
    },
    {
      "x": -2,
      "y": -6,
      "z": 3,
      "name": "Rock_Aqua_Brick_Smooth"
    },
    {
      "x": -2,
      "y": -5,
      "z": 3,
      "name": "Rock_Aqua_Brick_Smooth"
    },
    {
      "x": -2,
      "y": -4,
      "z": 3,
      "name": "Rock_Aqua_Brick_Decorative"
    },
    {
      "x": -2,
      "y": -3,
      "z": 3,
      "name": "Rock_Aqua_Brick_Smooth"
    },
    {
      "x": -2,
      "y": -2,
      "z": 3,
      "name": "Rock_Aqua_Brick_Smooth"
    },
    {
      "x": -2,
      "y": -1,
      "z": 3,
      "name": "Rock_Aqua_Brick_Decorative"
    },
    {
      "x": -2,
      "y": 0,
      "z": 3,
      "name": "Rock_Aqua_Brick_Smooth"
    },
    {
      "x": -2,
      "y": 1,
      "z": 3,
      "name": "Rock_Aqua_Brick_Smooth"
    },
    {
      "x": -2,
      "y": 2,
      "z": 3,
      "name": "Rock_Aqua_Brick_Decorative"
    },
    {
      "x": -2,
      "y": 3,
      "z": 3,
      "name": "Rock_Aqua_Brick_Smooth"
    },
    {
      "x": -2,
      "y": 4,
      "z": 3,
      "name": "Rock_Aqua_Brick_Smooth"
    },
    {
      "x": -2,
      "y": 5,
      "z": 3,
      "name": "Rock_Aqua_Brick_Decorative"
    },
    {
      "x": -2,
      "y": 6,
      "z": 3,
      "name": "Rock_Aqua_Brick_Smooth"
    },
    {
      "x": -2,
      "y": 7,
      "z": 3,
      "name": "Rock_Aqua_Brick_Smooth"
    },
    {
      "x": -2,
      "y": 8,
      "z": 3,
      "name": "Rock_Aqua_Brick_Decorative"
    },
    {
      "x": -2,
      "y": 9,
      "z": 3,
      "name": "Rock_Aqua_Brick_Stairs"
    },
    {
      "x": -2,
      "y": 10,
      "z": 3,
      "name": "Rock_Aqua_Brick_Half",
      "rotation": 4
    },
    {
      "x": -2,
      "y": 11,
      "z": 3,
      "name": "Rock_Aqua_Brick_Half",
      "rotation": 4
    },
    {
      "x": -2,
      "y": 12,
      "z": 3,
      "name": "Rock_Aqua_Brick_Half",
      "rotation": 4
    },
    {
      "x": -2,
      "y": 13,
      "z": 3,
      "name": "Rock_Aqua_Brick_Half",
      "rotation": 4
    },
    {
      "x": -2,
      "y": 14,
      "z": 3,
      "name": "Rock_Aqua_Brick_Half",
      "rotation": 4
    },
    {
      "x": -2,
      "y": 15,
      "z": 3,
      "name": "Rock_Aqua_Brick_Half",
      "rotation": 4
    },
    {
      "x": -2,
      "y": 16,
      "z": 3,
      "name": "Rock_Aqua_Brick_Stairs",
      "rotation": 10
    },
    {
      "x": -2,
      "y": 17,
      "z": 3,
      "name": "Rock_Aqua_Brick_Pillar_Base"
    },
    {
      "x": -2,
      "y": 18,
      "z": 3,
      "name": "Rock_Aqua_Brick_Pillar_Middle"
    },
    {
      "x": -2,
      "y": 19,
      "z": 3,
      "name": "Rock_Aqua_Brick_Beam"
    },
    {
      "x": -2,
      "y": 20,
      "z": 3,
      "name": "Rock_Aqua_Brick_Pillar_Base",
      "rotation": 8
    },
    {
      "x": -2,
      "y": 21,
      "z": 3,
      "name": "Rock_Aqua_Cobble_Roof"
    },
    {
      "x": -2,
      "y": 20,
      "z": 4,
      "name": "Rock_Aqua_Cobble_Roof_Shallow",
      "filler": 992
    },
    {
      "x": -2,
      "y": 20,
      "z": 5,
      "name": "Rock_Aqua_Cobble_Roof_Shallow"
    },
    {
      "x": -1,
      "y": 20,
      "z": -5,
      "name": "Rock_Aqua_Cobble_Roof_Shallow",
      "rotation": 2
    },
    {
      "x": -1,
      "y": -9,
      "z": -4,
      "name": "Rock_Aqua_Brick_Smooth"
    },
    {
      "x": -1,
      "y": -8,
      "z": -4,
      "name": "Rock_Aqua_Brick_Smooth"
    },
    {
      "x": -1,
      "y": -7,
      "z": -4,
      "name": "Rock_Aqua_Brick_Decorative"
    },
    {
      "x": -1,
      "y": -6,
      "z": -4,
      "name": "Rock_Aqua_Brick_Smooth"
    },
    {
      "x": -1,
      "y": -5,
      "z": -4,
      "name": "Rock_Aqua_Brick_Smooth"
    },
    {
      "x": -1,
      "y": -4,
      "z": -4,
      "name": "Rock_Aqua_Brick_Decorative"
    },
    {
      "x": -1,
      "y": -3,
      "z": -4,
      "name": "Rock_Aqua_Brick_Smooth"
    },
    {
      "x": -1,
      "y": -2,
      "z": -4,
      "name": "Rock_Aqua_Brick_Smooth"
    },
    {
      "x": -1,
      "y": -1,
      "z": -4,
      "name": "Rock_Aqua_Brick_Decorative"
    },
    {
      "x": -1,
      "y": 0,
      "z": -4,
      "name": "Rock_Aqua_Brick_Smooth"
    },
    {
      "x": -1,
      "y": 1,
      "z": -4,
      "name": "Rock_Aqua_Brick_Smooth"
    },
    {
      "x": -1,
      "y": 2,
      "z": -4,
      "name": "Rock_Aqua_Brick_Decorative"
    },
    {
      "x": -1,
      "y": 3,
      "z": -4,
      "name": "Rock_Aqua_Brick_Smooth"
    },
    {
      "x": -1,
      "y": 4,
      "z": -4,
      "name": "Rock_Aqua_Brick_Smooth"
    },
    {
      "x": -1,
      "y": 5,
      "z": -4,
      "name": "Rock_Aqua_Brick_Decorative"
    },
    {
      "x": -1,
      "y": 6,
      "z": -4,
      "name": "Rock_Aqua_Brick_Smooth"
    },
    {
      "x": -1,
      "y": 7,
      "z": -4,
      "name": "Rock_Aqua_Brick_Smooth"
    },
    {
      "x": -1,
      "y": 8,
      "z": -4,
      "name": "Rock_Aqua_Brick_Stairs",
      "rotation": 2
    },
    {
      "x": -1,
      "y": 20,
      "z": -4,
      "name": "Rock_Aqua_Cobble_Roof_Shallow",
      "filler": 32,
      "rotation": 2
    },
    {
      "x": -1,
      "y": -9,
      "z": -3,
      "name": "Rock_Aqua_Brick_Smooth"
    },
    {
      "x": -1,
      "y": -8,
      "z": -3,
      "name": "Rock_Aqua_Brick_Smooth"
    },
    {
      "x": -1,
      "y": -7,
      "z": -3,
      "name": "Rock_Aqua_Brick_Smooth"
    },
    {
      "x": -1,
      "y": -6,
      "z": -3,
      "name": "Rock_Aqua_Brick_Smooth"
    },
    {
      "x": -1,
      "y": -5,
      "z": -3,
      "name": "Rock_Aqua_Brick_Smooth"
    },
    {
      "x": -1,
      "y": -4,
      "z": -3,
      "name": "Rock_Aqua_Brick_Smooth"
    },
    {
      "x": -1,
      "y": -3,
      "z": -3,
      "name": "Rock_Aqua_Brick_Smooth"
    },
    {
      "x": -1,
      "y": -2,
      "z": -3,
      "name": "Rock_Aqua_Brick_Smooth"
    },
    {
      "x": -1,
      "y": -1,
      "z": -3,
      "name": "Rock_Aqua_Brick_Smooth"
    },
    {
      "x": -1,
      "y": 0,
      "z": -3,
      "name": "Rock_Aqua_Brick_Smooth"
    },
    {
      "x": -1,
      "y": 1,
      "z": -3,
      "name": "Rock_Aqua_Brick_Smooth"
    },
    {
      "x": -1,
      "y": 2,
      "z": -3,
      "name": "Rock_Aqua_Brick_Smooth"
    },
    {
      "x": -1,
      "y": 3,
      "z": -3,
      "name": "Rock_Aqua_Brick_Smooth"
    },
    {
      "x": -1,
      "y": 4,
      "z": -3,
      "name": "Rock_Aqua_Brick_Smooth"
    },
    {
      "x": -1,
      "y": 5,
      "z": -3,
      "name": "Rock_Aqua_Brick_Smooth"
    },
    {
      "x": -1,
      "y": 6,
      "z": -3,
      "name": "Rock_Aqua_Brick_Smooth"
    },
    {
      "x": -1,
      "y": 7,
      "z": -3,
      "name": "Rock_Aqua_Brick_Smooth"
    },
    {
      "x": -1,
      "y": 8,
      "z": -3,
      "name": "Rock_Aqua_Brick_Decorative",
      "rotation": 3
    },
    {
      "x": -1,
      "y": 9,
      "z": -3,
      "name": "Rock_Aqua_Brick_Smooth",
      "rotation": 3
    },
    {
      "x": -1,
      "y": 10,
      "z": -3,
      "name": "Rock_Aqua_Brick_Smooth",
      "rotation": 3
    },
    {
      "x": -1,
      "y": 11,
      "z": -3,
      "name": "Rock_Aqua_Brick_Decorative",
      "rotation": 3
    },
    {
      "x": -1,
      "y": 12,
      "z": -3,
      "name": "Rock_Aqua_Brick_Smooth",
      "support": 15,
      "rotation": 3
    },
    {
      "x": -1,
      "y": 13,
      "z": -3,
      "name": "Rock_Aqua_Brick_Smooth",
      "rotation": 3
    },
    {
      "x": -1,
      "y": 14,
      "z": -3,
      "name": "Rock_Aqua_Brick_Decorative",
      "rotation": 3
    },
    {
      "x": -1,
      "y": 15,
      "z": -3,
      "name": "Rock_Aqua_Brick_Smooth",
      "rotation": 3
    },
    {
      "x": -1,
      "y": 16,
      "z": -3,
      "name": "Rock_Aqua_Brick_Smooth",
      "rotation": 3
    },
    {
      "x": -1,
      "y": 17,
      "z": -3,
      "name": "Rock_Aqua_Brick_Wall"
    },
    {
      "x": -1,
      "y": 20,
      "z": -3,
      "name": "Rock_Aqua_Brick_Wall"
    },
    {
      "x": -1,
      "y": 21,
      "z": -3,
      "name": "Rock_Aqua_Cobble_Roof",
      "rotation": 2
    },
    {
      "x": -1,
      "y": -9,
      "z": -2,
      "name": "Rock_Aqua_Brick_Smooth"
    },
    {
      "x": -1,
      "y": -8,
      "z": -2,
      "name": "Rock_Aqua_Brick_Smooth"
    },
    {
      "x": -1,
      "y": -7,
      "z": -2,
      "name": "Rock_Aqua_Brick_Smooth"
    },
    {
      "x": -1,
      "y": -6,
      "z": -2,
      "name": "Rock_Aqua_Brick_Smooth"
    },
    {
      "x": -1,
      "y": -5,
      "z": -2,
      "name": "Rock_Aqua_Brick_Smooth"
    },
    {
      "x": -1,
      "y": -4,
      "z": -2,
      "name": "Rock_Aqua_Brick_Smooth"
    },
    {
      "x": -1,
      "y": -3,
      "z": -2,
      "name": "Rock_Aqua_Brick_Smooth"
    },
    {
      "x": -1,
      "y": -2,
      "z": -2,
      "name": "Rock_Aqua_Brick_Smooth"
    },
    {
      "x": -1,
      "y": -1,
      "z": -2,
      "name": "Rock_Aqua_Brick_Smooth"
    },
    {
      "x": -1,
      "y": 0,
      "z": -2,
      "name": "Rock_Aqua_Brick_Smooth"
    },
    {
      "x": -1,
      "y": 1,
      "z": -2,
      "name": "Rock_Aqua_Brick_Smooth"
    },
    {
      "x": -1,
      "y": 2,
      "z": -2,
      "name": "Rock_Aqua_Brick_Smooth"
    },
    {
      "x": -1,
      "y": 3,
      "z": -2,
      "name": "Rock_Aqua_Brick_Smooth"
    },
    {
      "x": -1,
      "y": 4,
      "z": -2,
      "name": "Rock_Aqua_Brick_Smooth"
    },
    {
      "x": -1,
      "y": 5,
      "z": -2,
      "name": "Rock_Aqua_Brick_Smooth"
    },
    {
      "x": -1,
      "y": 6,
      "z": -2,
      "name": "Rock_Aqua_Brick_Smooth"
    },
    {
      "x": -1,
      "y": 7,
      "z": -2,
      "name": "Rock_Aqua_Brick_Smooth"
    },
    {
      "x": -1,
      "y": 8,
      "z": -2,
      "name": "Rock_Aqua_Brick_Smooth"
    },
    {
      "x": -1,
      "y": 9,
      "z": -2,
      "name": "Rock_Aqua_Brick_Smooth"
    },
    {
      "x": -1,
      "y": 10,
      "z": -2,
      "name": "Rock_Aqua_Brick_Smooth"
    },
    {
      "x": -1,
      "y": 11,
      "z": -2,
      "name": "Rock_Runic_Brick"
    },
    {
      "x": -1,
      "y": 12,
      "z": -2,
      "name": "Rock_Aqua_Brick_Smooth_Half",
      "rotation": 4
    },
    {
      "x": -1,
      "y": 15,
      "z": -2,
      "name": "Rock_Aqua_Brick_Smooth_Half",
      "rotation": 4
    },
    {
      "x": -1,
      "y": 16,
      "z": -2,
      "name": "Rock_Runic_Blue_Brick"
    },
    {
      "x": -1,
      "y": 22,
      "z": -2,
      "name": "Rock_Aqua_Cobble_Roof_Hollow",
      "rotation": 2
    },
    {
      "x": -1,
      "y": -9,
      "z": -1,
      "name": "Rock_Aqua_Brick_Smooth"
    },
    {
      "x": -1,
      "y": -8,
      "z": -1,
      "name": "Rock_Aqua_Brick_Smooth"
    },
    {
      "x": -1,
      "y": -7,
      "z": -1,
      "name": "Rock_Aqua_Brick_Smooth"
    },
    {
      "x": -1,
      "y": -6,
      "z": -1,
      "name": "Rock_Aqua_Brick_Smooth"
    },
    {
      "x": -1,
      "y": -5,
      "z": -1,
      "name": "Rock_Aqua_Brick_Smooth"
    },
    {
      "x": -1,
      "y": -4,
      "z": -1,
      "name": "Rock_Aqua_Brick_Smooth"
    },
    {
      "x": -1,
      "y": -3,
      "z": -1,
      "name": "Rock_Aqua_Brick_Smooth"
    },
    {
      "x": -1,
      "y": -2,
      "z": -1,
      "name": "Rock_Aqua_Brick_Smooth"
    },
    {
      "x": -1,
      "y": -1,
      "z": -1,
      "name": "Rock_Aqua_Brick_Smooth"
    },
    {
      "x": -1,
      "y": 0,
      "z": -1,
      "name": "Rock_Aqua_Brick_Smooth"
    },
    {
      "x": -1,
      "y": 1,
      "z": -1,
      "name": "Rock_Aqua_Brick_Smooth"
    },
    {
      "x": -1,
      "y": 2,
      "z": -1,
      "name": "Rock_Aqua_Brick_Smooth"
    },
    {
      "x": -1,
      "y": 3,
      "z": -1,
      "name": "Rock_Aqua_Brick_Smooth"
    },
    {
      "x": -1,
      "y": 4,
      "z": -1,
      "name": "Rock_Aqua_Brick_Smooth"
    },
    {
      "x": -1,
      "y": 5,
      "z": -1,
      "name": "Rock_Aqua_Brick_Smooth"
    },
    {
      "x": -1,
      "y": 6,
      "z": -1,
      "name": "Rock_Aqua_Brick_Smooth"
    },
    {
      "x": -1,
      "y": 7,
      "z": -1,
      "name": "Rock_Aqua_Brick_Smooth"
    },
    {
      "x": -1,
      "y": 8,
      "z": -1,
      "name": "Rock_Aqua_Brick_Smooth"
    },
    {
      "x": -1,
      "y": 9,
      "z": -1,
      "name": "Rock_Aqua_Brick_Smooth"
    },
    {
      "x": -1,
      "y": 10,
      "z": -1,
      "name": "Rock_Aqua_Brick_Smooth"
    },
    {
      "x": -1,
      "y": 11,
      "z": -1,
      "name": "Rock_Runic_Brick_Ornate"
    },
    {
      "x": -1,
      "y": 16,
      "z": -1,
      "name": "Rock_Runic_Blue_Brick"
    },
    {
      "x": -1,
      "y": 23,
      "z": -1,
      "name": "*Rock_Aqua_Cobble_Roof_Steep_State_Definitions_Corner_Right",
      "rotation": 3
    },
    {
      "x": -1,
      "y": 24,
      "z": -1,
      "name": "*Rock_Aqua_Cobble_Roof_Steep_State_Definitions_Corner_Right",
      "filler": 1024,
      "rotation": 3
    },
    {
      "x": -1,
      "y": -9,
      "z": 0,
      "name": "Rock_Aqua_Brick_Smooth"
    },
    {
      "x": -1,
      "y": -8,
      "z": 0,
      "name": "Rock_Aqua_Brick_Smooth"
    },
    {
      "x": -1,
      "y": -7,
      "z": 0,
      "name": "Rock_Aqua_Brick_Smooth"
    },
    {
      "x": -1,
      "y": -6,
      "z": 0,
      "name": "Rock_Aqua_Brick_Smooth"
    },
    {
      "x": -1,
      "y": -5,
      "z": 0,
      "name": "Rock_Aqua_Brick_Smooth"
    },
    {
      "x": -1,
      "y": -4,
      "z": 0,
      "name": "Rock_Aqua_Brick_Smooth"
    },
    {
      "x": -1,
      "y": -3,
      "z": 0,
      "name": "Rock_Aqua_Brick_Smooth"
    },
    {
      "x": -1,
      "y": -2,
      "z": 0,
      "name": "Rock_Aqua_Brick_Smooth"
    },
    {
      "x": -1,
      "y": -1,
      "z": 0,
      "name": "Rock_Aqua_Brick_Smooth"
    },
    {
      "x": -1,
      "y": 0,
      "z": 0,
      "name": "Rock_Aqua_Brick_Smooth"
    },
    {
      "x": -1,
      "y": 1,
      "z": 0,
      "name": "Rock_Aqua_Brick_Smooth"
    },
    {
      "x": -1,
      "y": 2,
      "z": 0,
      "name": "Rock_Aqua_Brick_Smooth"
    },
    {
      "x": -1,
      "y": 3,
      "z": 0,
      "name": "Rock_Aqua_Brick_Smooth"
    },
    {
      "x": -1,
      "y": 4,
      "z": 0,
      "name": "Rock_Aqua_Brick_Smooth"
    },
    {
      "x": -1,
      "y": 5,
      "z": 0,
      "name": "Rock_Aqua_Brick_Smooth"
    },
    {
      "x": -1,
      "y": 6,
      "z": 0,
      "name": "Rock_Aqua_Brick_Smooth"
    },
    {
      "x": -1,
      "y": 7,
      "z": 0,
      "name": "Rock_Aqua_Brick_Smooth"
    },
    {
      "x": -1,
      "y": 8,
      "z": 0,
      "name": "Rock_Aqua_Brick_Smooth"
    },
    {
      "x": -1,
      "y": 9,
      "z": 0,
      "name": "Rock_Aqua_Brick_Smooth"
    },
    {
      "x": -1,
      "y": 10,
      "z": 0,
      "name": "Rock_Aqua_Brick_Smooth"
    },
    {
      "x": -1,
      "y": 11,
      "z": 0,
      "name": "Rock_Runic_Brick_Ornate"
    },
    {
      "x": -1,
      "y": 16,
      "z": 0,
      "name": "Rock_Runic_Blue_Brick"
    },
    {
      "x": -1,
      "y": 23,
      "z": 0,
      "name": "Rock_Aqua_Cobble_Roof_Steep",
      "rotation": 3
    },
    {
      "x": -1,
      "y": 24,
      "z": 0,
      "name": "Rock_Aqua_Cobble_Roof_Steep",
      "filler": 1024,
      "rotation": 3
    },
    {
      "x": -1,
      "y": -9,
      "z": 1,
      "name": "Rock_Aqua_Brick_Smooth"
    },
    {
      "x": -1,
      "y": -8,
      "z": 1,
      "name": "Rock_Aqua_Brick_Smooth"
    },
    {
      "x": -1,
      "y": -7,
      "z": 1,
      "name": "Rock_Aqua_Brick_Smooth"
    },
    {
      "x": -1,
      "y": -6,
      "z": 1,
      "name": "Rock_Aqua_Brick_Smooth"
    },
    {
      "x": -1,
      "y": -5,
      "z": 1,
      "name": "Rock_Aqua_Brick_Smooth"
    },
    {
      "x": -1,
      "y": -4,
      "z": 1,
      "name": "Rock_Aqua_Brick_Smooth"
    },
    {
      "x": -1,
      "y": -3,
      "z": 1,
      "name": "Rock_Aqua_Brick_Smooth"
    },
    {
      "x": -1,
      "y": -2,
      "z": 1,
      "name": "Rock_Aqua_Brick_Smooth"
    },
    {
      "x": -1,
      "y": -1,
      "z": 1,
      "name": "Rock_Aqua_Brick_Smooth"
    },
    {
      "x": -1,
      "y": 0,
      "z": 1,
      "name": "Rock_Aqua_Brick_Smooth"
    },
    {
      "x": -1,
      "y": 1,
      "z": 1,
      "name": "Rock_Aqua_Brick_Smooth"
    },
    {
      "x": -1,
      "y": 2,
      "z": 1,
      "name": "Rock_Aqua_Brick_Smooth"
    },
    {
      "x": -1,
      "y": 3,
      "z": 1,
      "name": "Rock_Aqua_Brick_Smooth"
    },
    {
      "x": -1,
      "y": 4,
      "z": 1,
      "name": "Rock_Aqua_Brick_Smooth"
    },
    {
      "x": -1,
      "y": 5,
      "z": 1,
      "name": "Rock_Aqua_Brick_Smooth"
    },
    {
      "x": -1,
      "y": 6,
      "z": 1,
      "name": "Rock_Aqua_Brick_Smooth"
    },
    {
      "x": -1,
      "y": 7,
      "z": 1,
      "name": "Rock_Aqua_Brick_Smooth"
    },
    {
      "x": -1,
      "y": 8,
      "z": 1,
      "name": "Rock_Aqua_Brick_Smooth"
    },
    {
      "x": -1,
      "y": 9,
      "z": 1,
      "name": "Rock_Aqua_Brick_Smooth"
    },
    {
      "x": -1,
      "y": 10,
      "z": 1,
      "name": "Rock_Aqua_Brick_Smooth"
    },
    {
      "x": -1,
      "y": 11,
      "z": 1,
      "name": "Rock_Runic_Brick"
    },
    {
      "x": -1,
      "y": 16,
      "z": 1,
      "name": "Rock_Runic_Blue_Brick"
    },
    {
      "x": -1,
      "y": 23,
      "z": 1,
      "name": "*Rock_Aqua_Cobble_Roof_Steep_State_Definitions_Corner_Left",
      "rotation": 3
    },
    {
      "x": -1,
      "y": 24,
      "z": 1,
      "name": "*Rock_Aqua_Cobble_Roof_Steep_State_Definitions_Corner_Left",
      "filler": 1024,
      "rotation": 3
    },
    {
      "x": -1,
      "y": -9,
      "z": 2,
      "name": "Rock_Aqua_Brick_Smooth"
    },
    {
      "x": -1,
      "y": -8,
      "z": 2,
      "name": "Rock_Aqua_Brick_Smooth"
    },
    {
      "x": -1,
      "y": -7,
      "z": 2,
      "name": "Rock_Aqua_Brick_Smooth"
    },
    {
      "x": -1,
      "y": -6,
      "z": 2,
      "name": "Rock_Aqua_Brick_Smooth"
    },
    {
      "x": -1,
      "y": -5,
      "z": 2,
      "name": "Rock_Aqua_Brick_Smooth"
    },
    {
      "x": -1,
      "y": -4,
      "z": 2,
      "name": "Rock_Aqua_Brick_Smooth"
    },
    {
      "x": -1,
      "y": -3,
      "z": 2,
      "name": "Rock_Aqua_Brick_Smooth"
    },
    {
      "x": -1,
      "y": -2,
      "z": 2,
      "name": "Rock_Aqua_Brick_Smooth"
    },
    {
      "x": -1,
      "y": -1,
      "z": 2,
      "name": "Rock_Aqua_Brick_Smooth"
    },
    {
      "x": -1,
      "y": 0,
      "z": 2,
      "name": "Rock_Aqua_Brick_Smooth"
    },
    {
      "x": -1,
      "y": 1,
      "z": 2,
      "name": "Rock_Aqua_Brick_Smooth"
    },
    {
      "x": -1,
      "y": 2,
      "z": 2,
      "name": "Rock_Aqua_Brick_Smooth"
    },
    {
      "x": -1,
      "y": 3,
      "z": 2,
      "name": "Rock_Aqua_Brick_Smooth"
    },
    {
      "x": -1,
      "y": 4,
      "z": 2,
      "name": "Rock_Aqua_Brick_Smooth"
    },
    {
      "x": -1,
      "y": 5,
      "z": 2,
      "name": "Rock_Aqua_Brick_Smooth"
    },
    {
      "x": -1,
      "y": 6,
      "z": 2,
      "name": "Rock_Aqua_Brick_Smooth"
    },
    {
      "x": -1,
      "y": 7,
      "z": 2,
      "name": "Rock_Aqua_Brick_Smooth"
    },
    {
      "x": -1,
      "y": 8,
      "z": 2,
      "name": "Rock_Aqua_Brick_Smooth"
    },
    {
      "x": -1,
      "y": 9,
      "z": 2,
      "name": "Rock_Aqua_Brick_Smooth"
    },
    {
      "x": -1,
      "y": 10,
      "z": 2,
      "name": "Rock_Aqua_Brick_Smooth"
    },
    {
      "x": -1,
      "y": 11,
      "z": 2,
      "name": "Rock_Runic_Brick"
    },
    {
      "x": -1,
      "y": 12,
      "z": 2,
      "name": "Rock_Aqua_Brick_Smooth_Half",
      "rotation": 6
    },
    {
      "x": -1,
      "y": 15,
      "z": 2,
      "name": "Rock_Aqua_Brick_Smooth_Half",
      "rotation": 6
    },
    {
      "x": -1,
      "y": 16,
      "z": 2,
      "name": "Rock_Runic_Blue_Brick"
    },
    {
      "x": -1,
      "y": 22,
      "z": 2,
      "name": "Rock_Aqua_Cobble_Roof_Hollow"
    },
    {
      "x": -1,
      "y": -9,
      "z": 3,
      "name": "Rock_Aqua_Brick_Smooth"
    },
    {
      "x": -1,
      "y": -8,
      "z": 3,
      "name": "Rock_Aqua_Brick_Smooth"
    },
    {
      "x": -1,
      "y": -7,
      "z": 3,
      "name": "Rock_Aqua_Brick_Smooth"
    },
    {
      "x": -1,
      "y": -6,
      "z": 3,
      "name": "Rock_Aqua_Brick_Smooth"
    },
    {
      "x": -1,
      "y": -5,
      "z": 3,
      "name": "Rock_Aqua_Brick_Smooth"
    },
    {
      "x": -1,
      "y": -4,
      "z": 3,
      "name": "Rock_Aqua_Brick_Smooth"
    },
    {
      "x": -1,
      "y": -3,
      "z": 3,
      "name": "Rock_Aqua_Brick_Smooth"
    },
    {
      "x": -1,
      "y": -2,
      "z": 3,
      "name": "Rock_Aqua_Brick_Smooth"
    },
    {
      "x": -1,
      "y": -1,
      "z": 3,
      "name": "Rock_Aqua_Brick_Smooth"
    },
    {
      "x": -1,
      "y": 0,
      "z": 3,
      "name": "Rock_Aqua_Brick_Smooth"
    },
    {
      "x": -1,
      "y": 1,
      "z": 3,
      "name": "Rock_Aqua_Brick_Smooth"
    },
    {
      "x": -1,
      "y": 2,
      "z": 3,
      "name": "Rock_Aqua_Brick_Smooth"
    },
    {
      "x": -1,
      "y": 3,
      "z": 3,
      "name": "Rock_Aqua_Brick_Smooth"
    },
    {
      "x": -1,
      "y": 4,
      "z": 3,
      "name": "Rock_Aqua_Brick_Smooth"
    },
    {
      "x": -1,
      "y": 5,
      "z": 3,
      "name": "Rock_Aqua_Brick_Smooth"
    },
    {
      "x": -1,
      "y": 6,
      "z": 3,
      "name": "Rock_Aqua_Brick_Smooth"
    },
    {
      "x": -1,
      "y": 7,
      "z": 3,
      "name": "Rock_Aqua_Brick_Smooth"
    },
    {
      "x": -1,
      "y": 8,
      "z": 3,
      "name": "Rock_Aqua_Brick_Decorative"
    },
    {
      "x": -1,
      "y": 9,
      "z": 3,
      "name": "Rock_Aqua_Brick_Smooth"
    },
    {
      "x": -1,
      "y": 10,
      "z": 3,
      "name": "Rock_Aqua_Brick_Smooth"
    },
    {
      "x": -1,
      "y": 11,
      "z": 3,
      "name": "Rock_Aqua_Brick_Decorative"
    },
    {
      "x": -1,
      "y": 12,
      "z": 3,
      "name": "Rock_Aqua_Brick_Smooth"
    },
    {
      "x": -1,
      "y": 13,
      "z": 3,
      "name": "Rock_Aqua_Brick_Smooth"
    },
    {
      "x": -1,
      "y": 14,
      "z": 3,
      "name": "Rock_Aqua_Brick_Decorative"
    },
    {
      "x": -1,
      "y": 15,
      "z": 3,
      "name": "Rock_Aqua_Brick_Smooth"
    },
    {
      "x": -1,
      "y": 16,
      "z": 3,
      "name": "Rock_Aqua_Brick_Smooth"
    },
    {
      "x": -1,
      "y": 20,
      "z": 3,
      "name": "Rock_Aqua_Brick_Wall"
    },
    {
      "x": -1,
      "y": 21,
      "z": 3,
      "name": "Rock_Aqua_Cobble_Roof"
    },
    {
      "x": -1,
      "y": -9,
      "z": 4,
      "name": "Rock_Aqua_Brick_Smooth"
    },
    {
      "x": -1,
      "y": -8,
      "z": 4,
      "name": "Rock_Aqua_Brick_Smooth"
    },
    {
      "x": -1,
      "y": -7,
      "z": 4,
      "name": "Rock_Aqua_Brick_Decorative"
    },
    {
      "x": -1,
      "y": -6,
      "z": 4,
      "name": "Rock_Aqua_Brick_Smooth"
    },
    {
      "x": -1,
      "y": -5,
      "z": 4,
      "name": "Rock_Aqua_Brick_Smooth"
    },
    {
      "x": -1,
      "y": -4,
      "z": 4,
      "name": "Rock_Aqua_Brick_Decorative"
    },
    {
      "x": -1,
      "y": -3,
      "z": 4,
      "name": "Rock_Aqua_Brick_Smooth"
    },
    {
      "x": -1,
      "y": -2,
      "z": 4,
      "name": "Rock_Aqua_Brick_Smooth"
    },
    {
      "x": -1,
      "y": -1,
      "z": 4,
      "name": "Rock_Aqua_Brick_Decorative"
    },
    {
      "x": -1,
      "y": 0,
      "z": 4,
      "name": "Rock_Aqua_Brick_Smooth"
    },
    {
      "x": -1,
      "y": 1,
      "z": 4,
      "name": "Rock_Aqua_Brick_Smooth"
    },
    {
      "x": -1,
      "y": 2,
      "z": 4,
      "name": "Rock_Aqua_Brick_Decorative"
    },
    {
      "x": -1,
      "y": 3,
      "z": 4,
      "name": "Rock_Aqua_Brick_Smooth"
    },
    {
      "x": -1,
      "y": 4,
      "z": 4,
      "name": "Rock_Aqua_Brick_Smooth"
    },
    {
      "x": -1,
      "y": 5,
      "z": 4,
      "name": "Rock_Aqua_Brick_Decorative"
    },
    {
      "x": -1,
      "y": 6,
      "z": 4,
      "name": "Rock_Aqua_Brick_Smooth"
    },
    {
      "x": -1,
      "y": 7,
      "z": 4,
      "name": "Rock_Aqua_Brick_Smooth"
    },
    {
      "x": -1,
      "y": 8,
      "z": 4,
      "name": "Rock_Aqua_Brick_Stairs"
    },
    {
      "x": -1,
      "y": 20,
      "z": 4,
      "name": "Rock_Aqua_Cobble_Roof_Shallow",
      "filler": 992
    },
    {
      "x": -1,
      "y": 20,
      "z": 5,
      "name": "Rock_Aqua_Cobble_Roof_Shallow"
    },
    {
      "x": 0,
      "y": 20,
      "z": -5,
      "name": "Rock_Aqua_Cobble_Roof_Shallow",
      "rotation": 2
    },
    {
      "x": 0,
      "y": 20,
      "z": -4,
      "name": "Rock_Aqua_Cobble_Roof_Shallow",
      "filler": 32,
      "rotation": 2
    },
    {
      "x": 0,
      "y": -9,
      "z": -3,
      "name": "Rock_Aqua_Brick_Smooth"
    },
    {
      "x": 0,
      "y": -8,
      "z": -3,
      "name": "Rock_Aqua_Brick_Smooth"
    },
    {
      "x": 0,
      "y": -7,
      "z": -3,
      "name": "Rock_Aqua_Brick_Decorative"
    },
    {
      "x": 0,
      "y": -6,
      "z": -3,
      "name": "Rock_Aqua_Brick_Smooth"
    },
    {
      "x": 0,
      "y": -5,
      "z": -3,
      "name": "Rock_Aqua_Brick_Smooth"
    },
    {
      "x": 0,
      "y": -4,
      "z": -3,
      "name": "Rock_Aqua_Brick_Decorative"
    },
    {
      "x": 0,
      "y": -3,
      "z": -3,
      "name": "Rock_Aqua_Brick_Smooth"
    },
    {
      "x": 0,
      "y": -2,
      "z": -3,
      "name": "Rock_Aqua_Brick_Smooth"
    },
    {
      "x": 0,
      "y": -1,
      "z": -3,
      "name": "Rock_Aqua_Brick_Decorative"
    },
    {
      "x": 0,
      "y": 0,
      "z": -3,
      "name": "Rock_Aqua_Brick_Smooth"
    },
    {
      "x": 0,
      "y": 1,
      "z": -3,
      "name": "Rock_Aqua_Brick_Smooth"
    },
    {
      "x": 0,
      "y": 2,
      "z": -3,
      "name": "Rock_Aqua_Brick_Decorative"
    },
    {
      "x": 0,
      "y": 3,
      "z": -3,
      "name": "Rock_Aqua_Brick_Smooth"
    },
    {
      "x": 0,
      "y": 4,
      "z": -3,
      "name": "Rock_Aqua_Brick_Smooth"
    },
    {
      "x": 0,
      "y": 5,
      "z": -3,
      "name": "Rock_Aqua_Brick_Decorative"
    },
    {
      "x": 0,
      "y": 6,
      "z": -3,
      "name": "Rock_Aqua_Brick_Smooth"
    },
    {
      "x": 0,
      "y": 7,
      "z": -3,
      "name": "Rock_Aqua_Brick_Smooth"
    },
    {
      "x": 0,
      "y": 8,
      "z": -3,
      "name": "Rock_Aqua_Brick_Decorative"
    },
    {
      "x": 0,
      "y": 9,
      "z": -3,
      "name": "Rock_Aqua_Brick_Stairs",
      "rotation": 2
    },
    {
      "x": 0,
      "y": 10,
      "z": -3,
      "name": "Rock_Aqua_Brick_Half",
      "rotation": 6
    },
    {
      "x": 0,
      "y": 11,
      "z": -3,
      "name": "Rock_Aqua_Brick_Half",
      "support": 15,
      "rotation": 6
    },
    {
      "x": 0,
      "y": 12,
      "z": -3,
      "name": "Rock_Aqua_Brick_Half",
      "rotation": 6
    },
    {
      "x": 0,
      "y": 13,
      "z": -3,
      "name": "Rock_Aqua_Brick_Half",
      "rotation": 6
    },
    {
      "x": 0,
      "y": 14,
      "z": -3,
      "name": "Rock_Aqua_Brick_Half",
      "rotation": 6
    },
    {
      "x": 0,
      "y": 15,
      "z": -3,
      "name": "Rock_Aqua_Brick_Half",
      "rotation": 6
    },
    {
      "x": 0,
      "y": 16,
      "z": -3,
      "name": "Rock_Aqua_Brick_Stairs",
      "rotation": 8
    },
    {
      "x": 0,
      "y": 17,
      "z": -3,
      "name": "Rock_Aqua_Brick_Wall"
    },
    {
      "x": 0,
      "y": 20,
      "z": -3,
      "name": "Rock_Aqua_Brick_Pillar_Base",
      "rotation": 8
    },
    {
      "x": 0,
      "y": 21,
      "z": -3,
      "name": "Rock_Aqua_Cobble_Roof",
      "rotation": 2
    },
    {
      "x": 0,
      "y": -9,
      "z": -2,
      "name": "Rock_Aqua_Brick_Smooth"
    },
    {
      "x": 0,
      "y": -8,
      "z": -2,
      "name": "Rock_Aqua_Brick_Smooth"
    },
    {
      "x": 0,
      "y": -7,
      "z": -2,
      "name": "Rock_Aqua_Brick_Smooth"
    },
    {
      "x": 0,
      "y": -6,
      "z": -2,
      "name": "Rock_Aqua_Brick_Smooth"
    },
    {
      "x": 0,
      "y": -5,
      "z": -2,
      "name": "Rock_Aqua_Brick_Smooth"
    },
    {
      "x": 0,
      "y": -4,
      "z": -2,
      "name": "Rock_Aqua_Brick_Smooth"
    },
    {
      "x": 0,
      "y": -3,
      "z": -2,
      "name": "Rock_Aqua_Brick_Smooth"
    },
    {
      "x": 0,
      "y": -2,
      "z": -2,
      "name": "Rock_Aqua_Brick_Smooth"
    },
    {
      "x": 0,
      "y": -1,
      "z": -2,
      "name": "Rock_Aqua_Brick_Smooth"
    },
    {
      "x": 0,
      "y": 0,
      "z": -2,
      "name": "Rock_Aqua_Brick_Smooth"
    },
    {
      "x": 0,
      "y": 1,
      "z": -2,
      "name": "Rock_Aqua_Brick_Smooth"
    },
    {
      "x": 0,
      "y": 2,
      "z": -2,
      "name": "Rock_Aqua_Brick_Smooth"
    },
    {
      "x": 0,
      "y": 3,
      "z": -2,
      "name": "Rock_Aqua_Brick_Smooth"
    },
    {
      "x": 0,
      "y": 4,
      "z": -2,
      "name": "Rock_Aqua_Brick_Smooth"
    },
    {
      "x": 0,
      "y": 5,
      "z": -2,
      "name": "Rock_Aqua_Brick_Smooth"
    },
    {
      "x": 0,
      "y": 6,
      "z": -2,
      "name": "Rock_Aqua_Brick_Smooth"
    },
    {
      "x": 0,
      "y": 7,
      "z": -2,
      "name": "Rock_Aqua_Brick_Smooth"
    },
    {
      "x": 0,
      "y": 8,
      "z": -2,
      "name": "Rock_Aqua_Brick_Smooth"
    },
    {
      "x": 0,
      "y": 9,
      "z": -2,
      "name": "Rock_Aqua_Brick_Smooth"
    },
    {
      "x": 0,
      "y": 10,
      "z": -2,
      "name": "Rock_Aqua_Brick_Smooth"
    },
    {
      "x": 0,
      "y": 11,
      "z": -2,
      "name": "Rock_Runic_Brick"
    },
    {
      "x": 0,
      "y": 16,
      "z": -2,
      "name": "Rock_Runic_Blue_Brick"
    },
    {
      "x": 0,
      "y": 17,
      "z": -2,
      "name": "Cloth_Roof_Blue_Flat"
    },
    {
      "x": 0,
      "y": 22,
      "z": -2,
      "name": "Rock_Aqua_Cobble_Roof_Hollow",
      "rotation": 2
    },
    {
      "x": 0,
      "y": -9,
      "z": -1,
      "name": "Rock_Aqua_Brick_Smooth"
    },
    {
      "x": 0,
      "y": -8,
      "z": -1,
      "name": "Rock_Aqua_Brick_Smooth"
    },
    {
      "x": 0,
      "y": -7,
      "z": -1,
      "name": "Rock_Aqua_Brick_Smooth"
    },
    {
      "x": 0,
      "y": -6,
      "z": -1,
      "name": "Rock_Aqua_Brick_Smooth"
    },
    {
      "x": 0,
      "y": -5,
      "z": -1,
      "name": "Rock_Aqua_Brick_Smooth"
    },
    {
      "x": 0,
      "y": -4,
      "z": -1,
      "name": "Rock_Aqua_Brick_Smooth"
    },
    {
      "x": 0,
      "y": -3,
      "z": -1,
      "name": "Rock_Aqua_Brick_Smooth"
    },
    {
      "x": 0,
      "y": -2,
      "z": -1,
      "name": "Rock_Aqua_Brick_Smooth"
    },
    {
      "x": 0,
      "y": -1,
      "z": -1,
      "name": "Rock_Aqua_Brick_Smooth"
    },
    {
      "x": 0,
      "y": 0,
      "z": -1,
      "name": "Rock_Aqua_Brick_Smooth"
    },
    {
      "x": 0,
      "y": 1,
      "z": -1,
      "name": "Rock_Aqua_Brick_Smooth"
    },
    {
      "x": 0,
      "y": 2,
      "z": -1,
      "name": "Rock_Aqua_Brick_Smooth"
    },
    {
      "x": 0,
      "y": 3,
      "z": -1,
      "name": "Rock_Aqua_Brick_Smooth"
    },
    {
      "x": 0,
      "y": 4,
      "z": -1,
      "name": "Rock_Aqua_Brick_Smooth"
    },
    {
      "x": 0,
      "y": 5,
      "z": -1,
      "name": "Rock_Aqua_Brick_Smooth"
    },
    {
      "x": 0,
      "y": 6,
      "z": -1,
      "name": "Rock_Aqua_Brick_Smooth"
    },
    {
      "x": 0,
      "y": 7,
      "z": -1,
      "name": "Rock_Aqua_Brick_Smooth"
    },
    {
      "x": 0,
      "y": 8,
      "z": -1,
      "name": "Rock_Aqua_Brick_Smooth"
    },
    {
      "x": 0,
      "y": 9,
      "z": -1,
      "name": "Rock_Aqua_Brick_Smooth"
    },
    {
      "x": 0,
      "y": 10,
      "z": -1,
      "name": "Rock_Aqua_Brick_Smooth"
    },
    {
      "x": 0,
      "y": 11,
      "z": -1,
      "name": "Rock_Runic_Brick"
    },
    {
      "x": 0,
      "y": 12,
      "z": -1,
      "name": "Furniture_Temple_Light_Ladder"
    },
    {
      "x": 0,
      "y": 13,
      "z": -1,
      "name": "Furniture_Temple_Light_Ladder"
    },
    {
      "x": 0,
      "y": 14,
      "z": -1,
      "name": "Furniture_Temple_Light_Ladder"
    },
    {
      "x": 0,
      "y": 15,
      "z": -1,
      "name": "Furniture_Temple_Light_Ladder"
    },
    {
      "x": 0,
      "y": 16,
      "z": -1,
      "name": "Furniture_Temple_Light_Ladder"
    },
    {
      "x": 0,
      "y": 23,
      "z": -1,
      "name": "Rock_Aqua_Cobble_Roof_Steep",
      "rotation": 2
    },
    {
      "x": 0,
      "y": 24,
      "z": -1,
      "name": "Rock_Aqua_Cobble_Roof_Steep",
      "filler": 1024,
      "rotation": 2
    },
    {
      "x": 0,
      "y": -9,
      "z": 0,
      "name": "Rock_Aqua_Brick_Smooth"
    },
    {
      "x": 0,
      "y": -8,
      "z": 0,
      "name": "Rock_Aqua_Brick_Smooth"
    },
    {
      "x": 0,
      "y": -7,
      "z": 0,
      "name": "Rock_Aqua_Brick_Smooth"
    },
    {
      "x": 0,
      "y": -6,
      "z": 0,
      "name": "Rock_Aqua_Brick_Smooth"
    },
    {
      "x": 0,
      "y": -5,
      "z": 0,
      "name": "Rock_Aqua_Brick_Smooth"
    },
    {
      "x": 0,
      "y": -4,
      "z": 0,
      "name": "Rock_Aqua_Brick_Smooth"
    },
    {
      "x": 0,
      "y": -3,
      "z": 0,
      "name": "Rock_Aqua_Brick_Smooth"
    },
    {
      "x": 0,
      "y": -2,
      "z": 0,
      "name": "Rock_Aqua_Brick_Smooth"
    },
    {
      "x": 0,
      "y": -1,
      "z": 0,
      "name": "Rock_Aqua_Brick_Smooth"
    },
    {
      "x": 0,
      "y": 0,
      "z": 0,
      "name": "Rock_Aqua_Brick_Smooth"
    },
    {
      "x": 0,
      "y": 1,
      "z": 0,
      "name": "Rock_Aqua_Brick_Smooth"
    },
    {
      "x": 0,
      "y": 2,
      "z": 0,
      "name": "Rock_Aqua_Brick_Smooth"
    },
    {
      "x": 0,
      "y": 3,
      "z": 0,
      "name": "Rock_Aqua_Brick_Smooth"
    },
    {
      "x": 0,
      "y": 4,
      "z": 0,
      "name": "Rock_Aqua_Brick_Smooth"
    },
    {
      "x": 0,
      "y": 5,
      "z": 0,
      "name": "Rock_Aqua_Brick_Smooth"
    },
    {
      "x": 0,
      "y": 6,
      "z": 0,
      "name": "Rock_Aqua_Brick_Smooth"
    },
    {
      "x": 0,
      "y": 7,
      "z": 0,
      "name": "Rock_Aqua_Brick_Smooth"
    },
    {
      "x": 0,
      "y": 8,
      "z": 0,
      "name": "Rock_Aqua_Brick_Smooth"
    },
    {
      "x": 0,
      "y": 9,
      "z": 0,
      "name": "Rock_Aqua_Brick_Smooth"
    },
    {
      "x": 0,
      "y": 10,
      "z": 0,
      "name": "Rock_Aqua_Brick_Smooth"
    },
    {
      "x": 0,
      "y": 11,
      "z": 0,
      "name": "Rock_Runic_Brick_Ornate"
    },
    {
      "x": 0,
      "y": 16,
      "z": 0,
      "name": "Rock_Runic_Blue_Brick"
    },
    {
      "x": 0,
      "y": 21,
      "z": 0,
      "name": "Furniture_Temple_Light_Lantern_Ceiling"
    },
    {
      "x": 0,
      "y": 22,
      "z": 0,
      "name": "Deco_Iron_Chain_Small"
    },
    {
      "x": 0,
      "y": 23,
      "z": 0,
      "name": "Rock_Aqua_Cobble"
    },
    {
      "x": 0,
      "y": 24,
      "z": 0,
      "name": "Rock_Aqua_Brick_Ornate"
    },
    {
      "x": 0,
      "y": 25,
      "z": 0,
      "name": "Rock_Aqua_Brick_Ornate"
    },
    {
      "x": 0,
      "y": 26,
      "z": 0,
      "name": "Rock_Aqua_Brick_Pillar_Middle"
    },
    {
      "x": 0,
      "y": 27,
      "z": 0,
      "name": "Rock_Aqua_Brick_Beam"
    },
    {
      "x": 0,
      "y": 28,
      "z": 0,
      "name": "Furniture_Human_Ruins_Lantern"
    },
    {
      "x": 0,
      "y": -9,
      "z": 1,
      "name": "Rock_Aqua_Brick_Smooth"
    },
    {
      "x": 0,
      "y": -8,
      "z": 1,
      "name": "Rock_Aqua_Brick_Smooth"
    },
    {
      "x": 0,
      "y": -7,
      "z": 1,
      "name": "Rock_Aqua_Brick_Smooth"
    },
    {
      "x": 0,
      "y": -6,
      "z": 1,
      "name": "Rock_Aqua_Brick_Smooth"
    },
    {
      "x": 0,
      "y": -5,
      "z": 1,
      "name": "Rock_Aqua_Brick_Smooth"
    },
    {
      "x": 0,
      "y": -4,
      "z": 1,
      "name": "Rock_Aqua_Brick_Smooth"
    },
    {
      "x": 0,
      "y": -3,
      "z": 1,
      "name": "Rock_Aqua_Brick_Smooth"
    },
    {
      "x": 0,
      "y": -2,
      "z": 1,
      "name": "Rock_Aqua_Brick_Smooth"
    },
    {
      "x": 0,
      "y": -1,
      "z": 1,
      "name": "Rock_Aqua_Brick_Smooth"
    },
    {
      "x": 0,
      "y": 0,
      "z": 1,
      "name": "Rock_Aqua_Brick_Smooth"
    },
    {
      "x": 0,
      "y": 1,
      "z": 1,
      "name": "Rock_Aqua_Brick_Smooth"
    },
    {
      "x": 0,
      "y": 2,
      "z": 1,
      "name": "Rock_Aqua_Brick_Smooth"
    },
    {
      "x": 0,
      "y": 3,
      "z": 1,
      "name": "Rock_Aqua_Brick_Smooth"
    },
    {
      "x": 0,
      "y": 4,
      "z": 1,
      "name": "Rock_Aqua_Brick_Smooth"
    },
    {
      "x": 0,
      "y": 5,
      "z": 1,
      "name": "Rock_Aqua_Brick_Smooth"
    },
    {
      "x": 0,
      "y": 6,
      "z": 1,
      "name": "Rock_Aqua_Brick_Smooth"
    },
    {
      "x": 0,
      "y": 7,
      "z": 1,
      "name": "Rock_Aqua_Brick_Smooth"
    },
    {
      "x": 0,
      "y": 8,
      "z": 1,
      "name": "Rock_Aqua_Brick_Smooth"
    },
    {
      "x": 0,
      "y": 9,
      "z": 1,
      "name": "Rock_Aqua_Brick_Smooth"
    },
    {
      "x": 0,
      "y": 10,
      "z": 1,
      "name": "Rock_Aqua_Brick_Smooth"
    },
    {
      "x": 0,
      "y": 11,
      "z": 1,
      "name": "Rock_Runic_Brick"
    },
    {
      "x": 0,
      "y": 16,
      "z": 1,
      "name": "Rock_Runic_Blue_Brick"
    },
    {
      "x": 0,
      "y": 23,
      "z": 1,
      "name": "Rock_Aqua_Cobble_Roof_Steep"
    },
    {
      "x": 0,
      "y": 24,
      "z": 1,
      "name": "Rock_Aqua_Cobble_Roof_Steep",
      "filler": 1024
    },
    {
      "x": 0,
      "y": -9,
      "z": 2,
      "name": "Rock_Aqua_Brick_Smooth"
    },
    {
      "x": 0,
      "y": -8,
      "z": 2,
      "name": "Rock_Aqua_Brick_Smooth"
    },
    {
      "x": 0,
      "y": -7,
      "z": 2,
      "name": "Rock_Aqua_Brick_Smooth"
    },
    {
      "x": 0,
      "y": -6,
      "z": 2,
      "name": "Rock_Aqua_Brick_Smooth"
    },
    {
      "x": 0,
      "y": -5,
      "z": 2,
      "name": "Rock_Aqua_Brick_Smooth"
    },
    {
      "x": 0,
      "y": -4,
      "z": 2,
      "name": "Rock_Aqua_Brick_Smooth"
    },
    {
      "x": 0,
      "y": -3,
      "z": 2,
      "name": "Rock_Aqua_Brick_Smooth"
    },
    {
      "x": 0,
      "y": -2,
      "z": 2,
      "name": "Rock_Aqua_Brick_Smooth"
    },
    {
      "x": 0,
      "y": -1,
      "z": 2,
      "name": "Rock_Aqua_Brick_Smooth"
    },
    {
      "x": 0,
      "y": 0,
      "z": 2,
      "name": "Rock_Aqua_Brick_Smooth"
    },
    {
      "x": 0,
      "y": 1,
      "z": 2,
      "name": "Rock_Aqua_Brick_Smooth"
    },
    {
      "x": 0,
      "y": 2,
      "z": 2,
      "name": "Rock_Aqua_Brick_Smooth"
    },
    {
      "x": 0,
      "y": 3,
      "z": 2,
      "name": "Rock_Aqua_Brick_Smooth"
    },
    {
      "x": 0,
      "y": 4,
      "z": 2,
      "name": "Rock_Aqua_Brick_Smooth"
    },
    {
      "x": 0,
      "y": 5,
      "z": 2,
      "name": "Rock_Aqua_Brick_Smooth"
    },
    {
      "x": 0,
      "y": 6,
      "z": 2,
      "name": "Rock_Aqua_Brick_Smooth"
    },
    {
      "x": 0,
      "y": 7,
      "z": 2,
      "name": "Rock_Aqua_Brick_Smooth"
    },
    {
      "x": 0,
      "y": 8,
      "z": 2,
      "name": "Rock_Aqua_Brick_Smooth"
    },
    {
      "x": 0,
      "y": 9,
      "z": 2,
      "name": "Rock_Aqua_Brick_Smooth"
    },
    {
      "x": 0,
      "y": 10,
      "z": 2,
      "name": "Rock_Aqua_Brick_Smooth"
    },
    {
      "x": 0,
      "y": 11,
      "z": 2,
      "name": "Rock_Runic_Brick"
    },
    {
      "x": 0,
      "y": 12,
      "z": 2,
      "name": "Furniture_Temple_Dark_Pot"
    },
    {
      "x": 0,
      "y": 16,
      "z": 2,
      "name": "Rock_Runic_Blue_Brick"
    },
    {
      "x": 0,
      "y": 22,
      "z": 2,
      "name": "Rock_Aqua_Cobble_Roof_Hollow"
    },
    {
      "x": 0,
      "y": -9,
      "z": 3,
      "name": "Rock_Aqua_Brick_Smooth"
    },
    {
      "x": 0,
      "y": -8,
      "z": 3,
      "name": "Rock_Aqua_Brick_Smooth"
    },
    {
      "x": 0,
      "y": -7,
      "z": 3,
      "name": "Rock_Aqua_Brick_Decorative"
    },
    {
      "x": 0,
      "y": -6,
      "z": 3,
      "name": "Rock_Aqua_Brick_Smooth"
    },
    {
      "x": 0,
      "y": -5,
      "z": 3,
      "name": "Rock_Aqua_Brick_Smooth"
    },
    {
      "x": 0,
      "y": -4,
      "z": 3,
      "name": "Rock_Aqua_Brick_Decorative"
    },
    {
      "x": 0,
      "y": -3,
      "z": 3,
      "name": "Rock_Aqua_Brick_Smooth"
    },
    {
      "x": 0,
      "y": -2,
      "z": 3,
      "name": "Rock_Aqua_Brick_Smooth"
    },
    {
      "x": 0,
      "y": -1,
      "z": 3,
      "name": "Rock_Aqua_Brick_Decorative"
    },
    {
      "x": 0,
      "y": 0,
      "z": 3,
      "name": "Rock_Aqua_Brick_Smooth"
    },
    {
      "x": 0,
      "y": 1,
      "z": 3,
      "name": "Rock_Aqua_Brick_Smooth"
    },
    {
      "x": 0,
      "y": 2,
      "z": 3,
      "name": "Rock_Aqua_Brick_Decorative"
    },
    {
      "x": 0,
      "y": 3,
      "z": 3,
      "name": "Rock_Aqua_Brick_Smooth"
    },
    {
      "x": 0,
      "y": 4,
      "z": 3,
      "name": "Rock_Aqua_Brick_Smooth"
    },
    {
      "x": 0,
      "y": 5,
      "z": 3,
      "name": "Rock_Aqua_Brick_Decorative"
    },
    {
      "x": 0,
      "y": 6,
      "z": 3,
      "name": "Rock_Aqua_Brick_Smooth"
    },
    {
      "x": 0,
      "y": 7,
      "z": 3,
      "name": "Rock_Aqua_Brick_Smooth"
    },
    {
      "x": 0,
      "y": 8,
      "z": 3,
      "name": "Rock_Aqua_Brick_Decorative"
    },
    {
      "x": 0,
      "y": 9,
      "z": 3,
      "name": "Rock_Aqua_Brick_Stairs"
    },
    {
      "x": 0,
      "y": 10,
      "z": 3,
      "name": "Rock_Aqua_Brick_Half",
      "rotation": 4
    },
    {
      "x": 0,
      "y": 11,
      "z": 3,
      "name": "Rock_Aqua_Brick_Half",
      "rotation": 4
    },
    {
      "x": 0,
      "y": 12,
      "z": 3,
      "name": "Rock_Aqua_Brick_Half",
      "rotation": 4
    },
    {
      "x": 0,
      "y": 13,
      "z": 3,
      "name": "Rock_Aqua_Brick_Half",
      "rotation": 4
    },
    {
      "x": 0,
      "y": 14,
      "z": 3,
      "name": "Rock_Aqua_Brick_Half",
      "rotation": 4
    },
    {
      "x": 0,
      "y": 15,
      "z": 3,
      "name": "Rock_Aqua_Brick_Half",
      "rotation": 4
    },
    {
      "x": 0,
      "y": 16,
      "z": 3,
      "name": "Rock_Aqua_Brick_Stairs",
      "rotation": 10
    },
    {
      "x": 0,
      "y": 20,
      "z": 3,
      "name": "Rock_Aqua_Brick_Wall"
    },
    {
      "x": 0,
      "y": 21,
      "z": 3,
      "name": "Rock_Aqua_Cobble_Roof"
    },
    {
      "x": 0,
      "y": 20,
      "z": 4,
      "name": "Rock_Aqua_Cobble_Roof_Shallow",
      "filler": 992
    },
    {
      "x": 0,
      "y": 20,
      "z": 5,
      "name": "Rock_Aqua_Cobble_Roof_Shallow"
    },
    {
      "x": 1,
      "y": 20,
      "z": -5,
      "name": "Rock_Aqua_Cobble_Roof_Shallow",
      "rotation": 2
    },
    {
      "x": 1,
      "y": -9,
      "z": -4,
      "name": "Rock_Aqua_Brick_Smooth"
    },
    {
      "x": 1,
      "y": -8,
      "z": -4,
      "name": "Rock_Aqua_Brick_Smooth"
    },
    {
      "x": 1,
      "y": -7,
      "z": -4,
      "name": "Rock_Aqua_Brick_Decorative"
    },
    {
      "x": 1,
      "y": -6,
      "z": -4,
      "name": "Rock_Aqua_Brick_Smooth"
    },
    {
      "x": 1,
      "y": -5,
      "z": -4,
      "name": "Rock_Aqua_Brick_Smooth"
    },
    {
      "x": 1,
      "y": -4,
      "z": -4,
      "name": "Rock_Aqua_Brick_Decorative"
    },
    {
      "x": 1,
      "y": -3,
      "z": -4,
      "name": "Rock_Aqua_Brick_Smooth"
    },
    {
      "x": 1,
      "y": -2,
      "z": -4,
      "name": "Rock_Aqua_Brick_Smooth"
    },
    {
      "x": 1,
      "y": -1,
      "z": -4,
      "name": "Rock_Aqua_Brick_Decorative"
    },
    {
      "x": 1,
      "y": 0,
      "z": -4,
      "name": "Rock_Aqua_Brick_Smooth"
    },
    {
      "x": 1,
      "y": 1,
      "z": -4,
      "name": "Rock_Aqua_Brick_Smooth"
    },
    {
      "x": 1,
      "y": 2,
      "z": -4,
      "name": "Rock_Aqua_Brick_Decorative"
    },
    {
      "x": 1,
      "y": 3,
      "z": -4,
      "name": "Rock_Aqua_Brick_Smooth"
    },
    {
      "x": 1,
      "y": 4,
      "z": -4,
      "name": "Rock_Aqua_Brick_Smooth"
    },
    {
      "x": 1,
      "y": 5,
      "z": -4,
      "name": "Rock_Aqua_Brick_Decorative"
    },
    {
      "x": 1,
      "y": 6,
      "z": -4,
      "name": "Rock_Aqua_Brick_Smooth"
    },
    {
      "x": 1,
      "y": 7,
      "z": -4,
      "name": "Rock_Aqua_Brick_Smooth"
    },
    {
      "x": 1,
      "y": 8,
      "z": -4,
      "name": "Rock_Aqua_Brick_Stairs",
      "rotation": 2
    },
    {
      "x": 1,
      "y": 20,
      "z": -4,
      "name": "Rock_Aqua_Cobble_Roof_Shallow",
      "filler": 32,
      "rotation": 2
    },
    {
      "x": 1,
      "y": -9,
      "z": -3,
      "name": "Rock_Aqua_Brick_Smooth"
    },
    {
      "x": 1,
      "y": -8,
      "z": -3,
      "name": "Rock_Aqua_Brick_Smooth"
    },
    {
      "x": 1,
      "y": -7,
      "z": -3,
      "name": "Rock_Aqua_Brick_Smooth"
    },
    {
      "x": 1,
      "y": -6,
      "z": -3,
      "name": "Rock_Aqua_Brick_Smooth"
    },
    {
      "x": 1,
      "y": -5,
      "z": -3,
      "name": "Rock_Aqua_Brick_Smooth"
    },
    {
      "x": 1,
      "y": -4,
      "z": -3,
      "name": "Rock_Aqua_Brick_Smooth"
    },
    {
      "x": 1,
      "y": -3,
      "z": -3,
      "name": "Rock_Aqua_Brick_Smooth"
    },
    {
      "x": 1,
      "y": -2,
      "z": -3,
      "name": "Rock_Aqua_Brick_Smooth"
    },
    {
      "x": 1,
      "y": -1,
      "z": -3,
      "name": "Rock_Aqua_Brick_Smooth"
    },
    {
      "x": 1,
      "y": 0,
      "z": -3,
      "name": "Rock_Aqua_Brick_Smooth"
    },
    {
      "x": 1,
      "y": 1,
      "z": -3,
      "name": "Rock_Aqua_Brick_Smooth"
    },
    {
      "x": 1,
      "y": 2,
      "z": -3,
      "name": "Rock_Aqua_Brick_Smooth"
    },
    {
      "x": 1,
      "y": 3,
      "z": -3,
      "name": "Rock_Aqua_Brick_Smooth"
    },
    {
      "x": 1,
      "y": 4,
      "z": -3,
      "name": "Rock_Aqua_Brick_Smooth"
    },
    {
      "x": 1,
      "y": 5,
      "z": -3,
      "name": "Rock_Aqua_Brick_Smooth"
    },
    {
      "x": 1,
      "y": 6,
      "z": -3,
      "name": "Rock_Aqua_Brick_Smooth"
    },
    {
      "x": 1,
      "y": 7,
      "z": -3,
      "name": "Rock_Aqua_Brick_Smooth"
    },
    {
      "x": 1,
      "y": 8,
      "z": -3,
      "name": "Rock_Aqua_Brick_Decorative",
      "rotation": 2
    },
    {
      "x": 1,
      "y": 9,
      "z": -3,
      "name": "Rock_Aqua_Brick_Smooth",
      "rotation": 2
    },
    {
      "x": 1,
      "y": 10,
      "z": -3,
      "name": "Rock_Aqua_Brick_Smooth",
      "rotation": 2
    },
    {
      "x": 1,
      "y": 11,
      "z": -3,
      "name": "Rock_Aqua_Brick_Decorative",
      "support": 15,
      "rotation": 2
    },
    {
      "x": 1,
      "y": 12,
      "z": -3,
      "name": "Rock_Aqua_Brick_Smooth",
      "rotation": 2
    },
    {
      "x": 1,
      "y": 13,
      "z": -3,
      "name": "Rock_Aqua_Brick_Smooth",
      "rotation": 2
    },
    {
      "x": 1,
      "y": 14,
      "z": -3,
      "name": "Rock_Aqua_Brick_Decorative",
      "rotation": 2
    },
    {
      "x": 1,
      "y": 15,
      "z": -3,
      "name": "Rock_Aqua_Brick_Smooth",
      "rotation": 2
    },
    {
      "x": 1,
      "y": 16,
      "z": -3,
      "name": "Rock_Aqua_Brick_Smooth",
      "rotation": 2
    },
    {
      "x": 1,
      "y": 17,
      "z": -3,
      "name": "Rock_Aqua_Brick_Wall"
    },
    {
