{
  "version": 8,
  "blockIdVersion": 11,
  "anchorX": 0,
  "anchorY": 1,
  "anchorZ": 0,
  "blocks": [
    {
      "x": -3,
      "y": 2,
      "z": 0,
      "name": "Rock_Aqua"
    },
    {
      "x": -3,
      "y": 3,
      "z": 0,
      "name": "Rock_Aqua_Cobble"
    },
    {
      "x": -3,
      "y": 4,
      "z": 0,
      "name": "Rock_Aqua_Cobble"
    },
    {
      "x": -3,
      "y": 5,
      "z": 0,
      "name": "Rock_Aqua_Cobble"
    },
    {
      "x": -3,
      "y": 2,
      "z": 1,
      "name": "Rock_Aqua"
    },
    {
      "x": -3,
      "y": 3,
      "z": 1,
      "name": "Rock_Aqua"
    },
    {
      "x": -3,
      "y": 4,
      "z": 1,
      "name": "Rock_Aqua_Cobble"
    },
    {
      "x": -3,
      "y": 5,
      "z": 1,
      "name": "Rock_Aqua_Cobble"
    },
    {
      "x": -3,
      "y": 3,
      "z": 2,
      "name": "Rock_Aqua"
    },
    {
      "x": -3,
      "y": 4,
      "z": 2,
      "name": "Rock_Aqua"
    },
    {
      "x": -2,
      "y": 1,
      "z": -2,
      "name": "Rock_Aqua_Cobble"
    },
    {
      "x": -2,
      "y": 2,
      "z": -2,
      "name": "Rock_Aqua_Cobble"
    },
    {
      "x": -2,
      "y": 3,
      "z": -2,
      "name": "Rock_Aqua_Cobble"
    },
    {
      "x": -2,
      "y": 0,
      "z": -1,
      "name": "Rock_Aqua_Cobble"
    },
    {
      "x": -2,
      "y": 1,
      "z": -1,
      "name": "Rock_Aqua_Cobble"
    },
    {
      "x": -2,
      "y": 2,
      "z": -1,
      "name": "Rock_Aqua_Cobble"
    },
    {
      "x": -2,
      "y": 3,
      "z": -1,
      "name": "Rock_Aqua_Cobble"
    },
    {
      "x": -2,
      "y": 4,
      "z": -1,
      "name": "Rock_Aqua_Cobble"
    },
    {
      "x": -2,
      "y": 0,
      "z": 0,
      "name": "Rock_Aqua_Cobble"
    },
    {
      "x": -2,
      "y": 1,
      "z": 0,
      "name": "Rock_Aqua"
    },
    {
      "x": -2,
      "y": 2,
      "z": 0,
      "name": "Rock_Aqua"
    },
    {
      "x": -2,
      "y": 3,
      "z": 0,
      "name": "Rock_Aqua"
    },
    {
      "x": -2,
      "y": 4,
      "z": 0,
      "name": "Rock_Aqua_Cobble"
    },
    {
      "x": -2,
      "y": 5,
      "z": 0,
      "name": "Rock_Aqua_Cobble"
    },
    {
      "x": -2,
      "y": 0,
      "z": 1,
      "name": "Rock_Aqua_Cobble"
    },
    {
      "x": -2,
      "y": 1,
      "z": 1,
      "name": "Rock_Aqua"
    },
    {
      "x": -2,
      "y": 2,
      "z": 1,
      "name": "Rock_Aqua"
    },
    {
      "x": -2,
      "y": 3,
      "z": 1,
      "name": "Rock_Aqua"
    },
    {
      "x": -2,
      "y": 4,
      "z": 1,
      "name": "Rock_Aqua"
    },
    {
      "x": -2,
      "y": 5,
      "z": 1,
      "name": "Rock_Aqua_Cobble"
    },
    {
      "x": -2,
      "y": 6,
      "z": 1,
      "name": "Rock_Aqua_Cobble"
    },
    {
      "x": -2,
      "y": 1,
      "z": 2,
      "name": "Rock_Aqua"
    },
    {
      "x": -2,
      "y": 2,
      "z": 2,
      "name": "Rock_Aqua"
    },
    {
      "x": -2,
      "y": 3,
      "z": 2,
      "name": "Rock_Aqua"
    },
    {
      "x": -2,
      "y": 4,
      "z": 2,
      "name": "Rock_Aqua"
    },
    {
      "x": -2,
      "y": 5,
      "z": 2,
      "name": "Rock_Aqua_Cobble"
    },
    {
      "x": -2,
      "y": 6,
      "z": 2,
      "name": "Rock_Aqua_Cobble"
    },
    {
      "x": -2,
      "y": 4,
      "z": 3,
      "name": "Rock_Aqua"
    },
    {
      "x": -2,
      "y": 5,
      "z": 3,
      "name": "Rock_Aqua_Cobble"
    },
    {
      "x": -2,
      "y": 6,
      "z": 3,
      "name": "Rock_Aqua_Cobble"
    },
    {
      "x": -1,
      "y": 2,
      "z": -3,
      "name": "Rock_Aqua_Cobble_Half",
      "rotation": 7
    },
    {
      "x": -1,
      "y": 0,
      "z": -2,
      "name": "Rock_Aqua_Cobble"
    },
    {
      "x": -1,
      "y": 1,
      "z": -2,
      "name": "Rock_Aqua_Cobble"
    },
    {
      "x": -1,
      "y": 2,
      "z": -2,
      "name": "Rock_Aqua_Cobble"
    },
    {
      "x": -1,
      "y": 3,
      "z": -2,
      "name": "Rock_Aqua_Cobble"
    },
    {
      "x": -1,
      "y": 4,
      "z": -2,
      "name": "Rock_Aqua_Cobble"
    },
    {
      "x": -1,
      "y": 0,
      "z": -1,
      "name": "Rock_Aqua_Cobble"
    },
    {
      "x": -1,
      "y": 1,
      "z": -1,
      "name": "Rock_Aqua_Cobble"
    },
    {
      "x": -1,
      "y": 2,
      "z": -1,
      "name": "Rock_Aqua_Cobble"
    },
    {
      "x": -1,
      "y": 3,
      "z": -1,
      "name": "Rock_Aqua_Cobble"
    },
    {
      "x": -1,
      "y": 4,
      "z": -1,
      "name": "Rock_Aqua_Cobble"
    },
    {
      "x": -1,
      "y": 5,
      "z": -1,
      "name": "Rock_Aqua_Cobble"
    },
    {
      "x": -1,
      "y": 0,
      "z": 0,
      "name": "Rock_Aqua_Cobble"
    },
    {
      "x": -1,
      "y": 1,
      "z": 0,
      "name": "Rock_Aqua"
    },
    {
      "x": -1,
      "y": 2,
      "z": 0,
      "name": "Rock_Aqua"
    },
    {
      "x": -1,
      "y": 3,
      "z": 0,
      "name": "Rock_Aqua_Cobble"
    },
    {
      "x": -1,
      "y": 4,
      "z": 0,
      "name": "Rock_Aqua_Cobble"
    },
    {
      "x": -1,
      "y": 5,
      "z": 0,
      "name": "Rock_Aqua_Cobble"
    },
    {
      "x": -1,
      "y": 6,
      "z": 0,
      "name": "Rock_Aqua_Cobble_Half"
    },
    {
      "x": -1,
      "y": 0,
      "z": 1,
      "name": "Rock_Aqua_Cobble"
    },
    {
      "x": -1,
      "y": 1,
      "z": 1,
      "name": "Rock_Aqua"
    },
    {
      "x": -1,
      "y": 2,
      "z": 1,
      "name": "Rock_Aqua"
    },
    {
      "x": -1,
      "y": 3,
      "z": 1,
      "name": "Rock_Aqua"
    },
    {
      "x": -1,
      "y": 4,
      "z": 1,
      "name": "Rock_Aqua_Cobble"
    },
    {
      "x": -1,
      "y": 5,
      "z": 1,
      "name": "Rock_Aqua_Cobble"
    },
    {
      "x": -1,
      "y": 6,
      "z": 1,
      "name": "Rock_Aqua_Cobble"
    },
    {
      "x": -1,
      "y": 0,
      "z": 2,
      "name": "Rock_Aqua_Cobble"
    },
    {
      "x": -1,
      "y": 1,
      "z": 2,
      "name": "Rock_Aqua"
    },
    {
      "x": -1,
      "y": 2,
      "z": 2,
      "name": "Rock_Aqua"
    },
    {
      "x": -1,
      "y": 3,
      "z": 2,
      "name": "Rock_Aqua"
    },
    {
      "x": -1,
      "y": 4,
      "z": 2,
      "name": "Rock_Aqua"
    },
    {
      "x": -1,
      "y": 5,
      "z": 2,
      "name": "Rock_Aqua_Cobble"
    },
    {
      "x": -1,
      "y": 6,
      "z": 2,
      "name": "Rock_Aqua_Cobble"
    },
    {
      "x": -1,
      "y": 7,
      "z": 2,
      "name": "Rubble_Aqua_Medium",
      "support": 15
    },
    {
      "x": -1,
      "y": 2,
      "z": 3,
      "name": "Rock_Aqua"
    },
    {
      "x": -1,
      "y": 3,
      "z": 3,
      "name": "Rock_Aqua"
    },
    {
      "x": -1,
      "y": 4,
      "z": 3,
      "name": "Rock_Aqua_Cobble"
    },
    {
      "x": -1,
      "y": 5,
      "z": 3,
      "name": "Rock_Aqua_Cobble"
    },
    {
      "x": 0,
      "y": 1,
      "z": -3,
      "name": "Rock_Aqua_Cobble"
    },
    {
      "x": 0,
      "y": 2,
      "z": -3,
      "name": "Rock_Aqua_Cobble"
    },
    {
      "x": 0,
      "y": 3,
      "z": -3,
      "name": "Rock_Aqua_Cobble"
    },
    {
      "x": 0,
      "y": 0,
      "z": -2,
      "name": "Rock_Aqua_Cobble"
    },
    {
      "x": 0,
      "y": 1,
      "z": -2,
      "name": "Rock_Aqua_Cobble"
    },
    {
      "x": 0,
      "y": 2,
      "z": -2,
      "name": "Rock_Aqua_Cobble"
    },
    {
      "x": 0,
      "y": 3,
      "z": -2,
      "name": "Rock_Aqua_Cobble"
    },
    {
      "x": 0,
      "y": 4,
      "z": -2,
      "name": "Rock_Aqua_Cobble"
    },
    {
      "x": 0,
      "y": 0,
      "z": -1,
      "name": "Rock_Aqua_Cobble"
    },
    {
      "x": 0,
      "y": 1,
      "z": -1,
      "name": "Rock_Aqua_Cobble"
    },
    {
      "x": 0,
      "y": 2,
      "z": -1,
      "name": "Rock_Aqua_Cobble"
    },
    {
      "x": 0,
      "y": 3,
      "z": -1,
      "name": "Rock_Aqua_Cobble"
    },
    {
      "x": 0,
      "y": 4,
      "z": -1,
      "name": "Rock_Aqua_Cobble"
    },
    {
      "x": 0,
      "y": 5,
      "z": -1,
      "name": "Rock_Aqua_Cobble"
    },
    {
      "x": 0,
      "y": 0,
      "z": 0,
      "name": "Rock_Aqua_Cobble"
    },
    {
      "x": 0,
      "y": 1,
      "z": 0,
      "name": "Rock_Aqua"
    },
    {
      "x": 0,
      "y": 2,
      "z": 0,
      "name": "Rock_Aqua"
    },
    {
      "x": 0,
      "y": 3,
      "z": 0,
      "name": "Rock_Aqua_Cobble"
    },
    {
      "x": 0,
      "y": 4,
      "z": 0,
      "name": "Rock_Aqua_Cobble"
    },
    {
      "x": 0,
      "y": 5,
      "z": 0,
      "name": "Rock_Aqua_Cobble"
    },
    {
      "x": 0,
      "y": 0,
      "z": 1,
      "name": "Rock_Aqua_Cobble"
    },
    {
      "x": 0,
      "y": 1,
      "z": 1,
      "name": "Rock_Aqua"
    },
    {
      "x": 0,
      "y": 2,
      "z": 1,
      "name": "Rock_Aqua"
    },
    {
      "x": 0,
      "y": 3,
      "z": 1,
      "name": "Rock_Aqua"
    },
    {
      "x": 0,
      "y": 4,
      "z": 1,
      "name": "Rock_Aqua_Cobble"
    },
    {
      "x": 0,
      "y": 5,
      "z": 1,
      "name": "Rock_Aqua_Cobble"
    },
    {
      "x": 0,
      "y": 6,
      "z": 1,
      "name": "Rock_Aqua_Cobble"
    },
    {
      "x": 0,
      "y": 0,
      "z": 2,
      "name": "Rock_Aqua_Cobble"
    },
    {
      "x": 0,
      "y": 1,
      "z": 2,
      "name": "Rock_Aqua"
    },
    {
      "x": 0,
      "y": 2,
      "z": 2,
      "name": "Rock_Aqua"
    },
    {
      "x": 0,
      "y": 3,
      "z": 2,
      "name": "Rock_Aqua"
    },
    {
      "x": 0,
      "y": 4,
      "z": 2,
      "name": "Rock_Aqua_Cobble"
    },
    {
      "x": 0,
      "y": 5,
      "z": 2,
      "name": "Rock_Aqua_Cobble"
    },
    {
      "x": 0,
      "y": 6,
      "z": 2,
      "name": "Rock_Aqua_Cobble"
    },
    {
      "x": 0,
      "y": 3,
      "z": 3,
      "name": "Rock_Aqua"
    },
    {
      "x": 0,
      "y": 4,
      "z": 3,
      "name": "Rock_Aqua_Cobble"
    },
    {
      "x": 0,
      "y": 5,
      "z": 3,
      "name": "Rock_Aqua_Cobble"
    },
    {
      "x": 0,
      "y": 6,
      "z": 3,
      "name": "Rubble_Aqua"
    },
    {
      "x": 1,
      "y": 2,
      "z": -3,
      "name": "Rock_Aqua_Cobble"
    },
    {
      "x": 1,
      "y": 3,
      "z": -3,
      "name": "Rock_Aqua_Cobble"
    },
    {
      "x": 1,
      "y": 4,
      "z": -3,
      "name": "Rubble_Aqua"
    },
    {
      "x": 1,
      "y": 0,
      "z": -2,
      "name": "Rock_Aqua_Cobble"
    },
    {
      "x": 1,
      "y": 1,
      "z": -2,
      "name": "Rock_Aqua_Cobble"
    },
    {
      "x": 1,
      "y": 2,
      "z": -2,
      "name": "Rock_Aqua_Cobble"
    },
    {
      "x": 1,
      "y": 3,
      "z": -2,
      "name": "Rock_Aqua_Cobble"
    },
    {
      "x": 1,
      "y": 4,
      "z": -2,
      "name": "Rock_Aqua_Cobble"
    },
    {
      "x": 1,
      "y": 5,
      "z": -2,
      "name": "Rubble_Aqua"
    },
    {
      "x": 1,
      "y": 0,
      "z": -1,
      "name": "Rock_Aqua_Cobble"
    },
    {
      "x": 1,
      "y": 1,
      "z": -1,
      "name": "Rock_Aqua_Cobble"
    },
    {
      "x": 1,
      "y": 2,
      "z": -1,
      "name": "Rock_Aqua_Cobble"
    },
    {
      "x": 1,
      "y": 3,
      "z": -1,
      "name": "Rock_Aqua_Cobble"
    },
    {
      "x": 1,
      "y": 4,
      "z": -1,
      "name": "Rock_Aqua_Cobble"
    },
    {
      "x": 1,
      "y": 5,
      "z": -1,
      "name": "Rock_Aqua_Cobble"
    },
    {
      "x": 1,
      "y": 0,
      "z": 0,
      "name": "Rock_Aqua_Cobble"
    },
    {
      "x": 1,
      "y": 1,
      "z": 0,
      "name": "Rock_Aqua"
    },
    {
      "x": 1,
      "y": 2,
      "z": 0,
      "name": "Rock_Aqua_Cobble"
    },
    {
      "x": 1,
      "y": 3,
      "z": 0,
      "name": "Rock_Aqua_Cobble"
    },
    {
      "x": 1,
      "y": 4,
      "z": 0,
      "name": "Rock_Aqua_Cobble"
    },
    {
      "x": 1,
      "y": 5,
      "z": 0,
      "name": "Rock_Aqua_Cobble"
    },
    {
      "x": 1,
      "y": 0,
      "z": 1,
      "name": "Rock_Aqua_Cobble"
    },
    {
      "x": 1,
      "y": 1,
      "z": 1,
      "name": "Rock_Aqua"
    },
    {
      "x": 1,
      "y": 2,
      "z": 1,
      "name": "Rock_Aqua"
    },
    {
      "x": 1,
      "y": 3,
      "z": 1,
      "name": "Rock_Aqua_Cobble"
    },
    {
      "x": 1,
      "y": 4,
      "z": 1,
      "name": "Rock_Aqua_Cobble"
    },
    {
      "x": 1,
      "y": 5,
      "z": 1,
      "name": "Rock_Aqua_Cobble"
    },
    {
      "x": 1,
      "y": 6,
      "z": 1,
      "name": "Rubble_Aqua"
    },
    {
      "x": 1,
      "y": 0,
      "z": 2,
      "name": "Rock_Aqua_Cobble"
    },
    {
      "x": 1,
      "y": 1,
      "z": 2,
      "name": "Rock_Aqua"
    },
    {
      "x": 1,
      "y": 2,
      "z": 2,
      "name": "Rock_Aqua"
    },
    {
      "x": 1,
      "y": 3,
      "z": 2,
      "name": "Rock_Aqua"
    },
    {
      "x": 1,
      "y": 4,
      "z": 2,
      "name": "Rock_Aqua_Cobble"
    },
    {
      "x": 1,
      "y": 5,
      "z": 2,
      "name": "Rock_Aqua_Cobble"
    },
    {
      "x": 1,
      "y": 4,
      "z": 3,
      "name": "Rock_Aqua_Cobble_Half",
      "rotation": 5
    },
    {
      "x": 2,
      "y": 0,
      "z": -2,
      "name": "Rock_Aqua_Cobble"
    },
    {
      "x": 2,
      "y": 1,
      "z": -2,
      "name": "Rock_Aqua_Cobble"
    },
    {
      "x": 2,
      "y": 2,
      "z": -2,
      "name": "Rock_Aqua_Cobble"
    },
    {
      "x": 2,
      "y": 3,
      "z": -2,
      "name": "Rock_Aqua_Cobble"
    },
    {
      "x": 2,
      "y": 0,
      "z": -1,
      "name": "Rock_Aqua_Cobble"
    },
    {
      "x": 2,
      "y": 1,
      "z": -1,
      "name": "Rock_Aqua_Cobble"
    },
    {
      "x": 2,
      "y": 2,
      "z": -1,
      "name": "Rock_Aqua_Cobble"
    },
    {
      "x": 2,
      "y": 3,
      "z": -1,
      "name": "Rock_Aqua_Cobble"
    },
    {
      "x": 2,
      "y": 4,
      "z": -1,
      "name": "Rock_Aqua_Cobble"
    },
    {
      "x": 2,
      "y": 5,
      "z": -1,
      "name": "Rubble_Aqua"
    },
    {
      "x": 2,
      "y": 0,
      "z": 0,
      "name": "Rock_Aqua_Cobble"
    },
    {
      "x": 2,
      "y": 1,
      "z": 0,
      "name": "Rock_Aqua_Cobble"
    },
    {
      "x": 2,
      "y": 2,
      "z": 0,
      "name": "Rock_Aqua_Cobble"
    },
    {
      "x": 2,
      "y": 3,
      "z": 0,
      "name": "Rock_Aqua_Cobble"
    },
    {
      "x": 2,
      "y": 4,
      "z": 0,
      "name": "Rock_Aqua_Cobble"
    },
    {
      "x": 2,
      "y": 5,
      "z": 0,
      "name": "Rock_Aqua_Cobble"
    },
    {
      "x": 2,
      "y": 0,
      "z": 1,
      "name": "Rock_Aqua_Cobble"
    },
    {
      "x": 2,
      "y": 1,
      "z": 1,
      "name": "Rock_Aqua"
    },
    {
      "x": 2,
      "y": 2,
      "z": 1,
      "name": "Rock_Aqua_Cobble"
    },
    {
      "x": 2,
      "y": 3,
      "z": 1,
      "name": "Rock_Aqua_Cobble"
    },
    {
      "x": 2,
      "y": 4,
      "z": 1,
      "name": "Rock_Aqua_Cobble"
    },
    {
      "x": 2,
      "y": 5,
      "z": 1,
      "name": "Rock_Aqua_Cobble"
    },
    {
      "x": 2,
      "y": 1,
      "z": 2,
      "name": "Rock_Aqua"
    },
    {
      "x": 2,
      "y": 2,
      "z": 2,
      "name": "Rock_Aqua"
    },
    {
      "x": 2,
      "y": 3,
      "z": 2,
      "name": "Rock_Aqua_Cobble"
    },
    {
      "x": 2,
      "y": 4,
      "z": 2,
      "name": "Rock_Aqua_Cobble"
    },
    {
      "x": 2,
      "y": 5,
      "z": 2,
      "name": "Rock_Aqua_Cobble_Half"
    },
    {
      "x": 3,
      "y": 1,
      "z": -1,
      "name": "Rock_Aqua_Cobble"
    },
    {
      "x": 3,
      "y": 2,
      "z": -1,
      "name": "Rock_Aqua_Cobble"
    },
    {
      "x": 3,
      "y": 3,
      "z": -1,
      "name": "Rock_Aqua_Cobble"
    },
    {
      "x": 3,
      "y": 1,
      "z": 0,
      "name": "Rock_Aqua_Cobble"
    },
    {
      "x": 3,
      "y": 2,
      "z": 0,
      "name": "Rock_Aqua_Cobble"
    },
    {
      "x": 3,
      "y": 3,
      "z": 0,
      "name": "Rock_Aqua_Cobble"
    },
    {
      "x": 3,
      "y": 4,
      "z": 0,
      "name": "Rock_Aqua_Cobble"
    },
    {
      "x": 3,
      "y": 1,
      "z": 1,
      "name": "Rock_Aqua_Cobble"
    },
    {
      "x": 3,
      "y": 2,
      "z": 1,
      "name": "Rock_Aqua_Cobble"
    },
    {
      "x": 3,
      "y": 3,
      "z": 1,
      "name": "Rock_Aqua_Cobble"
    },
    {
      "x": 3,
      "y": 4,
      "z": 1,
      "name": "Rock_Aqua_Cobble"
    }
  ],
  "fluids": [
    {
      "x": -1,
      "y": 2,
      "z": -3,
      "name": "Water_Source",
      "level": 1
    },
    {
      "x": -1,
      "y": 6,
      "z": 0,
      "name": "Water_Source",
      "level": 1
    },
    {
      "x": -1,
      "y": 7,
      "z": 2,
      "name": "Water_Source",
      "level": 1
    },
    {
      "x": 0,
      "y": 6,
      "z": 3,
      "name": "Water_Source",
      "level": 1
    },
    {
      "x": 1,
      "y": 4,
      "z": -3,
      "name": "Water_Source",
      "level": 1
    },
    {
      "x": 1,
      "y": 5,
      "z": -2,
      "name": "Water_Source",
      "level": 1
    },
    {
      "x": 1,
      "y": 6,
      "z": 1,
      "name": "Water_Source",
      "level": 1
    },
    {
      "x": 1,
      "y": 4,
      "z": 3,
      "name": "Water_Source",
      "level": 1
    },
    {
      "x": 2,
      "y": 5,
      "z": -1,
      "name": "Water_Source",
      "level": 1
    }
  ]
}