{
  "version": 8,
  "blockIdVersion": 11,
  "anchorX": 1,
  "anchorY": 1,
  "anchorZ": 0,
  "blocks": [
    {
      "x": -2,
      "y": 1,
      "z": -1,
      "name": "Rock_Aqua_Cobble_Half",
      "rotation": 6
    },
    {
      "x": -2,
      "y": 2,
      "z": -1,
      "name": "Rock_Aqua_Cobble_Half",
      "rotation": 6
    },
    {
      "x": -2,
      "y": 0,
      "z": 0,
      "name": "Rock_Aqua_Cobble"
    },
    {
      "x": -2,
      "y": 1,
      "z": 0,
      "name": "Rock_Aqua_Cobble"
    },
    {
      "x": -2,
      "y": 2,
      "z": 0,
      "name": "Rock_Aqua_Cobble"
    },
    {
      "x": -2,
      "y": 3,
      "z": 0,
      "name": "Rock_Aqua_Cobble"
    },
    {
      "x": -2,
      "y": 0,
      "z": 1,
      "name": "Rock_Aqua_Cobble"
    },
    {
      "x": -2,
      "y": 1,
      "z": 1,
      "name": "Rock_Aqua_Cobble"
    },
    {
      "x": -2,
      "y": 2,
      "z": 1,
      "name": "Rock_Aqua_Cobble"
    },
    {
      "x": -1,
      "y": 1,
      "z": -2,
      "name": "Rock_Aqua_Cobble"
    },
    {
      "x": -1,
      "y": 2,
      "z": -2,
      "name": "Rock_Aqua_Cobble"
    },
    {
      "x": -1,
      "y": 3,
      "z": -2,
      "name": "Rock_Aqua_Cobble"
    },
    {
      "x": -1,
      "y": 0,
      "z": -1,
      "name": "Rock_Aqua_Cobble"
    },
    {
      "x": -1,
      "y": 1,
      "z": -1,
      "name": "Rock_Aqua_Cobble"
    },
    {
      "x": -1,
      "y": 2,
      "z": -1,
      "name": "Rock_Aqua_Cobble"
    },
    {
      "x": -1,
      "y": 3,
      "z": -1,
      "name": "Rock_Aqua_Cobble"
    },
    {
      "x": -1,
      "y": 4,
      "z": -1,
      "name": "Rock_Aqua_Cobble"
    },
    {
      "x": -1,
      "y": 0,
      "z": 0,
      "name": "Rock_Aqua_Cobble"
    },
    {
      "x": -1,
      "y": 1,
      "z": 0,
      "name": "Rock_Aqua_Cobble"
    },
    {
      "x": -1,
      "y": 2,
      "z": 0,
      "name": "Rock_Aqua_Cobble"
    },
    {
      "x": -1,
      "y": 3,
      "z": 0,
      "name": "Rock_Aqua"
    },
    {
      "x": -1,
      "y": 4,
      "z": 0,
      "name": "Rock_Aqua_Cobble"
    },
    {
      "x": -1,
      "y": 0,
      "z": 1,
      "name": "Rock_Aqua_Cobble"
    },
    {
      "x": -1,
      "y": 1,
      "z": 1,
      "name": "Rock_Aqua_Cobble"
    },
    {
      "x": -1,
      "y": 2,
      "z": 1,
      "name": "Rock_Aqua"
    },
    {
      "x": -1,
      "y": 3,
      "z": 1,
      "name": "Rock_Aqua"
    },
    {
      "x": -1,
      "y": 4,
      "z": 1,
      "name": "Rock_Aqua"
    },
    {
      "x": -1,
      "y": 1,
      "z": 2,
      "name": "Rock_Aqua"
    },
    {
      "x": -1,
      "y": 2,
      "z": 2,
      "name": "Rock_Aqua"
    },
    {
      "x": -1,
      "y": 3,
      "z": 2,
      "name": "Rock_Aqua"
    },
    {
      "x": -1,
      "y": 4,
      "z": 2,
      "name": "Rock_Aqua"
    },
    {
      "x": 0,
      "y": 1,
      "z": -3,
      "name": "Rock_Aqua_Cobble"
    },
    {
      "x": 0,
      "y": 2,
      "z": -3,
      "name": "Rock_Aqua_Cobble"
    },
    {
      "x": 0,
      "y": 0,
      "z": -2,
      "name": "Rock_Aqua_Cobble"
    },
    {
      "x": 0,
      "y": 1,
      "z": -2,
      "name": "Rock_Aqua_Cobble"
    },
    {
      "x": 0,
      "y": 2,
      "z": -2,
      "name": "Rock_Aqua_Cobble"
    },
    {
      "x": 0,
      "y": 3,
      "z": -2,
      "name": "Rock_Aqua_Cobble"
    },
    {
      "x": 0,
      "y": 4,
      "z": -2,
      "name": "Rock_Aqua_Cobble"
    },
    {
      "x": 0,
      "y": 0,
      "z": -1,
      "name": "Rock_Aqua_Cobble"
    },
    {
      "x": 0,
      "y": 1,
      "z": -1,
      "name": "Rock_Aqua_Cobble"
    },
    {
      "x": 0,
      "y": 2,
      "z": -1,
      "name": "Rock_Aqua_Cobble"
    },
    {
      "x": 0,
      "y": 3,
      "z": -1,
      "name": "Rock_Aqua_Cobble"
    },
    {
      "x": 0,
      "y": 4,
      "z": -1,
      "name": "Rock_Aqua_Cobble"
    },
    {
      "x": 0,
      "y": 0,
      "z": 0,
      "name": "Rock_Aqua_Cobble"
    },
    {
      "x": 0,
      "y": 1,
      "z": 0,
      "name": "Rock_Aqua_Cobble"
    },
    {
      "x": 0,
      "y": 2,
      "z": 0,
      "name": "Rock_Aqua"
    },
    {
      "x": 0,
      "y": 3,
      "z": 0,
      "name": "Rock_Aqua"
    },
    {
      "x": 0,
      "y": 4,
      "z": 0,
      "name": "Rock_Aqua"
    },
    {
      "x": 0,
      "y": 5,
      "z": 0,
      "name": "Rock_Aqua_Cobble_Half"
    },
    {
      "x": 0,
      "y": 0,
      "z": 1,
      "name": "Rock_Aqua_Cobble"
    },
    {
      "x": 0,
      "y": 1,
      "z": 1,
      "name": "Rock_Aqua"
    },
    {
      "x": 0,
      "y": 2,
      "z": 1,
      "name": "Rock_Aqua"
    },
    {
      "x": 0,
      "y": 3,
      "z": 1,
      "name": "Rock_Aqua"
    },
    {
      "x": 0,
      "y": 4,
      "z": 1,
      "name": "Rock_Aqua"
    },
    {
      "x": 0,
      "y": 5,
      "z": 1,
      "name": "Rock_Aqua"
    },
    {
      "x": 0,
      "y": 0,
      "z": 2,
      "name": "Rock_Aqua_Cobble"
    },
    {
      "x": 0,
      "y": 1,
      "z": 2,
      "name": "Rock_Aqua"
    },
    {
      "x": 0,
      "y": 2,
      "z": 2,
      "name": "Rock_Aqua"
    },
    {
      "x": 0,
      "y": 3,
      "z": 2,
      "name": "Rock_Aqua"
    },
    {
      "x": 0,
      "y": 4,
      "z": 2,
      "name": "Rock_Aqua"
    },
    {
      "x": 0,
      "y": 1,
      "z": 3,
      "name": "Rock_Aqua"
    },
    {
      "x": 0,
      "y": 2,
      "z": 3,
      "name": "Rock_Aqua"
    },
    {
      "x": 1,
      "y": 1,
      "z": -3,
      "name": "Rock_Aqua_Cobble"
    },
    {
      "x": 1,
      "y": 2,
      "z": -3,
      "name": "Rock_Aqua_Cobble"
    },
    {
      "x": 1,
      "y": 0,
      "z": -2,
      "name": "Rock_Aqua_Cobble"
    },
    {
      "x": 1,
      "y": 1,
      "z": -2,
      "name": "Rock_Aqua_Cobble"
    },
    {
      "x": 1,
      "y": 2,
      "z": -2,
      "name": "Rock_Aqua_Cobble"
    },
    {
      "x": 1,
      "y": 3,
      "z": -2,
      "name": "Rock_Aqua_Cobble"
    },
    {
      "x": 1,
      "y": 4,
      "z": -2,
      "name": "Rock_Aqua_Cobble"
    },
    {
      "x": 1,
      "y": 5,
      "z": -2,
      "name": "Rubble_Aqua"
    },
    {
      "x": 1,
      "y": 0,
      "z": -1,
      "name": "Rock_Aqua_Cobble"
    },
    {
      "x": 1,
      "y": 1,
      "z": -1,
      "name": "Rock_Aqua_Cobble"
    },
    {
      "x": 1,
      "y": 2,
      "z": -1,
      "name": "Rock_Aqua_Cobble"
    },
    {
      "x": 1,
      "y": 3,
      "z": -1,
      "name": "Rock_Aqua_Cobble"
    },
    {
      "x": 1,
      "y": 4,
      "z": -1,
      "name": "Rock_Aqua_Cobble"
    },
    {
      "x": 1,
      "y": 0,
      "z": 0,
      "name": "Rock_Aqua_Cobble"
    },
    {
      "x": 1,
      "y": 1,
      "z": 0,
      "name": "Rock_Aqua_Cobble"
    },
    {
      "x": 1,
      "y": 2,
      "z": 0,
      "name": "Rock_Aqua_Cobble"
    },
    {
      "x": 1,
      "y": 3,
      "z": 0,
      "name": "Rock_Aqua"
    },
    {
      "x": 1,
      "y": 4,
      "z": 0,
      "name": "Rock_Aqua_Cobble"
    },
    {
      "x": 1,
      "y": 5,
      "z": 0,
      "name": "Rock_Aqua_Cobble"
    },
    {
      "x": 1,
      "y": 0,
      "z": 1,
      "name": "Rock_Aqua_Cobble"
    },
    {
      "x": 1,
      "y": 1,
      "z": 1,
      "name": "Rock_Aqua_Cobble"
    },
    {
      "x": 1,
      "y": 2,
      "z": 1,
      "name": "Rock_Aqua"
    },
    {
      "x": 1,
      "y": 3,
      "z": 1,
      "name": "Rock_Aqua"
    },
    {
      "x": 1,
      "y": 4,
      "z": 1,
      "name": "Rock_Aqua"
    },
    {
      "x": 1,
      "y": 5,
      "z": 1,
      "name": "Rock_Aqua_Cobble"
    },
    {
      "x": 1,
      "y": 0,
      "z": 2,
      "name": "Rock_Aqua_Cobble"
    },
    {
      "x": 1,
      "y": 1,
      "z": 2,
      "name": "Rock_Aqua"
    },
    {
      "x": 1,
      "y": 2,
      "z": 2,
      "name": "Rock_Aqua"
    },
    {
      "x": 1,
      "y": 3,
      "z": 2,
      "name": "Rock_Aqua"
    },
    {
      "x": 1,
      "y": 4,
      "z": 2,
      "name": "Rock_Aqua"
    },
    {
      "x": 1,
      "y": 5,
      "z": 2,
      "name": "Rock_Aqua_Cobble_Half"
    },
    {
      "x": 1,
      "y": 1,
      "z": 3,
      "name": "Rock_Aqua_Cobble"
    },
    {
      "x": 1,
      "y": 2,
      "z": 3,
      "name": "Rock_Aqua"
    },
    {
      "x": 1,
      "y": 3,
      "z": 3,
      "name": "Rock_Aqua"
    },
    {
      "x": 1,
      "y": 4,
      "z": 3,
      "name": "Rock_Aqua_Cobble_Half"
    },
    {
      "x": 2,
      "y": 0,
      "z": -2,
      "name": "Rock_Aqua_Cobble"
    },
    {
      "x": 2,
      "y": 1,
      "z": -2,
      "name": "Rock_Aqua_Cobble"
    },
    {
      "x": 2,
      "y": 2,
      "z": -2,
      "name": "Rock_Aqua_Cobble"
    },
    {
      "x": 2,
      "y": 3,
      "z": -2,
      "name": "Rock_Aqua_Cobble"
    },
    {
      "x": 2,
      "y": 4,
      "z": -2,
      "name": "Rock_Aqua_Cobble"
    },
    {
      "x": 2,
      "y": 0,
      "z": -1,
      "name": "Rock_Aqua_Cobble"
    },
    {
      "x": 2,
      "y": 1,
      "z": -1,
      "name": "Rock_Aqua_Cobble"
    },
    {
      "x": 2,
      "y": 2,
      "z": -1,
      "name": "Rock_Aqua_Cobble"
    },
    {
      "x": 2,
      "y": 3,
      "z": -1,
      "name": "Rock_Aqua_Cobble"
    },
    {
      "x": 2,
      "y": 4,
      "z": -1,
      "name": "Rock_Aqua_Cobble"
    },
    {
      "x": 2,
      "y": 0,
      "z": 0,
      "name": "Rock_Aqua_Cobble"
    },
    {
      "x": 2,
      "y": 1,
      "z": 0,
      "name": "Rock_Aqua_Cobble"
    },
    {
      "x": 2,
      "y": 2,
      "z": 0,
      "name": "Rock_Aqua_Cobble"
    },
    {
      "x": 2,
      "y": 3,
      "z": 0,
      "name": "Rock_Aqua_Cobble"
    },
    {
      "x": 2,
      "y": 4,
      "z": 0,
      "name": "Rock_Aqua_Cobble"
    },
    {
      "x": 2,
      "y": 5,
      "z": 0,
      "name": "Rock_Aqua_Cobble"
    },
    {
      "x": 2,
      "y": 0,
      "z": 1,
      "name": "Rock_Aqua_Cobble"
    },
    {
      "x": 2,
      "y": 1,
      "z": 1,
      "name": "Rock_Aqua_Cobble"
    },
    {
      "x": 2,
      "y": 2,
      "z": 1,
      "name": "Rock_Aqua_Cobble"
    },
    {
      "x": 2,
      "y": 3,
      "z": 1,
      "name": "Rock_Aqua"
    },
    {
      "x": 2,
      "y": 4,
      "z": 1,
      "name": "Rock_Aqua_Cobble"
    },
    {
      "x": 2,
      "y": 5,
      "z": 1,
      "name": "Rock_Aqua_Cobble"
    },
    {
      "x": 2,
      "y": 0,
      "z": 2,
      "name": "Rock_Aqua_Cobble"
    },
    {
      "x": 2,
      "y": 1,
      "z": 2,
      "name": "Rock_Aqua_Cobble"
    },
    {
      "x": 2,
      "y": 2,
      "z": 2,
      "name": "Rock_Aqua"
    },
    {
      "x": 2,
      "y": 3,
      "z": 2,
      "name": "Rock_Aqua"
    },
    {
      "x": 2,
      "y": 4,
      "z": 2,
      "name": "Rock_Aqua"
    },
    {
      "x": 2,
      "y": 2,
      "z": 3,
      "name": "Rock_Aqua_Cobble"
    },
    {
      "x": 2,
      "y": 3,
      "z": 3,
      "name": "Rock_Aqua"
    },
    {
      "x": 3,
      "y": 1,
      "z": -2,
      "name": "Rock_Aqua_Cobble"
    },
    {
      "x": 3,
      "y": 2,
      "z": -2,
      "name": "Rock_Aqua_Cobble"
    },
    {
      "x": 3,
      "y": 3,
      "z": -2,
      "name": "Rock_Aqua_Cobble"
    },
    {
      "x": 3,
      "y": 0,
      "z": -1,
      "name": "Rock_Aqua_Cobble"
    },
    {
      "x": 3,
      "y": 1,
      "z": -1,
      "name": "Rock_Aqua_Cobble"
    },
    {
      "x": 3,
      "y": 2,
      "z": -1,
      "name": "Rock_Aqua_Cobble"
    },
    {
      "x": 3,
      "y": 3,
      "z": -1,
      "name": "Rock_Aqua_Cobble"
    },
    {
      "x": 3,
      "y": 4,
      "z": -1,
      "name": "Rock_Aqua_Cobble"
    },
    {
      "x": 3,
      "y": 0,
      "z": 0,
      "name": "Rock_Aqua_Cobble"
    },
    {
      "x": 3,
      "y": 1,
      "z": 0,
      "name": "Rock_Aqua_Cobble"
    },
    {
      "x": 3,
      "y": 2,
      "z": 0,
      "name": "Rock_Aqua_Cobble"
    },
    {
      "x": 3,
      "y": 3,
      "z": 0,
      "name": "Rock_Aqua_Cobble"
    },
    {
      "x": 3,
      "y": 4,
      "z": 0,
      "name": "Rock_Aqua_Cobble"
    },
    {
      "x": 3,
      "y": 5,
      "z": 0,
      "name": "Rubble_Aqua"
    },
    {
      "x": 3,
      "y": 0,
      "z": 1,
      "name": "Rock_Aqua_Cobble"
    },
    {
      "x": 3,
      "y": 1,
      "z": 1,
      "name": "Rock_Aqua_Cobble"
    },
    {
      "x": 3,
      "y": 2,
      "z": 1,
      "name": "Rock_Aqua_Cobble"
    },
    {
      "x": 3,
      "y": 3,
      "z": 1,
      "name": "Rock_Aqua_Cobble"
    },
    {
      "x": 3,
      "y": 4,
      "z": 1,
      "name": "Rock_Aqua_Cobble"
    },
    {
      "x": 3,
      "y": 1,
      "z": 2,
      "name": "Rock_Aqua_Cobble"
    },
    {
      "x": 3,
      "y": 2,
      "z": 2,
      "name": "Rock_Aqua_Cobble"
    },
    {
      "x": 3,
      "y": 3,
      "z": 2,
      "name": "Rock_Aqua_Cobble"
    },
    {
      "x": 3,
      "y": 4,
      "z": 2,
      "name": "Rock_Aqua_Cobble"
    },
    {
      "x": 4,
      "y": 2,
      "z": 0,
      "name": "Rock_Aqua_Cobble_Half",
      "rotation": 5
    },
    {
      "x": 4,
      "y": 3,
      "z": 0,
      "name": "Rock_Aqua_Cobble_Half",
      "rotation": 5
    },
    {
      "x": 4,
      "y": 2,
      "z": 1,
      "name": "Rock_Aqua_Cobble_Half",
      "rotation": 5
    }
  ],
  "fluids": [
    {
      "x": -2,
      "y": 1,
      "z": -1,
      "name": "Water_Source",
      "level": 1
    },
    {
      "x": -2,
      "y": 2,
      "z": -1,
      "name": "Water_Source",
      "level": 1
    },
    {
      "x": 0,
      "y": 5,
      "z": 0,
      "name": "Water_Source",
      "level": 1
    },
    {
      "x": 1,
      "y": 5,
      "z": -2,
      "name": "Water_Source",
      "level": 1
    },
    {
      "x": 1,
      "y": 5,
      "z": 2,
      "name": "Water_Source",
      "level": 1
    },
    {
      "x": 1,
      "y": 4,
      "z": 3,
      "name": "Water_Source",
      "level": 1
    },
    {
      "x": 3,
      "y": 5,
      "z": 0,
      "name": "Water_Source",
      "level": 1
    },
    {
      "x": 4,
      "y": 2,
      "z": 0,
      "name": "Water_Source",
      "level": 1
    },
    {
      "x": 4,
      "y": 3,
      "z": 0,
      "name": "Water_Source",
      "level": 1
    },
    {
      "x": 4,
      "y": 2,
      "z": 1,
      "name": "Water_Source",
      "level": 1
    }
  ]
}