{
  "version": 8,
  "blockIdVersion": 11,
  "anchorX": 0,
  "anchorY": 0,
  "anchorZ": 0,
  "blocks": [
    {
      "x": -18,
      "y": 10,
      "z": -4,
      "name": "Plant_Coral_Block_Cyan"
    },
    {
      "x": -18,
      "y": 10,
      "z": -3,
      "name": "Plant_Coral_Block_Cyan"
    },
    {
      "x": -18,
      "y": 11,
      "z": -3,
      "name": "Rock_Crystal_Cyan_Medium"
    },
    {
      "x": -18,
      "y": 12,
      "z": -3,
      "name": "Plant_Coral_Block_Cyan"
    },
    {
      "x": -18,
      "y": 10,
      "z": -2,
      "name": "Plant_Coral_Block_Cyan"
    },
    {
      "x": -18,
      "y": 11,
      "z": -2,
      "name": "Plant_Coral_Block_Cyan"
    },
    {
      "x": -18,
      "y": 12,
      "z": -2,
      "name": "Plant_Coral_Block_Cyan"
    },
    {
      "x": -18,
      "y": 10,
      "z": -1,
      "name": "Plant_Coral_Block_Cyan"
    },
    {
      "x": -18,
      "y": 11,
      "z": -1,
      "name": "Plant_Coral_Block_Cyan"
    },
    {
      "x": -18,
      "y": 12,
      "z": -1,
      "name": "Plant_Coral_Block_Cyan"
    },
    {
      "x": -18,
      "y": 10,
      "z": 0,
      "name": "Plant_Coral_Block_Cyan"
    },
    {
      "x": -18,
      "y": 11,
      "z": 0,
      "name": "Plant_Coral_Block_Cyan"
    },
    {
      "x": -18,
      "y": 12,
      "z": 0,
      "name": "Plant_Coral_Block_Cyan"
    },
    {
      "x": -18,
      "y": 10,
      "z": 1,
      "name": "Plant_Coral_Block_Cyan"
    },
    {
      "x": -18,
      "y": 11,
      "z": 1,
      "name": "Plant_Coral_Block_Cyan"
    },
    {
      "x": -18,
      "y": 12,
      "z": 1,
      "name": "Plant_Coral_Block_Cyan"
    },
    {
      "x": -18,
      "y": 10,
      "z": 2,
      "name": "Plant_Coral_Block_Cyan"
    },
    {
      "x": -18,
      "y": 11,
      "z": 2,
      "name": "Plant_Coral_Block_Cyan"
    },
    {
      "x": -18,
      "y": 12,
      "z": 2,
      "name": "Plant_Coral_Block_Cyan"
    },
    {
      "x": -18,
      "y": 10,
      "z": 3,
      "name": "Plant_Coral_Block_Cyan"
    },
    {
      "x": -18,
      "y": 12,
      "z": 3,
      "name": "Plant_Coral_Block_Cyan"
    },
    {
      "x": -18,
      "y": 10,
      "z": 4,
      "name": "Plant_Coral_Block_Cyan"
    },
    {
      "x": -17,
      "y": 12,
      "z": -7,
      "name": "Plant_Coral_Block_Cyan"
    },
    {
      "x": -17,
      "y": 12,
      "z": -6,
      "name": "Plant_Coral_Block_Cyan"
    },
    {
      "x": -17,
      "y": 10,
      "z": -5,
      "name": "Plant_Coral_Block_Cyan"
    },
    {
      "x": -17,
      "y": 11,
      "z": -5,
      "name": "Plant_Coral_Block_Cyan"
    },
    {
      "x": -17,
      "y": 12,
      "z": -5,
      "name": "Plant_Coral_Block_Cyan"
    },
    {
      "x": -17,
      "y": 10,
      "z": -4,
      "name": "Plant_Coral_Block_Cyan"
    },
    {
      "x": -17,
      "y": 11,
      "z": -4,
      "name": "Plant_Coral_Block_Cyan"
    },
    {
      "x": -17,
      "y": 12,
      "z": -4,
      "name": "Plant_Coral_Block_Cyan"
    },
    {
      "x": -17,
      "y": 10,
      "z": -3,
      "name": "Plant_Coral_Block_Cyan"
    },
    {
      "x": -17,
      "y": 11,
      "z": -3,
      "name": "Plant_Coral_Block_Cyan"
    },
    {
      "x": -17,
      "y": 12,
      "z": -3,
      "name": "Plant_Coral_Block_Cyan"
    },
    {
      "x": -17,
      "y": 10,
      "z": -2,
      "name": "Plant_Coral_Block_Blue"
    },
    {
      "x": -17,
      "y": 11,
      "z": -2,
      "name": "Plant_Coral_Block_Blue"
    },
    {
      "x": -17,
      "y": 12,
      "z": -2,
      "name": "Plant_Coral_Block_Blue"
    },
    {
      "x": -17,
      "y": 10,
      "z": -1,
      "name": "Plant_Coral_Block_Blue"
    },
    {
      "x": -17,
      "y": 11,
      "z": -1,
      "name": "Plant_Coral_Block_Blue"
    },
    {
      "x": -17,
      "y": 12,
      "z": -1,
      "name": "Plant_Coral_Block_Blue"
    },
    {
      "x": -17,
      "y": 10,
      "z": 0,
      "name": "Plant_Coral_Block_Blue"
    },
    {
      "x": -17,
      "y": 11,
      "z": 0,
      "name": "Plant_Coral_Block_Blue"
    },
    {
      "x": -17,
      "y": 12,
      "z": 0,
      "name": "Plant_Coral_Block_Blue"
    },
    {
      "x": -17,
      "y": 10,
      "z": 1,
      "name": "Plant_Coral_Block_Blue"
    },
    {
      "x": -17,
      "y": 11,
      "z": 1,
      "name": "Plant_Coral_Block_Blue"
    },
    {
      "x": -17,
      "y": 12,
      "z": 1,
      "name": "Plant_Coral_Block_Blue"
    },
    {
      "x": -17,
      "y": 10,
      "z": 2,
      "name": "Plant_Coral_Block_Blue"
    },
    {
      "x": -17,
      "y": 11,
      "z": 2,
      "name": "Plant_Coral_Block_Blue"
    },
    {
      "x": -17,
      "y": 12,
      "z": 2,
      "name": "Plant_Coral_Block_Blue"
    },
    {
      "x": -17,
      "y": 10,
      "z": 3,
      "name": "Plant_Coral_Block_Cyan"
    },
    {
      "x": -17,
      "y": 11,
      "z": 3,
      "name": "Plant_Coral_Block_Cyan"
    },
    {
      "x": -17,
      "y": 12,
      "z": 3,
      "name": "Plant_Coral_Block_Cyan"
    },
    {
      "x": -17,
      "y": 10,
      "z": 4,
      "name": "Plant_Coral_Block_Cyan"
    },
    {
      "x": -17,
      "y": 11,
      "z": 4,
      "name": "Plant_Coral_Block_Cyan"
    },
    {
      "x": -17,
      "y": 12,
      "z": 4,
      "name": "Plant_Coral_Block_Cyan"
    },
    {
      "x": -17,
      "y": 10,
      "z": 5,
      "name": "Plant_Coral_Block_Cyan"
    },
    {
      "x": -17,
      "y": 11,
      "z": 5,
      "name": "Plant_Coral_Block_Cyan"
    },
    {
      "x": -17,
      "y": 12,
      "z": 5,
      "name": "Plant_Coral_Block_Cyan"
    },
    {
      "x": -17,
      "y": 10,
      "z": 6,
      "name": "Plant_Coral_Block_Cyan"
    },
    {
      "x": -17,
      "y": 11,
      "z": 6,
      "name": "Plant_Coral_Block_Cyan"
    },
    {
      "x": -17,
      "y": 12,
      "z": 6,
      "name": "Plant_Coral_Block_Cyan"
    },
    {
      "x": -17,
      "y": 10,
      "z": 7,
      "name": "Plant_Coral_Block_Cyan"
    },
    {
      "x": -17,
      "y": 11,
      "z": 7,
      "name": "Rock_Crystal_Cyan_Small"
    },
    {
      "x": -16,
      "y": 10,
      "z": -9,
      "name": "Plant_Coral_Block_Cyan"
    },
    {
      "x": -16,
      "y": 12,
      "z": -9,
      "name": "Plant_Coral_Block_Cyan"
    },
    {
      "x": -16,
      "y": 10,
      "z": -8,
      "name": "Plant_Coral_Block_Cyan"
    },
    {
      "x": -16,
      "y": 11,
      "z": -8,
      "name": "Plant_Coral_Block_Cyan"
    },
    {
      "x": -16,
      "y": 12,
      "z": -8,
      "name": "Plant_Coral_Block_Cyan"
    },
    {
      "x": -16,
      "y": 10,
      "z": -7,
      "name": "Plant_Coral_Block_Cyan"
    },
    {
      "x": -16,
      "y": 11,
      "z": -7,
      "name": "Plant_Coral_Block_Cyan"
    },
    {
      "x": -16,
      "y": 12,
      "z": -7,
      "name": "Plant_Coral_Block_Cyan"
    },
    {
      "x": -16,
      "y": 10,
      "z": -6,
      "name": "Plant_Coral_Block_Cyan"
    },
    {
      "x": -16,
      "y": 11,
      "z": -6,
      "name": "Plant_Coral_Block_Cyan"
    },
    {
      "x": -16,
      "y": 12,
      "z": -6,
      "name": "Plant_Coral_Block_Cyan"
    },
    {
      "x": -16,
      "y": 10,
      "z": -5,
      "name": "Plant_Coral_Block_Blue"
    },
    {
      "x": -16,
      "y": 11,
      "z": -5,
      "name": "Plant_Coral_Block_Blue"
    },
    {
      "x": -16,
      "y": 12,
      "z": -5,
      "name": "Plant_Coral_Block_Blue"
    },
    {
      "x": -16,
      "y": 10,
      "z": -4,
      "name": "Plant_Coral_Block_Blue"
    },
    {
      "x": -16,
      "y": 11,
      "z": -4,
      "name": "Plant_Coral_Block_Blue"
    },
    {
      "x": -16,
      "y": 12,
      "z": -4,
      "name": "Plant_Coral_Block_Blue"
    },
    {
      "x": -16,
      "y": 10,
      "z": -3,
      "name": "Plant_Coral_Block_Blue"
    },
    {
      "x": -16,
      "y": 11,
      "z": -3,
      "name": "Plant_Coral_Block_Blue"
    },
    {
      "x": -16,
      "y": 12,
      "z": -3,
      "name": "Plant_Coral_Block_Blue"
    },
    {
      "x": -16,
      "y": 10,
      "z": -2,
      "name": "Plant_Coral_Block_Blue"
    },
    {
      "x": -16,
      "y": 11,
      "z": -2,
      "name": "Plant_Coral_Block_Blue"
    },
    {
      "x": -16,
      "y": 12,
      "z": -2,
      "name": "Plant_Coral_Block_Blue"
    },
    {
      "x": -16,
      "y": 10,
      "z": -1,
      "name": "Plant_Coral_Block_Blue"
    },
    {
      "x": -16,
      "y": 11,
      "z": -1,
      "name": "Plant_Coral_Block_Blue"
    },
    {
      "x": -16,
      "y": 12,
      "z": -1,
      "name": "Plant_Coral_Block_Blue"
    },
    {
      "x": -16,
      "y": 10,
      "z": 0,
      "name": "Plant_Coral_Block_Blue"
    },
    {
      "x": -16,
      "y": 11,
      "z": 0,
      "name": "Plant_Coral_Block_Blue"
    },
    {
      "x": -16,
      "y": 12,
      "z": 0,
      "name": "Plant_Coral_Block_Blue"
    },
    {
      "x": -16,
      "y": 10,
      "z": 1,
      "name": "Plant_Coral_Block_Blue"
    },
    {
      "x": -16,
      "y": 11,
      "z": 1,
      "name": "Plant_Coral_Block_Blue"
    },
    {
      "x": -16,
      "y": 12,
      "z": 1,
      "name": "Plant_Coral_Block_Blue"
    },
    {
      "x": -16,
      "y": 10,
      "z": 2,
      "name": "Plant_Coral_Block_Blue"
    },
    {
      "x": -16,
      "y": 11,
      "z": 2,
      "name": "Plant_Coral_Block_Blue"
    },
    {
      "x": -16,
      "y": 12,
      "z": 2,
      "name": "Plant_Coral_Block_Blue"
    },
    {
      "x": -16,
      "y": 10,
      "z": 3,
      "name": "Plant_Coral_Block_Blue"
    },
    {
      "x": -16,
      "y": 11,
      "z": 3,
      "name": "Plant_Coral_Block_Blue"
    },
    {
      "x": -16,
      "y": 12,
      "z": 3,
      "name": "Plant_Coral_Block_Blue"
    },
    {
      "x": -16,
      "y": 10,
      "z": 4,
      "name": "Plant_Coral_Block_Blue"
    },
    {
      "x": -16,
      "y": 11,
      "z": 4,
      "name": "Plant_Coral_Block_Blue"
    },
    {
      "x": -16,
      "y": 12,
      "z": 4,
      "name": "Plant_Coral_Block_Blue"
    },
    {
      "x": -16,
      "y": 10,
      "z": 5,
      "name": "Plant_Coral_Block_Blue"
    },
    {
      "x": -16,
      "y": 11,
      "z": 5,
      "name": "Plant_Coral_Block_Blue"
    },
    {
      "x": -16,
      "y": 12,
      "z": 5,
      "name": "Plant_Coral_Block_Blue"
    },
    {
      "x": -16,
      "y": 10,
      "z": 6,
      "name": "Plant_Coral_Block_Cyan"
    },
    {
      "x": -16,
      "y": 11,
      "z": 6,
      "name": "Plant_Coral_Block_Cyan"
    },
    {
      "x": -16,
      "y": 12,
      "z": 6,
      "name": "Plant_Coral_Block_Cyan"
    },
    {
      "x": -16,
      "y": 10,
      "z": 7,
      "name": "Plant_Coral_Block_Cyan"
    },
    {
      "x": -16,
      "y": 11,
      "z": 7,
      "name": "Plant_Coral_Block_Cyan"
    },
    {
      "x": -16,
      "y": 12,
      "z": 7,
      "name": "Plant_Coral_Block_Cyan"
    },
    {
      "x": -16,
      "y": 10,
      "z": 8,
      "name": "Plant_Coral_Block_Cyan"
    },
    {
      "x": -16,
      "y": 11,
      "z": 8,
      "name": "Plant_Coral_Block_Cyan"
    },
    {
      "x": -16,
      "y": 12,
      "z": 8,
      "name": "Plant_Coral_Block_Cyan"
    },
    {
      "x": -16,
      "y": 10,
      "z": 9,
      "name": "Plant_Coral_Block_Cyan"
    },
    {
      "x": -16,
      "y": 11,
      "z": 9,
      "name": "Plant_Coral_Block_Cyan"
    },
    {
      "x": -15,
      "y": 10,
      "z": -11,
      "name": "Plant_Coral_Block_Cyan"
    },
    {
      "x": -15,
      "y": 10,
      "z": -10,
      "name": "Plant_Coral_Block_Cyan"
    },
    {
      "x": -15,
      "y": 11,
      "z": -10,
      "name": "Plant_Coral_Block_Cyan"
    },
    {
      "x": -15,
      "y": 12,
      "z": -10,
      "name": "Plant_Coral_Block_Cyan"
    },
    {
      "x": -15,
      "y": 10,
      "z": -9,
      "name": "Plant_Coral_Block_Cyan"
    },
    {
      "x": -15,
      "y": 11,
      "z": -9,
      "name": "Plant_Coral_Block_Cyan"
    },
    {
      "x": -15,
      "y": 12,
      "z": -9,
      "name": "Plant_Coral_Block_Cyan"
    },
    {
      "x": -15,
      "y": 10,
      "z": -8,
      "name": "Plant_Coral_Block_Blue"
    },
    {
      "x": -15,
      "y": 11,
      "z": -8,
      "name": "Plant_Coral_Block_Blue"
    },
    {
      "x": -15,
      "y": 12,
      "z": -8,
      "name": "Plant_Coral_Block_Blue"
    },
    {
      "x": -15,
      "y": 10,
      "z": -7,
      "name": "Plant_Coral_Block_Blue"
    },
    {
      "x": -15,
      "y": 11,
      "z": -7,
      "name": "Plant_Coral_Block_Blue"
    },
    {
      "x": -15,
      "y": 12,
      "z": -7,
      "name": "Plant_Coral_Block_Blue"
    },
    {
      "x": -15,
      "y": 10,
      "z": -6,
      "name": "Plant_Coral_Block_Blue"
    },
    {
      "x": -15,
      "y": 11,
      "z": -6,
      "name": "Plant_Coral_Block_Blue"
    },
    {
      "x": -15,
      "y": 12,
      "z": -6,
      "name": "Plant_Coral_Block_Blue"
    },
    {
      "x": -15,
      "y": 10,
      "z": -5,
      "name": "Plant_Coral_Block_Blue"
    },
    {
      "x": -15,
      "y": 11,
      "z": -5,
      "name": "Plant_Coral_Block_Blue"
    },
    {
      "x": -15,
      "y": 12,
      "z": -5,
      "name": "Plant_Coral_Block_Blue"
    },
    {
      "x": -15,
      "y": 10,
      "z": -4,
      "name": "Plant_Coral_Block_Blue"
    },
    {
      "x": -15,
      "y": 11,
      "z": -4,
      "name": "Plant_Coral_Block_Blue"
    },
    {
      "x": -15,
      "y": 12,
      "z": -4,
      "name": "Plant_Coral_Block_Blue"
    },
    {
      "x": -15,
      "y": 10,
      "z": -3,
      "name": "Plant_Coral_Block_Blue"
    },
    {
      "x": -15,
      "y": 11,
      "z": -3,
      "name": "Plant_Coral_Block_Blue"
    },
    {
      "x": -15,
      "y": 12,
      "z": -3,
      "name": "Plant_Coral_Block_Blue"
    },
    {
      "x": -15,
      "y": 10,
      "z": -2,
      "name": "Plant_Coral_Block_Blue"
    },
    {
      "x": -15,
      "y": 11,
      "z": -2,
      "name": "Plant_Coral_Block_Blue"
    },
    {
      "x": -15,
      "y": 12,
      "z": -2,
      "name": "Plant_Coral_Block_Blue"
    },
    {
      "x": -15,
      "y": 10,
      "z": -1,
      "name": "Plant_Coral_Block_Blue"
    },
    {
      "x": -15,
      "y": 11,
      "z": -1,
      "name": "Plant_Coral_Block_Blue"
    },
    {
      "x": -15,
      "y": 12,
      "z": -1,
      "name": "Plant_Coral_Block_Blue"
    },
    {
      "x": -15,
      "y": 10,
      "z": 0,
      "name": "Plant_Coral_Block_Blue"
    },
    {
      "x": -15,
      "y": 11,
      "z": 0,
      "name": "Plant_Coral_Block_Blue"
    },
    {
      "x": -15,
      "y": 12,
      "z": 0,
      "name": "Plant_Coral_Block_Blue"
    },
    {
      "x": -15,
      "y": 10,
      "z": 1,
      "name": "Plant_Coral_Block_Blue"
    },
    {
      "x": -15,
      "y": 11,
      "z": 1,
      "name": "Plant_Coral_Block_Blue"
    },
    {
      "x": -15,
      "y": 12,
      "z": 1,
      "name": "Plant_Coral_Block_Blue"
    },
    {
      "x": -15,
      "y": 10,
      "z": 2,
      "name": "Plant_Coral_Block_Blue"
    },
    {
      "x": -15,
      "y": 11,
      "z": 2,
      "name": "Plant_Coral_Block_Blue"
    },
    {
      "x": -15,
      "y": 12,
      "z": 2,
      "name": "Plant_Coral_Block_Blue"
    },
    {
      "x": -15,
      "y": 10,
      "z": 3,
      "name": "Plant_Coral_Block_Blue"
    },
    {
      "x": -15,
      "y": 11,
      "z": 3,
      "name": "Plant_Coral_Block_Blue"
    },
    {
      "x": -15,
      "y": 12,
      "z": 3,
      "name": "Plant_Coral_Block_Blue"
    },
    {
      "x": -15,
      "y": 10,
      "z": 4,
      "name": "Plant_Coral_Block_Blue"
    },
    {
      "x": -15,
      "y": 11,
      "z": 4,
      "name": "Plant_Coral_Block_Blue"
    },
    {
      "x": -15,
      "y": 12,
      "z": 4,
      "name": "Plant_Coral_Block_Blue"
    },
    {
      "x": -15,
      "y": 10,
      "z": 5,
      "name": "Plant_Coral_Block_Blue"
    },
    {
      "x": -15,
      "y": 11,
      "z": 5,
      "name": "Plant_Coral_Block_Blue"
    },
    {
      "x": -15,
      "y": 12,
      "z": 5,
      "name": "Plant_Coral_Block_Blue"
    },
    {
      "x": -15,
      "y": 10,
      "z": 6,
      "name": "Plant_Coral_Block_Blue"
    },
    {
      "x": -15,
      "y": 11,
      "z": 6,
      "name": "Plant_Coral_Block_Blue"
    },
    {
      "x": -15,
      "y": 12,
      "z": 6,
      "name": "Plant_Coral_Block_Blue"
    },
    {
      "x": -15,
      "y": 10,
      "z": 7,
      "name": "Plant_Coral_Block_Blue"
    },
    {
      "x": -15,
      "y": 11,
      "z": 7,
      "name": "Plant_Coral_Block_Blue"
    },
    {
      "x": -15,
      "y": 12,
      "z": 7,
      "name": "Plant_Coral_Block_Blue"
    },
    {
      "x": -15,
      "y": 10,
      "z": 8,
      "name": "Plant_Coral_Block_Blue"
    },
    {
      "x": -15,
      "y": 11,
      "z": 8,
      "name": "Plant_Coral_Block_Blue"
    },
    {
      "x": -15,
      "y": 12,
      "z": 8,
      "name": "Plant_Coral_Block_Cyan"
    },
    {
      "x": -15,
      "y": 10,
      "z": 9,
      "name": "Plant_Coral_Block_Cyan"
    },
    {
      "x": -15,
      "y": 11,
      "z": 9,
      "name": "Plant_Coral_Block_Cyan"
    },
    {
      "x": -15,
      "y": 12,
      "z": 9,
      "name": "Plant_Coral_Block_Cyan"
    },
    {
      "x": -15,
      "y": 10,
      "z": 10,
      "name": "Plant_Coral_Block_Cyan"
    },
    {
      "x": -15,
      "y": 11,
      "z": 10,
      "name": "Plant_Coral_Block_Cyan"
    },
    {
      "x": -15,
      "y": 12,
      "z": 10,
      "name": "Plant_Coral_Block_Cyan"
    },
    {
      "x": -15,
      "y": 10,
      "z": 11,
      "name": "Plant_Coral_Block_Cyan"
    },
    {
      "x": -15,
      "y": 11,
      "z": 11,
      "name": "Plant_Coral_Block_Cyan"
    },
    {
      "x": -15,
      "y": 10,
      "z": 12,
      "name": "Plant_Coral_Block_Cyan"
    },
    {
      "x": -14,
      "y": 11,
      "z": -13,
      "name": "Plant_Coral_Block_Cyan"
    },
    {
      "x": -14,
      "y": 12,
      "z": -13,
      "name": "Plant_Coral_Block_Cyan"
    },
    {
      "x": -14,
      "y": 10,
      "z": -12,
      "name": "Plant_Coral_Block_Cyan"
    },
    {
      "x": -14,
      "y": 11,
      "z": -12,
      "name": "Plant_Coral_Block_Cyan"
    },
    {
      "x": -14,
      "y": 12,
      "z": -12,
      "name": "Plant_Coral_Block_Cyan"
    },
    {
      "x": -14,
      "y": 10,
      "z": -11,
      "name": "Plant_Coral_Block_Cyan"
    },
    {
      "x": -14,
      "y": 11,
      "z": -11,
      "name": "Plant_Coral_Block_Cyan"
    },
    {
      "x": -14,
      "y": 12,
      "z": -11,
      "name": "Plant_Coral_Block_Cyan"
    },
    {
      "x": -14,
      "y": 10,
      "z": -10,
      "name": "Plant_Coral_Block_Blue"
    },
    {
      "x": -14,
      "y": 11,
      "z": -10,
      "name": "Plant_Coral_Block_Blue"
    },
    {
      "x": -14,
      "y": 12,
      "z": -10,
      "name": "Plant_Coral_Block_Cyan"
    },
    {
      "x": -14,
      "y": 10,
      "z": -9,
      "name": "Plant_Coral_Block_Blue"
    },
    {
      "x": -14,
      "y": 11,
      "z": -9,
      "name": "Plant_Coral_Block_Blue"
    },
    {
      "x": -14,
      "y": 12,
      "z": -9,
      "name": "Plant_Coral_Block_Blue"
    },
    {
      "x": -14,
      "y": 10,
      "z": -8,
      "name": "Plant_Coral_Block_Blue"
    },
    {
      "x": -14,
      "y": 11,
      "z": -8,
      "name": "Plant_Coral_Block_Blue"
    },
    {
      "x": -14,
      "y": 12,
      "z": -8,
      "name": "Plant_Coral_Block_Blue"
    },
    {
      "x": -14,
      "y": 10,
      "z": -7,
      "name": "Plant_Coral_Block_Blue"
    },
    {
      "x": -14,
      "y": 11,
      "z": -7,
      "name": "Plant_Coral_Block_Blue"
    },
    {
      "x": -14,
      "y": 12,
      "z": -7,
      "name": "Plant_Coral_Block_Blue"
    },
    {
      "x": -14,
      "y": 10,
      "z": -6,
      "name": "Plant_Coral_Block_Blue"
    },
    {
      "x": -14,
      "y": 11,
      "z": -6,
      "name": "Plant_Coral_Block_Blue"
    },
    {
      "x": -14,
      "y": 12,
      "z": -6,
      "name": "Plant_Coral_Block_Blue"
    },
    {
      "x": -14,
      "y": 10,
      "z": -5,
      "name": "Plant_Coral_Block_Blue"
    },
    {
      "x": -14,
      "y": 11,
      "z": -5,
      "name": "Plant_Coral_Block_Blue"
    },
    {
      "x": -14,
      "y": 12,
      "z": -5,
      "name": "Plant_Coral_Block_Blue"
    },
    {
      "x": -14,
      "y": 10,
      "z": -4,
      "name": "Plant_Coral_Block_Blue"
    },
    {
      "x": -14,
      "y": 11,
      "z": -4,
      "name": "Plant_Coral_Block_Blue"
    },
    {
      "x": -14,
      "y": 12,
      "z": -4,
      "name": "Plant_Coral_Block_Blue"
    },
    {
      "x": -14,
      "y": 10,
      "z": -3,
      "name": "Plant_Coral_Block_Blue"
    },
    {
      "x": -14,
      "y": 11,
      "z": -3,
      "name": "Plant_Coral_Block_Blue"
    },
    {
      "x": -14,
      "y": 12,
      "z": -3,
      "name": "Plant_Coral_Block_Blue"
    },
    {
      "x": -14,
      "y": 10,
      "z": -2,
      "name": "Plant_Coral_Block_Blue"
    },
    {
      "x": -14,
      "y": 11,
      "z": -2,
      "name": "Plant_Coral_Block_Blue"
    },
    {
      "x": -14,
      "y": 12,
      "z": -2,
      "name": "Plant_Coral_Block_Blue"
    },
    {
      "x": -14,
      "y": 10,
      "z": -1,
      "name": "Plant_Coral_Block_Blue"
    },
    {
      "x": -14,
      "y": 11,
      "z": -1,
      "name": "Plant_Coral_Block_Blue"
    },
    {
      "x": -14,
      "y": 12,
      "z": -1,
      "name": "Plant_Coral_Block_Blue"
    },
    {
      "x": -14,
      "y": 10,
      "z": 0,
      "name": "Plant_Coral_Block_Blue"
    },
    {
      "x": -14,
      "y": 11,
      "z": 0,
      "name": "Plant_Coral_Block_Blue"
    },
    {
      "x": -14,
      "y": 12,
      "z": 0,
      "name": "Plant_Coral_Block_Blue"
    },
    {
      "x": -14,
      "y": 10,
      "z": 1,
      "name": "Plant_Coral_Block_Blue"
    },
    {
      "x": -14,
      "y": 11,
      "z": 1,
      "name": "Plant_Coral_Block_Blue"
    },
    {
      "x": -14,
      "y": 12,
      "z": 1,
      "name": "Plant_Coral_Block_Blue"
    },
    {
      "x": -14,
      "y": 10,
      "z": 2,
      "name": "Plant_Coral_Block_Blue"
    },
    {
      "x": -14,
      "y": 11,
      "z": 2,
      "name": "Plant_Coral_Block_Blue"
    },
    {
      "x": -14,
      "y": 12,
      "z": 2,
      "name": "Plant_Coral_Block_Blue"
    },
    {
      "x": -14,
      "y": 10,
      "z": 3,
      "name": "Plant_Coral_Block_Blue"
    },
    {
      "x": -14,
      "y": 11,
      "z": 3,
      "name": "Plant_Coral_Block_Blue"
    },
    {
      "x": -14,
      "y": 12,
      "z": 3,
      "name": "Plant_Coral_Block_Blue"
    },
    {
      "x": -14,
      "y": 10,
      "z": 4,
      "name": "Plant_Coral_Block_Blue"
    },
    {
      "x": -14,
      "y": 11,
      "z": 4,
      "name": "Plant_Coral_Block_Blue"
    },
    {
      "x": -14,
      "y": 12,
      "z": 4,
      "name": "Plant_Coral_Block_Blue"
    },
    {
      "x": -14,
      "y": 10,
      "z": 5,
      "name": "Plant_Coral_Block_Blue"
    },
    {
      "x": -14,
      "y": 11,
      "z": 5,
      "name": "Plant_Coral_Block_Blue"
    },
    {
      "x": -14,
      "y": 12,
      "z": 5,
      "name": "Plant_Coral_Block_Blue"
    },
    {
      "x": -14,
      "y": 10,
      "z": 6,
      "name": "Plant_Coral_Block_Blue"
    },
    {
      "x": -14,
      "y": 11,
      "z": 6,
      "name": "Plant_Coral_Block_Blue"
    },
    {
      "x": -14,
      "y": 12,
      "z": 6,
      "name": "Plant_Coral_Block_Blue"
    },
    {
      "x": -14,
      "y": 10,
      "z": 7,
      "name": "Plant_Coral_Block_Blue"
    },
    {
      "x": -14,
      "y": 11,
      "z": 7,
      "name": "Plant_Coral_Block_Blue"
    },
    {
      "x": -14,
      "y": 12,
      "z": 7,
      "name": "Plant_Coral_Block_Blue"
    },
    {
      "x": -14,
      "y": 10,
      "z": 8,
      "name": "Plant_Coral_Block_Blue"
    },
    {
      "x": -14,
      "y": 11,
      "z": 8,
      "name": "Plant_Coral_Block_Blue"
    },
    {
      "x": -14,
      "y": 12,
      "z": 8,
      "name": "Plant_Coral_Block_Blue"
    },
    {
      "x": -14,
      "y": 10,
      "z": 9,
      "name": "Plant_Coral_Block_Blue"
    },
    {
      "x": -14,
      "y": 11,
      "z": 9,
      "name": "Plant_Coral_Block_Blue"
    },
    {
      "x": -14,
      "y": 12,
      "z": 9,
      "name": "Plant_Coral_Block_Blue"
    },
    {
      "x": -14,
      "y": 10,
      "z": 10,
      "name": "Plant_Coral_Block_Blue"
    },
    {
      "x": -14,
      "y": 11,
      "z": 10,
      "name": "Plant_Coral_Block_Blue"
    },
    {
      "x": -14,
      "y": 12,
      "z": 10,
      "name": "Plant_Coral_Block_Blue"
    },
    {
      "x": -14,
      "y": 10,
      "z": 11,
      "name": "Plant_Coral_Block_Cyan"
    },
    {
      "x": -14,
      "y": 11,
      "z": 11,
      "name": "Plant_Coral_Block_Cyan"
    },
    {
      "x": -14,
      "y": 12,
      "z": 11,
      "name": "Plant_Coral_Block_Cyan"
    },
    {
      "x": -14,
      "y": 10,
      "z": 12,
      "name": "Plant_Coral_Block_Cyan"
    },
    {
      "x": -14,
      "y": 11,
      "z": 12,
      "name": "Plant_Coral_Block_Cyan"
    },
    {
      "x": -14,
      "y": 12,
      "z": 12,
      "name": "Plant_Coral_Block_Cyan"
    },
    {
      "x": -13,
      "y": 11,
      "z": -14,
      "name": "Rock_Crystal_Cyan_Small",
      "rotation": 8
    },
    {
      "x": -13,
      "y": 12,
      "z": -14,
      "name": "Plant_Coral_Block_Cyan"
    },
    {
      "x": -13,
      "y": 10,
      "z": -13,
      "name": "Plant_Coral_Block_Cyan"
    },
    {
      "x": -13,
      "y": 11,
      "z": -13,
      "name": "Plant_Coral_Block_Cyan"
    },
    {
      "x": -13,
      "y": 12,
      "z": -13,
      "name": "Plant_Coral_Block_Cyan"
    },
    {
      "x": -13,
      "y": 10,
      "z": -12,
      "name": "Plant_Coral_Block_Blue"
    },
    {
      "x": -13,
      "y": 11,
      "z": -12,
      "name": "Plant_Coral_Block_Blue"
    },
    {
      "x": -13,
      "y": 12,
      "z": -12,
      "name": "Plant_Coral_Block_Blue"
    },
    {
      "x": -13,
      "y": 10,
      "z": -11,
      "name": "Plant_Coral_Block_Blue"
    },
    {
      "x": -13,
      "y": 11,
      "z": -11,
      "name": "Plant_Coral_Block_Blue"
    },
    {
      "x": -13,
      "y": 12,
      "z": -11,
      "name": "Plant_Coral_Block_Blue"
    },
    {
      "x": -13,
      "y": 10,
      "z": -10,
      "name": "Plant_Coral_Block_Blue"
    },
    {
      "x": -13,
      "y": 11,
      "z": -10,
      "name": "Plant_Coral_Block_Blue"
    },
    {
      "x": -13,
      "y": 12,
      "z": -10,
      "name": "Plant_Coral_Block_Blue"
    },
    {
      "x": -13,
      "y": 10,
      "z": -9,
      "name": "Plant_Coral_Block_Blue"
    },
    {
      "x": -13,
      "y": 11,
      "z": -9,
      "name": "Plant_Coral_Block_Blue"
    },
    {
      "x": -13,
      "y": 12,
      "z": -9,
      "name": "Plant_Coral_Block_Blue"
    },
    {
      "x": -13,
      "y": 10,
      "z": -8,
      "name": "Plant_Coral_Block_Blue"
    },
    {
      "x": -13,
      "y": 11,
      "z": -8,
      "name": "Plant_Coral_Block_Blue"
    },
    {
      "x": -13,
      "y": 12,
      "z": -8,
      "name": "Plant_Coral_Block_Blue"
    },
    {
      "x": -13,
      "y": 10,
      "z": -7,
      "name": "Plant_Coral_Block_Blue"
    },
    {
      "x": -13,
      "y": 11,
      "z": -7,
      "name": "Plant_Coral_Block_Blue"
    },
    {
      "x": -13,
      "y": 12,
      "z": -7,
      "name": "Plant_Coral_Block_Blue"
    },
    {
      "x": -13,
      "y": 10,
      "z": -6,
      "name": "Plant_Coral_Block_Blue"
    },
    {
      "x": -13,
      "y": 11,
      "z": -6,
      "name": "Plant_Coral_Block_Blue"
    },
    {
      "x": -13,
      "y": 12,
      "z": -6,
      "name": "Plant_Coral_Block_Blue"
    },
    {
      "x": -13,
      "y": 10,
      "z": -5,
      "name": "Plant_Coral_Block_Blue"
    },
    {
      "x": -13,
      "y": 11,
      "z": -5,
      "name": "Plant_Coral_Block_Blue"
    },
    {
      "x": -13,
      "y": 12,
      "z": -5,
      "name": "Plant_Coral_Block_Blue"
    },
    {
      "x": -13,
      "y": 10,
      "z": -4,
      "name": "Plant_Coral_Block_Blue"
    },
    {
      "x": -13,
      "y": 11,
      "z": -4,
      "name": "Plant_Coral_Block_Blue"
    },
    {
      "x": -13,
      "y": 12,
      "z": -4,
      "name": "Plant_Coral_Block_Blue"
    },
    {
      "x": -13,
      "y": 10,
      "z": -3,
      "name": "Plant_Coral_Block_Blue"
    },
    {
      "x": -13,
      "y": 11,
      "z": -3,
      "name": "Plant_Coral_Block_Blue"
    },
    {
      "x": -13,
      "y": 12,
      "z": -3,
      "name": "Plant_Coral_Block_Blue"
    },
    {
      "x": -13,
      "y": 10,
      "z": -2,
      "name": "Plant_Coral_Block_Blue"
    },
    {
      "x": -13,
      "y": 11,
      "z": -2,
      "name": "Plant_Coral_Block_Blue"
    },
    {
      "x": -13,
      "y": 12,
      "z": -2,
      "name": "Plant_Coral_Block_Blue"
    },
    {
      "x": -13,
      "y": 10,
      "z": -1,
      "name": "Plant_Coral_Block_Blue"
    },
    {
      "x": -13,
      "y": 11,
      "z": -1,
      "name": "Plant_Coral_Block_Blue"
    },
    {
      "x": -13,
      "y": 12,
      "z": -1,
      "name": "Plant_Coral_Block_Blue"
    },
    {
      "x": -13,
      "y": 10,
      "z": 0,
      "name": "Plant_Coral_Block_Blue"
    },
    {
      "x": -13,
      "y": 11,
      "z": 0,
      "name": "Plant_Coral_Block_Blue"
    },
    {
      "x": -13,
      "y": 12,
      "z": 0,
      "name": "Plant_Coral_Block_Blue"
    },
    {
      "x": -13,
      "y": 10,
      "z": 1,
      "name": "Plant_Coral_Block_Blue"
    },
    {
      "x": -13,
      "y": 11,
      "z": 1,
      "name": "Plant_Coral_Block_Blue"
    },
    {
      "x": -13,
      "y": 12,
      "z": 1,
      "name": "Plant_Coral_Block_Blue"
    },
    {
      "x": -13,
      "y": 10,
      "z": 2,
      "name": "Plant_Coral_Block_Blue"
    },
    {
      "x": -13,
      "y": 11,
      "z": 2,
      "name": "Plant_Coral_Block_Blue"
    },
    {
      "x": -13,
      "y": 12,
      "z": 2,
      "name": "Plant_Coral_Block_Blue"
    },
    {
      "x": -13,
      "y": 10,
      "z": 3,
      "name": "Plant_Coral_Block_Blue"
    },
    {
      "x": -13,
      "y": 11,
      "z": 3,
      "name": "Plant_Coral_Block_Blue"
    },
    {
      "x": -13,
      "y": 12,
      "z": 3,
      "name": "Plant_Coral_Block_Blue"
    },
    {
      "x": -13,
      "y": 10,
      "z": 4,
      "name": "Plant_Coral_Block_Blue"
    },
    {
      "x": -13,
      "y": 11,
      "z": 4,
      "name": "Plant_Coral_Block_Blue"
    },
    {
      "x": -13,
      "y": 12,
      "z": 4,
      "name": "Plant_Coral_Block_Blue"
    },
    {
      "x": -13,
      "y": 10,
      "z": 5,
      "name": "Plant_Coral_Block_Blue"
    },
    {
      "x": -13,
      "y": 11,
      "z": 5,
      "name": "Plant_Coral_Block_Blue"
    },
    {
      "x": -13,
      "y": 12,
      "z": 5,
      "name": "Plant_Coral_Block_Blue"
    },
    {
      "x": -13,
      "y": 10,
      "z": 6,
      "name": "Plant_Coral_Block_Blue"
    },
    {
      "x": -13,
      "y": 11,
      "z": 6,
      "name": "Plant_Coral_Block_Blue"
    },
    {
      "x": -13,
      "y": 12,
      "z": 6,
      "name": "Plant_Coral_Block_Blue"
    },
    {
      "x": -13,
      "y": 10,
      "z": 7,
      "name": "Plant_Coral_Block_Blue"
    },
    {
      "x": -13,
      "y": 11,
      "z": 7,
      "name": "Plant_Coral_Block_Blue"
    },
    {
      "x": -13,
      "y": 12,
      "z": 7,
      "name": "Plant_Coral_Block_Blue"
    },
    {
      "x": -13,
      "y": 10,
      "z": 8,
      "name": "Plant_Coral_Block_Blue"
    },
    {
      "x": -13,
      "y": 11,
      "z": 8,
      "name": "Plant_Coral_Block_Blue"
    },
    {
      "x": -13,
      "y": 12,
      "z": 8,
      "name": "Plant_Coral_Block_Blue"
    },
    {
      "x": -13,
      "y": 10,
      "z": 9,
      "name": "Plant_Coral_Block_Blue"
    },
    {
      "x": -13,
      "y": 11,
      "z": 9,
      "name": "Plant_Coral_Block_Blue"
    },
    {
      "x": -13,
      "y": 12,
      "z": 9,
      "name": "Plant_Coral_Block_Blue"
    },
    {
      "x": -13,
      "y": 10,
      "z": 10,
      "name": "Plant_Coral_Block_Blue"
    },
    {
      "x": -13,
      "y": 11,
      "z": 10,
      "name": "Plant_Coral_Block_Blue"
    },
    {
      "x": -13,
      "y": 12,
      "z": 10,
      "name": "Plant_Coral_Block_Blue"
    },
    {
      "x": -13,
      "y": 10,
      "z": 11,
      "name": "Plant_Coral_Block_Blue"
    },
    {
      "x": -13,
      "y": 11,
      "z": 11,
      "name": "Plant_Coral_Block_Blue"
    },
    {
      "x": -13,
      "y": 12,
      "z": 11,
      "name": "Plant_Coral_Block_Blue"
    },
    {
      "x": -13,
      "y": 10,
      "z": 12,
      "name": "Plant_Coral_Block_Blue"
    },
    {
      "x": -13,
      "y": 11,
      "z": 12,
      "name": "Plant_Coral_Block_Blue"
    },
    {
      "x": -13,
      "y": 12,
      "z": 12,
      "name": "Plant_Coral_Block_Cyan"
    },
    {
      "x": -13,
      "y": 10,
      "z": 13,
      "name": "Plant_Coral_Block_Cyan"
    },
    {
      "x": -13,
      "y": 11,
      "z": 13,
      "name": "Plant_Coral_Block_Cyan"
    },
    {
      "x": -13,
      "y": 12,
      "z": 13,
      "name": "Plant_Coral_Block_Cyan"
    },
    {
      "x": -13,
      "y": 12,
      "z": 14,
      "name": "Plant_Coral_Block_Cyan"
    },
    {
      "x": -12,
      "y": 10,
      "z": -14,
      "name": "Plant_Coral_Block_Cyan"
    },
    {
      "x": -12,
      "y": 11,
      "z": -14,
      "name": "Plant_Coral_Block_Cyan"
    },
    {
      "x": -12,
      "y": 12,
      "z": -14,
      "name": "Plant_Coral_Block_Cyan"
    },
    {
      "x": -12,
      "y": 10,
      "z": -13,
      "name": "Plant_Coral_Block_Blue"
    },
    {
      "x": -12,
      "y": 11,
      "z": -13,
      "name": "Plant_Coral_Block_Blue"
    },
    {
      "x": -12,
      "y": 12,
      "z": -13,
      "name": "Plant_Coral_Block_Blue"
    },
    {
      "x": -12,
      "y": 10,
      "z": -12,
      "name": "Plant_Coral_Block_Blue"
    },
    {
      "x": -12,
      "y": 11,
      "z": -12,
      "name": "Plant_Coral_Block_Blue"
    },
    {
      "x": -12,
      "y": 12,
      "z": -12,
      "name": "Plant_Coral_Block_Blue"
    },
    {
      "x": -12,
      "y": 10,
      "z": -11,
      "name": "Plant_Coral_Block_Blue"
    },
    {
      "x": -12,
      "y": 11,
      "z": -11,
      "name": "Plant_Coral_Block_Blue"
    },
    {
      "x": -12,
      "y": 12,
      "z": -11,
      "name": "Plant_Coral_Block_Blue"
    },
    {
      "x": -12,
      "y": 10,
      "z": -10,
      "name": "Plant_Coral_Block_Blue"
    },
    {
      "x": -12,
      "y": 11,
      "z": -10,
      "name": "Plant_Coral_Block_Blue"
    },
    {
      "x": -12,
      "y": 12,
      "z": -10,
      "name": "Plant_Coral_Block_Blue"
    },
    {
      "x": -12,
      "y": 10,
      "z": -9,
      "name": "Plant_Coral_Block_Blue"
    },
    {
      "x": -12,
      "y": 11,
      "z": -9,
      "name": "Plant_Coral_Block_Blue"
    },
    {
      "x": -12,
      "y": 12,
      "z": -9,
      "name": "Plant_Coral_Block_Blue"
    },
    {
      "x": -12,
      "y": 10,
      "z": -8,
      "name": "Plant_Coral_Block_Blue"
    },
    {
      "x": -12,
      "y": 11,
      "z": -8,
      "name": "Plant_Coral_Block_Blue"
    },
    {
      "x": -12,
      "y": 12,
      "z": -8,
      "name": "Plant_Coral_Block_Blue"
    },
    {
      "x": -12,
      "y": 10,
      "z": -7,
      "name": "Plant_Coral_Block_Blue"
    },
    {
      "x": -12,
      "y": 11,
      "z": -7,
      "name": "Plant_Coral_Block_Blue"
    },
    {
      "x": -12,
      "y": 12,
      "z": -7,
      "name": "Plant_Coral_Block_Blue"
    },
    {
      "x": -12,
      "y": 10,
      "z": -6,
      "name": "Plant_Coral_Block_Blue"
    },
    {
      "x": -12,
      "y": 11,
      "z": -6,
      "name": "Plant_Coral_Block_Blue"
    },
    {
      "x": -12,
      "y": 12,
      "z": -6,
      "name": "Plant_Coral_Block_Blue"
    },
    {
      "x": -12,
      "y": 10,
      "z": -5,
      "name": "Plant_Coral_Block_Blue"
    },
    {
      "x": -12,
      "y": 11,
      "z": -5,
      "name": "Plant_Coral_Block_Blue"
    },
    {
      "x": -12,
      "y": 12,
      "z": -5,
      "name": "Plant_Coral_Block_Blue"
    },
    {
      "x": -12,
      "y": 10,
      "z": -4,
      "name": "Plant_Coral_Block_Blue"
    },
    {
      "x": -12,
      "y": 11,
      "z": -4,
      "name": "Plant_Coral_Block_Blue"
    },
    {
      "x": -12,
      "y": 12,
      "z": -4,
      "name": "Plant_Coral_Block_Blue"
    },
    {
      "x": -12,
      "y": 10,
      "z": -3,
      "name": "Plant_Coral_Block_Blue"
    },
    {
      "x": -12,
      "y": 11,
      "z": -3,
      "name": "Plant_Coral_Block_Blue"
    },
    {
      "x": -12,
      "y": 12,
      "z": -3,
      "name": "Plant_Coral_Block_Blue"
    },
    {
      "x": -12,
      "y": 10,
      "z": -2,
      "name": "Plant_Coral_Block_Blue"
    },
    {
      "x": -12,
      "y": 11,
      "z": -2,
      "name": "Plant_Coral_Block_Blue"
    },
    {
      "x": -12,
      "y": 12,
      "z": -2,
      "name": "Plant_Coral_Block_Blue"
    },
    {
      "x": -12,
      "y": 10,
      "z": -1,
      "name": "Plant_Coral_Block_Blue"
    },
    {
      "x": -12,
      "y": 11,
      "z": -1,
      "name": "Plant_Coral_Block_Blue"
    },
    {
      "x": -12,
      "y": 12,
      "z": -1,
      "name": "Plant_Coral_Block_Blue"
    },
    {
      "x": -12,
      "y": 10,
      "z": 0,
      "name": "Plant_Coral_Block_Blue"
    },
    {
      "x": -12,
      "y": 11,
      "z": 0,
      "name": "Plant_Coral_Block_Blue"
    },
    {
      "x": -12,
      "y": 12,
      "z": 0,
      "name": "Plant_Coral_Block_Blue"
    },
    {
      "x": -12,
      "y": 10,
      "z": 1,
      "name": "Plant_Coral_Block_Blue"
    },
    {
      "x": -12,
      "y": 11,
      "z": 1,
      "name": "Plant_Coral_Block_Blue"
    },
    {
      "x": -12,
      "y": 12,
      "z": 1,
      "name": "Plant_Coral_Block_Blue"
    },
    {
      "x": -12,
      "y": 10,
      "z": 2,
      "name": "Plant_Coral_Block_Blue"
    },
    {
      "x": -12,
      "y": 11,
      "z": 2,
      "name": "Plant_Coral_Block_Blue"
    },
    {
      "x": -12,
      "y": 12,
      "z": 2,
      "name": "Plant_Coral_Block_Blue"
    },
    {
      "x": -12,
      "y": 10,
      "z": 3,
      "name": "Plant_Coral_Block_Blue"
    },
    {
      "x": -12,
      "y": 11,
      "z": 3,
      "name": "Plant_Coral_Block_Blue"
    },
    {
      "x": -12,
      "y": 12,
      "z": 3,
      "name": "Plant_Coral_Block_Blue"
    },
    {
      "x": -12,
      "y": 10,
      "z": 4,
      "name": "Plant_Coral_Block_Blue"
    },
    {
      "x": -12,
      "y": 11,
      "z": 4,
      "name": "Plant_Coral_Block_Blue"
    },
    {
      "x": -12,
      "y": 12,
      "z": 4,
      "name": "Plant_Coral_Block_Blue"
    },
    {
      "x": -12,
      "y": 10,
      "z": 5,
      "name": "Plant_Coral_Block_Blue"
    },
    {
      "x": -12,
      "y": 11,
      "z": 5,
      "name": "Plant_Coral_Block_Blue"
    },
    {
      "x": -12,
      "y": 12,
      "z": 5,
      "name": "Plant_Coral_Block_Blue"
    },
    {
      "x": -12,
      "y": 10,
      "z": 6,
      "name": "Plant_Coral_Block_Blue"
    },
    {
      "x": -12,
      "y": 11,
      "z": 6,
      "name": "Plant_Coral_Block_Blue"
    },
    {
      "x": -12,
      "y": 12,
      "z": 6,
      "name": "Plant_Coral_Block_Blue"
    },
    {
      "x": -12,
      "y": 10,
      "z": 7,
      "name": "Plant_Coral_Block_Blue"
    },
    {
      "x": -12,
      "y": 11,
      "z": 7,
      "name": "Plant_Coral_Block_Blue"
    },
    {
      "x": -12,
      "y": 12,
      "z": 7,
      "name": "Plant_Coral_Block_Blue"
    },
    {
      "x": -12,
      "y": 10,
      "z": 8,
      "name": "Plant_Coral_Block_Blue"
    },
    {
      "x": -12,
      "y": 11,
      "z": 8,
      "name": "Plant_Coral_Block_Blue"
    },
    {
      "x": -12,
      "y": 12,
      "z": 8,
      "name": "Plant_Coral_Block_Blue"
    },
    {
      "x": -12,
      "y": 10,
      "z": 9,
      "name": "Plant_Coral_Block_Blue"
    },
    {
      "x": -12,
      "y": 11,
      "z": 9,
      "name": "Plant_Coral_Block_Blue"
    },
    {
      "x": -12,
      "y": 12,
      "z": 9,
      "name": "Plant_Coral_Block_Blue"
    },
    {
      "x": -12,
      "y": 10,
      "z": 10,
      "name": "Plant_Coral_Block_Blue"
    },
    {
      "x": -12,
      "y": 11,
      "z": 10,
      "name": "Plant_Coral_Block_Blue"
    },
    {
      "x": -12,
      "y": 12,
      "z": 10,
      "name": "Plant_Coral_Block_Blue"
    },
    {
      "x": -12,
      "y": 10,
      "z": 11,
      "name": "Plant_Coral_Block_Blue"
    },
    {
      "x": -12,
      "y": 11,
      "z": 11,
      "name": "Plant_Coral_Block_Blue"
    },
    {
      "x": -12,
      "y": 12,
      "z": 11,
      "name": "Plant_Coral_Block_Blue"
    },
    {
      "x": -12,
      "y": 10,
      "z": 12,
      "name": "Plant_Coral_Block_Blue"
    },
    {
      "x": -12,
      "y": 11,
      "z": 12,
      "name": "Plant_Coral_Block_Blue"
    },
    {
      "x": -12,
      "y": 12,
      "z": 12,
      "name": "Plant_Coral_Block_Blue"
    },
    {
      "x": -12,
      "y": 10,
      "z": 13,
      "name": "Plant_Coral_Block_Blue"
    },
    {
      "x": -12,
      "y": 11,
      "z": 13,
      "name": "Plant_Coral_Block_Blue"
    },
    {
      "x": -12,
      "y": 12,
      "z": 13,
      "name": "Plant_Coral_Block_Blue"
    },
    {
      "x": -12,
      "y": 10,
      "z": 14,
      "name": "Plant_Coral_Block_Cyan"
    },
    {
      "x": -12,
      "y": 11,
      "z": 14,
      "name": "Plant_Coral_Block_Cyan"
    },
    {
      "x": -12,
      "y": 12,
      "z": 14,
      "name": "Plant_Coral_Block_Cyan"
    },
    {
      "x": -11,
      "y": 10,
      "z": -15,
      "name": "Plant_Coral_Block_Cyan"
    },
    {
      "x": -11,
      "y": 11,
      "z": -15,
      "name": "Plant_Coral_Block_Cyan"
    },
    {
      "x": -11,
      "y": 10,
      "z": -14,
      "name": "Plant_Coral_Block_Cyan"
    },
    {
      "x": -11,
      "y": 11,
      "z": -14,
      "name": "Plant_Coral_Block_Cyan"
    },
    {
      "x": -11,
      "y": 12,
      "z": -14,
      "name": "Plant_Coral_Block_Cyan"
    },
    {
      "x": -11,
      "y": 10,
      "z": -13,
      "name": "Plant_Coral_Block_Blue"
    },
    {
      "x": -11,
      "y": 11,
      "z": -13,
      "name": "Plant_Coral_Block_Blue"
    },
    {
      "x": -11,
      "y": 12,
      "z": -13,
      "name": "Plant_Coral_Block_Blue"
    },
    {
      "x": -11,
      "y": 10,
      "z": -12,
      "name": "Plant_Coral_Block_Blue"
    },
    {
      "x": -11,
      "y": 11,
      "z": -12,
      "name": "Plant_Coral_Block_Blue"
    },
    {
      "x": -11,
      "y": 12,
      "z": -12,
      "name": "Plant_Coral_Block_Blue"
    },
    {
      "x": -11,
      "y": 10,
      "z": -11,
      "name": "Plant_Coral_Block_Blue"
    },
    {
      "x": -11,
      "y": 11,
      "z": -11,
      "name": "Plant_Coral_Block_Blue"
    },
    {
      "x": -11,
      "y": 12,
      "z": -11,
      "name": "Plant_Coral_Block_Blue"
    },
    {
      "x": -11,
      "y": 10,
      "z": -10,
      "name": "Plant_Coral_Block_Blue"
    },
    {
      "x": -11,
      "y": 11,
      "z": -10,
      "name": "Plant_Coral_Block_Blue"
    },
    {
      "x": -11,
      "y": 12,
      "z": -10,
      "name": "Plant_Coral_Block_Blue"
    },
    {
      "x": -11,
      "y": 10,
      "z": -9,
      "name": "Plant_Coral_Block_Blue"
    },
    {
      "x": -11,
      "y": 11,
      "z": -9,
      "name": "Plant_Coral_Block_Blue"
    },
    {
      "x": -11,
      "y": 12,
      "z": -9,
      "name": "Plant_Coral_Block_Blue"
    },
    {
      "x": -11,
      "y": 10,
      "z": -8,
      "name": "Plant_Coral_Block_Blue"
    },
    {
      "x": -11,
      "y": 11,
      "z": -8,
      "name": "Plant_Coral_Block_Blue"
    },
    {
      "x": -11,
      "y": 12,
      "z": -8,
      "name": "Plant_Coral_Block_Blue"
    },
    {
      "x": -11,
      "y": 10,
      "z": -7,
      "name": "Plant_Coral_Block_Blue"
    },
    {
      "x": -11,
      "y": 11,
      "z": -7,
      "name": "Plant_Coral_Block_Blue"
    },
    {
      "x": -11,
      "y": 12,
      "z": -7,
      "name": "Plant_Coral_Block_Blue"
    },
    {
      "x": -11,
      "y": 10,
      "z": -6,
      "name": "Plant_Coral_Block_Blue"
    },
    {
      "x": -11,
      "y": 11,
      "z": -6,
      "name": "Plant_Coral_Block_Blue"
    },
    {
      "x": -11,
      "y": 12,
      "z": -6,
      "name": "Plant_Coral_Block_Blue"
    },
    {
      "x": -11,
      "y": 10,
      "z": -5,
      "name": "Plant_Coral_Block_Blue"
    },
    {
      "x": -11,
      "y": 11,
      "z": -5,
      "name": "Plant_Coral_Block_Blue"
    },
    {
      "x": -11,
      "y": 12,
      "z": -5,
      "name": "Plant_Coral_Block_Blue"
    },
    {
      "x": -11,
      "y": 10,
      "z": -4,
      "name": "Plant_Coral_Block_Blue"
    },
    {
      "x": -11,
      "y": 11,
      "z": -4,
      "name": "Plant_Coral_Block_Blue"
    },
    {
      "x": -11,
      "y": 12,
      "z": -4,
      "name": "Plant_Coral_Block_Blue"
    },
    {
      "x": -11,
      "y": 10,
      "z": -3,
      "name": "Plant_Coral_Block_Blue"
    },
    {
      "x": -11,
      "y": 11,
      "z": -3,
      "name": "Plant_Coral_Block_Blue"
    },
    {
      "x": -11,
      "y": 12,
      "z": -3,
      "name": "Plant_Coral_Block_Blue"
    },
    {
      "x": -11,
      "y": 10,
      "z": -2,
      "name": "Plant_Coral_Block_Blue"
    },
    {
      "x": -11,
      "y": 11,
      "z": -2,
      "name": "Plant_Coral_Block_Blue"
    },
    {
      "x": -11,
      "y": 12,
      "z": -2,
      "name": "Plant_Coral_Block_Blue"
    },
    {
      "x": -11,
      "y": 10,
      "z": -1,
      "name": "Plant_Coral_Block_Blue"
    },
    {
      "x": -11,
      "y": 11,
      "z": -1,
      "name": "Plant_Coral_Block_Blue"
    },
    {
      "x": -11,
      "y": 12,
      "z": -1,
      "name": "Plant_Coral_Block_Blue"
    },
    {
      "x": -11,
      "y": 10,
      "z": 0,
      "name": "Plant_Coral_Block_Blue"
    },
    {
      "x": -11,
      "y": 11,
      "z": 0,
      "name": "Plant_Coral_Block_Blue"
    },
    {
      "x": -11,
      "y": 12,
      "z": 0,
      "name": "Plant_Coral_Block_Blue"
    },
    {
      "x": -11,
      "y": 10,
      "z": 1,
      "name": "Plant_Coral_Block_Blue"
    },
    {
      "x": -11,
      "y": 11,
      "z": 1,
      "name": "Plant_Coral_Block_Blue"
    },
    {
      "x": -11,
      "y": 12,
      "z": 1,
      "name": "Plant_Coral_Block_Blue"
    },
    {
      "x": -11,
      "y": 10,
      "z": 2,
      "name": "Plant_Coral_Block_Blue"
    },
    {
      "x": -11,
      "y": 11,
      "z": 2,
      "name": "Plant_Coral_Block_Blue"
    },
    {
      "x": -11,
      "y": 12,
      "z": 2,
      "name": "Plant_Coral_Block_Blue"
    },
    {
      "x": -11,
      "y": 10,
      "z": 3,
      "name": "Plant_Coral_Block_Blue"
    },
    {
      "x": -11,
      "y": 11,
      "z": 3,
      "name": "Plant_Coral_Block_Blue"
    },
    {
      "x": -11,
      "y": 12,
      "z": 3,
      "name": "Plant_Coral_Block_Blue"
    },
    {
      "x": -11,
      "y": 10,
      "z": 4,
      "name": "Plant_Coral_Block_Blue"
    },
    {
      "x": -11,
      "y": 11,
      "z": 4,
      "name": "Plant_Coral_Block_Blue"
    },
    {
      "x": -11,
      "y": 12,
      "z": 4,
      "name": "Plant_Coral_Block_Blue"
    },
    {
      "x": -11,
      "y": 10,
      "z": 5,
      "name": "Plant_Coral_Block_Blue"
    },
    {
      "x": -11,
      "y": 11,
      "z": 5,
      "name": "Plant_Coral_Block_Blue"
    },
    {
      "x": -11,
      "y": 12,
      "z": 5,
      "name": "Plant_Coral_Block_Blue"
    },
    {
      "x": -11,
      "y": 10,
      "z": 6,
      "name": "Plant_Coral_Block_Blue"
    },
    {
      "x": -11,
      "y": 11,
      "z": 6,
      "name": "Plant_Coral_Block_Blue"
    },
    {
      "x": -11,
      "y": 12,
      "z": 6,
      "name": "Plant_Coral_Block_Blue"
    },
    {
      "x": -11,
      "y": 10,
      "z": 7,
      "name": "Plant_Coral_Block_Blue"
    },
    {
      "x": -11,
      "y": 11,
      "z": 7,
      "name": "Plant_Coral_Block_Blue"
    },
    {
      "x": -11,
      "y": 12,
      "z": 7,
      "name": "Plant_Coral_Block_Blue"
    },
    {
      "x": -11,
      "y": 10,
      "z": 8,
      "name": "Plant_Coral_Block_Blue"
    },
    {
      "x": -11,
      "y": 11,
      "z": 8,
      "name": "Plant_Coral_Block_Blue"
    },
    {
      "x": -11,
      "y": 12,
      "z": 8,
      "name": "Plant_Coral_Block_Blue"
    },
    {
      "x": -11,
      "y": 10,
      "z": 9,
      "name": "Plant_Coral_Block_Blue"
    },
    {
      "x": -11,
      "y": 11,
      "z": 9,
      "name": "Plant_Coral_Block_Blue"
    },
    {
      "x": -11,
      "y": 12,
      "z": 9,
      "name": "Plant_Coral_Block_Blue"
    },
    {
      "x": -11,
      "y": 10,
      "z": 10,
      "name": "Plant_Coral_Block_Blue"
    },
    {
      "x": -11,
      "y": 11,
      "z": 10,
      "name": "Plant_Coral_Block_Blue"
    },
    {
      "x": -11,
      "y": 12,
      "z": 10,
      "name": "Plant_Coral_Block_Blue"
    },
    {
      "x": -11,
      "y": 10,
      "z": 11,
      "name": "Plant_Coral_Block_Blue"
    },
    {
      "x": -11,
      "y": 11,
      "z": 11,
      "name": "Plant_Coral_Block_Blue"
    },
    {
      "x": -11,
      "y": 12,
      "z": 11,
      "name": "Plant_Coral_Block_Blue"
    },
    {
      "x": -11,
      "y": 10,
      "z": 12,
      "name": "Plant_Coral_Block_Blue"
    },
    {
      "x": -11,
      "y": 11,
      "z": 12,
      "name": "Plant_Coral_Block_Blue"
    },
    {
      "x": -11,
      "y": 12,
      "z": 12,
      "name": "Plant_Coral_Block_Blue"
    },
    {
      "x": -11,
      "y": 10,
      "z": 13,
      "name": "Plant_Coral_Block_Blue"
    },
    {
      "x": -11,
      "y": 11,
      "z": 13,
      "name": "Plant_Coral_Block_Blue"
    },
    {
      "x": -11,
      "y": 12,
      "z": 13,
      "name": "Plant_Coral_Block_Blue"
    },
    {
      "x": -11,
      "y": 10,
      "z": 14,
      "name": "Plant_Coral_Block_Cyan"
    },
    {
      "x": -11,
      "y": 11,
      "z": 14,
      "name": "Plant_Coral_Block_Cyan"
    },
    {
      "x": -11,
      "y": 12,
      "z": 14,
      "name": "Plant_Coral_Block_Cyan"
    },
    {
      "x": -11,
      "y": 10,
      "z": 15,
      "name": "Rock_Crystal_Cyan_Medium",
      "rotation": 8
    },
    {
      "x": -11,
      "y": 11,
      "z": 15,
      "name": "Plant_Coral_Block_Cyan"
    },
    {
      "x": -11,
      "y": 12,
      "z": 15,
      "name": "Plant_Coral_Block_Cyan"
    },
    {
      "x": -10,
      "y": 10,
      "z": -16,
      "name": "Plant_Coral_Block_Cyan"
    },
    {
      "x": -10,
      "y": 10,
      "z": -15,
      "name": "Plant_Coral_Block_Cyan"
    },
    {
      "x": -10,
      "y": 11,
      "z": -15,
      "name": "Plant_Coral_Block_Cyan"
    },
    {
      "x": -10,
      "y": 12,
      "z": -15,
      "name": "Plant_Coral_Block_Cyan"
    },
    {
      "x": -10,
      "y": 10,
      "z": -14,
      "name": "Plant_Coral_Block_Blue"
    },
    {
      "x": -10,
      "y": 11,
      "z": -14,
      "name": "Plant_Coral_Block_Blue"
    },
    {
      "x": -10,
      "y": 12,
      "z": -14,
      "name": "Plant_Coral_Block_Blue"
    },
    {
      "x": -10,
      "y": 10,
      "z": -13,
      "name": "Plant_Coral_Block_Blue"
    },
    {
      "x": -10,
      "y": 11,
      "z": -13,
      "name": "Plant_Coral_Block_Blue"
    },
    {
      "x": -10,
      "y": 12,
      "z": -13,
      "name": "Plant_Coral_Block_Blue"
    },
    {
      "x": -10,
      "y": 10,
      "z": -12,
      "name": "Plant_Coral_Block_Blue"
    },
    {
      "x": -10,
      "y": 11,
      "z": -12,
      "name": "Plant_Coral_Block_Blue"
    },
    {
      "x": -10,
      "y": 12,
      "z": -12,
      "name": "Plant_Coral_Block_Blue"
    },
    {
      "x": -10,
      "y": 10,
      "z": -11,
      "name": "Plant_Coral_Block_Blue"
    },
    {
      "x": -10,
      "y": 11,
      "z": -11,
      "name": "Plant_Coral_Block_Blue"
    },
    {
      "x": -10,
      "y": 12,
      "z": -11,
      "name": "Plant_Coral_Block_Blue"
    },
    {
      "x": -10,
      "y": 10,
      "z": -10,
      "name": "Plant_Coral_Block_Blue"
    },
    {
      "x": -10,
      "y": 11,
      "z": -10,
      "name": "Plant_Coral_Block_Blue"
    },
    {
      "x": -10,
      "y": 12,
      "z": -10,
      "name": "Plant_Coral_Block_Blue"
    },
    {
      "x": -10,
      "y": 10,
      "z": -9,
      "name": "Plant_Coral_Block_Blue"
    },
    {
      "x": -10,
      "y": 11,
      "z": -9,
      "name": "Plant_Coral_Block_Blue"
    },
    {
      "x": -10,
      "y": 12,
      "z": -9,
      "name": "Plant_Coral_Block_Blue"
    },
    {
      "x": -10,
      "y": 10,
      "z": -8,
      "name": "Plant_Coral_Block_Blue"
    },
    {
      "x": -10,
      "y": 11,
      "z": -8,
      "name": "Plant_Coral_Block_Blue"
    },
    {
      "x": -10,
      "y": 12,
      "z": -8,
      "name": "Plant_Coral_Block_Blue"
    },
    {
      "x": -10,
      "y": 10,
      "z": -7,
      "name": "Plant_Coral_Block_Blue"
    },
    {
      "x": -10,
      "y": 11,
      "z": -7,
      "name": "Plant_Coral_Block_Blue"
    },
    {
      "x": -10,
      "y": 12,
      "z": -7,
      "name": "Plant_Coral_Block_Blue"
    },
    {
      "x": -10,
      "y": 10,
      "z": -6,
      "name": "Plant_Coral_Block_Blue"
    },
    {
      "x": -10,
      "y": 11,
      "z": -6,
      "name": "Plant_Coral_Block_Blue"
    },
    {
      "x": -10,
      "y": 12,
      "z": -6,
      "name": "Plant_Coral_Block_Blue"
    },
    {
      "x": -10,
      "y": 10,
      "z": -5,
      "name": "Plant_Coral_Block_Blue"
    },
    {
      "x": -10,
      "y": 11,
      "z": -5,
      "name": "Plant_Coral_Block_Blue"
    },
    {
      "x": -10,
      "y": 12,
      "z": -5,
      "name": "Plant_Coral_Block_Blue"
    },
    {
      "x": -10,
      "y": 10,
      "z": -4,
      "name": "Plant_Coral_Block_Blue"
    },
    {
      "x": -10,
      "y": 11,
      "z": -4,
      "name": "Plant_Coral_Block_Blue"
    },
    {
      "x": -10,
      "y": 12,
      "z": -4,
      "name": "Plant_Coral_Block_Blue"
    },
    {
      "x": -10,
      "y": 10,
      "z": -3,
      "name": "Plant_Coral_Block_Blue"
    },
    {
      "x": -10,
      "y": 11,
      "z": -3,
      "name": "Plant_Coral_Block_Blue"
    },
    {
      "x": -10,
      "y": 12,
      "z": -3,
      "name": "Plant_Coral_Block_Blue"
    },
    {
      "x": -10,
      "y": 10,
      "z": -2,
      "name": "Plant_Coral_Block_Blue"
    },
    {
      "x": -10,
      "y": 11,
      "z": -2,
      "name": "Plant_Coral_Block_Blue"
    },
    {
      "x": -10,
      "y": 12,
      "z": -2,
      "name": "Plant_Coral_Block_Blue"
    },
    {
      "x": -10,
      "y": 10,
      "z": -1,
      "name": "Plant_Coral_Block_Blue"
    },
    {
      "x": -10,
      "y": 11,
      "z": -1,
      "name": "Plant_Coral_Block_Blue"
    },
    {
      "x": -10,
      "y": 12,
      "z": -1,
      "name": "Plant_Coral_Block_Blue"
    },
    {
      "x": -10,
      "y": 10,
      "z": 0,
      "name": "Plant_Coral_Block_Blue"
    },
    {
      "x": -10,
      "y": 11,
      "z": 0,
      "name": "Plant_Coral_Block_Blue"
    },
    {
      "x": -10,
      "y": 12,
      "z": 0,
      "name": "Plant_Coral_Block_Blue"
    },
    {
      "x": -10,
      "y": 10,
      "z": 1,
      "name": "Plant_Coral_Block_Blue"
    },
    {
      "x": -10,
      "y": 11,
      "z": 1,
      "name": "Plant_Coral_Block_Blue"
    },
    {
      "x": -10,
      "y": 12,
      "z": 1,
      "name": "Plant_Coral_Block_Blue"
    },
    {
      "x": -10,
      "y": 10,
      "z": 2,
      "name": "Plant_Coral_Block_Blue"
    },
    {
      "x": -10,
      "y": 11,
      "z": 2,
      "name": "Plant_Coral_Block_Blue"
    },
    {
      "x": -10,
      "y": 12,
      "z": 2,
      "name": "Plant_Coral_Block_Blue"
    },
    {
      "x": -10,
      "y": 10,
      "z": 3,
      "name": "Plant_Coral_Block_Blue"
    },
    {
      "x": -10,
      "y": 11,
      "z": 3,
      "name": "Plant_Coral_Block_Blue"
    },
    {
      "x": -10,
      "y": 12,
      "z": 3,
      "name": "Plant_Coral_Block_Blue"
    },
    {
      "x": -10,
      "y": 10,
      "z": 4,
      "name": "Plant_Coral_Block_Blue"
    },
    {
      "x": -10,
      "y": 11,
      "z": 4,
      "name": "Plant_Coral_Block_Blue"
    },
    {
      "x": -10,
      "y": 12,
      "z": 4,
      "name": "Plant_Coral_Block_Blue"
    },
    {
      "x": -10,
      "y": 10,
      "z": 5,
      "name": "Plant_Coral_Block_Blue"
    },
    {
      "x": -10,
      "y": 11,
      "z": 5,
      "name": "Plant_Coral_Block_Blue"
    },
    {
      "x": -10,
      "y": 12,
      "z": 5,
      "name": "Plant_Coral_Block_Blue"
    },
    {
      "x": -10,
      "y": 10,
      "z": 6,
      "name": "Plant_Coral_Block_Blue"
    },
    {
      "x": -10,
      "y": 11,
      "z": 6,
      "name": "Plant_Coral_Block_Blue"
    },
    {
      "x": -10,
      "y": 12,
      "z": 6,
      "name": "Plant_Coral_Block_Blue"
    },
    {
      "x": -10,
      "y": 10,
      "z": 7,
      "name": "Plant_Coral_Block_Blue"
    },
    {
      "x": -10,
      "y": 11,
      "z": 7,
      "name": "Plant_Coral_Block_Blue"
    },
    {
      "x": -10,
      "y": 12,
      "z": 7,
      "name": "Plant_Coral_Block_Blue"
    },
    {
      "x": -10,
      "y": 10,
      "z": 8,
      "name": "Plant_Coral_Block_Blue"
    },
    {
      "x": -10,
      "y": 11,
      "z": 8,
      "name": "Plant_Coral_Block_Blue"
    },
    {
      "x": -10,
      "y": 12,
      "z": 8,
      "name": "Plant_Coral_Block_Blue"
    },
    {
      "x": -10,
      "y": 10,
      "z": 9,
      "name": "Plant_Coral_Block_Blue"
    },
    {
      "x": -10,
      "y": 11,
      "z": 9,
      "name": "Plant_Coral_Block_Blue"
    },
    {
      "x": -10,
      "y": 12,
      "z": 9,
      "name": "Plant_Coral_Block_Blue"
    },
    {
      "x": -10,
      "y": 10,
      "z": 10,
      "name": "Plant_Coral_Block_Blue"
    },
    {
      "x": -10,
      "y": 11,
      "z": 10,
      "name": "Plant_Coral_Block_Blue"
    },
    {
      "x": -10,
      "y": 12,
      "z": 10,
      "name": "Plant_Coral_Block_Blue"
    },
    {
      "x": -10,
      "y": 10,
      "z": 11,
      "name": "Plant_Coral_Block_Blue"
    },
    {
      "x": -10,
      "y": 11,
      "z": 11,
      "name": "Plant_Coral_Block_Blue"
    },
    {
      "x": -10,
      "y": 12,
      "z": 11,
      "name": "Plant_Coral_Block_Blue"
    },
    {
      "x": -10,
      "y": 10,
      "z": 12,
      "name": "Plant_Coral_Block_Blue"
    },
    {
      "x": -10,
      "y": 11,
      "z": 12,
      "name": "Plant_Coral_Block_Blue"
    },
    {
      "x": -10,
      "y": 12,
      "z": 12,
      "name": "Plant_Coral_Block_Blue"
    },
    {
      "x": -10,
      "y": 10,
      "z": 13,
      "name": "Plant_Coral_Block_Blue"
    },
    {
      "x": -10,
      "y": 11,
      "z": 13,
      "name": "Plant_Coral_Block_Blue"
    },
    {
      "x": -10,
      "y": 12,
      "z": 13,
      "name": "Plant_Coral_Block_Blue"
    },
    {
      "x": -10,
      "y": 10,
      "z": 14,
      "name": "Plant_Coral_Block_Blue"
    },
    {
      "x": -10,
      "y": 11,
      "z": 14,
      "name": "Plant_Coral_Block_Blue"
    },
    {
      "x": -10,
      "y": 12,
      "z": 14,
      "name": "Plant_Coral_Block_Blue"
    },
    {
      "x": -10,
      "y": 10,
      "z": 15,
      "name": "Plant_Coral_Block_Cyan"
    },
    {
      "x": -10,
      "y": 11,
      "z": 15,
      "name": "Plant_Coral_Block_Cyan"
    },
    {
      "x": -10,
      "y": 12,
      "z": 15,
      "name": "Plant_Coral_Block_Cyan"
    },
    {
      "x": -9,
      "y": 10,
      "z": -16,
      "name": "Plant_Coral_Block_Cyan"
    },
    {
      "x": -9,
      "y": 12,
      "z": -16,
      "name": "Plant_Coral_Block_Cyan"
    },
    {
      "x": -9,
      "y": 10,
      "z": -15,
      "name": "Plant_Coral_Block_Cyan"
    },
    {
      "x": -9,
      "y": 11,
      "z": -15,
      "name": "Plant_Coral_Block_Cyan"
    },
    {
      "x": -9,
      "y": 12,
      "z": -15,
      "name": "Plant_Coral_Block_Cyan"
    },
    {
      "x": -9,
      "y": 10,
      "z": -14,
      "name": "Plant_Coral_Block_Blue"
    },
    {
      "x": -9,
      "y": 11,
      "z": -14,
      "name": "Plant_Coral_Block_Blue"
    },
    {
      "x": -9,
      "y": 12,
      "z": -14,
      "name": "Plant_Coral_Block_Blue"
    },
    {
      "x": -9,
      "y": 10,
      "z": -13,
      "name": "Plant_Coral_Block_Blue"
    },
    {
      "x": -9,
      "y": 11,
      "z": -13,
      "name": "Plant_Coral_Block_Blue"
    },
    {
      "x": -9,
      "y": 12,
      "z": -13,
      "name": "Plant_Coral_Block_Blue"
    },
    {
      "x": -9,
      "y": 10,
      "z": -12,
      "name": "Plant_Coral_Block_Blue"
    },
    {
      "x": -9,
      "y": 11,
      "z": -12,
      "name": "Plant_Coral_Block_Blue"
    },
    {
      "x": -9,
      "y": 12,
      "z": -12,
      "name": "Plant_Coral_Block_Blue"
    },
    {
      "x": -9,
      "y": 10,
      "z": -11,
      "name": "Plant_Coral_Block_Blue"
    },
    {
      "x": -9,
      "y": 11,
      "z": -11,
      "name": "Plant_Coral_Block_Blue"
    },
    {
      "x": -9,
      "y": 12,
      "z": -11,
      "name": "Plant_Coral_Block_Blue"
    },
    {
      "x": -9,
      "y": 10,
      "z": -10,
      "name": "Plant_Coral_Block_Blue"
    },
    {
      "x": -9,
      "y": 11,
      "z": -10,
      "name": "Plant_Coral_Block_Blue"
    },
    {
      "x": -9,
      "y": 12,
      "z": -10,
      "name": "Plant_Coral_Block_Blue"
    },
    {
      "x": -9,
      "y": 10,
      "z": -9,
      "name": "Plant_Coral_Block_Blue"
    },
    {
      "x": -9,
      "y": 11,
      "z": -9,
      "name": "Plant_Coral_Block_Blue"
    },
    {
      "x": -9,
      "y": 12,
      "z": -9,
      "name": "Plant_Coral_Block_Blue"
    },
    {
      "x": -9,
      "y": 10,
      "z": -8,
      "name": "Plant_Coral_Block_Blue"
    },
    {
      "x": -9,
      "y": 11,
      "z": -8,
      "name": "Plant_Coral_Block_Blue"
    },
    {
      "x": -9,
      "y": 12,
      "z": -8,
      "name": "Plant_Coral_Block_Blue"
    },
    {
      "x": -9,
      "y": 10,
      "z": -7,
      "name": "Plant_Coral_Block_Blue"
    },
    {
      "x": -9,
      "y": 11,
      "z": -7,
      "name": "Plant_Coral_Block_Blue"
    },
    {
      "x": -9,
      "y": 12,
      "z": -7,
      "name": "Plant_Coral_Block_Blue"
    },
    {
      "x": -9,
      "y": 10,
      "z": -6,
      "name": "Plant_Coral_Block_Blue"
    },
    {
      "x": -9,
      "y": 11,
      "z": -6,
      "name": "Plant_Coral_Block_Blue"
    },
    {
      "x": -9,
      "y": 12,
      "z": -6,
      "name": "Plant_Coral_Block_Blue"
    },
    {
      "x": -9,
      "y": 10,
      "z": -5,
      "name": "Plant_Coral_Block_Blue"
    },
    {
      "x": -9,
      "y": 11,
      "z": -5,
      "name": "Plant_Coral_Block_Blue"
    },
    {
      "x": -9,
      "y": 12,
      "z": -5,
      "name": "Plant_Coral_Block_Blue"
    },
    {
      "x": -9,
      "y": 10,
      "z": -4,
      "name": "Plant_Coral_Block_Blue"
    },
    {
      "x": -9,
      "y": 11,
      "z": -4,
      "name": "Plant_Coral_Block_Blue"
    },
    {
      "x": -9,
      "y": 12,
      "z": -4,
      "name": "Plant_Coral_Block_Blue"
    },
    {
      "x": -9,
      "y": 10,
      "z": -3,
      "name": "Plant_Coral_Block_Blue"
    },
    {
      "x": -9,
      "y": 11,
      "z": -3,
      "name": "Plant_Coral_Block_Blue"
    },
    {
      "x": -9,
      "y": 12,
      "z": -3,
      "name": "Plant_Coral_Block_Blue"
    },
    {
      "x": -9,
      "y": 10,
      "z": -2,
      "name": "Plant_Coral_Block_Blue"
    },
    {
      "x": -9,
      "y": 11,
      "z": -2,
      "name": "Plant_Coral_Block_Blue"
    },
    {
      "x": -9,
      "y": 12,
      "z": -2,
      "name": "Plant_Coral_Block_Blue"
    },
    {
      "x": -9,
      "y": 10,
      "z": -1,
      "name": "Plant_Coral_Block_Blue"
    },
    {
      "x": -9,
      "y": 11,
      "z": -1,
      "name": "Plant_Coral_Block_Blue"
    },
    {
      "x": -9,
      "y": 12,
      "z": -1,
      "name": "Plant_Coral_Block_Blue"
    },
    {
      "x": -9,
      "y": 10,
      "z": 0,
      "name": "Plant_Coral_Block_Blue"
    },
    {
      "x": -9,
      "y": 11,
      "z": 0,
      "name": "Plant_Coral_Block_Blue"
    },
    {
      "x": -9,
      "y": 12,
      "z": 0,
      "name": "Plant_Coral_Block_Blue"
    },
    {
      "x": -9,
      "y": 10,
      "z": 1,
      "name": "Plant_Coral_Block_Blue"
    },
    {
      "x": -9,
      "y": 11,
      "z": 1,
      "name": "Plant_Coral_Block_Blue"
    },
    {
      "x": -9,
      "y": 12,
      "z": 1,
      "name": "Plant_Coral_Block_Blue"
    },
    {
      "x": -9,
      "y": 10,
      "z": 2,
      "name": "Plant_Coral_Block_Blue"
    },
    {
      "x": -9,
      "y": 11,
      "z": 2,
      "name": "Plant_Coral_Block_Blue"
    },
    {
      "x": -9,
      "y": 12,
      "z": 2,
      "name": "Plant_Coral_Block_Blue"
    },
    {
      "x": -9,
      "y": 10,
      "z": 3,
      "name": "Plant_Coral_Block_Blue"
    },
    {
      "x": -9,
      "y": 11,
      "z": 3,
      "name": "Plant_Coral_Block_Blue"
    },
    {
      "x": -9,
      "y": 12,
      "z": 3,
      "name": "Plant_Coral_Block_Blue"
    },
    {
      "x": -9,
      "y": 10,
      "z": 4,
      "name": "Plant_Coral_Block_Blue"
    },
    {
      "x": -9,
      "y": 11,
      "z": 4,
      "name": "Plant_Coral_Block_Blue"
    },
    {
      "x": -9,
      "y": 12,
      "z": 4,
      "name": "Plant_Coral_Block_Blue"
    },
    {
      "x": -9,
      "y": 10,
      "z": 5,
      "name": "Plant_Coral_Block_Blue"
    },
    {
      "x": -9,
      "y": 11,
      "z": 5,
      "name": "Plant_Coral_Block_Blue"
    },
    {
      "x": -9,
      "y": 12,
      "z": 5,
      "name": "Plant_Coral_Block_Blue"
    },
    {
      "x": -9,
      "y": 10,
      "z": 6,
      "name": "Plant_Coral_Block_Blue"
    },
    {
      "x": -9,
      "y": 11,
      "z": 6,
      "name": "Plant_Coral_Block_Blue"
    },
    {
      "x": -9,
      "y": 12,
      "z": 6,
      "name": "Plant_Coral_Block_Blue"
    },
    {
      "x": -9,
      "y": 10,
      "z": 7,
      "name": "Plant_Coral_Block_Blue"
    },
    {
      "x": -9,
      "y": 11,
      "z": 7,
      "name": "Plant_Coral_Block_Blue"
    },
    {
      "x": -9,
      "y": 12,
      "z": 7,
      "name": "Plant_Coral_Block_Blue"
    },
    {
      "x": -9,
      "y": 10,
      "z": 8,
      "name": "Plant_Coral_Block_Blue"
    },
    {
      "x": -9,
      "y": 11,
      "z": 8,
      "name": "Plant_Coral_Block_Blue"
    },
    {
      "x": -9,
      "y": 12,
      "z": 8,
      "name": "Plant_Coral_Block_Blue"
    },
    {
      "x": -9,
      "y": 10,
      "z": 9,
      "name": "Plant_Coral_Block_Blue"
    },
    {
      "x": -9,
      "y": 11,
      "z": 9,
      "name": "Plant_Coral_Block_Blue"
    },
    {
      "x": -9,
      "y": 12,
      "z": 9,
      "name": "Plant_Coral_Block_Blue"
    },
    {
      "x": -9,
      "y": 10,
      "z": 10,
      "name": "Plant_Coral_Block_Blue"
    },
    {
      "x": -9,
      "y": 11,
      "z": 10,
      "name": "Plant_Coral_Block_Blue"
    },
    {
      "x": -9,
      "y": 12,
      "z": 10,
      "name": "Plant_Coral_Block_Blue"
    },
    {
      "x": -9,
      "y": 10,
      "z": 11,
      "name": "Plant_Coral_Block_Blue"
    },
    {
      "x": -9,
      "y": 11,
      "z": 11,
      "name": "Plant_Coral_Block_Blue"
    },
    {
      "x": -9,
      "y": 12,
      "z": 11,
      "name": "Plant_Coral_Block_Blue"
    },
    {
      "x": -9,
      "y": 10,
      "z": 12,
      "name": "Plant_Coral_Block_Blue"
    },
    {
      "x": -9,
      "y": 11,
      "z": 12,
      "name": "Plant_Coral_Block_Blue"
    },
    {
      "x": -9,
      "y": 12,
      "z": 12,
      "name": "Plant_Coral_Block_Blue"
    },
    {
      "x": -9,
      "y": 10,
      "z": 13,
      "name": "Plant_Coral_Block_Blue"
    },
    {
      "x": -9,
      "y": 11,
      "z": 13,
      "name": "Plant_Coral_Block_Blue"
    },
    {
      "x": -9,
      "y": 12,
      "z": 13,
      "name": "Plant_Coral_Block_Blue"
    },
    {
      "x": -9,
      "y": 10,
      "z": 14,
      "name": "Plant_Coral_Block_Blue"
    },
    {
      "x": -9,
      "y": 11,
      "z": 14,
      "name": "Plant_Coral_Block_Blue"
    },
    {
      "x": -9,
      "y": 12,
      "z": 14,
      "name": "Plant_Coral_Block_Blue"
    },
    {
      "x": -9,
      "y": 10,
      "z": 15,
      "name": "Plant_Coral_Block_Cyan"
    },
    {
      "x": -9,
      "y": 11,
      "z": 15,
      "name": "Plant_Coral_Block_Cyan"
    },
    {
      "x": -9,
      "y": 12,
      "z": 15,
      "name": "Plant_Coral_Block_Cyan"
    },
    {
      "x": -9,
      "y": 11,
      "z": 16,
      "name": "Plant_Coral_Block_Cyan"
    },
    {
      "x": -9,
      "y": 12,
      "z": 16,
      "name": "Plant_Coral_Block_Cyan"
    },
    {
      "x": -8,
      "y": 10,
      "z": -16,
      "name": "Plant_Coral_Block_Cyan"
    },
    {
      "x": -8,
      "y": 11,
      "z": -16,
      "name": "Plant_Coral_Block_Cyan"
    },
    {
      "x": -8,
      "y": 12,
      "z": -16,
      "name": "Plant_Coral_Block_Cyan"
    },
    {
      "x": -8,
      "y": 10,
      "z": -15,
      "name": "Plant_Coral_Block_Blue"
    },
    {
      "x": -8,
      "y": 11,
      "z": -15,
      "name": "Plant_Coral_Block_Blue"
    },
    {
      "x": -8,
      "y": 12,
      "z": -15,
      "name": "Plant_Coral_Block_Blue"
    },
    {
      "x": -8,
      "y": 10,
      "z": -14,
      "name": "Plant_Coral_Block_Blue"
    },
    {
      "x": -8,
      "y": 11,
      "z": -14,
      "name": "Plant_Coral_Block_Blue"
    },
    {
      "x": -8,
      "y": 12,
      "z": -14,
      "name": "Plant_Coral_Block_Blue"
    },
    {
      "x": -8,
      "y": 10,
      "z": -13,
      "name": "Plant_Coral_Block_Blue"
    },
    {
      "x": -8,
      "y": 11,
      "z": -13,
      "name": "Plant_Coral_Block_Blue"
    },
    {
      "x": -8,
      "y": 12,
      "z": -13,
      "name": "Plant_Coral_Block_Blue"
    },
    {
      "x": -8,
      "y": 10,
      "z": -12,
      "name": "Plant_Coral_Block_Blue"
    },
    {
      "x": -8,
      "y": 11,
      "z": -12,
      "name": "Plant_Coral_Block_Blue"
    },
    {
      "x": -8,
      "y": 12,
      "z": -12,
      "name": "Plant_Coral_Block_Blue"
    },
    {
      "x": -8,
      "y": 10,
      "z": -11,
      "name": "Plant_Coral_Block_Blue"
    },
    {
      "x": -8,
      "y": 11,
      "z": -11,
      "name": "Plant_Coral_Block_Blue"
    },
    {
      "x": -8,
      "y": 12,
      "z": -11,
      "name": "Plant_Coral_Block_Blue"
    },
    {
      "x": -8,
      "y": 10,
      "z": -10,
      "name": "Plant_Coral_Block_Blue"
    },
    {
      "x": -8,
      "y": 11,
      "z": -10,
      "name": "Plant_Coral_Block_Blue"
    },
    {
      "x": -8,
      "y": 12,
      "z": -10,
      "name": "Plant_Coral_Block_Blue"
    },
    {
      "x": -8,
      "y": 10,
      "z": -9,
      "name": "Plant_Coral_Block_Blue"
    },
    {
      "x": -8,
      "y": 11,
      "z": -9,
      "name": "Plant_Coral_Block_Blue"
    },
    {
      "x": -8,
      "y": 12,
      "z": -9,
      "name": "Plant_Coral_Block_Blue"
    },
    {
      "x": -8,
      "y": 10,
      "z": -8,
      "name": "Plant_Coral_Block_Blue"
    },
    {
      "x": -8,
      "y": 11,
      "z": -8,
      "name": "Plant_Coral_Block_Blue"
    },
    {
      "x": -8,
      "y": 12,
      "z": -8,
      "name": "Plant_Coral_Block_Blue"
    },
    {
      "x": -8,
      "y": 10,
      "z": -7,
      "name": "Plant_Coral_Block_Blue"
    },
    {
      "x": -8,
      "y": 11,
      "z": -7,
      "name": "Plant_Coral_Block_Blue"
    },
    {
      "x": -8,
      "y": 12,
      "z": -7,
      "name": "Plant_Coral_Block_Blue"
    },
    {
      "x": -8,
      "y": 10,
      "z": -6,
      "name": "Plant_Coral_Block_Blue"
    },
    {
      "x": -8,
      "y": 11,
      "z": -6,
      "name": "Plant_Coral_Block_Blue"
    },
    {
      "x": -8,
      "y": 12,
      "z": -6,
      "name": "Plant_Coral_Block_Blue"
    },
    {
      "x": -8,
      "y": 10,
      "z": -5,
      "name": "Plant_Coral_Block_Blue"
    },
    {
      "x": -8,
      "y": 11,
      "z": -5,
      "name": "Plant_Coral_Block_Blue"
    },
    {
      "x": -8,
      "y": 12,
      "z": -5,
      "name": "Plant_Coral_Block_Blue"
    },
    {
      "x": -8,
      "y": 10,
      "z": -4,
      "name": "Plant_Coral_Block_Blue"
    },
    {
      "x": -8,
      "y": 11,
      "z": -4,
      "name": "Plant_Coral_Block_Blue"
    },
    {
      "x": -8,
      "y": 12,
      "z": -4,
      "name": "Plant_Coral_Block_Blue"
    },
    {
      "x": -8,
      "y": 10,
      "z": -3,
      "name": "Plant_Coral_Block_Blue"
    },
    {
      "x": -8,
      "y": 11,
      "z": -3,
      "name": "Plant_Coral_Block_Blue"
    },
    {
      "x": -8,
      "y": 12,
      "z": -3,
      "name": "Plant_Coral_Block_Blue"
    },
    {
      "x": -8,
      "y": 10,
      "z": -2,
      "name": "Plant_Coral_Block_Blue"
    },
    {
      "x": -8,
      "y": 11,
      "z": -2,
      "name": "Plant_Coral_Block_Blue"
    },
    {
      "x": -8,
      "y": 12,
      "z": -2,
      "name": "Plant_Coral_Block_Blue"
    },
    {
      "x": -8,
      "y": 10,
      "z": -1,
      "name": "Plant_Coral_Block_Blue"
    },
    {
      "x": -8,
      "y": 11,
      "z": -1,
      "name": "Plant_Coral_Block_Blue"
    },
    {
      "x": -8,
      "y": 12,
      "z": -1,
      "name": "Plant_Coral_Block_Blue"
    },
    {
      "x": -8,
      "y": 10,
      "z": 0,
      "name": "Plant_Coral_Block_Blue"
    },
    {
      "x": -8,
      "y": 11,
      "z": 0,
      "name": "Plant_Coral_Block_Blue"
    },
    {
      "x": -8,
      "y": 12,
      "z": 0,
      "name": "Plant_Coral_Block_Blue"
    },
    {
      "x": -8,
      "y": 10,
      "z": 1,
      "name": "Plant_Coral_Block_Blue"
    },
    {
      "x": -8,
      "y": 11,
      "z": 1,
      "name": "Plant_Coral_Block_Blue"
    },
    {
      "x": -8,
      "y": 12,
      "z": 1,
      "name": "Plant_Coral_Block_Blue"
    },
    {
      "x": -8,
      "y": 10,
      "z": 2,
      "name": "Plant_Coral_Block_Blue"
    },
    {
      "x": -8,
      "y": 11,
      "z": 2,
      "name": "Plant_Coral_Block_Blue"
    },
    {
      "x": -8,
      "y": 12,
      "z": 2,
      "name": "Plant_Coral_Block_Blue"
    },
    {
      "x": -8,
      "y": 10,
      "z": 3,
      "name": "Plant_Coral_Block_Blue"
    },
    {
      "x": -8,
      "y": 11,
      "z": 3,
      "name": "Plant_Coral_Block_Blue"
    },
    {
      "x": -8,
      "y": 12,
      "z": 3,
      "name": "Plant_Coral_Block_Blue"
    },
    {
      "x": -8,
      "y": 10,
      "z": 4,
      "name": "Plant_Coral_Block_Blue"
    },
    {
      "x": -8,
      "y": 11,
      "z": 4,
      "name": "Plant_Coral_Block_Blue"
    },
    {
      "x": -8,
      "y": 12,
      "z": 4,
      "name": "Plant_Coral_Block_Blue"
    },
    {
      "x": -8,
      "y": 10,
      "z": 5,
      "name": "Plant_Coral_Block_Blue"
    },
    {
      "x": -8,
      "y": 11,
      "z": 5,
      "name": "Plant_Coral_Block_Blue"
    },
    {
      "x": -8,
      "y": 12,
      "z": 5,
      "name": "Plant_Coral_Block_Blue"
    },
    {
      "x": -8,
      "y": 10,
      "z": 6,
      "name": "Plant_Coral_Block_Blue"
    },
    {
      "x": -8,
      "y": 11,
      "z": 6,
      "name": "Plant_Coral_Block_Blue"
    },
    {
      "x": -8,
      "y": 12,
      "z": 6,
      "name": "Plant_Coral_Block_Blue"
    },
    {
      "x": -8,
      "y": 10,
      "z": 7,
      "name": "Plant_Coral_Block_Blue"
    },
    {
      "x": -8,
      "y": 11,
      "z": 7,
      "name": "Plant_Coral_Block_Blue"
    },
    {
      "x": -8,
      "y": 12,
      "z": 7,
      "name": "Plant_Coral_Block_Blue"
    },
    {
      "x": -8,
      "y": 10,
      "z": 8,
      "name": "Plant_Coral_Block_Blue"
    },
    {
      "x": -8,
      "y": 11,
      "z": 8,
      "name": "Plant_Coral_Block_Blue"
    },
    {
      "x": -8,
      "y": 12,
      "z": 8,
      "name": "Plant_Coral_Block_Blue"
    },
    {
      "x": -8,
      "y": 10,
      "z": 9,
      "name": "Plant_Coral_Block_Blue"
    },
    {
      "x": -8,
      "y": 11,
      "z": 9,
      "name": "Plant_Coral_Block_Blue"
    },
    {
      "x": -8,
      "y": 12,
      "z": 9,
      "name": "Plant_Coral_Block_Blue"
    },
    {
      "x": -8,
      "y": 10,
      "z": 10,
      "name": "Plant_Coral_Block_Blue"
    },
    {
      "x": -8,
      "y": 11,
      "z": 10,
      "name": "Plant_Coral_Block_Blue"
    },
    {
      "x": -8,
      "y": 12,
      "z": 10,
      "name": "Plant_Coral_Block_Blue"
    },
    {
      "x": -8,
      "y": 10,
      "z": 11,
      "name": "Plant_Coral_Block_Blue"
    },
    {
      "x": -8,
      "y": 11,
      "z": 11,
      "name": "Plant_Coral_Block_Blue"
    },
    {
      "x": -8,
      "y": 12,
      "z": 11,
      "name": "Plant_Coral_Block_Blue"
    },
    {
      "x": -8,
      "y": 10,
      "z": 12,
      "name": "Plant_Coral_Block_Blue"
    },
    {
      "x": -8,
      "y": 11,
      "z": 12,
      "name": "Plant_Coral_Block_Blue"
    },
    {
      "x": -8,
      "y": 12,
      "z": 12,
      "name": "Plant_Coral_Block_Blue"
    },
    {
      "x": -8,
      "y": 10,
      "z": 13,
      "name": "Plant_Coral_Block_Blue"
    },
    {
      "x": -8,
      "y": 11,
      "z": 13,
      "name": "Plant_Coral_Block_Blue"
    },
    {
      "x": -8,
      "y": 12,
      "z": 13,
      "name": "Plant_Coral_Block_Blue"
    },
    {
      "x": -8,
      "y": 10,
      "z": 14,
      "name": "Plant_Coral_Block_Blue"
    },
    {
      "x": -8,
      "y": 11,
      "z": 14,
      "name": "Plant_Coral_Block_Blue"
    },
    {
      "x": -8,
      "y": 12,
      "z": 14,
      "name": "Plant_Coral_Block_Blue"
    },
    {
      "x": -8,
      "y": 10,
      "z": 15,
      "name": "Plant_Coral_Block_Blue"
    },
    {
      "x": -8,
      "y": 11,
      "z": 15,
      "name": "Plant_Coral_Block_Blue"
    },
    {
      "x": -8,
      "y": 12,
      "z": 15,
      "name": "Plant_Coral_Block_Blue"
    },
    {
      "x": -8,
      "y": 10,
      "z": 16,
      "name": "Plant_Coral_Block_Cyan"
    },
    {
      "x": -8,
      "y": 11,
      "z": 16,
      "name": "Plant_Coral_Block_Cyan"
    },
    {
      "x": -8,
      "y": 12,
      "z": 16,
      "name": "Plant_Coral_Block_Cyan"
    },
    {
      "x": -7,
      "y": 11,
      "z": -17,
      "name": "Rock_Crystal_Cyan_Medium",
      "rotation": 6
    },
    {
      "x": -7,
      "y": 12,
      "z": -17,
      "name": "Plant_Coral_Block_Cyan"
    },
    {
      "x": -7,
      "y": 10,
      "z": -16,
      "name": "Plant_Coral_Block_Cyan"
    },
    {
      "x": -7,
      "y": 11,
      "z": -16,
      "name": "Plant_Coral_Block_Cyan"
    },
    {
      "x": -7,
      "y": 12,
      "z": -16,
      "name": "Plant_Coral_Block_Cyan"
    },
    {
      "x": -7,
      "y": 10,
      "z": -15,
      "name": "Plant_Coral_Block_Blue"
    },
    {
      "x": -7,
      "y": 11,
      "z": -15,
      "name": "Plant_Coral_Block_Blue"
    },
    {
      "x": -7,
      "y": 12,
      "z": -15,
      "name": "Plant_Coral_Block_Blue"
    },
    {
      "x": -7,
      "y": 10,
      "z": -14,
      "name": "Plant_Coral_Block_Blue"
    },
    {
      "x": -7,
      "y": 11,
      "z": -14,
      "name": "Plant_Coral_Block_Blue"
    },
    {
      "x": -7,
      "y": 12,
      "z": -14,
      "name": "Plant_Coral_Block_Blue"
    },
    {
      "x": -7,
      "y": 10,
      "z": -13,
      "name": "Plant_Coral_Block_Blue"
    },
    {
      "x": -7,
      "y": 11,
      "z": -13,
      "name": "Plant_Coral_Block_Blue"
    },
    {
      "x": -7,
      "y": 12,
      "z": -13,
      "name": "Plant_Coral_Block_Blue"
    },
    {
      "x": -7,
      "y": 10,
      "z": -12,
      "name": "Plant_Coral_Block_Blue"
    },
    {
      "x": -7,
      "y": 11,
      "z": -12,
      "name": "Plant_Coral_Block_Blue"
    },
    {
      "x": -7,
      "y": 12,
      "z": -12,
      "name": "Plant_Coral_Block_Blue"
    },
    {
      "x": -7,
      "y": 10,
      "z": -11,
      "name": "Plant_Coral_Block_Blue"
    },
    {
      "x": -7,
      "y": 11,
      "z": -11,
      "name": "Plant_Coral_Block_Blue"
    },
    {
      "x": -7,
      "y": 12,
      "z": -11,
      "name": "Plant_Coral_Block_Blue"
    },
    {
      "x": -7,
      "y": 10,
      "z": -10,
      "name": "Plant_Coral_Block_Blue"
    },
    {
      "x": -7,
      "y": 11,
      "z": -10,
      "name": "Plant_Coral_Block_Blue"
    },
    {
      "x": -7,
      "y": 12,
      "z": -10,
      "name": "Plant_Coral_Block_Blue"
    },
    {
      "x": -7,
      "y": 10,
      "z": -9,
      "name": "Plant_Coral_Block_Blue"
    },
    {
      "x": -7,
      "y": 11,
      "z": -9,
      "name": "Plant_Coral_Block_Blue"
    },
    {
      "x": -7,
      "y": 12,
      "z": -9,
      "name": "Plant_Coral_Block_Blue"
    },
    {
      "x": -7,
      "y": 10,
      "z": -8,
      "name": "Plant_Coral_Block_Blue"
    },
    {
      "x": -7,
      "y": 11,
      "z": -8,
      "name": "Plant_Coral_Block_Blue"
    },
    {
      "x": -7,
      "y": 12,
      "z": -8,
      "name": "Plant_Coral_Block_Blue"
    },
    {
      "x": -7,
      "y": 10,
      "z": -7,
      "name": "Plant_Coral_Block_Blue"
    },
    {
      "x": -7,
      "y": 11,
      "z": -7,
      "name": "Plant_Coral_Block_Blue"
    },
    {
      "x": -7,
      "y": 12,
      "z": -7,
      "name": "Plant_Coral_Block_Blue"
    },
    {
      "x": -7,
      "y": 10,
      "z": -6,
      "name": "Plant_Coral_Block_Blue"
    },
    {
      "x": -7,
      "y": 11,
      "z": -6,
      "name": "Plant_Coral_Block_Blue"
    },
    {
      "x": -7,
      "y": 12,
      "z": -6,
      "name": "Plant_Coral_Block_Blue"
    },
    {
      "x": -7,
      "y": 10,
      "z": -5,
      "name": "Plant_Coral_Block_Blue"
    },
    {
      "x": -7,
      "y": 11,
      "z": -5,
      "name": "Plant_Coral_Block_Blue"
    },
    {
      "x": -7,
      "y": 12,
      "z": -5,
      "name": "Plant_Coral_Block_Blue"
    },
    {
      "x": -7,
      "y": 10,
      "z": -4,
      "name": "Plant_Coral_Block_Blue"
    },
    {
      "x": -7,
      "y": 11,
      "z": -4,
      "name": "Plant_Coral_Block_Blue"
    },
    {
      "x": -7,
      "y": 12,
      "z": -4,
      "name": "Plant_Coral_Block_Blue"
    },
    {
      "x": -7,
      "y": 10,
      "z": -3,
      "name": "Plant_Coral_Block_Blue"
    },
    {
      "x": -7,
      "y": 11,
      "z": -3,
      "name": "Plant_Coral_Block_Blue"
    },
    {
      "x": -7,
      "y": 12,
      "z": -3,
      "name": "Plant_Coral_Block_Blue"
    },
    {
      "x": -7,
      "y": 10,
      "z": -2,
      "name": "Plant_Coral_Block_Blue"
    },
    {
      "x": -7,
      "y": 11,
      "z": -2,
      "name": "Plant_Coral_Block_Blue"
    },
    {
      "x": -7,
      "y": 12,
      "z": -2,
      "name": "Plant_Coral_Block_Blue"
    },
    {
      "x": -7,
      "y": 10,
      "z": -1,
      "name": "Plant_Coral_Block_Blue"
    },
    {
      "x": -7,
      "y": 11,
      "z": -1,
      "name": "Plant_Coral_Block_Blue"
    },
    {
      "x": -7,
      "y": 12,
      "z": -1,
      "name": "Plant_Coral_Block_Blue"
    },
    {
      "x": -7,
      "y": 10,
      "z": 0,
      "name": "Plant_Coral_Block_Blue"
    },
    {
      "x": -7,
      "y": 11,
      "z": 0,
      "name": "Plant_Coral_Block_Blue"
    },
    {
      "x": -7,
      "y": 12,
      "z": 0,
      "name": "Plant_Coral_Block_Blue"
    },
    {
      "x": -7,
      "y": 10,
      "z": 1,
      "name": "Plant_Coral_Block_Blue"
    },
    {
      "x": -7,
      "y": 11,
      "z": 1,
      "name": "Plant_Coral_Block_Blue"
    },
    {
      "x": -7,
      "y": 12,
      "z": 1,
      "name": "Plant_Coral_Block_Blue"
    },
    {
      "x": -7,
      "y": 10,
      "z": 2,
      "name": "Plant_Coral_Block_Blue"
    },
    {
      "x": -7,
      "y": 11,
      "z": 2,
      "name": "Plant_Coral_Block_Blue"
    },
    {
      "x": -7,
      "y": 12,
      "z": 2,
      "name": "Plant_Coral_Block_Blue"
    },
    {
      "x": -7,
      "y": 10,
      "z": 3,
      "name": "Plant_Coral_Block_Blue"
    },
    {
      "x": -7,
      "y": 11,
      "z": 3,
      "name": "Plant_Coral_Block_Blue"
    },
    {
      "x": -7,
      "y": 12,
      "z": 3,
      "name": "Plant_Coral_Block_Blue"
    },
    {
      "x": -7,
      "y": 10,
      "z": 4,
      "name": "Plant_Coral_Block_Blue"
    },
    {
      "x": -7,
      "y": 11,
      "z": 4,
      "name": "Plant_Coral_Block_Blue"
    },
    {
      "x": -7,
      "y": 12,
      "z": 4,
      "name": "Plant_Coral_Block_Blue"
    },
    {
      "x": -7,
      "y": 10,
      "z": 5,
      "name": "Plant_Coral_Block_Blue"
    },
    {
      "x": -7,
      "y": 11,
      "z": 5,
      "name": "Plant_Coral_Block_Blue"
    },
    {
      "x": -7,
      "y": 12,
      "z": 5,
      "name": "Plant_Coral_Block_Blue"
    },
    {
      "x": -7,
      "y": 10,
      "z": 6,
      "name": "Plant_Coral_Block_Blue"
    },
    {
      "x": -7,
      "y": 11,
      "z": 6,
      "name": "Plant_Coral_Block_Blue"
    },
    {
      "x": -7,
      "y": 12,
      "z": 6,
      "name": "Plant_Coral_Block_Blue"
    },
    {
      "x": -7,
      "y": 10,
      "z": 7,
      "name": "Plant_Coral_Block_Blue"
    },
    {
      "x": -7,
      "y": 11,
      "z": 7,
      "name": "Plant_Coral_Block_Blue"
    },
    {
      "x": -7,
      "y": 12,
      "z": 7,
      "name": "Plant_Coral_Block_Blue"
    },
    {
      "x": -7,
      "y": 10,
      "z": 8,
      "name": "Plant_Coral_Block_Blue"
    },
    {
      "x": -7,
      "y": 11,
      "z": 8,
      "name": "Plant_Coral_Block_Blue"
    },
    {
      "x": -7,
      "y": 12,
      "z": 8,
      "name": "Plant_Coral_Block_Blue"
    },
    {
      "x": -7,
      "y": 10,
      "z": 9,
      "name": "Plant_Coral_Block_Blue"
    },
    {
      "x": -7,
      "y": 11,
      "z": 9,
      "name": "Plant_Coral_Block_Blue"
    },
    {
      "x": -7,
      "y": 12,
      "z": 9,
      "name": "Plant_Coral_Block_Blue"
    },
    {
      "x": -7,
      "y": 10,
      "z": 10,
      "name": "Plant_Coral_Block_Blue"
    },
    {
      "x": -7,
      "y": 11,
      "z": 10,
      "name": "Plant_Coral_Block_Blue"
    },
    {
      "x": -7,
      "y": 12,
      "z": 10,
      "name": "Plant_Coral_Block_Blue"
    },
    {
      "x": -7,
      "y": 10,
      "z": 11,
      "name": "Plant_Coral_Block_Blue"
    },
    {
      "x": -7,
      "y": 11,
      "z": 11,
      "name": "Plant_Coral_Block_Blue"
    },
    {
      "x": -7,
      "y": 12,
      "z": 11,
      "name": "Plant_Coral_Block_Blue"
    },
    {
      "x": -7,
      "y": 10,
      "z": 12,
      "name": "Plant_Coral_Block_Blue"
    },
    {
      "x": -7,
      "y": 11,
      "z": 12,
      "name": "Plant_Coral_Block_Blue"
    },
    {
      "x": -7,
      "y": 12,
      "z": 12,
      "name": "Plant_Coral_Block_Blue"
    },
    {
      "x": -7,
      "y": 10,
      "z": 13,
      "name": "Plant_Coral_Block_Blue"
    },
    {
      "x": -7,
      "y": 11,
      "z": 13,
      "name": "Plant_Coral_Block_Blue"
    },
    {
      "x": -7,
      "y": 12,
      "z": 13,
      "name": "Plant_Coral_Block_Blue"
    },
    {
      "x": -7,
      "y": 10,
      "z": 14,
      "name": "Plant_Coral_Block_Blue"
    },
    {
      "x": -7,
      "y": 11,
      "z": 14,
      "name": "Plant_Coral_Block_Blue"
    },
    {
      "x": -7,
      "y": 12,
      "z": 14,
      "name": "Plant_Coral_Block_Blue"
    },
    {
      "x": -7,
      "y": 10,
      "z": 15,
      "name": "Plant_Coral_Block_Blue"
    },
    {
      "x": -7,
      "y": 11,
      "z": 15,
      "name": "Plant_Coral_Block_Blue"
    },
    {
      "x": -7,
      "y": 12,
      "z": 15,
      "name": "Plant_Coral_Block_Blue"
    },
    {
      "x": -7,
      "y": 10,
      "z": 16,
      "name": "Plant_Coral_Block_Cyan"
    },
    {
      "x": -7,
      "y": 11,
      "z": 16,
      "name": "Plant_Coral_Block_Cyan"
    },
    {
      "x": -7,
      "y": 12,
      "z": 16,
      "name": "Plant_Coral_Block_Cyan"
    },
    {
      "x": -7,
      "y": 12,
      "z": 17,
      "name": "Plant_Coral_Block_Cyan"
    },
    {
      "x": -6,
      "y": 11,
      "z": -17,
      "name": "Plant_Coral_Block_Cyan"
    },
    {
      "x": -6,
      "y": 12,
      "z": -17,
      "name": "Plant_Coral_Block_Cyan"
    },
    {
      "x": -6,
      "y": 10,
      "z": -16,
      "name": "Plant_Coral_Block_Cyan"
    },
    {
      "x": -6,
      "y": 11,
      "z": -16,
      "name": "Plant_Coral_Block_Cyan"
    },
    {
      "x": -6,
      "y": 12,
      "z": -16,
      "name": "Plant_Coral_Block_Cyan"
    },
    {
      "x": -6,
      "y": 10,
      "z": -15,
      "name": "Plant_Coral_Block_Blue"
    },
    {
      "x": -6,
      "y": 11,
      "z": -15,
      "name": "Plant_Coral_Block_Blue"
    },
    {
      "x": -6,
      "y": 12,
      "z": -15,
      "name": "Plant_Coral_Block_Blue"
    },
    {
      "x": -6,
      "y": 10,
      "z": -14,
      "name": "Plant_Coral_Block_Blue"
    },
    {
      "x": -6,
      "y": 11,
      "z": -14,
      "name": "Plant_Coral_Block_Blue"
    },
    {
      "x": -6,
      "y": 12,
      "z": -14,
      "name": "Plant_Coral_Block_Blue"
    },
    {
      "x": -6,
      "y": 10,
      "z": -13,
      "name": "Plant_Coral_Block_Blue"
    },
    {
      "x": -6,
      "y": 11,
      "z": -13,
      "name": "Plant_Coral_Block_Blue"
    },
    {
      "x": -6,
      "y": 12,
      "z": -13,
      "name": "Plant_Coral_Block_Blue"
    },
    {
      "x": -6,
      "y": 10,
      "z": -12,
      "name": "Plant_Coral_Block_Blue"
    },
    {
      "x": -6,
      "y": 11,
      "z": -12,
      "name": "Plant_Coral_Block_Blue"
    },
    {
      "x": -6,
      "y": 12,
      "z": -12,
      "name": "Plant_Coral_Block_Blue"
    },
    {
      "x": -6,
      "y": 10,
      "z": -11,
      "name": "Plant_Coral_Block_Blue"
    },
    {
      "x": -6,
      "y": 11,
      "z": -11,
      "name": "Plant_Coral_Block_Blue"
    },
    {
      "x": -6,
      "y": 12,
      "z": -11,
      "name": "Plant_Coral_Block_Blue"
    },
    {
      "x": -6,
      "y": 10,
      "z": -10,
      "name": "Plant_Coral_Block_Blue"
    },
    {
      "x": -6,
      "y": 11,
      "z": -10,
      "name": "Plant_Coral_Block_Blue"
    },
    {
      "x": -6,
      "y": 12,
      "z": -10,
      "name": "Plant_Coral_Block_Blue"
    },
    {
      "x": -6,
      "y": 10,
      "z": -9,
      "name": "Plant_Coral_Block_Blue"
    },
    {
      "x": -6,
      "y": 11,
      "z": -9,
      "name": "Plant_Coral_Block_Blue"
    },
    {
      "x": -6,
      "y": 12,
      "z": -9,
      "name": "Plant_Coral_Block_Blue"
    },
    {
      "x": -6,
      "y": 10,
      "z": -8,
      "name": "Plant_Coral_Block_Blue"
    },
    {
      "x": -6,
      "y": 11,
      "z": -8,
      "name": "Plant_Coral_Block_Blue"
    },
    {
      "x": -6,
      "y": 12,
      "z": -8,
      "name": "Plant_Coral_Block_Blue"
    },
    {
      "x": -6,
      "y": 10,
      "z": -7,
      "name": "Plant_Coral_Block_Blue"
    },
    {
      "x": -6,
      "y": 11,
      "z": -7,
      "name": "Plant_Coral_Block_Blue"
    },
    {
      "x": -6,
      "y": 12,
      "z": -7,
      "name": "Plant_Coral_Block_Blue"
    },
    {
      "x": -6,
      "y": 10,
      "z": -6,
      "name": "Plant_Coral_Block_Blue"
    },
    {
      "x": -6,
      "y": 11,
      "z": -6,
      "name": "Plant_Coral_Block_Blue"
    },
    {
      "x": -6,
      "y": 12,
      "z": -6,
      "name": "Plant_Coral_Block_Blue"
    },
    {
      "x": -6,
      "y": 10,
      "z": -5,
      "name": "Plant_Coral_Block_Blue"
    },
    {
      "x": -6,
      "y": 11,
      "z": -5,
      "name": "Plant_Coral_Block_Blue"
    },
    {
      "x": -6,
      "y": 12,
      "z": -5,
      "name": "Plant_Coral_Block_Blue"
    },
    {
      "x": -6,
      "y": 10,
      "z": -4,
      "name": "Plant_Coral_Block_Blue"
    },
    {
      "x": -6,
      "y": 11,
      "z": -4,
      "name": "Plant_Coral_Block_Blue"
    },
    {
      "x": -6,
      "y": 12,
      "z": -4,
      "name": "Plant_Coral_Block_Blue"
    },
    {
      "x": -6,
      "y": 10,
      "z": -3,
      "name": "Plant_Coral_Block_Blue"
    },
    {
      "x": -6,
      "y": 11,
      "z": -3,
      "name": "Plant_Coral_Block_Blue"
    },
    {
      "x": -6,
      "y": 12,
      "z": -3,
      "name": "Plant_Coral_Block_Blue"
    },
    {
      "x": -6,
      "y": 10,
      "z": -2,
      "name": "Plant_Coral_Block_Blue"
    },
    {
      "x": -6,
      "y": 11,
      "z": -2,
      "name": "Plant_Coral_Block_Blue"
    },
    {
      "x": -6,
      "y": 12,
      "z": -2,
      "name": "Plant_Coral_Block_Blue"
    },
    {
      "x": -6,
      "y": 10,
      "z": -1,
      "name": "Plant_Coral_Block_Blue"
    },
    {
      "x": -6,
      "y": 11,
      "z": -1,
      "name": "Plant_Coral_Block_Blue"
    },
    {
      "x": -6,
      "y": 12,
      "z": -1,
      "name": "Plant_Coral_Block_Blue"
    },
    {
      "x": -6,
      "y": 10,
      "z": 0,
      "name": "Plant_Coral_Block_Blue"
    },
    {
      "x": -6,
      "y": 11,
      "z": 0,
      "name": "Plant_Coral_Block_Blue"
    },
    {
      "x": -6,
      "y": 12,
      "z": 0,
      "name": "Plant_Coral_Block_Blue"
    },
    {
      "x": -6,
      "y": 10,
      "z": 1,
      "name": "Plant_Coral_Block_Blue"
    },
    {
      "x": -6,
      "y": 11,
      "z": 1,
      "name": "Plant_Coral_Block_Blue"
    },
    {
      "x": -6,
      "y": 12,
      "z": 1,
      "name": "Plant_Coral_Block_Blue"
    },
    {
      "x": -6,
      "y": 10,
      "z": 2,
      "name": "Plant_Coral_Block_Blue"
    },
    {
      "x": -6,
      "y": 11,
      "z": 2,
      "name": "Plant_Coral_Block_Blue"
    },
    {
      "x": -6,
      "y": 12,
      "z": 2,
      "name": "Plant_Coral_Block_Blue"
    },
    {
      "x": -6,
      "y": 10,
      "z": 3,
      "name": "Plant_Coral_Block_Blue"
    },
    {
      "x": -6,
      "y": 11,
      "z": 3,
      "name": "Plant_Coral_Block_Blue"
    },
    {
      "x": -6,
      "y": 12,
      "z": 3,
      "name": "Plant_Coral_Block_Blue"
    },
    {
      "x": -6,
      "y": 10,
      "z": 4,
      "name": "Plant_Coral_Block_Blue"
    },
    {
      "x": -6,
      "y": 11,
      "z": 4,
      "name": "Plant_Coral_Block_Blue"
    },
    {
      "x": -6,
      "y": 12,
      "z": 4,
      "name": "Plant_Coral_Block_Blue"
    },
    {
      "x": -6,
      "y": 10,
      "z": 5,
      "name": "Plant_Coral_Block_Blue"
    },
    {
      "x": -6,
      "y": 11,
      "z": 5,
      "name": "Plant_Coral_Block_Blue"
    },
    {
      "x": -6,
      "y": 12,
      "z": 5,
      "name": "Plant_Coral_Block_Blue"
    },
    {
      "x": -6,
      "y": 10,
      "z": 6,
      "name": "Plant_Coral_Block_Blue"
    },
    {
      "x": -6,
      "y": 11,
      "z": 6,
      "name": "Plant_Coral_Block_Blue"
    },
    {
      "x": -6,
      "y": 12,
      "z": 6,
      "name": "Plant_Coral_Block_Blue"
    },
    {
      "x": -6,
      "y": 10,
      "z": 7,
      "name": "Plant_Coral_Block_Blue"
    },
    {
      "x": -6,
      "y": 11,
      "z": 7,
      "name": "Plant_Coral_Block_Blue"
    },
    {
      "x": -6,
      "y": 12,
      "z": 7,
      "name": "Plant_Coral_Block_Blue"
    },
    {
      "x": -6,
      "y": 10,
      "z": 8,
      "name": "Plant_Coral_Block_Blue"
    },
    {
      "x": -6,
      "y": 11,
      "z": 8,
      "name": "Plant_Coral_Block_Blue"
    },
    {
      "x": -6,
      "y": 12,
      "z": 8,
      "name": "Plant_Coral_Block_Blue"
    },
    {
      "x": -6,
      "y": 10,
      "z": 9,
      "name": "Plant_Coral_Block_Blue"
    },
    {
      "x": -6,
      "y": 11,
      "z": 9,
      "name": "Plant_Coral_Block_Blue"
    },
    {
      "x": -6,
      "y": 12,
      "z": 9,
      "name": "Plant_Coral_Block_Blue"
    },
    {
      "x": -6,
      "y": 10,
      "z": 10,
      "name": "Plant_Coral_Block_Blue"
    },
    {
      "x": -6,
      "y": 11,
      "z": 10,
      "name": "Plant_Coral_Block_Blue"
    },
    {
      "x": -6,
      "y": 12,
      "z": 10,
      "name": "Plant_Coral_Block_Blue"
    },
    {
      "x": -6,
      "y": 10,
      "z": 11,
      "name": "Plant_Coral_Block_Blue"
    },
    {
      "x": -6,
      "y": 11,
      "z": 11,
      "name": "Plant_Coral_Block_Blue"
    },
    {
      "x": -6,
      "y": 12,
      "z": 11,
      "name": "Plant_Coral_Block_Blue"
    },
    {
      "x": -6,
      "y": 10,
      "z": 12,
      "name": "Plant_Coral_Block_Blue"
    },
    {
      "x": -6,
      "y": 11,
      "z": 12,
      "name": "Plant_Coral_Block_Blue"
    },
    {
      "x": -6,
      "y": 12,
      "z": 12,
      "name": "Plant_Coral_Block_Blue"
    },
    {
      "x": -6,
      "y": 10,
      "z": 13,
      "name": "Plant_Coral_Block_Blue"
    },
    {
      "x": -6,
      "y": 11,
      "z": 13,
      "name": "Plant_Coral_Block_Blue"
    },
    {
      "x": -6,
      "y": 12,
      "z": 13,
      "name": "Plant_Coral_Block_Blue"
    },
    {
      "x": -6,
      "y": 10,
      "z": 14,
      "name": "Plant_Coral_Block_Blue"
    },
    {
      "x": -6,
      "y": 11,
      "z": 14,
      "name": "Plant_Coral_Block_Blue"
    },
    {
      "x": -6,
      "y": 12,
      "z": 14,
      "name": "Plant_Coral_Block_Blue"
    },
    {
      "x": -6,
      "y": 10,
      "z": 15,
      "name": "Plant_Coral_Block_Blue"
    },
    {
      "x": -6,
      "y": 11,
      "z": 15,
      "name": "Plant_Coral_Block_Blue"
    },
    {
      "x": -6,
      "y": 12,
      "z": 15,
      "name": "Plant_Coral_Block_Blue"
    },
    {
      "x": -6,
      "y": 10,
      "z": 16,
      "name": "Plant_Coral_Block_Cyan"
    },
    {
      "x": -6,
      "y": 11,
      "z": 16,
      "name": "Plant_Coral_Block_Cyan"
    },
    {
      "x": -6,
      "y": 12,
      "z": 16,
      "name": "Plant_Coral_Block_Cyan"
    },
    {
      "x": -6,
      "y": 12,
      "z": 17,
      "name": "Plant_Coral_Block_Cyan"
    },
    {
      "x": -5,
      "y": 10,
      "z": -17,
      "name": "Plant_Coral_Block_Cyan"
    },
    {
      "x": -5,
      "y": 11,
      "z": -17,
      "name": "Plant_Coral_Block_Cyan"
    },
    {
      "x": -5,
      "y": 12,
      "z": -17,
      "name": "Plant_Coral_Block_Cyan"
    },
    {
      "x": -5,
      "y": 10,
      "z": -16,
      "name": "Plant_Coral_Block_Blue"
    },
    {
      "x": -5,
      "y": 11,
      "z": -16,
      "name": "Plant_Coral_Block_Blue"
    },
    {
      "x": -5,
      "y": 12,
      "z": -16,
      "name": "Plant_Coral_Block_Blue"
    },
    {
      "x": -5,
      "y": 10,
      "z": -15,
