{
  "version": 8,
  "blockIdVersion": 11,
  "anchorX": 0,
  "anchorY": 4,
  "anchorZ": -5,
  "blocks": [
    {
      "x": -6,
      "y": 4,
      "z": -3,
      "name": "Rock_Aqua_Brick_Smooth"
    },
    {
      "x": -6,
      "y": 5,
      "z": -3,
      "name": "Rock_Aqua_Brick_Smooth"
    },
    {
      "x": -6,
      "y": 6,
      "z": -3,
      "name": "Rock_Aqua_Brick_Smooth"
    },
    {
      "x": -6,
      "y": 7,
      "z": -3,
      "name": "Rock_Aqua_Brick_Smooth"
    },
    {
      "x": -6,
      "y": 8,
      "z": -3,
      "name": "Rock_Aqua_Brick_Smooth"
    },
    {
      "x": -6,
      "y": 9,
      "z": -3,
      "name": "Rock_Aqua"
    },
    {
      "x": -6,
      "y": 4,
      "z": -2,
      "name": "Rock_Aqua_Brick_Smooth"
    },
    {
      "x": -6,
      "y": 5,
      "z": -2,
      "name": "Furniture_Human_Ruins_Bookshelf",
      "rotation": 1
    },
    {
      "x": -6,
      "y": 6,
      "z": -2,
      "name": "Furniture_Ancient_Bookshelf",
      "support": 1,
      "rotation": 1
    },
    {
      "x": -6,
      "y": 7,
      "z": -2,
      "name": "Furniture_Human_Ruins_Bookshelf",
      "rotation": 1
    },
    {
      "x": -6,
      "y": 8,
      "z": -2,
      "name": "Rock_Aqua_Brick_Smooth"
    },
    {
      "x": -6,
      "y": 9,
      "z": -2,
      "name": "Rock_Aqua"
    },
    {
      "x": -6,
      "y": 4,
      "z": -1,
      "name": "Rock_Aqua_Brick_Smooth"
    },
    {
      "x": -6,
      "y": 5,
      "z": -1,
      "name": "Furniture_Human_Ruins_Bookshelf",
      "rotation": 1
    },
    {
      "x": -6,
      "y": 6,
      "z": -1,
      "name": "Furniture_Human_Ruins_Bookshelf",
      "support": 1,
      "rotation": 1
    },
    {
      "x": -6,
      "y": 7,
      "z": -1,
      "name": "Furniture_Ancient_Bookshelf",
      "rotation": 1
    },
    {
      "x": -6,
      "y": 8,
      "z": -1,
      "name": "Rock_Aqua_Brick_Smooth"
    },
    {
      "x": -6,
      "y": 9,
      "z": -1,
      "name": "Rock_Aqua"
    },
    {
      "x": -6,
      "y": 4,
      "z": 0,
      "name": "Rock_Aqua_Brick_Smooth"
    },
    {
      "x": -6,
      "y": 5,
      "z": 0,
      "name": "Furniture_Village_Bookcase",
      "rotation": 1
    },
    {
      "x": -6,
      "y": 6,
      "z": 0,
      "name": "Rock_Aqua_Brick_Half",
      "rotation": 5
    },
    {
      "x": -6,
      "y": 7,
      "z": 0,
      "name": "Furniture_Human_Ruins_Bookshelf",
      "rotation": 1
    },
    {
      "x": -6,
      "y": 8,
      "z": 0,
      "name": "Rock_Aqua_Brick_Smooth"
    },
    {
      "x": -6,
      "y": 9,
      "z": 0,
      "name": "Rock_Aqua"
    },
    {
      "x": -6,
      "y": 4,
      "z": 1,
      "name": "Rock_Aqua_Brick_Smooth"
    },
    {
      "x": -6,
      "y": 5,
      "z": 1,
      "name": "Rock_Aqua_Brick_Smooth"
    },
    {
      "x": -6,
      "y": 6,
      "z": 1,
      "name": "Rock_Aqua_Brick_Smooth"
    },
    {
      "x": -6,
      "y": 7,
      "z": 1,
      "name": "Rock_Aqua_Brick_Smooth"
    },
    {
      "x": -6,
      "y": 8,
      "z": 1,
      "name": "Rock_Aqua_Brick_Smooth"
    },
    {
      "x": -6,
      "y": 9,
      "z": 1,
      "name": "Rock_Aqua"
    },
    {
      "x": -6,
      "y": 4,
      "z": 2,
      "name": "Rock_Aqua_Brick_Smooth"
    },
    {
      "x": -6,
      "y": 5,
      "z": 2,
      "name": "Furniture_Human_Ruins_Bookshelf",
      "rotation": 1
    },
    {
      "x": -6,
      "y": 6,
      "z": 2,
      "name": "Furniture_Village_Bookcase",
      "support": 1,
      "rotation": 1
    },
    {
      "x": -6,
      "y": 7,
      "z": 2,
      "name": "Rock_Aqua_Brick_Half",
      "rotation": 5
    },
    {
      "x": -6,
      "y": 8,
      "z": 2,
      "name": "Rock_Aqua_Brick_Smooth"
    },
    {
      "x": -6,
      "y": 9,
      "z": 2,
      "name": "Rock_Aqua"
    },
    {
      "x": -6,
      "y": 4,
      "z": 3,
      "name": "Rock_Aqua_Brick_Smooth"
    },
    {
      "x": -6,
      "y": 5,
      "z": 3,
      "name": "Furniture_Ancient_Bookshelf",
      "rotation": 1
    },
    {
      "x": -6,
      "y": 6,
      "z": 3,
      "name": "Furniture_Village_Bookcase",
      "rotation": 1
    },
    {
      "x": -6,
      "y": 7,
      "z": 3,
      "name": "Rock_Aqua_Brick_Half",
      "rotation": 5
    },
    {
      "x": -6,
      "y": 8,
      "z": 3,
      "name": "Rock_Aqua_Brick_Smooth"
    },
    {
      "x": -6,
      "y": 9,
      "z": 3,
      "name": "Rock_Aqua"
    },
    {
      "x": -6,
      "y": 4,
      "z": 4,
      "name": "Rock_Aqua_Brick_Smooth"
    },
    {
      "x": -6,
      "y": 5,
      "z": 4,
      "name": "Furniture_Village_Bookcase",
      "rotation": 1
    },
    {
      "x": -6,
      "y": 6,
      "z": 4,
      "name": "Rock_Aqua_Brick_Half",
      "rotation": 5
    },
    {
      "x": -6,
      "y": 7,
      "z": 4,
      "name": "Rock_Aqua_Brick_Half",
      "rotation": 5
    },
    {
      "x": -6,
      "y": 8,
      "z": 4,
      "name": "Rock_Aqua_Brick_Smooth"
    },
    {
      "x": -6,
      "y": 9,
      "z": 4,
      "name": "Rock_Aqua"
    },
    {
      "x": -6,
      "y": 4,
      "z": 5,
      "name": "Rock_Aqua_Brick_Smooth"
    },
    {
      "x": -6,
      "y": 5,
      "z": 5,
      "name": "Rock_Aqua_Brick_Smooth"
    },
    {
      "x": -6,
      "y": 6,
      "z": 5,
      "name": "Rock_Aqua_Brick_Smooth"
    },
    {
      "x": -6,
      "y": 7,
      "z": 5,
      "name": "Rock_Aqua_Brick_Smooth"
    },
    {
      "x": -6,
      "y": 8,
      "z": 5,
      "name": "Rock_Aqua_Brick_Smooth"
    },
    {
      "x": -6,
      "y": 9,
      "z": 5,
      "name": "Rock_Aqua"
    },
    {
      "x": -5,
      "y": 4,
      "z": -3,
      "name": "Rock_Aqua_Brick_Smooth"
    },
    {
      "x": -5,
      "y": 5,
      "z": -3,
      "name": "Furniture_Village_Bookcase"
    },
    {
      "x": -5,
      "y": 6,
      "z": -3,
      "name": "Rock_Aqua_Brick_Half",
      "rotation": 4
    },
    {
      "x": -5,
      "y": 7,
      "z": -3,
      "name": "Rock_Aqua_Brick_Half",
      "rotation": 4
    },
    {
      "x": -5,
      "y": 8,
      "z": -3,
      "name": "Rock_Aqua_Brick_Smooth"
    },
    {
      "x": -5,
      "y": 9,
      "z": -3,
      "name": "Rock_Aqua"
    },
    {
      "x": -5,
      "y": 4,
      "z": -2,
      "name": "Rock_Runic_Blue_Brick"
    },
    {
      "x": -5,
      "y": 8,
      "z": -2,
      "name": "Furniture_Temple_Light_Lantern_Ceiling"
    },
    {
      "x": -5,
      "y": 9,
      "z": -2,
      "name": "Rock_Aqua"
    },
    {
      "x": -5,
      "y": 4,
      "z": -1,
      "name": "Rock_Runic_Blue_Brick"
    },
    {
      "x": -5,
      "y": 9,
      "z": -1,
      "name": "Rock_Aqua"
    },
    {
      "x": -5,
      "y": 4,
      "z": 0,
      "name": "Rock_Runic_Blue_Brick"
    },
    {
      "x": -5,
      "y": 5,
      "z": 0,
      "name": "Cloth_Roof_Blue_Flat"
    },
    {
      "x": -5,
      "y": 9,
      "z": 0,
      "name": "Rock_Aqua"
    },
    {
      "x": -5,
      "y": 4,
      "z": 1,
      "name": "Rock_Runic_Blue_Brick"
    },
    {
      "x": -5,
      "y": 9,
      "z": 1,
      "name": "Rock_Aqua"
    },
    {
      "x": -5,
      "y": 4,
      "z": 2,
      "name": "Rock_Runic_Blue_Brick"
    },
    {
      "x": -5,
      "y": 9,
      "z": 2,
      "name": "Rock_Aqua"
    },
    {
      "x": -5,
      "y": 4,
      "z": 3,
      "name": "Rock_Runic_Blue_Brick"
    },
    {
      "x": -5,
      "y": 9,
      "z": 3,
      "name": "Rock_Aqua"
    },
    {
      "x": -5,
      "y": 4,
      "z": 4,
      "name": "Rock_Runic_Blue_Brick"
    },
    {
      "x": -5,
      "y": 5,
      "z": 4,
      "name": "Furniture_Temple_Dark_Pot"
    },
    {
      "x": -5,
      "y": 9,
      "z": 4,
      "name": "Rock_Aqua"
    },
    {
      "x": -5,
      "y": 4,
      "z": 5,
      "name": "Rock_Aqua_Brick_Smooth"
    },
    {
      "x": -5,
      "y": 5,
      "z": 5,
      "name": "Furniture_Human_Ruins_Bookshelf",
      "rotation": 2
    },
    {
      "x": -5,
      "y": 6,
      "z": 5,
      "name": "Furniture_Human_Ruins_Bookshelf",
      "support": 1,
      "rotation": 2
    },
    {
      "x": -5,
      "y": 7,
      "z": 5,
      "name": "Rock_Aqua_Brick_Half",
      "rotation": 6
    },
    {
      "x": -5,
      "y": 8,
      "z": 5,
      "name": "Rock_Aqua_Brick_Smooth"
    },
    {
      "x": -5,
      "y": 9,
      "z": 5,
      "name": "Rock_Aqua"
    },
    {
      "x": -4,
      "y": 4,
      "z": -3,
      "name": "Rock_Aqua_Brick_Smooth"
    },
    {
      "x": -4,
      "y": 5,
      "z": -3,
      "name": "Furniture_Ancient_Bookshelf"
    },
    {
      "x": -4,
      "y": 6,
      "z": -3,
      "name": "Furniture_Ancient_Bookshelf"
    },
    {
      "x": -4,
      "y": 7,
      "z": -3,
      "name": "Rock_Aqua_Brick_Half",
      "rotation": 4
    },
    {
      "x": -4,
      "y": 8,
      "z": -3,
      "name": "Rock_Aqua_Brick_Smooth"
    },
    {
      "x": -4,
      "y": 9,
      "z": -3,
      "name": "Rock_Aqua"
    },
    {
      "x": -4,
      "y": 4,
      "z": -2,
      "name": "Rock_Runic_Blue_Brick"
    },
    {
      "x": -4,
      "y": 5,
      "z": -2,
      "name": "Cloth_Roof_Blue_Flat"
    },
    {
      "x": -4,
      "y": 9,
      "z": -2,
      "name": "Rock_Aqua"
    },
    {
      "x": -4,
      "y": 4,
      "z": -1,
      "name": "Rock_Runic_Blue_Brick"
    },
    {
      "x": -4,
      "y": 9,
      "z": -1,
      "name": "Rock_Aqua"
    },
    {
      "x": -4,
      "y": 4,
      "z": 0,
      "name": "Rock_Runic_Blue_Brick"
    },
    {
      "x": -4,
      "y": 5,
      "z": 0,
      "name": "Cloth_Roof_Blue_Flat"
    },
    {
      "x": -4,
      "y": 9,
      "z": 0,
      "name": "Rock_Aqua"
    },
    {
      "x": -4,
      "y": 4,
      "z": 1,
      "name": "Rock_Runic_Blue_Brick"
    },
    {
      "x": -4,
      "y": 5,
      "z": 1,
      "name": "Cloth_Roof_Blue_Flat"
    },
    {
      "x": -4,
      "y": 7,
      "z": 1,
      "name": "Cloth_Roof_Blue_Flap",
      "rotation": 3
    },
    {
      "x": -4,
      "y": 9,
      "z": 1,
      "name": "Rock_Aqua"
    },
    {
      "x": -4,
      "y": 4,
      "z": 2,
      "name": "Rock_Runic_Blue_Brick"
    },
    {
      "x": -4,
      "y": 5,
      "z": 2,
      "name": "Deco_Book_Pile_Small",
      "rotation": 2
    },
    {
      "x": -4,
      "y": 9,
      "z": 2,
      "name": "Rock_Aqua"
    },
    {
      "x": -4,
      "y": 4,
      "z": 3,
      "name": "Rock_Runic_Blue_Brick"
    },
    {
      "x": -4,
      "y": 9,
      "z": 3,
      "name": "Rock_Aqua"
    },
    {
      "x": -4,
      "y": 4,
      "z": 4,
      "name": "Rock_Runic_Blue_Brick"
    },
    {
      "x": -4,
      "y": 9,
      "z": 4,
      "name": "Rock_Aqua"
    },
    {
      "x": -4,
      "y": 4,
      "z": 5,
      "name": "Rock_Aqua_Brick_Smooth"
    },
    {
      "x": -4,
      "y": 5,
      "z": 5,
      "name": "Furniture_Ancient_Bookshelf",
      "rotation": 2
    },
    {
      "x": -4,
      "y": 6,
      "z": 5,
      "name": "Furniture_Ancient_Bookshelf",
      "rotation": 2
    },
    {
      "x": -4,
      "y": 7,
      "z": 5,
      "name": "Rock_Aqua_Brick_Half",
      "rotation": 6
    },
    {
      "x": -4,
      "y": 8,
      "z": 5,
      "name": "Rock_Aqua_Brick_Smooth"
    },
    {
      "x": -4,
      "y": 9,
      "z": 5,
      "name": "Rock_Aqua"
    },
    {
      "x": -3,
      "y": 4,
      "z": -3,
      "name": "Rock_Aqua_Brick_Smooth"
    },
    {
      "x": -3,
      "y": 5,
      "z": -3,
      "name": "Furniture_Human_Ruins_Bookshelf"
    },
    {
      "x": -3,
      "y": 6,
      "z": -3,
      "name": "Furniture_Human_Ruins_Bookshelf",
      "support": 1
    },
    {
      "x": -3,
      "y": 7,
      "z": -3,
      "name": "Rock_Aqua_Brick_Half",
      "rotation": 4
    },
    {
      "x": -3,
      "y": 8,
      "z": -3,
      "name": "Rock_Aqua_Brick_Smooth"
    },
    {
      "x": -3,
      "y": 9,
      "z": -3,
      "name": "Rock_Aqua"
    },
    {
      "x": -3,
      "y": 4,
      "z": -2,
      "name": "Rock_Runic_Blue_Brick"
    },
    {
      "x": -3,
      "y": 5,
      "z": -2,
      "name": "Deco_Book_Pile_Large",
      "rotation": 3
    },
    {
      "x": -3,
      "y": 9,
      "z": -2,
      "name": "Rock_Aqua"
    },
    {
      "x": -3,
      "y": 4,
      "z": -1,
      "name": "Rock_Runic_Blue_Brick"
    },
    {
      "x": -3,
      "y": 5,
      "z": -1,
      "name": "Cloth_Roof_Blue_Flat"
    },
    {
      "x": -3,
      "y": 9,
      "z": -1,
      "name": "Rock_Aqua"
    },
    {
      "x": -3,
      "y": 4,
      "z": 0,
      "name": "Rock_Runic_Blue_Brick"
    },
    {
      "x": -3,
      "y": 9,
      "z": 0,
      "name": "Rock_Aqua_Half",
      "rotation": 8
    },
    {
      "x": -3,
      "y": 4,
      "z": 1,
      "name": "Rock_Runic_Blue_Brick"
    },
    {
      "x": -3,
      "y": 5,
      "z": 1,
      "name": "Furniture_Ancient_Bookshelf",
      "rotation": 2
    },
    {
      "x": -3,
      "y": 6,
      "z": 1,
      "name": "Furniture_Ancient_Bookshelf",
      "rotation": 2
    },
    {
      "x": -3,
      "y": 7,
      "z": 1,
      "name": "Furniture_Ancient_Bookshelf",
      "rotation": 2
    },
    {
      "x": -3,
      "y": 9,
      "z": 1,
      "name": "Rock_Aqua_Half",
      "rotation": 8
    },
    {
      "x": -3,
      "y": 4,
      "z": 2,
      "name": "Rock_Runic_Blue_Brick"
    },
    {
      "x": -3,
      "y": 5,
      "z": 2,
      "name": "Furniture_Human_Ruins_Bookshelf"
    },
    {
      "x": -3,
      "y": 6,
      "z": 2,
      "name": "Furniture_Human_Ruins_Bookshelf",
      "support": 1
    },
    {
      "x": -3,
      "y": 7,
      "z": 2,
      "name": "Deco_Book_Pile_Small"
    },
    {
      "x": -3,
      "y": 9,
      "z": 2,
      "name": "Rock_Aqua_Half",
      "rotation": 8
    },
    {
      "x": -3,
      "y": 4,
      "z": 3,
      "name": "Rock_Runic_Blue_Brick"
    },
    {
      "x": -3,
      "y": 5,
      "z": 3,
      "name": "Cloth_Roof_Blue_Flat"
    },
    {
      "x": -3,
      "y": 9,
      "z": 3,
      "name": "Rock_Aqua"
    },
    {
      "x": -3,
      "y": 4,
      "z": 4,
      "name": "Rock_Runic_Blue_Brick"
    },
    {
      "x": -3,
      "y": 9,
      "z": 4,
      "name": "Rock_Aqua"
    },
    {
      "x": -3,
      "y": 4,
      "z": 5,
      "name": "Rock_Aqua_Brick_Smooth"
    },
    {
      "x": -3,
      "y": 5,
      "z": 5,
      "name": "Furniture_Village_Bookcase",
      "rotation": 2
    },
    {
      "x": -3,
      "y": 6,
      "z": 5,
      "name": "Rock_Aqua_Brick_Half",
      "rotation": 6
    },
    {
      "x": -3,
      "y": 7,
      "z": 5,
      "name": "Rock_Aqua_Brick_Half",
      "rotation": 6
    },
    {
      "x": -3,
      "y": 8,
      "z": 5,
      "name": "Rock_Aqua_Brick_Smooth"
    },
    {
      "x": -3,
      "y": 9,
      "z": 5,
      "name": "Rock_Aqua"
    },
    {
      "x": -2,
      "y": 4,
      "z": -5,
      "name": "Rock_Aqua_Brick_Smooth"
    },
    {
      "x": -2,
      "y": 5,
      "z": -5,
      "name": "Rock_Aqua_Brick_Smooth"
    },
    {
      "x": -2,
      "y": 6,
      "z": -5,
      "name": "Rock_Aqua_Brick_Smooth"
    },
    {
      "x": -2,
      "y": 7,
      "z": -5,
      "name": "Rock_Aqua_Brick_Smooth"
    },
    {
      "x": -2,
      "y": 8,
      "z": -5,
      "name": "Rock_Aqua_Brick_Smooth"
    },
    {
      "x": -2,
      "y": 9,
      "z": -5,
      "name": "Rock_Aqua_Brick_Smooth"
    },
    {
      "x": -2,
      "y": 4,
      "z": -4,
      "name": "Rock_Aqua_Brick_Smooth"
    },
    {
      "x": -2,
      "y": 5,
      "z": -4,
      "name": "Rock_Aqua_Brick_Pillar_Base",
      "rotation": 7
    },
    {
      "x": -2,
      "y": 6,
      "z": -4,
      "name": "Rock_Aqua_Brick_Ornate"
    },
    {
      "x": -2,
      "y": 7,
      "z": -4,
      "name": "Rock_Aqua_Brick_Pillar_Base",
      "rotation": 7
    },
    {
      "x": -2,
      "y": 8,
      "z": -4,
      "name": "Rock_Aqua_Brick_Smooth"
    },
    {
      "x": -2,
      "y": 9,
      "z": -4,
      "name": "Rock_Aqua_Brick_Smooth"
    },
    {
      "x": -2,
      "y": 4,
      "z": -3,
      "name": "Rock_Aqua_Brick_Smooth"
    },
    {
      "x": -2,
      "y": 5,
      "z": -3,
      "name": "Rock_Aqua_Brick_Smooth"
    },
    {
      "x": -2,
      "y": 6,
      "z": -3,
      "name": "Rock_Aqua_Brick_Smooth"
    },
    {
      "x": -2,
      "y": 7,
      "z": -3,
      "name": "Rock_Aqua_Brick_Smooth"
    },
    {
      "x": -2,
      "y": 8,
      "z": -3,
      "name": "Rock_Aqua_Brick_Smooth"
    },
    {
      "x": -2,
      "y": 9,
      "z": -3,
      "name": "Rock_Aqua"
    },
    {
      "x": -2,
      "y": 4,
      "z": -2,
      "name": "Rock_Runic_Blue_Brick"
    },
    {
      "x": -2,
      "y": 5,
      "z": -2,
      "name": "Furniture_Ancient_Bookshelf"
    },
    {
      "x": -2,
      "y": 6,
      "z": -2,
      "name": "Furniture_Human_Ruins_Bookshelf"
    },
    {
      "x": -2,
      "y": 7,
      "z": -2,
      "name": "Deco_Book_Pile_Small"
    },
    {
      "x": -2,
      "y": 9,
      "z": -2,
      "name": "Rock_Aqua"
    },
    {
      "x": -2,
      "y": 4,
      "z": -1,
      "name": "Rock_Runic_Blue_Brick"
    },
    {
      "x": -2,
      "y": 5,
      "z": -1,
      "name": "Cloth_Roof_Blue_Flat"
    },
    {
      "x": -2,
      "y": 9,
      "z": -1,
      "name": "Rock_Aqua"
    },
    {
      "x": -2,
      "y": 4,
      "z": 0,
      "name": "Rock_Runic_Blue_Brick"
    },
    {
      "x": -2,
      "y": 9,
      "z": 0,
      "name": "Rock_Aqua_Half",
      "rotation": 8
    },
    {
      "x": -2,
      "y": 4,
      "z": 1,
      "name": "Rock_Runic_Blue_Brick"
    },
    {
      "x": -2,
      "y": 5,
      "z": 1,
      "name": "Furniture_Ancient_Bookshelf",
      "rotation": 2
    },
    {
      "x": -2,
      "y": 6,
      "z": 1,
      "name": "Furniture_Ancient_Bookshelf",
      "rotation": 2
    },
    {
      "x": -2,
      "y": 7,
      "z": 1,
      "name": "Furniture_Ancient_Bookshelf",
      "rotation": 2
    },
    {
      "x": -2,
      "y": 9,
      "z": 1,
      "name": "Rock_Aqua_Half",
      "rotation": 8
    },
    {
      "x": -2,
      "y": 4,
      "z": 2,
      "name": "Rock_Runic_Blue_Brick"
    },
    {
      "x": -2,
      "y": 5,
      "z": 2,
      "name": "Furniture_Village_Bookcase"
    },
    {
      "x": -2,
      "y": 6,
      "z": 2,
      "name": "Furniture_Village_Bookcase",
      "support": 1
    },
    {
      "x": -2,
      "y": 7,
      "z": 2,
      "name": "Furniture_Village_Bookcase",
      "support": 2
    },
    {
      "x": -2,
      "y": 9,
      "z": 2,
      "name": "Rock_Aqua_Half",
      "rotation": 8
    },
    {
      "x": -2,
      "y": 4,
      "z": 3,
      "name": "Rock_Runic_Blue_Brick"
    },
    {
      "x": -2,
      "y": 9,
      "z": 3,
      "name": "Rock_Aqua"
    },
    {
      "x": -2,
      "y": 4,
      "z": 4,
      "name": "Rock_Runic_Blue_Brick"
    },
    {
      "x": -2,
      "y": 5,
      "z": 4,
      "name": "Cloth_Roof_Blue_Flat"
    },
    {
      "x": -2,
      "y": 9,
      "z": 4,
      "name": "Rock_Aqua"
    },
    {
      "x": -2,
      "y": 4,
      "z": 5,
      "name": "Rock_Aqua_Brick_Smooth"
    },
    {
      "x": -2,
      "y": 5,
      "z": 5,
      "name": "Rock_Aqua_Brick_Smooth"
    },
    {
      "x": -2,
      "y": 6,
      "z": 5,
      "name": "Rock_Aqua_Brick_Smooth"
    },
    {
      "x": -2,
      "y": 7,
      "z": 5,
      "name": "Rock_Aqua_Brick_Smooth"
    },
    {
      "x": -2,
      "y": 8,
      "z": 5,
      "name": "Rock_Aqua_Brick_Smooth"
    },
    {
      "x": -2,
      "y": 9,
      "z": 5,
      "name": "Rock_Aqua"
    },
    {
      "x": -1,
      "y": 4,
      "z": -5,
      "name": "Rock_Aqua_Brick_Smooth"
    },
    {
      "x": -1,
      "y": 8,
      "z": -5,
      "name": "Rock_Aqua_Brick_Smooth"
    },
    {
      "x": -1,
      "y": 9,
      "z": -5,
      "name": "Rock_Aqua_Brick_Smooth"
    },
    {
      "x": -1,
      "y": 4,
      "z": -4,
      "name": "Rock_Aqua_Brick_Pillar_Base",
      "rotation": 8
    },
    {
      "x": -1,
      "y": 8,
      "z": -4,
      "name": "Rock_Aqua_Brick_Pillar_Base"
    },
    {
      "x": -1,
      "y": 9,
      "z": -4,
      "name": "Rock_Aqua_Brick_Smooth"
    },
    {
      "x": -1,
      "y": 4,
      "z": -3,
      "name": "Rock_Aqua_Brick_Smooth"
    },
    {
      "x": -1,
      "y": 8,
      "z": -3,
      "name": "Rock_Aqua_Brick_Smooth"
    },
    {
      "x": -1,
      "y": 9,
      "z": -3,
      "name": "Rock_Aqua"
    },
    {
      "x": -1,
      "y": 4,
      "z": -2,
      "name": "Rock_Runic_Blue_Brick"
    },
    {
      "x": -1,
      "y": 9,
      "z": -2,
      "name": "Rock_Aqua"
    },
    {
      "x": -1,
      "y": 4,
      "z": -1,
      "name": "Rock_Runic_Blue_Brick"
    },
    {
      "x": -1,
      "y": 9,
      "z": -1,
      "name": "Rock_Aqua"
    },
    {
      "x": -1,
      "y": 4,
      "z": 0,
      "name": "Rock_Runic_Blue_Brick"
    },
    {
      "x": -1,
      "y": 9,
      "z": 0,
      "name": "Rock_Aqua_Half",
      "rotation": 8
    },
    {
      "x": -1,
      "y": 4,
      "z": 1,
      "name": "Rock_Runic_Blue_Brick"
    },
    {
      "x": -1,
      "y": 5,
      "z": 1,
      "name": "Furniture_Village_Bookcase",
      "rotation": 2
    },
    {
      "x": -1,
      "y": 6,
      "z": 1,
      "name": "Furniture_Village_Bookcase",
      "support": 1,
      "rotation": 2
    },
    {
      "x": -1,
      "y": 7,
      "z": 1,
      "name": "Furniture_Village_Bookcase",
      "support": 2,
      "rotation": 2
    },
    {
      "x": -1,
      "y": 9,
      "z": 1,
      "name": "Rock_Aqua_Half",
      "rotation": 8
    },
    {
      "x": -1,
      "y": 4,
      "z": 2,
      "name": "Rock_Runic_Blue_Brick"
    },
    {
      "x": -1,
      "y": 5,
      "z": 2,
      "name": "Furniture_Human_Ruins_Bookshelf"
    },
    {
      "x": -1,
      "y": 6,
      "z": 2,
      "name": "Furniture_Human_Ruins_Bookshelf",
      "support": 1
    },
    {
      "x": -1,
      "y": 7,
      "z": 2,
      "name": "Furniture_Human_Ruins_Bookshelf",
      "support": 2
    },
    {
      "x": -1,
      "y": 9,
      "z": 2,
      "name": "Rock_Aqua_Half",
      "rotation": 8
    },
    {
      "x": -1,
      "y": 4,
      "z": 3,
      "name": "Rock_Runic_Blue_Brick"
    },
    {
      "x": -1,
      "y": 5,
      "z": 3,
      "name": "Cloth_Roof_Blue_Flat"
    },
    {
      "x": -1,
      "y": 9,
      "z": 3,
      "name": "Rock_Aqua"
    },
    {
      "x": -1,
      "y": 4,
      "z": 4,
      "name": "Rock_Runic_Blue_Brick"
    },
    {
      "x": -1,
      "y": 5,
      "z": 4,
      "name": "Cloth_Roof_Blue_Flat"
    },
    {
      "x": -1,
      "y": 9,
      "z": 4,
      "name": "Rock_Aqua"
    },
    {
      "x": -1,
      "y": 4,
      "z": 5,
      "name": "Rock_Aqua_Brick_Smooth"
    },
    {
      "x": -1,
      "y": 5,
      "z": 5,
      "name": "Rock_Aqua_Brick_Half",
      "rotation": 6
    },
    {
      "x": -1,
      "y": 6,
      "z": 5,
      "name": "Rock_Aqua_Brick_Half",
      "rotation": 6
    },
    {
      "x": -1,
      "y": 7,
      "z": 5,
      "name": "Rock_Aqua_Brick_Half",
      "rotation": 6
    },
    {
      "x": -1,
      "y": 8,
      "z": 5,
      "name": "Rock_Aqua_Brick_Smooth"
    },
    {
      "x": -1,
      "y": 9,
      "z": 5,
      "name": "Rock_Aqua"
    },
    {
      "x": 0,
      "y": 4,
      "z": -5,
      "name": "Rock_Aqua_Brick_Smooth"
    },
    {
      "x": 0,
      "y": 8,
      "z": -5,
      "name": "Rock_Aqua_Brick_Smooth"
    },
    {
      "x": 0,
      "y": 9,
      "z": -5,
      "name": "Rock_Aqua_Brick_Smooth"
    },
    {
      "x": 0,
      "y": 4,
      "z": -4,
      "name": "Rock_Aqua_Brick_Ornate"
    },
    {
      "x": 0,
      "y": 8,
      "z": -4,
      "name": "Rock_Aqua_Brick_Ornate"
    },
    {
      "x": 0,
      "y": 9,
      "z": -4,
      "name": "Rock_Aqua_Brick_Smooth"
    },
    {
      "x": 0,
      "y": 4,
      "z": -3,
      "name": "Rock_Aqua_Brick_Smooth"
    },
    {
      "x": 0,
      "y": 8,
      "z": -3,
      "name": "Rock_Aqua_Brick_Smooth"
    },
    {
      "x": 0,
      "y": 9,
      "z": -3,
      "name": "Rock_Aqua"
    },
    {
      "x": 0,
      "y": 4,
      "z": -2,
      "name": "Rock_Runic_Blue_Brick"
    },
    {
      "x": 0,
      "y": 8,
      "z": -2,
      "name": "Rock_Aqua_Brick_Half",
      "rotation": 4
    },
    {
      "x": 0,
      "y": 9,
      "z": -2,
      "name": "Rock_Aqua"
    },
    {
      "x": 0,
      "y": 4,
      "z": -1,
      "name": "Rock_Runic_Blue_Brick"
    },
    {
      "x": 0,
      "y": 9,
      "z": -1,
      "name": "Rock_Aqua"
    },
    {
      "x": 0,
      "y": 4,
      "z": 0,
      "name": "Rock_Runic_Blue_Brick"
    },
    {
      "x": 0,
      "y": 9,
      "z": 0,
      "name": "Rock_Aqua_Half",
      "rotation": 8
    },
    {
      "x": 0,
      "y": 4,
      "z": 1,
      "name": "Rock_Runic_Blue_Brick"
    },
    {
      "x": 0,
      "y": 9,
      "z": 1,
      "name": "Rock_Aqua_Half",
      "rotation": 8
    },
    {
      "x": 0,
      "y": 4,
      "z": 2,
      "name": "Rock_Runic_Blue_Brick"
    },
    {
      "x": 0,
      "y": 5,
      "z": 2,
      "name": "Cloth_Roof_Blue_Flat"
    },
    {
      "x": 0,
      "y": 7,
      "z": 2,
      "name": "Cloth_Roof_Blue_Flap",
      "rotation": 1
    },
    {
      "x": 0,
      "y": 9,
      "z": 2,
      "name": "Rock_Aqua_Half",
      "rotation": 8
    },
    {
      "x": 0,
      "y": 4,
      "z": 3,
      "name": "Rock_Runic_Blue_Brick"
    },
    {
      "x": 0,
      "y": 9,
      "z": 3,
      "name": "Rock_Aqua"
    },
    {
      "x": 0,
      "y": 4,
      "z": 4,
      "name": "Rock_Runic_Blue_Brick"
    },
    {
      "x": 0,
      "y": 5,
      "z": 4,
      "name": "Cloth_Roof_Blue_Flat"
    },
    {
      "x": 0,
      "y": 8,
      "z": 4,
      "name": "Furniture_Temple_Light_Lantern_Ceiling"
    },
    {
      "x": 0,
      "y": 9,
      "z": 4,
      "name": "Rock_Aqua"
    },
    {
      "x": 0,
      "y": 4,
      "z": 5,
      "name": "Rock_Aqua_Brick_Smooth"
    },
    {
      "x": 0,
      "y": 5,
      "z": 5,
      "name": "Rock_Aqua_Brick_Half",
      "rotation": 6
    },
    {
      "x": 0,
      "y": 6,
      "z": 5,
      "name": "Rock_Aqua_Brick_Half",
      "rotation": 6
    },
    {
      "x": 0,
      "y": 7,
      "z": 5,
      "name": "Rock_Aqua_Brick_Half",
      "rotation": 6
    },
    {
      "x": 0,
      "y": 8,
      "z": 5,
      "name": "Rock_Aqua_Brick_Smooth"
    },
    {
      "x": 0,
      "y": 9,
      "z": 5,
      "name": "Rock_Aqua"
    },
    {
      "x": 1,
      "y": 4,
      "z": -5,
      "name": "Rock_Aqua_Brick_Smooth"
    },
    {
      "x": 1,
      "y": 8,
      "z": -5,
      "name": "Rock_Aqua_Brick_Smooth"
    },
    {
      "x": 1,
      "y": 9,
      "z": -5,
      "name": "Rock_Aqua_Brick_Smooth"
    },
    {
      "x": 1,
      "y": 4,
      "z": -4,
      "name": "Rock_Aqua_Brick_Pillar_Base",
      "rotation": 8
    },
    {
      "x": 1,
      "y": 8,
      "z": -4,
      "name": "Rock_Aqua_Brick_Pillar_Base"
    },
    {
      "x": 1,
      "y": 9,
      "z": -4,
      "name": "Rock_Aqua_Brick_Smooth"
    },
    {
      "x": 1,
      "y": 4,
      "z": -3,
      "name": "Rock_Aqua_Brick_Smooth"
    },
    {
      "x": 1,
      "y": 5,
      "z": -3,
      "name": "Furniture_Temple_Dark_Pot"
    },
    {
      "x": 1,
      "y": 8,
      "z": -3,
      "name": "Rock_Aqua_Brick_Smooth"
    },
    {
      "x": 1,
      "y": 9,
      "z": -3,
      "name": "Rock_Aqua"
    },
    {
      "x": 1,
      "y": 4,
      "z": -2,
      "name": "Rock_Runic_Blue_Brick"
    },
    {
      "x": 1,
      "y": 9,
      "z": -2,
      "name": "Rock_Aqua"
    },
    {
      "x": 1,
      "y": 4,
      "z": -1,
      "name": "Rock_Runic_Blue_Brick"
    },
    {
      "x": 1,
      "y": 9,
      "z": -1,
      "name": "Rock_Aqua"
    },
    {
      "x": 1,
      "y": 4,
      "z": 0,
      "name": "Rock_Runic_Blue_Brick"
    },
    {
      "x": 1,
      "y": 9,
      "z": 0,
      "name": "Rock_Aqua_Half",
      "rotation": 8
    },
    {
      "x": 1,
      "y": 4,
      "z": 1,
      "name": "Rock_Runic_Blue_Brick"
    },
    {
      "x": 1,
      "y": 9,
      "z": 1,
      "name": "Rock_Aqua_Half",
      "rotation": 8
    },
    {
      "x": 1,
      "y": 4,
      "z": 2,
      "name": "Rock_Runic_Blue_Brick"
    },
    {
      "x": 1,
      "y": 9,
      "z": 2,
      "name": "Rock_Aqua_Half",
      "rotation": 8
    },
    {
      "x": 1,
      "y": 4,
      "z": 3,
      "name": "Rock_Runic_Blue_Brick"
    },
    {
      "x": 1,
      "y": 5,
      "z": 3,
      "name": "Cloth_Roof_Blue_Flat"
    },
    {
      "x": 1,
      "y": 9,
      "z": 3,
      "name": "Rock_Aqua"
    },
    {
      "x": 1,
      "y": 4,
      "z": 4,
      "name": "Rock_Runic_Blue_Brick"
    },
    {
      "x": 1,
      "y": 9,
      "z": 4,
      "name": "Rock_Aqua"
    },
    {
      "x": 1,
      "y": 4,
      "z": 5,
      "name": "Rock_Aqua_Brick_Smooth"
    },
    {
      "x": 1,
      "y": 5,
      "z": 5,
      "name": "Rock_Aqua_Brick_Half",
      "rotation": 6
    },
    {
      "x": 1,
      "y": 6,
      "z": 5,
      "name": "Rock_Aqua_Brick_Half",
      "rotation": 6
    },
    {
      "x": 1,
      "y": 7,
      "z": 5,
      "name": "Rock_Aqua_Brick_Half",
      "rotation": 6
    },
    {
      "x": 1,
      "y": 8,
      "z": 5,
      "name": "Rock_Aqua_Brick_Smooth"
    },
    {
      "x": 1,
      "y": 9,
      "z": 5,
      "name": "Rock_Aqua"
    },
    {
      "x": 2,
      "y": 4,
      "z": -5,
      "name": "Rock_Aqua_Brick_Smooth"
    },
    {
      "x": 2,
      "y": 5,
      "z": -5,
      "name": "Rock_Aqua_Brick_Smooth"
    },
    {
      "x": 2,
      "y": 6,
      "z": -5,
      "name": "Rock_Aqua_Brick_Smooth"
    },
    {
      "x": 2,
      "y": 7,
      "z": -5,
      "name": "Rock_Aqua_Brick_Smooth"
    },
    {
      "x": 2,
      "y": 8,
      "z": -5,
      "name": "Rock_Aqua_Brick_Smooth"
    },
    {
      "x": 2,
      "y": 9,
      "z": -5,
      "name": "Rock_Aqua_Brick_Smooth"
    },
    {
      "x": 2,
      "y": 4,
      "z": -4,
      "name": "Rock_Aqua_Brick_Smooth"
    },
    {
      "x": 2,
      "y": 5,
      "z": -4,
      "name": "Rock_Aqua_Brick_Pillar_Base",
      "rotation": 5
    },
    {
      "x": 2,
      "y": 6,
      "z": -4,
      "name": "Rock_Aqua_Brick_Ornate"
    },
    {
      "x": 2,
      "y": 7,
      "z": -4,
      "name": "Rock_Aqua_Brick_Pillar_Base",
      "rotation": 5
    },
    {
      "x": 2,
      "y": 8,
      "z": -4,
      "name": "Rock_Aqua_Brick_Smooth"
    },
    {
      "x": 2,
      "y": 9,
      "z": -4,
      "name": "Rock_Aqua_Brick_Smooth"
    },
    {
      "x": 2,
      "y": 0,
      "z": -3,
      "name": "Rock_Aqua_Brick_Smooth"
    },
    {
      "x": 2,
      "y": 1,
      "z": -3,
      "name": "Rock_Aqua_Brick_Smooth"
    },
    {
      "x": 2,
      "y": 2,
      "z": -3,
      "name": "Rock_Aqua_Brick_Smooth"
    },
    {
      "x": 2,
      "y": 3,
      "z": -3,
      "name": "Rock_Aqua_Brick_Smooth"
    },
    {
      "x": 2,
      "y": 4,
      "z": -3,
      "name": "Rock_Aqua_Brick_Smooth"
    },
    {
      "x": 2,
      "y": 5,
      "z": -3,
      "name": "Rock_Aqua_Brick_Smooth"
    },
    {
      "x": 2,
      "y": 6,
      "z": -3,
      "name": "Rock_Aqua_Brick_Smooth"
    },
    {
      "x": 2,
      "y": 7,
      "z": -3,
      "name": "Rock_Aqua_Brick_Smooth"
    },
    {
      "x": 2,
      "y": 8,
      "z": -3,
      "name": "Rock_Aqua_Brick_Smooth"
    },
    {
      "x": 2,
      "y": 9,
      "z": -3,
      "name": "Rock_Aqua"
    },
    {
      "x": 2,
      "y": 0,
      "z": -2,
      "name": "Rock_Aqua_Brick_Smooth"
    },
    {
      "x": 2,
      "y": 1,
      "z": -2,
      "name": "Rock_Aqua_Brick_Decorative"
    },
    {
      "x": 2,
      "y": 2,
      "z": -2,
      "name": "Rock_Aqua_Brick_Smooth"
    },
    {
      "x": 2,
      "y": 3,
      "z": -2,
      "name": "Rock_Aqua_Brick_Smooth"
    },
    {
      "x": 2,
      "y": 4,
      "z": -2,
      "name": "Rock_Runic_Blue_Brick"
    },
    {
      "x": 2,
      "y": 9,
      "z": -2,
      "name": "Rock_Aqua"
    },
    {
      "x": 2,
      "y": 0,
      "z": -1,
      "name": "Rock_Aqua_Brick_Smooth"
    },
    {
      "x": 2,
      "y": 1,
      "z": -1,
      "name": "Rock_Aqua_Brick_Decorative"
    },
    {
      "x": 2,
      "y": 2,
      "z": -1,
      "name": "Rock_Aqua_Brick_Smooth"
    },
    {
      "x": 2,
      "y": 3,
      "z": -1,
      "name": "Rock_Aqua_Brick_Smooth"
    },
    {
      "x": 2,
      "y": 4,
      "z": -1,
      "name": "Rock_Runic_Blue_Brick"
    },
    {
      "x": 2,
      "y": 7,
      "z": -1,
      "name": "Cloth_Roof_Green_Flap",
      "rotation": 2
    },
    {
      "x": 2,
      "y": 9,
      "z": -1,
      "name": "Rock_Aqua"
    },
    {
      "x": 2,
      "y": 0,
      "z": 0,
      "name": "Rock_Aqua_Brick_Smooth"
    },
    {
      "x": 2,
      "y": 1,
      "z": 0,
      "name": "Rock_Aqua_Brick_Decorative"
    },
    {
      "x": 2,
      "y": 2,
      "z": 0,
      "name": "Rock_Aqua_Brick_Smooth"
    },
    {
      "x": 2,
      "y": 3,
      "z": 0,
      "name": "Rock_Aqua_Brick_Smooth"
    },
    {
      "x": 2,
      "y": 4,
      "z": 0,
      "name": "Rock_Runic_Blue_Brick"
    },
    {
      "x": 2,
      "y": 5,
      "z": 0,
      "name": "Furniture_Human_Ruins_Bookshelf",
      "rotation": 3
    },
    {
      "x": 2,
      "y": 6,
      "z": 0,
      "name": "Furniture_Human_Ruins_Bookshelf",
      "support": 1,
      "rotation": 3
    },
    {
      "x": 2,
      "y": 7,
      "z": 0,
      "name": "Furniture_Human_Ruins_Bookshelf",
      "support": 2,
      "rotation": 3
    },
    {
      "x": 2,
      "y": 9,
      "z": 0,
      "name": "Rock_Aqua_Half",
      "rotation": 8
    },
    {
      "x": 2,
      "y": 0,
      "z": 1,
      "name": "Rock_Aqua_Brick_Smooth"
    },
    {
      "x": 2,
      "y": 1,
      "z": 1,
      "name": "Rock_Aqua_Brick_Smooth"
    },
    {
      "x": 2,
      "y": 2,
      "z": 1,
      "name": "Rock_Aqua_Brick_Ornate"
    },
    {
      "x": 2,
      "y": 3,
      "z": 1,
      "name": "Rock_Aqua_Brick_Smooth"
    },
    {
      "x": 2,
      "y": 4,
      "z": 1,
      "name": "Rock_Runic_Blue_Brick"
    },
    {
      "x": 2,
      "y": 5,
      "z": 1,
      "name": "Furniture_Village_Bookcase",
      "rotation": 3
    },
    {
      "x": 2,
      "y": 6,
      "z": 1,
      "name": "Furniture_Village_Bookcase",
      "support": 1,
      "rotation": 3
    },
    {
      "x": 2,
      "y": 7,
      "z": 1,
      "name": "Furniture_Village_Bookcase",
      "support": 2,
      "rotation": 3
    },
    {
      "x": 2,
      "y": 9,
      "z": 1,
      "name": "Rock_Aqua_Half",
      "rotation": 8
    },
    {
      "x": 2,
      "y": 0,
      "z": 2,
      "name": "Rock_Aqua_Brick_Smooth"
    },
    {
      "x": 2,
      "y": 1,
      "z": 2,
      "name": "Rock_Aqua_Brick_Decorative"
    },
    {
      "x": 2,
      "y": 2,
      "z": 2,
      "name": "Rock_Aqua_Brick_Stairs",
      "rotation": 1
    },
    {
      "x": 2,
      "y": 3,
      "z": 2,
      "name": "Rock_Aqua_Brick_Stairs",
      "rotation": 11
    },
    {
      "x": 2,
      "y": 4,
      "z": 2,
      "name": "Rock_Runic_Blue_Brick"
    },
    {
      "x": 2,
      "y": 5,
      "z": 2,
      "name": "Furniture_Human_Ruins_Bookshelf",
      "rotation": 3
    },
    {
      "x": 2,
      "y": 6,
      "z": 2,
      "name": "Furniture_Human_Ruins_Bookshelf",
      "support": 1,
      "rotation": 3
    },
    {
      "x": 2,
      "y": 7,
      "z": 2,
      "name": "Deco_Book_Pile_Large"
    },
    {
      "x": 2,
      "y": 9,
      "z": 2,
      "name": "Rock_Aqua_Half",
      "rotation": 8
    },
    {
      "x": 2,
      "y": 0,
      "z": 3,
      "name": "Rock_Aqua_Brick_Smooth"
    },
    {
      "x": 2,
      "y": 1,
      "z": 3,
      "name": "Rock_Aqua_Brick_Decorative"
    },
    {
      "x": 2,
      "y": 2,
      "z": 3,
      "name": "Rock_Aqua_Brick_Stairs",
      "rotation": 1
    },
    {
      "x": 2,
      "y": 3,
      "z": 3,
      "name": "Rock_Aqua_Brick_Stairs",
      "rotation": 11
    },
    {
      "x": 2,
      "y": 4,
      "z": 3,
      "name": "Rock_Runic_Blue_Brick"
    },
    {
      "x": 2,
      "y": 9,
      "z": 3,
      "name": "Rock_Aqua"
    },
    {
      "x": 2,
      "y": 0,
      "z": 4,
      "name": "Rock_Aqua_Brick_Smooth"
    },
    {
      "x": 2,
      "y": 1,
      "z": 4,
      "name": "Rock_Aqua_Brick_Decorative"
    },
    {
      "x": 2,
      "y": 2,
      "z": 4,
      "name": "Rock_Aqua_Brick_Stairs",
      "rotation": 1
    },
    {
      "x": 2,
      "y": 3,
      "z": 4,
      "name": "Rock_Aqua_Brick_Stairs",
      "rotation": 11
    },
    {
      "x": 2,
      "y": 4,
      "z": 4,
      "name": "Rock_Runic_Blue_Brick"
    },
    {
      "x": 2,
      "y": 9,
      "z": 4,
      "name": "Rock_Aqua"
    },
    {
      "x": 2,
      "y": 0,
      "z": 5,
      "name": "Rock_Aqua_Brick_Smooth"
    },
    {
      "x": 2,
      "y": 1,
      "z": 5,
      "name": "Rock_Aqua_Brick_Smooth"
    },
    {
      "x": 2,
      "y": 2,
      "z": 5,
      "name": "Rock_Aqua_Brick_Smooth"
    },
    {
      "x": 2,
      "y": 3,
      "z": 5,
      "name": "Rock_Aqua_Brick_Smooth"
    },
    {
      "x": 2,
      "y": 4,
      "z": 5,
      "name": "Rock_Aqua_Brick_Smooth"
    },
    {
      "x": 2,
      "y": 5,
      "z": 5,
      "name": "Rock_Aqua_Brick_Smooth"
    },
    {
      "x": 2,
      "y": 6,
      "z": 5,
      "name": "Rock_Aqua_Brick_Smooth"
    },
    {
      "x": 2,
      "y": 7,
      "z": 5,
      "name": "Rock_Aqua_Brick_Smooth"
    },
    {
      "x": 2,
      "y": 8,
      "z": 5,
      "name": "Rock_Aqua_Brick_Smooth"
    },
    {
      "x": 2,
      "y": 9,
      "z": 5,
      "name": "Rock_Aqua"
    },
    {
      "x": 3,
      "y": 0,
      "z": -3,
      "name": "Rock_Aqua_Brick_Smooth"
    },
    {
      "x": 3,
      "y": 1,
      "z": -3,
      "name": "Rock_Aqua_Brick_Smooth"
    },
    {
      "x": 3,
      "y": 2,
      "z": -3,
      "name": "Rock_Aqua_Brick_Smooth"
    },
    {
      "x": 3,
      "y": 3,
      "z": -3,
      "name": "Rock_Aqua_Brick_Smooth"
    },
    {
      "x": 3,
      "y": 4,
      "z": -3,
      "name": "Rock_Aqua_Brick_Smooth"
    },
    {
      "x": 3,
      "y": 5,
      "z": -3,
      "name": "Furniture_Human_Ruins_Bookshelf"
    },
    {
      "x": 3,
      "y": 6,
      "z": -3,
      "name": "Rock_Aqua_Brick_Half",
      "rotation": 4
    },
    {
      "x": 3,
      "y": 7,
      "z": -3,
      "name": "Rock_Aqua_Brick_Half",
      "rotation": 4
    },
    {
      "x": 3,
      "y": 8,
      "z": -3,
      "name": "Rock_Aqua_Brick_Smooth"
    },
    {
      "x": 3,
      "y": 9,
      "z": -3,
      "name": "Rock_Aqua"
    },
    {
      "x": 3,
      "y": 0,
      "z": -2,
      "name": "Rock_Aqua_Brick_Smooth"
    },
    {
      "x": 3,
      "y": 1,
      "z": -2,
      "name": "Rock_Aqua_Brick_Decorative"
    },
    {
      "x": 3,
      "y": 2,
      "z": -2,
      "name": "Rock_Aqua_Brick_Smooth"
    },
    {
      "x": 3,
      "y": 3,
      "z": -2,
      "name": "Rock_Aqua_Brick_Smooth"
    },
    {
      "x": 3,
      "y": 4,
      "z": -2,
      "name": "Rock_Runic_Blue_Brick"
    },
    {
      "x": 3,
      "y": 9,
      "z": -2,
      "name": "Rock_Aqua"
    },
    {
      "x": 3,
      "y": 0,
      "z": -1,
      "name": "Rock_Runic_Teal_Brick"
    },
    {
      "x": 3,
      "y": 1,
      "z": -1,
      "name": "Rock_Aqua_Stalactite_Small"
    },
    {
      "x": 3,
      "y": 4,
      "z": -1,
      "name": "Rock_Runic_Blue_Brick"
    },
    {
      "x": 3,
      "y": 5,
      "z": -1,
      "name": "Cloth_Roof_Blue_Flat"
    },
    {
      "x": 3,
      "y": 7,
      "z": -1,
      "name": "Cloth_Roof_Green_Flap",
      "rotation": 2
    },
    {
      "x": 3,
      "y": 9,
      "z": -1,
      "name": "Rock_Aqua"
    },
    {
      "x": 3,
      "y": 0,
      "z": 0,
      "name": "Rock_Runic_Teal_Brick"
    },
    {
      "x": 3,
      "y": 4,
      "z": 0,
      "name": "Rock_Runic_Blue_Brick"
    },
    {
      "x": 3,
      "y": 5,
      "z": 0,
      "name": "Furniture_Ancient_Bookshelf",
      "rotation": 1
    },
    {
      "x": 3,
      "y": 6,
      "z": 0,
      "name": "Furniture_Ancient_Bookshelf",
      "rotation": 1
    },
    {
      "x": 3,
      "y": 7,
      "z": 0,
      "name": "Furniture_Ancient_Bookshelf",
      "rotation": 1
    },
    {
      "x": 3,
      "y": 9,
      "z": 0,
      "name": "Rock_Aqua_Half",
      "rotation": 8
    },
    {
      "x": 3,
      "y": 0,
      "z": 1,
      "name": "Rock_Runic_Teal_Brick"
    },
    {
      "x": 3,
      "y": 1,
      "z": 1,
      "name": "Deco_Iron_Bars"
    },
    {
      "x": 3,
      "y": 2,
      "z": 1,
      "name": "Deco_Iron_Bars"
    },
    {
      "x": 3,
      "y": 3,
      "z": 1,
      "name": "Deco_Iron_Bars"
    },
    {
      "x": 3,
      "y": 4,
      "z": 1,
      "name": "Rock_Runic_Blue_Brick"
    },
    {
      "x": 3,
      "y": 5,
      "z": 1,
      "name": "Furniture_Ancient_Bookshelf",
      "rotation": 1
    },
    {
      "x": 3,
      "y": 6,
      "z": 1,
      "name": "Furniture_Ancient_Bookshelf",
      "rotation": 1
    },
    {
      "x": 3,
      "y": 7,
      "z": 1,
      "name": "Furniture_Ancient_Bookshelf",
      "rotation": 1
    },
    {
      "x": 3,
      "y": 9,
      "z": 1,
      "name": "Rock_Aqua_Half",
      "rotation": 8
    },
    {
      "x": 3,
      "y": 0,
      "z": 2,
      "name": "Rock_Runic_Teal_Brick"
    },
    {
      "x": 3,
      "y": 4,
      "z": 2,
      "name": "Rock_Runic_Blue_Brick"
    },
    {
      "x": 3,
      "y": 5,
      "z": 2,
      "name": "Furniture_Village_Bookcase",
      "rotation": 1
    },
    {
      "x": 3,
      "y": 6,
      "z": 2,
      "name": "Furniture_Village_Bookcase",
      "support": 1,
      "rotation": 1
    },
    {
      "x": 3,
      "y": 7,
      "z": 2,
      "name": "Furniture_Village_Bookcase",
      "support": 2,
      "rotation": 1
    },
    {
      "x": 3,
      "y": 9,
      "z": 2,
      "name": "Rock_Aqua_Half",
      "rotation": 8
    },
    {
      "x": 3,
      "y": 0,
      "z": 3,
      "name": "Rock_Runic_Teal_Brick"
    },
    {
      "x": 3,
      "y": 4,
      "z": 3,
      "name": "Rock_Runic_Blue_Brick"
    },
    {
      "x": 3,
      "y": 5,
      "z": 3,
      "name": "Plant_Coral_Model_Blue"
    },
    {
      "x": 3,
      "y": 8,
      "z": 3,
      "name": "Plant_Crop_Mushroom_Block_Blue_Mycelium"
    },
    {
      "x": 3,
      "y": 9,
      "z": 3,
      "name": "Rock_Aqua"
    },
    {
      "x": 3,
      "y": 0,
      "z": 4,
      "name": "Rock_Runic_Teal_Brick"
    },
    {
      "x": 3,
      "y": 1,
      "z": 4,
      "name": "Rock_Aqua_Brick_Beam"
    },
    {
      "x": 3,
      "y": 2,
      "z": 4,
      "name": "Furniture_Human_Ruins_Lantern"
    },
    {
      "x": 3,
      "y": 4,
      "z": 4,
      "name": "Rock_Runic_Blue_Brick"
    },
    {
      "x": 3,
      "y": 9,
      "z": 4,
      "name": "Rock_Aqua"
    },
    {
      "x": 3,
      "y": 0,
      "z": 5,
      "name": "Rock_Aqua_Brick_Smooth"
    },
    {
      "x": 3,
      "y": 1,
      "z": 5,
      "name": "Rock_Aqua_Brick_Decorative"
    },
    {
      "x": 3,
      "y": 2,
      "z": 5,
      "name": "Rock_Aqua_Brick_Stairs",
      "rotation": 2
    },
    {
      "x": 3,
      "y": 3,
      "z": 5,
      "name": "Rock_Aqua_Brick_Stairs",
      "rotation": 8
    },
    {
      "x": 3,
      "y": 4,
      "z": 5,
      "name": "Rock_Aqua_Brick_Smooth"
    },
    {
      "x": 3,
      "y": 5,
      "z": 5,
      "name": "Furniture_Ancient_Bookshelf",
      "rotation": 2
    },
    {
      "x": 3,
      "y": 6,
      "z": 5,
      "name": "Rock_Aqua_Brick_Half",
      "rotation": 6
    },
    {
      "x": 3,
      "y": 7,
      "z": 5,
      "name": "Rock_Aqua_Brick_Half",
      "rotation": 6
    },
    {
      "x": 3,
      "y": 8,
      "z": 5,
      "name": "Rock_Aqua_Brick_Smooth"
    },
    {
      "x": 3,
      "y": 9,
      "z": 5,
      "name": "Rock_Aqua"
    },
    {
      "x": 4,
      "y": 0,
      "z": -3,
      "name": "Rock_Aqua_Brick_Smooth"
    },
    {
      "x": 4,
      "y": 1,
      "z": -3,
      "name": "Rock_Aqua_Brick_Smooth"
    },
    {
      "x": 4,
      "y": 2,
      "z": -3,
      "name": "Rock_Aqua_Brick_Smooth"
    },
    {
      "x": 4,
      "y": 3,
      "z": -3,
      "name": "Rock_Aqua_Brick_Smooth"
    },
    {
      "x": 4,
      "y": 4,
      "z": -3,
      "name": "Rock_Aqua_Brick_Smooth"
    },
    {
      "x": 4,
      "y": 5,
      "z": -3,
      "name": "Furniture_Village_Bookcase"
    },
    {
      "x": 4,
      "y": 6,
      "z": -3,
      "name": "Rock_Aqua_Brick_Half",
      "rotation": 4
    },
    {
      "x": 4,
      "y": 7,
      "z": -3,
      "name": "Rock_Aqua_Brick_Half",
      "rotation": 4
    },
    {
      "x": 4,
      "y": 8,
      "z": -3,
      "name": "Rock_Aqua_Brick_Smooth"
    },
    {
      "x": 4,
      "y": 9,
      "z": -3,
      "name": "Rock_Aqua"
    },
    {
      "x": 4,
      "y": 0,
      "z": -2,
      "name": "Rock_Aqua_Brick_Smooth"
    },
    {
      "x": 4,
      "y": 1,
      "z": -2,
      "name": "Rock_Aqua_Brick_Decorative"
    },
    {
      "x": 4,
      "y": 2,
      "z": -2,
      "name": "Rock_Aqua_Brick_Smooth"
    },
    {
      "x": 4,
      "y": 3,
      "z": -2,
      "name": "Rock_Aqua_Brick_Smooth"
    },
    {
      "x": 4,
      "y": 4,
      "z": -2,
      "name": "Rock_Runic_Blue_Brick"
    },
    {
      "x": 4,
      "y": 5,
      "z": -2,
      "name": "Cloth_Roof_Blue_Flat"
    },
    {
      "x": 4,
      "y": 9,
      "z": -2,
      "name": "Rock_Aqua"
    },
    {
      "x": 4,
      "y": 0,
      "z": -1,
      "name": "Rock_Runic_Teal_Brick"
    },
    {
      "x": 4,
      "y": 1,
      "z": -1,
      "name": "Block_Spawner_Block",
      "components": {
        "Components": {
          "PlacedByInteraction": {
            "WhoPlacedUuid": {
              "$binary": "ownTYu6PR7ebL9OJmdXyVA==",
              "$type": "04"
            }
          },
          "BlockSpawner": {
            "BlockSpawnerId": "The_Aqua_Subterrain_Tier2"
          }
        }
      }
    },
    {
      "x": 4,
      "y": 4,
      "z": -1,
      "name": "Rock_Runic_Blue_Brick"
    },
    {
      "x": 4,
      "y": 5,
      "z": -1,
      "name": "Cloth_Roof_Blue_Flat"
    },
    {
      "x": 4,
      "y": 9,
      "z": -1,
      "name": "Rock_Aqua"
    },
    {
      "x": 4,
      "y": 0,
      "z": 0,
      "name": "Rock_Runic_Teal_Brick"
    },
    {
      "x": 4,
      "y": 1,
      "z": 0,
      "name": "Rubble_Aqua",
      "support": 15
    },
    {
      "x": 4,
      "y": 4,
      "z": 0,
      "name": "Rock_Runic_Blue_Brick"
    },
    {
      "x": 4,
      "y": 5,
      "z": 0,
      "name": "Plant_Coral_Model_Blue"
    },
    {
      "x": 4,
      "y": 9,
      "z": 0,
      "name": "Rock_Aqua"
    },
    {
      "x": 4,
      "y": 0,
      "z": 1,
      "name": "Rock_Runic_Teal_Brick"
    },
    {
      "x": 4,
      "y": 1,
      "z": 1,
      "name": "Deco_Iron_Bars"
    },
    {
      "x": 4,
      "y": 2,
      "z": 1,
      "name": "Deco_Iron_Bars"
    },
    {
      "x": 4,
      "y": 3,
      "z": 1,
      "name": "Deco_Iron_Bars"
    },
    {
      "x": 4,
      "y": 4,
      "z": 1,
      "name": "Rock_Runic_Blue_Brick"
    },
    {
      "x": 4,
      "y": 5,
      "z": 1,
      "name": "Cloth_Roof_Blue_Flat"
    },
    {
      "x": 4,
      "y": 9,
      "z": 1,
      "name": "Rock_Aqua"
    },
    {
      "x": 4,
      "y": 0,
      "z": 2,
      "name": "Rock_Runic_Teal_Brick"
    },
    {
      "x": 4,
      "y": 4,
      "z": 2,
      "name": "Rock_Runic_Blue_Brick"
    },
    {
      "x": 4,
      "y": 5,
      "z": 2,
      "name": "Cloth_Roof_Blue_Flat"
    },
    {
      "x": 4,
      "y": 9,
      "z": 2,
      "name": "Rock_Aqua"
    },
    {
      "x": 4,
      "y": 0,
      "z": 3,
      "name": "Rock_Runic_Teal_Brick"
    },
    {
      "x": 4,
      "y": 3,
      "z": 3,
      "name": "Furniture_Temple_Light_Ladder",
      "rotation": 2
    },
    {
      "x": 4,
      "y": 4,
      "z": 3,
      "name": "Furniture_Temple_Light_Ladder",
      "rotation": 2
    },
    {
      "x": 4,
      "y": 9,
      "z": 3,
      "name": "Rock_Aqua"
    },
    {
      "x": 4,
      "y": 0,
      "z": 4,
      "name": "Rock_Runic_Teal_Brick"
    },
    {
      "x": 4,
      "y": 1,
      "z": 4,
      "name": "Rubble_Aqua_Medium",
      "support": 15
    },
    {
      "x": 4,
      "y": 3,
      "z": 4,
      "name": "Furniture_Temple_Light_Ladder"
    },
    {
      "x": 4,
      "y": 4,
      "z": 4,
      "name": "Rock_Runic_Blue_Brick"
    },
    {
      "x": 4,
      "y": 5,
      "z": 4,
      "name": "Plant_Crop_Mushroom_Common_Blue",
      "components": {
        "Components": {
          "FarmingBlock": {
            "LastTickGameTime": "0001-01-01T12:00:00Z"
          }
        }
      }
    },
    {
      "x": 4,
      "y": 9,
      "z": 4,
      "name": "Rock_Aqua"
    },
    {
      "x": 4,
      "y": 0,
      "z": 5,
      "name": "Rock_Aqua_Brick_Smooth"
    },
    {
      "x": 4,
      "y": 1,
      "z": 5,
      "name": "Rock_Aqua_Brick_Decorative"
    },
    {
      "x": 4,
      "y": 2,
      "z": 5,
      "name": "Rock_Aqua_Brick_Stairs",
      "rotation": 2
    },
    {
      "x": 4,
      "y": 3,
      "z": 5,
      "name": "Rock_Aqua_Brick_Stairs",
      "rotation": 8
    },
    {
      "x": 4,
      "y": 4,
      "z": 5,
      "name": "Rock_Aqua_Brick_Smooth"
    },
    {
      "x": 4,
      "y": 5,
      "z": 5,
      "name": "Furniture_Village_Bookcase",
      "rotation": 2
    },
    {
      "x": 4,
      "y": 6,
      "z": 5,
      "name": "Rock_Aqua_Brick_Half",
      "rotation": 6
    },
    {
      "x": 4,
      "y": 7,
      "z": 5,
      "name": "Rock_Aqua_Brick_Half",
      "rotation": 6
    },
    {
      "x": 4,
      "y": 8,
      "z": 5,
      "name": "Rock_Aqua_Brick_Smooth"
    },
    {
      "x": 4,
      "y": 9,
      "z": 5,
      "name": "Rock_Aqua"
    },
    {
      "x": 5,
      "y": 0,
      "z": -3,
      "name": "Rock_Aqua_Brick_Smooth"
    },
    {
      "x": 5,
      "y": 1,
      "z": -3,
      "name": "Rock_Aqua_Brick_Smooth"
    },
    {
      "x": 5,
      "y": 2,
      "z": -3,
      "name": "Rock_Aqua_Brick_Smooth"
    },
    {
      "x": 5,
      "y": 3,
      "z": -3,
      "name": "Rock_Aqua_Brick_Smooth"
    },
    {
      "x": 5,
      "y": 4,
      "z": -3,
      "name": "Rock_Aqua_Brick_Smooth"
    },
    {
      "x": 5,
      "y": 5,
      "z": -3,
      "name": "Furniture_Ancient_Bookshelf"
    },
    {
      "x": 5,
      "y": 6,
      "z": -3,
      "name": "Furniture_Ancient_Bookshelf"
    },
    {
      "x": 5,
      "y": 7,
      "z": -3,
      "name": "Rock_Aqua_Brick_Half",
      "rotation": 4
    },
    {
      "x": 5,
      "y": 8,
      "z": -3,
      "name": "Rock_Aqua_Brick_Smooth"
    },
    {
      "x": 5,
      "y": 9,
      "z": -3,
      "name": "Rock_Aqua"
    },
    {
      "x": 5,
      "y": 0,
      "z": -2,
      "name": "Rock_Aqua_Brick_Smooth"
    },
    {
      "x": 5,
      "y": 1,
      "z": -2,
      "name": "Rock_Aqua_Brick_Decorative"
    },
    {
      "x": 5,
      "y": 2,
      "z": -2,
      "name": "Rock_Aqua_Brick_Smooth"
    },
    {
      "x": 5,
      "y": 3,
      "z": -2,
      "name": "Rock_Aqua_Brick_Smooth"
    },
    {
      "x": 5,
      "y": 4,
      "z": -2,
      "name": "Rock_Runic_Blue_Brick"
    },
    {
      "x": 5,
      "y": 5,
      "z": -2,
      "name": "Deco_Book_Pile_Small",
      "rotation": 3
    },
    {
      "x": 5,
      "y": 9,
      "z": -2,
      "name": "Rock_Aqua"
    },
    {
      "x": 5,
      "y": 0,
      "z": -1,
      "name": "Rock_Runic_Teal_Brick"
    },
    {
      "x": 5,
      "y": 1,
      "z": -1,
      "name": "Rubble_Aqua_Medium",
      "support": 15
    },
    {
      "x": 5,
      "y": 4,
      "z": -1,
      "name": "Rock_Runic_Blue_Brick"
    },
    {
      "x": 5,
      "y": 5,
      "z": -1,
      "name": "Cloth_Roof_Blue_Flat"
    },
    {
      "x": 5,
      "y": 9,
      "z": -1,
      "name": "Rock_Aqua"
    },
    {
      "x": 5,
      "y": 0,
      "z": 0,
      "name": "Rock_Runic_Teal_Brick"
    },
    {
      "x": 5,
      "y": 1,
      "z": 0,
      "name": "Rubble_Aqua",
      "support": 15
    },
    {
      "x": 5,
      "y": 4,
      "z": 0,
      "name": "Rock_Runic_Blue_Brick"
    },
    {
      "x": 5,
      "y": 9,
      "z": 0,
      "name": "Rock_Aqua"
    },
    {
      "x": 5,
      "y": 0,
      "z": 1,
      "name": "Rock_Runic_Teal_Brick"
    },
    {
      "x": 5,
      "y": 1,
      "z": 1,
      "name": "Deco_Iron_Bars"
    },
    {
      "x": 5,
      "y": 2,
      "z": 1,
      "name": "Deco_Iron_Bars"
    },
    {
      "x": 5,
      "y": 3,
      "z": 1,
      "name": "Deco_Iron_Bars"
    },
    {
      "x": 5,
      "y": 4,
      "z": 1,
      "name": "Rock_Runic_Blue_Brick"
    },
    {
      "x": 5,
      "y": 5,
      "z": 1,
      "name": "Cloth_Roof_Blue_Flat"
    },
    {
      "x": 5,
      "y": 9,
      "z": 1,
      "name": "Rock_Aqua"
    },
    {
      "x": 5,
      "y": 0,
      "z": 2,
      "name": "Rock_Runic_Teal_Brick"
    },
    {
      "x": 5,
      "y": 1,
      "z": 2,
      "name": "Rubble_Aqua_Medium",
      "support": 15
    },
    {
      "x": 5,
      "y": 4,
      "z": 2,
      "name": "Rock_Runic_Blue_Brick"
    },
    {
      "x": 5,
      "y": 5,
      "z": 2,
      "name": "Plant_Crop_Mushroom_Glowing_Blue"
    },
    {
      "x": 5,
      "y": 9,
      "z": 2,
      "name": "Rock_Aqua"
    },
    {
      "x": 5,
      "y": 0,
      "z": 3,
      "name": "Rock_Runic_Teal_Brick"
    },
    {
      "x": 5,
      "y": 1,
      "z": 3,
      "name": "Rock_Aqua_Stalactite_Small"
    },
    {
      "x": 5,
      "y": 4,
      "z": 3,
      "name": "Rock_Runic_Blue_Brick"
    },
    {
      "x": 5,
      "y": 5,
      "z": 3,
      "name": "Cloth_Roof_Blue_Flat"
    },
    {
      "x": 5,
      "y": 9,
      "z": 3,
      "name": "Rock_Aqua"
    },
    {
      "x": 5,
      "y": 0,
      "z": 4,
      "name": "Rock_Runic_Teal_Brick"
    },
    {
      "x": 5,
      "y": 1,
      "z": 4,
      "name": "Rubble_Aqua",
      "support": 15
    },
    {
      "x": 5,
      "y": 4,
      "z": 4,
      "name": "Rock_Runic_Blue_Brick"
    },
    {
      "x": 5,
      "y": 8,
      "z": 4,
      "name": "Plant_Crop_Mushroom_Block_Blue_Mycelium"
    },
    {
      "x": 5,
      "y": 9,
      "z": 4,
      "name": "Rock_Aqua"
    },
    {
      "x": 5,
      "y": 0,
      "z": 5,
      "name": "Rock_Aqua_Brick_Smooth"
    },
    {
      "x": 5,
      "y": 1,
      "z": 5,
      "name": "Rock_Aqua_Brick_Decorative"
    },
    {
      "x": 5,
      "y": 2,
      "z": 5,
      "name": "Rock_Aqua_Brick_Stairs",
      "rotation": 2
    },
    {
      "x": 5,
      "y": 3,
      "z": 5,
      "name": "Rock_Aqua_Brick_Stairs",
      "rotation": 8
    },
    {
      "x": 5,
      "y": 4,
      "z": 5,
      "name": "Rock_Aqua_Brick_Smooth"
    },
    {
      "x": 5,
      "y": 5,
      "z": 5,
      "name": "Rock_Aqua_Brick_Half",
      "rotation": 6
    },
    {
      "x": 5,
      "y": 6,
      "z": 5,
      "name": "Rock_Aqua_Brick_Half",
      "rotation": 6
    },
    {
      "x": 5,
      "y": 7,
      "z": 5,
      "name": "Rock_Aqua_Brick_Half",
      "rotation": 6
    },
    {
      "x": 5,
      "y": 8,
      "z": 5,
      "name": "Rock_Aqua_Brick_Smooth"
    },
    {
      "x": 5,
      "y": 9,
      "z": 5,
      "name": "Rock_Aqua"
    },
    {
      "x": 6,
      "y": 0,
      "z": -3,
      "name": "Rock_Aqua_Brick_Smooth"
    },
    {
      "x": 6,
      "y": 1,
      "z": -3,
      "name": "Rock_Aqua_Brick_Smooth"
    },
    {
      "x": 6,
      "y": 2,
      "z": -3,
      "name": "Rock_Aqua_Brick_Smooth"
    },
    {
      "x": 6,
      "y": 3,
      "z": -3,
      "name": "Rock_Aqua_Brick_Smooth"
    },
    {
      "x": 6,
      "y": 4,
      "z": -3,
      "name": "Rock_Aqua_Brick_Smooth"
    },
    {
      "x": 6,
      "y": 5,
      "z": -3,
      "name": "Rock_Aqua_Brick_Smooth"
    },
    {
      "x": 6,
      "y": 6,
      "z": -3,
      "name": "Rock_Aqua_Brick_Smooth"
    },
    {
      "x": 6,
      "y": 7,
      "z": -3,
      "name": "Rock_Aqua_Brick_Smooth"
    },
    {
      "x": 6,
      "y": 8,
      "z": -3,
      "name": "Rock_Aqua_Brick_Smooth"
    },
    {
      "x": 6,
      "y": 9,
      "z": -3,
      "name": "Rock_Aqua"
    },
    {
      "x": 6,
      "y": 0,
      "z": -2,
      "name": "Rock_Aqua_Brick_Smooth"
    },
    {
      "x": 6,
      "y": 1,
      "z": -2,
      "name": "Rock_Aqua_Brick_Decorative"
    },
    {
      "x": 6,
      "y": 2,
      "z": -2,
      "name": "Rock_Aqua_Brick_Smooth"
    },
    {
      "x": 6,
      "y": 3,
      "z": -2,
      "name": "Rock_Aqua_Brick_Smooth"
    },
    {
      "x": 6,
      "y": 4,
      "z": -2,
      "name": "Rock_Aqua_Brick_Smooth"
    },
    {
      "x": 6,
      "y": 5,
      "z": -2,
      "name": "Rock_Aqua_Brick_Half",
      "rotation": 7
    },
    {
      "x": 6,
      "y": 6,
      "z": -2,
      "name": "Rock_Aqua_Brick_Half",
      "rotation": 7
    },
    {
      "x": 6,
      "y": 7,
      "z": -2,
      "name": "Rock_Aqua_Brick_Half",
      "rotation": 7
    },
    {
      "x": 6,
      "y": 8,
      "z": -2,
      "name": "Rock_Aqua_Brick_Smooth"
    },
    {
      "x": 6,
      "y": 9,
      "z": -2,
      "name": "Rock_Aqua"
    },
    {
      "x": 6,
      "y": 0,
      "z": -1,
      "name": "Rock_Aqua_Brick_Smooth"
    },
    {
      "x": 6,
      "y": 1,
      "z": -1,
      "name": "Rock_Aqua_Brick_Decorative"
    },
    {
      "x": 6,
      "y": 2,
      "z": -1,
      "name": "Rock_Aqua_Brick_Smooth"
    },
    {
      "x": 6,
      "y": 3,
      "z": -1,
      "name": "Rock_Aqua_Brick_Smooth"
    },
    {
      "x": 6,
      "y": 4,
      "z": -1,
      "name": "Rock_Aqua_Brick_Smooth"
    },
    {
      "x": 6,
      "y": 5,
      "z": -1,
      "name": "Rock_Aqua_Brick_Half",
      "rotation": 7
    },
    {
      "x": 6,
      "y": 6,
      "z": -1,
      "name": "Rock_Aqua_Brick_Half",
      "rotation": 7
    },
    {
      "x": 6,
      "y": 7,
      "z": -1,
      "name": "Rock_Aqua_Brick_Half",
      "rotation": 7
    },
    {
      "x": 6,
      "y": 8,
      "z": -1,
      "name": "Rock_Aqua_Brick_Smooth"
    },
    {
      "x": 6,
      "y": 9,
      "z": -1,
      "name": "Rock_Aqua"
    },
    {
      "x": 6,
      "y": 0,
      "z": 0,
      "name": "Rock_Aqua_Brick_Smooth"
    },
    {
      "x": 6,
      "y": 1,
      "z": 0,
      "name": "Rock_Aqua_Brick_Decorative"
    },
    {
      "x": 6,
      "y": 2,
      "z": 0,
      "name": "Rock_Aqua_Brick_Smooth"
    },
    {
      "x": 6,
      "y": 3,
      "z": 0,
      "name": "Rock_Aqua_Brick_Smooth"
    },
    {
      "x": 6,
      "y": 4,
      "z": 0,
      "name": "Rock_Aqua_Brick_Smooth"
    },
    {
      "x": 6,
      "y": 5,
      "z": 0,
      "name": "Rock_Aqua_Brick_Half",
      "rotation": 7
    },
    {
      "x": 6,
      "y": 6,
      "z": 0,
      "name": "Rock_Aqua_Brick_Half",
      "rotation": 7
    },
    {
      "x": 6,
      "y": 7,
      "z": 0,
      "name": "Rock_Aqua_Brick_Half",
      "rotation": 7
    },
    {
      "x": 6,
      "y": 8,
      "z": 0,
      "name": "Rock_Aqua_Brick_Smooth"
    },
    {
      "x": 6,
      "y": 9,
      "z": 0,
      "name": "Rock_Aqua"
    },
    {
      "x": 6,
      "y": 0,
      "z": 1,
      "name": "Rock_Aqua_Brick_Smooth"
    },
    {
      "x": 6,
      "y": 1,
      "z": 1,
      "name": "Rock_Aqua_Brick_Smooth"
    },
    {
      "x": 6,
      "y": 2,
      "z": 1,
      "name": "Rock_Aqua_Brick_Ornate"
    },
    {
      "x": 6,
      "y": 3,
      "z": 1,
      "name": "Rock_Aqua_Brick_Smooth"
    },
    {
      "x": 6,
      "y": 4,
      "z": 1,
      "name": "Rock_Aqua_Brick_Smooth"
    },
    {
      "x": 6,
      "y": 5,
      "z": 1,
      "name": "Rock_Aqua_Brick_Smooth"
    },
    {
      "x": 6,
      "y": 6,
      "z": 1,
      "name": "Rock_Aqua_Brick_Smooth"
    },
    {
      "x": 6,
      "y": 7,
      "z": 1,
      "name": "Rock_Aqua_Brick_Smooth"
    },
    {
      "x": 6,
      "y": 8,
      "z": 1,
      "name": "Rock_Aqua_Brick_Smooth"
    },
    {
      "x": 6,
      "y": 9,
      "z": 1,
      "name": "Rock_Aqua"
    },
    {
      "x": 6,
      "y": 0,
      "z": 2,
      "name": "Rock_Aqua_Brick_Smooth"
    },
    {
      "x": 6,
      "y": 1,
      "z": 2,
      "name": "Rock_Aqua_Brick_Decorative"
    },
    {
      "x": 6,
      "y": 2,
      "z": 2,
      "name": "Rock_Aqua_Brick_Stairs",
      "rotation": 3
    },
    {
      "x": 6,
      "y": 3,
      "z": 2,
      "name": "Rock_Aqua_Brick_Stairs",
      "rotation": 9
    },
    {
      "x": 6,
      "y": 4,
      "z": 2,
      "name": "Rock_Aqua_Brick_Smooth"
    },
    {
      "x": 6,
      "y": 5,
      "z": 2,
      "name": "Furniture_Village_Bookcase",
      "rotation": 3
    },
    {
      "x": 6,
      "y": 6,
      "z": 2,
      "name": "Rock_Aqua_Brick_Half",
      "rotation": 7
    },
    {
      "x": 6,
      "y": 7,
      "z": 2,
      "name": "Rock_Aqua_Brick_Half",
      "rotation": 7
    },
    {
      "x": 6,
      "y": 8,
      "z": 2,
      "name": "Rock_Aqua_Brick_Smooth"
    },
    {
      "x": 6,
      "y": 9,
      "z": 2,
      "name": "Rock_Aqua"
    },
    {
      "x": 6,
      "y": 0,
      "z": 3,
      "name": "Rock_Aqua_Brick_Smooth"
    },
    {
      "x": 6,
      "y": 1,
      "z": 3,
      "name": "Rock_Aqua_Brick_Decorative"
    },
    {
      "x": 6,
      "y": 2,
      "z": 3,
      "name": "Rock_Aqua_Brick_Stairs",
      "rotation": 3
    },
    {
      "x": 6,
      "y": 3,
      "z": 3,
      "name": "Rock_Aqua_Brick_Stairs",
      "rotation": 9
    },
    {
      "x": 6,
      "y": 4,
      "z": 3,
      "name": "Rock_Aqua_Brick_Smooth"
    },
    {
      "x": 6,
      "y": 5,
      "z": 3,
      "name": "Furniture_Ancient_Bookshelf",
      "rotation": 3
    },
    {
      "x": 6,
      "y": 6,
      "z": 3,
      "name": "Furniture_Ancient_Bookshelf",
      "rotation": 3
    },
    {
      "x": 6,
      "y": 7,
      "z": 3,
      "name": "Rock_Aqua_Brick_Half",
      "rotation": 7
    },
    {
      "x": 6,
      "y": 8,
      "z": 3,
      "name": "Rock_Aqua_Brick_Smooth"
    },
    {
      "x": 6,
      "y": 9,
      "z": 3,
      "name": "Rock_Aqua"
    },
    {
      "x": 6,
      "y": 0,
      "z": 4,
      "name": "Rock_Aqua_Brick_Smooth"
    },
    {
      "x": 6,
      "y": 1,
      "z": 4,
      "name": "Rock_Aqua_Brick_Decorative"
    },
    {
      "x": 6,
      "y": 2,
      "z": 4,
      "name": "Rock_Aqua_Brick_Stairs",
      "rotation": 3
    },
    {
      "x": 6,
      "y": 3,
      "z": 4,
      "name": "Rock_Aqua_Brick_Stairs",
      "rotation": 9
    },
    {
      "x": 6,
      "y": 4,
      "z": 4,
      "name": "Rock_Aqua_Brick_Smooth"
    },
    {
      "x": 6,
      "y": 5,
      "z": 4,
      "name": "Furniture_Human_Ruins_Bookshelf",
      "rotation": 3
    },
    {
      "x": 6,
      "y": 6,
      "z": 4,
      "name": "Furniture_Human_Ruins_Bookshelf",
      "support": 1,
      "rotation": 3
    },
    {
      "x": 6,
      "y": 7,
      "z": 4,
      "name": "Rock_Aqua_Brick_Half",
      "rotation": 7
    },
    {
      "x": 6,
      "y": 8,
      "z": 4,
      "name": "Rock_Aqua_Brick_Smooth"
    },
    {
      "x": 6,
      "y": 9,
      "z": 4,
      "name": "Rock_Aqua"
    },
    {
      "x": 6,
      "y": 0,
      "z": 5,
      "name": "Rock_Aqua_Brick_Smooth"
    },
    {
      "x": 6,
      "y": 1,
      "z": 5,
      "name": "Rock_Aqua_Brick_Smooth"
    },
    {
      "x": 6,
      "y": 2,
      "z": 5,
      "name": "Rock_Aqua_Brick_Smooth"
    },
    {
      "x": 6,
      "y": 3,
      "z": 5,
      "name": "Rock_Aqua_Brick_Smooth"
    },
    {
      "x": 6,
      "y": 4,
      "z": 5,
      "name": "Rock_Aqua_Brick_Smooth"
    },
    {
      "x": 6,
      "y": 5,
      "z": 5,
      "name": "Rock_Aqua_Brick_Smooth"
    },
    {
      "x": 6,
      "y": 6,
      "z": 5,
      "name": "Rock_Aqua_Brick_Smooth"
    },
    {
      "x": 6,
      "y": 7,
      "z": 5,
      "name": "Rock_Aqua_Brick_Smooth"
    },
    {
      "x": 6,
      "y": 8,
      "z": 5,
      "name": "Rock_Aqua_Brick_Smooth"
    },
    {
      "x": 6,
      "y": 9,
      "z": 5,
      "name": "Rock_Aqua"
    }
  ],
  "fluids": [
    {
      "x": -6,
      "y": 5,
      "z": -2,
      "name": "Water_Source",
      "level": 1
    },
    {
      "x": -6,
      "y": 6,
      "z": -2,
      "name": "Water_Source",
      "level": 1
    },
    {
      "x": -6,
      "y": 7,
      "z": -2,
      "name": "Water_Source",
      "level": 1
    },
    {
      "x": -6,
      "y": 5,
      "z": -1,
      "name": "Water_Source",
      "level": 1
    },
    {
      "x": -6,
      "y": 6,
      "z": -1,
      "name": "Water_Source",
      "level": 1
    },
    {
      "x": -6,
      "y": 7,
      "z": -1,
      "name": "Water_Source",
      "level": 1
    },
    {
      "x": -6,
      "y": 5,
      "z": 0,
      "name": "Water_Source",
      "level": 1
    },
    {
      "x": -6,
      "y": 6,
      "z": 0,
      "name": "Water_Source",
      "level": 1
    },
    {
      "x": -6,
      "y": 7,
      "z": 0,
      "name": "Water_Source",
      "level": 1
    },
    {
      "x": -6,
      "y": 5,
      "z": 2,
      "name": "Water_Source",
      "level": 1
    },
    {
      "x": -6,
      "y": 6,
      "z": 2,
      "name": "Water_Source",
      "level": 1
    },
    {
      "x": -6,
      "y": 7,
      "z": 2,
      "name": "Water_Source",
      "level": 1
    },
    {
      "x": -6,
      "y": 5,
      "z": 3,
      "name": "Water_Source",
      "level": 1
    },
    {
      "x": -6,
      "y": 6,
      "z": 3,
      "name": "Water_Source",
      "level": 1
    },
    {
      "x": -6,
      "y": 7,
      "z": 3,
      "name": "Water_Source",
      "level": 1
    },
    {
      "x": -6,
      "y": 5,
      "z": 4,
      "name": "Water_Source",
      "level": 1
    },
    {
      "x": -6,
      "y": 6,
      "z": 4,
      "name": "Water_Source",
      "level": 1
    },
    {
      "x": -6,
      "y": 7,
      "z": 4,
      "name": "Water_Source",
      "level": 1
    },
    {
      "x": -5,
      "y": 5,
      "z": -3,
      "name": "Water_Source",
      "level": 1
    },
    {
      "x": -5,
      "y": 6,
      "z": -3,
      "name": "Water_Source",
      "level": 1
    },
    {
      "x": -5,
      "y": 7,
      "z": -3,
      "name": "Water_Source",
      "level": 1
    },
    {
      "x": -5,
      "y": 5,
      "z": -2,
      "name": "Water_Source",
      "level": 1
    },
    {
      "x": -5,
      "y": 6,
      "z": -2,
      "name": "Water_Source",
      "level": 1
    },
    {
      "x": -5,
      "y": 7,
      "z": -2,
      "name": "Water_Source",
      "level": 1
    },
    {
      "x": -5,
      "y": 8,
      "z": -2,
      "name": "Water_Source",
      "level": 1
    },
    {
      "x": -5,
      "y": 5,
      "z": -1,
      "name": "Water_Source",
      "level": 1
    },
    {
      "x": -5,
      "y": 6,
      "z": -1,
      "name": "Water_Source",
      "level": 1
    },
    {
      "x": -5,
      "y": 7,
      "z": -1,
      "name": "Water_Source",
      "level": 1
    },
    {
      "x": -5,
      "y": 8,
      "z": -1,
      "name": "Water_Source",
      "level": 1
    },
    {
      "x": -5,
      "y": 5,
      "z": 0,
      "name": "Water_Source",
      "level": 1
    },
    {
      "x": -5,
      "y": 6,
      "z": 0,
      "name": "Water_Source",
      "level": 1
    },
    {
      "x": -5,
      "y": 7,
      "z": 0,
      "name": "Water_Source",
      "level": 1
    },
    {
      "x": -5,
      "y": 8,
      "z": 0,
      "name": "Water_Source",
      "level": 1
    },
    {
      "x": -5,
      "y": 5,
      "z": 1,
      "name": "Water_Source",
      "level": 1
    },
    {
      "x": -5,
      "y": 6,
      "z": 1,
      "name": "Water_Source",
      "level": 1
    },
    {
      "x": -5,
      "y": 7,
      "z": 1,
      "name": "Water_Source",
      "level": 1
    },
    {
      "x": -5,
      "y": 8,
      "z": 1,
      "name": "Water_Source",
      "level": 1
    },
    {
      "x": -5,
      "y": 5,
      "z": 2,
      "name": "Water_Source",
      "level": 1
    },
    {
      "x": -5,
      "y": 6,
      "z": 2,
      "name": "Water_Source",
      "level": 1
    },
    {
      "x": -5,
      "y": 7,
      "z": 2,
      "name": "Water_Source",
      "level": 1
    },
    {
      "x": -5,
      "y": 8,
      "z": 2,
      "name": "Water_Source",
      "level": 1
    },
    {
      "x": -5,
      "y": 5,
      "z": 3,
      "name": "Water_Source",
      "level": 1
    },
    {
      "x": -5,
      "y": 6,
      "z": 3,
      "name": "Water_Source",
      "level": 1
    },
    {
      "x": -5,
      "y": 7,
      "z": 3,
      "name": "Water_Source",
      "level": 1
    },
    {
      "x": -5,
      "y": 8,
      "z": 3,
      "name": "Water_Source",
      "level": 1
    },
    {
      "x": -5,
      "y": 5,
      "z": 4,
      "name": "Water_Source",
      "level": 1
    },
    {
      "x": -5,
      "y": 6,
      "z": 4,
      "name": "Water_Source",
      "level": 1
    },
    {
      "x": -5,
      "y": 7,
      "z": 4,
      "name": "Water_Source",
      "level": 1
    },
    {
      "x": -5,
      "y": 8,
      "z": 4,
      "name": "Water_Source",
      "level": 1
    },
    {
      "x": -5,
      "y": 5,
      "z": 5,
      "name": "Water_Source",
      "level": 1
    },
    {
      "x": -5,
      "y": 6,
      "z": 5,
      "name": "Water_Source",
      "level": 1
    },
    {
      "x": -5,
      "y": 7,
      "z": 5,
      "name": "Water_Source",
      "level": 1
    },
    {
      "x": -4,
      "y": 5,
      "z": -3,
      "name": "Water_Source",
      "level": 1
    },
    {
      "x": -4,
      "y": 6,
      "z": -3,
      "name": "Water_Source",
      "level": 1
    },
    {
      "x": -4,
      "y": 7,
      "z": -3,
      "name": "Water_Source",
      "level": 1
    },
    {
      "x": -4,
      "y": 5,
      "z": -2,
      "name": "Water_Source",
      "level": 1
    },
    {
      "x": -4,
      "y": 6,
      "z": -2,
      "name": "Water_Source",
      "level": 1
    },
    {
      "x": -4,
      "y": 7,
      "z": -2,
      "name": "Water_Source",
      "level": 1
    },
    {
      "x": -4,
      "y": 8,
      "z": -2,
      "name": "Water_Source",
      "level": 1
    },
    {
      "x": -4,
      "y": 5,
      "z": -1,
      "name": "Water_Source",
      "level": 1
    },
    {
      "x": -4,
      "y": 6,
      "z": -1,
      "name": "Water_Source",
      "level": 1
    },
    {
      "x": -4,
      "y": 7,
      "z": -1,
      "name": "Water_Source",
      "level": 1
    },
    {
      "x": -4,
      "y": 8,
      "z": -1,
      "name": "Water_Source",
      "level": 1
    },
    {
      "x": -4,
      "y": 5,
      "z": 0,
      "name": "Water_Source",
      "level": 1
    },
    {
      "x": -4,
      "y": 6,
      "z": 0,
      "name": "Water_Source",
      "level": 1
    },
    {
      "x": -4,
      "y": 7,
      "z": 0,
      "name": "Water_Source",
      "level": 1
    },
    {
      "x": -4,
      "y": 8,
      "z": 0,
      "name": "Water_Source",
      "level": 1
    },
    {
      "x": -4,
      "y": 5,
      "z": 1,
      "name": "Water_Source",
      "level": 1
    },
    {
      "x": -4,
      "y": 6,
      "z": 1,
      "name": "Water_Source",
      "level": 1
    },
    {
      "x": -4,
      "y": 7,
      "z": 1,
      "name": "Water_Source",
      "level": 1
    },
    {
      "x": -4,
      "y": 8,
      "z": 1,
      "name": "Water_Source",
      "level": 1
    },
    {
      "x": -4,
      "y": 5,
      "z": 2,
      "name": "Water_Source",
      "level": 1
    },
    {
      "x": -4,
      "y": 6,
      "z": 2,
      "name": "Water_Source",
      "level": 1
    },
    {
      "x": -4,
      "y": 7,
      "z": 2,
      "name": "Water_Source",
      "level": 1
    },
    {
      "x": -4,
      "y": 8,
      "z": 2,
      "name": "Water_Source",
      "level": 1
    },
    {
      "x": -4,
      "y": 5,
      "z": 3,
      "name": "Water_Source",
      "level": 1
    },
    {
      "x": -4,
      "y": 6,
      "z": 3,
      "name": "Water_Source",
      "level": 1
    },
    {
      "x": -4,
      "y": 7,
      "z": 3,
      "name": "Water_Source",
      "level": 1
    },
    {
      "x": -4,
      "y": 8,
      "z": 3,
      "name": "Water_Source",
      "level": 1
    },
    {
      "x": -4,
      "y": 5,
      "z": 4,
      "name": "Water_Source",
      "level": 1
    },
    {
      "x": -4,
      "y": 6,
      "z": 4,
      "name": "Water_Source",
      "level": 1
    },
    {
      "x": -4,
      "y": 7,
      "z": 4,
      "name": "Water_Source",
      "level": 1
    },
    {
      "x": -4,
      "y": 8,
      "z": 4,
      "name": "Water_Source",
      "level": 1
    },
    {
      "x": -4,
      "y": 5,
      "z": 5,
      "name": "Water_Source",
      "level": 1
    },
    {
      "x": -4,
      "y": 6,
      "z": 5,
      "name": "Water_Source",
      "level": 1
    },
    {
      "x": -4,
      "y": 7,
      "z": 5,
      "name": "Water_Source",
      "level": 1
    },
    {
      "x": -3,
      "y": 5,
      "z": -3,
      "name": "Water_Source",
      "level": 1
    },
    {
      "x": -3,
      "y": 6,
      "z": -3,
      "name": "Water_Source",
      "level": 1
    },
    {
      "x": -3,
      "y": 7,
      "z": -3,
      "name": "Water_Source",
      "level": 1
    },
    {
      "x": -3,
      "y": 5,
      "z": -2,
      "name": "Water_Source",
      "level": 1
    },
    {
      "x": -3,
      "y": 6,
      "z": -2,
      "name": "Water_Source",
      "level": 1
    },
    {
      "x": -3,
      "y": 7,
      "z": -2,
      "name": "Water_Source",
      "level": 1
    },
    {
      "x": -3,
      "y": 8,
      "z": -2,
      "name": "Water_Source",
      "level": 1
    },
    {
      "x": -3,
      "y": 5,
      "z": -1,
      "name": "Water_Source",
      "level": 1
    },
    {
      "x": -3,
      "y": 6,
      "z": -1,
      "name": "Water_Source",
      "level": 1
    },
    {
      "x": -3,
      "y": 7,
      "z": -1,
      "name": "Water_Source",
      "level": 1
    },
    {
      "x": -3,
      "y": 8,
      "z": -1,
      "name": "Water_Source",
      "level": 1
    },
    {
      "x": -3,
      "y": 5,
      "z": 0,
      "name": "Water_Source",
      "level": 1
    },
    {
      "x": -3,
      "y": 6,
      "z": 0,
      "name": "Water_Source",
      "level": 1
    },
    {
      "x": -3,
      "y": 7,
      "z": 0,
      "name": "Water_Source",
      "level": 1
    },
    {
      "x": -3,
      "y": 8,
      "z": 0,
      "name": "Water_Source",
      "level": 1
    },
    {
      "x": -3,
      "y": 9,
      "z": 0,
      "name": "Water_Source",
      "level": 1
    },
    {
      "x": -3,
      "y": 5,
      "z": 1,
      "name": "Water_Source",
      "level": 1
    },
    {
      "x": -3,
      "y": 6,
      "z": 1,
      "name": "Water_Source",
      "level": 1
    },
    {
      "x": -3,
      "y": 7,
      "z": 1,
      "name": "Water_Source",
      "level": 1
    },
    {
      "x": -3,
      "y": 8,
      "z": 1,
      "name": "Water_Source",
      "level": 1
    },
    {
      "x": -3,
      "y": 9,
      "z": 1,
      "name": "Water_Source",
      "level": 1
    },
    {
      "x": -3,
      "y": 5,
      "z": 2,
      "name": "Water_Source",
      "level": 1
    },
    {
      "x": -3,
      "y": 6,
      "z": 2,
      "name": "Water_Source",
      "level": 1
    },
    {
      "x": -3,
      "y": 7,
      "z": 2,
      "name": "Water_Source",
      "level": 1
    },
    {
      "x": -3,
      "y": 8,
      "z": 2,
      "name": "Water_Source",
      "level": 1
    },
    {
      "x": -3,
      "y": 9,
      "z": 2,
      "name": "Water_Source",
      "level": 1
    },
    {
      "x": -3,
      "y": 5,
      "z": 3,
      "name": "Water_Source",
      "level": 1
    },
    {
      "x": -3,
      "y": 6,
      "z": 3,
      "name": "Water_Source",
      "level": 1
    },
    {
      "x": -3,
      "y": 7,
      "z": 3,
      "name": "Water_Source",
      "level": 1
    },
    {
      "x": -3,
      "y": 8,
      "z": 3,
      "name": "Water_Source",
      "level": 1
    },
    {
      "x": -3,
      "y": 5,
      "z": 4,
      "name": "Water_Source",
      "level": 1
    },
    {
      "x": -3,
      "y": 6,
      "z": 4,
      "name": "Water_Source",
      "level": 1
    },
    {
      "x": -3,
      "y": 7,
      "z": 4,
      "name": "Water_Source",
      "level": 1
    },
    {
      "x": -3,
      "y": 8,
      "z": 4,
      "name": "Water_Source",
      "level": 1
    },
    {
      "x": -3,
      "y": 5,
      "z": 5,
      "name": "Water_Source",
      "level": 1
    },
    {
      "x": -3,
      "y": 6,
      "z": 5,
      "name": "Water_Source",
      "level": 1
    },
    {
      "x": -3,
      "y": 7,
      "z": 5,
      "name": "Water_Source",
      "level": 1
    },
    {
      "x": -2,
      "y": 5,
      "z": -4,
      "name": "Water_Source",
      "level": 1
    },
    {
      "x": -2,
      "y": 7,
      "z": -4,
      "name": "Water_Source",
      "level": 1
    },
    {
      "x": -2,
      "y": 5,
      "z": -2,
      "name": "Water_Source",
      "level": 1
    },
    {
      "x": -2,
      "y": 6,
      "z": -2,
      "name": "Water_Source",
      "level": 1
    },
    {
      "x": -2,
      "y": 7,
      "z": -2,
      "name": "Water_Source",
      "level": 1
    },
    {
      "x": -2,
      "y": 8,
      "z": -2,
      "name": "Water_Source",
      "level": 1
    },
    {
      "x": -2,
      "y": 5,
      "z": -1,
      "name": "Water_Source",
      "level": 1
    },
    {
      "x": -2,
      "y": 6,
      "z": -1,
      "name": "Water_Source",
      "level": 1
    },
    {
      "x": -2,
      "y": 7,
      "z": -1,
      "name": "Water_Source",
      "level": 1
    },
    {
      "x": -2,
      "y": 8,
      "z": -1,
      "name": "Water_Source",
      "level": 1
    },
    {
      "x": -2,
      "y": 5,
      "z": 0,
      "name": "Water_Source",
      "level": 1
    },
    {
      "x": -2,
      "y": 6,
      "z": 0,
      "name": "Water_Source",
      "level": 1
    },
    {
      "x": -2,
      "y": 7,
      "z": 0,
      "name": "Water_Source",
      "level": 1
    },
    {
      "x": -2,
      "y": 8,
      "z": 0,
      "name": "Water_Source",
      "level": 1
    },
    {
      "x": -2,
      "y": 9,
      "z": 0,
      "name": "Water_Source",
      "level": 1
    },
    {
      "x": -2,
      "y": 5,
      "z": 1,
      "name": "Water_Source",
      "level": 1
    },
    {
      "x": -2,
      "y": 6,
      "z": 1,
      "name": "Water_Source",
      "level": 1
    },
    {
      "x": -2,
      "y": 7,
      "z": 1,
      "name": "Water_Source",
      "level": 1
    },
    {
      "x": -2,
      "y": 8,
      "z": 1,
      "name": "Water_Source",
      "level": 1
    },
    {
      "x": -2,
      "y": 9,
      "z": 1,
      "name": "Water_Source",
      "level": 1
    },
    {
      "x": -2,
      "y": 5,
      "z": 2,
      "name": "Water_Source",
      "level": 1
    },
    {
      "x": -2,
      "y": 6,
      "z": 2,
      "name": "Water_Source",
      "level": 1
    },
    {
      "x": -2,
      "y": 7,
      "z": 2,
      "name": "Water_Source",
      "level": 1
    },
    {
      "x": -2,
      "y": 8,
      "z": 2,
      "name": "Water_Source",
      "level": 1
    },
    {
      "x": -2,
      "y": 9,
      "z": 2,
      "name": "Water_Source",
      "level": 1
    },
    {
      "x": -2,
      "y": 5,
      "z": 3,
      "name": "Water_Source",
      "level": 1
    },
    {
      "x": -2,
      "y": 6,
      "z": 3,
      "name": "Water_Source",
      "level": 1
    },
    {
      "x": -2,
      "y": 7,
      "z": 3,
      "name": "Water_Source",
      "level": 1
    },
    {
      "x": -2,
      "y": 8,
      "z": 3,
      "name": "Water_Source",
      "level": 1
    },
    {
      "x": -2,
      "y": 5,
      "z": 4,
      "name": "Water_Source",
      "level": 1
    },
    {
      "x": -2,
      "y": 6,
      "z": 4,
      "name": "Water_Source",
      "level": 1
    },
    {
      "x": -2,
      "y": 7,
      "z": 4,
      "name": "Water_Source",
      "level": 1
    },
    {
      "x": -2,
      "y": 8,
      "z": 4,
      "name": "Water_Source",
      "level": 1
    },
    {
      "x": -1,
      "y": 5,
      "z": -5,
      "name": "Water_Source",
      "level": 1
    },
    {
      "x": -1,
      "y": 6,
      "z": -5,
      "name": "Water_Source",
      "level": 1
    },
    {
      "x": -1,
      "y": 7,
      "z": -5,
      "name": "Water_Source",
      "level": 1
    },
    {
      "x": -1,
      "y": 4,
      "z": -4,
      "name": "Water_Source",
      "level": 1
    },
    {
      "x": -1,
      "y": 5,
      "z": -4,
      "name": "Water_Source",
      "level": 1
    },
    {
      "x": -1,
      "y": 6,
      "z": -4,
      "name": "Water_Source",
      "level": 1
    },
    {
      "x": -1,
      "y": 7,
      "z": -4,
      "name": "Water_Source",
      "level": 1
    },
    {
      "x": -1,
      "y": 8,
      "z": -4,
      "name": "Water_Source",
      "level": 1
    },
    {
      "x": -1,
      "y": 5,
      "z": -3,
      "name": "Water_Source",
      "level": 1
    },
    {
      "x": -1,
      "y": 6,
      "z": -3,
      "name": "Water_Source",
      "level": 1
    },
    {
      "x": -1,
      "y": 7,
      "z": -3,
      "name": "Water_Source",
      "level": 1
    },
    {
      "x": -1,
      "y": 5,
      "z": -2,
      "name": "Water_Source",
      "level": 1
    },
    {
      "x": -1,
      "y": 6,
      "z": -2,
      "name": "Water_Source",
      "level": 1
    },
    {
      "x": -1,
      "y": 7,
      "z": -2,
      "name": "Water_Source",
      "level": 1
    },
    {
      "x": -1,
      "y": 8,
      "z": -2,
      "name": "Water_Source",
      "level": 1
    },
    {
      "x": -1,
      "y": 5,
      "z": -1,
      "name": "Water_Source",
      "level": 1
    },
    {
      "x": -1,
      "y": 6,
      "z": -1,
      "name": "Water_Source",
      "level": 1
    },
    {
      "x": -1,
      "y": 7,
      "z": -1,
      "name": "Water_Source",
      "level": 1
    },
    {
      "x": -1,
      "y": 8,
      "z": -1,
      "name": "Water_Source",
      "level": 1
    },
    {
      "x": -1,
      "y": 5,
      "z": 0,
      "name": "Water_Source",
      "level": 1
    },
    {
      "x": -1,
      "y": 6,
      "z": 0,
      "name": "Water_Source",
      "level": 1
    },
    {
      "x": -1,
      "y": 7,
      "z": 0,
      "name": "Water_Source",
      "level": 1
    },
    {
      "x": -1,
      "y": 8,
      "z": 0,
      "name": "Water_Source",
      "level": 1
    },
    {
      "x": -1,
      "y": 9,
      "z": 0,
      "name": "Water_Source",
      "level": 1
    },
    {
      "x": -1,
      "y": 5,
      "z": 1,
      "name": "Water_Source",
      "level": 1
    },
    {
      "x": -1,
      "y": 6,
      "z": 1,
      "name": "Water_Source",
      "level": 1
    },
    {
      "x": -1,
      "y": 7,
      "z": 1,
      "name": "Water_Source",
      "level": 1
    },
    {
      "x": -1,
      "y": 8,
      "z": 1,
      "name": "Water_Source",
      "level": 1
    },
    {
      "x": -1,
      "y": 9,
      "z": 1,
      "name": "Water_Source",
      "level": 1
    },
    {
      "x": -1,
      "y": 5,
      "z": 2,
      "name": "Water_Source",
      "level": 1
    },
    {
      "x": -1,
      "y": 6,
      "z": 2,
      "name": "Water_Source",
      "level": 1
    },
    {
      "x": -1,
      "y": 7,
      "z": 2,
      "name": "Water_Source",
      "level": 1
    },
    {
      "x": -1,
      "y": 8,
      "z": 2,
      "name": "Water_Source",
      "level": 1
    },
    {
      "x": -1,
      "y": 9,
      "z": 2,
      "name": "Water_Source",
      "level": 1
    },
    {
      "x": -1,
      "y": 5,
      "z": 3,
      "name": "Water_Source",
      "level": 1
    },
    {
      "x": -1,
      "y": 6,
      "z": 3,
      "name": "Water_Source",
      "level": 1
    },
    {
      "x": -1,
      "y": 7,
      "z": 3,
      "name": "Water_Source",
      "level": 1
    },
    {
      "x": -1,
      "y": 8,
      "z": 3,
      "name": "Water_Source",
      "level": 1
    },
    {
      "x": -1,
      "y": 5,
      "z": 4,
      "name": "Water_Source",
      "level": 1
    },
    {
      "x": -1,
      "y": 6,
      "z": 4,
      "name": "Water_Source",
      "level": 1
    },
    {
      "x": -1,
      "y": 7,
      "z": 4,
      "name": "Water_Source",
      "level": 1
    },
    {
      "x": -1,
      "y": 8,
      "z": 4,
      "name": "Water_Source",
      "level": 1
    },
    {
      "x": -1,
      "y": 5,
      "z": 5,
      "name": "Water_Source",
      "level": 1
    },
    {
      "x": -1,
      "y": 6,
      "z": 5,
      "name": "Water_Source",
      "level": 1
    },
    {
      "x": -1,
      "y": 7,
      "z": 5,
      "name": "Water_Source",
      "level": 1
    },
    {
      "x": 0,
      "y": 5,
      "z": -5,
      "name": "Water_Source",
      "level": 1
    },
    {
      "x": 0,
      "y": 6,
      "z": -5,
      "name": "Water_Source",
      "level": 1
    },
    {
      "x": 0,
      "y": 7,
      "z": -5,
      "name": "Water_Source",
      "level": 1
    },
    {
      "x": 0,
      "y": 5,
      "z": -4,
      "name": "Water_Source",
      "level": 1
    },
    {
      "x": 0,
      "y": 6,
      "z": -4,
      "name": "Water_Source",
      "level": 1
    },
    {
      "x": 0,
      "y": 7,
      "z": -4,
      "name": "Water_Source",
      "level": 1
    },
    {
      "x": 0,
      "y": 5,
      "z": -3,
      "name": "Water_Source",
      "level": 1
    },
    {
      "x": 0,
      "y": 6,
      "z": -3,
      "name": "Water_Source",
      "level": 1
    },
    {
      "x": 0,
      "y": 7,
      "z": -3,
      "name": "Water_Source",
      "level": 1
    },
    {
      "x": 0,
      "y": 5,
      "z": -2,
      "name": "Water_Source",
      "level": 1
    },
    {
      "x": 0,
      "y": 6,
      "z": -2,
      "name": "Water_Source",
      "level": 1
    },
    {
      "x": 0,
      "y": 7,
      "z": -2,
      "name": "Water_Source",
      "level": 1
    },
    {
      "x": 0,
      "y": 8,
      "z": -2,
      "name": "Water_Source",
      "level": 1
    },
    {
      "x": 0,
      "y": 5,
      "z": -1,
      "name": "Water_Source",
      "level": 1
    },
    {
      "x": 0,
      "y": 6,
      "z": -1,
      "name": "Water_Source",
      "level": 1
    },
    {
      "x": 0,
      "y": 7,
      "z": -1,
      "name": "Water_Source",
      "level": 1
    },
    {
      "x": 0,
      "y": 8,
      "z": -1,
      "name": "Water_Source",
      "level": 1
    },
    {
      "x": 0,
      "y": 5,
      "z": 0,
      "name": "Water_Source",
      "level": 1
    },
    {
      "x": 0,
      "y": 6,
      "z": 0,
      "name": "Water_Source",
      "level": 1
    },
    {
      "x": 0,
      "y": 7,
      "z": 0,
      "name": "Water_Source",
      "level": 1
    },
    {
      "x": 0,
      "y": 8,
      "z": 0,
      "name": "Water_Source",
      "level": 1
    },
    {
      "x": 0,
      "y": 9,
      "z": 0,
      "name": "Water_Source",
      "level": 1
    },
    {
      "x": 0,
      "y": 5,
      "z": 1,
      "name": "Water_Source",
      "level": 1
    },
    {
      "x": 0,
      "y": 6,
      "z": 1,
      "name": "Water_Source",
      "level": 1
    },
    {
      "x": 0,
      "y": 7,
      "z": 1,
      "name": "Water_Source",
      "level": 1
    },
    {
      "x": 0,
      "y": 8,
      "z": 1,
      "name": "Water_Source",
      "level": 1
    },
    {
      "x": 0,
      "y": 9,
      "z": 1,
      "name": "Water_Source",
      "level": 1
    },
    {
      "x": 0,
      "y": 5,
      "z": 2,
      "name": "Water_Source",
      "level": 1
    },
    {
      "x": 0,
      "y": 6,
      "z": 2,
      "name": "Water_Source",
      "level": 1
    },
    {
      "x": 0,
      "y": 7,
      "z": 2,
      "name": "Water_Source",
      "level": 1
    },
    {
      "x": 0,
      "y": 8,
      "z": 2,
      "name": "Water_Source",
      "level": 1
    },
    {
      "x": 0,
      "y": 9,
      "z": 2,
      "name": "Water_Source",
      "level": 1
    },
    {
      "x": 0,
      "y": 5,
      "z": 3,
      "name": "Water_Source",
      "level": 1
    },
    {
      "x": 0,
      "y": 6,
      "z": 3,
      "name": "Water_Source",
      "level": 1
    },
    {
      "x": 0,
      "y": 7,
      "z": 3,
      "name": "Water_Source",
      "level": 1
    },
    {
      "x": 0,
      "y": 8,
      "z": 3,
      "name": "Water_Source",
      "level": 1
    },
    {
      "x": 0,
      "y": 5,
      "z": 4,
      "name": "Water_Source",
      "level": 1
    },
    {
      "x": 0,
      "y": 6,
      "z": 4,
      "name": "Water_Source",
      "level": 1
    },
    {
      "x": 0,
      "y": 7,
      "z": 4,
      "name": "Water_Source",
      "level": 1
    },
    {
      "x": 0,
      "y": 8,
      "z": 4,
      "name": "Water_Source",
      "level": 1
    },
    {
      "x": 0,
      "y": 5,
      "z": 5,
      "name": "Water_Source",
      "level": 1
    },
    {
      "x": 0,
      "y": 6,
      "z": 5,
      "name": "Water_Source",
      "level": 1
    },
    {
      "x": 0,
      "y": 7,
      "z": 5,
      "name": "Water_Source",
      "level": 1
    },
    {
      "x": 1,
      "y": 5,
      "z": -5,
      "name": "Water_Source",
      "level": 1
    },
    {
      "x": 1,
      "y": 6,
      "z": -5,
      "name": "Water_Source",
      "level": 1
    },
    {
      "x": 1,
      "y": 7,
      "z": -5,
      "name": "Water_Source",
      "level": 1
    },
    {
      "x": 1,
      "y": 4,
      "z": -4,
      "name": "Water_Source",
      "level": 1
    },
    {
      "x": 1,
      "y": 5,
      "z": -4,
      "name": "Water_Source",
      "level": 1
    },
    {
      "x": 1,
      "y": 6,
      "z": -4,
      "name": "Water_Source",
      "level": 1
    },
    {
      "x": 1,
      "y": 7,
      "z": -4,
      "name": "Water_Source",
      "level": 1
    },
    {
      "x": 1,
      "y": 8,
      "z": -4,
      "name": "Water_Source",
      "level": 1
    },
    {
      "x": 1,
      "y": 5,
      "z": -3,
      "name": "Water_Source",
      "level": 1
    },
    {
      "x": 1,
      "y": 6,
      "z": -3,
      "name": "Water_Source",
      "level": 1
    },
    {
      "x": 1,
      "y": 7,
      "z": -3,
      "name": "Water_Source",
      "level": 1
    },
    {
      "x": 1,
      "y": 5,
      "z": -2,
      "name": "Water_Source",
      "level": 1
    },
    {
      "x": 1,
      "y": 6,
      "z": -2,
      "name": "Water_Source",
      "level": 1
    },
    {
      "x": 1,
      "y": 7,
      "z": -2,
      "name": "Water_Source",
      "level": 1
    },
    {
      "x": 1,
      "y": 8,
      "z": -2,
      "name": "Water_Source",
      "level": 1
    },
    {
      "x": 1,
      "y": 5,
      "z": -1,
      "name": "Water_Source",
      "level": 1
    },
    {
      "x": 1,
      "y": 6,
      "z": -1,
      "name": "Water_Source",
      "level": 1
    },
    {
      "x": 1,
      "y": 7,
      "z": -1,
      "name": "Water_Source",
      "level": 1
    },
    {
      "x": 1,
      "y": 8,
      "z": -1,
      "name": "Water_Source",
      "level": 1
    },
    {
      "x": 1,
      "y": 5,
      "z": 0,
      "name": "Water_Source",
      "level": 1
    },
    {
      "x": 1,
      "y": 6,
      "z": 0,
      "name": "Water_Source",
      "level": 1
    },
    {
      "x": 1,
      "y": 7,
      "z": 0,
      "name": "Water_Source",
      "level": 1
    },
    {
      "x": 1,
      "y": 8,
      "z": 0,
      "name": "Water_Source",
      "level": 1
    },
    {
      "x": 1,
      "y": 9,
      "z": 0,
      "name": "Water_Source",
      "level": 1
    },
    {
      "x": 1,
      "y": 5,
      "z": 1,
      "name": "Water_Source",
      "level": 1
    },
    {
      "x": 1,
      "y": 6,
      "z": 1,
      "name": "Water_Source",
      "level": 1
    },
    {
      "x": 1,
      "y": 7,
      "z": 1,
      "name": "Water_Source",
      "level": 1
    },
    {
      "x": 1,
      "y": 8,
      "z": 1,
      "name": "Water_Source",
      "level": 1
    },
    {
      "x": 1,
      "y": 9,
      "z": 1,
      "name": "Water_Source",
      "level": 1
    },
    {
      "x": 1,
      "y": 5,
      "z": 2,
      "name": "Water_Source",
      "level": 1
    },
    {
      "x": 1,
      "y": 6,
      "z": 2,
      "name": "Water_Source",
      "level": 1
    },
    {
      "x": 1,
      "y": 7,
      "z": 2,
      "name": "Water_Source",
      "level": 1
    },
    {
      "x": 1,
      "y": 8,
      "z": 2,
      "name": "Water_Source",
      "level": 1
    },
    {
      "x": 1,
      "y": 9,
      "z": 2,
      "name": "Water_Source",
      "level": 1
    },
    {
      "x": 1,
      "y": 5,
      "z": 3,
      "name": "Water_Source",
      "level": 1
    },
    {
      "x": 1,
      "y": 6,
      "z": 3,
      "name": "Water_Source",
      "level": 1
    },
    {
      "x": 1,
      "y": 7,
      "z": 3,
      "name": "Water_Source",
      "level": 1
    },
    {
      "x": 1,
      "y": 8,
      "z": 3,
      "name": "Water_Source",
      "level": 1
    },
    {
      "x": 1,
      "y": 5,
      "z": 4,
      "name": "Water_Source",
      "level": 1
    },
    {
      "x": 1,
      "y": 6,
      "z": 4,
      "name": "Water_Source",
      "level": 1
    },
    {
      "x": 1,
      "y": 7,
      "z": 4,
      "name": "Water_Source",
      "level": 1
    },
    {
      "x": 1,
      "y": 8,
      "z": 4,
      "name": "Water_Source",
      "level": 1
    },
    {
      "x": 1,
      "y": 5,
      "z": 5,
      "name": "Water_Source",
      "level": 1
    },
    {
      "x": 1,
      "y": 6,
      "z": 5,
      "name": "Water_Source",
      "level": 1
    },
    {
      "x": 1,
      "y": 7,
      "z": 5,
      "name": "Water_Source",
      "level": 1
    },
    {
      "x": 2,
      "y": 5,
      "z": -4,
      "name": "Water_Source",
      "level": 1
    },
    {
      "x": 2,
      "y": 7,
      "z": -4,
      "name": "Water_Source",
      "level": 1
    },
    {
      "x": 2,
      "y": 5,
      "z": -2,
      "name": "Water_Source",
      "level": 1
    },
    {
      "x": 2,
      "y": 6,
      "z": -2,
      "name": "Water_Source",
      "level": 1
    },
    {
      "x": 2,
      "y": 7,
      "z": -2,
      "name": "Water_Source",
      "level": 1
    },
    {
      "x": 2,
      "y": 8,
      "z": -2,
      "name": "Water_Source",
      "level": 1
    },
    {
      "x": 2,
      "y": 5,
      "z": -1,
      "name": "Water_Source",
      "level": 1
    },
    {
      "x": 2,
      "y": 6,
      "z": -1,
      "name": "Water_Source",
      "level": 1
    },
    {
      "x": 2,
      "y": 7,
      "z": -1,
      "name": "Water_Source",
      "level": 1
    },
    {
      "x": 2,
      "y": 8,
      "z": -1,
      "name": "Water_Source",
      "level": 1
    },
    {
      "x": 2,
      "y": 5,
      "z": 0,
      "name": "Water_Source",
      "level": 1
    },
    {
      "x": 2,
      "y": 6,
      "z": 0,
      "name": "Water_Source",
      "level": 1
    },
    {
      "x": 2,
      "y": 7,
      "z": 0,
      "name": "Water_Source",
      "level": 1
    },
    {
      "x": 2,
      "y": 8,
      "z": 0,
      "name": "Water_Source",
      "level": 1
    },
    {
      "x": 2,
      "y": 9,
      "z": 0,
      "name": "Water_Source",
      "level": 1
    },
    {
      "x": 2,
      "y": 5,
      "z": 1,
      "name": "Water_Source",
      "level": 1
    },
    {
      "x": 2,
      "y": 6,
      "z": 1,
      "name": "Water_Source",
      "level": 1
    },
    {
      "x": 2,
      "y": 7,
      "z": 1,
      "name": "Water_Source",
      "level": 1
    },
    {
      "x": 2,
      "y": 8,
      "z": 1,
      "name": "Water_Source",
      "level": 1
    },
    {
      "x": 2,
      "y": 9,
      "z": 1,
      "name": "Water_Source",
      "level": 1
    },
    {
      "x": 2,
      "y": 2,
      "z": 2,
      "name": "Water_Source",
      "level": 1
    },
    {
      "x": 2,
      "y": 3,
      "z": 2,
      "name": "Water_Source",
      "level": 1
    },
    {
      "x": 2,
      "y": 5,
      "z": 2,
      "name": "Water_Source",
      "level": 1
    },
    {
      "x": 2,
      "y": 6,
      "z": 2,
      "name": "Water_Source",
      "level": 1
    },
    {
      "x": 2,
      "y": 7,
      "z": 2,
      "name": "Water_Source",
      "level": 1
    },
    {
      "x": 2,
      "y": 8,
      "z": 2,
      "name": "Water_Source",
      "level": 1
    },
    {
      "x": 2,
      "y": 9,
      "z": 2,
      "name": "Water_Source",
      "level": 1
    },
    {
      "x": 2,
      "y": 2,
      "z": 3,
      "name": "Water_Source",
      "level": 1
    },
    {
      "x": 2,
      "y": 3,
      "z": 3,
      "name": "Water_Source",
      "level": 1
    },
    {
      "x": 2,
      "y": 5,
      "z": 3,
      "name": "Water_Source",
      "level": 1
    },
    {
      "x": 2,
      "y": 6,
      "z": 3,
      "name": "Water_Source",
      "level": 1
    },
    {
      "x": 2,
      "y": 7,
      "z": 3,
      "name": "Water_Source",
      "level": 1
    },
    {
      "x": 2,
      "y": 8,
      "z": 3,
      "name": "Water_Source",
      "level": 1
    },
    {
      "x": 2,
      "y": 2,
      "z": 4,
      "name": "Water_Source",
      "level": 1
    },
    {
      "x": 2,
      "y": 3,
      "z": 4,
      "name": "Water_Source",
      "level": 1
    },
    {
      "x": 2,
      "y": 5,
      "z": 4,
      "name": "Water_Source",
      "level": 1
    },
    {
      "x": 2,
      "y": 6,
      "z": 4,
      "name": "Water_Source",
      "level": 1
    },
    {
      "x": 2,
      "y": 7,
      "z": 4,
      "name": "Water_Source",
      "level": 1
    },
    {
      "x": 2,
      "y": 8,
      "z": 4,
      "name": "Water_Source",
      "level": 1
    },
    {
      "x": 3,
      "y": 5,
      "z": -3,
      "name": "Water_Source",
      "level": 1
    },
    {
      "x": 3,
      "y": 6,
      "z": -3,
      "name": "Water_Source",
      "level": 1
    },
    {
      "x": 3,
      "y": 7,
      "z": -3,
      "name": "Water_Source",
      "level": 1
    },
    {
      "x": 3,
      "y": 5,
      "z": -2,
      "name": "Water_Source",
      "level": 1
    },
    {
      "x": 3,
      "y": 6,
      "z": -2,
      "name": "Water_Source",
      "level": 1
    },
    {
      "x": 3,
      "y": 7,
      "z": -2,
      "name": "Water_Source",
      "level": 1
    },
    {
      "x": 3,
      "y": 8,
      "z": -2,
      "name": "Water_Source",
      "level": 1
    },
    {
      "x": 3,
      "y": 1,
      "z": -1,
      "name": "Water_Source",
      "level": 1
    },
    {
      "x": 3,
      "y": 2,
      "z": -1,
      "name": "Water_Source",
      "level": 1
    },
    {
      "x": 3,
      "y": 3,
      "z": -1,
      "name": "Water_Source",
      "level": 1
    },
    {
      "x": 3,
      "y": 5,
      "z": -1,
      "name": "Water_Source",
