{
  "version": 8,
  "blockIdVersion": 11,
  "anchorX": 0,
  "anchorY": 8,
  "anchorZ": 12,
  "blocks": [
    {
      "x": -2,
      "y": -8,
      "z": -12,
      "name": "Rock_Aqua"
    },
    {
      "x": -2,
      "y": -7,
      "z": -12,
      "name": "Rock_Aqua"
    },
    {
      "x": -2,
      "y": -6,
      "z": -12,
      "name": "Rock_Aqua"
    },
    {
      "x": -2,
      "y": -5,
      "z": -12,
      "name": "Rock_Aqua"
    },
    {
      "x": -2,
      "y": -4,
      "z": -12,
      "name": "Rock_Aqua"
    },
    {
      "x": -2,
      "y": -3,
      "z": -12,
      "name": "Rock_Aqua"
    },
    {
      "x": -2,
      "y": -2,
      "z": -12,
      "name": "Rock_Aqua"
    },
    {
      "x": -2,
      "y": -1,
      "z": -12,
      "name": "Rock_Aqua_Brick_Smooth"
    },
    {
      "x": -2,
      "y": 0,
      "z": -12,
      "name": "Rock_Aqua_Brick_Stairs",
      "rotation": 3
    },
    {
      "x": -2,
      "y": 1,
      "z": -12,
      "name": "Rock_Aqua_Brick_Smooth_Half",
      "rotation": 7
    },
    {
      "x": -2,
      "y": 2,
      "z": -12,
      "name": "Rock_Aqua_Brick_Stairs",
      "rotation": 9
    },
    {
      "x": -2,
      "y": 3,
      "z": -12,
      "name": "Rock_Aqua_Brick_Stairs",
      "rotation": 3
    },
    {
      "x": -2,
      "y": 4,
      "z": -12,
      "name": "Rock_Aqua_Brick_Smooth_Half",
      "rotation": 7
    },
    {
      "x": -2,
      "y": 5,
      "z": -12,
      "name": "Rock_Aqua_Brick_Stairs",
      "rotation": 9
    },
    {
      "x": -2,
      "y": 6,
      "z": -12,
      "name": "Rock_Aqua_Brick_Stairs",
      "rotation": 3
    },
    {
      "x": -2,
      "y": 7,
      "z": -12,
      "name": "Rock_Aqua_Brick_Smooth_Half",
      "rotation": 7
    },
    {
      "x": -2,
      "y": 8,
      "z": -12,
      "name": "Rock_Aqua_Brick_Stairs",
      "rotation": 9
    },
    {
      "x": -2,
      "y": 9,
      "z": -12,
      "name": "Rock_Aqua_Brick_Wall",
      "rotation": 3
    },
    {
      "x": -2,
      "y": 4,
      "z": -11,
      "name": "Rock_Aqua_Brick_Smooth_Half",
      "rotation": 7
    },
    {
      "x": -2,
      "y": 5,
      "z": -11,
      "name": "Rock_Aqua_Brick_Stairs",
      "rotation": 9
    },
    {
      "x": -2,
      "y": 6,
      "z": -11,
      "name": "Rock_Aqua_Brick_Stairs",
      "rotation": 3
    },
    {
      "x": -2,
      "y": 7,
      "z": -11,
      "name": "Rock_Aqua_Brick_Smooth_Half",
      "rotation": 7
    },
    {
      "x": -2,
      "y": 8,
      "z": -11,
      "name": "Rock_Aqua_Brick_Stairs",
      "rotation": 9
    },
    {
      "x": -2,
      "y": 9,
      "z": -11,
      "name": "Rock_Aqua_Brick_Wall",
      "rotation": 3
    },
    {
      "x": -2,
      "y": 6,
      "z": -10,
      "name": "Rock_Aqua_Brick_Stairs",
      "rotation": 3
    },
    {
      "x": -2,
      "y": 7,
      "z": -10,
      "name": "Rock_Aqua_Brick_Smooth_Half",
      "rotation": 7
    },
    {
      "x": -2,
      "y": 8,
      "z": -10,
      "name": "Rock_Aqua_Brick_Stairs",
      "rotation": 9
    },
    {
      "x": -2,
      "y": 9,
      "z": -10,
      "name": "Rock_Aqua_Brick_Wall",
      "rotation": 3
    },
    {
      "x": -2,
      "y": 7,
      "z": -9,
      "name": "Rock_Aqua_Brick_Smooth_Half",
      "rotation": 7
    },
    {
      "x": -2,
      "y": 8,
      "z": -9,
      "name": "Rock_Aqua_Brick_Stairs",
      "rotation": 9
    },
    {
      "x": -2,
      "y": 9,
      "z": -9,
      "name": "Rock_Aqua_Brick_Wall",
      "rotation": 3
    },
    {
      "x": -2,
      "y": 8,
      "z": -8,
      "name": "Rock_Aqua_Brick_Stairs",
      "rotation": 9
    },
    {
      "x": -2,
      "y": 9,
      "z": -8,
      "name": "Rock_Aqua_Brick_Wall",
      "rotation": 3
    },
    {
      "x": -2,
      "y": 8,
      "z": -7,
      "name": "Rock_Aqua_Brick_Stairs",
      "rotation": 9
    },
    {
      "x": -2,
      "y": 9,
      "z": -7,
      "name": "Plant_Moss_Rug_Blue",
      "support": 15
    },
    {
      "x": -2,
      "y": 8,
      "z": -6,
      "name": "Plant_Moss_Wall_Blue",
      "support": 15,
      "rotation": 3
    },
    {
      "x": -2,
      "y": 7,
      "z": -4,
      "name": "Plant_Moss_Wall_Blue",
      "support": 15,
      "rotation": 3
    },
    {
      "x": -2,
      "y": 8,
      "z": -4,
      "name": "Rock_Aqua_Brick_Stairs",
      "rotation": 9
    },
    {
      "x": -2,
      "y": 9,
      "z": -4,
      "name": "Plant_Moss_Rug_Blue",
      "support": 15
    },
    {
      "x": -2,
      "y": 7,
      "z": -3,
      "name": "Rock_Aqua_Brick_Smooth_Half",
      "rotation": 7
    },
    {
      "x": -2,
      "y": 8,
      "z": -3,
      "name": "Rock_Aqua_Brick_Stairs",
      "rotation": 9
    },
    {
      "x": -2,
      "y": 9,
      "z": -3,
      "name": "Rock_Aqua_Brick_Wall",
      "rotation": 3
    },
    {
      "x": -2,
      "y": 6,
      "z": -2,
      "name": "Rock_Aqua_Brick_Stairs",
      "rotation": 3
    },
    {
      "x": -2,
      "y": 7,
      "z": -2,
      "name": "Rock_Aqua_Brick_Smooth_Half",
      "rotation": 7
    },
    {
      "x": -2,
      "y": 8,
      "z": -2,
      "name": "Rock_Aqua_Brick_Stairs",
      "rotation": 9
    },
    {
      "x": -2,
      "y": 9,
      "z": -2,
      "name": "Rock_Aqua_Brick_Wall",
      "rotation": 3
    },
    {
      "x": -2,
      "y": 4,
      "z": -1,
      "name": "Rock_Aqua_Brick_Smooth_Half",
      "rotation": 7
    },
    {
      "x": -2,
      "y": 5,
      "z": -1,
      "name": "Rock_Aqua_Brick_Stairs",
      "rotation": 9
    },
    {
      "x": -2,
      "y": 6,
      "z": -1,
      "name": "Rock_Aqua_Brick_Stairs",
      "rotation": 3
    },
    {
      "x": -2,
      "y": 7,
      "z": -1,
      "name": "Rock_Aqua_Brick_Smooth_Half",
      "rotation": 7
    },
    {
      "x": -2,
      "y": 8,
      "z": -1,
      "name": "Rock_Aqua_Brick_Stairs",
      "rotation": 9
    },
    {
      "x": -2,
      "y": 9,
      "z": -1,
      "name": "Rock_Aqua_Brick_Wall",
      "rotation": 3
    },
    {
      "x": -2,
      "y": -8,
      "z": 0,
      "name": "Rock_Aqua"
    },
    {
      "x": -2,
      "y": -7,
      "z": 0,
      "name": "Rock_Aqua"
    },
    {
      "x": -2,
      "y": -6,
      "z": 0,
      "name": "Rock_Aqua"
    },
    {
      "x": -2,
      "y": -5,
      "z": 0,
      "name": "Rock_Aqua"
    },
    {
      "x": -2,
      "y": -4,
      "z": 0,
      "name": "Rock_Aqua"
    },
    {
      "x": -2,
      "y": -3,
      "z": 0,
      "name": "Rock_Aqua"
    },
    {
      "x": -2,
      "y": -2,
      "z": 0,
      "name": "Rock_Aqua"
    },
    {
      "x": -2,
      "y": -1,
      "z": 0,
      "name": "Rock_Aqua_Brick_Smooth"
    },
    {
      "x": -2,
      "y": 0,
      "z": 0,
      "name": "Rock_Aqua_Brick_Stairs",
      "rotation": 3
    },
    {
      "x": -2,
      "y": 1,
      "z": 0,
      "name": "Rock_Aqua_Brick_Smooth_Half",
      "rotation": 7
    },
    {
      "x": -2,
      "y": 2,
      "z": 0,
      "name": "Rock_Aqua_Brick_Stairs",
      "rotation": 9
    },
    {
      "x": -2,
      "y": 3,
      "z": 0,
      "name": "Rock_Aqua_Brick_Stairs",
      "rotation": 3
    },
    {
      "x": -2,
      "y": 4,
      "z": 0,
      "name": "Rock_Aqua_Brick_Smooth_Half",
      "rotation": 7
    },
    {
      "x": -2,
      "y": 5,
      "z": 0,
      "name": "Rock_Aqua_Brick_Stairs",
      "rotation": 9
    },
    {
      "x": -2,
      "y": 6,
      "z": 0,
      "name": "Rock_Aqua_Brick_Stairs",
      "rotation": 3
    },
    {
      "x": -2,
      "y": 7,
      "z": 0,
      "name": "Rock_Aqua_Brick_Smooth_Half",
      "rotation": 7
    },
    {
      "x": -2,
      "y": 8,
      "z": 0,
      "name": "Rock_Aqua_Brick_Stairs",
      "rotation": 9
    },
    {
      "x": -2,
      "y": 9,
      "z": 0,
      "name": "Rock_Aqua_Brick_Wall",
      "rotation": 3
    },
    {
      "x": -2,
      "y": 4,
      "z": 1,
      "name": "Rock_Aqua_Brick_Smooth_Half",
      "rotation": 7
    },
    {
      "x": -2,
      "y": 5,
      "z": 1,
      "name": "Rock_Aqua_Brick_Stairs",
      "rotation": 9
    },
    {
      "x": -2,
      "y": 6,
      "z": 1,
      "name": "Rock_Aqua_Brick_Stairs",
      "rotation": 3
    },
    {
      "x": -2,
      "y": 7,
      "z": 1,
      "name": "Rock_Aqua_Brick_Smooth_Half",
      "rotation": 7
    },
    {
      "x": -2,
      "y": 8,
      "z": 1,
      "name": "Rock_Aqua_Brick_Stairs",
      "rotation": 9
    },
    {
      "x": -2,
      "y": 9,
      "z": 1,
      "name": "Rock_Aqua_Brick_Wall",
      "rotation": 3
    },
    {
      "x": -2,
      "y": 6,
      "z": 2,
      "name": "Rock_Aqua_Brick_Stairs",
      "rotation": 3
    },
    {
      "x": -2,
      "y": 7,
      "z": 2,
      "name": "Rock_Aqua_Brick_Smooth_Half",
      "rotation": 7
    },
    {
      "x": -2,
      "y": 8,
      "z": 2,
      "name": "Rock_Aqua_Brick_Stairs",
      "rotation": 9
    },
    {
      "x": -2,
      "y": 9,
      "z": 2,
      "name": "Rock_Aqua_Brick_Wall",
      "rotation": 3
    },
    {
      "x": -2,
      "y": 7,
      "z": 3,
      "name": "Rock_Aqua_Brick_Smooth_Half",
      "rotation": 7
    },
    {
      "x": -2,
      "y": 8,
      "z": 3,
      "name": "Rock_Aqua_Brick_Stairs",
      "rotation": 9
    },
    {
      "x": -2,
      "y": 9,
      "z": 3,
      "name": "Rock_Aqua_Brick_Wall",
      "rotation": 3
    },
    {
      "x": -2,
      "y": 8,
      "z": 4,
      "name": "Rock_Aqua_Brick_Stairs",
      "rotation": 9
    },
    {
      "x": -2,
      "y": 9,
      "z": 4,
      "name": "Rock_Aqua_Brick_Wall",
      "rotation": 3
    },
    {
      "x": -2,
      "y": 8,
      "z": 5,
      "name": "Rock_Aqua_Brick_Stairs",
      "rotation": 9
    },
    {
      "x": -2,
      "y": 9,
      "z": 5,
      "name": "Rock_Aqua_Brick_Wall",
      "rotation": 3
    },
    {
      "x": -2,
      "y": 8,
      "z": 6,
      "name": "Rock_Aqua_Brick_Stairs",
      "rotation": 9
    },
    {
      "x": -2,
      "y": 9,
      "z": 6,
      "name": "Rock_Aqua_Brick_Wall",
      "rotation": 3
    },
    {
      "x": -2,
      "y": 8,
      "z": 7,
      "name": "Rock_Aqua_Brick_Stairs",
      "rotation": 9
    },
    {
      "x": -2,
      "y": 9,
      "z": 7,
      "name": "Rock_Aqua_Brick_Wall",
      "rotation": 3
    },
    {
      "x": -2,
      "y": 8,
      "z": 8,
      "name": "Rock_Aqua_Brick_Stairs",
      "rotation": 9
    },
    {
      "x": -2,
      "y": 9,
      "z": 8,
      "name": "Rock_Aqua_Brick_Wall",
      "rotation": 3
    },
    {
      "x": -2,
      "y": 7,
      "z": 9,
      "name": "Rock_Aqua_Brick_Smooth_Half",
      "rotation": 7
    },
    {
      "x": -2,
      "y": 8,
      "z": 9,
      "name": "Rock_Aqua_Brick_Stairs",
      "rotation": 9
    },
    {
      "x": -2,
      "y": 9,
      "z": 9,
      "name": "Rock_Aqua_Brick_Wall",
      "rotation": 3
    },
    {
      "x": -2,
      "y": 6,
      "z": 10,
      "name": "Rock_Aqua_Brick_Stairs",
      "rotation": 3
    },
    {
      "x": -2,
      "y": 7,
      "z": 10,
      "name": "Rock_Aqua_Brick_Smooth_Half",
      "rotation": 7
    },
    {
      "x": -2,
      "y": 8,
      "z": 10,
      "name": "Rock_Aqua_Brick_Stairs",
      "rotation": 9
    },
    {
      "x": -2,
      "y": 9,
      "z": 10,
      "name": "Rock_Aqua_Brick_Wall",
      "rotation": 3
    },
    {
      "x": -2,
      "y": 2,
      "z": 11,
      "name": "Rock_Aqua_Brick_Stairs",
      "rotation": 9
    },
    {
      "x": -2,
      "y": 3,
      "z": 11,
      "name": "Rock_Aqua_Brick_Stairs",
      "rotation": 3
    },
    {
      "x": -2,
      "y": 4,
      "z": 11,
      "name": "Rock_Aqua_Brick_Smooth_Half",
      "rotation": 7
    },
    {
      "x": -2,
      "y": 5,
      "z": 11,
      "name": "Rock_Aqua_Brick_Stairs",
      "rotation": 9
    },
    {
      "x": -2,
      "y": 6,
      "z": 11,
      "name": "Rock_Aqua_Brick_Stairs",
      "rotation": 3
    },
    {
      "x": -2,
      "y": 7,
      "z": 11,
      "name": "Rock_Aqua_Brick_Smooth_Half",
      "rotation": 7
    },
    {
      "x": -2,
      "y": 8,
      "z": 11,
      "name": "Rock_Aqua_Brick_Stairs",
      "rotation": 9
    },
    {
      "x": -2,
      "y": 9,
      "z": 11,
      "name": "Rock_Aqua_Brick_Wall",
      "rotation": 3
    },
    {
      "x": -2,
      "y": -8,
      "z": 12,
      "name": "Rock_Aqua"
    },
    {
      "x": -2,
      "y": -7,
      "z": 12,
      "name": "Rock_Aqua"
    },
    {
      "x": -2,
      "y": -6,
      "z": 12,
      "name": "Rock_Aqua"
    },
    {
      "x": -2,
      "y": -5,
      "z": 12,
      "name": "Rock_Aqua"
    },
    {
      "x": -2,
      "y": -4,
      "z": 12,
      "name": "Rock_Aqua"
    },
    {
      "x": -2,
      "y": -3,
      "z": 12,
      "name": "Rock_Aqua"
    },
    {
      "x": -2,
      "y": -2,
      "z": 12,
      "name": "Rock_Aqua"
    },
    {
      "x": -2,
      "y": -1,
      "z": 12,
      "name": "Rock_Aqua_Brick_Smooth"
    },
    {
      "x": -2,
      "y": 0,
      "z": 12,
      "name": "Rock_Aqua_Brick_Stairs",
      "rotation": 3
    },
    {
      "x": -2,
      "y": 1,
      "z": 12,
      "name": "Rock_Aqua_Brick_Smooth_Half",
      "rotation": 7
    },
    {
      "x": -2,
      "y": 2,
      "z": 12,
      "name": "Rock_Aqua_Brick_Stairs",
      "rotation": 9
    },
    {
      "x": -2,
      "y": 3,
      "z": 12,
      "name": "Rock_Aqua_Brick_Stairs",
      "rotation": 3
    },
    {
      "x": -2,
      "y": 4,
      "z": 12,
      "name": "Rock_Aqua_Brick_Smooth_Half",
      "rotation": 7
    },
    {
      "x": -2,
      "y": 5,
      "z": 12,
      "name": "Rock_Aqua_Brick_Stairs",
      "rotation": 9
    },
    {
      "x": -2,
      "y": 6,
      "z": 12,
      "name": "Rock_Aqua_Brick_Stairs",
      "rotation": 3
    },
    {
      "x": -2,
      "y": 7,
      "z": 12,
      "name": "Rock_Aqua_Brick_Smooth_Half",
      "rotation": 7
    },
    {
      "x": -2,
      "y": 8,
      "z": 12,
      "name": "Rock_Aqua_Brick_Stairs",
      "rotation": 9
    },
    {
      "x": -2,
      "y": 9,
      "z": 12,
      "name": "Rock_Aqua_Brick_Wall",
      "rotation": 3
    },
    {
      "x": -1,
      "y": -8,
      "z": -12,
      "name": "Rock_Aqua"
    },
    {
      "x": -1,
      "y": -7,
      "z": -12,
      "name": "Rock_Aqua"
    },
    {
      "x": -1,
      "y": -6,
      "z": -12,
      "name": "Rock_Aqua"
    },
    {
      "x": -1,
      "y": -5,
      "z": -12,
      "name": "Rock_Aqua"
    },
    {
      "x": -1,
      "y": -4,
      "z": -12,
      "name": "Rock_Aqua"
    },
    {
      "x": -1,
      "y": -3,
      "z": -12,
      "name": "Rock_Aqua"
    },
    {
      "x": -1,
      "y": -2,
      "z": -12,
      "name": "Rock_Aqua"
    },
    {
      "x": -1,
      "y": -1,
      "z": -12,
      "name": "Rock_Aqua"
    },
    {
      "x": -1,
      "y": 0,
      "z": -12,
      "name": "Rock_Aqua"
    },
    {
      "x": -1,
      "y": 1,
      "z": -12,
      "name": "Rock_Aqua"
    },
    {
      "x": -1,
      "y": 2,
      "z": -12,
      "name": "Rock_Aqua"
    },
    {
      "x": -1,
      "y": 3,
      "z": -12,
      "name": "Rock_Aqua"
    },
    {
      "x": -1,
      "y": 4,
      "z": -12,
      "name": "Rock_Aqua"
    },
    {
      "x": -1,
      "y": 5,
      "z": -12,
      "name": "Rock_Aqua"
    },
    {
      "x": -1,
      "y": 6,
      "z": -12,
      "name": "Rock_Aqua"
    },
    {
      "x": -1,
      "y": 7,
      "z": -12,
      "name": "Rock_Aqua"
    },
    {
      "x": -1,
      "y": 8,
      "z": -12,
      "name": "Rock_Aqua"
    },
    {
      "x": -1,
      "y": -8,
      "z": -11,
      "name": "Rock_Aqua"
    },
    {
      "x": -1,
      "y": -7,
      "z": -11,
      "name": "Rock_Aqua"
    },
    {
      "x": -1,
      "y": -6,
      "z": -11,
      "name": "Rock_Aqua"
    },
    {
      "x": -1,
      "y": -5,
      "z": -11,
      "name": "Rock_Aqua"
    },
    {
      "x": -1,
      "y": -4,
      "z": -11,
      "name": "Rock_Aqua"
    },
    {
      "x": -1,
      "y": -3,
      "z": -11,
      "name": "Rock_Aqua"
    },
    {
      "x": -1,
      "y": -2,
      "z": -11,
      "name": "Rock_Aqua"
    },
    {
      "x": -1,
      "y": -1,
      "z": -11,
      "name": "Rock_Aqua"
    },
    {
      "x": -1,
      "y": 0,
      "z": -11,
      "name": "Rock_Aqua"
    },
    {
      "x": -1,
      "y": 1,
      "z": -11,
      "name": "Rock_Aqua"
    },
    {
      "x": -1,
      "y": 2,
      "z": -11,
      "name": "Rock_Aqua"
    },
    {
      "x": -1,
      "y": 3,
      "z": -11,
      "name": "Rock_Aqua"
    },
    {
      "x": -1,
      "y": 4,
      "z": -11,
      "name": "Rock_Aqua"
    },
    {
      "x": -1,
      "y": 5,
      "z": -11,
      "name": "Rock_Aqua"
    },
    {
      "x": -1,
      "y": 6,
      "z": -11,
      "name": "Rock_Aqua"
    },
    {
      "x": -1,
      "y": 7,
      "z": -11,
      "name": "Rock_Aqua"
    },
    {
      "x": -1,
      "y": 8,
      "z": -11,
      "name": "Rock_Aqua"
    },
    {
      "x": -1,
      "y": 2,
      "z": -10,
      "name": "Rock_Aqua_Half",
      "rotation": 4
    },
    {
      "x": -1,
      "y": 3,
      "z": -10,
      "name": "Rock_Aqua_Half",
      "rotation": 4
    },
    {
      "x": -1,
      "y": 4,
      "z": -10,
      "name": "Rock_Aqua"
    },
    {
      "x": -1,
      "y": 5,
      "z": -10,
      "name": "Rock_Aqua"
    },
    {
      "x": -1,
      "y": 6,
      "z": -10,
      "name": "Rock_Aqua"
    },
    {
      "x": -1,
      "y": 7,
      "z": -10,
      "name": "Rock_Aqua"
    },
    {
      "x": -1,
      "y": 8,
      "z": -10,
      "name": "Rock_Aqua"
    },
    {
      "x": -1,
      "y": 5,
      "z": -9,
      "name": "Rock_Aqua_Half",
      "rotation": 4
    },
    {
      "x": -1,
      "y": 6,
      "z": -9,
      "name": "Rock_Aqua"
    },
    {
      "x": -1,
      "y": 7,
      "z": -9,
      "name": "Rock_Aqua"
    },
    {
      "x": -1,
      "y": 8,
      "z": -9,
      "name": "Rock_Aqua"
    },
    {
      "x": -1,
      "y": 7,
      "z": -8,
      "name": "Rock_Aqua"
    },
    {
      "x": -1,
      "y": 8,
      "z": -8,
      "name": "*Rock_Aqua_Stairs_State_Definitions_Inverted_Corner_Left"
    },
    {
      "x": -1,
      "y": 7,
      "z": -7,
      "name": "Rock_Aqua_Half",
      "rotation": 8
    },
    {
      "x": -1,
      "y": 8,
      "z": -7,
      "name": "Rock_Aqua_Stairs",
      "rotation": 1
    },
    {
      "x": -1,
      "y": 7,
      "z": -6,
      "name": "Rock_Aqua_Half",
      "rotation": 8
    },
    {
      "x": -1,
      "y": 8,
      "z": -6,
      "name": "Rock_Aqua"
    },
    {
      "x": -1,
      "y": 9,
      "z": -6,
      "name": "Plant_Moss_Rug_Blue",
      "support": 15
    },
    {
      "x": -1,
      "y": 7,
      "z": -5,
      "name": "Rock_Aqua_Half",
      "rotation": 8
    },
    {
      "x": -1,
      "y": 8,
      "z": -5,
      "name": "Rock_Aqua_Stairs",
      "rotation": 3
    },
    {
      "x": -1,
      "y": 7,
      "z": -4,
      "name": "Rock_Aqua"
    },
    {
      "x": -1,
      "y": 8,
      "z": -4,
      "name": "Rock_Aqua"
    },
    {
      "x": -1,
      "y": 9,
      "z": -4,
      "name": "Plant_Moss_Short_Blue",
      "support": 15
    },
    {
      "x": -1,
      "y": 5,
      "z": -3,
      "name": "Rock_Aqua_Half",
      "rotation": 6
    },
    {
      "x": -1,
      "y": 6,
      "z": -3,
      "name": "Rock_Aqua"
    },
    {
      "x": -1,
      "y": 7,
      "z": -3,
      "name": "Rock_Aqua"
    },
    {
      "x": -1,
      "y": 8,
      "z": -3,
      "name": "Rock_Aqua"
    },
    {
      "x": -1,
      "y": 9,
      "z": -3,
      "name": "Rubble_Aqua",
      "support": 15
    },
    {
      "x": -1,
      "y": 2,
      "z": -2,
      "name": "Rock_Aqua_Half",
      "rotation": 6
    },
    {
      "x": -1,
      "y": 3,
      "z": -2,
      "name": "Rock_Aqua_Half",
      "rotation": 6
    },
    {
      "x": -1,
      "y": 4,
      "z": -2,
      "name": "Rock_Aqua"
    },
    {
      "x": -1,
      "y": 5,
      "z": -2,
      "name": "Rock_Aqua"
    },
    {
      "x": -1,
      "y": 6,
      "z": -2,
      "name": "Rock_Aqua"
    },
    {
      "x": -1,
      "y": 7,
      "z": -2,
      "name": "Rock_Aqua"
    },
    {
      "x": -1,
      "y": 8,
      "z": -2,
      "name": "Rock_Aqua"
    },
    {
      "x": -1,
      "y": -8,
      "z": -1,
      "name": "Rock_Aqua"
    },
    {
      "x": -1,
      "y": -7,
      "z": -1,
      "name": "Rock_Aqua"
    },
    {
      "x": -1,
      "y": -6,
      "z": -1,
      "name": "Rock_Aqua"
    },
    {
      "x": -1,
      "y": -5,
      "z": -1,
      "name": "Rock_Aqua"
    },
    {
      "x": -1,
      "y": -4,
      "z": -1,
      "name": "Rock_Aqua"
    },
    {
      "x": -1,
      "y": -3,
      "z": -1,
      "name": "Rock_Aqua"
    },
    {
      "x": -1,
      "y": -2,
      "z": -1,
      "name": "Rock_Aqua"
    },
    {
      "x": -1,
      "y": -1,
      "z": -1,
      "name": "Rock_Aqua"
    },
    {
      "x": -1,
      "y": 0,
      "z": -1,
      "name": "Rock_Aqua"
    },
    {
      "x": -1,
      "y": 1,
      "z": -1,
      "name": "Rock_Aqua"
    },
    {
      "x": -1,
      "y": 2,
      "z": -1,
      "name": "Rock_Aqua"
    },
    {
      "x": -1,
      "y": 3,
      "z": -1,
      "name": "Rock_Aqua"
    },
    {
      "x": -1,
      "y": 4,
      "z": -1,
      "name": "Rock_Aqua"
    },
    {
      "x": -1,
      "y": 5,
      "z": -1,
      "name": "Rock_Aqua"
    },
    {
      "x": -1,
      "y": 6,
      "z": -1,
      "name": "Rock_Aqua"
    },
    {
      "x": -1,
      "y": 7,
      "z": -1,
      "name": "Rock_Aqua"
    },
    {
      "x": -1,
      "y": 8,
      "z": -1,
      "name": "Rock_Aqua"
    },
    {
      "x": -1,
      "y": -8,
      "z": 0,
      "name": "Rock_Aqua"
    },
    {
      "x": -1,
      "y": -7,
      "z": 0,
      "name": "Rock_Aqua"
    },
    {
      "x": -1,
      "y": -6,
      "z": 0,
      "name": "Rock_Aqua"
    },
    {
      "x": -1,
      "y": -5,
      "z": 0,
      "name": "Rock_Aqua"
    },
    {
      "x": -1,
      "y": -4,
      "z": 0,
      "name": "Rock_Aqua"
    },
    {
      "x": -1,
      "y": -3,
      "z": 0,
      "name": "Rock_Aqua"
    },
    {
      "x": -1,
      "y": -2,
      "z": 0,
      "name": "Rock_Aqua"
    },
    {
      "x": -1,
      "y": -1,
      "z": 0,
      "name": "Rock_Aqua"
    },
    {
      "x": -1,
      "y": 0,
      "z": 0,
      "name": "Rock_Aqua"
    },
    {
      "x": -1,
      "y": 1,
      "z": 0,
      "name": "Rock_Aqua"
    },
    {
      "x": -1,
      "y": 2,
      "z": 0,
      "name": "Rock_Aqua"
    },
    {
      "x": -1,
      "y": 3,
      "z": 0,
      "name": "Rock_Aqua"
    },
    {
      "x": -1,
      "y": 4,
      "z": 0,
      "name": "Rock_Aqua"
    },
    {
      "x": -1,
      "y": 5,
      "z": 0,
      "name": "Rock_Aqua"
    },
    {
      "x": -1,
      "y": 6,
      "z": 0,
      "name": "Rock_Aqua"
    },
    {
      "x": -1,
      "y": 7,
      "z": 0,
      "name": "Rock_Aqua"
    },
    {
      "x": -1,
      "y": 8,
      "z": 0,
      "name": "Rock_Aqua"
    },
    {
      "x": -1,
      "y": -8,
      "z": 1,
      "name": "Rock_Aqua"
    },
    {
      "x": -1,
      "y": -7,
      "z": 1,
      "name": "Rock_Aqua"
    },
    {
      "x": -1,
      "y": -6,
      "z": 1,
      "name": "Rock_Aqua"
    },
    {
      "x": -1,
      "y": -5,
      "z": 1,
      "name": "Rock_Aqua"
    },
    {
      "x": -1,
      "y": -4,
      "z": 1,
      "name": "Rock_Aqua"
    },
    {
      "x": -1,
      "y": -3,
      "z": 1,
      "name": "Rock_Aqua"
    },
    {
      "x": -1,
      "y": -2,
      "z": 1,
      "name": "Rock_Aqua"
    },
    {
      "x": -1,
      "y": -1,
      "z": 1,
      "name": "Rock_Aqua"
    },
    {
      "x": -1,
      "y": 0,
      "z": 1,
      "name": "Rock_Aqua"
    },
    {
      "x": -1,
      "y": 1,
      "z": 1,
      "name": "Rock_Aqua"
    },
    {
      "x": -1,
      "y": 2,
      "z": 1,
      "name": "Rock_Aqua"
    },
    {
      "x": -1,
      "y": 3,
      "z": 1,
      "name": "Rock_Aqua"
    },
    {
      "x": -1,
      "y": 4,
      "z": 1,
      "name": "Rock_Aqua"
    },
    {
      "x": -1,
      "y": 5,
      "z": 1,
      "name": "Rock_Aqua"
    },
    {
      "x": -1,
      "y": 6,
      "z": 1,
      "name": "Rock_Aqua"
    },
    {
      "x": -1,
      "y": 7,
      "z": 1,
      "name": "Rock_Aqua"
    },
    {
      "x": -1,
      "y": 8,
      "z": 1,
      "name": "Rock_Aqua"
    },
    {
      "x": -1,
      "y": 2,
      "z": 2,
      "name": "Rock_Aqua_Half",
      "rotation": 4
    },
    {
      "x": -1,
      "y": 3,
      "z": 2,
      "name": "Rock_Aqua_Half",
      "rotation": 4
    },
    {
      "x": -1,
      "y": 4,
      "z": 2,
      "name": "Rock_Aqua"
    },
    {
      "x": -1,
      "y": 5,
      "z": 2,
      "name": "Rock_Aqua"
    },
    {
      "x": -1,
      "y": 6,
      "z": 2,
      "name": "Rock_Aqua"
    },
    {
      "x": -1,
      "y": 7,
      "z": 2,
      "name": "Rock_Aqua"
    },
    {
      "x": -1,
      "y": 8,
      "z": 2,
      "name": "Rock_Aqua_Stairs",
      "rotation": 3
    },
    {
      "x": -1,
      "y": 5,
      "z": 3,
      "name": "Rock_Aqua_Half",
      "rotation": 4
    },
    {
      "x": -1,
      "y": 6,
      "z": 3,
      "name": "Rock_Aqua"
    },
    {
      "x": -1,
      "y": 7,
      "z": 3,
      "name": "Rock_Aqua"
    },
    {
      "x": -1,
      "y": 8,
      "z": 3,
      "name": "Rock_Aqua_Stairs",
      "rotation": 3
    },
    {
      "x": -1,
      "y": 7,
      "z": 4,
      "name": "Rock_Aqua"
    },
    {
      "x": -1,
      "y": 8,
      "z": 4,
      "name": "Rock_Aqua"
    },
    {
      "x": -1,
      "y": 7,
      "z": 5,
      "name": "Rock_Aqua_Half",
      "rotation": 8
    },
    {
      "x": -1,
      "y": 8,
      "z": 5,
      "name": "Rock_Aqua"
    },
    {
      "x": -1,
      "y": 7,
      "z": 6,
      "name": "Rock_Aqua_Half",
      "rotation": 8
    },
    {
      "x": -1,
      "y": 8,
      "z": 6,
      "name": "Rock_Aqua"
    },
    {
      "x": -1,
      "y": 9,
      "z": 6,
      "name": "Rubble_Aqua",
      "support": 15
    },
    {
      "x": -1,
      "y": 7,
      "z": 7,
      "name": "Rock_Aqua_Half",
      "rotation": 8
    },
    {
      "x": -1,
      "y": 8,
      "z": 7,
      "name": "Rock_Aqua"
    },
    {
      "x": -1,
      "y": 7,
      "z": 8,
      "name": "Rock_Aqua"
    },
    {
      "x": -1,
      "y": 8,
      "z": 8,
      "name": "Rock_Aqua"
    },
    {
      "x": -1,
      "y": 5,
      "z": 9,
      "name": "Rock_Aqua_Half",
      "rotation": 6
    },
    {
      "x": -1,
      "y": 6,
      "z": 9,
      "name": "Rock_Aqua"
    },
    {
      "x": -1,
      "y": 7,
      "z": 9,
      "name": "Rock_Aqua"
    },
    {
      "x": -1,
      "y": 8,
      "z": 9,
      "name": "Rock_Aqua"
    },
    {
      "x": -1,
      "y": 2,
      "z": 10,
      "name": "Rock_Aqua_Half",
      "rotation": 6
    },
    {
      "x": -1,
      "y": 3,
      "z": 10,
      "name": "Rock_Aqua_Half",
      "rotation": 6
    },
    {
      "x": -1,
      "y": 4,
      "z": 10,
      "name": "Rock_Aqua"
    },
    {
      "x": -1,
      "y": 5,
      "z": 10,
      "name": "Rock_Aqua"
    },
    {
      "x": -1,
      "y": 6,
      "z": 10,
      "name": "Rock_Aqua"
    },
    {
      "x": -1,
      "y": 7,
      "z": 10,
      "name": "Rock_Aqua"
    },
    {
      "x": -1,
      "y": 8,
      "z": 10,
      "name": "Rock_Aqua"
    },
    {
      "x": -1,
      "y": -8,
      "z": 11,
      "name": "Rock_Aqua"
    },
    {
      "x": -1,
      "y": -7,
      "z": 11,
      "name": "Rock_Aqua"
    },
    {
      "x": -1,
      "y": -6,
      "z": 11,
      "name": "Rock_Aqua"
    },
    {
      "x": -1,
      "y": -5,
      "z": 11,
      "name": "Rock_Aqua"
    },
    {
      "x": -1,
      "y": -4,
      "z": 11,
      "name": "Rock_Aqua"
    },
    {
      "x": -1,
      "y": -3,
      "z": 11,
      "name": "Rock_Aqua"
    },
    {
      "x": -1,
      "y": -2,
      "z": 11,
      "name": "Rock_Aqua"
    },
    {
      "x": -1,
      "y": -1,
      "z": 11,
      "name": "Rock_Aqua"
    },
    {
      "x": -1,
      "y": 0,
      "z": 11,
      "name": "Rock_Aqua"
    },
    {
      "x": -1,
      "y": 1,
      "z": 11,
      "name": "Rock_Aqua"
    },
    {
      "x": -1,
      "y": 2,
      "z": 11,
      "name": "Rock_Aqua"
    },
    {
      "x": -1,
      "y": 3,
      "z": 11,
      "name": "Rock_Aqua"
    },
    {
      "x": -1,
      "y": 4,
      "z": 11,
      "name": "Rock_Aqua"
    },
    {
      "x": -1,
      "y": 5,
      "z": 11,
      "name": "Rock_Aqua"
    },
    {
      "x": -1,
      "y": 6,
      "z": 11,
      "name": "Rock_Aqua"
    },
    {
      "x": -1,
      "y": 7,
      "z": 11,
      "name": "Rock_Aqua"
    },
    {
      "x": -1,
      "y": 8,
      "z": 11,
      "name": "Rock_Aqua"
    },
    {
      "x": -1,
      "y": -8,
      "z": 12,
      "name": "Rock_Aqua"
    },
    {
      "x": -1,
      "y": -7,
      "z": 12,
      "name": "Rock_Aqua"
    },
    {
      "x": -1,
      "y": -6,
      "z": 12,
      "name": "Rock_Aqua"
    },
    {
      "x": -1,
      "y": -5,
      "z": 12,
      "name": "Rock_Aqua"
    },
    {
      "x": -1,
      "y": -4,
      "z": 12,
      "name": "Rock_Aqua"
    },
    {
      "x": -1,
      "y": -3,
      "z": 12,
      "name": "Rock_Aqua"
    },
    {
      "x": -1,
      "y": -2,
      "z": 12,
      "name": "Rock_Aqua"
    },
    {
      "x": -1,
      "y": -1,
      "z": 12,
      "name": "Rock_Aqua"
    },
    {
      "x": -1,
      "y": 0,
      "z": 12,
      "name": "Rock_Aqua"
    },
    {
      "x": -1,
      "y": 1,
      "z": 12,
      "name": "Rock_Aqua"
    },
    {
      "x": -1,
      "y": 2,
      "z": 12,
      "name": "Rock_Aqua"
    },
    {
      "x": -1,
      "y": 3,
      "z": 12,
      "name": "Rock_Aqua"
    },
    {
      "x": -1,
      "y": 4,
      "z": 12,
      "name": "Rock_Aqua"
    },
    {
      "x": -1,
      "y": 5,
      "z": 12,
      "name": "Rock_Aqua"
    },
    {
      "x": -1,
      "y": 6,
      "z": 12,
      "name": "Rock_Aqua"
    },
    {
      "x": -1,
      "y": 7,
      "z": 12,
      "name": "Rock_Aqua"
    },
    {
      "x": -1,
      "y": 8,
      "z": 12,
      "name": "Rock_Aqua"
    },
    {
      "x": 0,
      "y": -8,
      "z": -12,
      "name": "Rock_Aqua"
    },
    {
      "x": 0,
      "y": -7,
      "z": -12,
      "name": "Rock_Aqua"
    },
    {
      "x": 0,
      "y": -6,
      "z": -12,
      "name": "Rock_Aqua"
    },
    {
      "x": 0,
      "y": -5,
      "z": -12,
      "name": "Rock_Aqua"
    },
    {
      "x": 0,
      "y": -4,
      "z": -12,
      "name": "Rock_Aqua"
    },
    {
      "x": 0,
      "y": -3,
      "z": -12,
      "name": "Rock_Aqua"
    },
    {
      "x": 0,
      "y": -2,
      "z": -12,
      "name": "Rock_Aqua"
    },
    {
      "x": 0,
      "y": -1,
      "z": -12,
      "name": "Rock_Aqua"
    },
    {
      "x": 0,
      "y": 0,
      "z": -12,
      "name": "Rock_Aqua"
    },
    {
      "x": 0,
      "y": 1,
      "z": -12,
      "name": "Rock_Aqua"
    },
    {
      "x": 0,
      "y": 2,
      "z": -12,
      "name": "Rock_Aqua"
    },
    {
      "x": 0,
      "y": 3,
      "z": -12,
      "name": "Rock_Aqua"
    },
    {
      "x": 0,
      "y": 4,
      "z": -12,
      "name": "Rock_Aqua"
    },
    {
      "x": 0,
      "y": 5,
      "z": -12,
      "name": "Rock_Aqua"
    },
    {
      "x": 0,
      "y": 6,
      "z": -12,
      "name": "Rock_Aqua"
    },
    {
      "x": 0,
      "y": 7,
      "z": -12,
      "name": "Rock_Aqua"
    },
    {
      "x": 0,
      "y": 8,
      "z": -12,
      "name": "Rock_Aqua_Brick_Smooth"
    },
    {
      "x": 0,
      "y": -8,
      "z": -11,
      "name": "Rock_Aqua"
    },
    {
      "x": 0,
      "y": -7,
      "z": -11,
      "name": "Rock_Aqua"
    },
    {
      "x": 0,
      "y": -6,
      "z": -11,
      "name": "Rock_Aqua"
    },
    {
      "x": 0,
      "y": -5,
      "z": -11,
      "name": "Rock_Aqua"
    },
    {
      "x": 0,
      "y": -4,
      "z": -11,
      "name": "Rock_Aqua"
    },
    {
      "x": 0,
      "y": -3,
      "z": -11,
      "name": "Rock_Aqua"
    },
    {
      "x": 0,
      "y": -2,
      "z": -11,
      "name": "Rock_Aqua"
    },
    {
      "x": 0,
      "y": -1,
      "z": -11,
      "name": "Rock_Aqua"
    },
    {
      "x": 0,
      "y": 0,
      "z": -11,
      "name": "Rock_Aqua"
    },
    {
      "x": 0,
      "y": 1,
      "z": -11,
      "name": "Rock_Aqua"
    },
    {
      "x": 0,
      "y": 2,
      "z": -11,
      "name": "Rock_Aqua"
    },
    {
      "x": 0,
      "y": 3,
      "z": -11,
      "name": "Rock_Aqua"
    },
    {
      "x": 0,
      "y": 4,
      "z": -11,
      "name": "Rock_Aqua"
    },
    {
      "x": 0,
      "y": 5,
      "z": -11,
      "name": "Rock_Aqua"
    },
    {
      "x": 0,
      "y": 6,
      "z": -11,
      "name": "Rock_Aqua"
    },
    {
      "x": 0,
      "y": 7,
      "z": -11,
      "name": "Rock_Aqua"
    },
    {
      "x": 0,
      "y": 8,
      "z": -11,
      "name": "Rock_Aqua_Brick_Ornate"
    },
    {
      "x": 0,
      "y": 2,
      "z": -10,
      "name": "Rock_Aqua_Half",
      "rotation": 4
    },
    {
      "x": 0,
      "y": 3,
      "z": -10,
      "name": "Rock_Aqua_Half",
      "rotation": 4
    },
    {
      "x": 0,
      "y": 4,
      "z": -10,
      "name": "Rock_Aqua"
    },
    {
      "x": 0,
      "y": 5,
      "z": -10,
      "name": "Rock_Aqua"
    },
    {
      "x": 0,
      "y": 6,
      "z": -10,
      "name": "Rock_Aqua"
    },
    {
      "x": 0,
      "y": 7,
      "z": -10,
      "name": "Rock_Aqua"
    },
    {
      "x": 0,
      "y": 8,
      "z": -10,
      "name": "Rock_Aqua_Brick_Smooth"
    },
    {
      "x": 0,
      "y": 9,
      "z": -10,
      "name": "Rubble_Aqua_Medium",
      "support": 15
    },
    {
      "x": 0,
      "y": 5,
      "z": -9,
      "name": "Rock_Aqua_Half",
      "rotation": 4
    },
    {
      "x": 0,
      "y": 6,
      "z": -9,
      "name": "Rock_Aqua"
    },
    {
      "x": 0,
      "y": 7,
      "z": -9,
      "name": "Rock_Aqua"
    },
    {
      "x": 0,
      "y": 8,
      "z": -9,
      "name": "Rock_Aqua_Brick_Smooth"
    },
    {
      "x": 0,
      "y": 7,
      "z": -8,
      "name": "Rock_Aqua"
    },
    {
      "x": 0,
      "y": 8,
      "z": -8,
      "name": "Rock_Aqua_Brick_Ornate"
    },
    {
      "x": 0,
      "y": 7,
      "z": -7,
      "name": "Rock_Aqua_Half",
      "rotation": 8
    },
    {
      "x": 0,
      "y": 8,
      "z": -7,
      "name": "Rock_Aqua_Brick_Smooth"
    },
    {
      "x": 0,
      "y": 9,
      "z": -7,
      "name": "Plant_Moss_Blue",
      "support": 15
    },
    {
      "x": 0,
      "y": 7,
      "z": -6,
      "name": "Rock_Aqua_Half",
      "rotation": 8
    },
    {
      "x": 0,
      "y": 8,
      "z": -6,
      "name": "Rock_Aqua_Brick_Smooth"
    },
    {
      "x": 0,
      "y": 9,
      "z": -6,
      "name": "Plant_Moss_Short_Blue",
      "support": 15
    },
    {
      "x": 0,
      "y": 7,
      "z": -5,
      "name": "Rock_Aqua_Half",
      "rotation": 8
    },
    {
      "x": 0,
      "y": 8,
      "z": -5,
      "name": "Rock_Aqua_Brick_Ornate"
    },
    {
      "x": 0,
      "y": 7,
      "z": -4,
      "name": "Rock_Aqua"
    },
    {
      "x": 0,
      "y": 8,
      "z": -4,
      "name": "Rock_Aqua_Brick_Smooth"
    },
    {
      "x": 0,
      "y": 9,
      "z": -4,
      "name": "Plant_Moss_Rug_Blue",
      "support": 15
    },
    {
      "x": 0,
      "y": 5,
      "z": -3,
      "name": "Rock_Aqua_Half",
      "rotation": 6
    },
    {
      "x": 0,
      "y": 6,
      "z": -3,
      "name": "Rock_Aqua"
    },
    {
      "x": 0,
      "y": 7,
      "z": -3,
      "name": "Rock_Aqua"
    },
    {
      "x": 0,
      "y": 8,
      "z": -3,
      "name": "Rock_Aqua_Brick_Smooth"
    },
    {
      "x": 0,
      "y": 2,
      "z": -2,
      "name": "Rock_Aqua_Half",
      "rotation": 6
    },
    {
      "x": 0,
      "y": 3,
      "z": -2,
      "name": "Rock_Aqua_Half",
      "rotation": 6
    },
    {
      "x": 0,
      "y": 4,
      "z": -2,
      "name": "Rock_Aqua"
    },
    {
      "x": 0,
      "y": 5,
      "z": -2,
      "name": "Rock_Aqua"
    },
    {
      "x": 0,
      "y": 6,
      "z": -2,
      "name": "Rock_Aqua"
    },
    {
      "x": 0,
      "y": 7,
      "z": -2,
      "name": "Rock_Aqua"
    },
    {
      "x": 0,
      "y": 8,
      "z": -2,
      "name": "Rock_Aqua_Brick_Ornate"
    },
    {
      "x": 0,
      "y": -8,
      "z": -1,
      "name": "Rock_Aqua"
    },
    {
      "x": 0,
      "y": -7,
      "z": -1,
      "name": "Rock_Aqua"
    },
    {
      "x": 0,
      "y": -6,
      "z": -1,
      "name": "Rock_Aqua"
    },
    {
      "x": 0,
      "y": -5,
      "z": -1,
      "name": "Rock_Aqua"
    },
    {
      "x": 0,
      "y": -4,
      "z": -1,
      "name": "Rock_Aqua"
    },
    {
      "x": 0,
      "y": -3,
      "z": -1,
      "name": "Rock_Aqua"
    },
    {
      "x": 0,
      "y": -2,
      "z": -1,
      "name": "Rock_Aqua"
    },
    {
      "x": 0,
      "y": -1,
      "z": -1,
      "name": "Rock_Aqua"
    },
    {
      "x": 0,
      "y": 0,
      "z": -1,
      "name": "Rock_Aqua"
    },
    {
      "x": 0,
      "y": 1,
      "z": -1,
      "name": "Rock_Aqua"
    },
    {
      "x": 0,
      "y": 2,
      "z": -1,
      "name": "Rock_Aqua"
    },
    {
      "x": 0,
      "y": 3,
      "z": -1,
      "name": "Rock_Aqua"
    },
    {
      "x": 0,
      "y": 4,
      "z": -1,
      "name": "Rock_Aqua"
    },
    {
      "x": 0,
      "y": 5,
      "z": -1,
      "name": "Rock_Aqua"
    },
    {
      "x": 0,
      "y": 6,
      "z": -1,
      "name": "Rock_Aqua"
    },
    {
      "x": 0,
      "y": 7,
      "z": -1,
      "name": "Rock_Aqua"
    },
    {
      "x": 0,
      "y": 8,
      "z": -1,
      "name": "Rock_Aqua_Brick_Smooth"
    },
    {
      "x": 0,
      "y": -8,
      "z": 0,
      "name": "Rock_Aqua"
    },
    {
      "x": 0,
      "y": -7,
      "z": 0,
      "name": "Rock_Aqua"
    },
    {
      "x": 0,
      "y": -6,
      "z": 0,
      "name": "Rock_Aqua"
    },
    {
      "x": 0,
      "y": -5,
      "z": 0,
      "name": "Rock_Aqua"
    },
    {
      "x": 0,
      "y": -4,
      "z": 0,
      "name": "Rock_Aqua"
    },
    {
      "x": 0,
      "y": -3,
      "z": 0,
      "name": "Rock_Aqua"
    },
    {
      "x": 0,
      "y": -2,
      "z": 0,
      "name": "Rock_Aqua"
    },
    {
      "x": 0,
      "y": -1,
      "z": 0,
      "name": "Rock_Aqua"
    },
    {
      "x": 0,
      "y": 0,
      "z": 0,
      "name": "Rock_Aqua"
    },
    {
      "x": 0,
      "y": 1,
      "z": 0,
      "name": "Rock_Aqua"
    },
    {
      "x": 0,
      "y": 2,
      "z": 0,
      "name": "Rock_Aqua"
    },
    {
      "x": 0,
      "y": 3,
      "z": 0,
      "name": "Rock_Aqua"
    },
    {
      "x": 0,
      "y": 4,
      "z": 0,
      "name": "Rock_Aqua"
    },
    {
      "x": 0,
      "y": 5,
      "z": 0,
      "name": "Rock_Aqua"
    },
    {
      "x": 0,
      "y": 6,
      "z": 0,
      "name": "Rock_Aqua"
    },
    {
      "x": 0,
      "y": 7,
      "z": 0,
      "name": "Rock_Aqua"
    },
    {
      "x": 0,
      "y": 8,
      "z": 0,
      "name": "Rock_Aqua_Brick_Smooth"
    },
    {
      "x": 0,
      "y": -8,
      "z": 1,
      "name": "Rock_Aqua"
    },
    {
      "x": 0,
      "y": -7,
      "z": 1,
      "name": "Rock_Aqua"
    },
    {
      "x": 0,
      "y": -6,
      "z": 1,
      "name": "Rock_Aqua"
    },
    {
      "x": 0,
      "y": -5,
      "z": 1,
      "name": "Rock_Aqua"
    },
    {
      "x": 0,
      "y": -4,
      "z": 1,
      "name": "Rock_Aqua"
    },
    {
      "x": 0,
      "y": -3,
      "z": 1,
      "name": "Rock_Aqua"
    },
    {
      "x": 0,
      "y": -2,
      "z": 1,
      "name": "Rock_Aqua"
    },
    {
      "x": 0,
      "y": -1,
      "z": 1,
      "name": "Rock_Aqua"
    },
    {
      "x": 0,
      "y": 0,
      "z": 1,
      "name": "Rock_Aqua"
    },
    {
      "x": 0,
      "y": 1,
      "z": 1,
      "name": "Rock_Aqua"
    },
    {
      "x": 0,
      "y": 2,
      "z": 1,
      "name": "Rock_Aqua"
    },
    {
      "x": 0,
      "y": 3,
      "z": 1,
      "name": "Rock_Aqua"
    },
    {
      "x": 0,
      "y": 4,
      "z": 1,
      "name": "Rock_Aqua"
    },
    {
      "x": 0,
      "y": 5,
      "z": 1,
      "name": "Rock_Aqua"
    },
    {
      "x": 0,
      "y": 6,
      "z": 1,
      "name": "Rock_Aqua"
    },
    {
      "x": 0,
      "y": 7,
      "z": 1,
      "name": "Rock_Aqua"
    },
    {
      "x": 0,
      "y": 8,
      "z": 1,
      "name": "Rock_Aqua_Brick_Ornate"
    },
    {
      "x": 0,
      "y": 2,
      "z": 2,
      "name": "Rock_Aqua_Half",
      "rotation": 4
    },
    {
      "x": 0,
      "y": 3,
      "z": 2,
      "name": "Rock_Aqua_Half",
      "rotation": 4
    },
    {
      "x": 0,
      "y": 4,
      "z": 2,
      "name": "Rock_Aqua"
    },
    {
      "x": 0,
      "y": 5,
      "z": 2,
      "name": "Rock_Aqua"
    },
    {
      "x": 0,
      "y": 6,
      "z": 2,
      "name": "Rock_Aqua"
    },
    {
      "x": 0,
      "y": 7,
      "z": 2,
      "name": "Rock_Aqua"
    },
    {
      "x": 0,
      "y": 8,
      "z": 2,
      "name": "Rock_Aqua_Brick_Smooth"
    },
    {
      "x": 0,
      "y": 5,
      "z": 3,
      "name": "Rock_Aqua_Half",
      "rotation": 4
    },
    {
      "x": 0,
      "y": 6,
      "z": 3,
      "name": "Rock_Aqua"
    },
    {
      "x": 0,
      "y": 7,
      "z": 3,
      "name": "Rock_Aqua"
    },
    {
      "x": 0,
      "y": 8,
      "z": 3,
      "name": "Rock_Aqua_Brick_Smooth"
    },
    {
      "x": 0,
      "y": 7,
      "z": 4,
      "name": "Rock_Aqua"
    },
    {
      "x": 0,
      "y": 8,
      "z": 4,
      "name": "Rock_Aqua_Brick_Ornate"
    },
    {
      "x": 0,
      "y": 7,
      "z": 5,
      "name": "Rock_Aqua_Half",
      "rotation": 8
    },
    {
      "x": 0,
      "y": 8,
      "z": 5,
      "name": "Rock_Aqua_Brick_Smooth"
    },
    {
      "x": 0,
      "y": 7,
      "z": 6,
      "name": "Rock_Aqua_Half",
      "rotation": 8
    },
    {
      "x": 0,
      "y": 8,
      "z": 6,
      "name": "Rock_Aqua_Brick_Smooth"
    },
    {
      "x": 0,
      "y": 7,
      "z": 7,
      "name": "Rock_Aqua_Half",
      "rotation": 8
    },
    {
      "x": 0,
      "y": 8,
      "z": 7,
      "name": "Rock_Aqua_Brick_Ornate"
    },
    {
      "x": 0,
      "y": 7,
      "z": 8,
      "name": "Rock_Aqua"
    },
    {
      "x": 0,
      "y": 8,
      "z": 8,
      "name": "Rock_Aqua_Brick_Smooth"
    },
    {
      "x": 0,
      "y": 5,
      "z": 9,
      "name": "Rock_Aqua_Half",
      "rotation": 6
    },
    {
      "x": 0,
      "y": 6,
      "z": 9,
      "name": "Rock_Aqua"
    },
    {
      "x": 0,
      "y": 7,
      "z": 9,
      "name": "Rock_Aqua"
    },
    {
      "x": 0,
      "y": 8,
      "z": 9,
      "name": "Rock_Aqua_Brick_Smooth"
    },
    {
      "x": 0,
      "y": 9,
      "z": 9,
      "name": "Rubble_Aqua",
      "support": 15
    },
    {
      "x": 0,
      "y": 2,
      "z": 10,
      "name": "Rock_Aqua_Half",
      "rotation": 6
    },
    {
      "x": 0,
      "y": 3,
      "z": 10,
      "name": "Rock_Aqua_Half",
      "rotation": 6
    },
    {
      "x": 0,
      "y": 4,
      "z": 10,
      "name": "Rock_Aqua"
    },
    {
      "x": 0,
      "y": 5,
      "z": 10,
      "name": "Rock_Aqua"
    },
    {
      "x": 0,
      "y": 6,
      "z": 10,
      "name": "Rock_Aqua"
    },
    {
      "x": 0,
      "y": 7,
      "z": 10,
      "name": "Rock_Aqua"
    },
    {
      "x": 0,
      "y": 8,
      "z": 10,
      "name": "Rock_Aqua_Brick_Ornate"
    },
    {
      "x": 0,
      "y": -8,
      "z": 11,
      "name": "Rock_Aqua"
    },
    {
      "x": 0,
      "y": -7,
      "z": 11,
      "name": "Rock_Aqua"
    },
    {
      "x": 0,
      "y": -6,
      "z": 11,
      "name": "Rock_Aqua"
    },
    {
      "x": 0,
      "y": -5,
      "z": 11,
      "name": "Rock_Aqua"
    },
    {
      "x": 0,
      "y": -4,
      "z": 11,
      "name": "Rock_Aqua"
    },
    {
      "x": 0,
      "y": -3,
      "z": 11,
      "name": "Rock_Aqua"
    },
    {
      "x": 0,
      "y": -2,
      "z": 11,
      "name": "Rock_Aqua"
    },
    {
      "x": 0,
      "y": -1,
      "z": 11,
      "name": "Rock_Aqua"
    },
    {
      "x": 0,
      "y": 0,
      "z": 11,
      "name": "Rock_Aqua"
    },
    {
      "x": 0,
      "y": 1,
      "z": 11,
      "name": "Rock_Aqua"
    },
    {
      "x": 0,
      "y": 2,
      "z": 11,
      "name": "Rock_Aqua"
    },
    {
      "x": 0,
      "y": 3,
      "z": 11,
      "name": "Rock_Aqua"
    },
    {
      "x": 0,
      "y": 4,
      "z": 11,
      "name": "Rock_Aqua"
    },
    {
      "x": 0,
      "y": 5,
      "z": 11,
      "name": "Rock_Aqua"
    },
    {
      "x": 0,
      "y": 6,
      "z": 11,
      "name": "Rock_Aqua"
    },
    {
      "x": 0,
      "y": 7,
      "z": 11,
      "name": "Rock_Aqua"
    },
    {
      "x": 0,
      "y": 8,
      "z": 11,
      "name": "Rock_Aqua_Brick_Smooth"
    },
    {
      "x": 0,
      "y": -8,
      "z": 12,
      "name": "Rock_Aqua"
    },
    {
      "x": 0,
      "y": -7,
      "z": 12,
      "name": "Rock_Aqua"
    },
    {
      "x": 0,
      "y": -6,
      "z": 12,
      "name": "Rock_Aqua"
    },
    {
      "x": 0,
      "y": -5,
      "z": 12,
      "name": "Rock_Aqua"
    },
    {
      "x": 0,
      "y": -4,
      "z": 12,
      "name": "Rock_Aqua"
    },
    {
      "x": 0,
      "y": -3,
      "z": 12,
      "name": "Rock_Aqua"
    },
    {
      "x": 0,
      "y": -2,
      "z": 12,
      "name": "Rock_Aqua"
    },
    {
      "x": 0,
      "y": -1,
      "z": 12,
      "name": "Rock_Aqua"
    },
    {
      "x": 0,
      "y": 0,
      "z": 12,
      "name": "Rock_Aqua"
    },
    {
      "x": 0,
      "y": 1,
      "z": 12,
      "name": "Rock_Aqua"
    },
    {
      "x": 0,
      "y": 2,
      "z": 12,
      "name": "Rock_Aqua"
    },
    {
      "x": 0,
      "y": 3,
      "z": 12,
      "name": "Rock_Aqua"
    },
    {
      "x": 0,
      "y": 4,
      "z": 12,
      "name": "Rock_Aqua"
    },
    {
      "x": 0,
      "y": 5,
      "z": 12,
      "name": "Rock_Aqua"
    },
    {
      "x": 0,
      "y": 6,
      "z": 12,
      "name": "Rock_Aqua"
    },
    {
      "x": 0,
      "y": 7,
      "z": 12,
      "name": "Rock_Aqua"
    },
    {
      "x": 0,
      "y": 8,
      "z": 12,
      "name": "Rock_Aqua_Brick_Smooth"
    },
    {
      "x": 1,
      "y": -8,
      "z": -12,
      "name": "Rock_Aqua"
    },
    {
      "x": 1,
      "y": -7,
      "z": -12,
      "name": "Rock_Aqua"
    },
    {
      "x": 1,
      "y": -6,
      "z": -12,
      "name": "Rock_Aqua"
    },
    {
      "x": 1,
      "y": -5,
      "z": -12,
      "name": "Rock_Aqua"
    },
    {
      "x": 1,
      "y": -4,
      "z": -12,
      "name": "Rock_Aqua"
    },
    {
      "x": 1,
      "y": -3,
      "z": -12,
      "name": "Rock_Aqua"
    },
    {
      "x": 1,
      "y": -2,
      "z": -12,
      "name": "Rock_Aqua"
    },
    {
      "x": 1,
      "y": -1,
      "z": -12,
      "name": "Rock_Aqua"
    },
    {
      "x": 1,
      "y": 0,
      "z": -12,
      "name": "Rock_Aqua"
    },
    {
      "x": 1,
      "y": 1,
      "z": -12,
      "name": "Rock_Aqua"
    },
    {
      "x": 1,
      "y": 2,
      "z": -12,
      "name": "Rock_Aqua"
    },
    {
      "x": 1,
      "y": 3,
      "z": -12,
      "name": "Rock_Aqua"
    },
    {
      "x": 1,
      "y": 4,
      "z": -12,
      "name": "Rock_Aqua"
    },
    {
      "x": 1,
      "y": 5,
      "z": -12,
      "name": "Rock_Aqua"
    },
    {
      "x": 1,
      "y": 6,
      "z": -12,
      "name": "Rock_Aqua"
    },
    {
      "x": 1,
      "y": 7,
      "z": -12,
      "name": "Rock_Aqua"
    },
    {
      "x": 1,
      "y": 8,
      "z": -12,
      "name": "Rock_Aqua"
    },
    {
      "x": 1,
      "y": -8,
      "z": -11,
      "name": "Rock_Aqua"
    },
    {
      "x": 1,
      "y": -7,
      "z": -11,
      "name": "Rock_Aqua"
    },
    {
      "x": 1,
      "y": -6,
      "z": -11,
      "name": "Rock_Aqua"
    },
    {
      "x": 1,
      "y": -5,
      "z": -11,
      "name": "Rock_Aqua"
    },
    {
      "x": 1,
      "y": -4,
      "z": -11,
      "name": "Rock_Aqua"
    },
    {
      "x": 1,
      "y": -3,
      "z": -11,
      "name": "Rock_Aqua"
    },
    {
      "x": 1,
      "y": -2,
      "z": -11,
      "name": "Rock_Aqua"
    },
    {
      "x": 1,
      "y": -1,
      "z": -11,
      "name": "Rock_Aqua"
    },
    {
      "x": 1,
      "y": 0,
      "z": -11,
      "name": "Rock_Aqua"
    },
    {
      "x": 1,
      "y": 1,
      "z": -11,
      "name": "Rock_Aqua"
    },
    {
      "x": 1,
      "y": 2,
      "z": -11,
      "name": "Rock_Aqua"
    },
    {
      "x": 1,
      "y": 3,
      "z": -11,
      "name": "Rock_Aqua"
    },
    {
      "x": 1,
      "y": 4,
      "z": -11,
      "name": "Rock_Aqua"
    },
    {
      "x": 1,
      "y": 5,
      "z": -11,
      "name": "Rock_Aqua"
    },
    {
      "x": 1,
      "y": 6,
      "z": -11,
      "name": "Rock_Aqua"
    },
    {
      "x": 1,
      "y": 7,
      "z": -11,
      "name": "Rock_Aqua"
    },
    {
      "x": 1,
      "y": 8,
      "z": -11,
      "name": "Rock_Aqua"
    },
    {
      "x": 1,
      "y": 2,
      "z": -10,
      "name": "Rock_Aqua_Half",
      "rotation": 4
    },
    {
      "x": 1,
      "y": 3,
      "z": -10,
      "name": "Rock_Aqua_Half",
      "rotation": 4
    },
    {
      "x": 1,
      "y": 4,
      "z": -10,
      "name": "Rock_Aqua"
    },
    {
      "x": 1,
      "y": 5,
      "z": -10,
      "name": "Rock_Aqua"
    },
    {
      "x": 1,
      "y": 6,
      "z": -10,
      "name": "Rock_Aqua"
    },
    {
      "x": 1,
      "y": 7,
      "z": -10,
      "name": "Rock_Aqua"
    },
    {
      "x": 1,
      "y": 8,
      "z": -10,
      "name": "Rock_Aqua"
    },
    {
      "x": 1,
      "y": 5,
      "z": -9,
      "name": "Rock_Aqua_Half",
      "rotation": 4
    },
    {
      "x": 1,
      "y": 6,
      "z": -9,
      "name": "Rock_Aqua"
    },
    {
      "x": 1,
      "y": 7,
      "z": -9,
      "name": "Rock_Aqua"
    },
    {
      "x": 1,
      "y": 8,
      "z": -9,
      "name": "Rock_Aqua"
    },
    {
      "x": 1,
      "y": 7,
      "z": -8,
      "name": "Rock_Aqua"
    },
    {
      "x": 1,
      "y": 8,
      "z": -8,
      "name": "Rock_Aqua"
    },
    {
      "x": 1,
      "y": 9,
      "z": -8,
      "name": "Plant_Moss_Short_Blue",
      "support": 15
    },
    {
      "x": 1,
      "y": 7,
      "z": -7,
      "name": "Rock_Aqua_Half",
      "rotation": 8
    },
    {
      "x": 1,
      "y": 8,
      "z": -7,
      "name": "Rock_Aqua"
    },
    {
      "x": 1,
      "y": 7,
      "z": -6,
      "name": "Rock_Aqua_Half",
      "rotation": 8
    },
    {
      "x": 1,
      "y": 8,
      "z": -6,
      "name": "Rock_Aqua"
    },
    {
      "x": 1,
      "y": 9,
      "z": -6,
      "name": "Rubble_Aqua",
      "support": 15
    },
    {
      "x": 1,
      "y": 7,
      "z": -5,
      "name": "Rock_Aqua_Half",
      "rotation": 8
    },
    {
      "x": 1,
      "y": 8,
      "z": -5,
      "name": "Rock_Aqua_Stairs",
      "rotation": 3
    },
    {
      "x": 1,
      "y": 7,
      "z": -4,
      "name": "Rock_Aqua"
    },
    {
      "x": 1,
      "y": 8,
      "z": -4,
      "name": "*Rock_Aqua_Stairs_State_Definitions_Corner_Right"
    },
    {
      "x": 1,
      "y": 5,
      "z": -3,
      "name": "Rock_Aqua_Half",
      "rotation": 6
    },
    {
      "x": 1,
      "y": 6,
      "z": -3,
      "name": "Rock_Aqua"
    },
    {
      "x": 1,
      "y": 7,
      "z": -3,
      "name": "Rock_Aqua"
    },
    {
      "x": 1,
      "y": 8,
      "z": -3,
      "name": "Rock_Aqua"
    },
    {
      "x": 1,
      "y": 2,
      "z": -2,
      "name": "Rock_Aqua_Half",
      "rotation": 6
    },
    {
      "x": 1,
      "y": 3,
      "z": -2,
      "name": "Rock_Aqua_Half",
      "rotation": 6
    },
    {
      "x": 1,
      "y": 4,
      "z": -2,
      "name": "Rock_Aqua"
    },
    {
      "x": 1,
      "y": 5,
      "z": -2,
      "name": "Rock_Aqua"
    },
    {
      "x": 1,
      "y": 6,
      "z": -2,
      "name": "Rock_Aqua"
    },
    {
      "x": 1,
      "y": 7,
      "z": -2,
      "name": "Rock_Aqua"
    },
    {
      "x": 1,
      "y": 8,
      "z": -2,
      "name": "Rock_Aqua"
    },
    {
      "x": 1,
      "y": -8,
      "z": -1,
      "name": "Rock_Aqua"
    },
    {
      "x": 1,
      "y": -7,
      "z": -1,
      "name": "Rock_Aqua"
    },
    {
      "x": 1,
      "y": -6,
      "z": -1,
      "name": "Rock_Aqua"
    },
    {
      "x": 1,
      "y": -5,
      "z": -1,
      "name": "Rock_Aqua"
    },
    {
      "x": 1,
      "y": -4,
      "z": -1,
      "name": "Rock_Aqua"
    },
    {
      "x": 1,
      "y": -3,
      "z": -1,
      "name": "Rock_Aqua"
    },
    {
      "x": 1,
      "y": -2,
      "z": -1,
      "name": "Rock_Aqua"
    },
    {
      "x": 1,
      "y": -1,
      "z": -1,
      "name": "Rock_Aqua"
    },
    {
      "x": 1,
      "y": 0,
      "z": -1,
      "name": "Rock_Aqua"
    },
    {
      "x": 1,
      "y": 1,
      "z": -1,
      "name": "Rock_Aqua"
    },
    {
      "x": 1,
      "y": 2,
      "z": -1,
      "name": "Rock_Aqua"
    },
    {
      "x": 1,
      "y": 3,
      "z": -1,
      "name": "Rock_Aqua"
    },
    {
      "x": 1,
      "y": 4,
      "z": -1,
      "name": "Rock_Aqua"
    },
    {
      "x": 1,
      "y": 5,
      "z": -1,
      "name": "Rock_Aqua"
    },
    {
      "x": 1,
      "y": 6,
      "z": -1,
      "name": "Rock_Aqua"
    },
    {
      "x": 1,
      "y": 7,
      "z": -1,
      "name": "Rock_Aqua"
    },
    {
      "x": 1,
      "y": 8,
      "z": -1,
      "name": "Rock_Aqua"
    },
    {
      "x": 1,
      "y": -8,
      "z": 0,
      "name": "Rock_Aqua"
    },
    {
      "x": 1,
      "y": -7,
      "z": 0,
      "name": "Rock_Aqua"
    },
    {
      "x": 1,
      "y": -6,
      "z": 0,
      "name": "Rock_Aqua"
    },
    {
      "x": 1,
      "y": -5,
      "z": 0,
      "name": "Rock_Aqua"
    },
    {
      "x": 1,
      "y": -4,
      "z": 0,
      "name": "Rock_Aqua"
    },
    {
      "x": 1,
      "y": -3,
      "z": 0,
      "name": "Rock_Aqua"
    },
    {
      "x": 1,
      "y": -2,
      "z": 0,
      "name": "Rock_Aqua"
    },
    {
      "x": 1,
      "y": -1,
      "z": 0,
      "name": "Rock_Aqua"
    },
    {
      "x": 1,
      "y": 0,
      "z": 0,
      "name": "Rock_Aqua"
    },
    {
      "x": 1,
      "y": 1,
      "z": 0,
      "name": "Rock_Aqua"
    },
    {
      "x": 1,
      "y": 2,
      "z": 0,
      "name": "Rock_Aqua"
    },
    {
      "x": 1,
      "y": 3,
      "z": 0,
      "name": "Rock_Aqua"
    },
    {
      "x": 1,
      "y": 4,
      "z": 0,
      "name": "Rock_Aqua"
    },
    {
      "x": 1,
      "y": 5,
      "z": 0,
      "name": "Rock_Aqua"
    },
    {
      "x": 1,
      "y": 6,
      "z": 0,
      "name": "Rock_Aqua"
    },
    {
      "x": 1,
      "y": 7,
      "z": 0,
      "name": "Rock_Aqua"
    },
    {
      "x": 1,
      "y": 8,
      "z": 0,
      "name": "Rock_Aqua"
    },
    {
      "x": 1,
      "y": -8,
      "z": 1,
      "name": "Rock_Aqua"
    },
    {
      "x": 1,
      "y": -7,
      "z": 1,
      "name": "Rock_Aqua"
    },
    {
      "x": 1,
      "y": -6,
      "z": 1,
      "name": "Rock_Aqua"
    },
    {
      "x": 1,
      "y": -5,
      "z": 1,
      "name": "Rock_Aqua"
    },
    {
      "x": 1,
      "y": -4,
      "z": 1,
      "name": "Rock_Aqua"
    },
    {
      "x": 1,
      "y": -3,
      "z": 1,
      "name": "Rock_Aqua"
    },
    {
      "x": 1,
      "y": -2,
      "z": 1,
      "name": "Rock_Aqua"
    },
    {
      "x": 1,
      "y": -1,
      "z": 1,
      "name": "Rock_Aqua"
    },
    {
      "x": 1,
      "y": 0,
      "z": 1,
      "name": "Rock_Aqua"
    },
    {
      "x": 1,
      "y": 1,
      "z": 1,
      "name": "Rock_Aqua"
    },
    {
      "x": 1,
      "y": 2,
      "z": 1,
      "name": "Rock_Aqua"
    },
    {
      "x": 1,
      "y": 3,
      "z": 1,
      "name": "Rock_Aqua"
    },
    {
      "x": 1,
      "y": 4,
      "z": 1,
      "name": "Rock_Aqua"
    },
    {
      "x": 1,
      "y": 5,
      "z": 1,
      "name": "Rock_Aqua"
    },
    {
      "x": 1,
      "y": 6,
      "z": 1,
      "name": "Rock_Aqua"
    },
    {
      "x": 1,
      "y": 7,
      "z": 1,
      "name": "Rock_Aqua"
    },
    {
      "x": 1,
      "y": 8,
      "z": 1,
      "name": "Rock_Aqua"
    },
    {
      "x": 1,
      "y": 9,
      "z": 1,
      "name": "Rubble_Aqua_Medium",
      "support": 15
    },
    {
      "x": 1,
      "y": 2,
      "z": 2,
      "name": "Rock_Aqua_Half",
      "rotation": 4
    },
    {
      "x": 1,
      "y": 3,
      "z": 2,
      "name": "Rock_Aqua_Half",
      "rotation": 4
    },
    {
      "x": 1,
      "y": 4,
      "z": 2,
      "name": "Rock_Aqua"
    },
    {
      "x": 1,
      "y": 5,
      "z": 2,
      "name": "Rock_Aqua"
    },
    {
      "x": 1,
      "y": 6,
      "z": 2,
      "name": "Rock_Aqua"
    },
    {
      "x": 1,
      "y": 7,
      "z": 2,
      "name": "Rock_Aqua"
    },
    {
      "x": 1,
      "y": 8,
      "z": 2,
      "name": "Rock_Aqua"
    },
    {
      "x": 1,
      "y": 5,
      "z": 3,
      "name": "Rock_Aqua_Half",
      "rotation": 4
    },
    {
      "x": 1,
      "y": 6,
      "z": 3,
      "name": "Rock_Aqua"
    },
    {
      "x": 1,
      "y": 7,
      "z": 3,
      "name": "Rock_Aqua"
    },
    {
      "x": 1,
      "y": 8,
      "z": 3,
      "name": "Rock_Aqua"
    },
    {
      "x": 1,
      "y": 7,
      "z": 4,
      "name": "Rock_Aqua"
    },
    {
      "x": 1,
      "y": 8,
      "z": 4,
      "name": "Rock_Aqua"
    },
    {
      "x": 1,
      "y": 7,
      "z": 5,
      "name": "Rock_Aqua_Half",
      "rotation": 8
    },
    {
      "x": 1,
      "y": 8,
      "z": 5,
      "name": "*Rock_Aqua_Stairs_State_Definitions_Inverted_Corner_Right"
    },
    {
      "x": 1,
      "y": 7,
      "z": 6,
      "name": "Rock_Aqua_Half",
      "rotation": 8
    },
    {
      "x": 1,
      "y": 8,
      "z": 6,
      "name": "Rock_Aqua_Stairs",
      "rotation": 3
    },
    {
      "x": 1,
      "y": 7,
      "z": 7,
      "name": "Rock_Aqua_Half",
      "rotation": 8
    },
    {
      "x": 1,
      "y": 8,
      "z": 7,
      "name": "Rock_Aqua"
    },
    {
      "x": 1,
      "y": 9,
      "z": 7,
      "name": "Rubble_Aqua_Medium",
      "support": 15
    },
    {
      "x": 1,
      "y": 7,
      "z": 8,
      "name": "Rock_Aqua"
    },
    {
      "x": 1,
      "y": 8,
      "z": 8,
      "name": "Rock_Aqua"
    },
    {
      "x": 1,
      "y": 5,
      "z": 9,
      "name": "Rock_Aqua_Half",
      "rotation": 6
    },
    {
      "x": 1,
      "y": 6,
      "z": 9,
      "name": "Rock_Aqua"
    },
    {
      "x": 1,
      "y": 7,
      "z": 9,
      "name": "Rock_Aqua"
    },
    {
      "x": 1,
      "y": 8,
      "z": 9,
      "name": "Rock_Aqua"
    },
    {
      "x": 1,
      "y": 2,
      "z": 10,
      "name": "Rock_Aqua_Half",
      "rotation": 6
    },
    {
      "x": 1,
      "y": 3,
      "z": 10,
      "name": "Rock_Aqua_Half",
      "rotation": 6
    },
    {
      "x": 1,
      "y": 4,
      "z": 10,
      "name": "Rock_Aqua"
    },
    {
      "x": 1,
      "y": 5,
      "z": 10,
      "name": "Rock_Aqua"
    },
    {
      "x": 1,
      "y": 6,
      "z": 10,
      "name": "Rock_Aqua"
    },
    {
      "x": 1,
      "y": 7,
      "z": 10,
      "name": "Rock_Aqua"
    },
    {
      "x": 1,
      "y": 8,
      "z": 10,
      "name": "Rock_Aqua"
    },
    {
      "x": 1,
      "y": 9,
      "z": 10,
      "name": "Rock_Aqua_Stalactite_Small"
    },
    {
      "x": 1,
      "y": -8,
      "z": 11,
      "name": "Rock_Aqua"
    },
    {
      "x": 1,
      "y": -7,
      "z": 11,
      "name": "Rock_Aqua"
    },
    {
      "x": 1,
      "y": -6,
      "z": 11,
      "name": "Rock_Aqua"
    },
    {
      "x": 1,
      "y": -5,
      "z": 11,
      "name": "Rock_Aqua"
    },
    {
      "x": 1,
      "y": -4,
      "z": 11,
      "name": "Rock_Aqua"
    },
    {
      "x": 1,
      "y": -3,
      "z": 11,
      "name": "Rock_Aqua"
    },
    {
      "x": 1,
      "y": -2,
      "z": 11,
      "name": "Rock_Aqua"
    },
    {
      "x": 1,
      "y": -1,
      "z": 11,
      "name": "Rock_Aqua"
    },
    {
      "x": 1,
      "y": 0,
      "z": 11,
      "name": "Rock_Aqua"
    },
    {
      "x": 1,
      "y": 1,
      "z": 11,
      "name": "Rock_Aqua"
    },
    {
      "x": 1,
      "y": 2,
      "z": 11,
      "name": "Rock_Aqua"
    },
    {
      "x": 1,
      "y": 3,
      "z": 11,
      "name": "Rock_Aqua"
    },
    {
      "x": 1,
      "y": 4,
      "z": 11,
      "name": "Rock_Aqua"
    },
    {
      "x": 1,
      "y": 5,
      "z": 11,
      "name": "Rock_Aqua"
    },
    {
      "x": 1,
      "y": 6,
      "z": 11,
      "name": "Rock_Aqua"
    },
    {
      "x": 1,
      "y": 7,
      "z": 11,
      "name": "Rock_Aqua"
    },
    {
      "x": 1,
      "y": 8,
      "z": 11,
      "name": "Rock_Aqua"
    },
    {
      "x": 1,
      "y": 9,
      "z": 11,
      "name": "Rubble_Aqua_Medium",
      "support": 15
    },
    {
      "x": 1,
      "y": -8,
      "z": 12,
      "name": "Rock_Aqua"
    },
    {
      "x": 1,
      "y": -7,
      "z": 12,
      "name": "Rock_Aqua"
    },
    {
      "x": 1,
      "y": -6,
      "z": 12,
      "name": "Rock_Aqua"
    },
    {
      "x": 1,
      "y": -5,
      "z": 12,
      "name": "Rock_Aqua"
    },
    {
      "x": 1,
      "y": -4,
      "z": 12,
      "name": "Rock_Aqua"
    },
    {
      "x": 1,
      "y": -3,
      "z": 12,
      "name": "Rock_Aqua"
    },
    {
      "x": 1,
      "y": -2,
      "z": 12,
      "name": "Rock_Aqua"
    },
    {
      "x": 1,
      "y": -1,
      "z": 12,
      "name": "Rock_Aqua"
    },
    {
      "x": 1,
      "y": 0,
      "z": 12,
      "name": "Rock_Aqua"
    },
    {
      "x": 1,
      "y": 1,
      "z": 12,
      "name": "Rock_Aqua"
    },
    {
      "x": 1,
      "y": 2,
      "z": 12,
      "name": "Rock_Aqua"
    },
    {
      "x": 1,
      "y": 3,
      "z": 12,
      "name": "Rock_Aqua"
    },
    {
      "x": 1,
      "y": 4,
      "z": 12,
      "name": "Rock_Aqua"
    },
    {
      "x": 1,
      "y": 5,
      "z": 12,
      "name": "Rock_Aqua"
    },
    {
      "x": 1,
      "y": 6,
      "z": 12,
      "name": "Rock_Aqua"
    },
    {
      "x": 1,
      "y": 7,
      "z": 12,
      "name": "Rock_Aqua"
    },
    {
      "x": 1,
      "y": 8,
      "z": 12,
      "name": "Rock_Aqua"
    },
    {
      "x": 2,
      "y": -8,
      "z": -12,
      "name": "Rock_Aqua"
    },
    {
      "x": 2,
      "y": -7,
      "z": -12,
      "name": "Rock_Aqua"
    },
    {
      "x": 2,
      "y": -6,
      "z": -12,
      "name": "Rock_Aqua"
    },
    {
      "x": 2,
      "y": -5,
      "z": -12,
      "name": "Rock_Aqua"
    },
    {
      "x": 2,
      "y": -4,
      "z": -12,
      "name": "Rock_Aqua"
    },
    {
      "x": 2,
      "y": -3,
      "z": -12,
      "name": "Rock_Aqua"
    },
    {
      "x": 2,
      "y": -2,
      "z": -12,
      "name": "Rock_Aqua_Brick_Smooth"
    },
    {
      "x": 2,
      "y": -1,
      "z": -12,
      "name": "Rock_Aqua_Brick_Smooth"
    },
    {
      "x": 2,
      "y": 0,
      "z": -12,
      "name": "Rock_Aqua_Brick_Stairs",
      "rotation": 1
    },
    {
      "x": 2,
      "y": 1,
      "z": -12,
      "name": "Rock_Aqua_Brick_Smooth_Half",
      "rotation": 5
    },
    {
      "x": 2,
      "y": 2,
      "z": -12,
      "name": "Rock_Aqua_Brick_Stairs",
      "rotation": 11
    },
    {
      "x": 2,
      "y": 3,
      "z": -12,
      "name": "Rock_Aqua_Brick_Stairs",
      "rotation": 1
    },
    {
      "x": 2,
      "y": 4,
      "z": -12,
      "name": "Rock_Aqua_Brick_Smooth_Half",
      "rotation": 5
    },
    {
      "x": 2,
      "y": 5,
      "z": -12,
      "name": "Rock_Aqua_Brick_Stairs",
      "rotation": 11
    },
    {
      "x": 2,
      "y": 6,
      "z": -12,
      "name": "Rock_Aqua_Brick_Stairs",
      "rotation": 1
    },
    {
      "x": 2,
      "y": 7,
      "z": -12,
      "name": "Rock_Aqua_Brick_Smooth_Half",
      "rotation": 5
    },
    {
      "x": 2,
      "y": 8,
      "z": -12,
      "name": "Rock_Aqua_Brick_Stairs",
      "rotation": 11
    },
    {
      "x": 2,
      "y": 9,
      "z": -12,
      "name": "Rock_Aqua_Brick_Wall",
      "rotation": 1
    },
    {
      "x": 2,
      "y": 2,
      "z": -11,
      "name": "Rock_Aqua_Brick_Stairs",
      "rotation": 11
    },
    {
      "x": 2,
      "y": 3,
      "z": -11,
      "name": "Rock_Aqua_Brick_Stairs",
      "rotation": 1
    },
    {
      "x": 2,
      "y": 4,
      "z": -11,
      "name": "Rock_Aqua_Brick_Smooth_Half",
      "rotation": 5
    },
    {
      "x": 2,
      "y": 5,
      "z": -11,
      "name": "Rock_Aqua_Brick_Stairs",
      "rotation": 11
    },
    {
      "x": 2,
      "y": 6,
      "z": -11,
      "name": "Rock_Aqua_Brick_Stairs",
      "rotation": 1
    },
    {
      "x": 2,
      "y": 7,
      "z": -11,
      "name": "Rock_Aqua_Brick_Smooth_Half",
      "rotation": 5
    },
    {
      "x": 2,
      "y": 8,
      "z": -11,
      "name": "Rock_Aqua_Brick_Stairs",
      "rotation": 11
    },
    {
      "x": 2,
      "y": 9,
      "z": -11,
      "name": "Rock_Aqua_Brick_Wall",
      "rotation": 1
    },
    {
      "x": 2,
      "y": 6,
      "z": -10,
      "name": "Rock_Aqua_Brick_Stairs",
      "rotation": 1
    },
    {
      "x": 2,
      "y": 7,
      "z": -10,
      "name": "Rock_Aqua_Brick_Smooth_Half",
      "rotation": 5
    },
    {
      "x": 2,
      "y": 8,
      "z": -10,
      "name": "Rock_Aqua_Brick_Stairs",
      "rotation": 11
    },
    {
      "x": 2,
      "y": 9,
      "z": -10,
      "name": "Rock_Aqua_Brick_Wall",
      "rotation": 1
    },
    {
      "x": 2,
      "y": 7,
      "z": -9,
      "name": "Rock_Aqua_Brick_Smooth_Half",
      "rotation": 5
    },
    {
      "x": 2,
      "y": 8,
      "z": -9,
      "name": "Rock_Aqua_Brick_Stairs",
      "rotation": 11
    },
    {
      "x": 2,
      "y": 9,
      "z": -9,
      "name": "Rock_Aqua_Brick_Wall",
      "rotation": 1
    },
    {
      "x": 2,
      "y": 8,
      "z": -8,
      "name": "Rock_Aqua_Brick_Stairs",
      "rotation": 11
    },
    {
      "x": 2,
      "y": 9,
      "z": -8,
      "name": "Rock_Aqua_Brick_Wall",
      "rotation": 1
    },
    {
      "x": 2,
      "y": 8,
      "z": -7,
      "name": "Rock_Aqua_Brick_Stairs",
      "rotation": 11
    },
    {
      "x": 2,
      "y": 9,
      "z": -7,
      "name": "Rock_Aqua_Brick_Wall",
      "rotation": 1
    },
    {
      "x": 2,
      "y": 8,
      "z": -6,
      "name": "Rock_Aqua_Brick_Stairs",
      "rotation": 11
    },
    {
      "x": 2,
      "y": 9,
      "z": -6,
      "name": "Rock_Aqua_Brick_Wall",
      "rotation": 1
    },
    {
      "x": 2,
      "y": 8,
      "z": -5,
      "name": "Rock_Aqua_Brick_Stairs",
      "rotation": 11
    },
    {
      "x": 2,
      "y": 9,
      "z": -5,
      "name": "Rock_Aqua_Brick_Wall",
      "rotation": 1
    },
    {
      "x": 2,
      "y": 8,
      "z": -4,
      "name": "Rock_Aqua_Brick_Stairs",
      "rotation": 11
    },
    {
      "x": 2,
      "y": 9,
      "z": -4,
      "name": "Rock_Aqua_Brick_Wall",
      "rotation": 1
    },
    {
      "x": 2,
      "y": 7,
      "z": -3,
      "name": "Rock_Aqua_Brick_Smooth_Half",
      "rotation": 5
    },
    {
      "x": 2,
      "y": 8,
      "z": -3,
      "name": "Rock_Aqua_Brick_Stairs",
      "rotation": 11
    },
    {
      "x": 2,
      "y": 9,
      "z": -3,
      "name": "Rock_Aqua_Brick_Wall",
      "rotation": 1
    },
    {
      "x": 2,
      "y": 6,
      "z": -2,
      "name": "Rock_Aqua_Brick_Stairs",
      "rotation": 1
    },
    {
      "x": 2,
      "y": 7,
      "z": -2,
      "name": "Rock_Aqua_Brick_Smooth_Half",
      "rotation": 5
    },
    {
      "x": 2,
      "y": 8,
      "z": -2,
      "name": "Rock_Aqua_Brick_Stairs",
      "rotation": 11
    },
    {
      "x": 2,
      "y": 9,
      "z": -2,
      "name": "Rock_Aqua_Brick_Wall",
      "rotation": 1
    },
    {
      "x": 2,
      "y": 4,
      "z": -1,
      "name": "Rock_Aqua_Brick_Smooth_Half",
      "rotation": 5
    },
    {
      "x": 2,
      "y": 5,
      "z": -1,
      "name": "Rock_Aqua_Brick_Stairs",
      "rotation": 11
    },
    {
      "x": 2,
      "y": 6,
      "z": -1,
      "name": "Rock_Aqua_Brick_Stairs",
      "rotation": 1
    },
    {
      "x": 2,
      "y": 7,
      "z": -1,
      "name": "Rock_Aqua_Brick_Smooth_Half",
      "rotation": 5
    },
    {
      "x": 2,
      "y": 8,
      "z": -1,
      "name": "Rock_Aqua_Brick_Stairs",
      "rotation": 11
    },
    {
      "x": 2,
      "y": 9,
      "z": -1,
      "name": "Rock_Aqua_Brick_Wall",
      "rotation": 1
    },
    {
      "x": 2,
      "y": -8,
      "z": 0,
      "name": "Rock_Aqua"
    },
    {
      "x": 2,
      "y": -7,
      "z": 0,
      "name": "Rock_Aqua"
    },
    {
      "x": 2,
      "y": -6,
      "z": 0,
      "name": "Rock_Aqua"
    },
    {
      "x": 2,
      "y": -5,
      "z": 0,
      "name": "Rock_Aqua"
    },
    {
      "x": 2,
      "y": -4,
      "z": 0,
      "name": "Rock_Aqua"
    },
    {
      "x": 2,
      "y": -3,
      "z": 0,
      "name": "Rock_Aqua"
    },
    {
      "x": 2,
      "y": -2,
      "z": 0,
      "name": "Rock_Aqua"
    },
    {
      "x": 2,
      "y": -1,
      "z": 0,
      "name": "Rock_Aqua_Brick_Smooth"
    },
    {
      "x": 2,
      "y": 0,
      "z": 0,
      "name": "Rock_Aqua_Brick_Stairs",
      "rotation": 1
    },
    {
      "x": 2,
      "y": 1,
      "z": 0,
      "name": "Rock_Aqua_Brick_Smooth_Half",
      "rotation": 5
    },
    {
      "x": 2,
      "y": 2,
      "z": 0,
      "name": "Rock_Aqua_Brick_Stairs",
      "rotation": 11
    },
    {
      "x": 2,
      "y": 3,
      "z": 0,
      "name": "Rock_Aqua_Brick_Stairs",
      "rotation": 1
    },
    {
      "x": 2,
      "y": 4,
      "z": 0,
      "name": "Rock_Aqua_Brick_Smooth_Half",
      "rotation": 5
    },
    {
      "x": 2,
      "y": 5,
      "z": 0,
      "name": "Rock_Aqua_Brick_Stairs",
      "rotation": 11
    },
    {
      "x": 2,
      "y": 6,
      "z": 0,
      "name": "Rock_Aqua_Brick_Stairs",
      "rotation": 1
    },
    {
      "x": 2,
      "y": 7,
      "z": 0,
      "name": "Rock_Aqua_Brick_Smooth_Half",
      "rotation": 5
    },
    {
      "x": 2,
      "y": 8,
      "z": 0,
      "name": "Rock_Aqua_Brick_Stairs",
      "rotation": 11
    },
    {
      "x": 2,
      "y": 9,
      "z": 0,
      "name": "Rock_Aqua_Brick_Wall",
      "rotation": 1
    },
    {
      "x": 2,
      "y": 4,
      "z": 1,
      "name": "Rock_Aqua_Brick_Smooth_Half",
      "rotation": 5
    },
    {
      "x": 2,
      "y": 5,
      "z": 1,
      "name": "Rock_Aqua_Brick_Stairs",
      "rotation": 11
    },
    {
      "x": 2,
      "y": 6,
      "z": 1,
      "name": "Rock_Aqua_Brick_Stairs",
      "rotation": 1
    },
    {
      "x": 2,
      "y": 7,
      "z": 1,
      "name": "Rock_Aqua_Brick_Smooth_Half",
      "rotation": 5
    },
    {
      "x": 2,
      "y": 8,
      "z": 1,
      "name": "Rock_Aqua_Brick_Stairs",
      "rotation": 11
    },
    {
      "x": 2,
      "y": 9,
      "z": 1,
      "name": "Rock_Aqua_Brick_Wall",
      "rotation": 1
    },
    {
      "x": 2,
      "y": 6,
      "z": 2,
      "name": "Rock_Aqua_Brick_Stairs",
      "rotation": 1
    },
    {
      "x": 2,
      "y": 7,
      "z": 2,
      "name": "Rock_Aqua_Brick_Smooth_Half",
      "rotation": 5
    },
    {
      "x": 2,
      "y": 8,
      "z": 2,
      "name": "Rock_Aqua_Brick_Stairs",
      "rotation": 11
    },
    {
      "x": 2,
      "y": 9,
      "z": 2,
      "name": "Rock_Aqua_Brick_Wall",
      "rotation": 1
    },
    {
      "x": 2,
      "y": 7,
      "z": 3,
      "name": "Rock_Aqua_Brick_Smooth_Half",
      "rotation": 5
    },
    {
      "x": 2,
      "y": 8,
      "z": 3,
      "name": "Rock_Aqua_Brick_Stairs",
      "rotation": 11
    },
    {
      "x": 2,
      "y": 9,
      "z": 3,
      "name": "Rock_Aqua_Brick_Half"
    },
    {
      "x": 2,
      "y": 8,
      "z": 4,
      "name": "Rock_Aqua_Brick_Stairs",
      "rotation": 11
    },
    {
      "x": 2,
      "y": 9,
      "z": 4,
      "name": "Rock_Aqua_Brick_Half"
    },
    {
      "x": 2,
      "y": 8,
      "z": 5,
      "name": "Rock_Aqua_Brick_Stairs",
      "rotation": 11
    },
    {
      "x": 2,
      "y": 9,
      "z": 5,
      "name": "Rubble_Aqua_Medium",
      "support": 15
    },
    {
      "x": 2,
      "y": 8,
      "z": 6,
      "name": "Rock_Aqua_Brick_Stairs",
      "rotation": 11
    },
    {
      "x": 2,
      "y": 9,
      "z": 6,
      "name": "Rock_Aqua_Brick_Wall",
      "rotation": 1
    },
    {
      "x": 2,
      "y": 8,
      "z": 7,
      "name": "Rock_Aqua_Brick_Stairs",
      "rotation": 11
    },
    {
      "x": 2,
      "y": 9,
      "z": 7,
      "name": "Rock_Aqua_Brick_Wall",
      "rotation": 1
    },
    {
      "x": 2,
      "y": 8,
      "z": 8,
      "name": "Rock_Aqua_Brick_Stairs",
      "rotation": 11
    },
    {
      "x": 2,
      "y": 9,
      "z": 8,
      "name": "Rock_Aqua_Brick_Wall",
      "rotation": 1
    },
    {
      "x": 2,
      "y": 7,
      "z": 9,
      "name": "Rock_Aqua_Brick_Smooth_Half",
      "rotation": 5
    },
    {
      "x": 2,
      "y": 8,
      "z": 9,
      "name": "Rock_Aqua_Brick_Stairs",
      "rotation": 11
    },
    {
      "x": 2,
      "y": 9,
      "z": 9,
      "name": "Rock_Aqua_Brick_Wall",
      "rotation": 1
    },
    {
      "x": 2,
      "y": 6,
      "z": 10,
      "name": "Rock_Aqua_Brick_Stairs",
      "rotation": 1
    },
    {
      "x": 2,
      "y": 7,
      "z": 10,
      "name": "Rock_Aqua_Brick_Smooth_Half",
      "rotation": 5
    },
    {
      "x": 2,
      "y": 8,
      "z": 10,
      "name": "Rock_Aqua_Brick_Stairs",
      "rotation": 11
    },
    {
      "x": 2,
      "y": 9,
      "z": 10,
      "name": "Rock_Aqua_Brick_Wall",
      "rotation": 1
    },
    {
      "x": 2,
      "y": 4,
      "z": 11,
      "name": "Rock_Aqua_Brick_Smooth_Half",
      "rotation": 5
    },
    {
      "x": 2,
      "y": 5,
      "z": 11,
      "name": "Rock_Aqua_Brick_Stairs",
      "rotation": 11
    },
    {
      "x": 2,
      "y": 6,
      "z": 11,
      "name": "Rock_Aqua_Brick_Stairs",
      "rotation": 1
    },
    {
      "x": 2,
      "y": 7,
      "z": 11,
      "name": "Rock_Aqua_Brick_Smooth_Half",
      "rotation": 5
    },
    {
      "x": 2,
      "y": 8,
      "z": 11,
      "name": "Rock_Aqua_Brick_Stairs",
      "rotation": 11
    },
    {
      "x": 2,
      "y": 9,
      "z": 11,
      "name": "Rock_Aqua_Brick_Wall",
      "rotation": 1
    },
    {
      "x": 2,
      "y": -8,
      "z": 12,
      "name": "Rock_Aqua"
    },
    {
      "x": 2,
      "y": -7,
      "z": 12,
      "name": "Rock_Aqua"
    },
    {
      "x": 2,
      "y": -6,
      "z": 12,
      "name": "Rock_Aqua"
    },
    {
      "x": 2,
      "y": -5,
      "z": 12,
      "name": "Rock_Aqua"
    },
    {
      "x": 2,
      "y": -4,
      "z": 12,
      "name": "Rock_Aqua"
    },
    {
      "x": 2,
      "y": -3,
      "z": 12,
      "name": "Rock_Aqua"
    },
    {
      "x": 2,
      "y": -2,
      "z": 12,
      "name": "Rock_Aqua"
    },
    {
      "x": 2,
      "y": -1,
      "z": 12,
      "name": "Rock_Aqua_Brick_Smooth"
    },
    {
      "x": 2,
      "y": 0,
      "z": 12,
      "name": "Rock_Aqua_Brick_Stairs",
      "rotation": 1
    },
    {
      "x": 2,
      "y": 1,
      "z": 12,
      "name": "Rock_Aqua_Brick_Smooth_Half",
      "rotation": 5
    },
    {
      "x": 2,
      "y": 2,
      "z": 12,
      "name": "Rock_Aqua_Brick_Stairs",
      "rotation": 11
    },
    {
      "x": 2,
      "y": 3,
      "z": 12,
      "name": "Rock_Aqua_Brick_Stairs",
      "rotation": 1
    },
    {
      "x": 2,
      "y": 4,
      "z": 12,
      "name": "Rock_Aqua_Brick_Smooth_Half",
      "rotation": 5
    },
    {
      "x": 2,
      "y": 5,
      "z": 12,
      "name": "Rock_Aqua_Brick_Stairs",
      "rotation": 11
    },
    {
      "x": 2,
      "y": 6,
      "z": 12,
      "name": "Rock_Aqua_Brick_Stairs",
      "rotation": 1
    },
    {
      "x": 2,
      "y": 7,
      "z": 12,
      "name": "Rock_Aqua_Brick_Smooth_Half",
      "rotation": 5
    },
    {
      "x": 2,
      "y": 8,
      "z": 12,
      "name": "Rock_Aqua_Brick_Stairs",
      "rotation": 11
    },
    {
      "x": 2,
      "y": 9,
      "z": 12,
      "name": "Rock_Aqua_Brick_Wall",
      "rotation": 1
    }
  ]
}