{
  "version": 8,
  "blockIdVersion": 11,
  "anchorX": 0,
  "anchorY": 25,
  "anchorZ": 12,
  "blocks": [
    {
      "x": -2,
      "y": 0,
      "z": -12,
      "name": "Rock_Aqua"
    },
    {
      "x": -2,
      "y": 1,
      "z": -12,
      "name": "Rock_Aqua"
    },
    {
      "x": -2,
      "y": 2,
      "z": -12,
      "name": "Rock_Aqua"
    },
    {
      "x": -2,
      "y": 3,
      "z": -12,
      "name": "Rock_Aqua"
    },
    {
      "x": -2,
      "y": 4,
      "z": -12,
      "name": "Rock_Aqua"
    },
    {
      "x": -2,
      "y": 5,
      "z": -12,
      "name": "Rock_Aqua"
    },
    {
      "x": -2,
      "y": 6,
      "z": -12,
      "name": "Rock_Aqua"
    },
    {
      "x": -2,
      "y": 7,
      "z": -12,
      "name": "Rock_Aqua"
    },
    {
      "x": -2,
      "y": 8,
      "z": -12,
      "name": "Rock_Aqua"
    },
    {
      "x": -2,
      "y": 9,
      "z": -12,
      "name": "Rock_Aqua"
    },
    {
      "x": -2,
      "y": 10,
      "z": -12,
      "name": "Rock_Aqua"
    },
    {
      "x": -2,
      "y": 11,
      "z": -12,
      "name": "Rock_Aqua"
    },
    {
      "x": -2,
      "y": 12,
      "z": -12,
      "name": "Rock_Aqua"
    },
    {
      "x": -2,
      "y": 13,
      "z": -12,
      "name": "Rock_Aqua"
    },
    {
      "x": -2,
      "y": 14,
      "z": -12,
      "name": "Rock_Aqua"
    },
    {
      "x": -2,
      "y": 15,
      "z": -12,
      "name": "Rock_Aqua"
    },
    {
      "x": -2,
      "y": 16,
      "z": -12,
      "name": "Rock_Aqua_Brick_Smooth"
    },
    {
      "x": -2,
      "y": 17,
      "z": -12,
      "name": "Rock_Aqua_Brick_Stairs",
      "rotation": 3
    },
    {
      "x": -2,
      "y": 18,
      "z": -12,
      "name": "Rock_Aqua_Brick_Smooth_Half",
      "rotation": 7
    },
    {
      "x": -2,
      "y": 19,
      "z": -12,
      "name": "Rock_Aqua_Brick_Stairs",
      "rotation": 9
    },
    {
      "x": -2,
      "y": 20,
      "z": -12,
      "name": "Rock_Aqua_Brick_Stairs",
      "rotation": 3
    },
    {
      "x": -2,
      "y": 21,
      "z": -12,
      "name": "Rock_Aqua_Brick_Smooth_Half",
      "rotation": 7
    },
    {
      "x": -2,
      "y": 22,
      "z": -12,
      "name": "Rock_Aqua_Brick_Stairs",
      "rotation": 9
    },
    {
      "x": -2,
      "y": 23,
      "z": -12,
      "name": "Rock_Aqua_Brick_Stairs",
      "rotation": 3
    },
    {
      "x": -2,
      "y": 24,
      "z": -12,
      "name": "Rock_Aqua_Brick_Smooth_Half",
      "rotation": 7
    },
    {
      "x": -2,
      "y": 25,
      "z": -12,
      "name": "Rock_Aqua_Brick_Stairs",
      "rotation": 9
    },
    {
      "x": -2,
      "y": 26,
      "z": -12,
      "name": "Rock_Aqua_Brick_Wall",
      "rotation": 3
    },
    {
      "x": -2,
      "y": 21,
      "z": -11,
      "name": "Rock_Aqua_Brick_Smooth_Half",
      "rotation": 7
    },
    {
      "x": -2,
      "y": 22,
      "z": -11,
      "name": "Rock_Aqua_Brick_Stairs",
      "rotation": 9
    },
    {
      "x": -2,
      "y": 23,
      "z": -11,
      "name": "Rock_Aqua_Brick_Stairs",
      "rotation": 3
    },
    {
      "x": -2,
      "y": 24,
      "z": -11,
      "name": "Rock_Aqua_Brick_Smooth_Half",
      "rotation": 7
    },
    {
      "x": -2,
      "y": 25,
      "z": -11,
      "name": "Rock_Aqua_Brick_Stairs",
      "rotation": 9
    },
    {
      "x": -2,
      "y": 26,
      "z": -11,
      "name": "Rock_Aqua_Brick_Wall",
      "rotation": 3
    },
    {
      "x": -2,
      "y": 23,
      "z": -10,
      "name": "Rock_Aqua_Brick_Stairs",
      "rotation": 3
    },
    {
      "x": -2,
      "y": 24,
      "z": -10,
      "name": "Rock_Aqua_Brick_Smooth_Half",
      "rotation": 7
    },
    {
      "x": -2,
      "y": 25,
      "z": -10,
      "name": "Rock_Aqua_Brick_Stairs",
      "rotation": 9
    },
    {
      "x": -2,
      "y": 26,
      "z": -10,
      "name": "Rock_Aqua_Brick_Wall",
      "rotation": 3
    },
    {
      "x": -2,
      "y": 24,
      "z": -9,
      "name": "Rock_Aqua_Brick_Smooth_Half",
      "rotation": 7
    },
    {
      "x": -2,
      "y": 25,
      "z": -9,
      "name": "Rock_Aqua_Brick_Stairs",
      "rotation": 9
    },
    {
      "x": -2,
      "y": 26,
      "z": -9,
      "name": "Rock_Aqua_Brick_Wall",
      "rotation": 3
    },
    {
      "x": -2,
      "y": 25,
      "z": -8,
      "name": "Rock_Aqua_Brick_Stairs",
      "rotation": 9
    },
    {
      "x": -2,
      "y": 26,
      "z": -8,
      "name": "Rock_Aqua_Brick_Wall",
      "rotation": 3
    },
    {
      "x": -2,
      "y": 25,
      "z": -7,
      "name": "Rock_Aqua_Brick_Stairs",
      "rotation": 9
    },
    {
      "x": -2,
      "y": 25,
      "z": -4,
      "name": "Rock_Aqua_Brick_Stairs",
      "rotation": 9
    },
    {
      "x": -2,
      "y": 24,
      "z": -3,
      "name": "Rock_Aqua_Brick_Smooth_Half",
      "rotation": 7
    },
    {
      "x": -2,
      "y": 25,
      "z": -3,
      "name": "Rock_Aqua_Brick_Stairs",
      "rotation": 9
    },
    {
      "x": -2,
      "y": 26,
      "z": -3,
      "name": "Rock_Aqua_Brick_Wall",
      "rotation": 3
    },
    {
      "x": -2,
      "y": 23,
      "z": -2,
      "name": "Rock_Aqua_Brick_Stairs",
      "rotation": 3
    },
    {
      "x": -2,
      "y": 24,
      "z": -2,
      "name": "Rock_Aqua_Brick_Smooth_Half",
      "rotation": 7
    },
    {
      "x": -2,
      "y": 25,
      "z": -2,
      "name": "Rock_Aqua_Brick_Stairs",
      "rotation": 9
    },
    {
      "x": -2,
      "y": 26,
      "z": -2,
      "name": "Rock_Aqua_Brick_Wall",
      "rotation": 3
    },
    {
      "x": -2,
      "y": 21,
      "z": -1,
      "name": "Rock_Aqua_Brick_Smooth_Half",
      "rotation": 7
    },
    {
      "x": -2,
      "y": 22,
      "z": -1,
      "name": "Rock_Aqua_Brick_Stairs",
      "rotation": 9
    },
    {
      "x": -2,
      "y": 23,
      "z": -1,
      "name": "Rock_Aqua_Brick_Stairs",
      "rotation": 3
    },
    {
      "x": -2,
      "y": 24,
      "z": -1,
      "name": "Rock_Aqua_Brick_Smooth_Half",
      "rotation": 7
    },
    {
      "x": -2,
      "y": 25,
      "z": -1,
      "name": "Rock_Aqua_Brick_Stairs",
      "rotation": 9
    },
    {
      "x": -2,
      "y": 26,
      "z": -1,
      "name": "Rock_Aqua_Brick_Wall",
      "rotation": 3
    },
    {
      "x": -2,
      "y": 0,
      "z": 0,
      "name": "Rock_Aqua"
    },
    {
      "x": -2,
      "y": 1,
      "z": 0,
      "name": "Rock_Aqua"
    },
    {
      "x": -2,
      "y": 2,
      "z": 0,
      "name": "Rock_Aqua"
    },
    {
      "x": -2,
      "y": 3,
      "z": 0,
      "name": "Rock_Aqua"
    },
    {
      "x": -2,
      "y": 4,
      "z": 0,
      "name": "Rock_Aqua"
    },
    {
      "x": -2,
      "y": 5,
      "z": 0,
      "name": "Rock_Aqua"
    },
    {
      "x": -2,
      "y": 6,
      "z": 0,
      "name": "Rock_Aqua"
    },
    {
      "x": -2,
      "y": 7,
      "z": 0,
      "name": "Rock_Aqua"
    },
    {
      "x": -2,
      "y": 8,
      "z": 0,
      "name": "Rock_Aqua"
    },
    {
      "x": -2,
      "y": 9,
      "z": 0,
      "name": "Rock_Aqua"
    },
    {
      "x": -2,
      "y": 10,
      "z": 0,
      "name": "Rock_Aqua"
    },
    {
      "x": -2,
      "y": 11,
      "z": 0,
      "name": "Rock_Aqua"
    },
    {
      "x": -2,
      "y": 12,
      "z": 0,
      "name": "Rock_Aqua"
    },
    {
      "x": -2,
      "y": 13,
      "z": 0,
      "name": "Rock_Aqua"
    },
    {
      "x": -2,
      "y": 14,
      "z": 0,
      "name": "Rock_Aqua"
    },
    {
      "x": -2,
      "y": 15,
      "z": 0,
      "name": "Rock_Aqua"
    },
    {
      "x": -2,
      "y": 16,
      "z": 0,
      "name": "Rock_Aqua_Brick_Smooth"
    },
    {
      "x": -2,
      "y": 17,
      "z": 0,
      "name": "Rock_Aqua_Brick_Stairs",
      "rotation": 3
    },
    {
      "x": -2,
      "y": 18,
      "z": 0,
      "name": "Rock_Aqua_Brick_Smooth_Half",
      "rotation": 7
    },
    {
      "x": -2,
      "y": 19,
      "z": 0,
      "name": "Rock_Aqua_Brick_Stairs",
      "rotation": 9
    },
    {
      "x": -2,
      "y": 20,
      "z": 0,
      "name": "Rock_Aqua_Brick_Stairs",
      "rotation": 3
    },
    {
      "x": -2,
      "y": 21,
      "z": 0,
      "name": "Rock_Aqua_Brick_Smooth_Half",
      "rotation": 7
    },
    {
      "x": -2,
      "y": 22,
      "z": 0,
      "name": "Rock_Aqua_Brick_Stairs",
      "rotation": 9
    },
    {
      "x": -2,
      "y": 23,
      "z": 0,
      "name": "Rock_Aqua_Brick_Stairs",
      "rotation": 3
    },
    {
      "x": -2,
      "y": 24,
      "z": 0,
      "name": "Rock_Aqua_Brick_Smooth_Half",
      "rotation": 7
    },
    {
      "x": -2,
      "y": 25,
      "z": 0,
      "name": "Rock_Aqua_Brick_Stairs",
      "rotation": 9
    },
    {
      "x": -2,
      "y": 26,
      "z": 0,
      "name": "Rock_Aqua_Brick_Wall",
      "rotation": 3
    },
    {
      "x": -2,
      "y": 21,
      "z": 1,
      "name": "Rock_Aqua_Brick_Smooth_Half",
      "rotation": 7
    },
    {
      "x": -2,
      "y": 22,
      "z": 1,
      "name": "Rock_Aqua_Brick_Stairs",
      "rotation": 9
    },
    {
      "x": -2,
      "y": 23,
      "z": 1,
      "name": "Rock_Aqua_Brick_Stairs",
      "rotation": 3
    },
    {
      "x": -2,
      "y": 24,
      "z": 1,
      "name": "Rock_Aqua_Brick_Smooth_Half",
      "rotation": 7
    },
    {
      "x": -2,
      "y": 25,
      "z": 1,
      "name": "Rock_Aqua_Brick_Stairs",
      "rotation": 9
    },
    {
      "x": -2,
      "y": 26,
      "z": 1,
      "name": "Rubble_Aqua",
      "support": 15
    },
    {
      "x": -2,
      "y": 23,
      "z": 2,
      "name": "Rock_Aqua_Brick_Stairs",
      "rotation": 3
    },
    {
      "x": -2,
      "y": 24,
      "z": 2,
      "name": "Rock_Aqua_Brick_Smooth_Half",
      "rotation": 7
    },
    {
      "x": -2,
      "y": 25,
      "z": 2,
      "name": "Rock_Aqua_Brick_Stairs",
      "rotation": 9
    },
    {
      "x": -2,
      "y": 26,
      "z": 2,
      "name": "Rock_Aqua_Brick_Wall",
      "rotation": 3
    },
    {
      "x": -2,
      "y": 24,
      "z": 3,
      "name": "Rock_Aqua_Brick_Smooth_Half",
      "rotation": 7
    },
    {
      "x": -2,
      "y": 25,
      "z": 3,
      "name": "Rock_Aqua_Brick_Stairs",
      "rotation": 9
    },
    {
      "x": -2,
      "y": 26,
      "z": 3,
      "name": "Rock_Aqua_Brick_Wall",
      "rotation": 3
    },
    {
      "x": -2,
      "y": 25,
      "z": 8,
      "name": "Rock_Aqua_Brick_Stairs",
      "rotation": 9
    },
    {
      "x": -2,
      "y": 26,
      "z": 8,
      "name": "Rock_Aqua_Brick_Wall",
      "rotation": 3
    },
    {
      "x": -2,
      "y": 24,
      "z": 9,
      "name": "Rock_Aqua_Brick_Smooth_Half",
      "rotation": 7
    },
    {
      "x": -2,
      "y": 25,
      "z": 9,
      "name": "Rock_Aqua_Brick_Stairs",
      "rotation": 9
    },
    {
      "x": -2,
      "y": 26,
      "z": 9,
      "name": "Rock_Aqua_Brick_Wall",
      "rotation": 3
    },
    {
      "x": -2,
      "y": 23,
      "z": 10,
      "name": "Rock_Aqua_Brick_Stairs",
      "rotation": 3
    },
    {
      "x": -2,
      "y": 24,
      "z": 10,
      "name": "Rock_Aqua_Brick_Smooth_Half",
      "rotation": 7
    },
    {
      "x": -2,
      "y": 25,
      "z": 10,
      "name": "Rock_Aqua_Brick_Stairs",
      "rotation": 9
    },
    {
      "x": -2,
      "y": 26,
      "z": 10,
      "name": "Rock_Aqua_Brick_Wall",
      "rotation": 3
    },
    {
      "x": -2,
      "y": 19,
      "z": 11,
      "name": "Rock_Aqua_Brick_Stairs",
      "rotation": 9
    },
    {
      "x": -2,
      "y": 20,
      "z": 11,
      "name": "Rock_Aqua_Brick_Stairs",
      "rotation": 3
    },
    {
      "x": -2,
      "y": 21,
      "z": 11,
      "name": "Rock_Aqua_Brick_Smooth_Half",
      "rotation": 7
    },
    {
      "x": -2,
      "y": 22,
      "z": 11,
      "name": "Rock_Aqua_Brick_Stairs",
      "rotation": 9
    },
    {
      "x": -2,
      "y": 23,
      "z": 11,
      "name": "Rock_Aqua_Brick_Stairs",
      "rotation": 3
    },
    {
      "x": -2,
      "y": 24,
      "z": 11,
      "name": "Rock_Aqua_Brick_Smooth_Half",
      "rotation": 7
    },
    {
      "x": -2,
      "y": 25,
      "z": 11,
      "name": "Rock_Aqua_Brick_Stairs",
      "rotation": 9
    },
    {
      "x": -2,
      "y": 26,
      "z": 11,
      "name": "Rock_Aqua_Brick_Wall",
      "rotation": 3
    },
    {
      "x": -2,
      "y": 0,
      "z": 12,
      "name": "Rock_Aqua"
    },
    {
      "x": -2,
      "y": 1,
      "z": 12,
      "name": "Rock_Aqua"
    },
    {
      "x": -2,
      "y": 2,
      "z": 12,
      "name": "Rock_Aqua"
    },
    {
      "x": -2,
      "y": 3,
      "z": 12,
      "name": "Rock_Aqua"
    },
    {
      "x": -2,
      "y": 4,
      "z": 12,
      "name": "Rock_Aqua"
    },
    {
      "x": -2,
      "y": 5,
      "z": 12,
      "name": "Rock_Aqua"
    },
    {
      "x": -2,
      "y": 6,
      "z": 12,
      "name": "Rock_Aqua"
    },
    {
      "x": -2,
      "y": 7,
      "z": 12,
      "name": "Rock_Aqua"
    },
    {
      "x": -2,
      "y": 8,
      "z": 12,
      "name": "Rock_Aqua"
    },
    {
      "x": -2,
      "y": 9,
      "z": 12,
      "name": "Rock_Aqua"
    },
    {
      "x": -2,
      "y": 10,
      "z": 12,
      "name": "Rock_Aqua"
    },
    {
      "x": -2,
      "y": 11,
      "z": 12,
      "name": "Rock_Aqua"
    },
    {
      "x": -2,
      "y": 12,
      "z": 12,
      "name": "Rock_Aqua"
    },
    {
      "x": -2,
      "y": 13,
      "z": 12,
      "name": "Rock_Aqua"
    },
    {
      "x": -2,
      "y": 14,
      "z": 12,
      "name": "Rock_Aqua"
    },
    {
      "x": -2,
      "y": 15,
      "z": 12,
      "name": "Rock_Aqua"
    },
    {
      "x": -2,
      "y": 16,
      "z": 12,
      "name": "Rock_Aqua_Brick_Smooth"
    },
    {
      "x": -2,
      "y": 17,
      "z": 12,
      "name": "Rock_Aqua_Brick_Stairs",
      "rotation": 3
    },
    {
      "x": -2,
      "y": 18,
      "z": 12,
      "name": "Rock_Aqua_Brick_Smooth_Half",
      "rotation": 7
    },
    {
      "x": -2,
      "y": 19,
      "z": 12,
      "name": "Rock_Aqua_Brick_Stairs",
      "rotation": 9
    },
    {
      "x": -2,
      "y": 20,
      "z": 12,
      "name": "Rock_Aqua_Brick_Stairs",
      "rotation": 3
    },
    {
      "x": -2,
      "y": 21,
      "z": 12,
      "name": "Rock_Aqua_Brick_Smooth_Half",
      "rotation": 7
    },
    {
      "x": -2,
      "y": 22,
      "z": 12,
      "name": "Rock_Aqua_Brick_Stairs",
      "rotation": 9
    },
    {
      "x": -2,
      "y": 23,
      "z": 12,
      "name": "Rock_Aqua_Brick_Stairs",
      "rotation": 3
    },
    {
      "x": -2,
      "y": 24,
      "z": 12,
      "name": "Rock_Aqua_Brick_Smooth_Half",
      "rotation": 7
    },
    {
      "x": -2,
      "y": 25,
      "z": 12,
      "name": "Rock_Aqua_Brick_Stairs",
      "rotation": 9
    },
    {
      "x": -2,
      "y": 26,
      "z": 12,
      "name": "Rock_Aqua_Brick_Wall",
      "rotation": 3
    },
    {
      "x": -1,
      "y": 0,
      "z": -12,
      "name": "Rock_Aqua"
    },
    {
      "x": -1,
      "y": 1,
      "z": -12,
      "name": "Rock_Aqua"
    },
    {
      "x": -1,
      "y": 2,
      "z": -12,
      "name": "Rock_Aqua"
    },
    {
      "x": -1,
      "y": 3,
      "z": -12,
      "name": "Rock_Aqua"
    },
    {
      "x": -1,
      "y": 4,
      "z": -12,
      "name": "Rock_Aqua"
    },
    {
      "x": -1,
      "y": 5,
      "z": -12,
      "name": "Rock_Aqua"
    },
    {
      "x": -1,
      "y": 6,
      "z": -12,
      "name": "Rock_Aqua"
    },
    {
      "x": -1,
      "y": 7,
      "z": -12,
      "name": "Rock_Aqua"
    },
    {
      "x": -1,
      "y": 8,
      "z": -12,
      "name": "Rock_Aqua"
    },
    {
      "x": -1,
      "y": 9,
      "z": -12,
      "name": "Rock_Aqua"
    },
    {
      "x": -1,
      "y": 10,
      "z": -12,
      "name": "Rock_Aqua"
    },
    {
      "x": -1,
      "y": 11,
      "z": -12,
      "name": "Rock_Aqua"
    },
    {
      "x": -1,
      "y": 12,
      "z": -12,
      "name": "Rock_Aqua"
    },
    {
      "x": -1,
      "y": 13,
      "z": -12,
      "name": "Rock_Aqua"
    },
    {
      "x": -1,
      "y": 14,
      "z": -12,
      "name": "Rock_Aqua"
    },
    {
      "x": -1,
      "y": 15,
      "z": -12,
      "name": "Rock_Aqua"
    },
    {
      "x": -1,
      "y": 16,
      "z": -12,
      "name": "Rock_Aqua"
    },
    {
      "x": -1,
      "y": 17,
      "z": -12,
      "name": "Rock_Aqua"
    },
    {
      "x": -1,
      "y": 18,
      "z": -12,
      "name": "Rock_Aqua"
    },
    {
      "x": -1,
      "y": 19,
      "z": -12,
      "name": "Rock_Aqua"
    },
    {
      "x": -1,
      "y": 20,
      "z": -12,
      "name": "Rock_Aqua"
    },
    {
      "x": -1,
      "y": 21,
      "z": -12,
      "name": "Rock_Aqua"
    },
    {
      "x": -1,
      "y": 22,
      "z": -12,
      "name": "Rock_Aqua"
    },
    {
      "x": -1,
      "y": 23,
      "z": -12,
      "name": "Rock_Aqua"
    },
    {
      "x": -1,
      "y": 24,
      "z": -12,
      "name": "Rock_Aqua"
    },
    {
      "x": -1,
      "y": 25,
      "z": -12,
      "name": "Rock_Aqua"
    },
    {
      "x": -1,
      "y": 0,
      "z": -11,
      "name": "Rock_Aqua"
    },
    {
      "x": -1,
      "y": 1,
      "z": -11,
      "name": "Rock_Aqua"
    },
    {
      "x": -1,
      "y": 2,
      "z": -11,
      "name": "Rock_Aqua"
    },
    {
      "x": -1,
      "y": 3,
      "z": -11,
      "name": "Rock_Aqua"
    },
    {
      "x": -1,
      "y": 4,
      "z": -11,
      "name": "Rock_Aqua"
    },
    {
      "x": -1,
      "y": 5,
      "z": -11,
      "name": "Rock_Aqua"
    },
    {
      "x": -1,
      "y": 6,
      "z": -11,
      "name": "Rock_Aqua"
    },
    {
      "x": -1,
      "y": 7,
      "z": -11,
      "name": "Rock_Aqua"
    },
    {
      "x": -1,
      "y": 8,
      "z": -11,
      "name": "Rock_Aqua"
    },
    {
      "x": -1,
      "y": 9,
      "z": -11,
      "name": "Rock_Aqua"
    },
    {
      "x": -1,
      "y": 10,
      "z": -11,
      "name": "Rock_Aqua"
    },
    {
      "x": -1,
      "y": 11,
      "z": -11,
      "name": "Rock_Aqua"
    },
    {
      "x": -1,
      "y": 12,
      "z": -11,
      "name": "Rock_Aqua"
    },
    {
      "x": -1,
      "y": 13,
      "z": -11,
      "name": "Rock_Aqua"
    },
    {
      "x": -1,
      "y": 14,
      "z": -11,
      "name": "Rock_Aqua"
    },
    {
      "x": -1,
      "y": 15,
      "z": -11,
      "name": "Rock_Aqua"
    },
    {
      "x": -1,
      "y": 16,
      "z": -11,
      "name": "Rock_Aqua"
    },
    {
      "x": -1,
      "y": 17,
      "z": -11,
      "name": "Rock_Aqua_Stairs"
    },
    {
      "x": -1,
      "y": 18,
      "z": -11,
      "name": "Rock_Aqua_Stairs",
      "rotation": 10
    },
    {
      "x": -1,
      "y": 19,
      "z": -11,
      "name": "Rock_Aqua"
    },
    {
      "x": -1,
      "y": 20,
      "z": -11,
      "name": "Rock_Aqua"
    },
    {
      "x": -1,
      "y": 21,
      "z": -11,
      "name": "Rock_Aqua"
    },
    {
      "x": -1,
      "y": 22,
      "z": -11,
      "name": "Rock_Aqua"
    },
    {
      "x": -1,
      "y": 23,
      "z": -11,
      "name": "Rock_Aqua"
    },
    {
      "x": -1,
      "y": 24,
      "z": -11,
      "name": "Rock_Aqua"
    },
    {
      "x": -1,
      "y": 25,
      "z": -11,
      "name": "Rock_Aqua"
    },
    {
      "x": -1,
      "y": 19,
      "z": -10,
      "name": "Rock_Aqua_Half",
      "rotation": 4
    },
    {
      "x": -1,
      "y": 20,
      "z": -10,
      "name": "Rock_Aqua_Half",
      "rotation": 4
    },
    {
      "x": -1,
      "y": 21,
      "z": -10,
      "name": "Rock_Aqua"
    },
    {
      "x": -1,
      "y": 22,
      "z": -10,
      "name": "Rock_Aqua"
    },
    {
      "x": -1,
      "y": 23,
      "z": -10,
      "name": "Rock_Aqua"
    },
    {
      "x": -1,
      "y": 24,
      "z": -10,
      "name": "Rock_Aqua"
    },
    {
      "x": -1,
      "y": 25,
      "z": -10,
      "name": "Rock_Aqua"
    },
    {
      "x": -1,
      "y": 22,
      "z": -9,
      "name": "Rock_Aqua_Half",
      "rotation": 4
    },
    {
      "x": -1,
      "y": 23,
      "z": -9,
      "name": "Rock_Aqua"
    },
    {
      "x": -1,
      "y": 24,
      "z": -9,
      "name": "Rock_Aqua"
    },
    {
      "x": -1,
      "y": 25,
      "z": -9,
      "name": "Rock_Aqua"
    },
    {
      "x": -1,
      "y": 26,
      "z": -9,
      "name": "Rubble_Aqua_Medium",
      "support": 15
    },
    {
      "x": -1,
      "y": 24,
      "z": -8,
      "name": "Rock_Aqua"
    },
    {
      "x": -1,
      "y": 25,
      "z": -8,
      "name": "*Rock_Aqua_Stairs_State_Definitions_Inverted_Corner_Left"
    },
    {
      "x": -1,
      "y": 24,
      "z": -7,
      "name": "Rock_Aqua_Half",
      "rotation": 8
    },
    {
      "x": -1,
      "y": 25,
      "z": -7,
      "name": "Rock_Aqua_Stairs",
      "rotation": 1
    },
    {
      "x": -1,
      "y": 24,
      "z": -6,
      "name": "Rock_Aqua_Half",
      "rotation": 8
    },
    {
      "x": -1,
      "y": 25,
      "z": -6,
      "name": "Rock_Aqua"
    },
    {
      "x": -1,
      "y": 24,
      "z": -5,
      "name": "Rock_Aqua_Half",
      "rotation": 8
    },
    {
      "x": -1,
      "y": 25,
      "z": -5,
      "name": "Rock_Aqua_Stairs",
      "rotation": 3
    },
    {
      "x": -1,
      "y": 24,
      "z": -4,
      "name": "Rock_Aqua"
    },
    {
      "x": -1,
      "y": 25,
      "z": -4,
      "name": "Rock_Aqua"
    },
    {
      "x": -1,
      "y": 22,
      "z": -3,
      "name": "Rock_Aqua_Half",
      "rotation": 6
    },
    {
      "x": -1,
      "y": 23,
      "z": -3,
      "name": "Rock_Aqua"
    },
    {
      "x": -1,
      "y": 24,
      "z": -3,
      "name": "Rock_Aqua"
    },
    {
      "x": -1,
      "y": 25,
      "z": -3,
      "name": "Rock_Aqua"
    },
    {
      "x": -1,
      "y": 19,
      "z": -2,
      "name": "Rock_Aqua_Half",
      "rotation": 6
    },
    {
      "x": -1,
      "y": 20,
      "z": -2,
      "name": "Rock_Aqua_Half",
      "rotation": 6
    },
    {
      "x": -1,
      "y": 21,
      "z": -2,
      "name": "Rock_Aqua"
    },
    {
      "x": -1,
      "y": 22,
      "z": -2,
      "name": "Rock_Aqua"
    },
    {
      "x": -1,
      "y": 23,
      "z": -2,
      "name": "Rock_Aqua"
    },
    {
      "x": -1,
      "y": 24,
      "z": -2,
      "name": "Rock_Aqua"
    },
    {
      "x": -1,
      "y": 25,
      "z": -2,
      "name": "Rock_Aqua"
    },
    {
      "x": -1,
      "y": 0,
      "z": -1,
      "name": "Rock_Aqua"
    },
    {
      "x": -1,
      "y": 1,
      "z": -1,
      "name": "Rock_Aqua"
    },
    {
      "x": -1,
      "y": 2,
      "z": -1,
      "name": "Rock_Aqua"
    },
    {
      "x": -1,
      "y": 3,
      "z": -1,
      "name": "Rock_Aqua"
    },
    {
      "x": -1,
      "y": 4,
      "z": -1,
      "name": "Rock_Aqua"
    },
    {
      "x": -1,
      "y": 5,
      "z": -1,
      "name": "Rock_Aqua"
    },
    {
      "x": -1,
      "y": 6,
      "z": -1,
      "name": "Rock_Aqua"
    },
    {
      "x": -1,
      "y": 7,
      "z": -1,
      "name": "Rock_Aqua"
    },
    {
      "x": -1,
      "y": 8,
      "z": -1,
      "name": "Rock_Aqua"
    },
    {
      "x": -1,
      "y": 9,
      "z": -1,
      "name": "Rock_Aqua"
    },
    {
      "x": -1,
      "y": 10,
      "z": -1,
      "name": "Rock_Aqua"
    },
    {
      "x": -1,
      "y": 11,
      "z": -1,
      "name": "Rock_Aqua"
    },
    {
      "x": -1,
      "y": 12,
      "z": -1,
      "name": "Rock_Aqua"
    },
    {
      "x": -1,
      "y": 13,
      "z": -1,
      "name": "Rock_Aqua"
    },
    {
      "x": -1,
      "y": 14,
      "z": -1,
      "name": "Rock_Aqua"
    },
    {
      "x": -1,
      "y": 15,
      "z": -1,
      "name": "Rock_Aqua"
    },
    {
      "x": -1,
      "y": 16,
      "z": -1,
      "name": "Rock_Aqua"
    },
    {
      "x": -1,
      "y": 17,
      "z": -1,
      "name": "Rock_Aqua"
    },
    {
      "x": -1,
      "y": 18,
      "z": -1,
      "name": "Rock_Aqua"
    },
    {
      "x": -1,
      "y": 19,
      "z": -1,
      "name": "Rock_Aqua"
    },
    {
      "x": -1,
      "y": 20,
      "z": -1,
      "name": "Rock_Aqua"
    },
    {
      "x": -1,
      "y": 21,
      "z": -1,
      "name": "Rock_Aqua"
    },
    {
      "x": -1,
      "y": 22,
      "z": -1,
      "name": "Rock_Aqua"
    },
    {
      "x": -1,
      "y": 23,
      "z": -1,
      "name": "Rock_Aqua"
    },
    {
      "x": -1,
      "y": 24,
      "z": -1,
      "name": "Rock_Aqua"
    },
    {
      "x": -1,
      "y": 25,
      "z": -1,
      "name": "Rock_Aqua"
    },
    {
      "x": -1,
      "y": 0,
      "z": 0,
      "name": "Rock_Aqua"
    },
    {
      "x": -1,
      "y": 1,
      "z": 0,
      "name": "Rock_Aqua"
    },
    {
      "x": -1,
      "y": 2,
      "z": 0,
      "name": "Rock_Aqua"
    },
    {
      "x": -1,
      "y": 3,
      "z": 0,
      "name": "Rock_Aqua"
    },
    {
      "x": -1,
      "y": 4,
      "z": 0,
      "name": "Rock_Aqua"
    },
    {
      "x": -1,
      "y": 5,
      "z": 0,
      "name": "Rock_Aqua"
    },
    {
      "x": -1,
      "y": 6,
      "z": 0,
      "name": "Rock_Aqua"
    },
    {
      "x": -1,
      "y": 7,
      "z": 0,
      "name": "Rock_Aqua"
    },
    {
      "x": -1,
      "y": 8,
      "z": 0,
      "name": "Rock_Aqua"
    },
    {
      "x": -1,
      "y": 9,
      "z": 0,
      "name": "Rock_Aqua"
    },
    {
      "x": -1,
      "y": 10,
      "z": 0,
      "name": "Rock_Aqua"
    },
    {
      "x": -1,
      "y": 11,
      "z": 0,
      "name": "Rock_Aqua"
    },
    {
      "x": -1,
      "y": 12,
      "z": 0,
      "name": "Rock_Aqua"
    },
    {
      "x": -1,
      "y": 13,
      "z": 0,
      "name": "Rock_Aqua"
    },
    {
      "x": -1,
      "y": 14,
      "z": 0,
      "name": "Rock_Aqua"
    },
    {
      "x": -1,
      "y": 15,
      "z": 0,
      "name": "Rock_Aqua"
    },
    {
      "x": -1,
      "y": 16,
      "z": 0,
      "name": "Rock_Aqua"
    },
    {
      "x": -1,
      "y": 17,
      "z": 0,
      "name": "Rock_Aqua"
    },
    {
      "x": -1,
      "y": 18,
      "z": 0,
      "name": "Rock_Aqua"
    },
    {
      "x": -1,
      "y": 19,
      "z": 0,
      "name": "Rock_Aqua"
    },
    {
      "x": -1,
      "y": 20,
      "z": 0,
      "name": "Rock_Aqua"
    },
    {
      "x": -1,
      "y": 21,
      "z": 0,
      "name": "Rock_Aqua"
    },
    {
      "x": -1,
      "y": 22,
      "z": 0,
      "name": "Rock_Aqua"
    },
    {
      "x": -1,
      "y": 23,
      "z": 0,
      "name": "Rock_Aqua"
    },
    {
      "x": -1,
      "y": 24,
      "z": 0,
      "name": "Rock_Aqua"
    },
    {
      "x": -1,
      "y": 25,
      "z": 0,
      "name": "Rock_Aqua"
    },
    {
      "x": -1,
      "y": 26,
      "z": 0,
      "name": "Rubble_Aqua",
      "support": 15
    },
    {
      "x": -1,
      "y": 0,
      "z": 1,
      "name": "Rock_Aqua"
    },
    {
      "x": -1,
      "y": 1,
      "z": 1,
      "name": "Rock_Aqua"
    },
    {
      "x": -1,
      "y": 2,
      "z": 1,
      "name": "Rock_Aqua"
    },
    {
      "x": -1,
      "y": 3,
      "z": 1,
      "name": "Rock_Aqua"
    },
    {
      "x": -1,
      "y": 4,
      "z": 1,
      "name": "Rock_Aqua"
    },
    {
      "x": -1,
      "y": 5,
      "z": 1,
      "name": "Rock_Aqua"
    },
    {
      "x": -1,
      "y": 6,
      "z": 1,
      "name": "Rock_Aqua"
    },
    {
      "x": -1,
      "y": 7,
      "z": 1,
      "name": "Rock_Aqua"
    },
    {
      "x": -1,
      "y": 8,
      "z": 1,
      "name": "Rock_Aqua"
    },
    {
      "x": -1,
      "y": 9,
      "z": 1,
      "name": "Rock_Aqua"
    },
    {
      "x": -1,
      "y": 10,
      "z": 1,
      "name": "Rock_Aqua"
    },
    {
      "x": -1,
      "y": 11,
      "z": 1,
      "name": "Rock_Aqua"
    },
    {
      "x": -1,
      "y": 12,
      "z": 1,
      "name": "Rock_Aqua"
    },
    {
      "x": -1,
      "y": 13,
      "z": 1,
      "name": "Rock_Aqua"
    },
    {
      "x": -1,
      "y": 14,
      "z": 1,
      "name": "Rock_Aqua"
    },
    {
      "x": -1,
      "y": 15,
      "z": 1,
      "name": "Rock_Aqua"
    },
    {
      "x": -1,
      "y": 16,
      "z": 1,
      "name": "Rock_Aqua"
    },
    {
      "x": -1,
      "y": 17,
      "z": 1,
      "name": "Rock_Aqua"
    },
    {
      "x": -1,
      "y": 18,
      "z": 1,
      "name": "Rock_Aqua"
    },
    {
      "x": -1,
      "y": 19,
      "z": 1,
      "name": "Rock_Aqua"
    },
    {
      "x": -1,
      "y": 20,
      "z": 1,
      "name": "Rock_Aqua"
    },
    {
      "x": -1,
      "y": 21,
      "z": 1,
      "name": "Rock_Aqua"
    },
    {
      "x": -1,
      "y": 22,
      "z": 1,
      "name": "Rock_Aqua"
    },
    {
      "x": -1,
      "y": 23,
      "z": 1,
      "name": "Rock_Aqua"
    },
    {
      "x": -1,
      "y": 24,
      "z": 1,
      "name": "Rock_Aqua"
    },
    {
      "x": -1,
      "y": 25,
      "z": 1,
      "name": "Rock_Aqua"
    },
    {
      "x": -1,
      "y": 19,
      "z": 2,
      "name": "Rock_Aqua_Half",
      "rotation": 4
    },
    {
      "x": -1,
      "y": 20,
      "z": 2,
      "name": "Rock_Aqua_Stairs",
      "rotation": 10
    },
    {
      "x": -1,
      "y": 21,
      "z": 2,
      "name": "Rock_Aqua"
    },
    {
      "x": -1,
      "y": 22,
      "z": 2,
      "name": "Rock_Aqua"
    },
    {
      "x": -1,
      "y": 23,
      "z": 2,
      "name": "Rock_Aqua"
    },
    {
      "x": -1,
      "y": 24,
      "z": 2,
      "name": "Rock_Aqua"
    },
    {
      "x": -1,
      "y": 25,
      "z": 2,
      "name": "Rock_Aqua_Stairs",
      "rotation": 3
    },
    {
      "x": -1,
      "y": 22,
      "z": 3,
      "name": "Rock_Aqua_Half",
      "rotation": 4
    },
    {
      "x": -1,
      "y": 23,
      "z": 3,
      "name": "Rock_Aqua"
    },
    {
      "x": -1,
      "y": 24,
      "z": 3,
      "name": "Rock_Aqua"
    },
    {
      "x": -1,
      "y": 25,
      "z": 3,
      "name": "Rock_Aqua_Stairs",
      "rotation": 3
    },
    {
      "x": -1,
      "y": 24,
      "z": 4,
      "name": "Rock_Aqua"
    },
    {
      "x": -1,
      "y": 25,
      "z": 4,
      "name": "*Rock_Aqua_Stairs_State_Definitions_Corner_Right"
    },
    {
      "x": -1,
      "y": 24,
      "z": 6,
      "name": "Rock_Aqua_Half",
      "rotation": 8
    },
    {
      "x": -1,
      "y": 25,
      "z": 6,
      "name": "Rock_Aqua_Stairs",
      "rotation": 2
    },
    {
      "x": -1,
      "y": 24,
      "z": 7,
      "name": "Rock_Aqua_Half",
      "rotation": 8
    },
    {
      "x": -1,
      "y": 25,
      "z": 7,
      "name": "Rock_Aqua"
    },
    {
      "x": -1,
      "y": 26,
      "z": 7,
      "name": "Rubble_Aqua_Medium",
      "support": 15
    },
    {
      "x": -1,
      "y": 24,
      "z": 8,
      "name": "Rock_Aqua"
    },
    {
      "x": -1,
      "y": 25,
      "z": 8,
      "name": "Rock_Aqua"
    },
    {
      "x": -1,
      "y": 26,
      "z": 8,
      "name": "Rock_Aqua_Stalactite_Small"
    },
    {
      "x": -1,
      "y": 22,
      "z": 9,
      "name": "Rock_Aqua_Half",
      "rotation": 6
    },
    {
      "x": -1,
      "y": 23,
      "z": 9,
      "name": "Rock_Aqua_Stairs",
      "rotation": 8
    },
    {
      "x": -1,
      "y": 24,
      "z": 9,
      "name": "Rock_Aqua"
    },
    {
      "x": -1,
      "y": 25,
      "z": 9,
      "name": "Rock_Aqua"
    },
    {
      "x": -1,
      "y": 26,
      "z": 9,
      "name": "Rubble_Aqua_Medium",
      "support": 15
    },
    {
      "x": -1,
      "y": 19,
      "z": 10,
      "name": "Rock_Aqua_Half",
      "rotation": 6
    },
    {
      "x": -1,
      "y": 20,
      "z": 10,
      "name": "Rock_Aqua_Half",
      "rotation": 6
    },
    {
      "x": -1,
      "y": 21,
      "z": 10,
      "name": "Rock_Aqua"
    },
    {
      "x": -1,
      "y": 22,
      "z": 10,
      "name": "Rock_Aqua"
    },
    {
      "x": -1,
      "y": 23,
      "z": 10,
      "name": "Rock_Aqua"
    },
    {
      "x": -1,
      "y": 24,
      "z": 10,
      "name": "Rock_Aqua"
    },
    {
      "x": -1,
      "y": 25,
      "z": 10,
      "name": "Rock_Aqua"
    },
    {
      "x": -1,
      "y": 0,
      "z": 11,
      "name": "Rock_Aqua"
    },
    {
      "x": -1,
      "y": 1,
      "z": 11,
      "name": "Rock_Aqua"
    },
    {
      "x": -1,
      "y": 2,
      "z": 11,
      "name": "Rock_Aqua"
    },
    {
      "x": -1,
      "y": 3,
      "z": 11,
      "name": "Rock_Aqua"
    },
    {
      "x": -1,
      "y": 4,
      "z": 11,
      "name": "Rock_Aqua"
    },
    {
      "x": -1,
      "y": 5,
      "z": 11,
      "name": "Rock_Aqua"
    },
    {
      "x": -1,
      "y": 6,
      "z": 11,
      "name": "Rock_Aqua"
    },
    {
      "x": -1,
      "y": 7,
      "z": 11,
      "name": "Rock_Aqua"
    },
    {
      "x": -1,
      "y": 8,
      "z": 11,
      "name": "Rock_Aqua"
    },
    {
      "x": -1,
      "y": 9,
      "z": 11,
      "name": "Rock_Aqua"
    },
    {
      "x": -1,
      "y": 10,
      "z": 11,
      "name": "Rock_Aqua"
    },
    {
      "x": -1,
      "y": 11,
      "z": 11,
      "name": "Rock_Aqua"
    },
    {
      "x": -1,
      "y": 12,
      "z": 11,
      "name": "Rock_Aqua"
    },
    {
      "x": -1,
      "y": 13,
      "z": 11,
      "name": "Rock_Aqua"
    },
    {
      "x": -1,
      "y": 14,
      "z": 11,
      "name": "Rock_Aqua"
    },
    {
      "x": -1,
      "y": 15,
      "z": 11,
      "name": "Rock_Aqua"
    },
    {
      "x": -1,
      "y": 16,
      "z": 11,
      "name": "Rock_Aqua"
    },
    {
      "x": -1,
      "y": 17,
      "z": 11,
      "name": "Rock_Aqua"
    },
    {
      "x": -1,
      "y": 18,
      "z": 11,
      "name": "Rock_Aqua"
    },
    {
      "x": -1,
      "y": 19,
      "z": 11,
      "name": "Rock_Aqua"
    },
    {
      "x": -1,
      "y": 20,
      "z": 11,
      "name": "Rock_Aqua"
    },
    {
      "x": -1,
      "y": 21,
      "z": 11,
      "name": "Rock_Aqua"
    },
    {
      "x": -1,
      "y": 22,
      "z": 11,
      "name": "Rock_Aqua"
    },
    {
      "x": -1,
      "y": 23,
      "z": 11,
      "name": "Rock_Aqua"
    },
    {
      "x": -1,
      "y": 24,
      "z": 11,
      "name": "Rock_Aqua"
    },
    {
      "x": -1,
      "y": 25,
      "z": 11,
      "name": "Rock_Aqua"
    },
    {
      "x": -1,
      "y": 0,
      "z": 12,
      "name": "Rock_Aqua"
    },
    {
      "x": -1,
      "y": 1,
      "z": 12,
      "name": "Rock_Aqua"
    },
    {
      "x": -1,
      "y": 2,
      "z": 12,
      "name": "Rock_Aqua"
    },
    {
      "x": -1,
      "y": 3,
      "z": 12,
      "name": "Rock_Aqua"
    },
    {
      "x": -1,
      "y": 4,
      "z": 12,
      "name": "Rock_Aqua"
    },
    {
      "x": -1,
      "y": 5,
      "z": 12,
      "name": "Rock_Aqua"
    },
    {
      "x": -1,
      "y": 6,
      "z": 12,
      "name": "Rock_Aqua"
    },
    {
      "x": -1,
      "y": 7,
      "z": 12,
      "name": "Rock_Aqua"
    },
    {
      "x": -1,
      "y": 8,
      "z": 12,
      "name": "Rock_Aqua"
    },
    {
      "x": -1,
      "y": 9,
      "z": 12,
      "name": "Rock_Aqua"
    },
    {
      "x": -1,
      "y": 10,
      "z": 12,
      "name": "Rock_Aqua"
    },
    {
      "x": -1,
      "y": 11,
      "z": 12,
      "name": "Rock_Aqua"
    },
    {
      "x": -1,
      "y": 12,
      "z": 12,
      "name": "Rock_Aqua"
    },
    {
      "x": -1,
      "y": 13,
      "z": 12,
      "name": "Rock_Aqua"
    },
    {
      "x": -1,
      "y": 14,
      "z": 12,
      "name": "Rock_Aqua"
    },
    {
      "x": -1,
      "y": 15,
      "z": 12,
      "name": "Rock_Aqua"
    },
    {
      "x": -1,
      "y": 16,
      "z": 12,
      "name": "Rock_Aqua"
    },
    {
      "x": -1,
      "y": 17,
      "z": 12,
      "name": "Rock_Aqua"
    },
    {
      "x": -1,
      "y": 18,
      "z": 12,
      "name": "Rock_Aqua"
    },
    {
      "x": -1,
      "y": 19,
      "z": 12,
      "name": "Rock_Aqua"
    },
    {
      "x": -1,
      "y": 20,
      "z": 12,
      "name": "Rock_Aqua"
    },
    {
      "x": -1,
      "y": 21,
      "z": 12,
      "name": "Rock_Aqua"
    },
    {
      "x": -1,
      "y": 22,
      "z": 12,
      "name": "Rock_Aqua"
    },
    {
      "x": -1,
      "y": 23,
      "z": 12,
      "name": "Rock_Aqua"
    },
    {
      "x": -1,
      "y": 24,
      "z": 12,
      "name": "Rock_Aqua"
    },
    {
      "x": -1,
      "y": 25,
      "z": 12,
      "name": "Rock_Aqua_Stairs"
    },
    {
      "x": 0,
      "y": 0,
      "z": -12,
      "name": "Rock_Aqua"
    },
    {
      "x": 0,
      "y": 1,
      "z": -12,
      "name": "Rock_Aqua"
    },
    {
      "x": 0,
      "y": 2,
      "z": -12,
      "name": "Rock_Aqua"
    },
    {
      "x": 0,
      "y": 3,
      "z": -12,
      "name": "Rock_Aqua"
    },
    {
      "x": 0,
      "y": 4,
      "z": -12,
      "name": "Rock_Aqua"
    },
    {
      "x": 0,
      "y": 5,
      "z": -12,
      "name": "Rock_Aqua"
    },
    {
      "x": 0,
      "y": 6,
      "z": -12,
      "name": "Rock_Aqua"
    },
    {
      "x": 0,
      "y": 7,
      "z": -12,
      "name": "Rock_Aqua"
    },
    {
      "x": 0,
      "y": 8,
      "z": -12,
      "name": "Rock_Aqua"
    },
    {
      "x": 0,
      "y": 9,
      "z": -12,
      "name": "Rock_Aqua"
    },
    {
      "x": 0,
      "y": 10,
      "z": -12,
      "name": "Rock_Aqua"
    },
    {
      "x": 0,
      "y": 11,
      "z": -12,
      "name": "Rock_Aqua"
    },
    {
      "x": 0,
      "y": 12,
      "z": -12,
      "name": "Rock_Aqua"
    },
    {
      "x": 0,
      "y": 13,
      "z": -12,
      "name": "Rock_Aqua"
    },
    {
      "x": 0,
      "y": 14,
      "z": -12,
      "name": "Rock_Aqua"
    },
    {
      "x": 0,
      "y": 15,
      "z": -12,
      "name": "Rock_Aqua"
    },
    {
      "x": 0,
      "y": 16,
      "z": -12,
      "name": "Rock_Aqua"
    },
    {
      "x": 0,
      "y": 17,
      "z": -12,
      "name": "Rock_Aqua"
    },
    {
      "x": 0,
      "y": 18,
      "z": -12,
      "name": "Rock_Aqua"
    },
    {
      "x": 0,
      "y": 19,
      "z": -12,
      "name": "Rock_Aqua"
    },
    {
      "x": 0,
      "y": 20,
      "z": -12,
      "name": "Rock_Aqua"
    },
    {
      "x": 0,
      "y": 21,
      "z": -12,
      "name": "Rock_Aqua"
    },
    {
      "x": 0,
      "y": 22,
      "z": -12,
      "name": "Rock_Aqua"
    },
    {
      "x": 0,
      "y": 23,
      "z": -12,
      "name": "Rock_Aqua"
    },
    {
      "x": 0,
      "y": 24,
      "z": -12,
      "name": "Rock_Aqua"
    },
    {
      "x": 0,
      "y": 25,
      "z": -12,
      "name": "Rock_Aqua_Brick_Smooth"
    },
    {
      "x": 0,
      "y": 0,
      "z": -11,
      "name": "Rock_Aqua"
    },
    {
      "x": 0,
      "y": 1,
      "z": -11,
      "name": "Rock_Aqua"
    },
    {
      "x": 0,
      "y": 2,
      "z": -11,
      "name": "Rock_Aqua"
    },
    {
      "x": 0,
      "y": 3,
      "z": -11,
      "name": "Rock_Aqua"
    },
    {
      "x": 0,
      "y": 4,
      "z": -11,
      "name": "Rock_Aqua"
    },
    {
      "x": 0,
      "y": 5,
      "z": -11,
      "name": "Rock_Aqua"
    },
    {
      "x": 0,
      "y": 6,
      "z": -11,
      "name": "Rock_Aqua"
    },
    {
      "x": 0,
      "y": 7,
      "z": -11,
      "name": "Rock_Aqua"
    },
    {
      "x": 0,
      "y": 8,
      "z": -11,
      "name": "Rock_Aqua"
    },
    {
      "x": 0,
      "y": 9,
      "z": -11,
      "name": "Rock_Aqua"
    },
    {
      "x": 0,
      "y": 10,
      "z": -11,
      "name": "Rock_Aqua"
    },
    {
      "x": 0,
      "y": 11,
      "z": -11,
      "name": "Rock_Aqua"
    },
    {
      "x": 0,
      "y": 12,
      "z": -11,
      "name": "Rock_Aqua"
    },
    {
      "x": 0,
      "y": 13,
      "z": -11,
      "name": "Rock_Aqua"
    },
    {
      "x": 0,
      "y": 14,
      "z": -11,
      "name": "Rock_Aqua"
    },
    {
      "x": 0,
      "y": 15,
      "z": -11,
      "name": "Rock_Aqua"
    },
    {
      "x": 0,
      "y": 16,
      "z": -11,
      "name": "Rock_Aqua"
    },
    {
      "x": 0,
      "y": 17,
      "z": -11,
      "name": "Rock_Aqua"
    },
    {
      "x": 0,
      "y": 18,
      "z": -11,
      "name": "Rock_Aqua"
    },
    {
      "x": 0,
      "y": 19,
      "z": -11,
      "name": "Rock_Aqua"
    },
    {
      "x": 0,
      "y": 20,
      "z": -11,
      "name": "Rock_Aqua"
    },
    {
      "x": 0,
      "y": 21,
      "z": -11,
      "name": "Rock_Aqua"
    },
    {
      "x": 0,
      "y": 22,
      "z": -11,
      "name": "Rock_Aqua"
    },
    {
      "x": 0,
      "y": 23,
      "z": -11,
      "name": "Rock_Aqua"
    },
    {
      "x": 0,
      "y": 24,
      "z": -11,
      "name": "Rock_Aqua"
    },
    {
      "x": 0,
      "y": 25,
      "z": -11,
      "name": "Rock_Aqua_Brick_Ornate"
    },
    {
      "x": 0,
      "y": 19,
      "z": -10,
      "name": "Rock_Aqua_Half",
      "rotation": 4
    },
    {
      "x": 0,
      "y": 20,
      "z": -10,
      "name": "Rock_Aqua_Half",
      "rotation": 4
    },
    {
      "x": 0,
      "y": 21,
      "z": -10,
      "name": "Rock_Aqua"
    },
    {
      "x": 0,
      "y": 22,
      "z": -10,
      "name": "Rock_Aqua"
    },
    {
      "x": 0,
      "y": 23,
      "z": -10,
      "name": "Rock_Aqua"
    },
    {
      "x": 0,
      "y": 24,
      "z": -10,
      "name": "Rock_Aqua"
    },
    {
      "x": 0,
      "y": 25,
      "z": -10,
      "name": "Rock_Aqua_Brick_Smooth"
    },
    {
      "x": 0,
      "y": 22,
      "z": -9,
      "name": "Rock_Aqua_Half",
      "rotation": 4
    },
    {
      "x": 0,
      "y": 23,
      "z": -9,
      "name": "Rock_Aqua"
    },
    {
      "x": 0,
      "y": 24,
      "z": -9,
      "name": "Rock_Aqua"
    },
    {
      "x": 0,
      "y": 25,
      "z": -9,
      "name": "Rock_Aqua_Brick_Smooth"
    },
    {
      "x": 0,
      "y": 24,
      "z": -8,
      "name": "Rock_Aqua"
    },
    {
      "x": 0,
      "y": 25,
      "z": -8,
      "name": "Rock_Aqua_Brick_Ornate"
    },
    {
      "x": 0,
      "y": 24,
      "z": -7,
      "name": "Rock_Aqua_Half",
      "rotation": 8
    },
    {
      "x": 0,
      "y": 25,
      "z": -7,
      "name": "Rock_Aqua_Brick_Smooth"
    },
    {
      "x": 0,
      "y": 24,
      "z": -6,
      "name": "Rock_Aqua_Half",
      "rotation": 8
    },
    {
      "x": 0,
      "y": 25,
      "z": -6,
      "name": "Rock_Aqua_Brick_Smooth"
    },
    {
      "x": 0,
      "y": 24,
      "z": -5,
      "name": "Rock_Aqua_Half",
      "rotation": 8
    },
    {
      "x": 0,
      "y": 25,
      "z": -5,
      "name": "Rock_Aqua_Brick_Ornate"
    },
    {
      "x": 0,
      "y": 24,
      "z": -4,
      "name": "Rock_Aqua"
    },
    {
      "x": 0,
      "y": 25,
      "z": -4,
      "name": "Rock_Aqua_Brick_Smooth"
    },
    {
      "x": 0,
      "y": 22,
      "z": -3,
      "name": "Rock_Aqua_Half",
      "rotation": 6
    },
    {
      "x": 0,
      "y": 23,
      "z": -3,
      "name": "Rock_Aqua"
    },
    {
      "x": 0,
      "y": 24,
      "z": -3,
      "name": "Rock_Aqua"
    },
    {
      "x": 0,
      "y": 25,
      "z": -3,
      "name": "Rock_Aqua_Brick_Smooth"
    },
    {
      "x": 0,
      "y": 19,
      "z": -2,
      "name": "Rock_Aqua_Half",
      "rotation": 6
    },
    {
      "x": 0,
      "y": 20,
      "z": -2,
      "name": "Rock_Aqua_Half",
      "rotation": 6
    },
    {
      "x": 0,
      "y": 21,
      "z": -2,
      "name": "Rock_Aqua"
    },
    {
      "x": 0,
      "y": 22,
      "z": -2,
      "name": "Rock_Aqua"
    },
    {
      "x": 0,
      "y": 23,
      "z": -2,
      "name": "Rock_Aqua"
    },
    {
      "x": 0,
      "y": 24,
      "z": -2,
      "name": "Rock_Aqua"
    },
    {
      "x": 0,
      "y": 25,
      "z": -2,
      "name": "Rock_Aqua_Brick_Ornate"
    },
    {
      "x": 0,
      "y": 0,
      "z": -1,
      "name": "Rock_Aqua"
    },
    {
      "x": 0,
      "y": 1,
      "z": -1,
      "name": "Rock_Aqua"
    },
    {
      "x": 0,
      "y": 2,
      "z": -1,
      "name": "Rock_Aqua"
    },
    {
      "x": 0,
      "y": 3,
      "z": -1,
      "name": "Rock_Aqua"
    },
    {
      "x": 0,
      "y": 4,
      "z": -1,
      "name": "Rock_Aqua"
    },
    {
      "x": 0,
      "y": 5,
      "z": -1,
      "name": "Rock_Aqua"
    },
    {
      "x": 0,
      "y": 6,
      "z": -1,
      "name": "Rock_Aqua"
    },
    {
      "x": 0,
      "y": 7,
      "z": -1,
      "name": "Rock_Aqua"
    },
    {
      "x": 0,
      "y": 8,
      "z": -1,
      "name": "Rock_Aqua"
    },
    {
      "x": 0,
      "y": 9,
      "z": -1,
      "name": "Rock_Aqua"
    },
    {
      "x": 0,
      "y": 10,
      "z": -1,
      "name": "Rock_Aqua"
    },
    {
      "x": 0,
      "y": 11,
      "z": -1,
      "name": "Rock_Aqua"
    },
    {
      "x": 0,
      "y": 12,
      "z": -1,
      "name": "Rock_Aqua"
    },
    {
      "x": 0,
      "y": 13,
      "z": -1,
      "name": "Rock_Aqua"
    },
    {
      "x": 0,
      "y": 14,
      "z": -1,
      "name": "Rock_Aqua"
    },
    {
      "x": 0,
      "y": 15,
      "z": -1,
      "name": "Rock_Aqua"
    },
    {
      "x": 0,
      "y": 16,
      "z": -1,
      "name": "Rock_Aqua"
    },
    {
      "x": 0,
      "y": 17,
      "z": -1,
      "name": "Rock_Aqua"
    },
    {
      "x": 0,
      "y": 18,
      "z": -1,
      "name": "Rock_Aqua"
    },
    {
      "x": 0,
      "y": 19,
      "z": -1,
      "name": "Rock_Aqua"
    },
    {
      "x": 0,
      "y": 20,
      "z": -1,
      "name": "Rock_Aqua"
    },
    {
      "x": 0,
      "y": 21,
      "z": -1,
      "name": "Rock_Aqua"
    },
    {
      "x": 0,
      "y": 22,
      "z": -1,
      "name": "Rock_Aqua"
    },
    {
      "x": 0,
      "y": 23,
      "z": -1,
      "name": "Rock_Aqua"
    },
    {
      "x": 0,
      "y": 24,
      "z": -1,
      "name": "Rock_Aqua"
    },
    {
      "x": 0,
      "y": 25,
      "z": -1,
      "name": "Rock_Aqua_Brick_Smooth"
    },
    {
      "x": 0,
      "y": 0,
      "z": 0,
      "name": "Rock_Aqua"
    },
    {
      "x": 0,
      "y": 1,
      "z": 0,
      "name": "Rock_Aqua"
    },
    {
      "x": 0,
      "y": 2,
      "z": 0,
      "name": "Rock_Aqua"
    },
    {
      "x": 0,
      "y": 3,
      "z": 0,
      "name": "Rock_Aqua"
    },
    {
      "x": 0,
      "y": 4,
      "z": 0,
      "name": "Rock_Aqua"
    },
    {
      "x": 0,
      "y": 5,
      "z": 0,
      "name": "Rock_Aqua"
    },
    {
      "x": 0,
      "y": 6,
      "z": 0,
      "name": "Rock_Aqua"
    },
    {
      "x": 0,
      "y": 7,
      "z": 0,
      "name": "Rock_Aqua"
    },
    {
      "x": 0,
      "y": 8,
      "z": 0,
      "name": "Rock_Aqua"
    },
    {
      "x": 0,
      "y": 9,
      "z": 0,
      "name": "Rock_Aqua"
    },
    {
      "x": 0,
      "y": 10,
      "z": 0,
      "name": "Rock_Aqua"
    },
    {
      "x": 0,
      "y": 11,
      "z": 0,
      "name": "Rock_Aqua"
    },
    {
      "x": 0,
      "y": 12,
      "z": 0,
      "name": "Rock_Aqua"
    },
    {
      "x": 0,
      "y": 13,
      "z": 0,
      "name": "Rock_Aqua"
    },
    {
      "x": 0,
      "y": 14,
      "z": 0,
      "name": "Rock_Aqua"
    },
    {
      "x": 0,
      "y": 15,
      "z": 0,
      "name": "Rock_Aqua"
    },
    {
      "x": 0,
      "y": 16,
      "z": 0,
      "name": "Rock_Aqua"
    },
    {
      "x": 0,
      "y": 17,
      "z": 0,
      "name": "Rock_Aqua"
    },
    {
      "x": 0,
      "y": 18,
      "z": 0,
      "name": "Rock_Aqua"
    },
    {
      "x": 0,
      "y": 19,
      "z": 0,
      "name": "Rock_Aqua"
    },
    {
      "x": 0,
      "y": 20,
      "z": 0,
      "name": "Rock_Aqua"
    },
    {
      "x": 0,
      "y": 21,
      "z": 0,
      "name": "Rock_Aqua"
    },
    {
      "x": 0,
      "y": 22,
      "z": 0,
      "name": "Rock_Aqua"
    },
    {
      "x": 0,
      "y": 23,
      "z": 0,
      "name": "Rock_Aqua"
    },
    {
      "x": 0,
      "y": 24,
      "z": 0,
      "name": "Rock_Aqua"
    },
    {
      "x": 0,
      "y": 25,
      "z": 0,
      "name": "Rock_Aqua_Brick_Smooth"
    },
    {
      "x": 0,
      "y": 0,
      "z": 1,
      "name": "Rock_Aqua"
    },
    {
      "x": 0,
      "y": 1,
      "z": 1,
      "name": "Rock_Aqua"
    },
    {
      "x": 0,
      "y": 2,
      "z": 1,
      "name": "Rock_Aqua"
    },
    {
      "x": 0,
      "y": 3,
      "z": 1,
      "name": "Rock_Aqua"
    },
    {
      "x": 0,
      "y": 4,
      "z": 1,
      "name": "Rock_Aqua"
    },
    {
      "x": 0,
      "y": 5,
      "z": 1,
      "name": "Rock_Aqua"
    },
    {
      "x": 0,
      "y": 6,
      "z": 1,
      "name": "Rock_Aqua"
    },
    {
      "x": 0,
      "y": 7,
      "z": 1,
      "name": "Rock_Aqua"
    },
    {
      "x": 0,
      "y": 8,
      "z": 1,
      "name": "Rock_Aqua"
    },
    {
      "x": 0,
      "y": 9,
      "z": 1,
      "name": "Rock_Aqua"
    },
    {
      "x": 0,
      "y": 10,
      "z": 1,
      "name": "Rock_Aqua"
    },
    {
      "x": 0,
      "y": 11,
      "z": 1,
      "name": "Rock_Aqua"
    },
    {
      "x": 0,
      "y": 12,
      "z": 1,
      "name": "Rock_Aqua"
    },
    {
      "x": 0,
      "y": 13,
      "z": 1,
      "name": "Rock_Aqua"
    },
    {
      "x": 0,
      "y": 14,
      "z": 1,
      "name": "Rock_Aqua"
    },
    {
      "x": 0,
      "y": 15,
      "z": 1,
      "name": "Rock_Aqua"
    },
    {
      "x": 0,
      "y": 16,
      "z": 1,
      "name": "Rock_Aqua_Stairs",
      "rotation": 10
    },
    {
      "x": 0,
      "y": 17,
      "z": 1,
      "name": "Rock_Aqua_Stairs"
    },
    {
      "x": 0,
      "y": 18,
      "z": 1,
      "name": "Rock_Aqua"
    },
    {
      "x": 0,
      "y": 19,
      "z": 1,
      "name": "Rock_Aqua"
    },
    {
      "x": 0,
      "y": 20,
      "z": 1,
      "name": "Rock_Aqua"
    },
    {
      "x": 0,
      "y": 21,
      "z": 1,
      "name": "Rock_Aqua"
    },
    {
      "x": 0,
      "y": 22,
      "z": 1,
      "name": "Rock_Aqua"
    },
    {
      "x": 0,
      "y": 23,
      "z": 1,
      "name": "Rock_Aqua"
    },
    {
      "x": 0,
      "y": 24,
      "z": 1,
      "name": "Rock_Aqua"
    },
    {
      "x": 0,
      "y": 25,
      "z": 1,
      "name": "Rock_Aqua_Brick_Ornate"
    },
    {
      "x": 0,
      "y": 19,
      "z": 2,
      "name": "Rock_Aqua_Half",
      "rotation": 4
    },
    {
      "x": 0,
      "y": 20,
      "z": 2,
      "name": "Rock_Aqua_Half",
      "rotation": 4
    },
    {
      "x": 0,
      "y": 21,
      "z": 2,
      "name": "Rock_Aqua_Stairs",
      "rotation": 10
    },
    {
      "x": 0,
      "y": 22,
      "z": 2,
      "name": "Rock_Aqua"
    },
    {
      "x": 0,
      "y": 23,
      "z": 2,
      "name": "Rock_Aqua"
    },
    {
      "x": 0,
      "y": 24,
      "z": 2,
      "name": "Rock_Aqua"
    },
    {
      "x": 0,
      "y": 25,
      "z": 2,
      "name": "Rock_Aqua_Brick_Smooth"
    },
    {
      "x": 0,
      "y": 22,
      "z": 3,
      "name": "Rock_Aqua_Half",
      "rotation": 4
    },
    {
      "x": 0,
      "y": 23,
      "z": 3,
      "name": "Rock_Aqua"
    },
    {
      "x": 0,
      "y": 24,
      "z": 3,
      "name": "Rock_Aqua"
    },
    {
      "x": 0,
      "y": 25,
      "z": 3,
      "name": "Rock_Aqua_Brick_Smooth"
    },
    {
      "x": 0,
      "y": 24,
      "z": 4,
      "name": "Rock_Aqua"
    },
    {
      "x": 0,
      "y": 25,
      "z": 4,
      "name": "Rock_Aqua_Brick_Ornate"
    },
    {
      "x": 0,
      "y": 24,
      "z": 7,
      "name": "Rock_Aqua_Half",
      "rotation": 8
    },
    {
      "x": 0,
      "y": 25,
      "z": 7,
      "name": "Rock_Aqua_Brick_Ornate"
    },
    {
      "x": 0,
      "y": 24,
      "z": 8,
      "name": "Rock_Aqua"
    },
    {
      "x": 0,
      "y": 25,
      "z": 8,
      "name": "Rock_Aqua_Brick_Smooth"
    },
    {
      "x": 0,
      "y": 22,
      "z": 9,
      "name": "Rock_Aqua_Half",
      "rotation": 6
    },
    {
      "x": 0,
      "y": 23,
      "z": 9,
      "name": "Rock_Aqua"
    },
    {
      "x": 0,
      "y": 24,
      "z": 9,
      "name": "Rock_Aqua"
    },
    {
      "x": 0,
      "y": 25,
      "z": 9,
      "name": "Rock_Aqua_Brick_Smooth"
    },
    {
      "x": 0,
      "y": 26,
      "z": 9,
      "name": "Rubble_Aqua",
      "support": 15
    },
    {
      "x": 0,
      "y": 19,
      "z": 10,
      "name": "Rock_Aqua_Half",
      "rotation": 6
    },
    {
      "x": 0,
      "y": 20,
      "z": 10,
      "name": "Rock_Aqua_Half",
      "rotation": 6
    },
    {
      "x": 0,
      "y": 21,
      "z": 10,
      "name": "Rock_Aqua_Stairs",
      "rotation": 8
    },
    {
      "x": 0,
      "y": 22,
      "z": 10,
      "name": "Rock_Aqua"
    },
    {
      "x": 0,
      "y": 23,
      "z": 10,
      "name": "Rock_Aqua"
    },
    {
      "x": 0,
      "y": 24,
      "z": 10,
      "name": "Rock_Aqua"
    },
    {
      "x": 0,
      "y": 25,
      "z": 10,
      "name": "Rock_Aqua_Brick_Ornate"
    },
    {
      "x": 0,
      "y": 0,
      "z": 11,
      "name": "Rock_Aqua"
    },
    {
      "x": 0,
      "y": 1,
      "z": 11,
      "name": "Rock_Aqua"
    },
    {
      "x": 0,
      "y": 2,
      "z": 11,
      "name": "Rock_Aqua"
    },
    {
      "x": 0,
      "y": 3,
      "z": 11,
      "name": "Rock_Aqua"
    },
    {
      "x": 0,
      "y": 4,
      "z": 11,
      "name": "Rock_Aqua"
    },
    {
      "x": 0,
      "y": 5,
      "z": 11,
      "name": "Rock_Aqua"
    },
    {
      "x": 0,
      "y": 6,
      "z": 11,
      "name": "Rock_Aqua"
    },
    {
      "x": 0,
      "y": 7,
      "z": 11,
      "name": "Rock_Aqua"
    },
    {
      "x": 0,
      "y": 8,
      "z": 11,
      "name": "Rock_Aqua"
    },
    {
      "x": 0,
      "y": 9,
      "z": 11,
      "name": "Rock_Aqua"
    },
    {
      "x": 0,
      "y": 10,
      "z": 11,
      "name": "Rock_Aqua"
    },
    {
      "x": 0,
      "y": 11,
      "z": 11,
      "name": "Rock_Aqua"
    },
    {
      "x": 0,
      "y": 12,
      "z": 11,
      "name": "Rock_Aqua"
    },
    {
      "x": 0,
      "y": 13,
      "z": 11,
      "name": "Rock_Aqua"
    },
    {
      "x": 0,
      "y": 14,
      "z": 11,
      "name": "Rock_Aqua"
    },
    {
      "x": 0,
      "y": 15,
      "z": 11,
      "name": "Rock_Aqua"
    },
    {
      "x": 0,
      "y": 16,
      "z": 11,
      "name": "Rock_Aqua"
    },
    {
      "x": 0,
      "y": 17,
      "z": 11,
      "name": "Rock_Aqua"
    },
    {
      "x": 0,
      "y": 18,
      "z": 11,
      "name": "Rock_Aqua"
    },
    {
      "x": 0,
      "y": 19,
      "z": 11,
      "name": "Rock_Aqua"
    },
    {
      "x": 0,
      "y": 20,
      "z": 11,
      "name": "Rock_Aqua"
    },
    {
      "x": 0,
      "y": 21,
      "z": 11,
      "name": "Rock_Aqua"
    },
    {
      "x": 0,
      "y": 22,
      "z": 11,
      "name": "Rock_Aqua"
    },
    {
      "x": 0,
      "y": 23,
      "z": 11,
      "name": "Rock_Aqua"
    },
    {
      "x": 0,
      "y": 24,
      "z": 11,
      "name": "Rock_Aqua"
    },
    {
      "x": 0,
      "y": 25,
      "z": 11,
      "name": "Rock_Aqua_Brick_Smooth"
    },
    {
      "x": 0,
      "y": 0,
      "z": 12,
      "name": "Rock_Aqua"
    },
    {
      "x": 0,
      "y": 1,
      "z": 12,
      "name": "Rock_Aqua"
    },
    {
      "x": 0,
      "y": 2,
      "z": 12,
      "name": "Rock_Aqua"
    },
    {
      "x": 0,
      "y": 3,
      "z": 12,
      "name": "Rock_Aqua"
    },
    {
      "x": 0,
      "y": 4,
      "z": 12,
      "name": "Rock_Aqua"
    },
    {
      "x": 0,
      "y": 5,
      "z": 12,
      "name": "Rock_Aqua"
    },
    {
      "x": 0,
      "y": 6,
      "z": 12,
      "name": "Rock_Aqua"
    },
    {
      "x": 0,
      "y": 7,
      "z": 12,
      "name": "Rock_Aqua"
    },
    {
      "x": 0,
      "y": 8,
      "z": 12,
      "name": "Rock_Aqua"
    },
    {
      "x": 0,
      "y": 9,
      "z": 12,
      "name": "Rock_Aqua"
    },
    {
      "x": 0,
      "y": 10,
      "z": 12,
      "name": "Rock_Aqua"
    },
    {
      "x": 0,
      "y": 11,
      "z": 12,
      "name": "Rock_Aqua"
    },
    {
      "x": 0,
      "y": 12,
      "z": 12,
      "name": "Rock_Aqua"
    },
    {
      "x": 0,
      "y": 13,
      "z": 12,
      "name": "Rock_Aqua"
    },
    {
      "x": 0,
      "y": 14,
      "z": 12,
      "name": "Rock_Aqua"
    },
    {
      "x": 0,
      "y": 15,
      "z": 12,
      "name": "Rock_Aqua"
    },
    {
      "x": 0,
      "y": 16,
      "z": 12,
      "name": "Rock_Aqua"
    },
    {
      "x": 0,
      "y": 17,
      "z": 12,
      "name": "Rock_Aqua"
    },
    {
      "x": 0,
      "y": 18,
      "z": 12,
      "name": "Rock_Aqua"
    },
    {
      "x": 0,
      "y": 19,
      "z": 12,
      "name": "Rock_Aqua"
    },
    {
      "x": 0,
      "y": 20,
      "z": 12,
      "name": "Rock_Aqua"
    },
    {
      "x": 0,
      "y": 21,
      "z": 12,
      "name": "Rock_Aqua"
    },
    {
      "x": 0,
      "y": 22,
      "z": 12,
      "name": "Rock_Aqua"
    },
    {
      "x": 0,
      "y": 23,
      "z": 12,
      "name": "Rock_Aqua"
    },
    {
      "x": 0,
      "y": 24,
      "z": 12,
      "name": "Rock_Aqua"
    },
    {
      "x": 0,
      "y": 25,
      "z": 12,
      "name": "Rock_Aqua_Brick_Smooth"
    },
    {
      "x": 1,
      "y": 0,
      "z": -12,
      "name": "Rock_Aqua"
    },
    {
      "x": 1,
      "y": 1,
      "z": -12,
      "name": "Rock_Aqua"
    },
    {
      "x": 1,
      "y": 2,
      "z": -12,
      "name": "Rock_Aqua"
    },
    {
      "x": 1,
      "y": 3,
      "z": -12,
      "name": "Rock_Aqua"
    },
    {
      "x": 1,
      "y": 4,
      "z": -12,
      "name": "Rock_Aqua"
    },
    {
      "x": 1,
      "y": 5,
      "z": -12,
      "name": "Rock_Aqua"
    },
    {
      "x": 1,
      "y": 6,
      "z": -12,
      "name": "Rock_Aqua"
    },
    {
      "x": 1,
      "y": 7,
      "z": -12,
      "name": "Rock_Aqua"
    },
    {
      "x": 1,
      "y": 8,
      "z": -12,
      "name": "Rock_Aqua"
    },
    {
      "x": 1,
      "y": 9,
      "z": -12,
      "name": "Rock_Aqua"
    },
    {
      "x": 1,
      "y": 10,
      "z": -12,
      "name": "Rock_Aqua"
    },
    {
      "x": 1,
      "y": 11,
      "z": -12,
      "name": "Rock_Aqua"
    },
    {
      "x": 1,
      "y": 12,
      "z": -12,
      "name": "Rock_Aqua"
    },
    {
      "x": 1,
      "y": 13,
      "z": -12,
      "name": "Rock_Aqua"
    },
    {
      "x": 1,
      "y": 14,
      "z": -12,
      "name": "Rock_Aqua"
    },
    {
      "x": 1,
      "y": 15,
      "z": -12,
      "name": "Rock_Aqua"
    },
    {
      "x": 1,
      "y": 16,
      "z": -12,
      "name": "Rock_Aqua"
    },
    {
      "x": 1,
      "y": 17,
      "z": -12,
      "name": "Rock_Aqua"
    },
    {
      "x": 1,
      "y": 18,
      "z": -12,
      "name": "Rock_Aqua"
    },
    {
      "x": 1,
      "y": 19,
      "z": -12,
      "name": "Rock_Aqua"
    },
    {
      "x": 1,
      "y": 20,
      "z": -12,
      "name": "Rock_Aqua"
    },
    {
      "x": 1,
      "y": 21,
      "z": -12,
      "name": "Rock_Aqua"
    },
    {
      "x": 1,
      "y": 22,
      "z": -12,
      "name": "Rock_Aqua"
    },
    {
      "x": 1,
      "y": 23,
      "z": -12,
      "name": "Rock_Aqua"
    },
    {
      "x": 1,
      "y": 24,
      "z": -12,
      "name": "Rock_Aqua"
    },
    {
      "x": 1,
      "y": 25,
      "z": -12,
      "name": "Rock_Aqua"
    },
    {
      "x": 1,
      "y": 0,
      "z": -11,
      "name": "Rock_Aqua"
    },
    {
      "x": 1,
      "y": 1,
      "z": -11,
      "name": "Rock_Aqua"
    },
    {
      "x": 1,
      "y": 2,
      "z": -11,
      "name": "Rock_Aqua"
    },
    {
      "x": 1,
      "y": 3,
      "z": -11,
      "name": "Rock_Aqua"
    },
    {
      "x": 1,
      "y": 4,
      "z": -11,
      "name": "Rock_Aqua"
    },
    {
      "x": 1,
      "y": 5,
      "z": -11,
      "name": "Rock_Aqua"
    },
    {
      "x": 1,
      "y": 6,
      "z": -11,
      "name": "Rock_Aqua"
    },
    {
      "x": 1,
      "y": 7,
      "z": -11,
      "name": "Rock_Aqua"
    },
    {
      "x": 1,
      "y": 8,
      "z": -11,
      "name": "Rock_Aqua"
    },
    {
      "x": 1,
      "y": 9,
      "z": -11,
      "name": "Rock_Aqua"
    },
    {
      "x": 1,
      "y": 10,
      "z": -11,
      "name": "Rock_Aqua"
    },
    {
      "x": 1,
      "y": 11,
      "z": -11,
      "name": "Rock_Aqua"
    },
    {
      "x": 1,
      "y": 12,
      "z": -11,
      "name": "Rock_Aqua"
    },
    {
      "x": 1,
      "y": 13,
      "z": -11,
      "name": "Rock_Aqua"
    },
    {
      "x": 1,
      "y": 14,
      "z": -11,
      "name": "Rock_Aqua"
    },
    {
      "x": 1,
      "y": 15,
      "z": -11,
      "name": "Rock_Aqua"
    },
    {
      "x": 1,
      "y": 16,
      "z": -11,
      "name": "Rock_Aqua"
    },
    {
      "x": 1,
      "y": 17,
      "z": -11,
      "name": "Rock_Aqua"
    },
    {
      "x": 1,
      "y": 18,
      "z": -11,
      "name": "Rock_Aqua"
    },
    {
      "x": 1,
      "y": 19,
      "z": -11,
      "name": "Rock_Aqua"
    },
    {
      "x": 1,
      "y": 20,
      "z": -11,
      "name": "Rock_Aqua"
    },
    {
      "x": 1,
      "y": 21,
      "z": -11,
      "name": "Rock_Aqua"
    },
    {
      "x": 1,
      "y": 22,
      "z": -11,
      "name": "Rock_Aqua"
    },
    {
      "x": 1,
      "y": 23,
      "z": -11,
      "name": "Rock_Aqua"
    },
    {
      "x": 1,
      "y": 24,
      "z": -11,
      "name": "Rock_Aqua"
    },
    {
      "x": 1,
      "y": 25,
      "z": -11,
      "name": "Rock_Aqua"
    },
    {
      "x": 1,
      "y": 19,
      "z": -10,
      "name": "Rock_Aqua_Half",
      "rotation": 4
    },
    {
      "x": 1,
      "y": 20,
      "z": -10,
      "name": "Rock_Aqua_Half",
      "rotation": 4
    },
    {
      "x": 1,
      "y": 21,
      "z": -10,
      "name": "Rock_Aqua_Stairs",
      "rotation": 10
    },
    {
      "x": 1,
      "y": 22,
      "z": -10,
      "name": "Rock_Aqua"
    },
    {
      "x": 1,
      "y": 23,
      "z": -10,
      "name": "Rock_Aqua"
    },
    {
      "x": 1,
      "y": 24,
      "z": -10,
      "name": "Rock_Aqua"
    },
    {
      "x": 1,
      "y": 25,
      "z": -10,
      "name": "Rock_Aqua"
    },
    {
      "x": 1,
      "y": 22,
      "z": -9,
      "name": "Rock_Aqua_Half",
      "rotation": 4
    },
    {
      "x": 1,
      "y": 23,
      "z": -9,
      "name": "Rock_Aqua"
    },
    {
      "x": 1,
      "y": 24,
      "z": -9,
      "name": "Rock_Aqua"
    },
    {
      "x": 1,
      "y": 25,
      "z": -9,
      "name": "Rock_Aqua"
    },
    {
      "x": 1,
      "y": 24,
      "z": -8,
      "name": "Rock_Aqua"
    },
    {
      "x": 1,
      "y": 25,
      "z": -8,
      "name": "Rock_Aqua"
    },
    {
      "x": 1,
      "y": 26,
      "z": -8,
      "name": "Rubble_Aqua",
      "support": 15
    },
    {
      "x": 1,
      "y": 24,
      "z": -7,
      "name": "Rock_Aqua_Half",
      "rotation": 8
    },
    {
      "x": 1,
      "y": 25,
      "z": -7,
      "name": "Rock_Aqua"
    },
    {
      "x": 1,
      "y": 24,
      "z": -6,
      "name": "Rock_Aqua_Half",
      "rotation": 8
    },
    {
      "x": 1,
      "y": 25,
      "z": -6,
      "name": "Rock_Aqua"
    },
    {
      "x": 1,
      "y": 24,
      "z": -5,
      "name": "Rock_Aqua_Half",
      "rotation": 8
    },
    {
      "x": 1,
      "y": 25,
      "z": -5,
      "name": "Rock_Aqua"
    },
    {
      "x": 1,
      "y": 24,
      "z": -4,
      "name": "Rock_Aqua"
    },
    {
      "x": 1,
      "y": 25,
      "z": -4,
      "name": "Rock_Aqua"
    },
    {
      "x": 1,
      "y": 22,
      "z": -3,
      "name": "Rock_Aqua_Stairs",
      "rotation": 8
    },
    {
      "x": 1,
      "y": 23,
      "z": -3,
      "name": "Rock_Aqua"
    },
    {
      "x": 1,
      "y": 24,
      "z": -3,
      "name": "Rock_Aqua"
    },
    {
      "x": 1,
      "y": 25,
      "z": -3,
      "name": "Rock_Aqua_Stairs",
      "rotation": 1
    },
    {
      "x": 1,
      "y": 19,
      "z": -2,
      "name": "Rock_Aqua_Half",
      "rotation": 6
    },
    {
      "x": 1,
      "y": 20,
      "z": -2,
      "name": "Rock_Aqua_Half",
      "rotation": 6
    },
    {
      "x": 1,
      "y": 21,
      "z": -2,
      "name": "Rock_Aqua"
    },
    {
      "x": 1,
      "y": 22,
      "z": -2,
      "name": "Rock_Aqua"
    },
    {
      "x": 1,
      "y": 23,
      "z": -2,
      "name": "Rock_Aqua"
    },
    {
      "x": 1,
      "y": 24,
      "z": -2,
      "name": "Rock_Aqua"
    },
    {
      "x": 1,
      "y": 25,
      "z": -2,
      "name": "Rock_Aqua_Stairs",
      "rotation": 3
    },
    {
      "x": 1,
      "y": 0,
      "z": -1,
      "name": "Rock_Aqua"
    },
    {
      "x": 1,
      "y": 1,
      "z": -1,
      "name": "Rock_Aqua"
    },
    {
      "x": 1,
      "y": 2,
      "z": -1,
      "name": "Rock_Aqua"
    },
    {
      "x": 1,
      "y": 3,
      "z": -1,
      "name": "Rock_Aqua"
    },
    {
      "x": 1,
      "y": 4,
      "z": -1,
      "name": "Rock_Aqua"
    },
    {
      "x": 1,
      "y": 5,
      "z": -1,
      "name": "Rock_Aqua"
    },
    {
      "x": 1,
      "y": 6,
      "z": -1,
      "name": "Rock_Aqua"
    },
    {
      "x": 1,
      "y": 7,
      "z": -1,
      "name": "Rock_Aqua"
    },
    {
      "x": 1,
      "y": 8,
      "z": -1,
      "name": "Rock_Aqua"
    },
    {
      "x": 1,
      "y": 9,
      "z": -1,
      "name": "Rock_Aqua"
    },
    {
      "x": 1,
      "y": 10,
      "z": -1,
      "name": "Rock_Aqua"
    },
    {
      "x": 1,
      "y": 11,
      "z": -1,
      "name": "Rock_Aqua"
    },
    {
      "x": 1,
      "y": 12,
      "z": -1,
      "name": "Rock_Aqua"
    },
    {
      "x": 1,
      "y": 13,
      "z": -1,
      "name": "Rock_Aqua"
    },
    {
      "x": 1,
      "y": 14,
      "z": -1,
      "name": "Rock_Aqua"
    },
    {
      "x": 1,
      "y": 15,
      "z": -1,
      "name": "Rock_Aqua"
    },
    {
      "x": 1,
      "y": 16,
      "z": -1,
      "name": "Rock_Aqua"
    },
    {
      "x": 1,
      "y": 17,
      "z": -1,
      "name": "Rock_Aqua"
    },
    {
      "x": 1,
      "y": 18,
      "z": -1,
      "name": "Rock_Aqua"
    },
    {
      "x": 1,
      "y": 19,
      "z": -1,
      "name": "Rock_Aqua"
    },
    {
      "x": 1,
      "y": 20,
      "z": -1,
      "name": "Rock_Aqua"
    },
    {
      "x": 1,
      "y": 21,
      "z": -1,
      "name": "Rock_Aqua"
    },
    {
      "x": 1,
      "y": 22,
      "z": -1,
      "name": "Rock_Aqua"
    },
    {
      "x": 1,
      "y": 23,
      "z": -1,
      "name": "Rock_Aqua"
    },
    {
      "x": 1,
      "y": 24,
      "z": -1,
      "name": "Rock_Aqua"
    },
    {
      "x": 1,
      "y": 25,
      "z": -1,
      "name": "Rock_Aqua"
    },
    {
      "x": 1,
      "y": 0,
      "z": 0,
      "name": "Rock_Aqua"
    },
    {
      "x": 1,
      "y": 1,
      "z": 0,
      "name": "Rock_Aqua"
    },
    {
      "x": 1,
      "y": 2,
      "z": 0,
      "name": "Rock_Aqua"
    },
    {
      "x": 1,
      "y": 3,
      "z": 0,
      "name": "Rock_Aqua"
    },
    {
      "x": 1,
      "y": 4,
      "z": 0,
      "name": "Rock_Aqua"
    },
    {
      "x": 1,
      "y": 5,
      "z": 0,
      "name": "Rock_Aqua"
    },
    {
      "x": 1,
      "y": 6,
      "z": 0,
      "name": "Rock_Aqua"
    },
    {
      "x": 1,
      "y": 7,
      "z": 0,
      "name": "Rock_Aqua"
    },
    {
      "x": 1,
      "y": 8,
      "z": 0,
      "name": "Rock_Aqua"
    },
    {
      "x": 1,
      "y": 9,
      "z": 0,
      "name": "Rock_Aqua"
    },
    {
      "x": 1,
      "y": 10,
      "z": 0,
      "name": "Rock_Aqua"
    },
    {
      "x": 1,
      "y": 11,
      "z": 0,
      "name": "Rock_Aqua"
    },
    {
      "x": 1,
      "y": 12,
      "z": 0,
      "name": "Rock_Aqua"
    },
    {
      "x": 1,
      "y": 13,
      "z": 0,
      "name": "Rock_Aqua"
    },
    {
      "x": 1,
      "y": 14,
      "z": 0,
      "name": "Rock_Aqua"
    },
    {
      "x": 1,
      "y": 15,
      "z": 0,
      "name": "Rock_Aqua"
    },
    {
      "x": 1,
      "y": 16,
      "z": 0,
      "name": "Rock_Aqua"
    },
    {
      "x": 1,
      "y": 17,
      "z": 0,
      "name": "Rock_Aqua"
    },
    {
      "x": 1,
      "y": 18,
      "z": 0,
      "name": "Rock_Aqua"
    },
    {
      "x": 1,
      "y": 19,
      "z": 0,
      "name": "Rock_Aqua"
    },
    {
      "x": 1,
      "y": 20,
      "z": 0,
      "name": "Rock_Aqua"
    },
    {
      "x": 1,
      "y": 21,
      "z": 0,
      "name": "Rock_Aqua"
    },
    {
      "x": 1,
      "y": 22,
      "z": 0,
      "name": "Rock_Aqua"
    },
    {
      "x": 1,
      "y": 23,
      "z": 0,
      "name": "Rock_Aqua"
    },
    {
      "x": 1,
      "y": 24,
      "z": 0,
      "name": "Rock_Aqua"
    },
    {
      "x": 1,
      "y": 25,
      "z": 0,
      "name": "Rock_Aqua"
    },
    {
      "x": 1,
      "y": 0,
      "z": 1,
      "name": "Rock_Aqua"
    },
    {
      "x": 1,
      "y": 1,
      "z": 1,
      "name": "Rock_Aqua"
    },
    {
      "x": 1,
      "y": 2,
      "z": 1,
      "name": "Rock_Aqua"
    },
    {
      "x": 1,
      "y": 3,
      "z": 1,
      "name": "Rock_Aqua"
    },
    {
      "x": 1,
      "y": 4,
      "z": 1,
      "name": "Rock_Aqua"
    },
    {
      "x": 1,
      "y": 5,
      "z": 1,
      "name": "Rock_Aqua"
    },
    {
      "x": 1,
      "y": 6,
      "z": 1,
      "name": "Rock_Aqua"
    },
    {
      "x": 1,
      "y": 7,
      "z": 1,
      "name": "Rock_Aqua"
    },
    {
      "x": 1,
      "y": 8,
      "z": 1,
      "name": "Rock_Aqua"
    },
    {
      "x": 1,
      "y": 9,
      "z": 1,
      "name": "Rock_Aqua"
    },
    {
      "x": 1,
      "y": 10,
      "z": 1,
      "name": "Rock_Aqua"
    },
    {
      "x": 1,
      "y": 11,
      "z": 1,
      "name": "Rock_Aqua"
    },
    {
      "x": 1,
      "y": 12,
      "z": 1,
      "name": "Rock_Aqua"
    },
    {
      "x": 1,
      "y": 13,
      "z": 1,
      "name": "Rock_Aqua"
    },
    {
      "x": 1,
      "y": 14,
      "z": 1,
      "name": "Rock_Aqua"
    },
    {
      "x": 1,
      "y": 15,
      "z": 1,
      "name": "Rock_Aqua"
    },
    {
      "x": 1,
      "y": 16,
      "z": 1,
      "name": "Rock_Aqua"
    },
    {
      "x": 1,
      "y": 17,
      "z": 1,
      "name": "Rock_Aqua_Stairs"
    },
    {
      "x": 1,
      "y": 18,
      "z": 1,
      "name": "Rock_Aqua"
    },
    {
      "x": 1,
      "y": 19,
      "z": 1,
      "name": "Rock_Aqua"
    },
    {
      "x": 1,
      "y": 20,
      "z": 1,
      "name": "Rock_Aqua"
    },
    {
      "x": 1,
      "y": 21,
      "z": 1,
      "name": "Rock_Aqua"
    },
    {
      "x": 1,
      "y": 22,
      "z": 1,
      "name": "Rock_Aqua"
    },
    {
      "x": 1,
      "y": 23,
      "z": 1,
      "name": "Rock_Aqua"
    },
    {
      "x": 1,
      "y": 24,
      "z": 1,
      "name": "Rock_Aqua"
    },
    {
      "x": 1,
      "y": 25,
      "z": 1,
      "name": "Rock_Aqua"
    },
    {
      "x": 1,
      "y": 19,
      "z": 2,
      "name": "Rock_Aqua_Half",
      "rotation": 4
    },
    {
      "x": 1,
      "y": 20,
      "z": 2,
      "name": "Rock_Aqua_Half",
      "rotation": 4
    },
    {
      "x": 1,
      "y": 21,
      "z": 2,
      "name": "Rock_Aqua"
    },
    {
      "x": 1,
      "y": 22,
      "z": 2,
      "name": "Rock_Aqua"
    },
    {
      "x": 1,
      "y": 23,
      "z": 2,
      "name": "Rock_Aqua"
    },
    {
      "x": 1,
      "y": 24,
      "z": 2,
      "name": "Rock_Aqua"
    },
    {
      "x": 1,
      "y": 25,
      "z": 2,
      "name": "Rock_Aqua"
    },
    {
      "x": 1,
      "y": 26,
      "z": 2,
      "name": "Rubble_Aqua_Medium",
      "support": 15
    },
    {
      "x": 1,
      "y": 22,
      "z": 3,
      "name": "Rock_Aqua_Half",
      "rotation": 4
    },
    {
      "x": 1,
      "y": 23,
      "z": 3,
      "name": "Rock_Aqua"
    },
    {
      "x": 1,
      "y": 24,
      "z": 3,
      "name": "Rock_Aqua"
    },
    {
      "x": 1,
      "y": 25,
      "z": 3,
      "name": "Rock_Aqua"
    },
    {
      "x": 1,
      "y": 23,
      "z": 4,
      "name": "Rock_Aqua_Stalactite_Small",
      "rotation": 8
    },
    {
      "x": 1,
      "y": 24,
      "z": 4,
      "name": "Rock_Aqua"
    },
    {
      "x": 1,
      "y": 25,
      "z": 4,
      "name": "Rock_Aqua_Half",
      "rotation": 4
    },
    {
      "x": 1,
      "y": 24,
      "z": 7,
      "name": "Rock_Aqua_Half",
      "rotation": 8
    },
    {
      "x": 1,
      "y": 25,
      "z": 7,
      "name": "Rock_Aqua"
    },
    {
      "x": 1,
      "y": 24,
      "z": 8,
      "name": "Rock_Aqua"
    },
    {
      "x": 1,
      "y": 25,
      "z": 8,
      "name": "Rock_Aqua"
    },
    {
      "x": 1,
      "y": 26,
      "z": 8,
      "name": "Rubble_Aqua_Medium",
      "support": 15
    },
    {
      "x": 1,
      "y": 22,
      "z": 9,
      "name": "Rock_Aqua_Half",
      "rotation": 6
    },
    {
      "x": 1,
      "y": 23,
      "z": 9,
      "name": "Rock_Aqua"
    },
    {
      "x": 1,
      "y": 24,
      "z": 9,
      "name": "Rock_Aqua"
    },
    {
      "x": 1,
      "y": 25,
      "z": 9,
      "name": "Rock_Aqua"
    },
    {
      "x": 1,
      "y": 19,
      "z": 10,
      "name": "Rock_Aqua_Half",
      "rotation": 6
    },
    {
      "x": 1,
      "y": 20,
      "z": 10,
      "name": "Rock_Aqua_Half",
      "rotation": 6
    },
    {
      "x": 1,
      "y": 21,
      "z": 10,
      "name": "Rock_Aqua_Stairs",
      "rotation": 8
    },
    {
      "x": 1,
      "y": 22,
      "z": 10,
      "name": "Rock_Aqua"
    },
    {
      "x": 1,
      "y": 23,
      "z": 10,
      "name": "Rock_Aqua"
    },
    {
      "x": 1,
      "y": 24,
      "z": 10,
      "name": "Rock_Aqua"
    },
    {
      "x": 1,
      "y": 25,
      "z": 10,
      "name": "Rock_Aqua"
    },
    {
      "x": 1,
      "y": 0,
      "z": 11,
      "name": "Rock_Aqua"
    },
    {
      "x": 1,
      "y": 1,
      "z": 11,
      "name": "Rock_Aqua"
    },
    {
      "x": 1,
      "y": 2,
      "z": 11,
      "name": "Rock_Aqua"
    },
    {
      "x": 1,
      "y": 3,
      "z": 11,
      "name": "Rock_Aqua"
    },
    {
      "x": 1,
      "y": 4,
      "z": 11,
      "name": "Rock_Aqua"
    },
    {
      "x": 1,
      "y": 5,
      "z": 11,
      "name": "Rock_Aqua"
    },
    {
      "x": 1,
      "y": 6,
      "z": 11,
      "name": "Rock_Aqua"
    },
    {
      "x": 1,
      "y": 7,
      "z": 11,
      "name": "Rock_Aqua"
    },
    {
      "x": 1,
      "y": 8,
      "z": 11,
      "name": "Rock_Aqua"
    },
    {
      "x": 1,
      "y": 9,
      "z": 11,
      "name": "Rock_Aqua"
    },
    {
      "x": 1,
      "y": 10,
      "z": 11,
      "name": "Rock_Aqua"
    },
    {
      "x": 1,
      "y": 11,
      "z": 11,
      "name": "Rock_Aqua"
    },
    {
      "x": 1,
      "y": 12,
      "z": 11,
      "name": "Rock_Aqua"
    },
    {
      "x": 1,
      "y": 13,
      "z": 11,
      "name": "Rock_Aqua"
    },
    {
      "x": 1,
      "y": 14,
      "z": 11,
      "name": "Rock_Aqua"
    },
    {
      "x": 1,
      "y": 15,
      "z": 11,
      "name": "Rock_Aqua"
    },
    {
      "x": 1,
      "y": 16,
      "z": 11,
      "name": "Rock_Aqua"
    },
    {
      "x": 1,
      "y": 17,
      "z": 11,
      "name": "Rock_Aqua"
    },
    {
      "x": 1,
      "y": 18,
      "z": 11,
      "name": "Rock_Aqua"
    },
    {
      "x": 1,
      "y": 19,
      "z": 11,
      "name": "Rock_Aqua"
    },
    {
      "x": 1,
      "y": 20,
      "z": 11,
      "name": "Rock_Aqua"
    },
    {
      "x": 1,
      "y": 21,
      "z": 11,
      "name": "Rock_Aqua"
    },
    {
      "x": 1,
      "y": 22,
      "z": 11,
      "name": "Rock_Aqua"
    },
    {
      "x": 1,
      "y": 23,
      "z": 11,
      "name": "Rock_Aqua"
    },
    {
      "x": 1,
      "y": 24,
      "z": 11,
      "name": "Rock_Aqua"
    },
    {
      "x": 1,
      "y": 25,
      "z": 11,
      "name": "Rock_Aqua"
    },
    {
      "x": 1,
      "y": 0,
      "z": 12,
      "name": "Rock_Aqua"
    },
    {
      "x": 1,
      "y": 1,
      "z": 12,
      "name": "Rock_Aqua"
    },
    {
      "x": 1,
      "y": 2,
      "z": 12,
      "name": "Rock_Aqua"
    },
    {
      "x": 1,
      "y": 3,
      "z": 12,
      "name": "Rock_Aqua"
    },
    {
      "x": 1,
      "y": 4,
      "z": 12,
      "name": "Rock_Aqua"
    },
    {
      "x": 1,
      "y": 5,
      "z": 12,
      "name": "Rock_Aqua"
    },
    {
      "x": 1,
      "y": 6,
      "z": 12,
      "name": "Rock_Aqua"
    },
    {
      "x": 1,
      "y": 7,
      "z": 12,
      "name": "Rock_Aqua"
    },
    {
      "x": 1,
      "y": 8,
      "z": 12,
      "name": "Rock_Aqua"
    },
    {
      "x": 1,
      "y": 9,
      "z": 12,
      "name": "Rock_Aqua"
    },
    {
      "x": 1,
      "y": 10,
      "z": 12,
      "name": "Rock_Aqua"
    },
    {
      "x": 1,
      "y": 11,
      "z": 12,
      "name": "Rock_Aqua"
    },
    {
      "x": 1,
      "y": 12,
      "z": 12,
      "name": "Rock_Aqua"
    },
    {
      "x": 1,
      "y": 13,
      "z": 12,
      "name": "Rock_Aqua"
    },
    {
      "x": 1,
      "y": 14,
      "z": 12,
      "name": "Rock_Aqua"
    },
    {
      "x": 1,
      "y": 15,
      "z": 12,
      "name": "Rock_Aqua"
    },
    {
      "x": 1,
      "y": 16,
      "z": 12,
      "name": "Rock_Aqua"
    },
    {
      "x": 1,
      "y": 17,
      "z": 12,
      "name": "Rock_Aqua"
    },
    {
      "x": 1,
      "y": 18,
      "z": 12,
      "name": "Rock_Aqua"
    },
    {
      "x": 1,
      "y": 19,
      "z": 12,
      "name": "Rock_Aqua"
    },
    {
      "x": 1,
      "y": 20,
      "z": 12,
      "name": "Rock_Aqua"
    },
    {
      "x": 1,
      "y": 21,
      "z": 12,
      "name": "Rock_Aqua"
    },
    {
      "x": 1,
      "y": 22,
      "z": 12,
      "name": "Rock_Aqua"
    },
    {
      "x": 1,
      "y": 23,
      "z": 12,
      "name": "Rock_Aqua"
    },
    {
      "x": 1,
      "y": 24,
      "z": 12,
      "name": "Rock_Aqua"
    },
    {
      "x": 1,
      "y": 25,
      "z": 12,
      "name": "Rock_Aqua"
    },
    {
      "x": 2,
      "y": 0,
      "z": -12,
      "name": "Rock_Aqua"
    },
    {
      "x": 2,
      "y": 1,
      "z": -12,
      "name": "Rock_Aqua"
    },
    {
      "x": 2,
      "y": 2,
      "z": -12,
      "name": "Rock_Aqua"
    },
    {
      "x": 2,
      "y": 3,
      "z": -12,
      "name": "Rock_Aqua"
    },
    {
      "x": 2,
      "y": 4,
      "z": -12,
      "name": "Rock_Aqua"
    },
    {
      "x": 2,
      "y": 5,
      "z": -12,
      "name": "Rock_Aqua"
    },
    {
      "x": 2,
      "y": 6,
      "z": -12,
      "name": "Rock_Aqua"
    },
    {
      "x": 2,
      "y": 7,
      "z": -12,
      "name": "Rock_Aqua"
    },
    {
      "x": 2,
      "y": 8,
      "z": -12,
      "name": "Rock_Aqua"
    },
    {
      "x": 2,
      "y": 9,
      "z": -12,
      "name": "Rock_Aqua"
    },
    {
      "x": 2,
      "y": 10,
      "z": -12,
      "name": "Rock_Aqua"
    },
    {
      "x": 2,
      "y": 11,
      "z": -12,
      "name": "Rock_Aqua"
    },
    {
      "x": 2,
      "y": 12,
      "z": -12,
      "name": "Rock_Aqua"
    },
    {
      "x": 2,
      "y": 13,
      "z": -12,
      "name": "Rock_Aqua"
    },
    {
      "x": 2,
      "y": 14,
      "z": -12,
      "name": "Rock_Aqua"
    },
    {
      "x": 2,
      "y": 15,
      "z": -12,
      "name": "Rock_Aqua"
    },
    {
      "x": 2,
      "y": 16,
      "z": -12,
      "name": "Rock_Aqua_Brick_Smooth"
    },
    {
      "x": 2,
      "y": 17,
      "z": -12,
      "name": "Rock_Aqua_Brick_Stairs",
      "rotation": 1
    },
    {
      "x": 2,
      "y": 18,
      "z": -12,
      "name": "Rock_Aqua_Brick_Smooth_Half",
      "rotation": 5
    },
    {
      "x": 2,
      "y": 19,
      "z": -12,
      "name": "Rock_Aqua_Brick_Stairs",
      "rotation": 11
    },
    {
      "x": 2,
      "y": 20,
      "z": -12,
      "name": "Rock_Aqua_Brick_Stairs",
      "rotation": 1
    },
    {
      "x": 2,
      "y": 21,
      "z": -12,
      "name": "Rock_Aqua_Brick_Smooth_Half",
      "rotation": 5
    },
    {
      "x": 2,
      "y": 22,
      "z": -12,
      "name": "Rock_Aqua_Brick_Stairs",
      "rotation": 11
    },
    {
      "x": 2,
      "y": 23,
      "z": -12,
      "name": "Rock_Aqua_Brick_Stairs",
      "rotation": 1
    },
    {
      "x": 2,
      "y": 24,
      "z": -12,
      "name": "Rock_Aqua_Brick_Smooth_Half",
      "rotation": 5
    },
    {
      "x": 2,
      "y": 25,
      "z": -12,
      "name": "Rock_Aqua_Brick_Stairs",
      "rotation": 11
    },
    {
      "x": 2,
      "y": 26,
      "z": -12,
      "name": "Rock_Aqua_Brick_Wall",
      "rotation": 1
    },
    {
      "x": 2,
      "y": 19,
      "z": -11,
      "name": "Rock_Aqua_Brick_Stairs",
      "rotation": 11
    },
    {
      "x": 2,
      "y": 20,
      "z": -11,
      "name": "Rock_Aqua_Brick_Stairs",
      "rotation": 1
    },
    {
      "x": 2,
      "y": 21,
      "z": -11,
      "name": "Rock_Aqua_Brick_Smooth_Half",
      "rotation": 5
    },
    {
      "x": 2,
      "y": 22,
      "z": -11,
      "name": "Rock_Aqua_Brick_Stairs",
      "rotation": 11
    },
    {
      "x": 2,
      "y": 23,
      "z": -11,
      "name": "Rock_Aqua_Brick_Stairs",
      "rotation": 1
    },
    {
      "x": 2,
      "y": 24,
      "z": -11,
      "name": "Rock_Aqua_Brick_Smooth_Half",
      "rotation": 5
    },
    {
      "x": 2,
      "y": 25,
      "z": -11,
      "name": "Rock_Aqua_Brick_Stairs",
      "rotation": 11
    },
    {
      "x": 2,
      "y": 26,
      "z": -11,
      "name": "Rock_Aqua_Brick_Wall",
      "rotation": 1
    },
    {
      "x": 2,
      "y": 23,
      "z": -10,
      "name": "Rock_Aqua_Brick_Stairs",
      "rotation": 1
    },
    {
      "x": 2,
      "y": 24,
      "z": -10,
      "name": "Rock_Aqua_Brick_Smooth_Half",
      "rotation": 5
    },
    {
      "x": 2,
      "y": 25,
      "z": -10,
      "name": "Rock_Aqua_Brick_Stairs",
      "rotation": 11
    },
    {
      "x": 2,
      "y": 26,
      "z": -10,
      "name": "Rock_Aqua_Brick_Wall",
      "rotation": 1
    },
    {
      "x": 2,
      "y": 24,
      "z": -9,
      "name": "Rock_Aqua_Brick_Smooth_Half",
      "rotation": 5
    },
    {
      "x": 2,
      "y": 25,
      "z": -9,
      "name": "Rock_Aqua_Brick_Stairs",
      "rotation": 11
    },
    {
      "x": 2,
      "y": 26,
      "z": -9,
      "name": "Rock_Aqua_Brick_Wall",
      "rotation": 1
    },
    {
      "x": 2,
      "y": 25,
      "z": -8,
      "name": "Rock_Aqua_Brick_Stairs",
      "rotation": 11
    },
    {
      "x": 2,
      "y": 25,
      "z": -7,
      "name": "Rock_Aqua_Brick_Stairs",
      "rotation": 11
    },
    {
      "x": 2,
      "y": 25,
      "z": -6,
      "name": "Rock_Aqua_Brick_Stairs",
      "rotation": 11
    },
    {
      "x": 2,
      "y": 26,
      "z": -6,
      "name": "Rock_Aqua_Brick_Wall",
      "rotation": 1
    },
    {
      "x": 2,
      "y": 25,
      "z": -5,
      "name": "Rock_Aqua_Brick_Stairs",
      "rotation": 11
    },
    {
      "x": 2,
      "y": 26,
      "z": -5,
      "name": "Rock_Aqua_Brick_Wall",
      "rotation": 1
    },
    {
      "x": 2,
      "y": 25,
      "z": -4,
      "name": "Rock_Aqua_Brick_Stairs",
      "rotation": 11
    },
    {
      "x": 2,
      "y": 26,
      "z": -4,
      "name": "Rock_Aqua_Brick_Wall",
      "rotation": 1
    },
    {
      "x": 2,
      "y": 24,
      "z": -3,
      "name": "Rock_Aqua_Brick_Smooth_Half",
      "rotation": 5
    },
    {
      "x": 2,
      "y": 25,
      "z": -3,
      "name": "Rock_Aqua_Brick_Stairs",
      "rotation": 11
    },
    {
      "x": 2,
      "y": 26,
      "z": -3,
      "name": "Rock_Aqua_Brick_Wall",
      "rotation": 1
    },
    {
      "x": 2,
      "y": 23,
      "z": -2,
      "name": "Rock_Aqua_Brick_Stairs",
      "rotation": 1
    },
    {
      "x": 2,
      "y": 24,
      "z": -2,
      "name": "Rock_Aqua_Brick_Smooth_Half",
      "rotation": 5
    },
    {
      "x": 2,
      "y": 25,
      "z": -2,
      "name": "Rock_Aqua_Brick_Stairs",
      "rotation": 11
    },
    {
      "x": 2,
      "y": 26,
      "z": -2,
      "name": "Rock_Aqua_Brick_Wall",
      "rotation": 1
    },
    {
      "x": 2,
      "y": 21,
      "z": -1,
      "name": "Rock_Aqua_Brick_Smooth_Half",
      "rotation": 5
    },
    {
      "x": 2,
      "y": 22,
      "z": -1,
      "name": "Rock_Aqua_Brick_Stairs",
      "rotation": 11
    },
    {
      "x": 2,
      "y": 23,
      "z": -1,
      "name": "Rock_Aqua_Brick_Stairs",
      "rotation": 1
    },
    {
      "x": 2,
      "y": 24,
      "z": -1,
      "name": "Rock_Aqua_Brick_Smooth_Half",
      "rotation": 5
    },
    {
      "x": 2,
      "y": 25,
      "z": -1,
      "name": "Rock_Aqua_Brick_Stairs",
      "rotation": 11
    },
    {
      "x": 2,
      "y": 26,
      "z": -1,
      "name": "Rock_Aqua_Brick_Wall",
      "rotation": 1
    },
    {
      "x": 2,
      "y": 0,
      "z": 0,
      "name": "Rock_Aqua"
    },
    {
      "x": 2,
      "y": 1,
      "z": 0,
      "name": "Rock_Aqua"
    },
    {
      "x": 2,
      "y": 2,
      "z": 0,
      "name": "Rock_Aqua"
    },
    {
      "x": 2,
      "y": 3,
      "z": 0,
      "name": "Rock_Aqua"
    },
    {
      "x": 2,
      "y": 4,
      "z": 0,
      "name": "Rock_Aqua"
    },
    {
      "x": 2,
      "y": 5,
      "z": 0,
      "name": "Rock_Aqua"
    },
    {
      "x": 2,
      "y": 6,
      "z": 0,
      "name": "Rock_Aqua"
    },
    {
      "x": 2,
      "y": 7,
      "z": 0,
      "name": "Rock_Aqua"
    },
    {
      "x": 2,
      "y": 8,
      "z": 0,
      "name": "Rock_Aqua"
    },
    {
      "x": 2,
      "y": 9,
      "z": 0,
      "name": "Rock_Aqua"
    },
    {
      "x": 2,
      "y": 10,
      "z": 0,
      "name": "Rock_Aqua"
    },
    {
      "x": 2,
      "y": 11,
      "z": 0,
      "name": "Rock_Aqua"
    },
    {
      "x": 2,
      "y": 12,
      "z": 0,
      "name": "Rock_Aqua"
    },
    {
      "x": 2,
      "y": 13,
      "z": 0,
      "name": "Rock_Aqua"
    },
    {
      "x": 2,
      "y": 14,
      "z": 0,
      "name": "Rock_Aqua"
    },
    {
      "x": 2,
      "y": 15,
      "z": 0,
      "name": "Rock_Aqua"
    },
    {
      "x": 2,
      "y": 16,
      "z": 0,
      "name": "Rock_Aqua_Brick_Smooth"
    },
    {
      "x": 2,
      "y": 17,
      "z": 0,
      "name": "Rock_Aqua_Brick_Stairs",
      "rotation": 1
    },
    {
      "x": 2,
      "y": 18,
      "z": 0,
      "name": "Rock_Aqua_Brick_Smooth_Half",
      "rotation": 5
    },
    {
      "x": 2,
      "y": 19,
      "z": 0,
      "name": "Rock_Aqua_Brick_Stairs",
      "rotation": 11
    },
    {
      "x": 2,
      "y": 20,
      "z": 0,
      "name": "Rock_Aqua_Brick_Stairs",
      "rotation": 1
    },
    {
      "x": 2,
      "y": 21,
      "z": 0,
      "name": "Rock_Aqua_Brick_Smooth_Half",
      "rotation": 5
    },
    {
      "x": 2,
      "y": 22,
      "z": 0,
      "name": "Rock_Aqua_Brick_Stairs",
      "rotation": 11
    },
    {
      "x": 2,
      "y": 23,
      "z": 0,
      "name": "Rock_Aqua_Brick_Stairs",
      "rotation": 1
    },
    {
      "x": 2,
      "y": 24,
      "z": 0,
      "name": "Rock_Aqua_Brick_Smooth_Half",
      "rotation": 5
    },
    {
      "x": 2,
      "y": 25,
      "z": 0,
      "name": "Rock_Aqua_Brick_Stairs",
      "rotation": 11
    },
    {
      "x": 2,
      "y": 26,
      "z": 0,
      "name": "Rock_Aqua_Brick_Wall",
      "rotation": 1
    },
    {
      "x": 2,
      "y": 21,
      "z": 1,
      "name": "Rock_Aqua_Brick_Smooth_Half",
      "rotation": 5
    },
    {
      "x": 2,
      "y": 22,
      "z": 1,
      "name": "Rock_Aqua_Brick_Stairs",
      "rotation": 11
    },
    {
      "x": 2,
      "y": 23,
      "z": 1,
      "name": "Rock_Aqua_Brick_Stairs",
      "rotation": 1
    },
    {
      "x": 2,
      "y": 24,
      "z": 1,
      "name": "Rock_Aqua_Brick_Smooth_Half",
      "rotation": 5
    },
    {
      "x": 2,
      "y": 25,
      "z": 1,
      "name": "Rock_Aqua_Brick_Stairs",
      "rotation": 11
    },
    {
      "x": 2,
      "y": 26,
      "z": 1,
      "name": "Rock_Aqua_Brick_Wall",
      "rotation": 1
    },
    {
      "x": 2,
      "y": 23,
      "z": 2,
      "name": "Rock_Aqua_Brick_Stairs",
      "rotation": 1
    },
    {
      "x": 2,
      "y": 24,
      "z": 2,
      "name": "Rock_Aqua_Brick_Smooth_Half",
      "rotation": 5
    },
    {
      "x": 2,
      "y": 25,
      "z": 2,
      "name": "Rock_Aqua_Brick_Stairs",
      "rotation": 11
    },
    {
      "x": 2,
      "y": 26,
      "z": 2,
      "name": "Rock_Aqua_Brick_Wall",
      "rotation": 1
    },
    {
      "x": 2,
      "y": 24,
      "z": 3,
      "name": "Rock_Aqua_Brick_Smooth_Half",
      "rotation": 5
    },
    {
      "x": 2,
      "y": 25,
      "z": 3,
      "name": "Rock_Aqua_Brick_Stairs",
      "rotation": 11
    },
    {
      "x": 2,
      "y": 26,
      "z": 3,
      "name": "Rock_Aqua_Brick_Half"
    },
    {
      "x": 2,
      "y": 25,
      "z": 4,
      "name": "Rock_Aqua_Brick_Stairs",
      "rotation": 11
    },
    {
      "x": 2,
      "y": 26,
      "z": 4,
      "name": "Rock_Aqua_Brick_Half"
    },
    {
      "x": 2,
      "y": 25,
      "z": 8,
      "name": "Rock_Aqua_Brick_Stairs",
      "rotation": 11
    },
    {
      "x": 2,
      "y": 26,
      "z": 8,
      "name": "Rock_Aqua_Brick_Wall",
      "rotation": 1
    },
    {
      "x": 2,
      "y": 24,
      "z": 9,
      "name": "Rock_Aqua_Brick_Smooth_Half",
      "rotation": 5
    },
    {
      "x": 2,
      "y": 25,
      "z": 9,
      "name": "Rock_Aqua_Brick_Stairs",
      "rotation": 11
    },
    {
      "x": 2,
      "y": 26,
      "z": 9,
      "name": "Rock_Aqua_Brick_Wall",
      "rotation": 1
    },
    {
      "x": 2,
      "y": 23,
      "z": 10,
      "name": "Rock_Aqua_Brick_Stairs",
      "rotation": 1
    },
    {
      "x": 2,
      "y": 24,
      "z": 10,
      "name": "Rock_Aqua_Brick_Smooth_Half",
      "rotation": 5
    },
    {
      "x": 2,
      "y": 25,
      "z": 10,
      "name": "Rock_Aqua_Brick_Stairs",
      "rotation": 11
    },
    {
      "x": 2,
      "y": 26,
      "z": 10,
      "name": "Rock_Aqua_Brick_Wall",
      "rotation": 1
    },
    {
      "x": 2,
      "y": 21,
      "z": 11,
      "name": "Rock_Aqua_Brick_Smooth_Half",
      "rotation": 5
    },
    {
      "x": 2,
      "y": 22,
      "z": 11,
      "name": "Rock_Aqua_Brick_Stairs",
      "rotation": 11
    },
    {
      "x": 2,
      "y": 23,
      "z": 11,
      "name": "Rock_Aqua_Brick_Stairs",
      "rotation": 1
    },
    {
      "x": 2,
      "y": 24,
      "z": 11,
      "name": "Rock_Aqua_Brick_Smooth_Half",
      "rotation": 5
    },
    {
      "x": 2,
      "y": 25,
      "z": 11,
      "name": "Rock_Aqua_Brick_Stairs",
      "rotation": 11
    },
    {
      "x": 2,
      "y": 26,
      "z": 11,
      "name": "Rock_Aqua_Brick_Wall",
      "rotation": 1
    },
    {
      "x": 2,
      "y": 0,
      "z": 12,
      "name": "Rock_Aqua"
    },
    {
      "x": 2,
      "y": 1,
      "z": 12,
      "name": "Rock_Aqua"
    },
    {
      "x": 2,
      "y": 2,
      "z": 12,
      "name": "Rock_Aqua"
    },
    {
      "x": 2,
      "y": 3,
      "z": 12,
      "name": "Rock_Aqua"
    },
    {
      "x": 2,
      "y": 4,
      "z": 12,
      "name": "Rock_Aqua"
    },
    {
      "x": 2,
      "y": 5,
      "z": 12,
      "name": "Rock_Aqua"
    },
    {
      "x": 2,
      "y": 6,
      "z": 12,
      "name": "Rock_Aqua"
    },
    {
      "x": 2,
      "y": 7,
      "z": 12,
      "name": "Rock_Aqua"
    },
    {
      "x": 2,
      "y": 8,
      "z": 12,
      "name": "Rock_Aqua"
    },
    {
      "x": 2,
      "y": 9,
      "z": 12,
      "name": "Rock_Aqua"
    },
    {
      "x": 2,
      "y": 10,
      "z": 12,
      "name": "Rock_Aqua"
    },
    {
      "x": 2,
      "y": 11,
      "z": 12,
      "name": "Rock_Aqua"
    },
    {
      "x": 2,
      "y": 12,
      "z": 12,
      "name": "Rock_Aqua"
    },
    {
      "x": 2,
      "y": 13,
      "z": 12,
      "name": "Rock_Aqua"
    },
    {
      "x": 2,
      "y": 14,
      "z": 12,
      "name": "Rock_Aqua"
    },
    {
      "x": 2,
      "y": 15,
      "z": 12,
      "name": "Rock_Aqua"
    },
    {
      "x": 2,
      "y": 16,
      "z": 12,
      "name": "Rock_Aqua_Brick_Smooth"
    },
    {
      "x": 2,
      "y": 17,
      "z": 12,
      "name": "Rock_Aqua_Brick_Stairs",
      "rotation": 1
    },
    {
      "x": 2,
      "y": 18,
      "z": 12,
      "name": "Rock_Aqua_Brick_Smooth_Half",
      "rotation": 5
    },
    {
      "x": 2,
      "y": 19,
      "z": 12,
      "name": "Rock_Aqua_Brick_Stairs",
      "rotation": 11
    },
    {
      "x": 2,
      "y": 20,
      "z": 12,
      "name": "Rock_Aqua_Brick_Stairs",
      "rotation": 1
    },
    {
      "x": 2,
      "y": 21,
      "z": 12,
      "name": "Rock_Aqua_Brick_Smooth_Half",
      "rotation": 5
    },
    {
      "x": 2,
      "y": 22,
      "z": 12,
      "name": "Rock_Aqua_Brick_Stairs",
      "rotation": 11
    },
    {
      "x": 2,
      "y": 23,
      "z": 12,
      "name": "Rock_Aqua_Brick_Stairs",
      "rotation": 1
    },
    {
      "x": 2,
      "y": 24,
      "z": 12,
      "name": "Rock_Aqua_Brick_Smooth_Half",
      "rotation": 5
    },
    {
      "x": 2,
      "y": 25,
      "z": 12,
      "name": "Rock_Aqua_Brick_Stairs",
      "rotation": 11
    },
    {
      "x": 2,
      "y": 26,
      "z": 12,
      "name": "Rock_Aqua_Brick_Wall",
      "rotation": 1
    }
  ],
  "fluids": [
    {
      "x": -2,
      "y": 17,
      "z": -12,
      "name": "Water_Source",
      "level": 1
    },
    {
      "x": -2,
      "y": 18,
      "z": -12,
      "name": "Water_Source",
      "level": 1
    },
    {
      "x": -2,
      "y": 19,
      "z": -12,
      "name": "Water_Source",
      "level": 1
    },
    {
      "x": -2,
      "y": 20,
      "z": -12,
      "name": "Water_Source",
      "level": 1
    },
    {
      "x": -2,
      "y": 21,
      "z": -12,
      "name": "Water_Source",
      "level": 1
    },
    {
      "x": -2,
      "y": 22,
      "z": -12,
      "name": "Water_Source",
      "level": 1
    },
    {
      "x": -2,
      "y": 23,
      "z": -12,
      "name": "Water_Source",
      "level": 1
    },
    {
      "x": -2,
      "y": 24,
      "z": -12,
      "name": "Water_Source",
      "level": 1
    },
    {
      "x": -2,
      "y": 25,
      "z": -12,
      "name": "Water_Source",
      "level": 1
    },
    {
      "x": -2,
      "y": 26,
      "z": -12,
      "name": "Water_Source",
      "level": 1
    },
    {
      "x": -2,
      "y": 21,
      "z": -11,
      "name": "Water_Source",
      "level": 1
    },
    {
      "x": -2,
      "y": 22,
      "z": -11,
      "name": "Water_Source",
      "level": 1
    },
    {
      "x": -2,
      "y": 23,
      "z": -11,
      "name": "Water_Source",
      "level": 1
    },
    {
      "x": -2,
      "y": 24,
      "z": -11,
      "name": "Water_Source",
      "level": 1
    },
    {
      "x": -2,
      "y": 25,
      "z": -11,
      "name": "Water_Source",
      "level": 1
    },
    {
      "x": -2,
      "y": 26,
      "z": -11,
      "name": "Water_Source",
      "level": 1
    },
    {
      "x": -2,
      "y": 23,
      "z": -10,
      "name": "Water_Source",
      "level": 1
    },
    {
      "x": -2,
      "y": 24,
      "z": -10,
      "name": "Water_Source",
      "level": 1
    },
    {
      "x": -2,
      "y": 25,
      "z": -10,
      "name": "Water_Source",
      "level": 1
    },
    {
      "x": -2,
      "y": 26,
      "z": -10,
      "name": "Water_Source",
      "level": 1
    },
    {
      "x": -2,
      "y": 24,
      "z": -9,
      "name": "Water_Source",
      "level": 1
    },
    {
      "x": -2,
      "y": 25,
      "z": -9,
      "name": "Water_Source",
      "level": 1
    },
    {
      "x": -2,
      "y": 26,
      "z": -9,
      "name": "Water_Source",
      "level": 1
    },
    {
      "x": -2,
      "y": 25,
      "z": -8,
      "name": "Water_Source",
      "level": 1
    },
    {
      "x": -2,
      "y": 26,
      "z": -8,
      "name": "Water_Source",
      "level": 1
    },
    {
      "x": -2,
      "y": 25,
      "z": -7,
      "name": "Water_Source",
      "level": 1
    },
    {
      "x": -2,
      "y": 25,
      "z": -4,
      "name": "Water_Source",
      "level": 1
    },
    {
      "x": -2,
      "y": 24,
      "z": -3,
      "name": "Water_Source",
      "level": 1
    },
    {
      "x": -2,
      "y": 25,
      "z": -3,
      "name": "Water_Source",
      "level": 1
    },
    {
      "x": -2,
      "y": 26,
      "z": -3,
      "name": "Water_Source",
      "level": 1
    },
    {
      "x": -2,
      "y": 23,
      "z": -2,
      "name": "Water_Source",
      "level": 1
    },
    {
      "x": -2,
      "y": 24,
      "z": -2,
      "name": "Water_Source",
      "level": 1
    },
    {
      "x": -2,
      "y": 25,
      "z": -2,
      "name": "Water_Source",
      "level": 1
    },
    {
      "x": -2,
      "y": 26,
      "z": -2,
      "name": "Water_Source",
      "level": 1
    },
    {
      "x": -2,
      "y": 21,
      "z": -1,
      "name": "Water_Source",
      "level": 1
    },
    {
      "x": -2,
      "y": 22,
      "z": -1,
      "name": "Water_Source",
      "level": 1
    },
    {
      "x": -2,
      "y": 23,
      "z": -1,
      "name": "Water_Source",
      "level": 1
    },
    {
      "x": -2,
      "y": 24,
      "z": -1,
      "name": "Water_Source",
      "level": 1
    },
    {
      "x": -2,
      "y": 25,
      "z": -1,
      "name": "Water_Source",
      "level": 1
    },
    {
      "x": -2,
      "y": 26,
      "z": -1,
      "name": "Water_Source",
      "level": 1
    },
    {
      "x": -2,
      "y": 17,
      "z": 0,
      "name": "Water_Source",
      "level": 1
    },
    {
      "x": -2,
      "y": 18,
      "z": 0,
      "name": "Water_Source",
      "level": 1
    },
    {
      "x": -2,
      "y": 19,
      "z": 0,
      "name": "Water_Source",
      "level": 1
    },
    {
      "x": -2,
      "y": 20,
      "z": 0,
      "name": "Water_Source",
      "level": 1
    },
    {
      "x": -2,
      "y": 21,
      "z": 0,
      "name": "Water_Source",
      "level": 1
    },
    {
      "x": -2,
      "y": 22,
      "z": 0,
      "name": "Water_Source",
      "level": 1
    },
    {
      "x": -2,
      "y": 23,
      "z": 0,
      "name": "Water_Source",
      "level": 1
    },
    {
      "x": -2,
      "y": 24,
      "z": 0,
      "name": "Water_Source",
      "level": 1
    },
    {
      "x": -2,
      "y": 25,
      "z": 0,
      "name": "Water_Source",
      "level": 1
    },
    {
      "x": -2,
      "y": 26,
      "z": 0,
      "name": "Water_Source",
      "level": 1
    },
    {
      "x": -2,
      "y": 21,
      "z": 1,
      "name": "Water_Source",
      "level": 1
    },
    {
      "x": -2,
      "y": 22,
      "z": 1,
      "name": "Water_Source",
      "level": 1
    },
    {
      "x": -2,
      "y": 23,
      "z": 1,
      "name": "Water_Source",
      "level": 1
    },
    {
      "x": -2,
      "y": 24,
      "z": 1,
      "name": "Water_Source",
      "level": 1
    },
    {
      "x": -2,
      "y": 25,
