{
  "version": 8,
  "blockIdVersion": 11,
  "anchorX": 0,
  "anchorY": 8,
  "anchorZ": 12,
  "blocks": [
    {
      "x": -1,
      "y": 0,
      "z": -11,
      "name": "Rock_Aqua"
    },
    {
      "x": -1,
      "y": 1,
      "z": -11,
      "name": "Rock_Aqua"
    },
    {
      "x": -1,
      "y": 2,
      "z": -11,
      "name": "Rock_Aqua"
    },
    {
      "x": -1,
      "y": 3,
      "z": -11,
      "name": "Rock_Aqua"
    },
    {
      "x": -1,
      "y": 4,
      "z": -11,
      "name": "Rock_Aqua"
    },
    {
      "x": -1,
      "y": 5,
      "z": -11,
      "name": "Rock_Aqua"
    },
    {
      "x": -1,
      "y": 6,
      "z": -11,
      "name": "Rock_Aqua"
    },
    {
      "x": -1,
      "y": 7,
      "z": -11,
      "name": "Rock_Aqua"
    },
    {
      "x": -1,
      "y": 8,
      "z": -11,
      "name": "Rock_Aqua"
    },
    {
      "x": -1,
      "y": 0,
      "z": -10,
      "name": "Rock_Aqua"
    },
    {
      "x": -1,
      "y": 1,
      "z": -10,
      "name": "Rock_Aqua"
    },
    {
      "x": -1,
      "y": 2,
      "z": -10,
      "name": "Rock_Aqua"
    },
    {
      "x": -1,
      "y": 3,
      "z": -10,
      "name": "Rock_Aqua"
    },
    {
      "x": -1,
      "y": 4,
      "z": -10,
      "name": "Rock_Aqua"
    },
    {
      "x": -1,
      "y": 5,
      "z": -10,
      "name": "Rock_Aqua"
    },
    {
      "x": -1,
      "y": 6,
      "z": -10,
      "name": "Rock_Aqua"
    },
    {
      "x": -1,
      "y": 7,
      "z": -10,
      "name": "Rock_Aqua"
    },
    {
      "x": -1,
      "y": 8,
      "z": -10,
      "name": "Rock_Aqua"
    },
    {
      "x": -1,
      "y": 2,
      "z": -9,
      "name": "Rock_Aqua_Half",
      "rotation": 4
    },
    {
      "x": -1,
      "y": 3,
      "z": -9,
      "name": "Rock_Aqua_Half",
      "rotation": 4
    },
    {
      "x": -1,
      "y": 4,
      "z": -9,
      "name": "Rock_Aqua"
    },
    {
      "x": -1,
      "y": 5,
      "z": -9,
      "name": "Rock_Aqua"
    },
    {
      "x": -1,
      "y": 6,
      "z": -9,
      "name": "Rock_Aqua"
    },
    {
      "x": -1,
      "y": 7,
      "z": -9,
      "name": "Rock_Aqua"
    },
    {
      "x": -1,
      "y": 8,
      "z": -9,
      "name": "Rock_Aqua"
    },
    {
      "x": -1,
      "y": 5,
      "z": -8,
      "name": "Rock_Aqua_Half",
      "rotation": 4
    },
    {
      "x": -1,
      "y": 6,
      "z": -8,
      "name": "Rock_Aqua"
    },
    {
      "x": -1,
      "y": 7,
      "z": -8,
      "name": "Rock_Aqua"
    },
    {
      "x": -1,
      "y": 8,
      "z": -8,
      "name": "Rock_Aqua"
    },
    {
      "x": -1,
      "y": 7,
      "z": -7,
      "name": "Rock_Aqua"
    },
    {
      "x": -1,
      "y": 8,
      "z": -7,
      "name": "Rock_Aqua"
    },
    {
      "x": -1,
      "y": 7,
      "z": -6,
      "name": "Rock_Aqua_Half",
      "rotation": 8
    },
    {
      "x": -1,
      "y": 8,
      "z": -6,
      "name": "Rock_Aqua"
    },
    {
      "x": -1,
      "y": 7,
      "z": -5,
      "name": "Rock_Aqua_Half",
      "rotation": 8
    },
    {
      "x": -1,
      "y": 8,
      "z": -5,
      "name": "Rock_Aqua"
    },
    {
      "x": -1,
      "y": 7,
      "z": -4,
      "name": "Rock_Aqua_Half",
      "rotation": 8
    },
    {
      "x": -1,
      "y": 8,
      "z": -4,
      "name": "Rock_Aqua"
    },
    {
      "x": -1,
      "y": 7,
      "z": -3,
      "name": "Rock_Aqua"
    },
    {
      "x": -1,
      "y": 8,
      "z": -3,
      "name": "Rock_Aqua"
    },
    {
      "x": -1,
      "y": 5,
      "z": -2,
      "name": "Rock_Aqua_Half",
      "rotation": 6
    },
    {
      "x": -1,
      "y": 6,
      "z": -2,
      "name": "Rock_Aqua"
    },
    {
      "x": -1,
      "y": 7,
      "z": -2,
      "name": "Rock_Aqua"
    },
    {
      "x": -1,
      "y": 8,
      "z": -2,
      "name": "Rock_Aqua"
    },
    {
      "x": -1,
      "y": 2,
      "z": -1,
      "name": "Rock_Aqua_Half",
      "rotation": 6
    },
    {
      "x": -1,
      "y": 3,
      "z": -1,
      "name": "Rock_Aqua_Half",
      "rotation": 6
    },
    {
      "x": -1,
      "y": 4,
      "z": -1,
      "name": "Rock_Aqua"
    },
    {
      "x": -1,
      "y": 5,
      "z": -1,
      "name": "Rock_Aqua"
    },
    {
      "x": -1,
      "y": 6,
      "z": -1,
      "name": "Rock_Aqua"
    },
    {
      "x": -1,
      "y": 7,
      "z": -1,
      "name": "Rock_Aqua"
    },
    {
      "x": -1,
      "y": 8,
      "z": -1,
      "name": "Rock_Aqua"
    },
    {
      "x": -1,
      "y": 0,
      "z": 0,
      "name": "Rock_Aqua"
    },
    {
      "x": -1,
      "y": 1,
      "z": 0,
      "name": "Rock_Aqua"
    },
    {
      "x": -1,
      "y": 2,
      "z": 0,
      "name": "Rock_Aqua"
    },
    {
      "x": -1,
      "y": 3,
      "z": 0,
      "name": "Rock_Aqua"
    },
    {
      "x": -1,
      "y": 4,
      "z": 0,
      "name": "Rock_Aqua"
    },
    {
      "x": -1,
      "y": 5,
      "z": 0,
      "name": "Rock_Aqua"
    },
    {
      "x": -1,
      "y": 6,
      "z": 0,
      "name": "Rock_Aqua"
    },
    {
      "x": -1,
      "y": 7,
      "z": 0,
      "name": "Rock_Aqua"
    },
    {
      "x": -1,
      "y": 8,
      "z": 0,
      "name": "Rock_Aqua"
    },
    {
      "x": -1,
      "y": 0,
      "z": 1,
      "name": "Rock_Aqua"
    },
    {
      "x": -1,
      "y": 1,
      "z": 1,
      "name": "Rock_Aqua"
    },
    {
      "x": -1,
      "y": 2,
      "z": 1,
      "name": "Rock_Aqua"
    },
    {
      "x": -1,
      "y": 3,
      "z": 1,
      "name": "Rock_Aqua"
    },
    {
      "x": -1,
      "y": 4,
      "z": 1,
      "name": "Rock_Aqua"
    },
    {
      "x": -1,
      "y": 5,
      "z": 1,
      "name": "Rock_Aqua"
    },
    {
      "x": -1,
      "y": 6,
      "z": 1,
      "name": "Rock_Aqua"
    },
    {
      "x": -1,
      "y": 7,
      "z": 1,
      "name": "Rock_Aqua"
    },
    {
      "x": -1,
      "y": 8,
      "z": 1,
      "name": "Rock_Aqua"
    },
    {
      "x": -1,
      "y": 2,
      "z": 2,
      "name": "Rock_Aqua_Half",
      "rotation": 4
    },
    {
      "x": -1,
      "y": 3,
      "z": 2,
      "name": "Rock_Aqua_Half",
      "rotation": 4
    },
    {
      "x": -1,
      "y": 4,
      "z": 2,
      "name": "Rock_Aqua"
    },
    {
      "x": -1,
      "y": 5,
      "z": 2,
      "name": "Rock_Aqua"
    },
    {
      "x": -1,
      "y": 6,
      "z": 2,
      "name": "Rock_Aqua"
    },
    {
      "x": -1,
      "y": 7,
      "z": 2,
      "name": "Rock_Aqua"
    },
    {
      "x": -1,
      "y": 8,
      "z": 2,
      "name": "Rock_Aqua"
    },
    {
      "x": -1,
      "y": 5,
      "z": 3,
      "name": "Rock_Aqua_Half",
      "rotation": 4
    },
    {
      "x": -1,
      "y": 6,
      "z": 3,
      "name": "Rock_Aqua"
    },
    {
      "x": -1,
      "y": 7,
      "z": 3,
      "name": "Rock_Aqua"
    },
    {
      "x": -1,
      "y": 8,
      "z": 3,
      "name": "Rock_Aqua"
    },
    {
      "x": -1,
      "y": 7,
      "z": 4,
      "name": "Rock_Aqua"
    },
    {
      "x": -1,
      "y": 8,
      "z": 4,
      "name": "Rock_Aqua"
    },
    {
      "x": -1,
      "y": 7,
      "z": 5,
      "name": "Rock_Aqua_Half",
      "rotation": 8
    },
    {
      "x": -1,
      "y": 8,
      "z": 5,
      "name": "Rock_Aqua"
    },
    {
      "x": -1,
      "y": 7,
      "z": 6,
      "name": "Rock_Aqua_Half",
      "rotation": 8
    },
    {
      "x": -1,
      "y": 8,
      "z": 6,
      "name": "Rock_Aqua"
    },
    {
      "x": -1,
      "y": 7,
      "z": 7,
      "name": "Rock_Aqua_Half",
      "rotation": 8
    },
    {
      "x": -1,
      "y": 8,
      "z": 7,
      "name": "Rock_Aqua"
    },
    {
      "x": -1,
      "y": 7,
      "z": 8,
      "name": "Rock_Aqua"
    },
    {
      "x": -1,
      "y": 8,
      "z": 8,
      "name": "Rock_Aqua"
    },
    {
      "x": -1,
      "y": 5,
      "z": 9,
      "name": "Rock_Aqua_Half",
      "rotation": 6
    },
    {
      "x": -1,
      "y": 6,
      "z": 9,
      "name": "Rock_Aqua"
    },
    {
      "x": -1,
      "y": 7,
      "z": 9,
      "name": "Rock_Aqua"
    },
    {
      "x": -1,
      "y": 8,
      "z": 9,
      "name": "Rock_Aqua"
    },
    {
      "x": -1,
      "y": 2,
      "z": 10,
      "name": "Rock_Aqua_Half",
      "rotation": 6
    },
    {
      "x": -1,
      "y": 3,
      "z": 10,
      "name": "Rock_Aqua_Half",
      "rotation": 6
    },
    {
      "x": -1,
      "y": 4,
      "z": 10,
      "name": "Rock_Aqua"
    },
    {
      "x": -1,
      "y": 5,
      "z": 10,
      "name": "Rock_Aqua"
    },
    {
      "x": -1,
      "y": 6,
      "z": 10,
      "name": "Rock_Aqua"
    },
    {
      "x": -1,
      "y": 7,
      "z": 10,
      "name": "Rock_Aqua"
    },
    {
      "x": -1,
      "y": 8,
      "z": 10,
      "name": "Rock_Aqua"
    },
    {
      "x": -1,
      "y": 0,
      "z": 11,
      "name": "Rock_Aqua"
    },
    {
      "x": -1,
      "y": 1,
      "z": 11,
      "name": "Rock_Aqua"
    },
    {
      "x": -1,
      "y": 2,
      "z": 11,
      "name": "Rock_Aqua"
    },
    {
      "x": -1,
      "y": 3,
      "z": 11,
      "name": "Rock_Aqua"
    },
    {
      "x": -1,
      "y": 4,
      "z": 11,
      "name": "Rock_Aqua"
    },
    {
      "x": -1,
      "y": 5,
      "z": 11,
      "name": "Rock_Aqua"
    },
    {
      "x": -1,
      "y": 6,
      "z": 11,
      "name": "Rock_Aqua"
    },
    {
      "x": -1,
      "y": 7,
      "z": 11,
      "name": "Rock_Aqua"
    },
    {
      "x": -1,
      "y": 8,
      "z": 11,
      "name": "Rock_Aqua"
    },
    {
      "x": -1,
      "y": 0,
      "z": 12,
      "name": "Rock_Aqua"
    },
    {
      "x": -1,
      "y": 1,
      "z": 12,
      "name": "Rock_Aqua"
    },
    {
      "x": -1,
      "y": 2,
      "z": 12,
      "name": "Rock_Aqua"
    },
    {
      "x": -1,
      "y": 3,
      "z": 12,
      "name": "Rock_Aqua"
    },
    {
      "x": -1,
      "y": 4,
      "z": 12,
      "name": "Rock_Aqua"
    },
    {
      "x": -1,
      "y": 5,
      "z": 12,
      "name": "Rock_Aqua"
    },
    {
      "x": -1,
      "y": 6,
      "z": 12,
      "name": "Rock_Aqua"
    },
    {
      "x": -1,
      "y": 7,
      "z": 12,
      "name": "Rock_Aqua"
    },
    {
      "x": -1,
      "y": 8,
      "z": 12,
      "name": "Rock_Aqua"
    },
    {
      "x": 0,
      "y": 0,
      "z": -11,
      "name": "Rock_Aqua"
    },
    {
      "x": 0,
      "y": 1,
      "z": -11,
      "name": "Rock_Aqua"
    },
    {
      "x": 0,
      "y": 2,
      "z": -11,
      "name": "Rock_Aqua"
    },
    {
      "x": 0,
      "y": 3,
      "z": -11,
      "name": "Rock_Aqua"
    },
    {
      "x": 0,
      "y": 4,
      "z": -11,
      "name": "Rock_Aqua"
    },
    {
      "x": 0,
      "y": 5,
      "z": -11,
      "name": "Rock_Aqua"
    },
    {
      "x": 0,
      "y": 6,
      "z": -11,
      "name": "Rock_Aqua"
    },
    {
      "x": 0,
      "y": 7,
      "z": -11,
      "name": "Rock_Aqua"
    },
    {
      "x": 0,
      "y": 8,
      "z": -11,
      "name": "Rock_Aqua"
    },
    {
      "x": 0,
      "y": 0,
      "z": -10,
      "name": "Rock_Aqua"
    },
    {
      "x": 0,
      "y": 1,
      "z": -10,
      "name": "Rock_Aqua"
    },
    {
      "x": 0,
      "y": 2,
      "z": -10,
      "name": "Rock_Aqua"
    },
    {
      "x": 0,
      "y": 3,
      "z": -10,
      "name": "Rock_Aqua"
    },
    {
      "x": 0,
      "y": 4,
      "z": -10,
      "name": "Rock_Aqua"
    },
    {
      "x": 0,
      "y": 5,
      "z": -10,
      "name": "Rock_Aqua"
    },
    {
      "x": 0,
      "y": 6,
      "z": -10,
      "name": "Rock_Aqua"
    },
    {
      "x": 0,
      "y": 7,
      "z": -10,
      "name": "Rock_Aqua"
    },
    {
      "x": 0,
      "y": 8,
      "z": -10,
      "name": "Rock_Aqua"
    },
    {
      "x": 0,
      "y": 2,
      "z": -9,
      "name": "Rock_Aqua_Half",
      "rotation": 4
    },
    {
      "x": 0,
      "y": 3,
      "z": -9,
      "name": "Rock_Aqua_Half",
      "rotation": 4
    },
    {
      "x": 0,
      "y": 4,
      "z": -9,
      "name": "Rock_Aqua"
    },
    {
      "x": 0,
      "y": 5,
      "z": -9,
      "name": "Rock_Aqua"
    },
    {
      "x": 0,
      "y": 6,
      "z": -9,
      "name": "Rock_Aqua"
    },
    {
      "x": 0,
      "y": 7,
      "z": -9,
      "name": "Rock_Aqua"
    },
    {
      "x": 0,
      "y": 8,
      "z": -9,
      "name": "Rock_Aqua"
    },
    {
      "x": 0,
      "y": 5,
      "z": -8,
      "name": "Rock_Aqua_Half",
      "rotation": 4
    },
    {
      "x": 0,
      "y": 6,
      "z": -8,
      "name": "Rock_Aqua"
    },
    {
      "x": 0,
      "y": 7,
      "z": -8,
      "name": "Rock_Aqua"
    },
    {
      "x": 0,
      "y": 8,
      "z": -8,
      "name": "Rock_Aqua"
    },
    {
      "x": 0,
      "y": 7,
      "z": -7,
      "name": "Rock_Aqua"
    },
    {
      "x": 0,
      "y": 8,
      "z": -7,
      "name": "Rock_Aqua"
    },
    {
      "x": 0,
      "y": 7,
      "z": -6,
      "name": "Rock_Aqua_Half",
      "rotation": 8
    },
    {
      "x": 0,
      "y": 8,
      "z": -6,
      "name": "Rock_Aqua"
    },
    {
      "x": 0,
      "y": 7,
      "z": -5,
      "name": "Rock_Aqua_Half",
      "rotation": 8
    },
    {
      "x": 0,
      "y": 8,
      "z": -5,
      "name": "Rock_Aqua"
    },
    {
      "x": 0,
      "y": 7,
      "z": -4,
      "name": "Rock_Aqua_Half",
      "rotation": 8
    },
    {
      "x": 0,
      "y": 8,
      "z": -4,
      "name": "Rock_Aqua"
    },
    {
      "x": 0,
      "y": 7,
      "z": -3,
      "name": "Rock_Aqua"
    },
    {
      "x": 0,
      "y": 8,
      "z": -3,
      "name": "Rock_Aqua"
    },
    {
      "x": 0,
      "y": 5,
      "z": -2,
      "name": "Rock_Aqua_Half",
      "rotation": 6
    },
    {
      "x": 0,
      "y": 6,
      "z": -2,
      "name": "Rock_Aqua"
    },
    {
      "x": 0,
      "y": 7,
      "z": -2,
      "name": "Rock_Aqua"
    },
    {
      "x": 0,
      "y": 8,
      "z": -2,
      "name": "Rock_Aqua"
    },
    {
      "x": 0,
      "y": 2,
      "z": -1,
      "name": "Rock_Aqua_Half",
      "rotation": 6
    },
    {
      "x": 0,
      "y": 3,
      "z": -1,
      "name": "Rock_Aqua_Half",
      "rotation": 6
    },
    {
      "x": 0,
      "y": 4,
      "z": -1,
      "name": "Rock_Aqua"
    },
    {
      "x": 0,
      "y": 5,
      "z": -1,
      "name": "Rock_Aqua"
    },
    {
      "x": 0,
      "y": 6,
      "z": -1,
      "name": "Rock_Aqua"
    },
    {
      "x": 0,
      "y": 7,
      "z": -1,
      "name": "Rock_Aqua"
    },
    {
      "x": 0,
      "y": 8,
      "z": -1,
      "name": "Rock_Aqua"
    },
    {
      "x": 0,
      "y": 0,
      "z": 0,
      "name": "Rock_Aqua"
    },
    {
      "x": 0,
      "y": 1,
      "z": 0,
      "name": "Rock_Aqua"
    },
    {
      "x": 0,
      "y": 2,
      "z": 0,
      "name": "Rock_Aqua"
    },
    {
      "x": 0,
      "y": 3,
      "z": 0,
      "name": "Rock_Aqua"
    },
    {
      "x": 0,
      "y": 4,
      "z": 0,
      "name": "Rock_Aqua"
    },
    {
      "x": 0,
      "y": 5,
      "z": 0,
      "name": "Rock_Aqua"
    },
    {
      "x": 0,
      "y": 6,
      "z": 0,
      "name": "Rock_Aqua"
    },
    {
      "x": 0,
      "y": 7,
      "z": 0,
      "name": "Rock_Aqua"
    },
    {
      "x": 0,
      "y": 8,
      "z": 0,
      "name": "Rock_Aqua"
    },
    {
      "x": 0,
      "y": 0,
      "z": 1,
      "name": "Rock_Aqua"
    },
    {
      "x": 0,
      "y": 1,
      "z": 1,
      "name": "Rock_Aqua"
    },
    {
      "x": 0,
      "y": 2,
      "z": 1,
      "name": "Rock_Aqua"
    },
    {
      "x": 0,
      "y": 3,
      "z": 1,
      "name": "Rock_Aqua"
    },
    {
      "x": 0,
      "y": 4,
      "z": 1,
      "name": "Rock_Aqua"
    },
    {
      "x": 0,
      "y": 5,
      "z": 1,
      "name": "Rock_Aqua"
    },
    {
      "x": 0,
      "y": 6,
      "z": 1,
      "name": "Rock_Aqua"
    },
    {
      "x": 0,
      "y": 7,
      "z": 1,
      "name": "Rock_Aqua"
    },
    {
      "x": 0,
      "y": 8,
      "z": 1,
      "name": "Rock_Aqua"
    },
    {
      "x": 0,
      "y": 2,
      "z": 2,
      "name": "Rock_Aqua_Half",
      "rotation": 4
    },
    {
      "x": 0,
      "y": 3,
      "z": 2,
      "name": "Rock_Aqua_Half",
      "rotation": 4
    },
    {
      "x": 0,
      "y": 4,
      "z": 2,
      "name": "Rock_Aqua"
    },
    {
      "x": 0,
      "y": 5,
      "z": 2,
      "name": "Rock_Aqua"
    },
    {
      "x": 0,
      "y": 6,
      "z": 2,
      "name": "Rock_Aqua"
    },
    {
      "x": 0,
      "y": 7,
      "z": 2,
      "name": "Rock_Aqua"
    },
    {
      "x": 0,
      "y": 8,
      "z": 2,
      "name": "Rock_Aqua"
    },
    {
      "x": 0,
      "y": 5,
      "z": 3,
      "name": "Rock_Aqua_Half",
      "rotation": 4
    },
    {
      "x": 0,
      "y": 6,
      "z": 3,
      "name": "Rock_Aqua"
    },
    {
      "x": 0,
      "y": 7,
      "z": 3,
      "name": "Rock_Aqua"
    },
    {
      "x": 0,
      "y": 8,
      "z": 3,
      "name": "Rock_Aqua"
    },
    {
      "x": 0,
      "y": 7,
      "z": 4,
      "name": "Rock_Aqua"
    },
    {
      "x": 0,
      "y": 8,
      "z": 4,
      "name": "Rock_Aqua"
    },
    {
      "x": 0,
      "y": 7,
      "z": 5,
      "name": "Rock_Aqua_Half",
      "rotation": 8
    },
    {
      "x": 0,
      "y": 8,
      "z": 5,
      "name": "Rock_Aqua"
    },
    {
      "x": 0,
      "y": 7,
      "z": 6,
      "name": "Rock_Aqua_Half",
      "rotation": 8
    },
    {
      "x": 0,
      "y": 8,
      "z": 6,
      "name": "Rock_Aqua"
    },
    {
      "x": 0,
      "y": 7,
      "z": 7,
      "name": "Rock_Aqua_Half",
      "rotation": 8
    },
    {
      "x": 0,
      "y": 8,
      "z": 7,
      "name": "Rock_Aqua"
    },
    {
      "x": 0,
      "y": 7,
      "z": 8,
      "name": "Rock_Aqua"
    },
    {
      "x": 0,
      "y": 8,
      "z": 8,
      "name": "Rock_Aqua"
    },
    {
      "x": 0,
      "y": 5,
      "z": 9,
      "name": "Rock_Aqua_Half",
      "rotation": 6
    },
    {
      "x": 0,
      "y": 6,
      "z": 9,
      "name": "Rock_Aqua"
    },
    {
      "x": 0,
      "y": 7,
      "z": 9,
      "name": "Rock_Aqua"
    },
    {
      "x": 0,
      "y": 8,
      "z": 9,
      "name": "Rock_Aqua"
    },
    {
      "x": 0,
      "y": 2,
      "z": 10,
      "name": "Rock_Aqua_Half",
      "rotation": 6
    },
    {
      "x": 0,
      "y": 3,
      "z": 10,
      "name": "Rock_Aqua_Half",
      "rotation": 6
    },
    {
      "x": 0,
      "y": 4,
      "z": 10,
      "name": "Rock_Aqua"
    },
    {
      "x": 0,
      "y": 5,
      "z": 10,
      "name": "Rock_Aqua"
    },
    {
      "x": 0,
      "y": 6,
      "z": 10,
      "name": "Rock_Aqua"
    },
    {
      "x": 0,
      "y": 7,
      "z": 10,
      "name": "Rock_Aqua"
    },
    {
      "x": 0,
      "y": 8,
      "z": 10,
      "name": "Rock_Aqua"
    },
    {
      "x": 0,
      "y": 0,
      "z": 11,
      "name": "Rock_Aqua"
    },
    {
      "x": 0,
      "y": 1,
      "z": 11,
      "name": "Rock_Aqua"
    },
    {
      "x": 0,
      "y": 2,
      "z": 11,
      "name": "Rock_Aqua"
    },
    {
      "x": 0,
      "y": 3,
      "z": 11,
      "name": "Rock_Aqua"
    },
    {
      "x": 0,
      "y": 4,
      "z": 11,
      "name": "Rock_Aqua"
    },
    {
      "x": 0,
      "y": 5,
      "z": 11,
      "name": "Rock_Aqua"
    },
    {
      "x": 0,
      "y": 6,
      "z": 11,
      "name": "Rock_Aqua"
    },
    {
      "x": 0,
      "y": 7,
      "z": 11,
      "name": "Rock_Aqua"
    },
    {
      "x": 0,
      "y": 8,
      "z": 11,
      "name": "Rock_Aqua"
    },
    {
      "x": 0,
      "y": 0,
      "z": 12,
      "name": "Rock_Aqua"
    },
    {
      "x": 0,
      "y": 1,
      "z": 12,
      "name": "Rock_Aqua"
    },
    {
      "x": 0,
      "y": 2,
      "z": 12,
      "name": "Rock_Aqua"
    },
    {
      "x": 0,
      "y": 3,
      "z": 12,
      "name": "Rock_Aqua"
    },
    {
      "x": 0,
      "y": 4,
      "z": 12,
      "name": "Rock_Aqua"
    },
    {
      "x": 0,
      "y": 5,
      "z": 12,
      "name": "Rock_Aqua"
    },
    {
      "x": 0,
      "y": 6,
      "z": 12,
      "name": "Rock_Aqua"
    },
    {
      "x": 0,
      "y": 7,
      "z": 12,
      "name": "Rock_Aqua"
    },
    {
      "x": 0,
      "y": 8,
      "z": 12,
      "name": "Rock_Aqua"
    },
    {
      "x": 1,
      "y": 0,
      "z": -11,
      "name": "Rock_Aqua"
    },
    {
      "x": 1,
      "y": 1,
      "z": -11,
      "name": "Rock_Aqua"
    },
    {
      "x": 1,
      "y": 2,
      "z": -11,
      "name": "Rock_Aqua"
    },
    {
      "x": 1,
      "y": 3,
      "z": -11,
      "name": "Rock_Aqua"
    },
    {
      "x": 1,
      "y": 4,
      "z": -11,
      "name": "Rock_Aqua"
    },
    {
      "x": 1,
      "y": 5,
      "z": -11,
      "name": "Rock_Aqua"
    },
    {
      "x": 1,
      "y": 6,
      "z": -11,
      "name": "Rock_Aqua"
    },
    {
      "x": 1,
      "y": 7,
      "z": -11,
      "name": "Rock_Aqua"
    },
    {
      "x": 1,
      "y": 8,
      "z": -11,
      "name": "Rock_Aqua"
    },
    {
      "x": 1,
      "y": 0,
      "z": -10,
      "name": "Rock_Aqua"
    },
    {
      "x": 1,
      "y": 1,
      "z": -10,
      "name": "Rock_Aqua"
    },
    {
      "x": 1,
      "y": 2,
      "z": -10,
      "name": "Rock_Aqua"
    },
    {
      "x": 1,
      "y": 3,
      "z": -10,
      "name": "Rock_Aqua"
    },
    {
      "x": 1,
      "y": 4,
      "z": -10,
      "name": "Rock_Aqua"
    },
    {
      "x": 1,
      "y": 5,
      "z": -10,
      "name": "Rock_Aqua"
    },
    {
      "x": 1,
      "y": 6,
      "z": -10,
      "name": "Rock_Aqua"
    },
    {
      "x": 1,
      "y": 7,
      "z": -10,
      "name": "Rock_Aqua"
    },
    {
      "x": 1,
      "y": 8,
      "z": -10,
      "name": "Rock_Aqua"
    },
    {
      "x": 1,
      "y": 2,
      "z": -9,
      "name": "Rock_Aqua_Half",
      "rotation": 4
    },
    {
      "x": 1,
      "y": 3,
      "z": -9,
      "name": "Rock_Aqua_Half",
      "rotation": 4
    },
    {
      "x": 1,
      "y": 4,
      "z": -9,
      "name": "Rock_Aqua"
    },
    {
      "x": 1,
      "y": 5,
      "z": -9,
      "name": "Rock_Aqua"
    },
    {
      "x": 1,
      "y": 6,
      "z": -9,
      "name": "Rock_Aqua"
    },
    {
      "x": 1,
      "y": 7,
      "z": -9,
      "name": "Rock_Aqua"
    },
    {
      "x": 1,
      "y": 8,
      "z": -9,
      "name": "Rock_Aqua"
    },
    {
      "x": 1,
      "y": 5,
      "z": -8,
      "name": "Rock_Aqua_Half",
      "rotation": 4
    },
    {
      "x": 1,
      "y": 6,
      "z": -8,
      "name": "Rock_Aqua"
    },
    {
      "x": 1,
      "y": 7,
      "z": -8,
      "name": "Rock_Aqua"
    },
    {
      "x": 1,
      "y": 8,
      "z": -8,
      "name": "Rock_Aqua"
    },
    {
      "x": 1,
      "y": 7,
      "z": -7,
      "name": "Rock_Aqua"
    },
    {
      "x": 1,
      "y": 8,
      "z": -7,
      "name": "Rock_Aqua"
    },
    {
      "x": 1,
      "y": 7,
      "z": -6,
      "name": "Rock_Aqua_Half",
      "rotation": 8
    },
    {
      "x": 1,
      "y": 8,
      "z": -6,
      "name": "Rock_Aqua"
    },
    {
      "x": 1,
      "y": 7,
      "z": -5,
      "name": "Rock_Aqua_Half",
      "rotation": 8
    },
    {
      "x": 1,
      "y": 8,
      "z": -5,
      "name": "Rock_Aqua"
    },
    {
      "x": 1,
      "y": 7,
      "z": -4,
      "name": "Rock_Aqua_Half",
      "rotation": 8
    },
    {
      "x": 1,
      "y": 8,
      "z": -4,
      "name": "Rock_Aqua"
    },
    {
      "x": 1,
      "y": 7,
      "z": -3,
      "name": "Rock_Aqua"
    },
    {
      "x": 1,
      "y": 8,
      "z": -3,
      "name": "Rock_Aqua"
    },
    {
      "x": 1,
      "y": 5,
      "z": -2,
      "name": "Rock_Aqua_Half",
      "rotation": 6
    },
    {
      "x": 1,
      "y": 6,
      "z": -2,
      "name": "Rock_Aqua"
    },
    {
      "x": 1,
      "y": 7,
      "z": -2,
      "name": "Rock_Aqua"
    },
    {
      "x": 1,
      "y": 8,
      "z": -2,
      "name": "Rock_Aqua"
    },
    {
      "x": 1,
      "y": 2,
      "z": -1,
      "name": "Rock_Aqua_Half",
      "rotation": 6
    },
    {
      "x": 1,
      "y": 3,
      "z": -1,
      "name": "Rock_Aqua_Half",
      "rotation": 6
    },
    {
      "x": 1,
      "y": 4,
      "z": -1,
      "name": "Rock_Aqua"
    },
    {
      "x": 1,
      "y": 5,
      "z": -1,
      "name": "Rock_Aqua"
    },
    {
      "x": 1,
      "y": 6,
      "z": -1,
      "name": "Rock_Aqua"
    },
    {
      "x": 1,
      "y": 7,
      "z": -1,
      "name": "Rock_Aqua"
    },
    {
      "x": 1,
      "y": 8,
      "z": -1,
      "name": "Rock_Aqua"
    },
    {
      "x": 1,
      "y": 0,
      "z": 0,
      "name": "Rock_Aqua"
    },
    {
      "x": 1,
      "y": 1,
      "z": 0,
      "name": "Rock_Aqua"
    },
    {
      "x": 1,
      "y": 2,
      "z": 0,
      "name": "Rock_Aqua"
    },
    {
      "x": 1,
      "y": 3,
      "z": 0,
      "name": "Rock_Aqua"
    },
    {
      "x": 1,
      "y": 4,
      "z": 0,
      "name": "Rock_Aqua"
    },
    {
      "x": 1,
      "y": 5,
      "z": 0,
      "name": "Rock_Aqua"
    },
    {
      "x": 1,
      "y": 6,
      "z": 0,
      "name": "Rock_Aqua"
    },
    {
      "x": 1,
      "y": 7,
      "z": 0,
      "name": "Rock_Aqua"
    },
    {
      "x": 1,
      "y": 8,
      "z": 0,
      "name": "Rock_Aqua"
    },
    {
      "x": 1,
      "y": 0,
      "z": 1,
      "name": "Rock_Aqua"
    },
    {
      "x": 1,
      "y": 1,
      "z": 1,
      "name": "Rock_Aqua"
    },
    {
      "x": 1,
      "y": 2,
      "z": 1,
      "name": "Rock_Aqua"
    },
    {
      "x": 1,
      "y": 3,
      "z": 1,
      "name": "Rock_Aqua"
    },
    {
      "x": 1,
      "y": 4,
      "z": 1,
      "name": "Rock_Aqua"
    },
    {
      "x": 1,
      "y": 5,
      "z": 1,
      "name": "Rock_Aqua"
    },
    {
      "x": 1,
      "y": 6,
      "z": 1,
      "name": "Rock_Aqua"
    },
    {
      "x": 1,
      "y": 7,
      "z": 1,
      "name": "Rock_Aqua"
    },
    {
      "x": 1,
      "y": 8,
      "z": 1,
      "name": "Rock_Aqua"
    },
    {
      "x": 1,
      "y": 2,
      "z": 2,
      "name": "Rock_Aqua_Half",
      "rotation": 4
    },
    {
      "x": 1,
      "y": 3,
      "z": 2,
      "name": "Rock_Aqua_Half",
      "rotation": 4
    },
    {
      "x": 1,
      "y": 4,
      "z": 2,
      "name": "Rock_Aqua"
    },
    {
      "x": 1,
      "y": 5,
      "z": 2,
      "name": "Rock_Aqua"
    },
    {
      "x": 1,
      "y": 6,
      "z": 2,
      "name": "Rock_Aqua"
    },
    {
      "x": 1,
      "y": 7,
      "z": 2,
      "name": "Rock_Aqua"
    },
    {
      "x": 1,
      "y": 8,
      "z": 2,
      "name": "Rock_Aqua"
    },
    {
      "x": 1,
      "y": 5,
      "z": 3,
      "name": "Rock_Aqua_Half",
      "rotation": 4
    },
    {
      "x": 1,
      "y": 6,
      "z": 3,
      "name": "Rock_Aqua"
    },
    {
      "x": 1,
      "y": 7,
      "z": 3,
      "name": "Rock_Aqua"
    },
    {
      "x": 1,
      "y": 8,
      "z": 3,
      "name": "Rock_Aqua"
    },
    {
      "x": 1,
      "y": 7,
      "z": 4,
      "name": "Rock_Aqua"
    },
    {
      "x": 1,
      "y": 8,
      "z": 4,
      "name": "Rock_Aqua"
    },
    {
      "x": 1,
      "y": 7,
      "z": 5,
      "name": "Rock_Aqua_Half",
      "rotation": 8
    },
    {
      "x": 1,
      "y": 8,
      "z": 5,
      "name": "Rock_Aqua"
    },
    {
      "x": 1,
      "y": 7,
      "z": 6,
      "name": "Rock_Aqua_Half",
      "rotation": 8
    },
    {
      "x": 1,
      "y": 8,
      "z": 6,
      "name": "Rock_Aqua"
    },
    {
      "x": 1,
      "y": 7,
      "z": 7,
      "name": "Rock_Aqua_Half",
      "rotation": 8
    },
    {
      "x": 1,
      "y": 8,
      "z": 7,
      "name": "Rock_Aqua"
    },
    {
      "x": 1,
      "y": 7,
      "z": 8,
      "name": "Rock_Aqua"
    },
    {
      "x": 1,
      "y": 8,
      "z": 8,
      "name": "Rock_Aqua"
    },
    {
      "x": 1,
      "y": 5,
      "z": 9,
      "name": "Rock_Aqua_Half",
      "rotation": 6
    },
    {
      "x": 1,
      "y": 6,
      "z": 9,
      "name": "Rock_Aqua"
    },
    {
      "x": 1,
      "y": 7,
      "z": 9,
      "name": "Rock_Aqua"
    },
    {
      "x": 1,
      "y": 8,
      "z": 9,
      "name": "Rock_Aqua"
    },
    {
      "x": 1,
      "y": 2,
      "z": 10,
      "name": "Rock_Aqua_Half",
      "rotation": 6
    },
    {
      "x": 1,
      "y": 3,
      "z": 10,
      "name": "Rock_Aqua_Half",
      "rotation": 6
    },
    {
      "x": 1,
      "y": 4,
      "z": 10,
      "name": "Rock_Aqua"
    },
    {
      "x": 1,
      "y": 5,
      "z": 10,
      "name": "Rock_Aqua"
    },
    {
      "x": 1,
      "y": 6,
      "z": 10,
      "name": "Rock_Aqua"
    },
    {
      "x": 1,
      "y": 7,
      "z": 10,
      "name": "Rock_Aqua"
    },
    {
      "x": 1,
      "y": 8,
      "z": 10,
      "name": "Rock_Aqua"
    },
    {
      "x": 1,
      "y": 0,
      "z": 11,
      "name": "Rock_Aqua"
    },
    {
      "x": 1,
      "y": 1,
      "z": 11,
      "name": "Rock_Aqua"
    },
    {
      "x": 1,
      "y": 2,
      "z": 11,
      "name": "Rock_Aqua"
    },
    {
      "x": 1,
      "y": 3,
      "z": 11,
      "name": "Rock_Aqua"
    },
    {
      "x": 1,
      "y": 4,
      "z": 11,
      "name": "Rock_Aqua"
    },
    {
      "x": 1,
      "y": 5,
      "z": 11,
      "name": "Rock_Aqua"
    },
    {
      "x": 1,
      "y": 6,
      "z": 11,
      "name": "Rock_Aqua"
    },
    {
      "x": 1,
      "y": 7,
      "z": 11,
      "name": "Rock_Aqua"
    },
    {
      "x": 1,
      "y": 8,
      "z": 11,
      "name": "Rock_Aqua"
    },
    {
      "x": 1,
      "y": 0,
      "z": 12,
      "name": "Rock_Aqua"
    },
    {
      "x": 1,
      "y": 1,
      "z": 12,
      "name": "Rock_Aqua"
    },
    {
      "x": 1,
      "y": 2,
      "z": 12,
      "name": "Rock_Aqua"
    },
    {
      "x": 1,
      "y": 3,
      "z": 12,
      "name": "Rock_Aqua"
    },
    {
      "x": 1,
      "y": 4,
      "z": 12,
      "name": "Rock_Aqua"
    },
    {
      "x": 1,
      "y": 5,
      "z": 12,
      "name": "Rock_Aqua"
    },
    {
      "x": 1,
      "y": 6,
      "z": 12,
      "name": "Rock_Aqua"
    },
    {
      "x": 1,
      "y": 7,
      "z": 12,
      "name": "Rock_Aqua"
    },
    {
      "x": 1,
      "y": 8,
      "z": 12,
      "name": "Rock_Aqua"
    }
  ]
}