{
  "version": 8,
  "blockIdVersion": 11,
  "anchorX": 0,
  "anchorY": 4,
  "anchorZ": 0,
  "blocks": [
    {
      "x": -6,
      "y": 0,
      "z": 1,
      "name": "*Rock_Aqua_Stairs_State_Definitions_Corner_Left",
      "rotation": 9
    },
    {
      "x": -6,
      "y": 1,
      "z": 1,
      "name": "Rock_Aqua"
    },
    {
      "x": -6,
      "y": 2,
      "z": 1,
      "name": "Rock_Aqua"
    },
    {
      "x": -6,
      "y": 3,
      "z": 1,
      "name": "Rock_Aqua"
    },
    {
      "x": -6,
      "y": 4,
      "z": 1,
      "name": "*Rock_Aqua_Brick_Wall_State_Definitions_Corner",
      "rotation": 1
    },
    {
      "x": -6,
      "y": 0,
      "z": 2,
      "name": "Rock_Aqua_Stairs",
      "rotation": 9
    },
    {
      "x": -6,
      "y": 1,
      "z": 2,
      "name": "Rock_Aqua"
    },
    {
      "x": -6,
      "y": 2,
      "z": 2,
      "name": "Rock_Aqua"
    },
    {
      "x": -6,
      "y": 3,
      "z": 2,
      "name": "Rock_Aqua"
    },
    {
      "x": -6,
      "y": 4,
      "z": 2,
      "name": "Rock_Aqua_Brick_Wall",
      "rotation": 1
    },
    {
      "x": -6,
      "y": 0,
      "z": 3,
      "name": "Rock_Aqua_Stairs",
      "rotation": 9
    },
    {
      "x": -6,
      "y": 1,
      "z": 3,
      "name": "Rock_Aqua"
    },
    {
      "x": -6,
      "y": 2,
      "z": 3,
      "name": "Rock_Aqua"
    },
    {
      "x": -6,
      "y": 3,
      "z": 3,
      "name": "Rock_Aqua"
    },
    {
      "x": -6,
      "y": 4,
      "z": 3,
      "name": "Rock_Aqua_Brick_Wall",
      "rotation": 1
    },
    {
      "x": -6,
      "y": 0,
      "z": 4,
      "name": "Rock_Aqua_Stairs",
      "rotation": 9
    },
    {
      "x": -6,
      "y": 1,
      "z": 4,
      "name": "Rock_Aqua"
    },
    {
      "x": -6,
      "y": 0,
      "z": 5,
      "name": "*Rock_Aqua_Stairs_State_Definitions_Corner_Left",
      "rotation": 10
    },
    {
      "x": -6,
      "y": 1,
      "z": 5,
      "name": "Rock_Aqua"
    },
    {
      "x": -5,
      "y": 0,
      "z": 1,
      "name": "Rock_Aqua_Stairs",
      "rotation": 8
    },
    {
      "x": -5,
      "y": 1,
      "z": 1,
      "name": "Rock_Aqua"
    },
    {
      "x": -5,
      "y": 2,
      "z": 1,
      "name": "Rock_Aqua"
    },
    {
      "x": -5,
      "y": 3,
      "z": 1,
      "name": "Rock_Aqua"
    },
    {
      "x": -5,
      "y": 4,
      "z": 1,
      "name": "Rock_Aqua_Brick_Wall"
    },
    {
      "x": -5,
      "y": 0,
      "z": 2,
      "name": "Rock_Aqua"
    },
    {
      "x": -5,
      "y": 1,
      "z": 2,
      "name": "Rock_Aqua"
    },
    {
      "x": -5,
      "y": 2,
      "z": 2,
      "name": "Rock_Aqua"
    },
    {
      "x": -5,
      "y": 3,
      "z": 2,
      "name": "Rock_Aqua"
    },
    {
      "x": -5,
      "y": 4,
      "z": 2,
      "name": "Empty"
    },
    {
      "x": -5,
      "y": 0,
      "z": 3,
      "name": "Rock_Aqua"
    },
    {
      "x": -5,
      "y": 1,
      "z": 3,
      "name": "Rock_Aqua"
    },
    {
      "x": -5,
      "y": 2,
      "z": 3,
      "name": "Rock_Aqua"
    },
    {
      "x": -5,
      "y": 3,
      "z": 3,
      "name": "Rock_Aqua"
    },
    {
      "x": -5,
      "y": 4,
      "z": 3,
      "name": "Plant_Moss_Short_Blue",
      "support": 15
    },
    {
      "x": -5,
      "y": 0,
      "z": 4,
      "name": "Rock_Aqua"
    },
    {
      "x": -5,
      "y": 1,
      "z": 4,
      "name": "Rock_Aqua"
    },
    {
      "x": -5,
      "y": 2,
      "z": 4,
      "name": "Rock_Aqua"
    },
    {
      "x": -5,
      "y": 3,
      "z": 4,
      "name": "Rock_Aqua"
    },
    {
      "x": -5,
      "y": 4,
      "z": 4,
      "name": "Empty"
    },
    {
      "x": -5,
      "y": 0,
      "z": 5,
      "name": "Rock_Aqua_Stairs",
      "rotation": 10
    },
    {
      "x": -5,
      "y": 1,
      "z": 5,
      "name": "Rock_Aqua"
    },
    {
      "x": -5,
      "y": 2,
      "z": 5,
      "name": "Rock_Aqua"
    },
    {
      "x": -5,
      "y": 3,
      "z": 5,
      "name": "Rock_Aqua"
    },
    {
      "x": -5,
      "y": 4,
      "z": 5,
      "name": "Rock_Aqua_Brick_Decorative"
    },
    {
      "x": -5,
      "y": 5,
      "z": 5,
      "name": "Rock_Aqua_Brick_Smooth_Half"
    },
    {
      "x": -4,
      "y": 0,
      "z": 1,
      "name": "Rock_Aqua_Stairs",
      "rotation": 8
    },
    {
      "x": -4,
      "y": 1,
      "z": 1,
      "name": "Rock_Aqua"
    },
    {
      "x": -4,
      "y": 0,
      "z": 2,
      "name": "Rock_Aqua"
    },
    {
      "x": -4,
      "y": 1,
      "z": 2,
      "name": "Rock_Aqua"
    },
    {
      "x": -4,
      "y": 0,
      "z": 3,
      "name": "Rock_Aqua"
    },
    {
      "x": -4,
      "y": 1,
      "z": 3,
      "name": "Rock_Aqua"
    },
    {
      "x": -4,
      "y": 2,
      "z": 3,
      "name": "Rock_Aqua"
    },
    {
      "x": -4,
      "y": 3,
      "z": 3,
      "name": "Rock_Aqua"
    },
    {
      "x": -4,
      "y": 4,
      "z": 3,
      "name": "Empty"
    },
    {
      "x": -4,
      "y": 0,
      "z": 4,
      "name": "Rock_Aqua"
    },
    {
      "x": -4,
      "y": 1,
      "z": 4,
      "name": "Rock_Aqua"
    },
    {
      "x": -4,
      "y": 2,
      "z": 4,
      "name": "Rock_Aqua"
    },
    {
      "x": -4,
      "y": 3,
      "z": 4,
      "name": "Rock_Aqua"
    },
    {
      "x": -4,
      "y": 4,
      "z": 4,
      "name": "Empty"
    },
    {
      "x": -4,
      "y": 0,
      "z": 5,
      "name": "Rock_Aqua_Stairs",
      "rotation": 10
    },
    {
      "x": -4,
      "y": 1,
      "z": 5,
      "name": "Rock_Aqua"
    },
    {
      "x": -4,
      "y": 2,
      "z": 5,
      "name": "Rock_Aqua"
    },
    {
      "x": -4,
      "y": 3,
      "z": 5,
      "name": "Rock_Aqua"
    },
    {
      "x": -4,
      "y": 4,
      "z": 5,
      "name": "Rock_Aqua_Brick_Decorative"
    },
    {
      "x": -4,
      "y": 5,
      "z": 5,
      "name": "Rock_Aqua_Brick_Smooth"
    },
    {
      "x": -4,
      "y": 6,
      "z": 5,
      "name": "Rock_Aqua_Brick_Smooth"
    },
    {
      "x": -3,
      "y": 0,
      "z": -5,
      "name": "*Rock_Aqua_Stairs_State_Definitions_Corner_Right",
      "rotation": 8
    },
    {
      "x": -3,
      "y": 1,
      "z": -5,
      "name": "Rock_Aqua"
    },
    {
      "x": -3,
      "y": 2,
      "z": -5,
      "name": "Rock_Aqua"
    },
    {
      "x": -3,
      "y": 3,
      "z": -5,
      "name": "Rock_Aqua"
    },
    {
      "x": -3,
      "y": 4,
      "z": -5,
      "name": "Rock_Aqua_Brick_Decorative"
    },
    {
      "x": -3,
      "y": 5,
      "z": -5,
      "name": "Rock_Aqua_Brick_Smooth"
    },
    {
      "x": -3,
      "y": 6,
      "z": -5,
      "name": "Rock_Aqua_Brick_Smooth"
    },
    {
      "x": -3,
      "y": 0,
      "z": -4,
      "name": "Rock_Aqua_Stairs",
      "rotation": 9
    },
    {
      "x": -3,
      "y": 1,
      "z": -4,
      "name": "Rock_Aqua"
    },
    {
      "x": -3,
      "y": 2,
      "z": -4,
      "name": "Rock_Aqua"
    },
    {
      "x": -3,
      "y": 3,
      "z": -4,
      "name": "Rock_Aqua"
    },
    {
      "x": -3,
      "y": 4,
      "z": -4,
      "name": "Rock_Aqua_Brick_Decorative"
    },
    {
      "x": -3,
      "y": 5,
      "z": -4,
      "name": "Rock_Aqua_Brick_Smooth"
    },
    {
      "x": -3,
      "y": 0,
      "z": -3,
      "name": "Rock_Aqua_Stairs",
      "rotation": 9
    },
    {
      "x": -3,
      "y": 1,
      "z": -3,
      "name": "Rock_Aqua"
    },
    {
      "x": -3,
      "y": 2,
      "z": -3,
      "name": "Rock_Aqua"
    },
    {
      "x": -3,
      "y": 3,
      "z": -3,
      "name": "Rock_Aqua"
    },
    {
      "x": -3,
      "y": 4,
      "z": -3,
      "name": "Rock_Aqua_Brick_Smooth_Half"
    },
    {
      "x": -3,
      "y": 0,
      "z": -2,
      "name": "Rock_Aqua_Stairs",
      "rotation": 9
    },
    {
      "x": -3,
      "y": 1,
      "z": -2,
      "name": "Rock_Aqua"
    },
    {
      "x": -3,
      "y": 2,
      "z": -2,
      "name": "Rock_Aqua"
    },
    {
      "x": -3,
      "y": 3,
      "z": -2,
      "name": "Rock_Aqua"
    },
    {
      "x": -3,
      "y": 4,
      "z": -2,
      "name": "Rock_Aqua_Brick_Decorative"
    },
    {
      "x": -3,
      "y": 0,
      "z": -1,
      "name": "*Rock_Aqua_Stairs_State_Definitions_Corner_Left",
      "rotation": 10
    },
    {
      "x": -3,
      "y": 1,
      "z": -1,
      "name": "Rock_Aqua"
    },
    {
      "x": -3,
      "y": 2,
      "z": -1,
      "name": "Rock_Aqua"
    },
    {
      "x": -3,
      "y": 3,
      "z": -1,
      "name": "Rock_Aqua"
    },
    {
      "x": -3,
      "y": 4,
      "z": -1,
      "name": "Rock_Aqua_Brick_Decorative"
    },
    {
      "x": -3,
      "y": 5,
      "z": -1,
      "name": "Rock_Aqua_Brick_Smooth"
    },
    {
      "x": -3,
      "y": 6,
      "z": -1,
      "name": "Rock_Aqua_Cobble_Roof_Flat",
      "rotation": 3
    },
    {
      "x": -3,
      "y": 0,
      "z": 1,
      "name": "Rock_Aqua_Stairs",
      "rotation": 8
    },
    {
      "x": -3,
      "y": 1,
      "z": 1,
      "name": "Rock_Aqua"
    },
    {
      "x": -3,
      "y": 0,
      "z": 2,
      "name": "Rock_Aqua"
    },
    {
      "x": -3,
      "y": 1,
      "z": 2,
      "name": "Rock_Aqua"
    },
    {
      "x": -3,
      "y": 2,
      "z": 2,
      "name": "Rock_Aqua"
    },
    {
      "x": -3,
      "y": 3,
      "z": 2,
      "name": "Rock_Aqua"
    },
    {
      "x": -3,
      "y": 4,
      "z": 2,
      "name": "Empty"
    },
    {
      "x": -3,
      "y": 0,
      "z": 3,
      "name": "Rock_Aqua"
    },
    {
      "x": -3,
      "y": 1,
      "z": 3,
      "name": "Rock_Aqua"
    },
    {
      "x": -3,
      "y": 2,
      "z": 3,
      "name": "Rock_Aqua"
    },
    {
      "x": -3,
      "y": 3,
      "z": 3,
      "name": "Rock_Aqua"
    },
    {
      "x": -3,
      "y": 4,
      "z": 3,
      "name": "Rubble_Aqua_Medium",
      "support": 15
    },
    {
      "x": -3,
      "y": 0,
      "z": 4,
      "name": "Rock_Aqua"
    },
    {
      "x": -3,
      "y": 1,
      "z": 4,
      "name": "Rock_Aqua"
    },
    {
      "x": -3,
      "y": 2,
      "z": 4,
      "name": "Rock_Aqua"
    },
    {
      "x": -3,
      "y": 3,
      "z": 4,
      "name": "Rock_Aqua"
    },
    {
      "x": -3,
      "y": 4,
      "z": 4,
      "name": "Plant_Moss_Short_Blue",
      "support": 15
    },
    {
      "x": -3,
      "y": 0,
      "z": 5,
      "name": "Rock_Aqua_Stairs",
      "rotation": 10
    },
    {
      "x": -3,
      "y": 1,
      "z": 5,
      "name": "Rock_Aqua"
    },
    {
      "x": -3,
      "y": 2,
      "z": 5,
      "name": "Rock_Aqua"
    },
    {
      "x": -3,
      "y": 3,
      "z": 5,
      "name": "Rock_Aqua"
    },
    {
      "x": -3,
      "y": 4,
      "z": 5,
      "name": "Rock_Aqua_Brick_Decorative"
    },
    {
      "x": -3,
      "y": 5,
      "z": 5,
      "name": "Rock_Aqua_Brick_Smooth"
    },
    {
      "x": -3,
      "y": 6,
      "z": 5,
      "name": "Rock_Aqua_Brick_Smooth"
    },
    {
      "x": -2,
      "y": 0,
      "z": -5,
      "name": "Rock_Aqua_Stairs",
      "rotation": 8
    },
    {
      "x": -2,
      "y": 1,
      "z": -5,
      "name": "Rock_Aqua"
    },
    {
      "x": -2,
      "y": 2,
      "z": -5,
      "name": "Rock_Aqua"
    },
    {
      "x": -2,
      "y": 3,
      "z": -5,
      "name": "Rock_Aqua"
    },
    {
      "x": -2,
      "y": 4,
      "z": -5,
      "name": "Rock_Aqua_Brick_Decorative"
    },
    {
      "x": -2,
      "y": 5,
      "z": -5,
      "name": "Rock_Aqua_Brick_Smooth_Half"
    },
    {
      "x": -2,
      "y": 0,
      "z": -4,
      "name": "Rock_Aqua"
    },
    {
      "x": -2,
      "y": 1,
      "z": -4,
      "name": "Rock_Aqua"
    },
    {
      "x": -2,
      "y": 2,
      "z": -4,
      "name": "Rock_Aqua"
    },
    {
      "x": -2,
      "y": 3,
      "z": -4,
      "name": "Rock_Aqua"
    },
    {
      "x": -2,
      "y": 4,
      "z": -4,
      "name": "Empty"
    },
    {
      "x": -2,
      "y": 0,
      "z": -3,
      "name": "Rock_Aqua"
    },
    {
      "x": -2,
      "y": 1,
      "z": -3,
      "name": "Rock_Aqua"
    },
    {
      "x": -2,
      "y": 2,
      "z": -3,
      "name": "Rock_Aqua"
    },
    {
      "x": -2,
      "y": 3,
      "z": -3,
      "name": "Rock_Aqua"
    },
    {
      "x": -2,
      "y": 4,
      "z": -3,
      "name": "Rubble_Aqua",
      "support": 15
    },
    {
      "x": -2,
      "y": 0,
      "z": -2,
      "name": "Rock_Aqua"
    },
    {
      "x": -2,
      "y": 1,
      "z": -2,
      "name": "Rock_Aqua"
    },
    {
      "x": -2,
      "y": 2,
      "z": -2,
      "name": "Rock_Aqua"
    },
    {
      "x": -2,
      "y": 3,
      "z": -2,
      "name": "Rock_Aqua"
    },
    {
      "x": -2,
      "y": 4,
      "z": -2,
      "name": "Plant_Crop_Mushroom_Flatcap_Green",
      "components": {
        "Components": {
          "FarmingBlock": {
            "LastTickGameTime": "0001-01-01T12:00:00Z"
          },
          "PlacedByInteraction": {
            "WhoPlacedUuid": {
              "$binary": "ownTYu6PR7ebL9OJmdXyVA==",
              "$type": "04"
            }
          }
        }
      }
    },
    {
      "x": -2,
      "y": 0,
      "z": -1,
      "name": "Rock_Aqua_Stairs",
      "rotation": 10
    },
    {
      "x": -2,
      "y": 1,
      "z": -1,
      "name": "Rock_Aqua"
    },
    {
      "x": -2,
      "y": 2,
      "z": -1,
      "name": "Rock_Aqua"
    },
    {
      "x": -2,
      "y": 3,
      "z": -1,
      "name": "Rock_Aqua"
    },
    {
      "x": -2,
      "y": 4,
      "z": -1,
      "name": "Rubble_Aqua_Medium",
      "support": 15
    },
    {
      "x": -2,
      "y": 0,
      "z": 1,
      "name": "Rock_Aqua_Stairs",
      "rotation": 8
    },
    {
      "x": -2,
      "y": 1,
      "z": 1,
      "name": "Rock_Aqua"
    },
    {
      "x": -2,
      "y": 2,
      "z": 1,
      "name": "Rock_Aqua"
    },
    {
      "x": -2,
      "y": 3,
      "z": 1,
      "name": "Rock_Aqua"
    },
    {
      "x": -2,
      "y": 4,
      "z": 1,
      "name": "Empty"
    },
    {
      "x": -2,
      "y": 0,
      "z": 2,
      "name": "Rock_Aqua"
    },
    {
      "x": -2,
      "y": 1,
      "z": 2,
      "name": "Rock_Aqua"
    },
    {
      "x": -2,
      "y": 2,
      "z": 2,
      "name": "Rock_Aqua"
    },
    {
      "x": -2,
      "y": 3,
      "z": 2,
      "name": "Rock_Aqua"
    },
    {
      "x": -2,
      "y": 4,
      "z": 2,
      "name": "Empty"
    },
    {
      "x": -2,
      "y": 0,
      "z": 3,
      "name": "Rock_Aqua"
    },
    {
      "x": -2,
      "y": 1,
      "z": 3,
      "name": "Rock_Aqua"
    },
    {
      "x": -2,
      "y": 2,
      "z": 3,
      "name": "Rock_Aqua"
    },
    {
      "x": -2,
      "y": 3,
      "z": 3,
      "name": "Rock_Aqua"
    },
    {
      "x": -2,
      "y": 4,
      "z": 3,
      "name": "Empty"
    },
    {
      "x": -2,
      "y": 0,
      "z": 4,
      "name": "Rock_Aqua"
    },
    {
      "x": -2,
      "y": 1,
      "z": 4,
      "name": "Rock_Aqua"
    },
    {
      "x": -2,
      "y": 2,
      "z": 4,
      "name": "Rock_Aqua"
    },
    {
      "x": -2,
      "y": 3,
      "z": 4,
      "name": "Rock_Aqua"
    },
    {
      "x": -2,
      "y": 4,
      "z": 4,
      "name": "Empty"
    },
    {
      "x": -2,
      "y": 0,
      "z": 5,
      "name": "Rock_Aqua_Stairs",
      "rotation": 10
    },
    {
      "x": -2,
      "y": 1,
      "z": 5,
      "name": "Rock_Aqua"
    },
    {
      "x": -2,
      "y": 2,
      "z": 5,
      "name": "Rock_Aqua"
    },
    {
      "x": -2,
      "y": 3,
      "z": 5,
      "name": "Rock_Aqua"
    },
    {
      "x": -2,
      "y": 4,
      "z": 5,
      "name": "Rock_Aqua_Brick_Decorative"
    },
    {
      "x": -2,
      "y": 5,
      "z": 5,
      "name": "Rock_Aqua_Brick_Smooth"
    },
    {
      "x": -1,
      "y": 0,
      "z": -5,
      "name": "Rock_Aqua_Stairs",
      "rotation": 8
    },
    {
      "x": -1,
      "y": 1,
      "z": -5,
      "name": "Rock_Aqua"
    },
    {
      "x": -1,
      "y": 2,
      "z": -5,
      "name": "Rock_Aqua"
    },
    {
      "x": -1,
      "y": 3,
      "z": -5,
      "name": "Rock_Aqua"
    },
    {
      "x": -1,
      "y": 4,
      "z": -5,
      "name": "Rock_Aqua_Brick_Wall"
    },
    {
      "x": -1,
      "y": 0,
      "z": -4,
      "name": "Rock_Aqua"
    },
    {
      "x": -1,
      "y": 1,
      "z": -4,
      "name": "Rock_Aqua"
    },
    {
      "x": -1,
      "y": 2,
      "z": -4,
      "name": "Rock_Aqua"
    },
    {
      "x": -1,
      "y": 3,
      "z": -4,
      "name": "Rock_Aqua"
    },
    {
      "x": -1,
      "y": 4,
      "z": -4,
      "name": "Plant_Moss_Short_Blue",
      "support": 15
    },
    {
      "x": -1,
      "y": 0,
      "z": -3,
      "name": "Rock_Aqua"
    },
    {
      "x": -1,
      "y": 1,
      "z": -3,
      "name": "Rock_Aqua"
    },
    {
      "x": -1,
      "y": 2,
      "z": -3,
      "name": "Rock_Aqua"
    },
    {
      "x": -1,
      "y": 3,
      "z": -3,
      "name": "Rock_Aqua"
    },
    {
      "x": -1,
      "y": 4,
      "z": -3,
      "name": "Empty"
    },
    {
      "x": -1,
      "y": 0,
      "z": -2,
      "name": "Rock_Aqua"
    },
    {
      "x": -1,
      "y": 1,
      "z": -2,
      "name": "Rock_Aqua"
    },
    {
      "x": -1,
      "y": 2,
      "z": -2,
      "name": "Rock_Aqua"
    },
    {
      "x": -1,
      "y": 3,
      "z": -2,
      "name": "Rock_Aqua"
    },
    {
      "x": -1,
      "y": 4,
      "z": -2,
      "name": "Empty"
    },
    {
      "x": -1,
      "y": 0,
      "z": -1,
      "name": "Rock_Aqua_Stairs",
      "rotation": 10
    },
    {
      "x": -1,
      "y": 1,
      "z": -1,
      "name": "Rock_Aqua"
    },
    {
      "x": -1,
      "y": 2,
      "z": -1,
      "name": "Rock_Aqua"
    },
    {
      "x": -1,
      "y": 3,
      "z": -1,
      "name": "Rock_Aqua"
    },
    {
      "x": -1,
      "y": 4,
      "z": -1,
      "name": "Empty"
    },
    {
      "x": -1,
      "y": 0,
      "z": 1,
      "name": "Rock_Aqua_Stairs",
      "rotation": 8
    },
    {
      "x": -1,
      "y": 1,
      "z": 1,
      "name": "Rock_Aqua"
    },
    {
      "x": -1,
      "y": 2,
      "z": 1,
      "name": "Rock_Aqua"
    },
    {
      "x": -1,
      "y": 3,
      "z": 1,
      "name": "Rock_Aqua"
    },
    {
      "x": -1,
      "y": 4,
      "z": 1,
      "name": "Empty"
    },
    {
      "x": -1,
      "y": 0,
      "z": 2,
      "name": "Rock_Aqua"
    },
    {
      "x": -1,
      "y": 1,
      "z": 2,
      "name": "Rock_Aqua"
    },
    {
      "x": -1,
      "y": 2,
      "z": 2,
      "name": "Rock_Aqua"
    },
    {
      "x": -1,
      "y": 3,
      "z": 2,
      "name": "Rock_Aqua"
    },
    {
      "x": -1,
      "y": 4,
      "z": 2,
      "name": "Rubble_Aqua",
      "support": 15
    },
    {
      "x": -1,
      "y": 0,
      "z": 3,
      "name": "Rock_Aqua"
    },
    {
      "x": -1,
      "y": 1,
      "z": 3,
      "name": "Rock_Aqua"
    },
    {
      "x": -1,
      "y": 0,
      "z": 4,
      "name": "Rock_Aqua"
    },
    {
      "x": -1,
      "y": 1,
      "z": 4,
      "name": "Rock_Aqua"
    },
    {
      "x": -1,
      "y": 0,
      "z": 5,
      "name": "Rock_Aqua_Stairs",
      "rotation": 10
    },
    {
      "x": -1,
      "y": 1,
      "z": 5,
      "name": "Rock_Aqua"
    },
    {
      "x": -1,
      "y": 2,
      "z": 5,
      "name": "Rock_Aqua"
    },
    {
      "x": -1,
      "y": 3,
      "z": 5,
      "name": "Rock_Aqua"
    },
    {
      "x": -1,
      "y": 4,
      "z": 5,
      "name": "Rock_Aqua_Brick_Wall"
    },
    {
      "x": 0,
      "y": 0,
      "z": -5,
      "name": "Rock_Aqua_Stairs",
      "rotation": 8
    },
    {
      "x": 0,
      "y": 1,
      "z": -5,
      "name": "Rock_Aqua"
    },
    {
      "x": 0,
      "y": 2,
      "z": -5,
      "name": "Rock_Aqua"
    },
    {
      "x": 0,
      "y": 3,
      "z": -5,
      "name": "Rock_Aqua"
    },
    {
      "x": 0,
      "y": 4,
      "z": -5,
      "name": "Rock_Aqua_Brick_Wall"
    },
    {
      "x": 0,
      "y": 0,
      "z": -4,
      "name": "Rock_Aqua"
    },
    {
      "x": 0,
      "y": 1,
      "z": -4,
      "name": "Rock_Aqua"
    },
    {
      "x": 0,
      "y": 0,
      "z": -3,
      "name": "Rock_Aqua"
    },
    {
      "x": 0,
      "y": 1,
      "z": -3,
      "name": "Rock_Aqua"
    },
    {
      "x": 0,
      "y": 0,
      "z": -2,
      "name": "Rock_Aqua"
    },
    {
      "x": 0,
      "y": 1,
      "z": -2,
      "name": "Rock_Aqua"
    },
    {
      "x": 0,
      "y": 2,
      "z": -2,
      "name": "Rock_Aqua"
    },
    {
      "x": 0,
      "y": 3,
      "z": -2,
      "name": "Rock_Aqua"
    },
    {
      "x": 0,
      "y": 4,
      "z": -2,
      "name": "Empty"
    },
    {
      "x": 0,
      "y": 0,
      "z": -1,
      "name": "Rock_Aqua_Stairs",
      "rotation": 10
    },
    {
      "x": 0,
      "y": 1,
      "z": -1,
      "name": "Rock_Aqua"
    },
    {
      "x": 0,
      "y": 2,
      "z": -1,
      "name": "Rock_Aqua"
    },
    {
      "x": 0,
      "y": 3,
      "z": -1,
      "name": "Rock_Aqua"
    },
    {
      "x": 0,
      "y": 4,
      "z": -1,
      "name": "Rubble_Aqua",
      "support": 15
    },
    {
      "x": 0,
      "y": 1,
      "z": 0,
      "name": "Rock_Aqua_Brick_Ornate"
    },
    {
      "x": 0,
      "y": 2,
      "z": 0,
      "name": "Rock_Aqua_Brick_Smooth"
    },
    {
      "x": 0,
      "y": 3,
      "z": 0,
      "name": "Rock_Aqua_Brick_Ornate"
    },
    {
      "x": 0,
      "y": 0,
      "z": 1,
      "name": "Rock_Aqua_Stairs",
      "rotation": 8
    },
    {
      "x": 0,
      "y": 1,
      "z": 1,
      "name": "Rock_Aqua"
    },
    {
      "x": 0,
      "y": 2,
      "z": 1,
      "name": "Rock_Aqua"
    },
    {
      "x": 0,
      "y": 3,
      "z": 1,
      "name": "Rock_Aqua"
    },
    {
      "x": 0,
      "y": 4,
      "z": 1,
      "name": "Empty"
    },
    {
      "x": 0,
      "y": 0,
      "z": 2,
      "name": "Rock_Aqua"
    },
    {
      "x": 0,
      "y": 1,
      "z": 2,
      "name": "Rock_Aqua"
    },
    {
      "x": 0,
      "y": 2,
      "z": 2,
      "name": "Rock_Aqua"
    },
    {
      "x": 0,
      "y": 3,
      "z": 2,
      "name": "Rock_Aqua"
    },
    {
      "x": 0,
      "y": 4,
      "z": 2,
      "name": "Empty"
    },
    {
      "x": 0,
      "y": 0,
      "z": 3,
      "name": "Rock_Aqua"
    },
    {
      "x": 0,
      "y": 1,
      "z": 3,
      "name": "Rock_Aqua"
    },
    {
      "x": 0,
      "y": 0,
      "z": 4,
      "name": "Rock_Aqua"
    },
    {
      "x": 0,
      "y": 1,
      "z": 4,
      "name": "Rock_Aqua"
    },
    {
      "x": 0,
      "y": 0,
      "z": 5,
      "name": "Rock_Aqua_Stairs",
      "rotation": 10
    },
    {
      "x": 0,
      "y": 1,
      "z": 5,
      "name": "Rock_Aqua"
    },
    {
      "x": 1,
      "y": 0,
      "z": -5,
      "name": "Rock_Aqua_Stairs",
      "rotation": 8
    },
    {
      "x": 1,
      "y": 1,
      "z": -5,
      "name": "Rock_Aqua"
    },
    {
      "x": 1,
      "y": 0,
      "z": -4,
      "name": "Rock_Aqua"
    },
    {
      "x": 1,
      "y": 1,
      "z": -4,
      "name": "Rock_Aqua"
    },
    {
      "x": 1,
      "y": 0,
      "z": -3,
      "name": "Rock_Aqua"
    },
    {
      "x": 1,
      "y": 1,
      "z": -3,
      "name": "Rock_Aqua"
    },
    {
      "x": 1,
      "y": 0,
      "z": -2,
      "name": "Rock_Aqua"
    },
    {
      "x": 1,
      "y": 1,
      "z": -2,
      "name": "Rock_Aqua"
    },
    {
      "x": 1,
      "y": 2,
      "z": -2,
      "name": "Rock_Aqua"
    },
    {
      "x": 1,
      "y": 3,
      "z": -2,
      "name": "Rock_Aqua"
    },
    {
      "x": 1,
      "y": 4,
      "z": -2,
      "name": "Empty"
    },
    {
      "x": 1,
      "y": 0,
      "z": -1,
      "name": "Rock_Aqua_Stairs",
      "rotation": 10
    },
    {
      "x": 1,
      "y": 1,
      "z": -1,
      "name": "Rock_Aqua"
    },
    {
      "x": 1,
      "y": 2,
      "z": -1,
      "name": "Rock_Aqua"
    },
    {
      "x": 1,
      "y": 3,
      "z": -1,
      "name": "Rock_Aqua"
    },
    {
      "x": 1,
      "y": 4,
      "z": -1,
      "name": "Empty"
    },
    {
      "x": 1,
      "y": 0,
      "z": 1,
      "name": "Rock_Aqua_Stairs",
      "rotation": 8
    },
    {
      "x": 1,
      "y": 1,
      "z": 1,
      "name": "Rock_Aqua"
    },
    {
      "x": 1,
      "y": 2,
      "z": 1,
      "name": "Rock_Aqua"
    },
    {
      "x": 1,
      "y": 3,
      "z": 1,
      "name": "Rock_Aqua"
    },
    {
      "x": 1,
      "y": 4,
      "z": 1,
      "name": "Rubble_Aqua",
      "support": 15
    },
    {
      "x": 1,
      "y": 0,
      "z": 2,
      "name": "Rock_Aqua"
    },
    {
      "x": 1,
      "y": 1,
      "z": 2,
      "name": "Rock_Aqua"
    },
    {
      "x": 1,
      "y": 2,
      "z": 2,
      "name": "Rock_Aqua"
    },
    {
      "x": 1,
      "y": 3,
      "z": 2,
      "name": "Rock_Aqua"
    },
    {
      "x": 1,
      "y": 4,
      "z": 2,
      "name": "Empty"
    },
    {
      "x": 1,
      "y": 0,
      "z": 3,
      "name": "Rock_Aqua"
    },
    {
      "x": 1,
      "y": 1,
      "z": 3,
      "name": "Rock_Aqua"
    },
    {
      "x": 1,
      "y": 0,
      "z": 4,
      "name": "Rock_Aqua"
    },
    {
      "x": 1,
      "y": 1,
      "z": 4,
      "name": "Rock_Aqua"
    },
    {
      "x": 1,
      "y": 0,
      "z": 5,
      "name": "Rock_Aqua_Stairs",
      "rotation": 10
    },
    {
      "x": 1,
      "y": 1,
      "z": 5,
      "name": "Rock_Aqua"
    },
    {
      "x": 2,
      "y": 0,
      "z": -5,
      "name": "Rock_Aqua_Stairs",
      "rotation": 8
    },
    {
      "x": 2,
      "y": 1,
      "z": -5,
      "name": "Rock_Aqua"
    },
    {
      "x": 2,
      "y": 0,
      "z": -4,
      "name": "Rock_Aqua"
    },
    {
      "x": 2,
      "y": 1,
      "z": -4,
      "name": "Rock_Aqua"
    },
    {
      "x": 2,
      "y": 0,
      "z": -3,
      "name": "Rock_Aqua"
    },
    {
      "x": 2,
      "y": 1,
      "z": -3,
      "name": "Rock_Aqua"
    },
    {
      "x": 2,
      "y": 0,
      "z": -2,
      "name": "Rock_Aqua"
    },
    {
      "x": 2,
      "y": 1,
      "z": -2,
      "name": "Rock_Aqua"
    },
    {
      "x": 2,
      "y": 2,
      "z": -2,
      "name": "Rock_Aqua"
    },
    {
      "x": 2,
      "y": 3,
      "z": -2,
      "name": "Rock_Aqua"
    },
    {
      "x": 2,
      "y": 4,
      "z": -2,
      "name": "Empty"
    },
    {
      "x": 2,
      "y": 0,
      "z": -1,
      "name": "Rock_Aqua_Stairs",
      "rotation": 10
    },
    {
      "x": 2,
      "y": 1,
      "z": -1,
      "name": "Rock_Aqua"
    },
    {
      "x": 2,
      "y": 2,
      "z": -1,
      "name": "Rock_Aqua"
    },
    {
      "x": 2,
      "y": 3,
      "z": -1,
      "name": "Rock_Aqua"
    },
    {
      "x": 2,
      "y": 4,
      "z": -1,
      "name": "Rock_Aqua_Brick_Wall"
    },
    {
      "x": 2,
      "y": 0,
      "z": 1,
      "name": "Rock_Aqua_Stairs",
      "rotation": 8
    },
    {
      "x": 2,
      "y": 1,
      "z": 1,
      "name": "Rock_Aqua"
    },
    {
      "x": 2,
      "y": 2,
      "z": 1,
      "name": "Rock_Aqua"
    },
    {
      "x": 2,
      "y": 3,
      "z": 1,
      "name": "Rock_Aqua"
    },
    {
      "x": 2,
      "y": 4,
      "z": 1,
      "name": "Rock_Aqua_Brick_Decorative"
    },
    {
      "x": 2,
      "y": 5,
      "z": 1,
      "name": "Rock_Aqua_Brick_Smooth"
    },
    {
      "x": 2,
      "y": 0,
      "z": 2,
      "name": "Rock_Aqua"
    },
    {
      "x": 2,
      "y": 1,
      "z": 2,
      "name": "Rock_Aqua"
    },
    {
      "x": 2,
      "y": 2,
      "z": 2,
      "name": "Rock_Aqua"
    },
    {
      "x": 2,
      "y": 3,
      "z": 2,
      "name": "Rock_Aqua"
    },
    {
      "x": 2,
      "y": 4,
      "z": 2,
      "name": "Empty"
    },
    {
      "x": 2,
      "y": 0,
      "z": 3,
      "name": "Rock_Aqua"
    },
    {
      "x": 2,
      "y": 1,
      "z": 3,
      "name": "Rock_Aqua"
    },
    {
      "x": 2,
      "y": 2,
      "z": 3,
      "name": "Rock_Aqua"
    },
    {
      "x": 2,
      "y": 3,
      "z": 3,
      "name": "Rock_Aqua"
    },
    {
      "x": 2,
      "y": 4,
      "z": 3,
      "name": "Rubble_Aqua_Medium",
      "support": 15
    },
    {
      "x": 2,
      "y": 0,
      "z": 4,
      "name": "Rock_Aqua"
    },
    {
      "x": 2,
      "y": 1,
      "z": 4,
      "name": "Rock_Aqua"
    },
    {
      "x": 2,
      "y": 0,
      "z": 5,
      "name": "Rock_Aqua_Stairs",
      "rotation": 10
    },
    {
      "x": 2,
      "y": 1,
      "z": 5,
      "name": "Rock_Aqua"
    },
    {
      "x": 3,
      "y": 0,
      "z": -5,
      "name": "Rock_Aqua_Stairs",
      "rotation": 8
    },
    {
      "x": 3,
      "y": 1,
      "z": -5,
      "name": "Rock_Aqua"
    },
    {
      "x": 3,
      "y": 2,
      "z": -5,
      "name": "Rock_Aqua"
    },
    {
      "x": 3,
      "y": 3,
      "z": -5,
      "name": "Rock_Aqua"
    },
    {
      "x": 3,
      "y": 4,
      "z": -5,
      "name": "Rock_Aqua_Brick_Decorative"
    },
    {
      "x": 3,
      "y": 5,
      "z": -5,
      "name": "Rock_Aqua_Brick_Smooth_Half"
    },
    {
      "x": 3,
      "y": 0,
      "z": -4,
      "name": "Rock_Aqua"
    },
    {
      "x": 3,
      "y": 1,
      "z": -4,
      "name": "Rock_Aqua"
    },
    {
      "x": 3,
      "y": 0,
      "z": -3,
      "name": "Rock_Aqua"
    },
    {
      "x": 3,
      "y": 1,
      "z": -3,
      "name": "Rock_Aqua"
    },
    {
      "x": 3,
      "y": 2,
      "z": -3,
      "name": "Rock_Aqua"
    },
    {
      "x": 3,
      "y": 3,
      "z": -3,
      "name": "Rock_Aqua"
    },
    {
      "x": 3,
      "y": 4,
      "z": -3,
      "name": "Empty"
    },
    {
      "x": 3,
      "y": 0,
      "z": -2,
      "name": "Rock_Aqua"
    },
    {
      "x": 3,
      "y": 1,
      "z": -2,
      "name": "Rock_Aqua"
    },
    {
      "x": 3,
      "y": 2,
      "z": -2,
      "name": "Rock_Aqua"
    },
    {
      "x": 3,
      "y": 3,
      "z": -2,
      "name": "Rock_Aqua"
    },
    {
      "x": 3,
      "y": 4,
      "z": -2,
      "name": "Rubble_Aqua_Medium",
      "support": 15
    },
    {
      "x": 3,
      "y": 0,
      "z": -1,
      "name": "Rock_Aqua_Stairs",
      "rotation": 10
    },
    {
      "x": 3,
      "y": 1,
      "z": -1,
      "name": "Rock_Aqua"
    },
    {
      "x": 3,
      "y": 2,
      "z": -1,
      "name": "Rock_Aqua"
    },
    {
      "x": 3,
      "y": 3,
      "z": -1,
      "name": "Rock_Aqua"
    },
    {
      "x": 3,
      "y": 4,
      "z": -1,
      "name": "Rock_Aqua_Brick_Wall"
    },
    {
      "x": 3,
      "y": 0,
      "z": 1,
      "name": "*Rock_Aqua_Stairs_State_Definitions_Corner_Left",
      "rotation": 8
    },
    {
      "x": 3,
      "y": 1,
      "z": 1,
      "name": "Rock_Aqua"
    },
    {
      "x": 3,
      "y": 2,
      "z": 1,
      "name": "Rock_Aqua"
    },
    {
      "x": 3,
      "y": 3,
      "z": 1,
      "name": "Rock_Aqua"
    },
    {
      "x": 3,
      "y": 4,
      "z": 1,
      "name": "Rock_Aqua_Brick_Decorative"
    },
    {
      "x": 3,
      "y": 5,
      "z": 1,
      "name": "Rock_Aqua_Brick_Smooth"
    },
    {
      "x": 3,
      "y": 6,
      "z": 1,
      "name": "Rock_Aqua_Brick_Smooth"
    },
    {
      "x": 3,
      "y": 0,
      "z": 2,
      "name": "Rock_Aqua_Stairs",
      "rotation": 11
    },
    {
      "x": 3,
      "y": 1,
      "z": 2,
      "name": "Rock_Aqua"
    },
    {
      "x": 3,
      "y": 2,
      "z": 2,
      "name": "Rock_Aqua"
    },
    {
      "x": 3,
      "y": 3,
      "z": 2,
      "name": "Rock_Aqua"
    },
    {
      "x": 3,
      "y": 4,
      "z": 2,
      "name": "Rock_Aqua_Brick_Pillar_Base"
    },
    {
      "x": 3,
      "y": 0,
      "z": 3,
      "name": "Rock_Aqua_Stairs",
      "rotation": 11
    },
    {
      "x": 3,
      "y": 1,
      "z": 3,
      "name": "Rock_Aqua"
    },
    {
      "x": 3,
      "y": 2,
      "z": 3,
      "name": "Rock_Aqua"
    },
    {
      "x": 3,
      "y": 3,
      "z": 3,
      "name": "Rock_Aqua"
    },
    {
      "x": 3,
      "y": 4,
      "z": 3,
      "name": "Rock_Aqua_Brick_Decorative"
    },
    {
      "x": 3,
      "y": 5,
      "z": 3,
      "name": "Rock_Aqua_Brick_Pillar_Base"
    },
    {
      "x": 3,
      "y": 6,
      "z": 3,
      "name": "Rock_Aqua_Brick_Beam"
    },
    {
      "x": 3,
      "y": 0,
      "z": 4,
      "name": "Rock_Aqua_Stairs",
      "rotation": 11
    },
    {
      "x": 3,
      "y": 1,
      "z": 4,
      "name": "Rock_Aqua"
    },
    {
      "x": 3,
      "y": 2,
      "z": 4,
      "name": "Rock_Aqua"
    },
    {
      "x": 3,
      "y": 3,
      "z": 4,
      "name": "Rock_Aqua"
    },
    {
      "x": 3,
      "y": 4,
      "z": 4,
      "name": "Empty"
    },
    {
      "x": 3,
      "y": 0,
      "z": 5,
      "name": "*Rock_Aqua_Stairs_State_Definitions_Corner_Left",
      "rotation": 11
    },
    {
      "x": 3,
      "y": 1,
      "z": 5,
      "name": "Rock_Aqua"
    },
    {
      "x": 4,
      "y": 0,
      "z": -5,
      "name": "Rock_Aqua_Stairs",
      "rotation": 8
    },
    {
      "x": 4,
      "y": 1,
      "z": -5,
      "name": "Rock_Aqua"
    },
    {
      "x": 4,
      "y": 2,
      "z": -5,
      "name": "Rock_Aqua"
    },
    {
      "x": 4,
      "y": 3,
      "z": -5,
      "name": "Rock_Aqua"
    },
    {
      "x": 4,
      "y": 4,
      "z": -5,
      "name": "Rock_Aqua_Brick_Decorative"
    },
    {
      "x": 4,
      "y": 5,
      "z": -5,
      "name": "Rock_Aqua_Brick_Smooth"
    },
    {
      "x": 4,
      "y": 6,
      "z": -5,
      "name": "Rock_Aqua_Brick_Beam"
    },
    {
      "x": 4,
      "y": 0,
      "z": -4,
      "name": "Rock_Aqua"
    },
    {
      "x": 4,
      "y": 1,
      "z": -4,
      "name": "Rock_Aqua"
    },
    {
      "x": 4,
      "y": 2,
      "z": -4,
      "name": "Rock_Aqua"
    },
    {
      "x": 4,
      "y": 3,
      "z": -4,
      "name": "Rock_Aqua"
    },
    {
      "x": 4,
      "y": 4,
      "z": -4,
      "name": "Empty"
    },
    {
      "x": 4,
      "y": 0,
      "z": -3,
      "name": "Rock_Aqua"
    },
    {
      "x": 4,
      "y": 1,
      "z": -3,
      "name": "Rock_Aqua"
    },
    {
      "x": 4,
      "y": 2,
      "z": -3,
      "name": "Rock_Aqua"
    },
    {
      "x": 4,
      "y": 3,
      "z": -3,
      "name": "Rock_Aqua"
    },
    {
      "x": 4,
      "y": 4,
      "z": -3,
      "name": "Empty"
    },
    {
      "x": 4,
      "y": 0,
      "z": -2,
      "name": "Rock_Aqua"
    },
    {
      "x": 4,
      "y": 1,
      "z": -2,
      "name": "Rock_Aqua"
    },
    {
      "x": 4,
      "y": 2,
      "z": -2,
      "name": "Rock_Aqua"
    },
    {
      "x": 4,
      "y": 3,
      "z": -2,
      "name": "Rock_Aqua"
    },
    {
      "x": 4,
      "y": 4,
      "z": -2,
      "name": "Empty"
    },
    {
      "x": 4,
      "y": 0,
      "z": -1,
      "name": "Rock_Aqua_Stairs",
      "rotation": 10
    },
    {
      "x": 4,
      "y": 1,
      "z": -1,
      "name": "Rock_Aqua"
    },
    {
      "x": 4,
      "y": 2,
      "z": -1,
      "name": "Rock_Aqua"
    },
    {
      "x": 4,
      "y": 3,
      "z": -1,
      "name": "Rock_Aqua"
    },
    {
      "x": 4,
      "y": 4,
      "z": -1,
      "name": "Empty"
    },
    {
      "x": 5,
      "y": 0,
      "z": -5,
      "name": "Rock_Aqua_Stairs",
      "rotation": 8
    },
    {
      "x": 5,
      "y": 1,
      "z": -5,
      "name": "Rock_Aqua"
    },
    {
      "x": 5,
      "y": 2,
      "z": -5,
      "name": "Rock_Aqua"
    },
    {
      "x": 5,
      "y": 3,
      "z": -5,
      "name": "Rock_Aqua"
    },
    {
      "x": 5,
      "y": 4,
      "z": -5,
      "name": "Rubble_Aqua",
      "support": 15
    },
    {
      "x": 5,
      "y": 0,
      "z": -4,
      "name": "Rock_Aqua"
    },
    {
      "x": 5,
      "y": 1,
      "z": -4,
      "name": "Rock_Aqua"
    },
    {
      "x": 5,
      "y": 2,
      "z": -4,
      "name": "Rock_Aqua"
    },
    {
      "x": 5,
      "y": 3,
      "z": -4,
      "name": "Rock_Aqua"
    },
    {
      "x": 5,
      "y": 4,
      "z": -4,
      "name": "Empty"
    },
    {
      "x": 5,
      "y": 0,
      "z": -3,
      "name": "Rock_Aqua"
    },
    {
      "x": 5,
      "y": 1,
      "z": -3,
      "name": "Rock_Aqua"
    },
    {
      "x": 5,
      "y": 2,
      "z": -3,
      "name": "Rock_Aqua"
    },
    {
      "x": 5,
      "y": 3,
      "z": -3,
      "name": "Rock_Aqua"
    },
    {
      "x": 5,
      "y": 4,
      "z": -3,
      "name": "Rubble_Aqua",
      "support": 15
    },
    {
      "x": 5,
      "y": 0,
      "z": -2,
      "name": "Rock_Aqua"
    },
    {
      "x": 5,
      "y": 1,
      "z": -2,
      "name": "Rock_Aqua"
    },
    {
      "x": 5,
      "y": 2,
      "z": -2,
      "name": "Rock_Aqua"
    },
    {
      "x": 5,
      "y": 3,
      "z": -2,
      "name": "Rock_Aqua"
    },
    {
      "x": 5,
      "y": 4,
      "z": -2,
      "name": "Empty"
    },
    {
      "x": 5,
      "y": 0,
      "z": -1,
      "name": "Rock_Aqua_Stairs",
      "rotation": 10
    },
    {
      "x": 5,
      "y": 1,
      "z": -1,
      "name": "Rock_Aqua"
    },
    {
      "x": 5,
      "y": 2,
      "z": -1,
      "name": "Rock_Aqua"
    },
    {
      "x": 5,
      "y": 3,
      "z": -1,
      "name": "Rock_Aqua"
    },
    {
      "x": 5,
      "y": 4,
      "z": -1,
      "name": "Rock_Aqua_Brick_Wall"
    },
    {
      "x": 6,
      "y": 0,
      "z": -5,
      "name": "*Rock_Aqua_Stairs_State_Definitions_Corner_Right",
      "rotation": 11
    },
    {
      "x": 6,
      "y": 1,
      "z": -5,
      "name": "Rock_Aqua"
    },
    {
      "x": 6,
      "y": 0,
      "z": -4,
      "name": "Rock_Aqua_Stairs",
      "rotation": 11
    },
    {
      "x": 6,
      "y": 1,
      "z": -4,
      "name": "Rock_Aqua"
    },
    {
      "x": 6,
      "y": 2,
      "z": -4,
      "name": "Rock_Aqua"
    },
    {
      "x": 6,
      "y": 3,
      "z": -4,
      "name": "Rock_Aqua"
    },
    {
      "x": 6,
      "y": 4,
      "z": -4,
      "name": "Empty"
    },
    {
      "x": 6,
      "y": 0,
      "z": -3,
      "name": "Rock_Aqua_Stairs",
      "rotation": 11
    },
    {
      "x": 6,
      "y": 1,
      "z": -3,
      "name": "Rock_Aqua"
    },
    {
      "x": 6,
      "y": 2,
      "z": -3,
      "name": "Rock_Aqua"
    },
    {
      "x": 6,
      "y": 3,
      "z": -3,
      "name": "Rock_Aqua"
    },
    {
      "x": 6,
      "y": 4,
      "z": -3,
      "name": "Rock_Aqua_Brick_Wall",
      "rotation": 1
    },
    {
      "x": 6,
      "y": 0,
      "z": -2,
      "name": "Rock_Aqua_Stairs",
      "rotation": 11
    },
    {
      "x": 6,
      "y": 1,
      "z": -2,
      "name": "Rock_Aqua"
    },
    {
      "x": 6,
      "y": 2,
      "z": -2,
      "name": "Rock_Aqua"
    },
    {
      "x": 6,
      "y": 3,
      "z": -2,
      "name": "Rock_Aqua"
    },
    {
      "x": 6,
      "y": 4,
      "z": -2,
      "name": "Rock_Aqua_Brick_Decorative"
    },
    {
      "x": 6,
      "y": 0,
      "z": -1,
      "name": "*Rock_Aqua_Stairs_State_Definitions_Corner_Right",
      "rotation": 10
    },
    {
      "x": 6,
      "y": 1,
      "z": -1,
      "name": "Rock_Aqua"
    },
    {
      "x": 6,
      "y": 2,
      "z": -1,
      "name": "Rock_Aqua"
    },
    {
      "x": 6,
      "y": 3,
      "z": -1,
      "name": "Rock_Aqua"
    },
    {
      "x": 6,
      "y": 4,
      "z": -1,
      "name": "Rock_Aqua_Brick_Decorative"
    },
    {
      "x": 6,
      "y": 5,
      "z": -1,
      "name": "Rock_Aqua_Brick_Smooth"
    },
    {
      "x": 6,
      "y": 6,
      "z": -1,
      "name": "Rock_Aqua_Cobble_Roof_Flat",
      "rotation": 3
    }
  ],
  "fluids": [
    {
      "x": -6,
      "y": 0,
      "z": 1,
      "name": "Water_Source",
      "level": 1
    },
    {
      "x": -6,
      "y": 4,
      "z": 1,
      "name": "Water_Source",
      "level": 1
    },
    {
      "x": -6,
      "y": 0,
      "z": 2,
      "name": "Water_Source",
      "level": 1
    },
    {
      "x": -6,
      "y": 4,
      "z": 2,
      "name": "Water_Source",
      "level": 1
    },
    {
      "x": -6,
      "y": 0,
      "z": 3,
      "name": "Water_Source",
      "level": 1
    },
    {
      "x": -6,
      "y": 4,
      "z": 3,
      "name": "Water_Source",
      "level": 1
    },
    {
      "x": -6,
      "y": 0,
      "z": 4,
      "name": "Water_Source",
      "level": 1
    },
    {
      "x": -6,
      "y": 0,
      "z": 5,
      "name": "Water_Source",
      "level": 1
    },
    {
      "x": -5,
      "y": 0,
      "z": 1,
      "name": "Water_Source",
      "level": 1
    },
    {
      "x": -5,
      "y": 4,
      "z": 1,
      "name": "Water_Source",
      "level": 1
    },
    {
      "x": -5,
      "y": 4,
      "z": 2,
      "name": "Water_Source",
      "level": 1
    },
    {
      "x": -5,
      "y": 4,
      "z": 3,
      "name": "Water_Source",
      "level": 1
    },
    {
      "x": -5,
      "y": 4,
      "z": 4,
      "name": "Water_Source",
      "level": 1
    },
    {
      "x": -5,
      "y": 0,
      "z": 5,
      "name": "Water_Source",
      "level": 1
    },
    {
      "x": -5,
      "y": 5,
      "z": 5,
      "name": "Water_Source",
      "level": 1
    },
    {
      "x": -4,
      "y": 0,
      "z": 1,
      "name": "Water_Source",
      "level": 1
    },
    {
      "x": -4,
      "y": 4,
      "z": 3,
      "name": "Water_Source",
      "level": 1
    },
    {
      "x": -4,
      "y": 4,
      "z": 4,
      "name": "Water_Source",
      "level": 1
    },
    {
      "x": -4,
      "y": 0,
      "z": 5,
      "name": "Water_Source",
      "level": 1
    },
    {
      "x": -3,
      "y": 0,
      "z": -5,
      "name": "Water_Source",
      "level": 1
    },
    {
      "x": -3,
      "y": 0,
      "z": -4,
      "name": "Water_Source",
      "level": 1
    },
    {
      "x": -3,
      "y": 0,
      "z": -3,
      "name": "Water_Source",
      "level": 1
    },
    {
      "x": -3,
      "y": 4,
      "z": -3,
      "name": "Water_Source",
      "level": 1
    },
    {
      "x": -3,
      "y": 0,
      "z": -2,
      "name": "Water_Source",
      "level": 1
    },
    {
      "x": -3,
      "y": 0,
      "z": -1,
      "name": "Water_Source",
      "level": 1
    },
    {
      "x": -3,
      "y": 6,
      "z": -1,
      "name": "Water_Source",
      "level": 1
    },
    {
      "x": -3,
      "y": 0,
      "z": 1,
      "name": "Water_Source",
      "level": 1
    },
    {
      "x": -3,
      "y": 4,
      "z": 2,
      "name": "Water_Source",
      "level": 1
    },
    {
      "x": -3,
      "y": 4,
      "z": 3,
      "name": "Water_Source",
      "level": 1
    },
    {
      "x": -3,
      "y": 4,
      "z": 4,
      "name": "Water_Source",
      "level": 1
    },
    {
      "x": -3,
      "y": 0,
      "z": 5,
      "name": "Water_Source",
      "level": 1
    },
    {
      "x": -2,
      "y": 0,
      "z": -5,
      "name": "Water_Source",
      "level": 1
    },
    {
      "x": -2,
      "y": 5,
      "z": -5,
      "name": "Water_Source",
      "level": 1
    },
    {
      "x": -2,
      "y": 4,
      "z": -4,
      "name": "Water_Source",
      "level": 1
    },
    {
      "x": -2,
      "y": 4,
      "z": -3,
      "name": "Water_Source",
      "level": 1
    },
    {
      "x": -2,
      "y": 4,
      "z": -2,
      "name": "Water_Source",
      "level": 1
    },
    {
      "x": -2,
      "y": 0,
      "z": -1,
      "name": "Water_Source",
      "level": 1
    },
    {
      "x": -2,
      "y": 4,
      "z": -1,
      "name": "Water_Source",
      "level": 1
    },
    {
      "x": -2,
      "y": 0,
      "z": 1,
      "name": "Water_Source",
      "level": 1
    },
    {
      "x": -2,
      "y": 4,
      "z": 1,
      "name": "Water_Source",
      "level": 1
    },
    {
      "x": -2,
      "y": 4,
      "z": 2,
      "name": "Water_Source",
      "level": 1
    },
    {
      "x": -2,
      "y": 4,
      "z": 3,
      "name": "Water_Source",
      "level": 1
    },
    {
      "x": -2,
      "y": 4,
      "z": 4,
      "name": "Water_Source",
      "level": 1
    },
    {
      "x": -2,
      "y": 0,
      "z": 5,
      "name": "Water_Source",
      "level": 1
    },
    {
      "x": -1,
      "y": 0,
      "z": -5,
      "name": "Water_Source",
      "level": 1
    },
    {
      "x": -1,
      "y": 4,
      "z": -5,
      "name": "Water_Source",
      "level": 1
    },
    {
      "x": -1,
      "y": 4,
      "z": -4,
      "name": "Water_Source",
      "level": 1
    },
    {
      "x": -1,
      "y": 4,
      "z": -3,
      "name": "Water_Source",
      "level": 1
    },
    {
      "x": -1,
      "y": 4,
      "z": -2,
      "name": "Water_Source",
      "level": 1
    },
    {
      "x": -1,
      "y": 0,
      "z": -1,
      "name": "Water_Source",
      "level": 1
    },
    {
      "x": -1,
      "y": 4,
      "z": -1,
      "name": "Water_Source",
      "level": 1
    },
    {
      "x": -1,
      "y": 0,
      "z": 1,
      "name": "Water_Source",
      "level": 1
    },
    {
      "x": -1,
      "y": 4,
      "z": 1,
      "name": "Water_Source",
      "level": 1
    },
    {
      "x": -1,
      "y": 4,
      "z": 2,
      "name": "Water_Source",
      "level": 1
    },
    {
      "x": -1,
      "y": 0,
      "z": 5,
      "name": "Water_Source",
      "level": 1
    },
    {
      "x": -1,
      "y": 4,
      "z": 5,
      "name": "Water_Source",
      "level": 1
    },
    {
      "x": 0,
      "y": 0,
      "z": -5,
      "name": "Water_Source",
      "level": 1
    },
    {
      "x": 0,
      "y": 4,
      "z": -5,
      "name": "Water_Source",
      "level": 1
    },
    {
      "x": 0,
      "y": 4,
      "z": -2,
      "name": "Water_Source",
      "level": 1
    },
    {
      "x": 0,
      "y": 0,
      "z": -1,
      "name": "Water_Source",
      "level": 1
    },
    {
      "x": 0,
      "y": 4,
      "z": -1,
      "name": "Water_Source",
      "level": 1
    },
    {
      "x": 0,
      "y": 0,
      "z": 1,
      "name": "Water_Source",
      "level": 1
    },
    {
      "x": 0,
      "y": 4,
      "z": 1,
      "name": "Water_Source",
      "level": 1
    },
    {
      "x": 0,
      "y": 4,
      "z": 2,
      "name": "Water_Source",
      "level": 1
    },
    {
      "x": 0,
      "y": 0,
      "z": 5,
      "name": "Water_Source",
      "level": 1
    },
    {
      "x": 1,
      "y": 0,
      "z": -5,
      "name": "Water_Source",
      "level": 1
    },
    {
      "x": 1,
      "y": 4,
      "z": -2,
      "name": "Water_Source",
      "level": 1
    },
    {
      "x": 1,
      "y": 0,
      "z": -1,
      "name": "Water_Source",
      "level": 1
    },
    {
      "x": 1,
      "y": 4,
      "z": -1,
      "name": "Water_Source",
      "level": 1
    },
    {
      "x": 1,
      "y": 0,
      "z": 1,
      "name": "Water_Source",
      "level": 1
    },
    {
      "x": 1,
      "y": 4,
      "z": 1,
      "name": "Water_Source",
      "level": 1
    },
    {
      "x": 1,
      "y": 4,
      "z": 2,
      "name": "Water_Source",
      "level": 1
    },
    {
      "x": 1,
      "y": 0,
      "z": 5,
      "name": "Water_Source",
      "level": 1
    },
    {
      "x": 2,
      "y": 0,
      "z": -5,
      "name": "Water_Source",
      "level": 1
    },
    {
      "x": 2,
      "y": 4,
      "z": -2,
      "name": "Water_Source",
      "level": 1
    },
    {
      "x": 2,
      "y": 0,
      "z": -1,
      "name": "Water_Source",
      "level": 1
    },
    {
      "x": 2,
      "y": 4,
      "z": -1,
      "name": "Water_Source",
      "level": 1
    },
    {
      "x": 2,
      "y": 0,
      "z": 1,
      "name": "Water_Source",
      "level": 1
    },
    {
      "x": 2,
      "y": 4,
      "z": 2,
      "name": "Water_Source",
      "level": 1
    },
    {
      "x": 2,
      "y": 4,
      "z": 3,
      "name": "Water_Source",
      "level": 1
    },
    {
      "x": 2,
      "y": 0,
      "z": 5,
      "name": "Water_Source",
      "level": 1
    },
    {
      "x": 3,
      "y": 0,
      "z": -5,
      "name": "Water_Source",
      "level": 1
    },
    {
      "x": 3,
      "y": 5,
      "z": -5,
      "name": "Water_Source",
      "level": 1
    },
    {
      "x": 3,
      "y": 4,
      "z": -3,
      "name": "Water_Source",
      "level": 1
    },
    {
      "x": 3,
      "y": 4,
      "z": -2,
      "name": "Water_Source",
      "level": 1
    },
    {
      "x": 3,
      "y": 0,
      "z": -1,
      "name": "Water_Source",
      "level": 1
    },
    {
      "x": 3,
      "y": 4,
      "z": -1,
      "name": "Water_Source",
      "level": 1
    },
    {
      "x": 3,
      "y": 0,
      "z": 1,
      "name": "Water_Source",
      "level": 1
    },
    {
      "x": 3,
      "y": 0,
      "z": 2,
      "name": "Water_Source",
      "level": 1
    },
    {
      "x": 3,
      "y": 4,
      "z": 2,
      "name": "Water_Source",
      "level": 1
    },
    {
      "x": 3,
      "y": 0,
      "z": 3,
      "name": "Water_Source",
      "level": 1
    },
    {
      "x": 3,
      "y": 5,
      "z": 3,
      "name": "Water_Source",
      "level": 1
    },
    {
      "x": 3,
      "y": 6,
      "z": 3,
      "name": "Water_Source",
      "level": 1
    },
    {
      "x": 3,
      "y": 0,
      "z": 4,
      "name": "Water_Source",
      "level": 1
    },
    {
      "x": 3,
      "y": 4,
      "z": 4,
      "name": "Water_Source",
      "level": 1
    },
    {
      "x": 3,
      "y": 0,
      "z": 5,
      "name": "Water_Source",
      "level": 1
    },
    {
      "x": 4,
      "y": 0,
      "z": -5,
      "name": "Water_Source",
      "level": 1
    },
    {
      "x": 4,
      "y": 6,
      "z": -5,
      "name": "Water_Source",
      "level": 1
    },
    {
      "x": 4,
      "y": 4,
      "z": -4,
      "name": "Water_Source",
      "level": 1
    },
    {
      "x": 4,
      "y": 4,
      "z": -3,
      "name": "Water_Source",
      "level": 1
    },
    {
      "x": 4,
      "y": 4,
      "z": -2,
      "name": "Water_Source",
      "level": 1
    },
    {
      "x": 4,
      "y": 0,
      "z": -1,
      "name": "Water_Source",
      "level": 1
    },
    {
      "x": 4,
      "y": 4,
      "z": -1,
      "name": "Water_Source",
      "level": 1
    },
    {
      "x": 5,
      "y": 0,
      "z": -5,
      "name": "Water_Source",
      "level": 1
    },
    {
      "x": 5,
      "y": 4,
      "z": -5,
      "name": "Water_Source",
      "level": 1
    },
    {
      "x": 5,
      "y": 4,
      "z": -4,
      "name": "Water_Source",
      "level": 1
    },
    {
      "x": 5,
      "y": 4,
      "z": -3,
      "name": "Water_Source",
      "level": 1
    },
    {
      "x": 5,
      "y": 4,
      "z": -2,
      "name": "Water_Source",
      "level": 1
    },
    {
      "x": 5,
      "y": 0,
      "z": -1,
      "name": "Water_Source",
      "level": 1
    },
    {
      "x": 5,
      "y": 4,
      "z": -1,
      "name": "Water_Source",
      "level": 1
    },
    {
      "x": 6,
      "y": 0,
      "z": -5,
      "name": "Water_Source",
      "level": 1
    },
    {
      "x": 6,
      "y": 0,
      "z": -4,
      "name": "Water_Source",
      "level": 1
    },
    {
      "x": 6,
      "y": 4,
      "z": -4,
      "name": "Water_Source",
      "level": 1
    },
    {
      "x": 6,
      "y": 0,
      "z": -3,
      "name": "Water_Source",
      "level": 1
    },
    {
      "x": 6,
      "y": 4,
      "z": -3,
      "name": "Water_Source",
      "level": 1
    },
    {
      "x": 6,
      "y": 0,
      "z": -2,
      "name": "Water_Source",
      "level": 1
    },
    {
      "x": 6,
      "y": 0,
      "z": -1,
      "name": "Water_Source",
      "level": 1
    },
    {
      "x": 6,
      "y": 6,
      "z": -1,
      "name": "Water_Source",
      "level": 1
    }
  ]
}