{
  "version": 8,
  "blockIdVersion": 11,
  "anchorX": 0,
  "anchorY": 4,
  "anchorZ": 0,
  "blocks": [
    {
      "x": -6,
      "y": 0,
      "z": -1,
      "name": "*Rock_Aqua_Stairs_State_Definitions_Corner_Right",
      "rotation": 8
    },
    {
      "x": -6,
      "y": 1,
      "z": -1,
      "name": "Rock_Aqua"
    },
    {
      "x": -6,
      "y": 2,
      "z": -1,
      "name": "Rock_Aqua"
    },
    {
      "x": -6,
      "y": 3,
      "z": -1,
      "name": "Rock_Aqua"
    },
    {
      "x": -6,
      "y": 4,
      "z": -1,
      "name": "Rock_Aqua_Brick_Decorative"
    },
    {
      "x": -6,
      "y": 5,
      "z": -1,
      "name": "Rock_Aqua_Brick"
    },
    {
      "x": -6,
      "y": 6,
      "z": -1,
      "name": "Rock_Aqua_Brick_Smooth"
    },
    {
      "x": -6,
      "y": 7,
      "z": -1,
      "name": "Rock_Aqua_Cobble_Roof_Shallow",
      "rotation": 3
    },
    {
      "x": -6,
      "y": 0,
      "z": 0,
      "name": "Rock_Aqua_Stairs",
      "rotation": 9
    },
    {
      "x": -6,
      "y": 1,
      "z": 0,
      "name": "Rock_Aqua"
    },
    {
      "x": -6,
      "y": 2,
      "z": 0,
      "name": "Rock_Aqua"
    },
    {
      "x": -6,
      "y": 3,
      "z": 0,
      "name": "Rock_Aqua"
    },
    {
      "x": -6,
      "y": 4,
      "z": 0,
      "name": "Rock_Aqua_Brick_Decorative"
    },
    {
      "x": -6,
      "y": 5,
      "z": 0,
      "name": "Rubble_Aqua",
      "support": 15
    },
    {
      "x": -6,
      "y": 0,
      "z": 1,
      "name": "Rock_Aqua_Stairs",
      "rotation": 9
    },
    {
      "x": -6,
      "y": 1,
      "z": 1,
      "name": "Rock_Aqua"
    },
    {
      "x": -6,
      "y": 2,
      "z": 1,
      "name": "Rock_Aqua"
    },
    {
      "x": -6,
      "y": 3,
      "z": 1,
      "name": "Rock_Aqua"
    },
    {
      "x": -6,
      "y": 4,
      "z": 1,
      "name": "Empty"
    },
    {
      "x": -6,
      "y": 0,
      "z": 2,
      "name": "Rock_Aqua_Stairs",
      "rotation": 9
    },
    {
      "x": -6,
      "y": 1,
      "z": 2,
      "name": "Rock_Aqua"
    },
    {
      "x": -6,
      "y": 2,
      "z": 2,
      "name": "Rock_Aqua"
    },
    {
      "x": -6,
      "y": 3,
      "z": 2,
      "name": "Rock_Aqua"
    },
    {
      "x": -6,
      "y": 4,
      "z": 2,
      "name": "Empty"
    },
    {
      "x": -6,
      "y": 0,
      "z": 3,
      "name": "Rock_Aqua_Stairs",
      "rotation": 9
    },
    {
      "x": -6,
      "y": 1,
      "z": 3,
      "name": "Rock_Aqua"
    },
    {
      "x": -6,
      "y": 0,
      "z": 4,
      "name": "Rock_Aqua_Stairs",
      "rotation": 9
    },
    {
      "x": -6,
      "y": 1,
      "z": 4,
      "name": "Rock_Aqua"
    },
    {
      "x": -6,
      "y": 0,
      "z": 5,
      "name": "*Rock_Aqua_Stairs_State_Definitions_Corner_Left",
      "rotation": 10
    },
    {
      "x": -6,
      "y": 1,
      "z": 5,
      "name": "Rock_Aqua"
    },
    {
      "x": -6,
      "y": 2,
      "z": 5,
      "name": "Rock_Aqua"
    },
    {
      "x": -6,
      "y": 3,
      "z": 5,
      "name": "Rock_Aqua"
    },
    {
      "x": -6,
      "y": 4,
      "z": 5,
      "name": "Empty"
    },
    {
      "x": -5,
      "y": 0,
      "z": -1,
      "name": "Rock_Aqua_Stairs",
      "rotation": 8
    },
    {
      "x": -5,
      "y": 1,
      "z": -1,
      "name": "Rock_Aqua"
    },
    {
      "x": -5,
      "y": 2,
      "z": -1,
      "name": "Rock_Aqua"
    },
    {
      "x": -5,
      "y": 3,
      "z": -1,
      "name": "Rock_Aqua"
    },
    {
      "x": -5,
      "y": 4,
      "z": -1,
      "name": "Rock_Aqua_Brick_Smooth_Half"
    },
    {
      "x": -5,
      "y": 6,
      "z": -1,
      "name": "Rock_Aqua_Stairs",
      "rotation": 11
    },
    {
      "x": -5,
      "y": 7,
      "z": -1,
      "name": "Rock_Aqua_Cobble_Roof_Shallow",
      "filler": 1,
      "rotation": 3
    },
    {
      "x": -5,
      "y": 0,
      "z": 0,
      "name": "Rock_Aqua"
    },
    {
      "x": -5,
      "y": 1,
      "z": 0,
      "name": "Rock_Aqua"
    },
    {
      "x": -5,
      "y": 2,
      "z": 0,
      "name": "Rock_Aqua"
    },
    {
      "x": -5,
      "y": 3,
      "z": 0,
      "name": "Rock_Aqua"
    },
    {
      "x": -5,
      "y": 4,
      "z": 0,
      "name": "Empty"
    },
    {
      "x": -5,
      "y": 0,
      "z": 1,
      "name": "Rock_Aqua"
    },
    {
      "x": -5,
      "y": 1,
      "z": 1,
      "name": "Rock_Aqua"
    },
    {
      "x": -5,
      "y": 2,
      "z": 1,
      "name": "Rock_Aqua"
    },
    {
      "x": -5,
      "y": 3,
      "z": 1,
      "name": "Rock_Aqua"
    },
    {
      "x": -5,
      "y": 4,
      "z": 1,
      "name": "Empty"
    },
    {
      "x": -5,
      "y": 0,
      "z": 2,
      "name": "Rock_Aqua"
    },
    {
      "x": -5,
      "y": 1,
      "z": 2,
      "name": "Rock_Aqua"
    },
    {
      "x": -5,
      "y": 0,
      "z": 3,
      "name": "Rock_Aqua"
    },
    {
      "x": -5,
      "y": 1,
      "z": 3,
      "name": "Rock_Aqua"
    },
    {
      "x": -5,
      "y": 0,
      "z": 4,
      "name": "Rock_Aqua"
    },
    {
      "x": -5,
      "y": 1,
      "z": 4,
      "name": "Rock_Aqua"
    },
    {
      "x": -5,
      "y": 2,
      "z": 4,
      "name": "Rock_Aqua"
    },
    {
      "x": -5,
      "y": 3,
      "z": 4,
      "name": "Rock_Aqua_Stairs",
      "rotation": 2
    },
    {
      "x": -5,
      "y": 4,
      "z": 4,
      "name": "Empty"
    },
    {
      "x": -5,
      "y": 0,
      "z": 5,
      "name": "Rock_Aqua_Stairs",
      "rotation": 10
    },
    {
      "x": -5,
      "y": 1,
      "z": 5,
      "name": "Rock_Aqua"
    },
    {
      "x": -5,
      "y": 2,
      "z": 5,
      "name": "Rock_Aqua"
    },
    {
      "x": -5,
      "y": 3,
      "z": 5,
      "name": "Rock_Aqua"
    },
    {
      "x": -5,
      "y": 4,
      "z": 5,
      "name": "Rock_Aqua_Brick_Decorative"
    },
    {
      "x": -5,
      "y": 5,
      "z": 5,
      "name": "Rock_Aqua_Brick_Pillar_Base"
    },
    {
      "x": -4,
      "y": 0,
      "z": -1,
      "name": "Rock_Aqua_Stairs",
      "rotation": 8
    },
    {
      "x": -4,
      "y": 1,
      "z": -1,
      "name": "Rock_Aqua"
    },
    {
      "x": -4,
      "y": 2,
      "z": -1,
      "name": "Rock_Aqua"
    },
    {
      "x": -4,
      "y": 3,
      "z": -1,
      "name": "Rock_Aqua"
    },
    {
      "x": -4,
      "y": 4,
      "z": -1,
      "name": "Empty"
    },
    {
      "x": -4,
      "y": 0,
      "z": 0,
      "name": "Rock_Aqua"
    },
    {
      "x": -4,
      "y": 1,
      "z": 0,
      "name": "Rock_Aqua"
    },
    {
      "x": -4,
      "y": 2,
      "z": 0,
      "name": "Rock_Aqua"
    },
    {
      "x": -4,
      "y": 3,
      "z": 0,
      "name": "Rock_Aqua"
    },
    {
      "x": -4,
      "y": 4,
      "z": 0,
      "name": "Empty"
    },
    {
      "x": -4,
      "y": 0,
      "z": 1,
      "name": "Rock_Aqua"
    },
    {
      "x": -4,
      "y": 1,
      "z": 1,
      "name": "Rock_Aqua"
    },
    {
      "x": -4,
      "y": 2,
      "z": 1,
      "name": "Rock_Aqua"
    },
    {
      "x": -4,
      "y": 3,
      "z": 1,
      "name": "Rock_Aqua"
    },
    {
      "x": -4,
      "y": 4,
      "z": 1,
      "name": "Empty"
    },
    {
      "x": -4,
      "y": 0,
      "z": 2,
      "name": "Rock_Aqua"
    },
    {
      "x": -4,
      "y": 1,
      "z": 2,
      "name": "Rock_Aqua"
    },
    {
      "x": -4,
      "y": 0,
      "z": 3,
      "name": "Rock_Aqua"
    },
    {
      "x": -4,
      "y": 1,
      "z": 3,
      "name": "Rock_Aqua"
    },
    {
      "x": -4,
      "y": 0,
      "z": 4,
      "name": "Rock_Aqua"
    },
    {
      "x": -4,
      "y": 1,
      "z": 4,
      "name": "Rock_Aqua"
    },
    {
      "x": -4,
      "y": 0,
      "z": 5,
      "name": "Rock_Aqua_Stairs",
      "rotation": 10
    },
    {
      "x": -4,
      "y": 1,
      "z": 5,
      "name": "Rock_Aqua"
    },
    {
      "x": -4,
      "y": 2,
      "z": 5,
      "name": "Rock_Aqua"
    },
    {
      "x": -4,
      "y": 3,
      "z": 5,
      "name": "Rock_Aqua"
    },
    {
      "x": -4,
      "y": 4,
      "z": 5,
      "name": "Empty"
    },
    {
      "x": -3,
      "y": 0,
      "z": -1,
      "name": "*Rock_Aqua_Stairs_State_Definitions_Corner_Left",
      "rotation": 8
    },
    {
      "x": -3,
      "y": 1,
      "z": -1,
      "name": "Rock_Aqua"
    },
    {
      "x": -3,
      "y": 2,
      "z": -1,
      "name": "Rock_Aqua"
    },
    {
      "x": -3,
      "y": 3,
      "z": -1,
      "name": "Rock_Aqua"
    },
    {
      "x": -3,
      "y": 4,
      "z": -1,
      "name": "Empty"
    },
    {
      "x": -3,
      "y": 0,
      "z": 0,
      "name": "Rock_Aqua_Stairs",
      "rotation": 11
    },
    {
      "x": -3,
      "y": 1,
      "z": 0,
      "name": "Rock_Aqua"
    },
    {
      "x": -3,
      "y": 2,
      "z": 0,
      "name": "Rock_Aqua"
    },
    {
      "x": -3,
      "y": 3,
      "z": 0,
      "name": "Rock_Aqua"
    },
    {
      "x": -3,
      "y": 4,
      "z": 0,
      "name": "Rock_Aqua_Stalactite_Small"
    },
    {
      "x": -3,
      "y": 0,
      "z": 1,
      "name": "Rock_Aqua_Stairs",
      "rotation": 11
    },
    {
      "x": -3,
      "y": 1,
      "z": 1,
      "name": "Rock_Aqua"
    },
    {
      "x": -3,
      "y": 2,
      "z": 1,
      "name": "Rock_Aqua"
    },
    {
      "x": -3,
      "y": 3,
      "z": 1,
      "name": "Rock_Aqua"
    },
    {
      "x": -3,
      "y": 4,
      "z": 1,
      "name": "Rock_Aqua_Brick_Decorative"
    },
    {
      "x": -3,
      "y": 5,
      "z": 1,
      "name": "Rock_Aqua_Brick"
    },
    {
      "x": -3,
      "y": 6,
      "z": 1,
      "name": "Rock_Aqua_Brick_Smooth_Half"
    },
    {
      "x": -3,
      "y": 0,
      "z": 2,
      "name": "*Rock_Aqua_Stairs_State_Definitions_Inverted_Corner_Left",
      "rotation": 8
    },
    {
      "x": -3,
      "y": 1,
      "z": 2,
      "name": "Rock_Aqua"
    },
    {
      "x": -3,
      "y": 2,
      "z": 2,
      "name": "Rock_Aqua"
    },
    {
      "x": -3,
      "y": 3,
      "z": 2,
      "name": "Rock_Aqua"
    },
    {
      "x": -3,
      "y": 4,
      "z": 2,
      "name": "Plant_Moss_Short_Blue",
      "support": 15
    },
    {
      "x": -3,
      "y": 0,
      "z": 3,
      "name": "Rock_Aqua"
    },
    {
      "x": -3,
      "y": 1,
      "z": 3,
      "name": "Rock_Aqua"
    },
    {
      "x": -3,
      "y": 0,
      "z": 4,
      "name": "Rock_Aqua"
    },
    {
      "x": -3,
      "y": 1,
      "z": 4,
      "name": "Rock_Aqua"
    },
    {
      "x": -3,
      "y": 0,
      "z": 5,
      "name": "Rock_Aqua_Stairs",
      "rotation": 10
    },
    {
      "x": -3,
      "y": 1,
      "z": 5,
      "name": "Rock_Aqua"
    },
    {
      "x": -3,
      "y": 2,
      "z": 5,
      "name": "Rock_Aqua"
    },
    {
      "x": -3,
      "y": 3,
      "z": 5,
      "name": "Rock_Aqua"
    },
    {
      "x": -3,
      "y": 4,
      "z": 5,
      "name": "Rubble_Aqua_Medium",
      "support": 15
    },
    {
      "x": -2,
      "y": 0,
      "z": 2,
      "name": "Rock_Aqua_Stairs",
      "rotation": 8
    },
    {
      "x": -2,
      "y": 1,
      "z": 2,
      "name": "Rock_Aqua"
    },
    {
      "x": -2,
      "y": 2,
      "z": 2,
      "name": "Rock_Aqua"
    },
    {
      "x": -2,
      "y": 3,
      "z": 2,
      "name": "Rock_Aqua"
    },
    {
      "x": -2,
      "y": 4,
      "z": 2,
      "name": "Rubble_Aqua",
      "support": 15
    },
    {
      "x": -2,
      "y": 0,
      "z": 3,
      "name": "Rock_Aqua"
    },
    {
      "x": -2,
      "y": 1,
      "z": 3,
      "name": "Rock_Aqua"
    },
    {
      "x": -2,
      "y": 2,
      "z": 3,
      "name": "Rock_Aqua"
    },
    {
      "x": -2,
      "y": 3,
      "z": 3,
      "name": "Rock_Aqua"
    },
    {
      "x": -2,
      "y": 4,
      "z": 3,
      "name": "Plant_Moss_Rug_Blue",
      "support": 15
    },
    {
      "x": -2,
      "y": 0,
      "z": 4,
      "name": "Rock_Aqua"
    },
    {
      "x": -2,
      "y": 1,
      "z": 4,
      "name": "Rock_Aqua"
    },
    {
      "x": -2,
      "y": 2,
      "z": 4,
      "name": "Rock_Aqua"
    },
    {
      "x": -2,
      "y": 3,
      "z": 4,
      "name": "Rock_Aqua_Stairs",
      "rotation": 1
    },
    {
      "x": -2,
      "y": 4,
      "z": 4,
      "name": "Empty"
    },
    {
      "x": -2,
      "y": 0,
      "z": 5,
      "name": "Rock_Aqua_Stairs",
      "rotation": 10
    },
    {
      "x": -2,
      "y": 1,
      "z": 5,
      "name": "Rock_Aqua"
    },
    {
      "x": -2,
      "y": 2,
      "z": 5,
      "name": "Rock_Aqua"
    },
    {
      "x": -2,
      "y": 3,
      "z": 5,
      "name": "Rock_Aqua"
    },
    {
      "x": -2,
      "y": 4,
      "z": 5,
      "name": "Empty"
    },
    {
      "x": -1,
      "y": 0,
      "z": -4,
      "name": "*Rock_Aqua_Stairs_State_Definitions_Corner_Left",
      "rotation": 9
    },
    {
      "x": -1,
      "y": 1,
      "z": -4,
      "name": "Rock_Aqua"
    },
    {
      "x": -1,
      "y": 2,
      "z": -4,
      "name": "Rock_Aqua"
    },
    {
      "x": -1,
      "y": 3,
      "z": -4,
      "name": "Rock_Aqua"
    },
    {
      "x": -1,
      "y": 4,
      "z": -4,
      "name": "Rock_Aqua_Brick_Decorative"
    },
    {
      "x": -1,
      "y": 5,
      "z": -4,
      "name": "Rock_Aqua_Brick_Smooth"
    },
    {
      "x": -1,
      "y": 6,
      "z": -4,
      "name": "Rock_Aqua_Brick_Smooth"
    },
    {
      "x": -1,
      "y": 7,
      "z": -4,
      "name": "Rock_Aqua_Cobble_Roof_Flat"
    },
    {
      "x": -1,
      "y": 0,
      "z": -3,
      "name": "Rock_Aqua_Stairs",
      "rotation": 9
    },
    {
      "x": -1,
      "y": 1,
      "z": -3,
      "name": "Rock_Aqua"
    },
    {
      "x": -1,
      "y": 2,
      "z": -3,
      "name": "Rock_Aqua"
    },
    {
      "x": -1,
      "y": 3,
      "z": -3,
      "name": "Rock_Aqua"
    },
    {
      "x": -1,
      "y": 4,
      "z": -3,
      "name": "Rock_Aqua_Brick_Decorative"
    },
    {
      "x": -1,
      "y": 5,
      "z": -3,
      "name": "Rock_Aqua_Brick_Smooth_Half"
    },
    {
      "x": -1,
      "y": 0,
      "z": -2,
      "name": "Rock_Aqua_Stairs",
      "rotation": 9
    },
    {
      "x": -1,
      "y": 1,
      "z": -2,
      "name": "Rock_Aqua"
    },
    {
      "x": -1,
      "y": 2,
      "z": -2,
      "name": "Rock_Aqua"
    },
    {
      "x": -1,
      "y": 3,
      "z": -2,
      "name": "Rock_Aqua"
    },
    {
      "x": -1,
      "y": 4,
      "z": -2,
      "name": "Empty"
    },
    {
      "x": -1,
      "y": 5,
      "z": -2,
      "name": "Empty"
    },
    {
      "x": -1,
      "y": 0,
      "z": -1,
      "name": "Rock_Aqua_Stairs",
      "rotation": 9
    },
    {
      "x": -1,
      "y": 1,
      "z": -1,
      "name": "Rock_Aqua"
    },
    {
      "x": -1,
      "y": 2,
      "z": -1,
      "name": "Rock_Aqua"
    },
    {
      "x": -1,
      "y": 3,
      "z": -1,
      "name": "Rock_Aqua"
    },
    {
      "x": -1,
      "y": 4,
      "z": -1,
      "name": "Rock_Aqua_Brick_Beam"
    },
    {
      "x": -1,
      "y": 0,
      "z": 0,
      "name": "*Rock_Aqua_Stairs_State_Definitions_Corner_Right",
      "rotation": 9
    },
    {
      "x": -1,
      "y": 1,
      "z": 0,
      "name": "Rock_Aqua"
    },
    {
      "x": -1,
      "y": 2,
      "z": 0,
      "name": "Rock_Aqua"
    },
    {
      "x": -1,
      "y": 3,
      "z": 0,
      "name": "Rock_Aqua"
    },
    {
      "x": -1,
      "y": 4,
      "z": 0,
      "name": "Rock_Aqua_Brick_Decorative"
    },
    {
      "x": -1,
      "y": 5,
      "z": 0,
      "name": "Rock_Aqua_Brick_Beam"
    },
    {
      "x": -1,
      "y": 0,
      "z": 2,
      "name": "Rock_Aqua_Stairs",
      "rotation": 8
    },
    {
      "x": -1,
      "y": 1,
      "z": 2,
      "name": "Rock_Aqua"
    },
    {
      "x": -1,
      "y": 2,
      "z": 2,
      "name": "Rock_Aqua"
    },
    {
      "x": -1,
      "y": 3,
      "z": 2,
      "name": "Rock_Aqua"
    },
    {
      "x": -1,
      "y": 4,
      "z": 2,
      "name": "Plant_Moss_Rug_Blue",
      "support": 15
    },
    {
      "x": -1,
      "y": 0,
      "z": 3,
      "name": "Rock_Aqua"
    },
    {
      "x": -1,
      "y": 1,
      "z": 3,
      "name": "Rock_Aqua"
    },
    {
      "x": -1,
      "y": 2,
      "z": 3,
      "name": "Rock_Aqua"
    },
    {
      "x": -1,
      "y": 3,
      "z": 3,
      "name": "Rock_Aqua_Stairs"
    },
    {
      "x": -1,
      "y": 4,
      "z": 3,
      "name": "Empty"
    },
    {
      "x": -1,
      "y": 0,
      "z": 4,
      "name": "Rock_Aqua"
    },
    {
      "x": -1,
      "y": 1,
      "z": 4,
      "name": "Rock_Aqua"
    },
    {
      "x": -1,
      "y": 2,
      "z": 4,
      "name": "Rock_Aqua"
    },
    {
      "x": -1,
      "y": 3,
      "z": 4,
      "name": "Rock_Aqua"
    },
    {
      "x": -1,
      "y": 4,
      "z": 4,
      "name": "Plant_Moss_Short_Blue",
      "support": 15
    },
    {
      "x": -1,
      "y": 0,
      "z": 5,
      "name": "Rock_Aqua_Stairs",
      "rotation": 10
    },
    {
      "x": -1,
      "y": 1,
      "z": 5,
      "name": "Rock_Aqua"
    },
    {
      "x": -1,
      "y": 2,
      "z": 5,
      "name": "Rock_Aqua"
    },
    {
      "x": -1,
      "y": 3,
      "z": 5,
      "name": "Rock_Aqua"
    },
    {
      "x": -1,
      "y": 4,
      "z": 5,
      "name": "Empty"
    },
    {
      "x": 0,
      "y": 0,
      "z": -4,
      "name": "Rock_Aqua_Stairs",
      "rotation": 8
    },
    {
      "x": 0,
      "y": 1,
      "z": -4,
      "name": "Rock_Aqua"
    },
    {
      "x": 0,
      "y": 2,
      "z": -4,
      "name": "Rock_Aqua"
    },
    {
      "x": 0,
      "y": 3,
      "z": -4,
      "name": "Rock_Aqua"
    },
    {
      "x": 0,
      "y": 4,
      "z": -4,
      "name": "Rock_Aqua_Brick_Decorative"
    },
    {
      "x": 0,
      "y": 5,
      "z": -4,
      "name": "Rock_Aqua_Brick_Smooth"
    },
    {
      "x": 0,
      "y": 0,
      "z": -3,
      "name": "Rock_Aqua"
    },
    {
      "x": 0,
      "y": 1,
      "z": -3,
      "name": "Rock_Aqua"
    },
    {
      "x": 0,
      "y": 2,
      "z": -3,
      "name": "Rock_Aqua"
    },
    {
      "x": 0,
      "y": 3,
      "z": -3,
      "name": "Rock_Aqua"
    },
    {
      "x": 0,
      "y": 4,
      "z": -3,
      "name": "Empty"
    },
    {
      "x": 0,
      "y": 0,
      "z": -2,
      "name": "Rock_Aqua"
    },
    {
      "x": 0,
      "y": 1,
      "z": -2,
      "name": "Rock_Aqua"
    },
    {
      "x": 0,
      "y": 2,
      "z": -2,
      "name": "Rock_Aqua"
    },
    {
      "x": 0,
      "y": 3,
      "z": -2,
      "name": "Rock_Aqua_Stairs",
      "rotation": 2
    },
    {
      "x": 0,
      "y": 4,
      "z": -2,
      "name": "Empty"
    },
    {
      "x": 0,
      "y": 0,
      "z": -1,
      "name": "Rock_Aqua"
    },
    {
      "x": 0,
      "y": 1,
      "z": -1,
      "name": "Rock_Aqua"
    },
    {
      "x": 0,
      "y": 2,
      "z": -1,
      "name": "Rock_Aqua"
    },
    {
      "x": 0,
      "y": 3,
      "z": -1,
      "name": "Rock_Aqua"
    },
    {
      "x": 0,
      "y": 4,
      "z": -1,
      "name": "Empty"
    },
    {
      "x": 0,
      "y": 0,
      "z": 0,
      "name": "Rock_Aqua_Stairs",
      "rotation": 10
    },
    {
      "x": 0,
      "y": 1,
      "z": 0,
      "name": "Rock_Aqua"
    },
    {
      "x": 0,
      "y": 2,
      "z": 0,
      "name": "Rock_Aqua"
    },
    {
      "x": 0,
      "y": 3,
      "z": 0,
      "name": "Rock_Aqua"
    },
    {
      "x": 0,
      "y": 4,
      "z": 0,
      "name": "Plant_Moss_Short_Blue",
      "support": 15
    },
    {
      "x": 0,
      "y": 0,
      "z": 2,
      "name": "Rock_Aqua_Stairs",
      "rotation": 8
    },
    {
      "x": 0,
      "y": 1,
      "z": 2,
      "name": "Rock_Aqua"
    },
    {
      "x": 0,
      "y": 2,
      "z": 2,
      "name": "Rock_Aqua"
    },
    {
      "x": 0,
      "y": 3,
      "z": 2,
      "name": "Rock_Aqua"
    },
    {
      "x": 0,
      "y": 4,
      "z": 2,
      "name": "Empty"
    },
    {
      "x": 0,
      "y": 0,
      "z": 3,
      "name": "Rock_Aqua"
    },
    {
      "x": 0,
      "y": 1,
      "z": 3,
      "name": "Rock_Aqua"
    },
    {
      "x": 0,
      "y": 2,
      "z": 3,
      "name": "Rock_Aqua"
    },
    {
      "x": 0,
      "y": 3,
      "z": 3,
      "name": "Rock_Aqua"
    },
    {
      "x": 0,
      "y": 4,
      "z": 3,
      "name": "Rubble_Aqua_Medium",
      "support": 15
    },
    {
      "x": 0,
      "y": 0,
      "z": 4,
      "name": "Rock_Aqua"
    },
    {
      "x": 0,
      "y": 1,
      "z": 4,
      "name": "Rock_Aqua"
    },
    {
      "x": 0,
      "y": 0,
      "z": 5,
      "name": "Rock_Aqua_Stairs",
      "rotation": 10
    },
    {
      "x": 0,
      "y": 1,
      "z": 5,
      "name": "Rock_Aqua"
    },
    {
      "x": 1,
      "y": 0,
      "z": -4,
      "name": "Rock_Aqua_Stairs",
      "rotation": 8
    },
    {
      "x": 1,
      "y": 1,
      "z": -4,
      "name": "Rock_Aqua"
    },
    {
      "x": 1,
      "y": 2,
      "z": -4,
      "name": "Rock_Aqua"
    },
    {
      "x": 1,
      "y": 3,
      "z": -4,
      "name": "Rock_Aqua"
    },
    {
      "x": 1,
      "y": 4,
      "z": -4,
      "name": "Rock_Aqua_Brick_Wall"
    },
    {
      "x": 1,
      "y": 0,
      "z": -3,
      "name": "Rock_Aqua"
    },
    {
      "x": 1,
      "y": 1,
      "z": -3,
      "name": "Rock_Aqua"
    },
    {
      "x": 1,
      "y": 2,
      "z": -3,
      "name": "Rock_Aqua"
    },
    {
      "x": 1,
      "y": 3,
      "z": -3,
      "name": "Rock_Aqua"
    },
    {
      "x": 1,
      "y": 4,
      "z": -3,
      "name": "Rubble_Aqua",
      "support": 15
    },
    {
      "x": 1,
      "y": 0,
      "z": -2,
      "name": "Rock_Aqua"
    },
    {
      "x": 1,
      "y": 1,
      "z": -2,
      "name": "Rock_Aqua"
    },
    {
      "x": 1,
      "y": 2,
      "z": -2,
      "name": "Rock_Aqua"
    },
    {
      "x": 1,
      "y": 3,
      "z": -2,
      "name": "*Rock_Aqua_Stairs_State_Definitions_Inverted_Corner_Right",
      "rotation": 3
    },
    {
      "x": 1,
      "y": 4,
      "z": -2,
      "name": "Empty"
    },
    {
      "x": 1,
      "y": 0,
      "z": -1,
      "name": "Rock_Aqua"
    },
    {
      "x": 1,
      "y": 1,
      "z": -1,
      "name": "Rock_Aqua"
    },
    {
      "x": 1,
      "y": 0,
      "z": 0,
      "name": "Rock_Aqua_Stairs",
      "rotation": 10
    },
    {
      "x": 1,
      "y": 1,
      "z": 0,
      "name": "Rock_Aqua"
    },
    {
      "x": 1,
      "y": 2,
      "z": 0,
      "name": "Rock_Aqua"
    },
    {
      "x": 1,
      "y": 3,
      "z": 0,
      "name": "Rock_Aqua"
    },
    {
      "x": 1,
      "y": 4,
      "z": 0,
      "name": "Rubble_Aqua",
      "support": 15
    },
    {
      "x": 1,
      "y": 1,
      "z": 1,
      "name": "Rock_Aqua_Brick_Ornate"
    },
    {
      "x": 1,
      "y": 2,
      "z": 1,
      "name": "Rock_Aqua_Brick_Smooth"
    },
    {
      "x": 1,
      "y": 3,
      "z": 1,
      "name": "Rock_Aqua_Brick_Ornate"
    },
    {
      "x": 1,
      "y": 4,
      "z": 1,
      "name": "Empty"
    },
    {
      "x": 1,
      "y": 0,
      "z": 2,
      "name": "Rock_Aqua_Stairs",
      "rotation": 8
    },
    {
      "x": 1,
      "y": 1,
      "z": 2,
      "name": "Rock_Aqua"
    },
    {
      "x": 1,
      "y": 2,
      "z": 2,
      "name": "Rock_Aqua"
    },
    {
      "x": 1,
      "y": 3,
      "z": 2,
      "name": "Rock_Aqua"
    },
    {
      "x": 1,
      "y": 4,
      "z": 2,
      "name": "Plant_Moss_Short_Blue",
      "support": 15
    },
    {
      "x": 1,
      "y": 0,
      "z": 3,
      "name": "Rock_Aqua"
    },
    {
      "x": 1,
      "y": 1,
      "z": 3,
      "name": "Rock_Aqua"
    },
    {
      "x": 1,
      "y": 0,
      "z": 4,
      "name": "Rock_Aqua"
    },
    {
      "x": 1,
      "y": 1,
      "z": 4,
      "name": "Rock_Aqua"
    },
    {
      "x": 1,
      "y": 0,
      "z": 5,
      "name": "Rock_Aqua_Stairs",
      "rotation": 10
    },
    {
      "x": 1,
      "y": 1,
      "z": 5,
      "name": "Rock_Aqua"
    },
    {
      "x": 2,
      "y": 0,
      "z": -4,
      "name": "Rock_Aqua_Stairs",
      "rotation": 8
    },
    {
      "x": 2,
      "y": 1,
      "z": -4,
      "name": "Rock_Aqua"
    },
    {
      "x": 2,
      "y": 2,
      "z": -4,
      "name": "Rock_Aqua"
    },
    {
      "x": 2,
      "y": 3,
      "z": -4,
      "name": "Rock_Aqua"
    },
    {
      "x": 2,
      "y": 4,
      "z": -4,
      "name": "Empty"
    },
    {
      "x": 2,
      "y": 0,
      "z": -3,
      "name": "Rock_Aqua"
    },
    {
      "x": 2,
      "y": 1,
      "z": -3,
      "name": "Rock_Aqua"
    },
    {
      "x": 2,
      "y": 2,
      "z": -3,
      "name": "Rock_Aqua"
    },
    {
      "x": 2,
      "y": 3,
      "z": -3,
      "name": "Rock_Aqua"
    },
    {
      "x": 2,
      "y": 4,
      "z": -3,
      "name": "Empty"
    },
    {
      "x": 2,
      "y": 0,
      "z": -2,
      "name": "Rock_Aqua"
    },
    {
      "x": 2,
      "y": 1,
      "z": -2,
      "name": "Rock_Aqua"
    },
    {
      "x": 2,
      "y": 0,
      "z": -1,
      "name": "Rock_Aqua"
    },
    {
      "x": 2,
      "y": 1,
      "z": -1,
      "name": "Rock_Aqua"
    },
    {
      "x": 2,
      "y": 0,
      "z": 0,
      "name": "Rock_Aqua_Stairs",
      "rotation": 10
    },
    {
      "x": 2,
      "y": 1,
      "z": 0,
      "name": "Rock_Aqua"
    },
    {
      "x": 2,
      "y": 2,
      "z": 0,
      "name": "Rock_Aqua"
    },
    {
      "x": 2,
      "y": 3,
      "z": 0,
      "name": "Rock_Aqua_Stairs",
      "rotation": 1
    },
    {
      "x": 2,
      "y": 4,
      "z": 0,
      "name": "Empty"
    },
    {
      "x": 2,
      "y": 0,
      "z": 2,
      "name": "Rock_Aqua_Stairs",
      "rotation": 8
    },
    {
      "x": 2,
      "y": 1,
      "z": 2,
      "name": "Rock_Aqua"
    },
    {
      "x": 2,
      "y": 2,
      "z": 2,
      "name": "Rock_Aqua"
    },
    {
      "x": 2,
      "y": 3,
      "z": 2,
      "name": "Rock_Aqua"
    },
    {
      "x": 2,
      "y": 4,
      "z": 2,
      "name": "Empty"
    },
    {
      "x": 2,
      "y": 0,
      "z": 3,
      "name": "Rock_Aqua"
    },
    {
      "x": 2,
      "y": 1,
      "z": 3,
      "name": "Rock_Aqua"
    },
    {
      "x": 2,
      "y": 0,
      "z": 4,
      "name": "Rock_Aqua"
    },
    {
      "x": 2,
      "y": 1,
      "z": 4,
      "name": "Rock_Aqua"
    },
    {
      "x": 2,
      "y": 0,
      "z": 5,
      "name": "Rock_Aqua_Stairs",
      "rotation": 10
    },
    {
      "x": 2,
      "y": 1,
      "z": 5,
      "name": "Rock_Aqua"
    },
    {
      "x": 2,
      "y": 2,
      "z": 5,
      "name": "Rock_Aqua"
    },
    {
      "x": 2,
      "y": 3,
      "z": 5,
      "name": "Rock_Aqua"
    },
    {
      "x": 2,
      "y": 4,
      "z": 5,
      "name": "Empty"
    },
    {
      "x": 3,
      "y": 0,
      "z": -4,
      "name": "Rock_Aqua_Stairs",
      "rotation": 8
    },
    {
      "x": 3,
      "y": 1,
      "z": -4,
      "name": "Rock_Aqua"
    },
    {
      "x": 3,
      "y": 2,
      "z": -4,
      "name": "Rock_Aqua"
    },
    {
      "x": 3,
      "y": 3,
      "z": -4,
      "name": "Rock_Aqua"
    },
    {
      "x": 3,
      "y": 4,
      "z": -4,
      "name": "Rock_Aqua_Brick_Wall"
    },
    {
      "x": 3,
      "y": 0,
      "z": -3,
      "name": "Rock_Aqua"
    },
    {
      "x": 3,
      "y": 1,
      "z": -3,
      "name": "Rock_Aqua"
    },
    {
      "x": 3,
      "y": 2,
      "z": -3,
      "name": "Rock_Aqua"
    },
    {
      "x": 3,
      "y": 3,
      "z": -3,
      "name": "Rock_Aqua_Stairs",
      "rotation": 2
    },
    {
      "x": 3,
      "y": 4,
      "z": -3,
      "name": "Empty"
    },
    {
      "x": 3,
      "y": 0,
      "z": -2,
      "name": "Rock_Aqua"
    },
    {
      "x": 3,
      "y": 1,
      "z": -2,
      "name": "Rock_Aqua"
    },
    {
      "x": 3,
      "y": 0,
      "z": -1,
      "name": "Rock_Aqua"
    },
    {
      "x": 3,
      "y": 1,
      "z": -1,
      "name": "Rock_Aqua"
    },
    {
      "x": 3,
      "y": 0,
      "z": 0,
      "name": "Rock_Aqua_Stairs",
      "rotation": 10
    },
    {
      "x": 3,
      "y": 1,
      "z": 0,
      "name": "Rock_Aqua"
    },
    {
      "x": 3,
      "y": 0,
      "z": 2,
      "name": "*Rock_Aqua_Stairs_State_Definitions_Corner_Right",
      "rotation": 11
    },
    {
      "x": 3,
      "y": 1,
      "z": 2,
      "name": "Rock_Aqua"
    },
    {
      "x": 3,
      "y": 2,
      "z": 2,
      "name": "Rock_Aqua"
    },
    {
      "x": 3,
      "y": 3,
      "z": 2,
      "name": "Rock_Aqua"
    },
    {
      "x": 3,
      "y": 4,
      "z": 2,
      "name": "Empty"
    },
    {
      "x": 3,
      "y": 0,
      "z": 3,
      "name": "Rock_Aqua_Stairs",
      "rotation": 11
    },
    {
      "x": 3,
      "y": 1,
      "z": 3,
      "name": "Rock_Aqua"
    },
    {
      "x": 3,
      "y": 2,
      "z": 3,
      "name": "Rock_Aqua"
    },
    {
      "x": 3,
      "y": 3,
      "z": 3,
      "name": "Rock_Aqua"
    },
    {
      "x": 3,
      "y": 4,
      "z": 3,
      "name": "Rock_Aqua_Brick_Wall",
      "rotation": 1
    },
    {
      "x": 3,
      "y": 0,
      "z": 4,
      "name": "Rock_Aqua_Stairs",
      "rotation": 11
    },
    {
      "x": 3,
      "y": 1,
      "z": 4,
      "name": "Rock_Aqua"
    },
    {
      "x": 3,
      "y": 2,
      "z": 4,
      "name": "Rock_Aqua"
    },
    {
      "x": 3,
      "y": 3,
      "z": 4,
      "name": "Rock_Aqua"
    },
    {
      "x": 3,
      "y": 4,
      "z": 4,
      "name": "Rock_Aqua_Brick_Wall",
      "rotation": 1
    },
    {
      "x": 3,
      "y": 0,
      "z": 5,
      "name": "*Rock_Aqua_Stairs_State_Definitions_Corner_Left",
      "rotation": 11
    },
    {
      "x": 3,
      "y": 1,
      "z": 5,
      "name": "Rock_Aqua"
    },
    {
      "x": 3,
      "y": 2,
      "z": 5,
      "name": "Rock_Aqua"
    },
    {
      "x": 3,
      "y": 3,
      "z": 5,
      "name": "Rock_Aqua"
    },
    {
      "x": 3,
      "y": 4,
      "z": 5,
      "name": "Rock_Aqua_Brick_Decorative"
    },
    {
      "x": 3,
      "y": 5,
      "z": 5,
      "name": "Rock_Aqua_Brick_Smooth"
    },
    {
      "x": 3,
      "y": 6,
      "z": 5,
      "name": "Rock_Aqua_Brick_Smooth"
    },
    {
      "x": 3,
      "y": 7,
      "z": 5,
      "name": "Rock_Aqua_Cobble_Roof_Flat",
      "rotation": 3
    },
    {
      "x": 4,
      "y": 0,
      "z": -4,
      "name": "Rock_Aqua_Stairs",
      "rotation": 8
    },
    {
      "x": 4,
      "y": 1,
      "z": -4,
      "name": "Rock_Aqua"
    },
    {
      "x": 4,
      "y": 2,
      "z": -4,
      "name": "Rock_Aqua"
    },
    {
      "x": 4,
      "y": 3,
      "z": -4,
      "name": "Rock_Aqua"
    },
    {
      "x": 4,
      "y": 4,
      "z": -4,
      "name": "Rock_Aqua_Brick_Wall"
    },
    {
      "x": 4,
      "y": 0,
      "z": -3,
      "name": "Rock_Aqua"
    },
    {
      "x": 4,
      "y": 1,
      "z": -3,
      "name": "Rock_Aqua"
    },
    {
      "x": 4,
      "y": 2,
      "z": -3,
      "name": "Rock_Aqua"
    },
    {
      "x": 4,
      "y": 3,
      "z": -3,
      "name": "Rock_Aqua"
    },
    {
      "x": 4,
      "y": 4,
      "z": -3,
      "name": "Empty"
    },
    {
      "x": 4,
      "y": 0,
      "z": -2,
      "name": "Rock_Aqua"
    },
    {
      "x": 4,
      "y": 1,
      "z": -2,
      "name": "Rock_Aqua"
    },
    {
      "x": 4,
      "y": 0,
      "z": -1,
      "name": "Rock_Aqua"
    },
    {
      "x": 4,
      "y": 1,
      "z": -1,
      "name": "Rock_Aqua"
    },
    {
      "x": 4,
      "y": 0,
      "z": 0,
      "name": "Rock_Aqua_Stairs",
      "rotation": 10
    },
    {
      "x": 4,
      "y": 1,
      "z": 0,
      "name": "Rock_Aqua"
    },
    {
      "x": 5,
      "y": 0,
      "z": -4,
      "name": "Rock_Aqua_Stairs",
      "rotation": 8
    },
    {
      "x": 5,
      "y": 1,
      "z": -4,
      "name": "Rock_Aqua"
    },
    {
      "x": 5,
      "y": 2,
      "z": -4,
      "name": "Rock_Aqua"
    },
    {
      "x": 5,
      "y": 3,
      "z": -4,
      "name": "Rock_Aqua"
    },
    {
      "x": 5,
      "y": 4,
      "z": -4,
      "name": "Rock_Aqua_Brick_Wall"
    },
    {
      "x": 5,
      "y": 0,
      "z": -3,
      "name": "Rock_Aqua"
    },
    {
      "x": 5,
      "y": 1,
      "z": -3,
      "name": "Rock_Aqua"
    },
    {
      "x": 5,
      "y": 2,
      "z": -3,
      "name": "Rock_Aqua"
    },
    {
      "x": 5,
      "y": 3,
      "z": -3,
      "name": "Rock_Aqua"
    },
    {
      "x": 5,
      "y": 4,
      "z": -3,
      "name": "Empty"
    },
    {
      "x": 5,
      "y": 0,
      "z": -2,
      "name": "Rock_Aqua"
    },
    {
      "x": 5,
      "y": 1,
      "z": -2,
      "name": "Rock_Aqua"
    },
    {
      "x": 5,
      "y": 2,
      "z": -2,
      "name": "Rock_Aqua"
    },
    {
      "x": 5,
      "y": 3,
      "z": -2,
      "name": "Rock_Aqua"
    },
    {
      "x": 5,
      "y": 4,
      "z": -2,
      "name": "Empty"
    },
    {
      "x": 5,
      "y": 0,
      "z": -1,
      "name": "Rock_Aqua"
    },
    {
      "x": 5,
      "y": 1,
      "z": -1,
      "name": "Rock_Aqua"
    },
    {
      "x": 5,
      "y": 2,
      "z": -1,
      "name": "Rock_Aqua"
    },
    {
      "x": 5,
      "y": 3,
      "z": -1,
      "name": "Rock_Aqua_Stairs",
      "rotation": 1
    },
    {
      "x": 5,
      "y": 4,
      "z": -1,
      "name": "Empty"
    },
    {
      "x": 5,
      "y": 0,
      "z": 0,
      "name": "Rock_Aqua_Stairs",
      "rotation": 10
    },
    {
      "x": 5,
      "y": 1,
      "z": 0,
      "name": "Rock_Aqua"
    },
    {
      "x": 6,
      "y": 0,
      "z": -4,
      "name": "Rock_Aqua_Stairs",
      "rotation": 8
    },
    {
      "x": 6,
      "y": 1,
      "z": -4,
      "name": "Rock_Aqua"
    },
    {
      "x": 6,
      "y": 2,
      "z": -4,
      "name": "Rock_Aqua"
    },
    {
      "x": 6,
      "y": 3,
      "z": -4,
      "name": "Rock_Aqua_Stairs"
    },
    {
      "x": 6,
      "y": 4,
      "z": -4,
      "name": "Empty"
    },
    {
      "x": 6,
      "y": 0,
      "z": -3,
      "name": "Rock_Aqua"
    },
    {
      "x": 6,
      "y": 1,
      "z": -3,
      "name": "Rock_Aqua"
    },
    {
      "x": 6,
      "y": 2,
      "z": -3,
      "name": "Rock_Aqua"
    },
    {
      "x": 6,
      "y": 3,
      "z": -3,
      "name": "Rock_Aqua"
    },
    {
      "x": 6,
      "y": 4,
      "z": -3,
      "name": "Empty"
    },
    {
      "x": 6,
      "y": 0,
      "z": -2,
      "name": "Rock_Aqua"
    },
    {
      "x": 6,
      "y": 1,
      "z": -2,
      "name": "Rock_Aqua"
    },
    {
      "x": 6,
      "y": 2,
      "z": -2,
      "name": "Rock_Aqua"
    },
    {
      "x": 6,
      "y": 3,
      "z": -2,
      "name": "Rock_Aqua"
    },
    {
      "x": 6,
      "y": 4,
      "z": -2,
      "name": "Rubble_Aqua_Medium",
      "support": 15
    },
    {
      "x": 6,
      "y": 0,
      "z": -1,
      "name": "Rock_Aqua"
    },
    {
      "x": 6,
      "y": 1,
      "z": -1,
      "name": "Rock_Aqua"
    },
    {
      "x": 6,
      "y": 2,
      "z": -1,
      "name": "Rock_Aqua"
    },
    {
      "x": 6,
      "y": 3,
      "z": -1,
      "name": "Rock_Aqua"
    },
    {
      "x": 6,
      "y": 4,
      "z": -1,
      "name": "Empty"
    },
    {
      "x": 6,
      "y": 0,
      "z": 0,
      "name": "Rock_Aqua_Stairs",
      "rotation": 10
    },
    {
      "x": 6,
      "y": 1,
      "z": 0,
      "name": "Rock_Aqua"
    },
    {
      "x": 6,
      "y": 2,
      "z": 0,
      "name": "Rock_Aqua"
    },
    {
      "x": 6,
      "y": 3,
      "z": 0,
      "name": "Rock_Aqua"
    },
    {
      "x": 6,
      "y": 4,
      "z": 0,
      "name": "Empty"
    },
    {
      "x": 7,
      "y": 0,
      "z": -4,
      "name": "*Rock_Aqua_Stairs_State_Definitions_Corner_Left",
      "rotation": 8
    },
    {
      "x": 7,
      "y": 1,
      "z": -4,
      "name": "Rock_Aqua"
    },
    {
      "x": 7,
      "y": 2,
      "z": -4,
      "name": "Rock_Aqua"
    },
    {
      "x": 7,
      "y": 3,
      "z": -4,
      "name": "Rock_Aqua"
    },
    {
      "x": 7,
      "y": 4,
      "z": -4,
      "name": "Empty"
    },
    {
      "x": 7,
      "y": 0,
      "z": -3,
      "name": "Rock_Aqua_Stairs",
      "rotation": 11
    },
    {
      "x": 7,
      "y": 1,
      "z": -3,
      "name": "Rock_Aqua"
    },
    {
      "x": 7,
      "y": 2,
      "z": -3,
      "name": "Rock_Aqua"
    },
    {
      "x": 7,
      "y": 3,
      "z": -3,
      "name": "Rock_Aqua"
    },
    {
      "x": 7,
      "y": 4,
      "z": -3,
      "name": "Rock_Aqua_Brick_Decorative"
    },
    {
      "x": 7,
      "y": 0,
      "z": -2,
      "name": "Rock_Aqua_Stairs",
      "rotation": 11
    },
    {
      "x": 7,
      "y": 1,
      "z": -2,
      "name": "Rock_Aqua"
    },
    {
      "x": 7,
      "y": 2,
      "z": -2,
      "name": "Rock_Aqua"
    },
    {
      "x": 7,
      "y": 3,
      "z": -2,
      "name": "Rock_Aqua"
    },
    {
      "x": 7,
      "y": 5,
      "z": -2,
      "name": "Rock_Aqua_Brick_Smooth"
    },
    {
      "x": 7,
      "y": 0,
      "z": -1,
      "name": "Rock_Aqua_Stairs",
      "rotation": 11
    },
    {
      "x": 7,
      "y": 1,
      "z": -1,
      "name": "Rock_Aqua"
    },
    {
      "x": 7,
      "y": 2,
      "z": -1,
      "name": "Rock_Aqua"
    },
    {
      "x": 7,
      "y": 3,
      "z": -1,
      "name": "Rock_Aqua"
    },
    {
      "x": 7,
      "y": 4,
      "z": -1,
      "name": "Rock_Aqua_Brick_Decorative"
    },
    {
      "x": 7,
      "y": 5,
      "z": -1,
      "name": "Rock_Aqua_Brick"
    },
    {
      "x": 7,
      "y": 0,
      "z": 0,
      "name": "*Rock_Aqua_Stairs_State_Definitions_Corner_Left",
      "rotation": 11
    },
    {
      "x": 7,
      "y": 1,
      "z": 0,
      "name": "Rock_Aqua"
    },
    {
      "x": 7,
      "y": 2,
      "z": 0,
      "name": "Rock_Aqua"
    },
    {
      "x": 7,
      "y": 3,
      "z": 0,
      "name": "Rock_Aqua"
    },
    {
      "x": 7,
      "y": 4,
      "z": 0,
      "name": "Rock_Aqua_Brick_Decorative"
    },
    {
      "x": 7,
      "y": 5,
      "z": 0,
      "name": "Rock_Aqua_Brick_Smooth"
    },
    {
      "x": 7,
      "y": 6,
      "z": 0,
      "name": "Rock_Aqua_Brick_Smooth"
    },
    {
      "x": 7,
      "y": 7,
      "z": 0,
      "name": "Rock_Aqua_Brick_Beam"
    }
  ],
  "fluids": [
    {
      "x": -6,
      "y": 0,
      "z": -1,
      "name": "Water_Source",
      "level": 1
    },
    {
      "x": -6,
      "y": 7,
      "z": -1,
      "name": "Water_Source",
      "level": 1
    },
    {
      "x": -6,
      "y": 0,
      "z": 0,
      "name": "Water_Source",
      "level": 1
    },
    {
      "x": -6,
      "y": 5,
      "z": 0,
      "name": "Water_Source",
      "level": 1
    },
    {
      "x": -6,
      "y": 0,
      "z": 1,
      "name": "Water_Source",
      "level": 1
    },
    {
      "x": -6,
      "y": 4,
      "z": 1,
      "name": "Water_Source",
      "level": 1
    },
    {
      "x": -6,
      "y": 0,
      "z": 2,
      "name": "Water_Source",
      "level": 1
    },
    {
      "x": -6,
      "y": 4,
      "z": 2,
      "name": "Water_Source",
      "level": 1
    },
    {
      "x": -6,
      "y": 0,
      "z": 3,
      "name": "Water_Source",
      "level": 1
    },
    {
      "x": -6,
      "y": 0,
      "z": 4,
      "name": "Water_Source",
      "level": 1
    },
    {
      "x": -6,
      "y": 0,
      "z": 5,
      "name": "Water_Source",
      "level": 1
    },
    {
      "x": -6,
      "y": 4,
      "z": 5,
      "name": "Water_Source",
      "level": 1
    },
    {
      "x": -5,
      "y": 0,
      "z": -1,
      "name": "Water_Source",
      "level": 1
    },
    {
      "x": -5,
      "y": 4,
      "z": -1,
      "name": "Water_Source",
      "level": 1
    },
    {
      "x": -5,
      "y": 6,
      "z": -1,
      "name": "Water_Source",
      "level": 1
    },
    {
      "x": -5,
      "y": 4,
      "z": 0,
      "name": "Water_Source",
      "level": 1
    },
    {
      "x": -5,
      "y": 4,
      "z": 1,
      "name": "Water_Source",
      "level": 1
    },
    {
      "x": -5,
      "y": 3,
      "z": 4,
      "name": "Water_Source",
      "level": 1
    },
    {
      "x": -5,
      "y": 4,
      "z": 4,
      "name": "Water_Source",
      "level": 1
    },
    {
      "x": -5,
      "y": 0,
      "z": 5,
      "name": "Water_Source",
      "level": 1
    },
    {
      "x": -5,
      "y": 5,
      "z": 5,
      "name": "Water_Source",
      "level": 1
    },
    {
      "x": -4,
      "y": 0,
      "z": -1,
      "name": "Water_Source",
      "level": 1
    },
    {
      "x": -4,
      "y": 4,
      "z": -1,
      "name": "Water_Source",
      "level": 1
    },
    {
      "x": -4,
      "y": 4,
      "z": 0,
      "name": "Water_Source",
      "level": 1
    },
    {
      "x": -4,
      "y": 4,
      "z": 1,
      "name": "Water_Source",
      "level": 1
    },
    {
      "x": -4,
      "y": 0,
      "z": 5,
      "name": "Water_Source",
      "level": 1
    },
    {
      "x": -4,
      "y": 4,
      "z": 5,
      "name": "Water_Source",
      "level": 1
    },
    {
      "x": -3,
      "y": 0,
      "z": -1,
      "name": "Water_Source",
      "level": 1
    },
    {
      "x": -3,
      "y": 4,
      "z": -1,
      "name": "Water_Source",
      "level": 1
    },
    {
      "x": -3,
      "y": 0,
      "z": 0,
      "name": "Water_Source",
      "level": 1
    },
    {
      "x": -3,
      "y": 4,
      "z": 0,
      "name": "Water_Source",
      "level": 1
    },
    {
      "x": -3,
      "y": 0,
      "z": 1,
      "name": "Water_Source",
      "level": 1
    },
    {
      "x": -3,
      "y": 6,
      "z": 1,
      "name": "Water_Source",
      "level": 1
    },
    {
      "x": -3,
      "y": 0,
      "z": 2,
      "name": "Water_Source",
      "level": 1
    },
    {
      "x": -3,
      "y": 4,
      "z": 2,
      "name": "Water_Source",
      "level": 1
    },
    {
      "x": -3,
      "y": 0,
      "z": 5,
      "name": "Water_Source",
      "level": 1
    },
    {
      "x": -3,
      "y": 4,
      "z": 5,
      "name": "Water_Source",
      "level": 1
    },
    {
      "x": -2,
      "y": 0,
      "z": 2,
      "name": "Water_Source",
      "level": 1
    },
    {
      "x": -2,
      "y": 4,
      "z": 2,
      "name": "Water_Source",
      "level": 1
    },
    {
      "x": -2,
      "y": 4,
      "z": 3,
      "name": "Water_Source",
      "level": 1
    },
    {
      "x": -2,
      "y": 3,
      "z": 4,
      "name": "Water_Source",
      "level": 1
    },
    {
      "x": -2,
      "y": 4,
      "z": 4,
      "name": "Water_Source",
      "level": 1
    },
    {
      "x": -2,
      "y": 0,
      "z": 5,
      "name": "Water_Source",
      "level": 1
    },
    {
      "x": -2,
      "y": 4,
      "z": 5,
      "name": "Water_Source",
      "level": 1
    },
    {
      "x": -1,
      "y": 0,
      "z": -4,
      "name": "Water_Source",
      "level": 1
    },
    {
      "x": -1,
      "y": 7,
      "z": -4,
      "name": "Water_Source",
      "level": 1
    },
    {
      "x": -1,
      "y": 0,
      "z": -3,
      "name": "Water_Source",
      "level": 1
    },
    {
      "x": -1,
      "y": 5,
      "z": -3,
      "name": "Water_Source",
      "level": 1
    },
    {
      "x": -1,
      "y": 0,
      "z": -2,
      "name": "Water_Source",
      "level": 1
    },
    {
      "x": -1,
      "y": 4,
      "z": -2,
      "name": "Water_Source",
      "level": 1
    },
    {
      "x": -1,
      "y": 5,
      "z": -2,
      "name": "Water_Source",
      "level": 1
    },
    {
      "x": -1,
      "y": 0,
      "z": -1,
      "name": "Water_Source",
      "level": 1
    },
    {
      "x": -1,
      "y": 4,
      "z": -1,
      "name": "Water_Source",
      "level": 1
    },
    {
      "x": -1,
      "y": 0,
      "z": 0,
      "name": "Water_Source",
      "level": 1
    },
    {
      "x": -1,
      "y": 5,
      "z": 0,
      "name": "Water_Source",
      "level": 1
    },
    {
      "x": -1,
      "y": 0,
      "z": 2,
      "name": "Water_Source",
      "level": 1
    },
    {
      "x": -1,
      "y": 4,
      "z": 2,
      "name": "Water_Source",
      "level": 1
    },
    {
      "x": -1,
      "y": 3,
      "z": 3,
      "name": "Water_Source",
      "level": 1
    },
    {
      "x": -1,
      "y": 4,
      "z": 3,
      "name": "Water_Source",
      "level": 1
    },
    {
      "x": -1,
      "y": 4,
      "z": 4,
      "name": "Water_Source",
      "level": 1
    },
    {
      "x": -1,
      "y": 0,
      "z": 5,
      "name": "Water_Source",
      "level": 1
    },
    {
      "x": -1,
      "y": 4,
      "z": 5,
      "name": "Water_Source",
      "level": 1
    },
    {
      "x": 0,
      "y": 0,
      "z": -4,
      "name": "Water_Source",
      "level": 1
    },
    {
      "x": 0,
      "y": 4,
      "z": -3,
      "name": "Water_Source",
      "level": 1
    },
    {
      "x": 0,
      "y": 3,
      "z": -2,
      "name": "Water_Source",
      "level": 1
    },
    {
      "x": 0,
      "y": 4,
      "z": -2,
      "name": "Water_Source",
      "level": 1
    },
    {
      "x": 0,
      "y": 4,
      "z": -1,
      "name": "Water_Source",
      "level": 1
    },
    {
      "x": 0,
      "y": 0,
      "z": 0,
      "name": "Water_Source",
      "level": 1
    },
    {
      "x": 0,
      "y": 4,
      "z": 0,
      "name": "Water_Source",
      "level": 1
    },
    {
      "x": 0,
      "y": 0,
      "z": 2,
      "name": "Water_Source",
      "level": 1
    },
    {
      "x": 0,
      "y": 4,
      "z": 2,
      "name": "Water_Source",
      "level": 1
    },
    {
      "x": 0,
      "y": 4,
      "z": 3,
      "name": "Water_Source",
      "level": 1
    },
    {
      "x": 0,
      "y": 0,
      "z": 5,
      "name": "Water_Source",
      "level": 1
    },
    {
      "x": 1,
      "y": 0,
      "z": -4,
      "name": "Water_Source",
      "level": 1
    },
    {
      "x": 1,
      "y": 4,
      "z": -4,
      "name": "Water_Source",
      "level": 1
    },
    {
      "x": 1,
      "y": 4,
      "z": -3,
      "name": "Water_Source",
      "level": 1
    },
    {
      "x": 1,
      "y": 3,
      "z": -2,
      "name": "Water_Source",
      "level": 1
    },
    {
      "x": 1,
      "y": 4,
      "z": -2,
      "name": "Water_Source",
      "level": 1
    },
    {
      "x": 1,
      "y": 0,
      "z": 0,
      "name": "Water_Source",
      "level": 1
    },
    {
      "x": 1,
      "y": 4,
      "z": 0,
      "name": "Water_Source",
      "level": 1
    },
    {
      "x": 1,
      "y": 4,
      "z": 1,
      "name": "Water_Source",
      "level": 1
    },
    {
      "x": 1,
      "y": 0,
      "z": 2,
      "name": "Water_Source",
      "level": 1
    },
    {
      "x": 1,
      "y": 4,
      "z": 2,
      "name": "Water_Source",
      "level": 1
    },
    {
      "x": 1,
      "y": 0,
      "z": 5,
      "name": "Water_Source",
      "level": 1
    },
    {
      "x": 2,
      "y": 0,
      "z": -4,
      "name": "Water_Source",
      "level": 1
    },
    {
      "x": 2,
      "y": 4,
      "z": -4,
      "name": "Water_Source",
      "level": 1
    },
    {
      "x": 2,
      "y": 4,
      "z": -3,
      "name": "Water_Source",
      "level": 1
    },
    {
      "x": 2,
      "y": 0,
      "z": 0,
      "name": "Water_Source",
      "level": 1
    },
    {
      "x": 2,
      "y": 3,
      "z": 0,
      "name": "Water_Source",
      "level": 1
    },
    {
      "x": 2,
      "y": 4,
      "z": 0,
      "name": "Water_Source",
      "level": 1
    },
    {
      "x": 2,
      "y": 0,
      "z": 2,
      "name": "Water_Source",
      "level": 1
    },
    {
      "x": 2,
      "y": 4,
      "z": 2,
      "name": "Water_Source",
      "level": 1
    },
    {
      "x": 2,
      "y": 0,
      "z": 5,
      "name": "Water_Source",
      "level": 1
    },
    {
      "x": 2,
      "y": 4,
      "z": 5,
      "name": "Water_Source",
      "level": 1
    },
    {
      "x": 3,
      "y": 0,
      "z": -4,
      "name": "Water_Source",
      "level": 1
    },
    {
      "x": 3,
      "y": 4,
      "z": -4,
      "name": "Water_Source",
      "level": 1
    },
    {
      "x": 3,
      "y": 3,
      "z": -3,
      "name": "Water_Source",
      "level": 1
    },
    {
      "x": 3,
      "y": 4,
      "z": -3,
      "name": "Water_Source",
      "level": 1
    },
    {
      "x": 3,
      "y": 0,
      "z": 0,
      "name": "Water_Source",
      "level": 1
    },
    {
      "x": 3,
      "y": 0,
      "z": 2,
      "name": "Water_Source",
      "level": 1
    },
    {
      "x": 3,
      "y": 4,
      "z": 2,
      "name": "Water_Source",
      "level": 1
    },
    {
      "x": 3,
      "y": 0,
      "z": 3,
      "name": "Water_Source",
      "level": 1
    },
    {
      "x": 3,
      "y": 4,
      "z": 3,
      "name": "Water_Source",
      "level": 1
    },
    {
      "x": 3,
      "y": 0,
      "z": 4,
      "name": "Water_Source",
      "level": 1
    },
    {
      "x": 3,
      "y": 4,
      "z": 4,
      "name": "Water_Source",
      "level": 1
    },
    {
      "x": 3,
      "y": 0,
      "z": 5,
      "name": "Water_Source",
      "level": 1
    },
    {
      "x": 3,
      "y": 7,
      "z": 5,
      "name": "Water_Source",
      "level": 1
    },
    {
      "x": 4,
      "y": 0,
      "z": -4,
      "name": "Water_Source",
      "level": 1
    },
    {
      "x": 4,
      "y": 4,
      "z": -4,
      "name": "Water_Source",
      "level": 1
    },
    {
      "x": 4,
      "y": 4,
      "z": -3,
      "name": "Water_Source",
      "level": 1
    },
    {
      "x": 4,
      "y": 0,
      "z": 0,
      "name": "Water_Source",
      "level": 1
    },
    {
      "x": 5,
      "y": 0,
      "z": -4,
      "name": "Water_Source",
      "level": 1
    },
    {
      "x": 5,
      "y": 4,
      "z": -4,
      "name": "Water_Source",
      "level": 1
    },
    {
      "x": 5,
      "y": 4,
      "z": -3,
      "name": "Water_Source",
      "level": 1
    },
    {
      "x": 5,
      "y": 4,
      "z": -2,
      "name": "Water_Source",
      "level": 1
    },
    {
      "x": 5,
      "y": 3,
      "z": -1,
      "name": "Water_Source",
      "level": 1
    },
    {
      "x": 5,
      "y": 4,
      "z": -1,
      "name": "Water_Source",
      "level": 1
    },
    {
      "x": 5,
      "y": 0,
      "z": 0,
      "name": "Water_Source",
      "level": 1
    },
    {
      "x": 6,
      "y": 0,
      "z": -4,
      "name": "Water_Source",
      "level": 1
    },
    {
      "x": 6,
      "y": 3,
      "z": -4,
      "name": "Water_Source",
      "level": 1
    },
    {
      "x": 6,
      "y": 4,
      "z": -4,
      "name": "Water_Source",
      "level": 1
    },
    {
      "x": 6,
      "y": 4,
      "z": -3,
      "name": "Water_Source",
      "level": 1
    },
    {
      "x": 6,
      "y": 4,
      "z": -2,
      "name": "Water_Source",
      "level": 1
    },
    {
      "x": 6,
      "y": 4,
      "z": -1,
      "name": "Water_Source",
      "level": 1
    },
    {
      "x": 6,
      "y": 0,
      "z": 0,
      "name": "Water_Source",
      "level": 1
    },
    {
      "x": 6,
      "y": 4,
      "z": 0,
      "name": "Water_Source",
      "level": 1
    },
    {
      "x": 7,
      "y": 0,
      "z": -4,
      "name": "Water_Source",
      "level": 1
    },
    {
      "x": 7,
      "y": 4,
      "z": -4,
      "name": "Water_Source",
      "level": 1
    },
    {
      "x": 7,
      "y": 0,
      "z": -3,
      "name": "Water_Source",
      "level": 1
    },
    {
      "x": 7,
      "y": 0,
      "z": -2,
      "name": "Water_Source",
      "level": 1
    },
    {
      "x": 7,
      "y": 0,
      "z": -1,
      "name": "Water_Source",
      "level": 1
    },
    {
      "x": 7,
      "y": 0,
      "z": 0,
      "name": "Water_Source",
      "level": 1
    },
    {
      "x": 7,
      "y": 7,
      "z": 0,
      "name": "Water_Source",
      "level": 1
    }
  ]
}