{
  "version": 8,
  "blockIdVersion": 11,
  "anchorX": 0,
  "anchorY": 5,
  "anchorZ": 0,
  "blocks": [
    {
      "x": -7,
      "y": 2,
      "z": -3,
      "name": "Rock_Aqua"
    },
    {
      "x": -7,
      "y": 3,
      "z": -3,
      "name": "Rock_Aqua"
    },
    {
      "x": -7,
      "y": 4,
      "z": -3,
      "name": "Rock_Aqua"
    },
    {
      "x": -7,
      "y": 2,
      "z": -2,
      "name": "Rock_Aqua"
    },
    {
      "x": -7,
      "y": 3,
      "z": -2,
      "name": "Rock_Aqua"
    },
    {
      "x": -7,
      "y": 4,
      "z": -2,
      "name": "Rock_Aqua"
    },
    {
      "x": -7,
      "y": 2,
      "z": -1,
      "name": "Rock_Aqua"
    },
    {
      "x": -7,
      "y": 3,
      "z": -1,
      "name": "Rock_Aqua"
    },
    {
      "x": -7,
      "y": 4,
      "z": -1,
      "name": "Rock_Aqua"
    },
    {
      "x": -6,
      "y": 2,
      "z": -4,
      "name": "Rock_Aqua"
    },
    {
      "x": -6,
      "y": 3,
      "z": -4,
      "name": "Rock_Aqua"
    },
    {
      "x": -6,
      "y": 4,
      "z": -4,
      "name": "Rock_Aqua"
    },
    {
      "x": -6,
      "y": 2,
      "z": -3,
      "name": "Rock_Aqua"
    },
    {
      "x": -6,
      "y": 3,
      "z": -3,
      "name": "Rock_Aqua"
    },
    {
      "x": -6,
      "y": 4,
      "z": -3,
      "name": "Rock_Aqua"
    },
    {
      "x": -6,
      "y": 5,
      "z": -3,
      "name": "Rock_Aqua_Stalactite_Small"
    },
    {
      "x": -6,
      "y": 1,
      "z": -2,
      "name": "Rock_Aqua"
    },
    {
      "x": -6,
      "y": 2,
      "z": -2,
      "name": "Rock_Aqua"
    },
    {
      "x": -6,
      "y": 3,
      "z": -2,
      "name": "Rock_Aqua"
    },
    {
      "x": -6,
      "y": 4,
      "z": -2,
      "name": "Rock_Aqua"
    },
    {
      "x": -6,
      "y": 5,
      "z": -2,
      "name": "Rock_Aqua"
    },
    {
      "x": -6,
      "y": 1,
      "z": -1,
      "name": "Rock_Aqua"
    },
    {
      "x": -6,
      "y": 2,
      "z": -1,
      "name": "Rock_Aqua"
    },
    {
      "x": -6,
      "y": 3,
      "z": -1,
      "name": "Rock_Aqua"
    },
    {
      "x": -6,
      "y": 4,
      "z": -1,
      "name": "Rock_Aqua"
    },
    {
      "x": -6,
      "y": 5,
      "z": -1,
      "name": "Rock_Aqua"
    },
    {
      "x": -6,
      "y": 6,
      "z": -1,
      "name": "Plant_Moss_Short_Blue",
      "support": 15
    },
    {
      "x": -6,
      "y": 2,
      "z": 0,
      "name": "Rock_Aqua"
    },
    {
      "x": -6,
      "y": 3,
      "z": 0,
      "name": "Rock_Aqua"
    },
    {
      "x": -6,
      "y": 4,
      "z": 0,
      "name": "Rock_Aqua"
    },
    {
      "x": -5,
      "y": 2,
      "z": -4,
      "name": "Rock_Aqua"
    },
    {
      "x": -5,
      "y": 3,
      "z": -4,
      "name": "Rock_Aqua"
    },
    {
      "x": -5,
      "y": 4,
      "z": -4,
      "name": "Rock_Aqua"
    },
    {
      "x": -5,
      "y": 1,
      "z": -3,
      "name": "Rock_Aqua"
    },
    {
      "x": -5,
      "y": 2,
      "z": -3,
      "name": "Rock_Aqua"
    },
    {
      "x": -5,
      "y": 3,
      "z": -3,
      "name": "Rock_Aqua"
    },
    {
      "x": -5,
      "y": 4,
      "z": -3,
      "name": "Rock_Aqua"
    },
    {
      "x": -5,
      "y": 5,
      "z": -3,
      "name": "Rock_Aqua"
    },
    {
      "x": -5,
      "y": 1,
      "z": -2,
      "name": "Rock_Aqua"
    },
    {
      "x": -5,
      "y": 2,
      "z": -2,
      "name": "Rock_Aqua"
    },
    {
      "x": -5,
      "y": 3,
      "z": -2,
      "name": "Rock_Aqua"
    },
    {
      "x": -5,
      "y": 4,
      "z": -2,
      "name": "Rock_Aqua"
    },
    {
      "x": -5,
      "y": 5,
      "z": -2,
      "name": "Rock_Aqua"
    },
    {
      "x": -5,
      "y": 6,
      "z": -2,
      "name": "Plant_Moss_Blue",
      "support": 15
    },
    {
      "x": -5,
      "y": 0,
      "z": -1,
      "name": "Rock_Aqua"
    },
    {
      "x": -5,
      "y": 1,
      "z": -1,
      "name": "Rock_Aqua"
    },
    {
      "x": -5,
      "y": 2,
      "z": -1,
      "name": "Rubble_Aqua_Medium",
      "support": 15
    },
    {
      "x": -5,
      "y": 3,
      "z": -1,
      "name": "Rock_Aqua_Stalactite_Small",
      "rotation": 8
    },
    {
      "x": -5,
      "y": 4,
      "z": -1,
      "name": "Rock_Aqua"
    },
    {
      "x": -5,
      "y": 5,
      "z": -1,
      "name": "Rock_Aqua_Stairs"
    },
    {
      "x": -5,
      "y": 1,
      "z": 0,
      "name": "Rock_Aqua"
    },
    {
      "x": -5,
      "y": 2,
      "z": 0,
      "name": "Empty"
    },
    {
      "x": -5,
      "y": 3,
      "z": 0,
      "name": "Rock_Aqua"
    },
    {
      "x": -5,
      "y": 4,
      "z": 0,
      "name": "Rock_Aqua"
    },
    {
      "x": -5,
      "y": 5,
      "z": 0,
      "name": "Rubble_Aqua_Medium",
      "support": 15
    },
    {
      "x": -5,
      "y": 1,
      "z": 1,
      "name": "Rock_Aqua"
    },
    {
      "x": -5,
      "y": 2,
      "z": 1,
      "name": "Rock_Aqua"
    },
    {
      "x": -5,
      "y": 3,
      "z": 1,
      "name": "Rock_Aqua"
    },
    {
      "x": -5,
      "y": 4,
      "z": 1,
      "name": "Rock_Aqua"
    },
    {
      "x": -5,
      "y": 2,
      "z": 2,
      "name": "Rock_Aqua"
    },
    {
      "x": -5,
      "y": 3,
      "z": 2,
      "name": "Rock_Aqua"
    },
    {
      "x": -5,
      "y": 4,
      "z": 2,
      "name": "Rock_Aqua"
    },
    {
      "x": -4,
      "y": 1,
      "z": -4,
      "name": "Rock_Aqua"
    },
    {
      "x": -4,
      "y": 2,
      "z": -4,
      "name": "Rock_Aqua"
    },
    {
      "x": -4,
      "y": 3,
      "z": -4,
      "name": "Rock_Aqua"
    },
    {
      "x": -4,
      "y": 4,
      "z": -4,
      "name": "Rock_Aqua"
    },
    {
      "x": -4,
      "y": 0,
      "z": -3,
      "name": "Rock_Aqua"
    },
    {
      "x": -4,
      "y": 1,
      "z": -3,
      "name": "Rock_Aqua"
    },
    {
      "x": -4,
      "y": 2,
      "z": -3,
      "name": "Rock_Aqua"
    },
    {
      "x": -4,
      "y": 3,
      "z": -3,
      "name": "Rock_Aqua"
    },
    {
      "x": -4,
      "y": 4,
      "z": -3,
      "name": "Rock_Aqua"
    },
    {
      "x": -4,
      "y": 5,
      "z": -3,
      "name": "Rock_Aqua"
    },
    {
      "x": -4,
      "y": 0,
      "z": -2,
      "name": "Rock_Aqua"
    },
    {
      "x": -4,
      "y": 1,
      "z": -2,
      "name": "Rock_Aqua"
    },
    {
      "x": -4,
      "y": 2,
      "z": -2,
      "name": "Rock_Aqua"
    },
    {
      "x": -4,
      "y": 3,
      "z": -2,
      "name": "Rock_Aqua"
    },
    {
      "x": -4,
      "y": 4,
      "z": -2,
      "name": "Rock_Aqua"
    },
    {
      "x": -4,
      "y": 0,
      "z": -1,
      "name": "Rock_Aqua"
    },
    {
      "x": -4,
      "y": 1,
      "z": -1,
      "name": "*Rock_Aqua_Brick_Stairs_State_Definitions_Inverted_Corner_Left"
    },
    {
      "x": -4,
      "y": 2,
      "z": -1,
      "name": "Empty"
    },
    {
      "x": -4,
      "y": 3,
      "z": -1,
      "name": "Empty"
    },
    {
      "x": -4,
      "y": 4,
      "z": -1,
      "name": "Rock_Aqua"
    },
    {
      "x": -4,
      "y": 5,
      "z": -1,
      "name": "Rubble_Aqua_Medium",
      "support": 15
    },
    {
      "x": -4,
      "y": 0,
      "z": 0,
      "name": "Rock_Aqua"
    },
    {
      "x": -4,
      "y": 1,
      "z": 0,
      "name": "Rock_Aqua_Brick_Stairs",
      "rotation": 1
    },
    {
      "x": -4,
      "y": 2,
      "z": 0,
      "name": "Empty"
    },
    {
      "x": -4,
      "y": 3,
      "z": 0,
      "name": "Empty"
    },
    {
      "x": -4,
      "y": 4,
      "z": 0,
      "name": "Rock_Aqua"
    },
    {
      "x": -4,
      "y": 5,
      "z": 0,
      "name": "Plant_Moss_Short_Blue",
      "support": 15
    },
    {
      "x": -4,
      "y": 0,
      "z": 1,
      "name": "Rock_Aqua"
    },
    {
      "x": -4,
      "y": 1,
      "z": 1,
      "name": "*Rock_Aqua_Brick_Stairs_State_Definitions_Inverted_Corner_Left",
      "rotation": 1
    },
    {
      "x": -4,
      "y": 2,
      "z": 1,
      "name": "Empty"
    },
    {
      "x": -4,
      "y": 3,
      "z": 1,
      "name": "Rock_Aqua_Stalactite_Large",
      "rotation": 8
    },
    {
      "x": -4,
      "y": 4,
      "z": 1,
      "name": "Rock_Aqua"
    },
    {
      "x": -4,
      "y": 5,
      "z": 1,
      "name": "Plant_Moss_Blue",
      "support": 15
    },
    {
      "x": -4,
      "y": 1,
      "z": 2,
      "name": "Rock_Aqua"
    },
    {
      "x": -4,
      "y": 2,
      "z": 2,
      "name": "Rock_Aqua"
    },
    {
      "x": -4,
      "y": 3,
      "z": 2,
      "name": "Rock_Aqua"
    },
    {
      "x": -4,
      "y": 4,
      "z": 2,
      "name": "Rock_Aqua"
    },
    {
      "x": -4,
      "y": 1,
      "z": 3,
      "name": "Rock_Aqua"
    },
    {
      "x": -4,
      "y": 2,
      "z": 3,
      "name": "Rock_Aqua"
    },
    {
      "x": -4,
      "y": 3,
      "z": 3,
      "name": "Rock_Aqua"
    },
    {
      "x": -4,
      "y": 4,
      "z": 3,
      "name": "Rock_Aqua"
    },
    {
      "x": -3,
      "y": 1,
      "z": -4,
      "name": "Rock_Aqua"
    },
    {
      "x": -3,
      "y": 2,
      "z": -4,
      "name": "Rock_Aqua"
    },
    {
      "x": -3,
      "y": 3,
      "z": -4,
      "name": "Rock_Aqua"
    },
    {
      "x": -3,
      "y": 0,
      "z": -3,
      "name": "Rock_Aqua"
    },
    {
      "x": -3,
      "y": 1,
      "z": -3,
      "name": "Rock_Aqua"
    },
    {
      "x": -3,
      "y": 2,
      "z": -3,
      "name": "Rock_Aqua"
    },
    {
      "x": -3,
      "y": 3,
      "z": -3,
      "name": "Rock_Aqua"
    },
    {
      "x": -3,
      "y": 4,
      "z": -3,
      "name": "Rock_Aqua"
    },
    {
      "x": -3,
      "y": 5,
      "z": -3,
      "name": "Plant_Moss_Short_Blue",
      "support": 15
    },
    {
      "x": -3,
      "y": 0,
      "z": -2,
      "name": "Rock_Aqua"
    },
    {
      "x": -3,
      "y": 1,
      "z": -2,
      "name": "Rock_Aqua_Brick_Smooth"
    },
    {
      "x": -3,
      "y": 2,
      "z": -2,
      "name": "Rock_Aqua_Brick_Pillar_Middle"
    },
    {
      "x": -3,
      "y": 3,
      "z": -2,
      "name": "Rock_Aqua_Brick_Pillar_Middle"
    },
    {
      "x": -3,
      "y": 4,
      "z": -2,
      "name": "Rock_Aqua_Brick_Pillar_Middle"
    },
    {
      "x": -3,
      "y": 5,
      "z": -2,
      "name": "Rock_Aqua_Brick_Pillar_Middle"
    },
    {
      "x": -3,
      "y": 6,
      "z": -2,
      "name": "Rock_Aqua_Brick_Stairs",
      "rotation": 2
    },
    {
      "x": -3,
      "y": 0,
      "z": -1,
      "name": "Rock_Aqua"
    },
    {
      "x": -3,
      "y": 1,
      "z": -1,
      "name": "Rock_Aqua_Brick_Stairs"
    },
    {
      "x": -3,
      "y": 2,
      "z": -1,
      "name": "Empty"
    },
    {
      "x": -3,
      "y": 3,
      "z": -1,
      "name": "Empty"
    },
    {
      "x": -3,
      "y": 4,
      "z": -1,
      "name": "Empty"
    },
    {
      "x": -3,
      "y": 5,
      "z": -1,
      "name": "Empty"
    },
    {
      "x": -3,
      "y": 6,
      "z": -1,
      "name": "Rock_Aqua_Brick_Stairs",
      "rotation": 10
    },
    {
      "x": -3,
      "y": 7,
      "z": -1,
      "name": "Rock_Aqua_Brick_Smooth_Half"
    },
    {
      "x": -3,
      "y": 0,
      "z": 0,
      "name": "Rock_Aqua"
    },
    {
      "x": -3,
      "y": 1,
      "z": 0,
      "name": "Rock_Aqua_Brick_Smooth_Half"
    },
    {
      "x": -3,
      "y": 2,
      "z": 0,
      "name": "Empty"
    },
    {
      "x": -3,
      "y": 3,
      "z": 0,
      "name": "Empty"
    },
    {
      "x": -3,
      "y": 4,
      "z": 0,
      "name": "Empty"
    },
    {
      "x": -3,
      "y": 5,
      "z": 0,
      "name": "Empty"
    },
    {
      "x": -3,
      "y": 6,
      "z": 0,
      "name": "Empty"
    },
    {
      "x": -3,
      "y": 7,
      "z": 0,
      "name": "Rock_Aqua_Cobble_Roof_Flat",
      "rotation": 2
    },
    {
      "x": -3,
      "y": 0,
      "z": 1,
      "name": "Rock_Aqua"
    },
    {
      "x": -3,
      "y": 1,
      "z": 1,
      "name": "Rock_Aqua_Brick_Stairs",
      "rotation": 2
    },
    {
      "x": -3,
      "y": 2,
      "z": 1,
      "name": "Empty"
    },
    {
      "x": -3,
      "y": 3,
      "z": 1,
      "name": "Empty"
    },
    {
      "x": -3,
      "y": 4,
      "z": 1,
      "name": "Empty"
    },
    {
      "x": -3,
      "y": 5,
      "z": 1,
      "name": "Empty"
    },
    {
      "x": -3,
      "y": 6,
      "z": 1,
      "name": "Rock_Aqua_Brick_Stairs",
      "rotation": 8
    },
    {
      "x": -3,
      "y": 7,
      "z": 1,
      "name": "Rock_Aqua_Brick_Smooth_Half"
    },
    {
      "x": -3,
      "y": 0,
      "z": 2,
      "name": "Rock_Aqua"
    },
    {
      "x": -3,
      "y": 1,
      "z": 2,
      "name": "Rock_Aqua_Brick_Smooth"
    },
    {
      "x": -3,
      "y": 2,
      "z": 2,
      "name": "Rock_Aqua_Brick_Pillar_Middle"
    },
    {
      "x": -3,
      "y": 3,
      "z": 2,
      "name": "Rock_Aqua_Brick_Pillar_Middle"
    },
    {
      "x": -3,
      "y": 4,
      "z": 2,
      "name": "Rock_Aqua_Brick_Pillar_Middle"
    },
    {
      "x": -3,
      "y": 5,
      "z": 2,
      "name": "Rock_Aqua_Brick_Pillar_Middle"
    },
    {
      "x": -3,
      "y": 6,
      "z": 2,
      "name": "Rock_Aqua_Brick_Smooth_Half",
      "rotation": 4
    },
    {
      "x": -3,
      "y": 1,
      "z": 3,
      "name": "Rock_Aqua"
    },
    {
      "x": -3,
      "y": 2,
      "z": 3,
      "name": "Rock_Aqua"
    },
    {
      "x": -3,
      "y": 3,
      "z": 3,
      "name": "Rock_Aqua"
    },
    {
      "x": -3,
      "y": 4,
      "z": 3,
      "name": "Rock_Aqua"
    },
    {
      "x": -3,
      "y": 1,
      "z": 4,
      "name": "Rock_Aqua"
    },
    {
      "x": -3,
      "y": 2,
      "z": 4,
      "name": "Rock_Aqua"
    },
    {
      "x": -2,
      "y": 0,
      "z": -4,
      "name": "Rock_Aqua"
    },
    {
      "x": -2,
      "y": 1,
      "z": -4,
      "name": "Rock_Aqua"
    },
    {
      "x": -2,
      "y": 2,
      "z": -4,
      "name": "Rock_Aqua"
    },
    {
      "x": -2,
      "y": 3,
      "z": -4,
      "name": "Rock_Aqua"
    },
    {
      "x": -2,
      "y": 0,
      "z": -3,
      "name": "Rock_Aqua"
    },
    {
      "x": -2,
      "y": 1,
      "z": -3,
      "name": "Rock_Aqua"
    },
    {
      "x": -2,
      "y": 2,
      "z": -3,
      "name": "Rock_Aqua"
    },
    {
      "x": -2,
      "y": 3,
      "z": -3,
      "name": "Rock_Aqua_Stairs"
    },
    {
      "x": -2,
      "y": 4,
      "z": -3,
      "name": "Rock_Aqua"
    },
    {
      "x": -2,
      "y": 0,
      "z": -2,
      "name": "Rock_Aqua"
    },
    {
      "x": -2,
      "y": 1,
      "z": -2,
      "name": "Rock_Aqua_Brick_Smooth"
    },
    {
      "x": -2,
      "y": 2,
      "z": -2,
      "name": "Rubble_Aqua",
      "support": 15
    },
    {
      "x": -2,
      "y": 3,
      "z": -2,
      "name": "Empty"
    },
    {
      "x": -2,
      "y": 4,
      "z": -2,
      "name": "Empty"
    },
    {
      "x": -2,
      "y": 5,
      "z": -2,
      "name": "Empty"
    },
    {
      "x": -2,
      "y": 6,
      "z": -2,
      "name": "Rock_Aqua_Brick_Smooth_Half",
      "rotation": 6
    },
    {
      "x": -2,
      "y": 0,
      "z": -1,
      "name": "Rock_Aqua"
    },
    {
      "x": -2,
      "y": 1,
      "z": -1,
      "name": "Rock_Aqua_Brick_Stairs"
    },
    {
      "x": -2,
      "y": 2,
      "z": -1,
      "name": "Empty"
    },
    {
      "x": -2,
      "y": 3,
      "z": -1,
      "name": "Empty"
    },
    {
      "x": -2,
      "y": 4,
      "z": -1,
      "name": "Empty"
    },
    {
      "x": -2,
      "y": 5,
      "z": -1,
      "name": "Empty"
    },
    {
      "x": -2,
      "y": 6,
      "z": -1,
      "name": "Empty"
    },
    {
      "x": -2,
      "y": 7,
      "z": -1,
      "name": "Rock_Aqua_Brick_Smooth_Half"
    },
    {
      "x": -2,
      "y": 0,
      "z": 0,
      "name": "Rock_Aqua"
    },
    {
      "x": -2,
      "y": 1,
      "z": 0,
      "name": "Rock_Aqua_Brick_Smooth_Half"
    },
    {
      "x": -2,
      "y": 2,
      "z": 0,
      "name": "Empty"
    },
    {
      "x": -2,
      "y": 3,
      "z": 0,
      "name": "Empty"
    },
    {
      "x": -2,
      "y": 4,
      "z": 0,
      "name": "Empty"
    },
    {
      "x": -2,
      "y": 5,
      "z": 0,
      "name": "Empty"
    },
    {
      "x": -2,
      "y": 6,
      "z": 0,
      "name": "Empty"
    },
    {
      "x": -2,
      "y": 7,
      "z": 0,
      "name": "Rock_Aqua_Cobble_Roof_Flat",
      "rotation": 2
    },
    {
      "x": -2,
      "y": 0,
      "z": 1,
      "name": "Rock_Aqua"
    },
    {
      "x": -2,
      "y": 1,
      "z": 1,
      "name": "Rock_Aqua_Brick_Stairs",
      "rotation": 2
    },
    {
      "x": -2,
      "y": 2,
      "z": 1,
      "name": "Empty"
    },
    {
      "x": -2,
      "y": 3,
      "z": 1,
      "name": "Empty"
    },
    {
      "x": -2,
      "y": 4,
      "z": 1,
      "name": "Empty"
    },
    {
      "x": -2,
      "y": 5,
      "z": 1,
      "name": "Empty"
    },
    {
      "x": -2,
      "y": 6,
      "z": 1,
      "name": "Empty"
    },
    {
      "x": -2,
      "y": 7,
      "z": 1,
      "name": "Rock_Aqua_Brick_Smooth_Half"
    },
    {
      "x": -2,
      "y": 0,
      "z": 2,
      "name": "Rock_Aqua"
    },
    {
      "x": -2,
      "y": 1,
      "z": 2,
      "name": "Rock_Aqua_Brick_Smooth"
    },
    {
      "x": -2,
      "y": 2,
      "z": 2,
      "name": "Furniture_Human_Ruins_Lantern"
    },
    {
      "x": -2,
      "y": 3,
      "z": 2,
      "name": "Empty"
    },
    {
      "x": -2,
      "y": 4,
      "z": 2,
      "name": "Empty"
    },
    {
      "x": -2,
      "y": 5,
      "z": 2,
      "name": "Empty"
    },
    {
      "x": -2,
      "y": 6,
      "z": 2,
      "name": "Rock_Aqua_Brick_Stairs"
    },
    {
      "x": -2,
      "y": 0,
      "z": 3,
      "name": "Rock_Aqua"
    },
    {
      "x": -2,
      "y": 1,
      "z": 3,
      "name": "Rock_Aqua"
    },
    {
      "x": -2,
      "y": 2,
      "z": 3,
      "name": "Rock_Aqua"
    },
    {
      "x": -2,
      "y": 3,
      "z": 3,
      "name": "Rock_Aqua"
    },
    {
      "x": -2,
      "y": 4,
      "z": 3,
      "name": "Rock_Aqua"
    },
    {
      "x": -2,
      "y": 5,
      "z": 3,
      "name": "Rubble_Aqua_Medium",
      "support": 15
    },
    {
      "x": -2,
      "y": 1,
      "z": 4,
      "name": "Rock_Aqua"
    },
    {
      "x": -2,
      "y": 2,
      "z": 4,
      "name": "Rock_Aqua"
    },
    {
      "x": -2,
      "y": 3,
      "z": 4,
      "name": "Rock_Aqua"
    },
    {
      "x": -2,
      "y": 4,
      "z": 4,
      "name": "Rock_Aqua"
    },
    {
      "x": -1,
      "y": 0,
      "z": -4,
      "name": "Rock_Aqua"
    },
    {
      "x": -1,
      "y": 1,
      "z": -4,
      "name": "Rock_Aqua"
    },
    {
      "x": -1,
      "y": 2,
      "z": -4,
      "name": "Rock_Aqua"
    },
    {
      "x": -1,
      "y": 3,
      "z": -4,
      "name": "Rock_Aqua"
    },
    {
      "x": -1,
      "y": 4,
      "z": -4,
      "name": "Rock_Aqua"
    },
    {
      "x": -1,
      "y": 0,
      "z": -3,
      "name": "Rock_Aqua"
    },
    {
      "x": -1,
      "y": 1,
      "z": -3,
      "name": "Rock_Aqua"
    },
    {
      "x": -1,
      "y": 2,
      "z": -3,
      "name": "Rock_Aqua_Stalactite_Large"
    },
    {
      "x": -1,
      "y": 3,
      "z": -3,
      "name": "Empty"
    },
    {
      "x": -1,
      "y": 4,
      "z": -3,
      "name": "Rock_Aqua_Stairs",
      "rotation": 10
    },
    {
      "x": -1,
      "y": 5,
      "z": -3,
      "name": "Rubble_Aqua_Medium",
      "support": 15
    },
    {
      "x": -1,
      "y": 0,
      "z": -2,
      "name": "Rock_Aqua"
    },
    {
      "x": -1,
      "y": 1,
      "z": -2,
      "name": "Rock_Aqua_Brick_Smooth"
    },
    {
      "x": -1,
      "y": 2,
      "z": -2,
      "name": "Empty"
    },
    {
      "x": -1,
      "y": 3,
      "z": -2,
      "name": "Empty"
    },
    {
      "x": -1,
      "y": 4,
      "z": -2,
      "name": "Empty"
    },
    {
      "x": -1,
      "y": 5,
      "z": -2,
      "name": "Empty"
    },
    {
      "x": -1,
      "y": 6,
      "z": -2,
      "name": "Rock_Aqua_Brick_Stairs",
      "rotation": 2
    },
    {
      "x": -1,
      "y": 0,
      "z": -1,
      "name": "Rock_Aqua"
    },
    {
      "x": -1,
      "y": 1,
      "z": -1,
      "name": "Rock_Aqua_Brick_Stairs"
    },
    {
      "x": -1,
      "y": 2,
      "z": -1,
      "name": "Empty"
    },
    {
      "x": -1,
      "y": 3,
      "z": -1,
      "name": "Empty"
    },
    {
      "x": -1,
      "y": 4,
      "z": -1,
      "name": "Empty"
    },
    {
      "x": -1,
      "y": 5,
      "z": -1,
      "name": "Empty"
    },
    {
      "x": -1,
      "y": 6,
      "z": -1,
      "name": "Rock_Aqua_Brick_Stairs",
      "rotation": 10
    },
    {
      "x": -1,
      "y": 7,
      "z": -1,
      "name": "Rock_Aqua_Brick_Smooth_Half"
    },
    {
      "x": -1,
      "y": 0,
      "z": 0,
      "name": "Rock_Aqua"
    },
    {
      "x": -1,
      "y": 1,
      "z": 0,
      "name": "Rock_Aqua_Brick_Smooth_Half"
    },
    {
      "x": -1,
      "y": 2,
      "z": 0,
      "name": "Empty"
    },
    {
      "x": -1,
      "y": 3,
      "z": 0,
      "name": "Empty"
    },
    {
      "x": -1,
      "y": 4,
      "z": 0,
      "name": "Empty"
    },
    {
      "x": -1,
      "y": 5,
      "z": 0,
      "name": "Empty"
    },
    {
      "x": -1,
      "y": 6,
      "z": 0,
      "name": "Empty"
    },
    {
      "x": -1,
      "y": 7,
      "z": 0,
      "name": "Rock_Aqua_Cobble_Roof_Flat",
      "rotation": 2
    },
    {
      "x": -1,
      "y": 0,
      "z": 1,
      "name": "Rock_Aqua"
    },
    {
      "x": -1,
      "y": 1,
      "z": 1,
      "name": "Rock_Aqua_Brick_Stairs",
      "rotation": 2
    },
    {
      "x": -1,
      "y": 2,
      "z": 1,
      "name": "Empty"
    },
    {
      "x": -1,
      "y": 3,
      "z": 1,
      "name": "Empty"
    },
    {
      "x": -1,
      "y": 4,
      "z": 1,
      "name": "Empty"
    },
    {
      "x": -1,
      "y": 5,
      "z": 1,
      "name": "Empty"
    },
    {
      "x": -1,
      "y": 6,
      "z": 1,
      "name": "Rock_Aqua_Brick_Stairs",
      "rotation": 8
    },
    {
      "x": -1,
      "y": 7,
      "z": 1,
      "name": "Rock_Aqua_Brick_Stairs",
      "rotation": 2
    },
    {
      "x": -1,
      "y": 0,
      "z": 2,
      "name": "Rock_Aqua"
    },
    {
      "x": -1,
      "y": 1,
      "z": 2,
      "name": "Rock_Aqua_Brick_Smooth"
    },
    {
      "x": -1,
      "y": 2,
      "z": 2,
      "name": "Empty"
    },
    {
      "x": -1,
      "y": 3,
      "z": 2,
      "name": "Empty"
    },
    {
      "x": -1,
      "y": 4,
      "z": 2,
      "name": "Empty"
    },
    {
      "x": -1,
      "y": 5,
      "z": 2,
      "name": "Empty"
    },
    {
      "x": -1,
      "y": 6,
      "z": 2,
      "name": "Rock_Aqua_Brick_Stairs"
    },
    {
      "x": -1,
      "y": 0,
      "z": 3,
      "name": "Rock_Aqua"
    },
    {
      "x": -1,
      "y": 1,
      "z": 3,
      "name": "Rock_Aqua"
    },
    {
      "x": -1,
      "y": 2,
      "z": 3,
      "name": "Rock_Aqua"
    },
    {
      "x": -1,
      "y": 3,
      "z": 3,
      "name": "Rubble_Aqua_Medium",
      "support": 15
    },
    {
      "x": -1,
      "y": 4,
      "z": 3,
      "name": "Empty"
    },
    {
      "x": -1,
      "y": 0,
      "z": 4,
      "name": "Rock_Aqua"
    },
    {
      "x": -1,
      "y": 1,
      "z": 4,
      "name": "Rock_Aqua"
    },
    {
      "x": -1,
      "y": 2,
      "z": 4,
      "name": "Rock_Aqua"
    },
    {
      "x": -1,
      "y": 3,
      "z": 4,
      "name": "Rock_Aqua"
    },
    {
      "x": -1,
      "y": 4,
      "z": 4,
      "name": "Rock_Aqua"
    },
    {
      "x": -1,
      "y": 1,
      "z": 5,
      "name": "Rock_Aqua"
    },
    {
      "x": -1,
      "y": 2,
      "z": 5,
      "name": "Rock_Aqua"
    },
    {
      "x": -1,
      "y": 3,
      "z": 5,
      "name": "Rock_Aqua"
    },
    {
      "x": 0,
      "y": 0,
      "z": -4,
      "name": "Rock_Aqua"
    },
    {
      "x": 0,
      "y": 1,
      "z": -4,
      "name": "Rock_Aqua"
    },
    {
      "x": 0,
      "y": 2,
      "z": -4,
      "name": "Rock_Aqua"
    },
    {
      "x": 0,
      "y": 3,
      "z": -4,
      "name": "Rock_Aqua"
    },
    {
      "x": 0,
      "y": 4,
      "z": -4,
      "name": "Rock_Aqua"
    },
    {
      "x": 0,
      "y": 0,
      "z": -3,
      "name": "Rock_Aqua"
    },
    {
      "x": 0,
      "y": 1,
      "z": -3,
      "name": "Rock_Aqua"
    },
    {
      "x": 0,
      "y": 2,
      "z": -3,
      "name": "Rock_Aqua"
    },
    {
      "x": 0,
      "y": 3,
      "z": -3,
      "name": "Rubble_Aqua",
      "support": 15
    },
    {
      "x": 0,
      "y": 4,
      "z": -3,
      "name": "Rock_Aqua"
    },
    {
      "x": 0,
      "y": 0,
      "z": -2,
      "name": "Rock_Aqua"
    },
    {
      "x": 0,
      "y": 1,
      "z": -2,
      "name": "Rock_Aqua_Brick_Smooth"
    },
    {
      "x": 0,
      "y": 2,
      "z": -2,
      "name": "Plant_Crop_Mushroom_Common_Blue",
      "components": {
        "Components": {
          "FarmingBlock": {
            "LastTickGameTime": "0001-01-01T12:00:00Z"
          }
        }
      }
    },
    {
      "x": 0,
      "y": 3,
      "z": -2,
      "name": "Empty"
    },
    {
      "x": 0,
      "y": 4,
      "z": -2,
      "name": "Empty"
    },
    {
      "x": 0,
      "y": 5,
      "z": -2,
      "name": "Empty"
    },
    {
      "x": 0,
      "y": 6,
      "z": -2,
      "name": "Rock_Aqua_Brick_Stairs",
      "rotation": 2
    },
    {
      "x": 0,
      "y": 0,
      "z": -1,
      "name": "Rock_Aqua"
    },
    {
      "x": 0,
      "y": 1,
      "z": -1,
      "name": "Rock_Aqua_Brick_Stairs"
    },
    {
      "x": 0,
      "y": 2,
      "z": -1,
      "name": "Empty"
    },
    {
      "x": 0,
      "y": 3,
      "z": -1,
      "name": "Empty"
    },
    {
      "x": 0,
      "y": 4,
      "z": -1,
      "name": "Empty"
    },
    {
      "x": 0,
      "y": 5,
      "z": -1,
      "name": "Empty"
    },
    {
      "x": 0,
      "y": 6,
      "z": -1,
      "name": "Empty"
    },
    {
      "x": 0,
      "y": 7,
      "z": -1,
      "name": "Rock_Aqua_Brick_Smooth_Half"
    },
    {
      "x": 0,
      "y": 0,
      "z": 0,
      "name": "Rock_Aqua"
    },
    {
      "x": 0,
      "y": 1,
      "z": 0,
      "name": "Rock_Aqua_Brick_Smooth_Half"
    },
    {
      "x": 0,
      "y": 2,
      "z": 0,
      "name": "Empty"
    },
    {
      "x": 0,
      "y": 3,
      "z": 0,
      "name": "Empty"
    },
    {
      "x": 0,
      "y": 4,
      "z": 0,
      "name": "Empty"
    },
    {
      "x": 0,
      "y": 5,
      "z": 0,
      "name": "Empty"
    },
    {
      "x": 0,
      "y": 6,
      "z": 0,
      "name": "Empty"
    },
    {
      "x": 0,
      "y": 7,
      "z": 0,
      "name": "Rock_Aqua_Cobble_Roof_Flat",
      "rotation": 2
    },
    {
      "x": 0,
      "y": 0,
      "z": 1,
      "name": "Rock_Aqua"
    },
    {
      "x": 0,
      "y": 1,
      "z": 1,
      "name": "Rock_Aqua_Brick_Stairs",
      "rotation": 2
    },
    {
      "x": 0,
      "y": 2,
      "z": 1,
      "name": "Empty"
    },
    {
      "x": 0,
      "y": 3,
      "z": 1,
      "name": "Empty"
    },
    {
      "x": 0,
      "y": 4,
      "z": 1,
      "name": "Empty"
    },
    {
      "x": 0,
      "y": 5,
      "z": 1,
      "name": "Empty"
    },
    {
      "x": 0,
      "y": 6,
      "z": 1,
      "name": "Empty"
    },
    {
      "x": 0,
      "y": 7,
      "z": 1,
      "name": "Rock_Aqua_Brick_Smooth_Half"
    },
    {
      "x": 0,
      "y": 0,
      "z": 2,
      "name": "Rock_Aqua"
    },
    {
      "x": 0,
      "y": 1,
      "z": 2,
      "name": "Rock_Aqua_Brick_Smooth"
    },
    {
      "x": 0,
      "y": 2,
      "z": 2,
      "name": "Empty"
    },
    {
      "x": 0,
      "y": 3,
      "z": 2,
      "name": "Empty"
    },
    {
      "x": 0,
      "y": 4,
      "z": 2,
      "name": "Empty"
    },
    {
      "x": 0,
      "y": 5,
      "z": 2,
      "name": "Empty"
    },
    {
      "x": 0,
      "y": 6,
      "z": 2,
      "name": "Rock_Aqua_Brick_Smooth_Half",
      "rotation": 4
    },
    {
      "x": 0,
      "y": 0,
      "z": 3,
      "name": "Rock_Aqua"
    },
    {
      "x": 0,
      "y": 1,
      "z": 3,
      "name": "Rock_Aqua"
    },
    {
      "x": 0,
      "y": 2,
      "z": 3,
      "name": "Rock_Aqua"
    },
    {
      "x": 0,
      "y": 3,
      "z": 3,
      "name": "Rock_Aqua_Stalactite_Small"
    },
    {
      "x": 0,
      "y": 4,
      "z": 3,
      "name": "Empty"
    },
    {
      "x": 0,
      "y": 0,
      "z": 4,
      "name": "Rock_Aqua"
    },
    {
      "x": 0,
      "y": 1,
      "z": 4,
      "name": "Rock_Aqua"
    },
    {
      "x": 0,
      "y": 2,
      "z": 4,
      "name": "Rock_Aqua"
    },
    {
      "x": 0,
      "y": 3,
      "z": 4,
      "name": "Rock_Aqua"
    },
    {
      "x": 0,
      "y": 4,
      "z": 4,
      "name": "Rock_Aqua_Stairs",
      "rotation": 2
    },
    {
      "x": 0,
      "y": 1,
      "z": 5,
      "name": "Rock_Aqua"
    },
    {
      "x": 0,
      "y": 2,
      "z": 5,
      "name": "Rock_Aqua"
    },
    {
      "x": 0,
      "y": 3,
      "z": 5,
      "name": "Rock_Aqua"
    },
    {
      "x": 1,
      "y": 0,
      "z": -4,
      "name": "Rock_Aqua"
    },
    {
      "x": 1,
      "y": 1,
      "z": -4,
      "name": "Rock_Aqua"
    },
    {
      "x": 1,
      "y": 2,
      "z": -4,
      "name": "Rock_Aqua"
    },
    {
      "x": 1,
      "y": 3,
      "z": -4,
      "name": "Rock_Aqua"
    },
    {
      "x": 1,
      "y": 0,
      "z": -3,
      "name": "Rock_Aqua"
    },
    {
      "x": 1,
      "y": 1,
      "z": -3,
      "name": "Rock_Aqua"
    },
    {
      "x": 1,
      "y": 2,
      "z": -3,
      "name": "Rock_Aqua"
    },
    {
      "x": 1,
      "y": 3,
      "z": -3,
      "name": "Rock_Aqua"
    },
    {
      "x": 1,
      "y": 4,
      "z": -3,
      "name": "Rock_Aqua"
    },
    {
      "x": 1,
      "y": 0,
      "z": -2,
      "name": "Rock_Aqua"
    },
    {
      "x": 1,
      "y": 1,
      "z": -2,
      "name": "Rock_Aqua_Brick_Smooth"
    },
    {
      "x": 1,
      "y": 2,
      "z": -2,
      "name": "Plant_Crop_Mushroom_Glowing_Blue"
    },
    {
      "x": 1,
      "y": 3,
      "z": -2,
      "name": "Empty"
    },
    {
      "x": 1,
      "y": 4,
      "z": -2,
      "name": "Empty"
    },
    {
      "x": 1,
      "y": 5,
      "z": -2,
      "name": "Empty"
    },
    {
      "x": 1,
      "y": 6,
      "z": -2,
      "name": "Rock_Aqua_Brick_Stairs",
      "rotation": 2
    },
    {
      "x": 1,
      "y": 0,
      "z": -1,
      "name": "Rock_Aqua"
    },
    {
      "x": 1,
      "y": 1,
      "z": -1,
      "name": "Rock_Aqua_Brick_Stairs"
    },
    {
      "x": 1,
      "y": 2,
      "z": -1,
      "name": "Empty"
    },
    {
      "x": 1,
      "y": 3,
      "z": -1,
      "name": "Empty"
    },
    {
      "x": 1,
      "y": 4,
      "z": -1,
      "name": "Empty"
    },
    {
      "x": 1,
      "y": 5,
      "z": -1,
      "name": "Empty"
    },
    {
      "x": 1,
      "y": 6,
      "z": -1,
      "name": "Rock_Aqua_Brick_Stairs",
      "rotation": 10
    },
    {
      "x": 1,
      "y": 7,
      "z": -1,
      "name": "Rock_Aqua_Brick_Stairs",
      "rotation": 1
    },
    {
      "x": 1,
      "y": 0,
      "z": 0,
      "name": "Rock_Aqua"
    },
    {
      "x": 1,
      "y": 1,
      "z": 0,
      "name": "Rock_Aqua_Brick_Smooth_Half"
    },
    {
      "x": 1,
      "y": 2,
      "z": 0,
      "name": "Empty"
    },
    {
      "x": 1,
      "y": 3,
      "z": 0,
      "name": "Empty"
    },
    {
      "x": 1,
      "y": 4,
      "z": 0,
      "name": "Empty"
    },
    {
      "x": 1,
      "y": 5,
      "z": 0,
      "name": "Empty"
    },
    {
      "x": 1,
      "y": 6,
      "z": 0,
      "name": "Empty"
    },
    {
      "x": 1,
      "y": 7,
      "z": 0,
      "name": "Rock_Aqua_Cobble_Roof_Flat",
      "rotation": 2
    },
    {
      "x": 1,
      "y": 0,
      "z": 1,
      "name": "Rock_Aqua"
    },
    {
      "x": 1,
      "y": 1,
      "z": 1,
      "name": "Rock_Aqua_Brick_Stairs",
      "rotation": 2
    },
    {
      "x": 1,
      "y": 2,
      "z": 1,
      "name": "Empty"
    },
    {
      "x": 1,
      "y": 3,
      "z": 1,
      "name": "Empty"
    },
    {
      "x": 1,
      "y": 4,
      "z": 1,
      "name": "Empty"
    },
    {
      "x": 1,
      "y": 5,
      "z": 1,
      "name": "Empty"
    },
    {
      "x": 1,
      "y": 6,
      "z": 1,
      "name": "Rock_Aqua_Brick_Stairs",
      "rotation": 8
    },
    {
      "x": 1,
      "y": 7,
      "z": 1,
      "name": "Rock_Aqua_Brick_Smooth_Half"
    },
    {
      "x": 1,
      "y": 0,
      "z": 2,
      "name": "Rock_Aqua"
    },
    {
      "x": 1,
      "y": 1,
      "z": 2,
      "name": "Rock_Aqua_Brick_Smooth"
    },
    {
      "x": 1,
      "y": 2,
      "z": 2,
      "name": "Empty"
    },
    {
      "x": 1,
      "y": 3,
      "z": 2,
      "name": "Empty"
    },
    {
      "x": 1,
      "y": 4,
      "z": 2,
      "name": "Empty"
    },
    {
      "x": 1,
      "y": 5,
      "z": 2,
      "name": "Empty"
    },
    {
      "x": 1,
      "y": 6,
      "z": 2,
      "name": "Rock_Aqua_Brick_Stairs"
    },
    {
      "x": 1,
      "y": 0,
      "z": 3,
      "name": "Rock_Aqua"
    },
    {
      "x": 1,
      "y": 1,
      "z": 3,
      "name": "Rock_Aqua"
    },
    {
      "x": 1,
      "y": 2,
      "z": 3,
      "name": "Rock_Aqua"
    },
    {
      "x": 1,
      "y": 3,
      "z": 3,
      "name": "Rock_Aqua"
    },
    {
      "x": 1,
      "y": 4,
      "z": 3,
      "name": "Rock_Aqua_Stalactite_Large"
    },
    {
      "x": 1,
      "y": 5,
      "z": 3,
      "name": "Empty"
    },
    {
      "x": 1,
      "y": 0,
      "z": 4,
      "name": "Rock_Aqua"
    },
    {
      "x": 1,
      "y": 1,
      "z": 4,
      "name": "Rock_Aqua"
    },
    {
      "x": 1,
      "y": 2,
      "z": 4,
      "name": "Rock_Aqua"
    },
    {
      "x": 1,
      "y": 3,
      "z": 4,
      "name": "Rock_Aqua"
    },
    {
      "x": 1,
      "y": 4,
      "z": 4,
      "name": "Rock_Aqua"
    },
    {
      "x": 1,
      "y": 2,
      "z": 5,
      "name": "Rock_Aqua"
    },
    {
      "x": 2,
      "y": 1,
      "z": -4,
      "name": "Rock_Aqua"
    },
    {
      "x": 2,
      "y": 2,
      "z": -4,
      "name": "Rock_Aqua"
    },
    {
      "x": 2,
      "y": 0,
      "z": -3,
      "name": "Rock_Aqua"
    },
    {
      "x": 2,
      "y": 1,
      "z": -3,
      "name": "Rock_Aqua"
    },
    {
      "x": 2,
      "y": 2,
      "z": -3,
      "name": "Rock_Aqua"
    },
    {
      "x": 2,
      "y": 3,
      "z": -3,
      "name": "Rock_Aqua"
    },
    {
      "x": 2,
      "y": 4,
      "z": -3,
      "name": "Rock_Aqua"
    },
    {
      "x": 2,
      "y": 5,
      "z": -3,
      "name": "Rubble_Aqua",
      "support": 15
    },
    {
      "x": 2,
      "y": 0,
      "z": -2,
      "name": "Rock_Aqua"
    },
    {
      "x": 2,
      "y": 1,
      "z": -2,
      "name": "Rock_Aqua_Brick_Smooth"
    },
    {
      "x": 2,
      "y": 2,
      "z": -2,
      "name": "Rock_Aqua_Stalactite_Small",
      "rotation": 8
    },
    {
      "x": 2,
      "y": 3,
      "z": -2,
      "name": "Rock_Aqua"
    },
    {
      "x": 2,
      "y": 4,
      "z": -2,
      "name": "Rock_Aqua_Stairs"
    },
    {
      "x": 2,
      "y": 5,
      "z": -2,
      "name": "Empty"
    },
    {
      "x": 2,
      "y": 6,
      "z": -2,
      "name": "Rock_Aqua_Brick_Stairs",
      "rotation": 2
    },
    {
      "x": 2,
      "y": 0,
      "z": -1,
      "name": "Rock_Aqua"
    },
    {
      "x": 2,
      "y": 1,
      "z": -1,
      "name": "Rock_Aqua_Brick_Stairs"
    },
    {
      "x": 2,
      "y": 2,
      "z": -1,
      "name": "Empty"
    },
    {
      "x": 2,
      "y": 3,
      "z": -1,
      "name": "Empty"
    },
    {
      "x": 2,
      "y": 4,
      "z": -1,
      "name": "Empty"
    },
    {
      "x": 2,
      "y": 5,
      "z": -1,
      "name": "Empty"
    },
    {
      "x": 2,
      "y": 6,
      "z": -1,
      "name": "Empty"
    },
    {
      "x": 2,
      "y": 7,
      "z": -1,
      "name": "Rock_Aqua_Brick_Smooth_Half"
    },
    {
      "x": 2,
      "y": 0,
      "z": 0,
      "name": "Rock_Aqua"
    },
    {
      "x": 2,
      "y": 1,
      "z": 0,
      "name": "Rock_Aqua_Brick_Smooth_Half"
    },
    {
      "x": 2,
      "y": 2,
      "z": 0,
      "name": "Empty"
    },
    {
      "x": 2,
      "y": 3,
      "z": 0,
      "name": "Empty"
    },
    {
      "x": 2,
      "y": 4,
      "z": 0,
      "name": "Empty"
    },
    {
      "x": 2,
      "y": 5,
      "z": 0,
      "name": "Empty"
    },
    {
      "x": 2,
      "y": 6,
      "z": 0,
      "name": "Empty"
    },
    {
      "x": 2,
      "y": 7,
      "z": 0,
      "name": "Rock_Aqua_Cobble_Roof_Flat",
      "rotation": 2
    },
    {
      "x": 2,
      "y": 0,
      "z": 1,
      "name": "Rock_Aqua"
    },
    {
      "x": 2,
      "y": 1,
      "z": 1,
      "name": "Rock_Aqua_Brick_Stairs",
      "rotation": 2
    },
    {
      "x": 2,
      "y": 2,
      "z": 1,
      "name": "Empty"
    },
    {
      "x": 2,
      "y": 3,
      "z": 1,
      "name": "Empty"
    },
    {
      "x": 2,
      "y": 4,
      "z": 1,
      "name": "Empty"
    },
    {
      "x": 2,
      "y": 5,
      "z": 1,
      "name": "Empty"
    },
    {
      "x": 2,
      "y": 6,
      "z": 1,
      "name": "Empty"
    },
    {
      "x": 2,
      "y": 7,
      "z": 1,
      "name": "Rock_Aqua_Brick_Smooth_Half"
    },
    {
      "x": 2,
      "y": 0,
      "z": 2,
      "name": "Rock_Aqua"
    },
    {
      "x": 2,
      "y": 1,
      "z": 2,
      "name": "Rock_Aqua_Brick_Smooth"
    },
    {
      "x": 2,
      "y": 2,
      "z": 2,
      "name": "Rock_Aqua_Stalactite_Small"
    },
    {
      "x": 2,
      "y": 3,
      "z": 2,
      "name": "Empty"
    },
    {
      "x": 2,
      "y": 4,
      "z": 2,
      "name": "Empty"
    },
    {
      "x": 2,
      "y": 5,
      "z": 2,
      "name": "Empty"
    },
    {
      "x": 2,
      "y": 6,
      "z": 2,
      "name": "Rock_Aqua_Brick_Stairs"
    },
    {
      "x": 2,
      "y": 0,
      "z": 3,
      "name": "Rock_Aqua"
    },
    {
      "x": 2,
      "y": 1,
      "z": 3,
      "name": "Rock_Aqua"
    },
    {
      "x": 2,
      "y": 2,
      "z": 3,
      "name": "Rock_Aqua"
    },
    {
      "x": 2,
      "y": 3,
      "z": 3,
      "name": "Rock_Aqua_Stairs",
      "rotation": 8
    },
    {
      "x": 2,
      "y": 4,
      "z": 3,
      "name": "Rock_Aqua"
    },
    {
      "x": 2,
      "y": 1,
      "z": 4,
      "name": "Rock_Aqua"
    },
    {
      "x": 2,
      "y": 2,
      "z": 4,
      "name": "Rock_Aqua"
    },
    {
      "x": 2,
      "y": 3,
      "z": 4,
      "name": "Rock_Aqua"
    },
    {
      "x": 3,
      "y": 1,
      "z": -4,
      "name": "Rock_Aqua"
    },
    {
      "x": 3,
      "y": 2,
      "z": -4,
      "name": "Rock_Aqua"
    },
    {
      "x": 3,
      "y": 3,
      "z": -4,
      "name": "Rock_Aqua"
    },
    {
      "x": 3,
      "y": 0,
      "z": -3,
      "name": "Rock_Aqua"
    },
    {
      "x": 3,
      "y": 1,
      "z": -3,
      "name": "Rock_Aqua"
    },
    {
      "x": 3,
      "y": 2,
      "z": -3,
      "name": "Rock_Aqua"
    },
    {
      "x": 3,
      "y": 3,
      "z": -3,
      "name": "Rock_Aqua"
    },
    {
      "x": 3,
      "y": 4,
      "z": -3,
      "name": "Rock_Aqua"
    },
    {
      "x": 3,
      "y": 0,
      "z": -2,
      "name": "Rock_Aqua"
    },
    {
      "x": 3,
      "y": 1,
      "z": -2,
      "name": "Rock_Aqua_Brick_Smooth"
    },
    {
      "x": 3,
      "y": 2,
      "z": -2,
      "name": "Rock_Aqua_Brick_Pillar_Middle"
    },
    {
      "x": 3,
      "y": 3,
      "z": -2,
      "name": "Rock_Aqua"
    },
    {
      "x": 3,
      "y": 4,
      "z": -2,
      "name": "Rock_Aqua"
    },
    {
      "x": 3,
      "y": 5,
      "z": -2,
      "name": "Rock_Aqua_Brick_Pillar_Middle"
    },
    {
      "x": 3,
      "y": 6,
      "z": -2,
      "name": "Rock_Aqua_Brick_Stairs",
      "rotation": 2
    },
    {
      "x": 3,
      "y": 0,
      "z": -1,
      "name": "Rock_Aqua"
    },
    {
      "x": 3,
      "y": 1,
      "z": -1,
      "name": "Rock_Aqua_Brick_Stairs"
    },
    {
      "x": 3,
      "y": 2,
      "z": -1,
      "name": "Empty"
    },
    {
      "x": 3,
      "y": 3,
      "z": -1,
      "name": "Rock_Aqua"
    },
    {
      "x": 3,
      "y": 4,
      "z": -1,
      "name": "Rock_Aqua"
    },
    {
      "x": 3,
      "y": 5,
      "z": -1,
      "name": "Rubble_Aqua",
      "support": 15
    },
    {
      "x": 3,
      "y": 6,
      "z": -1,
      "name": "Rock_Aqua_Brick_Stairs",
      "rotation": 10
    },
    {
      "x": 3,
      "y": 7,
      "z": -1,
      "name": "Rock_Aqua_Brick_Smooth_Half"
    },
    {
      "x": 3,
      "y": 0,
      "z": 0,
      "name": "Rock_Aqua"
    },
    {
      "x": 3,
      "y": 1,
      "z": 0,
      "name": "Rock_Aqua_Brick_Smooth_Half"
    },
    {
      "x": 3,
      "y": 2,
      "z": 0,
      "name": "Empty"
    },
    {
      "x": 3,
      "y": 3,
      "z": 0,
      "name": "Rock_Aqua_Stalactite_Small",
      "rotation": 8
    },
    {
      "x": 3,
      "y": 4,
      "z": 0,
      "name": "Rock_Aqua"
    },
    {
      "x": 3,
      "y": 5,
      "z": 0,
      "name": "Empty"
    },
    {
      "x": 3,
      "y": 6,
      "z": 0,
      "name": "Empty"
    },
    {
      "x": 3,
      "y": 7,
      "z": 0,
      "name": "Rock_Aqua_Cobble_Roof_Flat",
      "rotation": 2
    },
    {
      "x": 3,
      "y": 0,
      "z": 1,
      "name": "Rock_Aqua"
    },
    {
      "x": 3,
      "y": 1,
      "z": 1,
      "name": "Rock_Aqua_Brick_Stairs",
      "rotation": 2
    },
    {
      "x": 3,
      "y": 2,
      "z": 1,
      "name": "Empty"
    },
    {
      "x": 3,
      "y": 3,
      "z": 1,
      "name": "Empty"
    },
    {
      "x": 3,
      "y": 4,
      "z": 1,
      "name": "Empty"
    },
    {
      "x": 3,
      "y": 5,
      "z": 1,
      "name": "Empty"
    },
    {
      "x": 3,
      "y": 6,
      "z": 1,
      "name": "Rock_Aqua_Brick_Stairs",
      "rotation": 8
    },
    {
      "x": 3,
      "y": 7,
      "z": 1,
      "name": "Rock_Aqua_Brick_Smooth_Half"
    },
    {
      "x": 3,
      "y": 0,
      "z": 2,
      "name": "Rock_Aqua"
    },
    {
      "x": 3,
      "y": 1,
      "z": 2,
      "name": "Rock_Aqua_Brick_Smooth"
    },
    {
      "x": 3,
      "y": 2,
      "z": 2,
      "name": "Rock_Aqua_Brick_Pillar_Middle"
    },
    {
      "x": 3,
      "y": 3,
      "z": 2,
      "name": "Rock_Aqua_Brick_Pillar_Middle"
    },
    {
      "x": 3,
      "y": 4,
      "z": 2,
      "name": "Rock_Aqua_Brick_Pillar_Middle"
    },
    {
      "x": 3,
      "y": 5,
      "z": 2,
      "name": "Rock_Aqua_Brick_Pillar_Middle"
    },
    {
      "x": 3,
      "y": 6,
      "z": 2,
      "name": "Rock_Aqua_Brick_Stairs"
    },
    {
      "x": 3,
      "y": 0,
      "z": 3,
      "name": "Rock_Aqua"
    },
    {
      "x": 3,
      "y": 1,
      "z": 3,
      "name": "Rock_Aqua"
    },
    {
      "x": 3,
      "y": 2,
      "z": 3,
      "name": "Rock_Aqua"
    },
    {
      "x": 3,
      "y": 3,
      "z": 3,
      "name": "Rock_Aqua"
    },
    {
      "x": 3,
      "y": 4,
      "z": 3,
      "name": "Rock_Aqua"
    },
    {
      "x": 3,
      "y": 1,
      "z": 4,
      "name": "Rock_Aqua"
    },
    {
      "x": 3,
      "y": 2,
      "z": 4,
      "name": "Rock_Aqua"
    },
    {
      "x": 4,
      "y": 1,
      "z": -4,
      "name": "Rock_Aqua"
    },
    {
      "x": 4,
      "y": 2,
      "z": -4,
      "name": "Rock_Aqua"
    },
    {
      "x": 4,
      "y": 3,
      "z": -4,
      "name": "Rock_Aqua"
    },
    {
      "x": 4,
      "y": 0,
      "z": -3,
      "name": "Rock_Aqua"
    },
    {
      "x": 4,
      "y": 1,
      "z": -3,
      "name": "Rock_Aqua"
    },
    {
      "x": 4,
      "y": 2,
      "z": -3,
      "name": "Rock_Aqua"
    },
    {
      "x": 4,
      "y": 3,
      "z": -3,
      "name": "Rock_Aqua"
    },
    {
      "x": 4,
      "y": 4,
      "z": -3,
      "name": "Rock_Aqua"
    },
    {
      "x": 4,
      "y": 0,
      "z": -2,
      "name": "Rock_Aqua"
    },
    {
      "x": 4,
      "y": 1,
      "z": -2,
      "name": "Rock_Aqua"
    },
    {
      "x": 4,
      "y": 2,
      "z": -2,
      "name": "Rock_Aqua"
    },
    {
      "x": 4,
      "y": 3,
      "z": -2,
      "name": "Rock_Aqua"
    },
    {
      "x": 4,
      "y": 4,
      "z": -2,
      "name": "Rock_Aqua"
    },
    {
      "x": 4,
      "y": 5,
      "z": -2,
      "name": "Rock_Aqua_Stairs"
    },
    {
      "x": 4,
      "y": 0,
      "z": -1,
      "name": "Soil_Clay_Ocean_Brick_Decorative"
    },
    {
      "x": 4,
      "y": 1,
      "z": -1,
      "name": "Deco_Iron_Bars",
      "rotation": 1
    },
    {
      "x": 4,
      "y": 2,
      "z": -1,
      "name": "Deco_Iron_Bars",
      "rotation": 1
    },
    {
      "x": 4,
      "y": 3,
      "z": -1,
      "name": "Rock_Aqua"
    },
    {
      "x": 4,
      "y": 4,
      "z": -1,
      "name": "Rock_Aqua"
    },
    {
      "x": 4,
      "y": 5,
      "z": -1,
      "name": "Rock_Aqua"
    },
    {
      "x": 4,
      "y": 0,
      "z": 0,
      "name": "Soil_Clay_Ocean_Brick_Decorative"
    },
    {
      "x": 4,
      "y": 1,
      "z": 0,
      "name": "Deco_Iron_Bars",
      "rotation": 1
    },
    {
      "x": 4,
      "y": 2,
      "z": 0,
      "name": "Deco_Iron_Bars",
      "rotation": 1
    },
    {
      "x": 4,
      "y": 3,
      "z": 0,
      "name": "Rock_Aqua"
    },
    {
      "x": 4,
      "y": 4,
      "z": 0,
      "name": "Rock_Aqua"
    },
    {
      "x": 4,
      "y": 0,
      "z": 1,
      "name": "Soil_Clay_Ocean_Brick_Decorative"
    },
    {
      "x": 4,
      "y": 1,
      "z": 1,
      "name": "Deco_Iron_Bars",
      "rotation": 1
    },
    {
      "x": 4,
      "y": 2,
      "z": 1,
      "name": "Deco_Iron_Bars",
      "rotation": 1
    },
    {
      "x": 4,
      "y": 3,
      "z": 1,
      "name": "Rock_Aqua"
    },
    {
      "x": 4,
      "y": 4,
      "z": 1,
      "name": "Rock_Aqua"
    },
    {
      "x": 4,
      "y": 0,
      "z": 2,
      "name": "Rock_Aqua"
    },
    {
      "x": 4,
      "y": 1,
      "z": 2,
      "name": "Rock_Aqua"
    },
    {
      "x": 4,
      "y": 2,
      "z": 2,
      "name": "Rock_Aqua"
    },
    {
      "x": 4,
      "y": 3,
      "z": 2,
      "name": "Rock_Aqua"
    },
    {
      "x": 4,
      "y": 4,
      "z": 2,
      "name": "Rock_Aqua"
    },
    {
      "x": 4,
      "y": 5,
      "z": 2,
      "name": "Rubble_Aqua_Medium",
      "support": 15
    },
    {
      "x": 4,
      "y": 1,
      "z": 3,
      "name": "Rock_Aqua"
    },
    {
      "x": 4,
      "y": 2,
      "z": 3,
      "name": "Rock_Aqua"
    },
    {
      "x": 4,
      "y": 3,
      "z": 3,
      "name": "Rock_Aqua"
    },
    {
      "x": 4,
      "y": 4,
      "z": 3,
      "name": "Rock_Aqua"
    },
    {
      "x": 5,
      "y": 1,
      "z": -4,
      "name": "Rock_Aqua"
    },
    {
      "x": 5,
      "y": 0,
      "z": -3,
      "name": "Rock_Aqua"
    },
    {
      "x": 5,
      "y": 1,
      "z": -3,
      "name": "Rock_Aqua"
    },
    {
      "x": 5,
      "y": 2,
      "z": -3,
      "name": "Rock_Aqua"
    },
    {
      "x": 5,
      "y": 3,
      "z": -3,
      "name": "Rock_Aqua"
    },
    {
      "x": 5,
      "y": 4,
      "z": -3,
      "name": "Rock_Aqua"
    },
    {
      "x": 5,
      "y": 0,
      "z": -2,
      "name": "Rock_Aqua"
    },
    {
      "x": 5,
      "y": 1,
      "z": -2,
      "name": "Rock_Aqua"
    },
    {
      "x": 5,
      "y": 2,
      "z": -2,
      "name": "Rock_Aqua"
    },
    {
      "x": 5,
      "y": 3,
      "z": -2,
      "name": "Rock_Aqua"
    },
    {
      "x": 5,
      "y": 4,
      "z": -2,
      "name": "Rock_Aqua"
    },
    {
      "x": 5,
      "y": 5,
      "z": -2,
      "name": "Rock_Aqua"
    },
    {
      "x": 5,
      "y": 0,
      "z": -1,
      "name": "Soil_Clay_Ocean_Brick_Decorative"
    },
    {
      "x": 5,
      "y": 1,
      "z": -1,
      "name": "Rubble_Aqua",
      "support": 15
    },
    {
      "x": 5,
      "y": 2,
      "z": -1,
      "name": "Empty"
    },
    {
      "x": 5,
      "y": 3,
      "z": -1,
      "name": "Empty"
    },
    {
      "x": 5,
      "y": 4,
      "z": -1,
      "name": "Rock_Aqua"
    },
    {
      "x": 5,
      "y": 5,
      "z": -1,
      "name": "Rock_Aqua"
    },
    {
      "x": 5,
      "y": 6,
      "z": -1,
      "name": "Rock_Aqua_Brick_Pillar_Base"
    },
    {
      "x": 5,
      "y": 0,
      "z": 0,
      "name": "Soil_Clay_Ocean_Brick_Decorative"
    },
    {
      "x": 5,
      "y": 1,
      "z": 0,
      "name": "Empty"
    },
    {
      "x": 5,
      "y": 2,
      "z": 0,
      "name": "Empty"
    },
    {
      "x": 5,
      "y": 3,
      "z": 0,
      "name": "Empty"
    },
    {
      "x": 5,
      "y": 4,
      "z": 0,
      "name": "Rock_Aqua"
    },
    {
      "x": 5,
      "y": 5,
      "z": 0,
      "name": "Rock_Aqua"
    },
    {
      "x": 5,
      "y": 0,
      "z": 1,
      "name": "Soil_Clay_Ocean_Brick_Decorative"
    },
    {
      "x": 5,
      "y": 1,
      "z": 1,
      "name": "Rock_Aqua_Stalactite_Small"
    },
    {
      "x": 5,
      "y": 2,
      "z": 1,
      "name": "Empty"
    },
    {
      "x": 5,
      "y": 3,
      "z": 1,
      "name": "Rock_Aqua"
    },
    {
      "x": 5,
      "y": 4,
      "z": 1,
      "name": "Rock_Aqua_Stairs",
      "rotation": 3
    },
    {
      "x": 5,
      "y": 0,
      "z": 2,
      "name": "Rock_Aqua"
    },
    {
      "x": 5,
      "y": 1,
      "z": 2,
      "name": "Rock_Aqua"
    },
    {
      "x": 5,
      "y": 2,
      "z": 2,
      "name": "Rock_Aqua"
    },
    {
      "x": 5,
      "y": 3,
      "z": 2,
      "name": "Rock_Aqua"
    },
    {
      "x": 5,
      "y": 4,
      "z": 2,
      "name": "Rock_Aqua"
    },
    {
      "x": 5,
      "y": 1,
      "z": 3,
      "name": "Rock_Aqua"
    },
    {
      "x": 5,
      "y": 2,
      "z": 3,
      "name": "Rock_Aqua"
    },
    {
      "x": 6,
      "y": 2,
      "z": -3,
      "name": "Rock_Aqua"
    },
    {
      "x": 6,
      "y": 3,
      "z": -3,
      "name": "Rock_Aqua"
    },
    {
      "x": 6,
      "y": 0,
      "z": -2,
      "name": "Rock_Aqua"
    },
    {
      "x": 6,
      "y": 1,
      "z": -2,
      "name": "Rock_Aqua"
    },
    {
      "x": 6,
      "y": 2,
      "z": -2,
      "name": "Rock_Aqua"
    },
    {
      "x": 6,
      "y": 3,
      "z": -2,
      "name": "Rock_Aqua"
    },
    {
      "x": 6,
      "y": 4,
      "z": -2,
      "name": "Rock_Aqua"
    },
    {
      "x": 6,
      "y": 0,
      "z": -1,
      "name": "Soil_Clay_Ocean_Brick_Decorative"
    },
    {
      "x": 6,
      "y": 1,
      "z": -1,
      "name": "Rock_Aqua_Brick_Pillar_Base"
    },
    {
      "x": 6,
      "y": 2,
      "z": -1,
      "name": "Rock_Aqua_Brick_Pillar_Middle"
    },
    {
      "x": 6,
      "y": 3,
      "z": -1,
      "name": "Rock_Aqua_Brick_Pillar_Base",
      "rotation": 8
    },
    {
      "x": 6,
      "y": 4,
      "z": -1,
      "name": "Rock_Aqua"
    },
    {
      "x": 6,
      "y": 5,
      "z": -1,
      "name": "Rock_Aqua_Brick_Smooth"
    },
    {
      "x": 6,
      "y": 6,
      "z": -1,
      "name": "Rubble_Aqua",
      "support": 15
    },
    {
      "x": 6,
      "y": 0,
      "z": 0,
      "name": "Soil_Clay_Ocean_Brick_Decorative"
    },
    {
      "x": 6,
      "y": 1,
      "z": 0,
      "name": "Block_Spawner_Block",
      "components": {
        "Components": {
          "PlacedByInteraction": {
            "WhoPlacedUuid": {
              "$binary": "ownTYu6PR7ebL9OJmdXyVA==",
              "$type": "04"
            }
          },
          "BlockSpawner": {
            "BlockSpawnerId": "The_Aqua_Subterrain_Tier1"
          }
        }
      },
      "rotation": 3
    },
    {
      "x": 6,
      "y": 2,
      "z": 0,
      "name": "Empty"
    },
    {
      "x": 6,
      "y": 3,
      "z": 0,
      "name": "Rock_Aqua_Stalactite_Large",
      "rotation": 8
    },
    {
      "x": 6,
      "y": 4,
      "z": 0,
      "name": "Rock_Aqua"
    },
    {
      "x": 6,
      "y": 5,
      "z": 0,
      "name": "Rubble_Aqua",
      "support": 15
    },
    {
      "x": 6,
      "y": 0,
      "z": 1,
      "name": "Soil_Clay_Ocean_Brick_Decorative"
    },
    {
      "x": 6,
      "y": 1,
      "z": 1,
      "name": "Rock_Aqua_Brick_Pillar_Base"
    },
    {
      "x": 6,
      "y": 2,
      "z": 1,
      "name": "Rock_Aqua_Brick_Pillar_Middle"
    },
    {
      "x": 6,
      "y": 3,
      "z": 1,
      "name": "Rock_Aqua"
    },
    {
      "x": 6,
      "y": 4,
      "z": 1,
      "name": "Rock_Aqua"
    },
    {
      "x": 6,
      "y": 0,
      "z": 2,
      "name": "Rock_Aqua"
    },
    {
      "x": 6,
      "y": 1,
      "z": 2,
      "name": "Rock_Aqua"
    },
    {
      "x": 6,
      "y": 2,
      "z": 2,
      "name": "Rock_Aqua"
    },
    {
      "x": 6,
      "y": 3,
      "z": 2,
      "name": "Rock_Aqua"
    },
    {
      "x": 6,
      "y": 4,
      "z": 2,
      "name": "Rock_Aqua"
    },
    {
      "x": 6,
      "y": 1,
      "z": 3,
      "name": "Rock_Aqua"
    },
    {
      "x": 7,
      "y": 1,
      "z": -2,
      "name": "Rock_Aqua"
    },
    {
      "x": 7,
      "y": 2,
      "z": -2,
      "name": "Rock_Aqua"
    },
    {
      "x": 7,
      "y": 3,
      "z": -2,
      "name": "Rock_Aqua"
    },
    {
      "x": 7,
      "y": 0,
      "z": -1,
      "name": "Rock_Aqua"
    },
    {
      "x": 7,
      "y": 1,
      "z": -1,
      "name": "Rock_Aqua"
    },
    {
      "x": 7,
      "y": 2,
      "z": -1,
      "name": "Rock_Aqua"
    },
    {
      "x": 7,
      "y": 3,
      "z": -1,
      "name": "Rock_Aqua"
    },
    {
      "x": 7,
      "y": 4,
      "z": -1,
      "name": "Rock_Aqua"
    },
    {
      "x": 7,
      "y": 0,
      "z": 0,
      "name": "Rock_Aqua"
    },
    {
      "x": 7,
      "y": 1,
      "z": 0,
      "name": "Rock_Aqua"
    },
    {
      "x": 7,
      "y": 2,
      "z": 0,
      "name": "Rock_Aqua"
    },
    {
      "x": 7,
      "y": 3,
      "z": 0,
      "name": "Rock_Aqua"
    },
    {
      "x": 7,
      "y": 4,
      "z": 0,
      "name": "Rock_Aqua"
    },
    {
      "x": 7,
      "y": 0,
      "z": 1,
      "name": "Rock_Aqua"
    },
    {
      "x": 7,
      "y": 1,
      "z": 1,
      "name": "Rock_Aqua"
    },
    {
      "x": 7,
      "y": 2,
      "z": 1,
      "name": "Rock_Aqua"
    },
    {
      "x": 7,
      "y": 3,
      "z": 1,
      "name": "Rock_Aqua"
    },
    {
      "x": 7,
      "y": 4,
      "z": 1,
      "name": "Rock_Aqua"
    },
    {
      "x": 7,
      "y": 1,
      "z": 2,
      "name": "Rock_Aqua"
    },
    {
      "x": 7,
      "y": 2,
      "z": 2,
      "name": "Rock_Aqua"
    },
    {
      "x": 7,
      "y": 3,
      "z": 2,
      "name": "Rock_Aqua"
    },
    {
      "x": 8,
      "y": 1,
      "z": -1,
      "name": "Rock_Aqua"
    },
    {
      "x": 8,
      "y": 2,
      "z": -1,
      "name": "Rock_Aqua"
    },
    {
      "x": 8,
      "y": 1,
      "z": 0,
      "name": "Rock_Aqua"
    },
    {
      "x": 8,
      "y": 2,
      "z": 0,
      "name": "Rock_Aqua"
    },
    {
      "x": 8,
      "y": 3,
      "z": 0,
      "name": "Rock_Aqua"
    },
    {
      "x": 8,
      "y": 1,
      "z": 1,
      "name": "Rock_Aqua"
    }
  ],
  "fluids": [
    {
      "x": -6,
      "y": 5,
      "z": -3,
      "name": "Water_Source",
      "level": 1
    },
    {
      "x": -6,
      "y": 6,
      "z": -1,
      "name": "Water_Source",
      "level": 1
    },
    {
      "x": -5,
      "y": 6,
      "z": -2,
      "name": "Water_Source",
      "level": 1
    },
    {
      "x": -5,
      "y": 2,
      "z": -1,
      "name": "Water_Source",
      "level": 1
    },
    {
      "x": -5,
      "y": 3,
      "z": -1,
      "name": "Water_Source",
      "level": 1
    },
    {
      "x": -5,
      "y": 5,
      "z": -1,
      "name": "Water_Source",
      "level": 1
    },
    {
      "x": -5,
      "y": 2,
      "z": 0,
      "name": "Water_Source",
      "level": 1
    },
    {
      "x": -5,
      "y": 5,
      "z": 0,
      "name": "Water_Source",
      "level": 1
    },
    {
      "x": -4,
      "y": 1,
      "z": -1,
      "name": "Water_Source",
      "level": 1
    },
    {
      "x": -4,
      "y": 2,
      "z": -1,
      "name": "Water_Source",
      "level": 1
    },
    {
      "x": -4,
      "y": 3,
      "z": -1,
      "name": "Water_Source",
      "level": 1
    },
    {
      "x": -4,
      "y": 5,
      "z": -1,
      "name": "Water_Source",
      "level": 1
    },
    {
      "x": -4,
      "y": 1,
      "z": 0,
      "name": "Water_Source",
      "level": 1
    },
    {
      "x": -4,
      "y": 2,
      "z": 0,
      "name": "Water_Source",
      "level": 1
    },
    {
      "x": -4,
      "y": 3,
      "z": 0,
      "name": "Water_Source",
      "level": 1
    },
    {
      "x": -4,
      "y": 5,
      "z": 0,
      "name": "Water_Source",
      "level": 1
    },
    {
      "x": -4,
      "y": 1,
      "z": 1,
      "name": "Water_Source",
      "level": 1
    },
    {
      "x": -4,
      "y": 2,
      "z": 1,
      "name": "Water_Source",
      "level": 1
    },
    {
      "x": -4,
      "y": 3,
      "z": 1,
      "name": "Water_Source",
      "level": 1
    },
    {
      "x": -4,
      "y": 5,
      "z": 1,
      "name": "Water_Source",
      "level": 1
    },
    {
      "x": -3,
      "y": 5,
      "z": -3,
      "name": "Water_Source",
      "level": 1
    },
    {
      "x": -3,
      "y": 2,
      "z": -2,
      "name": "Water_Source",
      "level": 1
    },
    {
      "x": -3,
      "y": 3,
      "z": -2,
      "name": "Water_Source",
      "level": 1
    },
    {
      "x": -3,
      "y": 4,
      "z": -2,
      "name": "Water_Source",
      "level": 1
    },
    {
      "x": -3,
      "y": 5,
      "z": -2,
      "name": "Water_Source",
      "level": 1
    },
    {
      "x": -3,
      "y": 6,
      "z": -2,
      "name": "Water_Source",
      "level": 1
    },
    {
      "x": -3,
      "y": 1,
      "z": -1,
      "name": "Water_Source",
      "level": 1
    },
    {
      "x": -3,
      "y": 2,
      "z": -1,
      "name": "Water_Source",
      "level": 1
    },
    {
      "x": -3,
      "y": 3,
      "z": -1,
      "name": "Water_Source",
      "level": 1
    },
    {
      "x": -3,
      "y": 4,
      "z": -1,
      "name": "Water_Source",
      "level": 1
    },
    {
      "x": -3,
      "y": 5,
      "z": -1,
      "name": "Water_Source",
      "level": 1
    },
    {
      "x": -3,
      "y": 6,
      "z": -1,
      "name": "Water_Source",
      "level": 1
    },
    {
      "x": -3,
      "y": 7,
      "z": -1,
      "name": "Water_Source",
      "level": 1
    },
    {
      "x": -3,
      "y": 1,
      "z": 0,
      "name": "Water_Source",
      "level": 1
    },
    {
      "x": -3,
      "y": 2,
      "z": 0,
      "name": "Water_Source",
      "level": 1
    },
    {
      "x": -3,
      "y": 3,
      "z": 0,
      "name": "Water_Source",
      "level": 1
    },
    {
      "x": -3,
      "y": 4,
      "z": 0,
      "name": "Water_Source",
      "level": 1
    },
    {
      "x": -3,
      "y": 5,
      "z": 0,
      "name": "Water_Source",
      "level": 1
    },
    {
      "x": -3,
      "y": 6,
      "z": 0,
      "name": "Water_Source",
      "level": 1
    },
    {
      "x": -3,
      "y": 7,
      "z": 0,
      "name": "Water_Source",
      "level": 1
    },
    {
      "x": -3,
      "y": 1,
      "z": 1,
      "name": "Water_Source",
      "level": 1
    },
    {
      "x": -3,
      "y": 2,
      "z": 1,
      "name": "Water_Source",
      "level": 1
    },
    {
      "x": -3,
      "y": 3,
      "z": 1,
      "name": "Water_Source",
      "level": 1
    },
    {
      "x": -3,
      "y": 4,
      "z": 1,
      "name": "Water_Source",
      "level": 1
    },
    {
      "x": -3,
      "y": 5,
      "z": 1,
      "name": "Water_Source",
      "level": 1
    },
    {
      "x": -3,
      "y": 6,
      "z": 1,
      "name": "Water_Source",
      "level": 1
    },
    {
      "x": -3,
      "y": 7,
      "z": 1,
      "name": "Water_Source",
      "level": 1
    },
    {
      "x": -3,
      "y": 2,
      "z": 2,
      "name": "Water_Source",
      "level": 1
    },
    {
      "x": -3,
      "y": 3,
      "z": 2,
      "name": "Water_Source",
      "level": 1
    },
    {
      "x": -3,
      "y": 4,
      "z": 2,
      "name": "Water_Source",
      "level": 1
    },
    {
      "x": -3,
      "y": 5,
      "z": 2,
      "name": "Water_Source",
      "level": 1
    },
    {
      "x": -3,
      "y": 6,
      "z": 2,
      "name": "Water_Source",
      "level": 1
    },
    {
      "x": -2,
      "y": 3,
      "z": -3,
      "name": "Water_Source",
      "level": 1
    },
    {
      "x": -2,
      "y": 2,
      "z": -2,
      "name": "Water_Source",
      "level": 1
    },
    {
      "x": -2,
      "y": 3,
      "z": -2,
      "name": "Water_Source",
      "level": 1
    },
    {
      "x": -2,
      "y": 4,
      "z": -2,
      "name": "Water_Source",
      "level": 1
    },
    {
      "x": -2,
      "y": 5,
      "z": -2,
      "name": "Water_Source",
      "level": 1
    },
    {
      "x": -2,
      "y": 6,
      "z": -2,
      "name": "Water_Source",
      "level": 1
    },
    {
      "x": -2,
      "y": 1,
      "z": -1,
      "name": "Water_Source",
      "level": 1
    },
    {
      "x": -2,
      "y": 2,
      "z": -1,
      "name": "Water_Source",
      "level": 1
    },
    {
      "x": -2,
      "y": 3,
      "z": -1,
      "name": "Water_Source",
      "level": 1
    },
    {
      "x": -2,
      "y": 4,
      "z": -1,
      "name": "Water_Source",
      "level": 1
    },
    {
      "x": -2,
      "y": 5,
      "z": -1,
      "name": "Water_Source",
      "level": 1
    },
    {
      "x": -2,
      "y": 6,
      "z": -1,
      "name": "Water_Source",
      "level": 1
    },
    {
      "x": -2,
      "y": 7,
      "z": -1,
      "name": "Water_Source",
      "level": 1
    },
    {
      "x": -2,
      "y": 1,
      "z": 0,
      "name": "Water_Source",
      "level": 1
    },
    {
      "x": -2,
      "y": 2,
      "z": 0,
      "name": "Water_Source",
      "level": 1
    },
    {
      "x": -2,
      "y": 3,
      "z": 0,
      "name": "Water_Source",
      "level": 1
    },
    {
      "x": -2,
      "y": 4,
      "z": 0,
      "name": "Water_Source",
      "level": 1
    },
    {
      "x": -2,
      "y": 5,
      "z": 0,
      "name": "Water_Source",
      "level": 1
    },
    {
      "x": -2,
      "y": 6,
      "z": 0,
      "name": "Water_Source",
      "level": 1
    },
    {
      "x": -2,
      "y": 7,
      "z": 0,
      "name": "Water_Source",
      "level": 1
    },
    {
      "x": -2,
      "y": 1,
      "z": 1,
      "name": "Water_Source",
      "level": 1
    },
    {
      "x": -2,
      "y": 2,
      "z": 1,
      "name": "Water_Source",
      "level": 1
    },
    {
      "x": -2,
      "y": 3,
      "z": 1,
      "name": "Water_Source",
      "level": 1
    },
    {
      "x": -2,
      "y": 4,
      "z": 1,
      "name": "Water_Source",
      "level": 1
    },
    {
      "x": -2,
      "y": 5,
      "z": 1,
      "name": "Water_Source",
      "level": 1
    },
    {
      "x": -2,
      "y": 6,
      "z": 1,
      "name": "Water_Source",
      "level": 1
    },
    {
      "x": -2,
      "y": 7,
      "z": 1,
      "name": "Water_Source",
      "level": 1
    },
    {
      "x": -2,
      "y": 2,
      "z": 2,
      "name": "Water_Source",
      "level": 1
    },
    {
      "x": -2,
      "y": 3,
      "z": 2,
      "name": "Water_Source",
      "level": 1
    },
    {
      "x": -2,
      "y": 4,
      "z": 2,
      "name": "Water_Source",
      "level": 1
    },
    {
      "x": -2,
      "y": 5,
      "z": 2,
      "name": "Water_Source",
      "level": 1
    },
    {
      "x": -2,
      "y": 6,
      "z": 2,
      "name": "Water_Source",
      "level": 1
    },
    {
      "x": -2,
      "y": 5,
      "z": 3,
      "name": "Water_Source",
      "level": 1
    },
    {
      "x": -1,
      "y": 2,
      "z": -3,
      "name": "Water_Source",
      "level": 1
    },
    {
      "x": -1,
      "y": 3,
      "z": -3,
      "name": "Water_Source",
      "level": 1
    },
    {
      "x": -1,
      "y": 4,
      "z": -3,
      "name": "Water_Source",
      "level": 1
    },
    {
      "x": -1,
      "y": 5,
      "z": -3,
      "name": "Water_Source",
      "level": 1
    },
    {
      "x": -1,
      "y": 2,
      "z": -2,
      "name": "Water_Source",
      "level": 1
    },
    {
      "x": -1,
      "y": 3,
      "z": -2,
      "name": "Water_Source",
      "level": 1
    },
    {
      "x": -1,
      "y": 4,
      "z": -2,
      "name": "Water_Source",
      "level": 1
    },
    {
      "x": -1,
      "y": 5,
      "z": -2,
      "name": "Water_Source",
      "level": 1
    },
    {
      "x": -1,
      "y": 6,
      "z": -2,
      "name": "Water_Source",
      "level": 1
    },
    {
      "x": -1,
      "y": 1,
      "z": -1,
      "name": "Water_Source",
      "level": 1
    },
    {
      "x": -1,
      "y": 2,
      "z": -1,
      "name": "Water_Source",
      "level": 1
    },
    {
      "x": -1,
      "y": 3,
      "z": -1,
      "name": "Water_Source",
      "level": 1
    },
    {
      "x": -1,
      "y": 4,
      "z": -1,
      "name": "Water_Source",
      "level": 1
    },
    {
      "x": -1,
      "y": 5,
      "z": -1,
      "name": "Water_Source",
      "level": 1
    },
    {
      "x": -1,
      "y": 6,
      "z": -1,
      "name": "Water_Source",
      "level": 1
    },
    {
      "x": -1,
      "y": 7,
      "z": -1,
      "name": "Water_Source",
      "level": 1
    },
    {
      "x": -1,
      "y": 1,
      "z": 0,
      "name": "Water_Source",
      "level": 1
    },
    {
      "x": -1,
      "y": 2,
      "z": 0,
      "name": "Water_Source",
      "level": 1
    },
    {
      "x": -1,
      "y": 3,
      "z": 0,
      "name": "Water_Source",
      "level": 1
    },
    {
      "x": -1,
      "y": 4,
      "z": 0,
      "name": "Water_Source",
      "level": 1
    },
    {
      "x": -1,
      "y": 5,
      "z": 0,
      "name": "Water_Source",
      "level": 1
    },
    {
      "x": -1,
      "y": 6,
      "z": 0,
      "name": "Water_Source",
      "level": 1
    },
    {
      "x": -1,
      "y": 7,
      "z": 0,
      "name": "Water_Source",
      "level": 1
    },
    {
      "x": -1,
      "y": 1,
      "z": 1,
      "name": "Water_Source",
      "level": 1
    },
    {
      "x": -1,
      "y": 2,
      "z": 1,
      "name": "Water_Source",
      "level": 1
    },
    {
      "x": -1,
      "y": 3,
      "z": 1,
      "name": "Water_Source",
      "level": 1
    },
    {
      "x": -1,
      "y": 4,
      "z": 1,
      "name": "Water_Source",
      "level": 1
    },
    {
      "x": -1,
      "y": 5,
      "z": 1,
      "name": "Water_Source",
      "level": 1
    },
    {
      "x": -1,
      "y": 6,
      "z": 1,
      "name": "Water_Source",
      "level": 1
    },
    {
      "x": -1,
      "y": 7,
      "z": 1,
      "name": "Water_Source",
      "level": 1
    },
    {
      "x": -1,
      "y": 2,
      "z": 2,
      "name": "Water_Source",
      "level": 1
    },
    {
      "x": -1,
      "y": 3,
      "z": 2,
      "name": "Water_Source",
      "level": 1
    },
    {
      "x": -1,
      "y": 4,
      "z": 2,
      "name": "Water_Source",
      "level": 1
    },
    {
      "x": -1,
      "y": 5,
      "z": 2,
      "name": "Water_Source",
      "level": 1
    },
    {
      "x": -1,
      "y": 6,
      "z": 2,
      "name": "Water_Source",
      "level": 1
    },
    {
      "x": -1,
      "y": 3,
      "z": 3,
      "name": "Water_Source",
      "level": 1
    },
    {
      "x": -1,
      "y": 4,
      "z": 3,
      "name": "Water_Source",
      "level": 1
    },
    {
      "x": 0,
      "y": 3,
      "z": -3,
      "name": "Water_Source",
      "level": 1
    },
    {
      "x": 0,
      "y": 2,
      "z": -2,
      "name": "Water_Source",
      "level": 1
    },
    {
      "x": 0,
      "y": 3,
      "z": -2,
      "name": "Water_Source",
      "level": 1
    },
    {
      "x": 0,
      "y": 4,
      "z": -2,
      "name": "Water_Source",
      "level": 1
    },
    {
      "x": 0,
      "y": 5,
      "z": -2,
      "name": "Water_Source",
      "level": 1
    },
    {
      "x": 0,
      "y": 6,
      "z": -2,
      "name": "Water_Source",
      "level": 1
    },
    {
      "x": 0,
      "y": 1,
      "z": -1,
      "name": "Water_Source",
      "level": 1
    },
    {
      "x": 0,
      "y": 2,
      "z": -1,
      "name": "Water_Source",
      "level": 1
    },
    {
      "x": 0,
      "y": 3,
      "z": -1,
      "name": "Water_Source",
      "level": 1
    },
    {
      "x": 0,
      "y": 4,
      "z": -1,
      "name": "Water_Source",
      "level": 1
    },
    {
      "x": 0,
      "y": 5,
      "z": -1,
      "name": "Water_Source",
      "level": 1
    },
    {
      "x": 0,
      "y": 6,
      "z": -1,
      "name": "Water_Source",
      "level": 1
    },
    {
      "x": 0,
      "y": 7,
      "z": -1,
      "name": "Water_Source",
      "level": 1
    },
    {
      "x": 0,
      "y": 1,
      "z": 0,
      "name": "Water_Source",
      "level": 1
    },
    {
      "x": 0,
      "y": 2,
      "z": 0,
      "name": "Water_Source",
      "level": 1
    },
    {
      "x": 0,
      "y": 3,
      "z": 0,
      "name": "Water_Source",
      "level": 1
    },
    {
      "x": 0,
      "y": 4,
      "z": 0,
      "name": "Water_Source",
      "level": 1
    },
    {
      "x": 0,
      "y": 5,
      "z": 0,
      "name": "Water_Source",
      "level": 1
    },
    {
      "x": 0,
      "y": 6,
      "z": 0,
      "name": "Water_Source",
      "level": 1
    },
    {
      "x": 0,
      "y": 7,
      "z": 0,
      "name": "Water_Source",
      "level": 1
    },
    {
      "x": 0,
      "y": 1,
      "z": 1,
      "name": "Water_Source",
      "level": 1
    },
    {
      "x": 0,
      "y": 2,
      "z": 1,
      "name": "Water_Source",
      "level": 1
    },
    {
      "x": 0,
      "y": 3,
      "z": 1,
      "name": "Water_Source",
      "level": 1
    },
    {
      "x": 0,
      "y": 4,
      "z": 1,
      "name": "Water_Source",
      "level": 1
    },
    {
      "x": 0,
      "y": 5,
      "z": 1,
      "name": "Water_Source",
      "level": 1
    },
    {
      "x": 0,
      "y": 6,
      "z": 1,
      "name": "Water_Source",
      "level": 1
    },
    {
      "x": 0,
      "y": 7,
      "z": 1,
      "name": "Water_Source",
      "level": 1
    },
    {
      "x": 0,
      "y": 2,
      "z": 2,
      "name": "Water_Source",
      "level": 1
    },
    {
      "x": 0,
      "y": 3,
      "z": 2,
      "name": "Water_Source",
      "level": 1
    },
    {
      "x": 0,
      "y": 4,
      "z": 2,
      "name": "Water_Source",
      "level": 1
    },
    {
      "x": 0,
      "y": 5,
      "z": 2,
      "name": "Water_Source",
      "level": 1
    },
    {
      "x": 0,
      "y": 6,
      "z": 2,
      "name": "Water_Source",
      "level": 1
    },
    {
      "x": 0,
      "y": 3,
      "z": 3,
      "name": "Water_Source",
      "level": 1
    },
    {
      "x": 0,
      "y": 4,
      "z": 3,
      "name": "Water_Source",
      "level": 1
    },
    {
      "x": 0,
      "y": 4,
      "z": 4,
      "name": "Water_Source",
      "level": 1
    },
    {
      "x": 1,
      "y": 2,
      "z": -2,
      "name": "Water_Source",
      "level": 1
    },
    {
      "x": 1,
      "y": 3,
      "z": -2,
      "name": "Water_Source",
      "level": 1
    },
    {
      "x": 1,
      "y": 4,
      "z": -2,
      "name": "Water_Source",
      "level": 1
    },
    {
      "x": 1,
      "y": 5,
      "z": -2,
      "name": "Water_Source",
      "level": 1
    },
    {
      "x": 1,
      "y": 6,
      "z": -2,
      "name": "Water_Source",
      "level": 1
    },
    {
      "x": 1,
      "y": 1,
      "z": -1,
      "name": "Water_Source",
      "level": 1
    },
    {
      "x": 1,
      "y": 2,
      "z": -1,
      "name": "Water_Source",
      "level": 1
    },
    {
      "x": 1,
      "y": 3,
      "z": -1,
      "name": "Water_Source",
      "level": 1
    },
    {
      "x": 1,
      "y": 4,
      "z": -1,
      "name": "Water_Source",
      "level": 1
    },
    {
      "x": 1,
      "y": 5,
      "z": -1,
      "name": "Water_Source",
      "level": 1
    },
    {
      "x": 1,
      "y": 6,
      "z": -1,
      "name": "Water_Source",
      "level": 1
    },
    {
      "x": 1,
      "y": 7,
      "z": -1,
      "name": "Water_Source",
      "level": 1
    },
    {
      "x": 1,
      "y": 1,
      "z": 0,
      "name": "Water_Source",
      "level": 1
    },
    {
      "x": 1,
      "y": 2,
      "z": 0,
      "name": "Water_Source",
      "level": 1
    },
    {
      "x": 1,
      "y": 3,
      "z": 0,
      "name": "Water_Source",
      "level": 1
    },
    {
      "x": 1,
      "y": 4,
      "z": 0,
      "name": "Water_Source",
      "level": 1
    },
    {
      "x": 1,
      "y": 5,
      "z": 0,
      "name": "Water_Source",
      "level": 1
    },
    {
      "x": 1,
      "y": 6,
      "z": 0,
      "name": "Water_Source",
      "level": 1
    },
    {
      "x": 1,
      "y": 7,
      "z": 0,
      "name": "Water_Source",
      "level": 1
    },
    {
      "x": 1,
      "y": 1,
      "z": 1,
      "name": "Water_Source",
      "level": 1
    },
    {
      "x": 1,
      "y": 2,
      "z": 1,
      "name": "Water_Source",
      "level": 1
    },
    {
      "x": 1,
      "y": 3,
      "z": 1,
      "name": "Water_Source",
      "level": 1
    },
    {
      "x": 1,
      "y": 4,
      "z": 1,
      "name": "Water_Source",
      "level": 1
    },
    {
      "x": 1,
      "y": 5,
      "z": 1,
      "name": "Water_Source",
      "level": 1
    },
    {
      "x": 1,
      "y": 6,
      "z": 1,
      "name": "Water_Source",
      "level": 1
    },
    {
      "x": 1,
      "y": 7,
      "z": 1,
      "name": "Water_Source",
      "level": 1
    },
    {
      "x": 1,
      "y": 2,
      "z": 2,
      "name": "Water_Source",
      "level": 1
    },
    {
      "x": 1,
      "y": 3,
      "z": 2,
      "name": "Water_Source",
      "level": 1
    },
    {
      "x": 1,
      "y": 4,
      "z": 2,
      "name": "Water_Source",
      "level": 1
    },
    {
      "x": 1,
      "y": 5,
      "z": 2,
      "name": "Water_Source",
      "level": 1
    },
    {
      "x": 1,
      "y": 6,
      "z": 2,
      "name": "Water_Source",
      "level": 1
    },
    {
      "x": 1,
      "y": 4,
      "z": 3,
      "name": "Water_Source",
      "level": 1
    },
    {
      "x": 1,
      "y": 5,
      "z": 3,
      "name": "Water_Source",
      "level": 1
    },
    {
      "x": 2,
      "y": 5,
      "z": -3,
      "name": "Water_Source",
      "level": 1
    },
    {
      "x": 2,
      "y": 2,
      "z": -2,
      "name": "Water_Source",
      "level": 1
    },
    {
      "x": 2,
      "y": 4,
      "z": -2,
      "name": "Water_Source",
      "level": 1
    },
    {
      "x": 2,
      "y": 5,
      "z": -2,
      "name": "Water_Source",
      "level": 1
    },
    {
      "x": 2,
      "y": 6,
      "z": -2,
      "name": "Water_Source",
      "level": 1
    },
    {
      "x": 2,
      "y": 1,
      "z": -1,
      "name": "Water_Source",
      "level": 1
    },
    {
      "x": 2,
      "y": 2,
      "z": -1,
      "name": "Water_Source",
      "level": 1
    },
    {
      "x": 2,
      "y": 3,
      "z": -1,
      "name": "Water_Source",
      "level": 1
    },
    {
      "x": 2,
      "y": 4,
      "z": -1,
      "name": "Water_Source",
      "level": 1
    },
    {
      "x": 2,
      "y": 5,
      "z": -1,
      "name": "Water_Source",
      "level": 1
    },
    {
      "x": 2,
      "y": 6,
      "z": -1,
      "name": "Water_Source",
      "level": 1
    },
    {
      "x": 2,
      "y": 7,
      "z": -1,
      "name": "Water_Source",
      "level": 1
    },
    {
      "x": 2,
      "y": 1,
      "z": 0,
      "name": "Water_Source",
      "level": 1
    },
    {
      "x": 2,
      "y": 2,
      "z": 0,
      "name": "Water_Source",
      "level": 1
    },
    {
      "x": 2,
      "y": 3,
      "z": 0,
      "name": "Water_Source",
      "level": 1
    },
    {
      "x": 2,
      "y": 4,
      "z": 0,
      "name": "Water_Source",
      "level": 1
    },
    {
      "x": 2,
      "y": 5,
      "z": 0,
      "name": "Water_Source",
      "level": 1
    },
    {
      "x": 2,
      "y": 6,
      "z": 0,
      "name": "Water_Source",
      "level": 1
    },
    {
      "x": 2,
      "y": 7,
      "z": 0,
      "name": "Water_Source",
      "level": 1
    },
    {
      "x": 2,
      "y": 1,
      "z": 1,
      "name": "Water_Source",
      "level": 1
    },
    {
      "x": 2,
      "y": 2,
      "z": 1,
      "name": "Water_Source",
      "level": 1
    },
    {
      "x": 2,
      "y": 3,
      "z": 1,
      "name": "Water_Source",
      "level": 1
    },
    {
      "x": 2,
      "y": 4,
      "z": 1,
      "name": "Water_Source",
      "level": 1
    },
    {
      "x": 2,
      "y": 5,
      "z": 1,
      "name": "Water_Source",
      "level": 1
    },
    {
      "x": 2,
      "y": 6,
      "z": 1,
      "name": "Water_Source",
      "level": 1
    },
    {
      "x": 2,
      "y": 7,
      "z": 1,
      "name": "Water_Source",
      "level": 1
    },
    {
      "x": 2,
      "y": 2,
      "z": 2,
      "name": "Water_Source",
      "level": 1
    },
    {
      "x": 2,
      "y": 3,
      "z": 2,
      "name": "Water_Source",
      "level": 1
    },
    {
      "x": 2,
      "y": 4,
      "z": 2,
      "name": "Water_Source",
      "level": 1
    },
    {
      "x": 2,
      "y": 5,
      "z": 2,
      "name": "Water_Source",
      "level": 1
    },
    {
      "x": 2,
      "y": 6,
      "z": 2,
      "name": "Water_Source",
      "level": 1
    },
    {
      "x": 2,
      "y": 3,
      "z": 3,
      "name": "Water_Source",
      "level": 1
    },
    {
      "x": 3,
      "y": 2,
      "z": -2,
      "name": "Water_Source",
      "level": 1
    },
    {
      "x": 3,
      "y": 5,
      "z": -2,
      "name": "Water_Source",
      "level": 1
    },
    {
      "x": 3,
      "y": 6,
      "z": -2,
      "name": "Water_Source",
      "level": 1
    },
    {
      "x": 3,
      "y": 1,
      "z": -1,
      "name": "Water_Source",
      "level": 1
    },
    {
      "x": 3,
      "y": 2,
      "z": -1,
      "name": "Water_Source",
      "level": 1
    },
    {
      "x": 3,
      "y": 5,
      "z": -1,
      "name": "Water_Source",
      "level": 1
    },
    {
      "x": 3,
      "y": 6,
      "z": -1,
      "name": "Water_Source",
      "level": 1
    },
    {
      "x": 3,
      "y": 7,
      "z": -1,
      "name": "Water_Source",
      "level": 1
    },
    {
      "x": 3,
      "y": 1,
      "z": 0,
      "name": "Water_Source",
      "level": 1
    },
    {
      "x": 3,
      "y": 2,
      "z": 0,
      "name": "Water_Source",
      "level": 1
    },
    {
      "x": 3,
      "y": 3,
      "z": 0,
      "name": "Water_Source",
      "level": 1
    },
    {
      "x": 3,
      "y": 5,
      "z": 0,
      "name": "Water_Source",
      "level": 1
    },
    {
      "x": 3,
      "y": 6,
      "z": 0,
      "name": "Water_Source",
      "level": 1
    },
    {
      "x": 3,
      "y": 7,
      "z": 0,
      "name": "Water_Source",
      "level": 1
    },
    {
      "x": 3,
      "y": 1,
      "z": 1,
      "name": "Water_Source",
      "level": 1
    },
    {
      "x": 3,
      "y": 2,
      "z": 1,
      "name": "Water_Source",
      "level": 1
    },
    {
      "x": 3,
      "y": 3,
      "z": 1,
      "name": "Water_Source",
      "level": 1
    },
    {
      "x": 3,
      "y": 4,
      "z": 1,
      "name": "Water_Source",
      "level": 1
    },
    {
      "x": 3,
      "y": 5,
      "z": 1,
      "name": "Water_Source",
      "level": 1
    },
    {
      "x": 3,
      "y": 6,
      "z": 1,
      "name": "Water_Source",
      "level": 1
    },
    {
      "x": 3,
      "y": 7,
      "z": 1,
      "name": "Water_Source",
      "level": 1
    },
    {
      "x": 3,
      "y": 2,
      "z": 2,
      "name": "Water_Source",
      "level": 1
    },
    {
      "x": 3,
      "y": 3,
      "z": 2,
      "name": "Water_Source",
      "level": 1
    },
    {
      "x": 3,
      "y": 4,
      "z": 2,
      "name": "Water_Source",
      "level": 1
    },
    {
      "x": 3,
      "y": 5,
      "z": 2,
      "name": "Water_Source",
      "level": 1
    },
    {
      "x": 3,
      "y": 6,
      "z": 2,
      "name": "Water_Source",
      "level": 1
    },
    {
      "x": 4,
      "y": 5,
      "z": -2,
      "name": "Water_Source",
      "level": 1
    },
    {
      "x": 4,
      "y": 1,
      "z": -1,
      "name": "Water_Source",
      "level": 1
    },
    {
      "x": 4,
      "y": 2,
      "z": -1,
      "name": "Water_Source",
      "level": 1
    },
    {
      "x": 4,
      "y": 1,
      "z": 0,
      "name": "Water_Source",
      "level": 1
    },
    {
      "x": 4,
      "y": 2,
      "z": 0,
      "name": "Water_Source",
      "level": 1
    },
    {
      "x": 4,
      "y": 1,
      "z": 1,
      "name": "Water_Source",
      "level": 1
    },
    {
      "x": 4,
      "y": 2,
      "z": 1,
      "name": "Water_Source",
      "level": 1
    },
    {
      "x": 4,
      "y": 5,
      "z": 2,
      "name": "Water_Source",
      "level": 1
    },
    {
      "x": 5,
      "y": 1,
      "z": -1,
      "name": "Water_Source",
      "level": 1
    },
    {
      "x": 5,
      "y": 2,
      "z": -1,
      "name": "Water_Source",
      "level": 1
    },
    {
      "x": 5,
      "y": 3,
      "z": -1,
      "name": "Water_Source",
      "level": 1
    },
    {
      "x": 5,
      "y": 6,
      "z": -1,
      "name": "Water_Source",
      "level": 1
    },
    {
      "x": 5,
      "y": 1,
      "z": 0,
      "name": "Water_Source",
      "level": 1
    },
    {
      "x": 5,
      "y": 2,
      "z": 0,
      "name": "Water_Source",
      "level": 1
    },
    {
      "x": 5,
      "y": 3,
      "z": 0,
      "name": "Water_Source",
      "level": 1
    },
    {
      "x": 5,
      "y": 1,
      "z": 1,
      "name": "Water_Source",
      "level": 1
    },
    {
      "x": 5,
      "y": 2,
      "z": 1,
      "name": "Water_Source",
      "level": 1
    },
    {
      "x": 5,
      "y": 4,
      "z": 1,
      "name": "Water_Source",
      "level": 1
    },
    {
      "x": 6,
      "y": 1,
      "z": -1,
      "name": "Water_Source",
      "level": 1
    },
    {
      "x": 6,
      "y": 2,
      "z": -1,
      "name": "Water_Source",
      "level": 1
    },
    {
      "x": 6,
      "y": 3,
      "z": -1,
      "name": "Water_Source",
      "level": 1
    },
    {
      "x": 6,
      "y": 6,
      "z": -1,
      "name": "Water_Source",
      "level": 1
    },
    {
      "x": 6,
      "y": 1,
      "z": 0,
      "name": "Water_Source",
      "level": 1
    },
    {
      "x": 6,
      "y": 2,
      "z": 0,
      "name": "Water_Source",
      "level": 1
    },
    {
      "x": 6,
      "y": 3,
      "z": 0,
      "name": "Water_Source",
      "level": 1
    },
    {
      "x": 6,
      "y": 5,
      "z": 0,
      "name": "Water_Source",
      "level": 1
    },
    {
      "x": 6,
      "y": 1,
      "z": 1,
      "name": "Water_Source",
      "level": 1
    },
    {
      "x": 6,
      "y": 2,
      "z": 1,
      "name": "Water_Source",
      "level": 1
    }
  ]
}