{
  "version": 8,
  "blockIdVersion": 11,
  "anchorX": 0,
  "anchorY": 7,
  "anchorZ": 0,
  "blocks": [
    {
      "x": -6,
      "y": 5,
      "z": -6,
      "name": "Rock_Aqua"
    },
    {
      "x": -6,
      "y": 6,
      "z": -6,
      "name": "Rock_Aqua"
    },
    {
      "x": -6,
      "y": 7,
      "z": -6,
      "name": "Rock_Aqua_Brick_Beam"
    },
    {
      "x": -6,
      "y": 8,
      "z": -6,
      "name": "Rock_Aqua_Brick_Beam"
    },
    {
      "x": -6,
      "y": 9,
      "z": -6,
      "name": "Rock_Aqua_Brick_Smooth_Half",
      "rotation": 7
    },
    {
      "x": -6,
      "y": 4,
      "z": -5,
      "name": "Rock_Aqua"
    },
    {
      "x": -6,
      "y": 5,
      "z": -5,
      "name": "Rock_Aqua"
    },
    {
      "x": -6,
      "y": 6,
      "z": -5,
      "name": "Rock_Aqua"
    },
    {
      "x": -6,
      "y": 3,
      "z": -4,
      "name": "Rock_Aqua"
    },
    {
      "x": -6,
      "y": 4,
      "z": -4,
      "name": "Rock_Aqua"
    },
    {
      "x": -6,
      "y": 3,
      "z": -3,
      "name": "Rock_Aqua"
    },
    {
      "x": -6,
      "y": 4,
      "z": -3,
      "name": "Rock_Aqua"
    },
    {
      "x": -6,
      "y": 3,
      "z": -2,
      "name": "Rock_Aqua"
    },
    {
      "x": -6,
      "y": 4,
      "z": -2,
      "name": "Rock_Aqua"
    },
    {
      "x": -6,
      "y": 2,
      "z": -1,
      "name": "Rock_Aqua"
    },
    {
      "x": -6,
      "y": 3,
      "z": -1,
      "name": "Rock_Aqua"
    },
    {
      "x": -6,
      "y": 4,
      "z": -1,
      "name": "Rock_Aqua"
    },
    {
      "x": -6,
      "y": 5,
      "z": -1,
      "name": "Rock_Aqua"
    },
    {
      "x": -6,
      "y": 2,
      "z": 0,
      "name": "Rock_Aqua"
    },
    {
      "x": -6,
      "y": 3,
      "z": 0,
      "name": "Rock_Aqua"
    },
    {
      "x": -6,
      "y": 4,
      "z": 0,
      "name": "Rock_Aqua"
    },
    {
      "x": -6,
      "y": 5,
      "z": 0,
      "name": "Rock_Aqua"
    },
    {
      "x": -6,
      "y": 6,
      "z": 0,
      "name": "Rock_Aqua"
    },
    {
      "x": -6,
      "y": 7,
      "z": 0,
      "name": "Rubble_Aqua",
      "support": 15
    },
    {
      "x": -6,
      "y": 2,
      "z": 1,
      "name": "Rock_Aqua"
    },
    {
      "x": -6,
      "y": 3,
      "z": 1,
      "name": "Rock_Aqua"
    },
    {
      "x": -6,
      "y": 4,
      "z": 1,
      "name": "Rock_Aqua"
    },
    {
      "x": -6,
      "y": 5,
      "z": 1,
      "name": "Rock_Aqua"
    },
    {
      "x": -6,
      "y": 6,
      "z": 1,
      "name": "Rock_Aqua"
    },
    {
      "x": -6,
      "y": 3,
      "z": 2,
      "name": "Rock_Aqua"
    },
    {
      "x": -6,
      "y": 4,
      "z": 2,
      "name": "Rock_Aqua"
    },
    {
      "x": -6,
      "y": 3,
      "z": 3,
      "name": "Rock_Aqua"
    },
    {
      "x": -6,
      "y": 4,
      "z": 3,
      "name": "Rock_Aqua"
    },
    {
      "x": -6,
      "y": 3,
      "z": 4,
      "name": "Rock_Aqua"
    },
    {
      "x": -6,
      "y": 4,
      "z": 4,
      "name": "Rock_Aqua"
    },
    {
      "x": -5,
      "y": 4,
      "z": -7,
      "name": "Rock_Aqua"
    },
    {
      "x": -5,
      "y": 5,
      "z": -7,
      "name": "Rock_Aqua"
    },
    {
      "x": -5,
      "y": 6,
      "z": -7,
      "name": "Rock_Aqua"
    },
    {
      "x": -5,
      "y": 3,
      "z": -6,
      "name": "Rock_Aqua"
    },
    {
      "x": -5,
      "y": 4,
      "z": -6,
      "name": "Rock_Aqua"
    },
    {
      "x": -5,
      "y": 5,
      "z": -6,
      "name": "Rock_Aqua"
    },
    {
      "x": -5,
      "y": 6,
      "z": -6,
      "name": "Rock_Aqua"
    },
    {
      "x": -5,
      "y": 7,
      "z": -6,
      "name": "Rock_Aqua_Brick_Decorative"
    },
    {
      "x": -5,
      "y": 8,
      "z": -6,
      "name": "Rock_Aqua_Brick_Smooth"
    },
    {
      "x": -5,
      "y": 9,
      "z": -6,
      "name": "Rock_Aqua_Brick_Smooth"
    },
    {
      "x": -5,
      "y": 10,
      "z": -6,
      "name": "Rock_Aqua_Brick_Smooth"
    },
    {
      "x": -5,
      "y": 11,
      "z": -6,
      "name": "Rock_Aqua_Brick_Smooth"
    },
    {
      "x": -5,
      "y": 12,
      "z": -6,
      "name": "Rock_Aqua_Brick_Beam"
    },
    {
      "x": -5,
      "y": 3,
      "z": -5,
      "name": "Rock_Aqua"
    },
    {
      "x": -5,
      "y": 4,
      "z": -5,
      "name": "Rock_Aqua"
    },
    {
      "x": -5,
      "y": 5,
      "z": -5,
      "name": "Rock_Aqua"
    },
    {
      "x": -5,
      "y": 6,
      "z": -5,
      "name": "Rock_Aqua"
    },
    {
      "x": -5,
      "y": 7,
      "z": -5,
      "name": "Rock_Aqua_Brick_Wall",
      "rotation": 1
    },
    {
      "x": -5,
      "y": 10,
      "z": -5,
      "name": "Rock_Runic_Blue_Brick_Half",
      "rotation": 7
    },
    {
      "x": -5,
      "y": 2,
      "z": -4,
      "name": "Rock_Aqua"
    },
    {
      "x": -5,
      "y": 3,
      "z": -4,
      "name": "Rock_Aqua"
    },
    {
      "x": -5,
      "y": 4,
      "z": -4,
      "name": "Rock_Aqua"
    },
    {
      "x": -5,
      "y": 5,
      "z": -4,
      "name": "Rock_Aqua"
    },
    {
      "x": -5,
      "y": 6,
      "z": -4,
      "name": "Rock_Aqua"
    },
    {
      "x": -5,
      "y": 7,
      "z": -4,
      "name": "Rock_Aqua_Brick_Wall",
      "rotation": 1
    },
    {
      "x": -5,
      "y": 10,
      "z": -4,
      "name": "Rock_Runic_Blue_Brick_Half",
      "rotation": 7
    },
    {
      "x": -5,
      "y": 2,
      "z": -3,
      "name": "Rock_Aqua"
    },
    {
      "x": -5,
      "y": 3,
      "z": -3,
      "name": "Rock_Aqua"
    },
    {
      "x": -5,
      "y": 4,
      "z": -3,
      "name": "Rock_Aqua"
    },
    {
      "x": -5,
      "y": 5,
      "z": -3,
      "name": "Rock_Aqua"
    },
    {
      "x": -5,
      "y": 6,
      "z": -3,
      "name": "Rock_Aqua"
    },
    {
      "x": -5,
      "y": 10,
      "z": -3,
      "name": "Rock_Runic_Blue_Brick_Half",
      "rotation": 7
    },
    {
      "x": -5,
      "y": 2,
      "z": -2,
      "name": "Rock_Aqua"
    },
    {
      "x": -5,
      "y": 3,
      "z": -2,
      "name": "Rock_Aqua"
    },
    {
      "x": -5,
      "y": 4,
      "z": -2,
      "name": "Rock_Aqua"
    },
    {
      "x": -5,
      "y": 5,
      "z": -2,
      "name": "Rock_Aqua"
    },
    {
      "x": -5,
      "y": 6,
      "z": -2,
      "name": "Rock_Aqua"
    },
    {
      "x": -5,
      "y": 9,
      "z": -2,
      "name": "Rock_Runic_Blue_Brick_Half",
      "rotation": 7
    },
    {
      "x": -5,
      "y": 2,
      "z": -1,
      "name": "Rock_Aqua"
    },
    {
      "x": -5,
      "y": 3,
      "z": -1,
      "name": "Rock_Aqua"
    },
    {
      "x": -5,
      "y": 4,
      "z": -1,
      "name": "Rock_Aqua"
    },
    {
      "x": -5,
      "y": 5,
      "z": -1,
      "name": "Rock_Aqua"
    },
    {
      "x": -5,
      "y": 6,
      "z": -1,
      "name": "Rock_Aqua"
    },
    {
      "x": -5,
      "y": 7,
      "z": -1,
      "name": "Rock_Aqua_Brick_Wall",
      "rotation": 1
    },
    {
      "x": -5,
      "y": 8,
      "z": -1,
      "name": "Rock_Runic_Blue_Brick_Half",
      "rotation": 7
    },
    {
      "x": -5,
      "y": 1,
      "z": 0,
      "name": "Rock_Aqua"
    },
    {
      "x": -5,
      "y": 2,
      "z": 0,
      "name": "Rock_Aqua"
    },
    {
      "x": -5,
      "y": 3,
      "z": 0,
      "name": "Rock_Aqua"
    },
    {
      "x": -5,
      "y": 4,
      "z": 0,
      "name": "Rock_Aqua"
    },
    {
      "x": -5,
      "y": 5,
      "z": 0,
      "name": "Rock_Aqua"
    },
    {
      "x": -5,
      "y": 6,
      "z": 0,
      "name": "Rock_Aqua"
    },
    {
      "x": -5,
      "y": 7,
      "z": 0,
      "name": "Rock_Aqua_Brick_Wall",
      "rotation": 1
    },
    {
      "x": -5,
      "y": 8,
      "z": 0,
      "name": "Rock_Runic_Blue_Brick_Half",
      "rotation": 7
    },
    {
      "x": -5,
      "y": 1,
      "z": 1,
      "name": "Rock_Aqua"
    },
    {
      "x": -5,
      "y": 2,
      "z": 1,
      "name": "Rock_Aqua"
    },
    {
      "x": -5,
      "y": 3,
      "z": 1,
      "name": "Rock_Aqua"
    },
    {
      "x": -5,
      "y": 4,
      "z": 1,
      "name": "Rock_Aqua"
    },
    {
      "x": -5,
      "y": 5,
      "z": 1,
      "name": "Rock_Aqua"
    },
    {
      "x": -5,
      "y": 6,
      "z": 1,
      "name": "Rock_Aqua"
    },
    {
      "x": -5,
      "y": 7,
      "z": 1,
      "name": "Rock_Aqua_Brick_Decorative"
    },
    {
      "x": -5,
      "y": 8,
      "z": 1,
      "name": "Rock_Aqua_Brick_Stairs",
      "rotation": 3
    },
    {
      "x": -5,
      "y": 9,
      "z": 1,
      "name": "Rock_Aqua_Brick_Stairs",
      "rotation": 9
    },
    {
      "x": -5,
      "y": 10,
      "z": 1,
      "name": "Rock_Aqua_Brick_Smooth"
    },
    {
      "x": -5,
      "y": 11,
      "z": 1,
      "name": "Rock_Aqua_Brick_Stairs",
      "rotation": 3
    },
    {
      "x": -5,
      "y": 2,
      "z": 2,
      "name": "Rock_Aqua"
    },
    {
      "x": -5,
      "y": 3,
      "z": 2,
      "name": "Rock_Aqua"
    },
    {
      "x": -5,
      "y": 4,
      "z": 2,
      "name": "Rock_Aqua"
    },
    {
      "x": -5,
      "y": 5,
      "z": 2,
      "name": "Rock_Aqua"
    },
    {
      "x": -5,
      "y": 6,
      "z": 2,
      "name": "Rock_Aqua"
    },
    {
      "x": -5,
      "y": 2,
      "z": 3,
      "name": "Rock_Aqua"
    },
    {
      "x": -5,
      "y": 3,
      "z": 3,
      "name": "Rock_Aqua"
    },
    {
      "x": -5,
      "y": 4,
      "z": 3,
      "name": "Rock_Aqua"
    },
    {
      "x": -5,
      "y": 5,
      "z": 3,
      "name": "Rock_Aqua"
    },
    {
      "x": -5,
      "y": 2,
      "z": 4,
      "name": "Rock_Aqua"
    },
    {
      "x": -5,
      "y": 3,
      "z": 4,
      "name": "Rock_Aqua"
    },
    {
      "x": -5,
      "y": 4,
      "z": 4,
      "name": "Rock_Aqua"
    },
    {
      "x": -5,
      "y": 2,
      "z": 5,
      "name": "Rock_Aqua"
    },
    {
      "x": -5,
      "y": 3,
      "z": 5,
      "name": "Rock_Aqua"
    },
    {
      "x": -5,
      "y": 4,
      "z": 5,
      "name": "Rock_Aqua"
    },
    {
      "x": -4,
      "y": 3,
      "z": -7,
      "name": "Rock_Aqua"
    },
    {
      "x": -4,
      "y": 4,
      "z": -7,
      "name": "Rock_Aqua"
    },
    {
      "x": -4,
      "y": 5,
      "z": -7,
      "name": "Rock_Aqua"
    },
    {
      "x": -4,
      "y": 6,
      "z": -7,
      "name": "Rock_Aqua"
    },
    {
      "x": -4,
      "y": 7,
      "z": -7,
      "name": "Rubble_Aqua",
      "support": 15
    },
    {
      "x": -4,
      "y": 3,
      "z": -6,
      "name": "Rock_Aqua"
    },
    {
      "x": -4,
      "y": 4,
      "z": -6,
      "name": "Rock_Aqua"
    },
    {
      "x": -4,
      "y": 5,
      "z": -6,
      "name": "Rock_Aqua"
    },
    {
      "x": -4,
      "y": 6,
      "z": -6,
      "name": "Rock_Aqua"
    },
    {
      "x": -4,
      "y": 7,
      "z": -6,
      "name": "Rock_Aqua_Brick_Wall"
    },
    {
      "x": -4,
      "y": 10,
      "z": -6,
      "name": "Rock_Runic_Blue_Brick_Half",
      "rotation": 6
    },
    {
      "x": -4,
      "y": 2,
      "z": -5,
      "name": "Rock_Aqua"
    },
    {
      "x": -4,
      "y": 3,
      "z": -5,
      "name": "Rock_Aqua"
    },
    {
      "x": -4,
      "y": 4,
      "z": -5,
      "name": "Rock_Aqua"
    },
    {
      "x": -4,
      "y": 5,
      "z": -5,
      "name": "Rock_Aqua"
    },
    {
      "x": -4,
      "y": 6,
      "z": -5,
      "name": "Rock_Aqua"
    },
    {
      "x": -4,
      "y": 10,
      "z": -5,
      "name": "Rock_Runic_Blue_Brick"
    },
    {
      "x": -4,
      "y": 2,
      "z": -4,
      "name": "Rock_Aqua"
    },
    {
      "x": -4,
      "y": 3,
      "z": -4,
      "name": "Rock_Aqua"
    },
    {
      "x": -4,
      "y": 4,
      "z": -4,
      "name": "Rock_Aqua"
    },
    {
      "x": -4,
      "y": 5,
      "z": -4,
      "name": "Rock_Aqua"
    },
    {
      "x": -4,
      "y": 6,
      "z": -4,
      "name": "Rock_Aqua"
    },
    {
      "x": -4,
      "y": 7,
      "z": -4,
      "name": "Plant_Moss_Short_Blue",
      "support": 15
    },
    {
      "x": -4,
      "y": 10,
      "z": -4,
      "name": "Rock_Runic_Blue_Brick"
    },
    {
      "x": -4,
      "y": 11,
      "z": -4,
      "name": "Cloth_Roof_Blue_Flat"
    },
    {
      "x": -4,
      "y": 1,
      "z": -3,
      "name": "Rock_Aqua"
    },
    {
      "x": -4,
      "y": 2,
      "z": -3,
      "name": "Rock_Aqua"
    },
    {
      "x": -4,
      "y": 3,
      "z": -3,
      "name": "Rock_Aqua"
    },
    {
      "x": -4,
      "y": 4,
      "z": -3,
      "name": "Rock_Aqua"
    },
    {
      "x": -4,
      "y": 5,
      "z": -3,
      "name": "Rock_Aqua"
    },
    {
      "x": -4,
      "y": 6,
      "z": -3,
      "name": "Rock_Aqua"
    },
    {
      "x": -4,
      "y": 7,
      "z": -3,
      "name": "Rubble_Aqua",
      "support": 15
    },
    {
      "x": -4,
      "y": 9,
      "z": -3,
      "name": "Rock_Runic_Blue_Brick_Stairs",
      "rotation": 8
    },
    {
      "x": -4,
      "y": 10,
      "z": -3,
      "name": "Rock_Runic_Blue_Brick_Stairs"
    },
    {
      "x": -4,
      "y": 1,
      "z": -2,
      "name": "Rock_Aqua"
    },
    {
      "x": -4,
      "y": 2,
      "z": -2,
      "name": "Rock_Aqua"
    },
    {
      "x": -4,
      "y": 3,
      "z": -2,
      "name": "Rock_Aqua"
    },
    {
      "x": -4,
      "y": 4,
      "z": -2,
      "name": "Rock_Aqua"
    },
    {
      "x": -4,
      "y": 5,
      "z": -2,
      "name": "Rock_Aqua"
    },
    {
      "x": -4,
      "y": 6,
      "z": -2,
      "name": "Rock_Aqua"
    },
    {
      "x": -4,
      "y": 8,
      "z": -2,
      "name": "Rock_Runic_Blue_Brick_Stairs",
      "rotation": 8
    },
    {
      "x": -4,
      "y": 9,
      "z": -2,
      "name": "Rock_Runic_Blue_Brick_Stairs"
    },
    {
      "x": -4,
      "y": 1,
      "z": -1,
      "name": "Rock_Aqua"
    },
    {
      "x": -4,
      "y": 2,
      "z": -1,
      "name": "Rock_Aqua"
    },
    {
      "x": -4,
      "y": 3,
      "z": -1,
      "name": "Rock_Aqua"
    },
    {
      "x": -4,
      "y": 4,
      "z": -1,
      "name": "Rock_Aqua"
    },
    {
      "x": -4,
      "y": 5,
      "z": -1,
      "name": "Rock_Aqua"
    },
    {
      "x": -4,
      "y": 6,
      "z": -1,
      "name": "Rock_Aqua"
    },
    {
      "x": -4,
      "y": 8,
      "z": -1,
      "name": "Rock_Runic_Blue_Brick"
    },
    {
      "x": -4,
      "y": 0,
      "z": 0,
      "name": "Rock_Aqua"
    },
    {
      "x": -4,
      "y": 1,
      "z": 0,
      "name": "Rock_Aqua"
    },
    {
      "x": -4,
      "y": 2,
      "z": 0,
      "name": "Rock_Aqua"
    },
    {
      "x": -4,
      "y": 3,
      "z": 0,
      "name": "Rock_Aqua"
    },
    {
      "x": -4,
      "y": 4,
      "z": 0,
      "name": "Rock_Aqua"
    },
    {
      "x": -4,
      "y": 5,
      "z": 0,
      "name": "Rock_Aqua"
    },
    {
      "x": -4,
      "y": 6,
      "z": 0,
      "name": "Rock_Aqua"
    },
    {
      "x": -4,
      "y": 8,
      "z": 0,
      "name": "Rock_Runic_Blue_Brick"
    },
    {
      "x": -4,
      "y": 9,
      "z": 0,
      "name": "Cloth_Roof_Blue_Flat"
    },
    {
      "x": -4,
      "y": 0,
      "z": 1,
      "name": "Rock_Aqua"
    },
    {
      "x": -4,
      "y": 1,
      "z": 1,
      "name": "Rock_Aqua"
    },
    {
      "x": -4,
      "y": 2,
      "z": 1,
      "name": "Rock_Aqua"
    },
    {
      "x": -4,
      "y": 3,
      "z": 1,
      "name": "Rock_Aqua"
    },
    {
      "x": -4,
      "y": 4,
      "z": 1,
      "name": "Rock_Aqua"
    },
    {
      "x": -4,
      "y": 5,
      "z": 1,
      "name": "Rock_Aqua"
    },
    {
      "x": -4,
      "y": 6,
      "z": 1,
      "name": "Rock_Aqua"
    },
    {
      "x": -4,
      "y": 7,
      "z": 1,
      "name": "Rock_Aqua_Brick_Wall"
    },
    {
      "x": -4,
      "y": 8,
      "z": 1,
      "name": "Rock_Runic_Blue_Brick_Half",
      "rotation": 4
    },
    {
      "x": -4,
      "y": 11,
      "z": 1,
      "name": "Rock_Aqua_Brick_Stairs",
      "rotation": 11
    },
    {
      "x": -4,
      "y": 12,
      "z": 1,
      "name": "Rock_Aqua_Brick_Smooth_Half"
    },
    {
      "x": -4,
      "y": 1,
      "z": 2,
      "name": "Rock_Aqua"
    },
    {
      "x": -4,
      "y": 2,
      "z": 2,
      "name": "Rock_Aqua"
    },
    {
      "x": -4,
      "y": 3,
      "z": 2,
      "name": "Rock_Aqua"
    },
    {
      "x": -4,
      "y": 4,
      "z": 2,
      "name": "Rock_Aqua"
    },
    {
      "x": -4,
      "y": 5,
      "z": 2,
      "name": "Rock_Aqua"
    },
    {
      "x": -4,
      "y": 6,
      "z": 2,
      "name": "Rock_Aqua"
    },
    {
      "x": -4,
      "y": 7,
      "z": 2,
      "name": "Rubble_Aqua_Medium",
      "support": 15
    },
    {
      "x": -4,
      "y": 1,
      "z": 3,
      "name": "Rock_Aqua"
    },
    {
      "x": -4,
      "y": 2,
      "z": 3,
      "name": "Rock_Aqua"
    },
    {
      "x": -4,
      "y": 3,
      "z": 3,
      "name": "Rock_Aqua"
    },
    {
      "x": -4,
      "y": 4,
      "z": 3,
      "name": "Rock_Aqua"
    },
    {
      "x": -4,
      "y": 5,
      "z": 3,
      "name": "Rock_Aqua"
    },
    {
      "x": -4,
      "y": 6,
      "z": 3,
      "name": "Rock_Aqua"
    },
    {
      "x": -4,
      "y": 1,
      "z": 4,
      "name": "Rock_Aqua"
    },
    {
      "x": -4,
      "y": 2,
      "z": 4,
      "name": "Rock_Aqua"
    },
    {
      "x": -4,
      "y": 3,
      "z": 4,
      "name": "Rock_Aqua"
    },
    {
      "x": -4,
      "y": 4,
      "z": 4,
      "name": "Rock_Aqua"
    },
    {
      "x": -4,
      "y": 5,
      "z": 4,
      "name": "Rock_Aqua"
    },
    {
      "x": -4,
      "y": 6,
      "z": 4,
      "name": "Rock_Aqua"
    },
    {
      "x": -4,
      "y": 1,
      "z": 5,
      "name": "Rock_Aqua"
    },
    {
      "x": -4,
      "y": 2,
      "z": 5,
      "name": "Rock_Aqua"
    },
    {
      "x": -4,
      "y": 3,
      "z": 5,
      "name": "Rock_Aqua"
    },
    {
      "x": -4,
      "y": 4,
      "z": 5,
      "name": "Rock_Aqua"
    },
    {
      "x": -4,
      "y": 2,
      "z": 6,
      "name": "Rock_Aqua"
    },
    {
      "x": -4,
      "y": 3,
      "z": 6,
      "name": "Rock_Aqua"
    },
    {
      "x": -4,
      "y": 4,
      "z": 6,
      "name": "Rock_Aqua"
    },
    {
      "x": -3,
      "y": 3,
      "z": -7,
      "name": "Rock_Aqua"
    },
    {
      "x": -3,
      "y": 4,
      "z": -7,
      "name": "Rock_Aqua"
    },
    {
      "x": -3,
      "y": 5,
      "z": -7,
      "name": "Rock_Aqua"
    },
    {
      "x": -3,
      "y": 2,
      "z": -6,
      "name": "Rock_Aqua"
    },
    {
      "x": -3,
      "y": 3,
      "z": -6,
      "name": "Rock_Aqua"
    },
    {
      "x": -3,
      "y": 4,
      "z": -6,
      "name": "Rock_Aqua"
    },
    {
      "x": -3,
      "y": 5,
      "z": -6,
      "name": "Rock_Aqua"
    },
    {
      "x": -3,
      "y": 6,
      "z": -6,
      "name": "Rock_Aqua"
    },
    {
      "x": -3,
      "y": 10,
      "z": -6,
      "name": "Rock_Runic_Blue_Brick_Half",
      "rotation": 6
    },
    {
      "x": -3,
      "y": 1,
      "z": -5,
      "name": "Rock_Aqua"
    },
    {
      "x": -3,
      "y": 2,
      "z": -5,
      "name": "Rock_Aqua"
    },
    {
      "x": -3,
      "y": 3,
      "z": -5,
      "name": "Rock_Aqua"
    },
    {
      "x": -3,
      "y": 4,
      "z": -5,
      "name": "Rock_Aqua"
    },
    {
      "x": -3,
      "y": 5,
      "z": -5,
      "name": "Rock_Aqua"
    },
    {
      "x": -3,
      "y": 6,
      "z": -5,
      "name": "Rock_Aqua"
    },
    {
      "x": -3,
      "y": 7,
      "z": -5,
      "name": "Rubble_Aqua_Medium",
      "support": 15
    },
    {
      "x": -3,
      "y": 10,
      "z": -5,
      "name": "Rock_Runic_Blue_Brick"
    },
    {
      "x": -3,
      "y": 1,
      "z": -4,
      "name": "Rock_Aqua"
    },
    {
      "x": -3,
      "y": 2,
      "z": -4,
      "name": "Rock_Aqua"
    },
    {
      "x": -3,
      "y": 3,
      "z": -4,
      "name": "Rock_Aqua"
    },
    {
      "x": -3,
      "y": 4,
      "z": -4,
      "name": "Rock_Aqua"
    },
    {
      "x": -3,
      "y": 5,
      "z": -4,
      "name": "Rock_Aqua"
    },
    {
      "x": -3,
      "y": 6,
      "z": -4,
      "name": "Rock_Aqua"
    },
    {
      "x": -3,
      "y": 9,
      "z": -4,
      "name": "Rock_Aqua_Brick_Smooth_Half",
      "rotation": 7
    },
    {
      "x": -3,
      "y": 10,
      "z": -4,
      "name": "Rock_Runic_Blue_Brick"
    },
    {
      "x": -3,
      "y": 0,
      "z": -3,
      "name": "Rock_Aqua"
    },
    {
      "x": -3,
      "y": 1,
      "z": -3,
      "name": "Rock_Runic_Brick"
    },
    {
      "x": -3,
      "y": 2,
      "z": -3,
      "name": "Rock_Aqua_Brick_Decorative"
    },
    {
      "x": -3,
      "y": 3,
      "z": -3,
      "name": "Rock_Aqua_Brick_Smooth"
    },
    {
      "x": -3,
      "y": 4,
      "z": -3,
      "name": "Rock_Aqua_Brick_Smooth"
    },
    {
      "x": -3,
      "y": 5,
      "z": -3,
      "name": "Rock_Aqua_Brick_Smooth"
    },
    {
      "x": -3,
      "y": 6,
      "z": -3,
      "name": "Rock_Aqua_Brick_Ornate"
    },
    {
      "x": -3,
      "y": 7,
      "z": -3,
      "name": "Rock_Aqua_Brick_Decorative"
    },
    {
      "x": -3,
      "y": 8,
      "z": -3,
      "name": "Rock_Aqua_Brick_Smooth"
    },
    {
      "x": -3,
      "y": 9,
      "z": -3,
      "name": "Rock_Aqua_Brick_Smooth"
    },
    {
      "x": -3,
      "y": 10,
      "z": -3,
      "name": "Rock_Runic_Blue_Brick_Stairs"
    },
    {
      "x": -3,
      "y": 0,
      "z": -2,
      "name": "Rock_Aqua"
    },
    {
      "x": -3,
      "y": 1,
      "z": -2,
      "name": "Rock_Runic_Brick"
    },
    {
      "x": -3,
      "y": 2,
      "z": -2,
      "name": "Rock_Aqua_Brick_Decorative"
    },
    {
      "x": -3,
      "y": 3,
      "z": -2,
      "name": "Rock_Aqua_Brick_Smooth"
    },
    {
      "x": -3,
      "y": 4,
      "z": -2,
      "name": "Rock_Aqua_Brick_Stairs",
      "rotation": 11
    },
    {
      "x": -3,
      "y": 5,
      "z": -2,
      "name": "Rock_Aqua_Brick_Smooth"
    },
    {
      "x": -3,
      "y": 6,
      "z": -2,
      "name": "Rock_Aqua_Brick_Ornate"
    },
    {
      "x": -3,
      "y": 7,
      "z": -2,
      "name": "Rock_Aqua_Brick_Decorative"
    },
    {
      "x": -3,
      "y": 8,
      "z": -2,
      "name": "Rock_Aqua_Brick_Smooth"
    },
    {
      "x": -3,
      "y": 9,
      "z": -2,
      "name": "Rock_Runic_Blue_Brick_Stairs"
    },
    {
      "x": -3,
      "y": 0,
      "z": -1,
      "name": "Rock_Aqua"
    },
    {
      "x": -3,
      "y": 1,
      "z": -1,
      "name": "Rock_Runic_Brick"
    },
    {
      "x": -3,
      "y": 2,
      "z": -1,
      "name": "Rock_Aqua_Brick_Decorative"
    },
    {
      "x": -3,
      "y": 3,
      "z": -1,
      "name": "Rock_Aqua_Brick_Smooth"
    },
    {
      "x": -3,
      "y": 4,
      "z": -1,
      "name": "Rock_Aqua_Brick_Smooth"
    },
    {
      "x": -3,
      "y": 5,
      "z": -1,
      "name": "Rock_Aqua_Brick_Smooth"
    },
    {
      "x": -3,
      "y": 6,
      "z": -1,
      "name": "Rock_Aqua_Brick_Ornate"
    },
    {
      "x": -3,
      "y": 7,
      "z": -1,
      "name": "Rock_Runic_Blue_Brick_Stairs",
      "rotation": 9
    },
    {
      "x": -3,
      "y": 8,
      "z": -1,
      "name": "Rock_Runic_Blue_Brick"
    },
    {
      "x": -3,
      "y": 9,
      "z": -1,
      "name": "Cloth_Roof_Blue_Flat"
    },
    {
      "x": -3,
      "y": 0,
      "z": 0,
      "name": "Rock_Aqua"
    },
    {
      "x": -3,
      "y": 1,
      "z": 0,
      "name": "Rock_Runic_Brick"
    },
    {
      "x": -3,
      "y": 2,
      "z": 0,
      "name": "Rock_Aqua_Brick_Decorative"
    },
    {
      "x": -3,
      "y": 3,
      "z": 0,
      "name": "Rock_Aqua_Brick_Stairs",
      "rotation": 1
    },
    {
      "x": -3,
      "y": 4,
      "z": 0,
      "name": "Rock_Aqua_Brick_Smooth"
    },
    {
      "x": -3,
      "y": 5,
      "z": 0,
      "name": "Rock_Aqua_Brick_Smooth"
    },
    {
      "x": -3,
      "y": 6,
      "z": 0,
      "name": "Rock_Aqua"
    },
    {
      "x": -3,
      "y": 7,
      "z": 0,
      "name": "Rock_Runic_Blue_Brick_Stairs",
      "rotation": 9
    },
    {
      "x": -3,
      "y": 8,
      "z": 0,
      "name": "Rock_Runic_Blue_Brick"
    },
    {
      "x": -3,
      "y": 0,
      "z": 1,
      "name": "Rock_Aqua"
    },
    {
      "x": -3,
      "y": 1,
      "z": 1,
      "name": "Rock_Runic_Brick"
    },
    {
      "x": -3,
      "y": 2,
      "z": 1,
      "name": "Rock_Aqua_Brick_Decorative"
    },
    {
      "x": -3,
      "y": 3,
      "z": 1,
      "name": "Rock_Aqua_Brick_Smooth"
    },
    {
      "x": -3,
      "y": 4,
      "z": 1,
      "name": "Rock_Aqua_Brick_Smooth"
    },
    {
      "x": -3,
      "y": 5,
      "z": 1,
      "name": "Rock_Aqua_Brick_Smooth"
    },
    {
      "x": -3,
      "y": 6,
      "z": 1,
      "name": "Rock_Aqua"
    },
    {
      "x": -3,
      "y": 7,
      "z": 1,
      "name": "Rock_Aqua_Brick_Wall"
    },
    {
      "x": -3,
      "y": 8,
      "z": 1,
      "name": "Rock_Runic_Blue_Brick_Half",
      "rotation": 4
    },
    {
      "x": -3,
      "y": 0,
      "z": 2,
      "name": "Rock_Aqua"
    },
    {
      "x": -3,
      "y": 1,
      "z": 2,
      "name": "Rock_Runic_Brick"
    },
    {
      "x": -3,
      "y": 2,
      "z": 2,
      "name": "Rock_Aqua_Brick_Decorative"
    },
    {
      "x": -3,
      "y": 3,
      "z": 2,
      "name": "Rock_Aqua_Brick_Smooth"
    },
    {
      "x": -3,
      "y": 4,
      "z": 2,
      "name": "Rock_Aqua_Brick_Stairs",
      "rotation": 11
    },
    {
      "x": -3,
      "y": 5,
      "z": 2,
      "name": "Rock_Aqua_Brick_Smooth"
    },
    {
      "x": -3,
      "y": 6,
      "z": 2,
      "name": "Rock_Aqua"
    },
    {
      "x": -3,
      "y": 0,
      "z": 3,
      "name": "Rock_Aqua"
    },
    {
      "x": -3,
      "y": 1,
      "z": 3,
      "name": "Rock_Runic_Brick"
    },
    {
      "x": -3,
      "y": 2,
      "z": 3,
      "name": "Rock_Aqua_Brick_Decorative"
    },
    {
      "x": -3,
      "y": 3,
      "z": 3,
      "name": "Rock_Aqua_Brick_Smooth"
    },
    {
      "x": -3,
      "y": 4,
      "z": 3,
      "name": "Rock_Aqua_Brick_Stairs",
      "rotation": 11
    },
    {
      "x": -3,
      "y": 5,
      "z": 3,
      "name": "Rock_Aqua_Brick_Smooth"
    },
    {
      "x": -3,
      "y": 6,
      "z": 3,
      "name": "Rock_Aqua"
    },
    {
      "x": -3,
      "y": 7,
      "z": 3,
      "name": "Rock_Aqua_Brick_Decorative"
    },
    {
      "x": -3,
      "y": 8,
      "z": 3,
      "name": "Rock_Aqua_Brick_Smooth"
    },
    {
      "x": -3,
      "y": 0,
      "z": 4,
      "name": "Rock_Aqua"
    },
    {
      "x": -3,
      "y": 1,
      "z": 4,
      "name": "Rock_Runic_Brick"
    },
    {
      "x": -3,
      "y": 2,
      "z": 4,
      "name": "Rock_Aqua_Brick_Decorative"
    },
    {
      "x": -3,
      "y": 3,
      "z": 4,
      "name": "Rock_Aqua_Brick_Smooth"
    },
    {
      "x": -3,
      "y": 4,
      "z": 4,
      "name": "Rock_Aqua_Brick_Smooth"
    },
    {
      "x": -3,
      "y": 5,
      "z": 4,
      "name": "Rock_Aqua_Brick_Smooth"
    },
    {
      "x": -3,
      "y": 6,
      "z": 4,
      "name": "Rock_Aqua"
    },
    {
      "x": -3,
      "y": 7,
      "z": 4,
      "name": "Rock_Aqua_Brick_Decorative"
    },
    {
      "x": -3,
      "y": 8,
      "z": 4,
      "name": "Rock_Aqua_Brick_Smooth_Half"
    },
    {
      "x": -3,
      "y": 0,
      "z": 5,
      "name": "Rock_Aqua"
    },
    {
      "x": -3,
      "y": 1,
      "z": 5,
      "name": "Rock_Runic_Brick"
    },
    {
      "x": -3,
      "y": 2,
      "z": 5,
      "name": "Rock_Aqua_Brick_Decorative"
    },
    {
      "x": -3,
      "y": 3,
      "z": 5,
      "name": "Rock_Aqua_Brick_Smooth"
    },
    {
      "x": -3,
      "y": 4,
      "z": 5,
      "name": "Rock_Aqua_Brick_Smooth"
    },
    {
      "x": -3,
      "y": 5,
      "z": 5,
      "name": "Rock_Aqua"
    },
    {
      "x": -3,
      "y": 6,
      "z": 5,
      "name": "Rock_Aqua"
    },
    {
      "x": -3,
      "y": 1,
      "z": 6,
      "name": "Rock_Aqua"
    },
    {
      "x": -3,
      "y": 2,
      "z": 6,
      "name": "Rock_Aqua"
    },
    {
      "x": -3,
      "y": 3,
      "z": 6,
      "name": "Rock_Aqua"
    },
    {
      "x": -3,
      "y": 4,
      "z": 6,
      "name": "Rock_Aqua"
    },
    {
      "x": -3,
      "y": 5,
      "z": 6,
      "name": "Rock_Aqua"
    },
    {
      "x": -2,
      "y": 3,
      "z": -7,
      "name": "Rock_Aqua"
    },
    {
      "x": -2,
      "y": 4,
      "z": -7,
      "name": "Rock_Aqua"
    },
    {
      "x": -2,
      "y": 1,
      "z": -6,
      "name": "Rock_Aqua"
    },
    {
      "x": -2,
      "y": 2,
      "z": -6,
      "name": "Rock_Aqua"
    },
    {
      "x": -2,
      "y": 3,
      "z": -6,
      "name": "Rock_Aqua"
    },
    {
      "x": -2,
      "y": 4,
      "z": -6,
      "name": "Rock_Aqua"
    },
    {
      "x": -2,
      "y": 5,
      "z": -6,
      "name": "Rock_Aqua"
    },
    {
      "x": -2,
      "y": 6,
      "z": -6,
      "name": "Rock_Aqua"
    },
    {
      "x": -2,
      "y": 1,
      "z": -5,
      "name": "Rock_Aqua"
    },
    {
      "x": -2,
      "y": 2,
      "z": -5,
      "name": "Rock_Aqua"
    },
    {
      "x": -2,
      "y": 3,
      "z": -5,
      "name": "Rock_Aqua"
    },
    {
      "x": -2,
      "y": 4,
      "z": -5,
      "name": "Rock_Aqua"
    },
    {
      "x": -2,
      "y": 5,
      "z": -5,
      "name": "Rock_Aqua"
    },
    {
      "x": -2,
      "y": 6,
      "z": -5,
      "name": "Rock_Aqua"
    },
    {
      "x": -2,
      "y": 7,
      "z": -5,
      "name": "Plant_Moss_Short_Blue",
      "support": 15
    },
    {
      "x": -2,
      "y": 9,
      "z": -5,
      "name": "Rock_Aqua_Brick_Smooth_Half",
      "rotation": 6
    },
    {
      "x": -2,
      "y": 10,
      "z": -5,
      "name": "Rock_Aqua_Brick_Smooth"
    },
    {
      "x": -2,
      "y": 11,
      "z": -5,
      "name": "Rock_Aqua_Brick_Stairs",
      "rotation": 3
    },
    {
      "x": -2,
      "y": 0,
      "z": -4,
      "name": "Rock_Aqua"
    },
    {
      "x": -2,
      "y": 1,
      "z": -4,
      "name": "Rock_Runic_Brick"
    },
    {
      "x": -2,
      "y": 2,
      "z": -4,
      "name": "Rock_Aqua_Brick_Decorative"
    },
    {
      "x": -2,
      "y": 3,
      "z": -4,
      "name": "Rock_Aqua_Brick_Smooth"
    },
    {
      "x": -2,
      "y": 4,
      "z": -4,
      "name": "Rock_Aqua_Brick_Stairs"
    },
    {
      "x": -2,
      "y": 5,
      "z": -4,
      "name": "Rock_Aqua_Brick_Smooth"
    },
    {
      "x": -2,
      "y": 6,
      "z": -4,
      "name": "Rock_Aqua_Brick_Ornate"
    },
    {
      "x": -2,
      "y": 7,
      "z": -4,
      "name": "Rock_Aqua_Brick_Decorative"
    },
    {
      "x": -2,
      "y": 8,
      "z": -4,
      "name": "Rock_Aqua_Brick_Smooth"
    },
    {
      "x": -2,
      "y": 9,
      "z": -4,
      "name": "Rock_Aqua_Brick_Smooth"
    },
    {
      "x": -2,
      "y": 10,
      "z": -4,
      "name": "Rock_Aqua_Brick_Smooth"
    },
    {
      "x": -2,
      "y": 11,
      "z": -4,
      "name": "Rock_Aqua_Brick_Stairs",
      "rotation": 3
    },
    {
      "x": -2,
      "y": 0,
      "z": -3,
      "name": "Rock_Aqua"
    },
    {
      "x": -2,
      "y": 1,
      "z": -3,
      "name": "Rock_Runic_Brick"
    },
    {
      "x": -2,
      "y": 2,
      "z": -3,
      "name": "Rock_Runic_Blue_Brick"
    },
    {
      "x": -2,
      "y": 3,
      "z": -3,
      "name": "Rock_Runic_Blue_Brick"
    },
    {
      "x": -2,
      "y": 9,
      "z": -3,
      "name": "Plant_Leaves_Camphor",
      "support": 15
    },
    {
      "x": -2,
      "y": 10,
      "z": -3,
      "name": "Rock_Runic_Blue_Brick_Half",
      "rotation": 5
    },
    {
      "x": -2,
      "y": 11,
      "z": -3,
      "name": "Rock_Runic_Teal_Brick_Half",
      "rotation": 8
    },
    {
      "x": -2,
      "y": 0,
      "z": -2,
      "name": "Rock_Aqua"
    },
    {
      "x": -2,
      "y": 1,
      "z": -2,
      "name": "Rock_Runic_Brick"
    },
    {
      "x": -2,
      "y": 2,
      "z": -2,
      "name": "Rock_Runic_Blue_Brick"
    },
    {
      "x": -2,
      "y": 3,
      "z": -2,
      "name": "Rock_Runic_Blue_Brick_Stairs"
    },
    {
      "x": -2,
      "y": 5,
      "z": -2,
      "name": "*Furniture_Temple_Dark_Trapdoor_State_Definitions_OpenDoorOut",
      "rotation": 1
    },
    {
      "x": -2,
      "y": 8,
      "z": -2,
      "name": "Rock_Runic_Blue_Brick_Half",
      "rotation": 6
    },
    {
      "x": -2,
      "y": 9,
      "z": -2,
      "name": "Rock_Runic_Blue_Brick_Half",
      "rotation": 5
    },
    {
      "x": -2,
      "y": 11,
      "z": -2,
      "name": "Rock_Runic_Teal_Brick_Half",
      "rotation": 8
    },
    {
      "x": -2,
      "y": 0,
      "z": -1,
      "name": "Rock_Aqua"
    },
    {
      "x": -2,
      "y": 1,
      "z": -1,
      "name": "Rock_Runic_Brick"
    },
    {
      "x": -2,
      "y": 2,
      "z": -1,
      "name": "Rock_Runic_Blue_Brick_Stairs"
    },
    {
      "x": -2,
      "y": 7,
      "z": -1,
      "name": "Rock_Runic_Blue_Brick"
    },
    {
      "x": -2,
      "y": 8,
      "z": -1,
      "name": "Rock_Runic_Blue_Brick_Stairs",
      "rotation": 1
    },
    {
      "x": -2,
      "y": 11,
      "z": -1,
      "name": "Rock_Runic_Teal_Brick_Half",
      "rotation": 8
    },
    {
      "x": -2,
      "y": 0,
      "z": 0,
      "name": "Rock_Aqua"
    },
    {
      "x": -2,
      "y": 1,
      "z": 0,
      "name": "Rock_Runic_Brick"
    },
    {
      "x": -2,
      "y": 5,
      "z": 0,
      "name": "Plant_Leaves_Camphor",
      "support": 15
    },
    {
      "x": -2,
      "y": 6,
      "z": 0,
      "name": "Rock_Aqua_Brick_Ornate"
    },
    {
      "x": -2,
      "y": 7,
      "z": 0,
      "name": "Rock_Runic_Blue_Brick"
    },
    {
      "x": -2,
      "y": 8,
      "z": 0,
      "name": "Rock_Runic_Blue_Brick_Stairs",
      "rotation": 1
    },
    {
      "x": -2,
      "y": 0,
      "z": 1,
      "name": "Rock_Aqua"
    },
    {
      "x": -2,
      "y": 1,
      "z": 1,
      "name": "Rock_Runic_Brick"
    },
    {
      "x": -2,
      "y": 4,
      "z": 1,
      "name": "Plant_Leaves_Camphor",
      "support": 15
    },
    {
      "x": -2,
      "y": 5,
      "z": 1,
      "name": "Rock_Aqua_Brick_Smooth"
    },
    {
      "x": -2,
      "y": 6,
      "z": 1,
      "name": "Rock_Aqua"
    },
    {
      "x": -2,
      "y": 7,
      "z": 1,
      "name": "Rock_Aqua_Brick_Wall"
    },
    {
      "x": -2,
      "y": 8,
      "z": 1,
      "name": "Rock_Runic_Blue_Brick_Half",
      "rotation": 4
    },
    {
      "x": -2,
      "y": 12,
      "z": 1,
      "name": "Rock_Aqua_Brick_Smooth_Half",
      "rotation": 7
    },
    {
      "x": -2,
      "y": 0,
      "z": 2,
      "name": "Rock_Aqua"
    },
    {
      "x": -2,
      "y": 1,
      "z": 2,
      "name": "Rock_Runic_Brick"
    },
    {
      "x": -2,
      "y": 2,
      "z": 2,
      "name": "Rubble_Chalk",
      "support": 15
    },
    {
      "x": -2,
      "y": 5,
      "z": 2,
      "name": "Soil_Clay_Cyan"
    },
    {
      "x": -2,
      "y": 6,
      "z": 2,
      "name": "Rock_Aqua"
    },
    {
      "x": -2,
      "y": 7,
      "z": 2,
      "name": "Plant_Moss_Short_Blue",
      "support": 15
    },
    {
      "x": -2,
      "y": 0,
      "z": 3,
      "name": "Rock_Aqua"
    },
    {
      "x": -2,
      "y": 1,
      "z": 3,
      "name": "Rock_Runic_Brick"
    },
    {
      "x": -2,
      "y": 2,
      "z": 3,
      "name": "Plant_Leaves_Camphor",
      "support": 15
    },
    {
      "x": -2,
      "y": 5,
      "z": 3,
      "name": "Soil_Clay_Cyan"
    },
    {
      "x": -2,
      "y": 6,
      "z": 3,
      "name": "Rock_Aqua"
    },
    {
      "x": -2,
      "y": 7,
      "z": 3,
      "name": "Plant_Moss_Rug_Blue",
      "support": 15
    },
    {
      "x": -2,
      "y": 0,
      "z": 4,
      "name": "Rock_Aqua"
    },
    {
      "x": -2,
      "y": 1,
      "z": 4,
      "name": "Rock_Runic_Brick"
    },
    {
      "x": -2,
      "y": 2,
      "z": 4,
      "name": "Rock_Runic_Dark_Brick_Pillar_Base"
    },
    {
      "x": -2,
      "y": 3,
      "z": 4,
      "name": "Rock_Calcite_Brick_Pillar_Middle"
    },
    {
      "x": -2,
      "y": 4,
      "z": 4,
      "name": "Rock_Runic_Dark_Brick_Pillar_Base",
      "rotation": 8
    },
    {
      "x": -2,
      "y": 5,
      "z": 4,
      "name": "Soil_Clay_Cyan"
    },
    {
      "x": -2,
      "y": 6,
      "z": 4,
      "name": "Rock_Aqua"
    },
    {
      "x": -2,
      "y": 0,
      "z": 5,
      "name": "Rock_Aqua"
    },
    {
      "x": -2,
      "y": 1,
      "z": 5,
      "name": "Rock_Runic_Brick"
    },
    {
      "x": -2,
      "y": 2,
      "z": 5,
      "name": "Rock_Aqua_Brick_Decorative"
    },
    {
      "x": -2,
      "y": 3,
      "z": 5,
      "name": "Rock_Aqua_Brick_Smooth"
    },
    {
      "x": -2,
      "y": 4,
      "z": 5,
      "name": "Rock_Aqua_Brick_Smooth"
    },
    {
      "x": -2,
      "y": 5,
      "z": 5,
      "name": "Rock_Aqua_Brick_Smooth"
    },
    {
      "x": -2,
      "y": 6,
      "z": 5,
      "name": "Rock_Aqua"
    },
    {
      "x": -2,
      "y": 7,
      "z": 5,
      "name": "Rubble_Aqua",
      "support": 15
    },
    {
      "x": -2,
      "y": 1,
      "z": 6,
      "name": "Rock_Aqua"
    },
    {
      "x": -2,
      "y": 2,
      "z": 6,
      "name": "Rock_Aqua"
    },
    {
      "x": -2,
      "y": 3,
      "z": 6,
      "name": "Rock_Aqua"
    },
    {
      "x": -2,
      "y": 4,
      "z": 6,
      "name": "Rock_Aqua"
    },
    {
      "x": -2,
      "y": 5,
      "z": 6,
      "name": "Rock_Aqua"
    },
    {
      "x": -2,
      "y": 6,
      "z": 6,
      "name": "Rock_Aqua"
    },
    {
      "x": -1,
      "y": 2,
      "z": -7,
      "name": "Rock_Aqua"
    },
    {
      "x": -1,
      "y": 3,
      "z": -7,
      "name": "Rock_Aqua"
    },
    {
      "x": -1,
      "y": 4,
      "z": -7,
      "name": "Rock_Aqua"
    },
    {
      "x": -1,
      "y": 1,
      "z": -6,
      "name": "Rock_Aqua"
    },
    {
      "x": -1,
      "y": 2,
      "z": -6,
      "name": "Rock_Aqua"
    },
    {
      "x": -1,
      "y": 3,
      "z": -6,
      "name": "Rock_Aqua"
    },
    {
      "x": -1,
      "y": 4,
      "z": -6,
      "name": "Rock_Aqua"
    },
    {
      "x": -1,
      "y": 5,
      "z": -6,
      "name": "Rock_Aqua"
    },
    {
      "x": -1,
      "y": 0,
      "z": -5,
      "name": "Rock_Aqua"
    },
    {
      "x": -1,
      "y": 1,
      "z": -5,
      "name": "Rock_Runic_Brick"
    },
    {
      "x": -1,
      "y": 2,
      "z": -5,
      "name": "Rock_Aqua_Brick_Decorative"
    },
    {
      "x": -1,
      "y": 3,
      "z": -5,
      "name": "Rock_Aqua_Brick_Smooth"
    },
    {
      "x": -1,
      "y": 4,
      "z": -5,
      "name": "Rock_Aqua_Brick_Smooth"
    },
    {
      "x": -1,
      "y": 5,
      "z": -5,
      "name": "Rock_Aqua_Brick_Smooth"
    },
    {
      "x": -1,
      "y": 6,
      "z": -5,
      "name": "Rock_Aqua_Brick_Ornate"
    },
    {
      "x": -1,
      "y": 7,
      "z": -5,
      "name": "Rock_Aqua_Brick_Decorative"
    },
    {
      "x": -1,
      "y": 8,
      "z": -5,
      "name": "Rock_Aqua_Brick_Smooth"
    },
    {
      "x": -1,
      "y": 9,
      "z": -5,
      "name": "Rock_Aqua_Brick_Smooth"
    },
    {
      "x": -1,
      "y": 10,
      "z": -5,
      "name": "Rock_Aqua_Brick_Stairs",
      "rotation": 2
    },
    {
      "x": -1,
      "y": 11,
      "z": -5,
      "name": "Rock_Aqua_Brick_Smooth"
    },
    {
      "x": -1,
      "y": 12,
      "z": -5,
      "name": "Rock_Aqua_Brick_Smooth_Half",
      "rotation": 7
    },
    {
      "x": -1,
      "y": 0,
      "z": -4,
      "name": "Rock_Aqua"
    },
    {
      "x": -1,
      "y": 1,
      "z": -4,
      "name": "Rock_Runic_Brick"
    },
    {
      "x": -1,
      "y": 3,
      "z": -4,
      "name": "Rock_Runic_Blue_Brick"
    },
    {
      "x": -1,
      "y": 11,
      "z": -4,
      "name": "Rock_Runic_Teal_Brick_Stairs",
      "rotation": 10
    },
    {
      "x": -1,
      "y": 0,
      "z": -3,
      "name": "Rock_Aqua"
    },
    {
      "x": -1,
      "y": 1,
      "z": -3,
      "name": "*Rock_Runic_Brick_Half_State_Definitions_Block",
      "rotation": 5
    },
    {
      "x": -1,
      "y": 2,
      "z": -3,
      "name": "Rock_Runic_Blue_Brick_Stairs",
      "rotation": 11
    },
    {
      "x": -1,
      "y": 3,
      "z": -3,
      "name": "Rock_Runic_Blue_Brick"
    },
    {
      "x": -1,
      "y": 4,
      "z": -3,
      "name": "Cloth_Roof_Blue_Flat"
    },
    {
      "x": -1,
      "y": 11,
      "z": -3,
      "name": "Rock_Runic_Teal_Brick_Half",
      "rotation": 8
    },
    {
      "x": -1,
      "y": 0,
      "z": -2,
      "name": "Rock_Aqua"
    },
    {
      "x": -1,
      "y": 1,
      "z": -2,
      "name": "*Rock_Runic_Brick_Half_State_Definitions_Block",
      "rotation": 5
    },
    {
      "x": -1,
      "y": 2,
      "z": -2,
      "name": "Rock_Runic_Blue_Brick"
    },
    {
      "x": -1,
      "y": 3,
      "z": -2,
      "name": "Rock_Runic_Blue_Brick_Stairs"
    },
    {
      "x": -1,
      "y": 7,
      "z": -2,
      "name": "Rock_Runic_Blue_Brick_Half",
      "rotation": 6
    },
    {
      "x": -1,
      "y": 11,
      "z": -2,
      "name": "Rock_Runic_Teal_Brick_Half",
      "rotation": 8
    },
    {
      "x": -1,
      "y": 0,
      "z": -1,
      "name": "Rock_Aqua"
    },
    {
      "x": -1,
      "y": 1,
      "z": -1,
      "name": "*Rock_Runic_Brick_Half_State_Definitions_Block",
      "rotation": 5
    },
    {
      "x": -1,
      "y": 2,
      "z": -1,
      "name": "Rock_Runic_Blue_Brick_Stairs"
    },
    {
      "x": -1,
      "y": 6,
      "z": -1,
      "name": "Rock_Runic_Blue_Brick_Stairs",
      "rotation": 9
    },
    {
      "x": -1,
      "y": 7,
      "z": -1,
      "name": "Rock_Runic_Blue_Brick_Stairs",
      "rotation": 1
    },
    {
      "x": -1,
      "y": 11,
      "z": -1,
      "name": "Rock_Runic_Teal_Brick_Half",
      "rotation": 8
    },
    {
      "x": -1,
      "y": 0,
      "z": 0,
      "name": "Rock_Aqua"
    },
    {
      "x": -1,
      "y": 1,
      "z": 0,
      "name": "Rock_Runic_Brick"
    },
    {
      "x": -1,
      "y": 6,
      "z": 0,
      "name": "Rock_Runic_Blue_Brick_Stairs",
      "rotation": 9
    },
    {
      "x": -1,
      "y": 7,
      "z": 0,
      "name": "Rock_Runic_Blue_Brick_Stairs",
      "rotation": 1
    },
    {
      "x": -1,
      "y": 11,
      "z": 0,
      "name": "Rock_Runic_Teal_Brick_Stairs",
      "rotation": 8
    },
    {
      "x": -1,
      "y": 0,
      "z": 1,
      "name": "Rock_Aqua"
    },
    {
      "x": -1,
      "y": 1,
      "z": 1,
      "name": "*Rock_Runic_Brick_Half_State_Definitions_Block",
      "rotation": 7
    },
    {
      "x": -1,
      "y": 5,
      "z": 1,
      "name": "Rock_Aqua_Brick_Smooth"
    },
    {
      "x": -1,
      "y": 6,
      "z": 1,
      "name": "Rock_Aqua_Brick_Ornate"
    },
    {
      "x": -1,
      "y": 7,
      "z": 1,
      "name": "Rock_Aqua_Brick_Decorative"
    },
    {
      "x": -1,
      "y": 8,
      "z": 1,
      "name": "Rock_Aqua_Brick_Smooth"
    },
    {
      "x": -1,
      "y": 9,
      "z": 1,
      "name": "Rock_Aqua_Brick_Smooth"
    },
    {
      "x": -1,
      "y": 10,
      "z": 1,
      "name": "Rock_Aqua_Brick_Smooth"
    },
    {
      "x": -1,
      "y": 11,
      "z": 1,
      "name": "Rock_Aqua_Brick_Stairs",
      "rotation": 10
    },
    {
      "x": -1,
      "y": 12,
      "z": 1,
      "name": "Rock_Aqua_Brick_Smooth"
    },
    {
      "x": -1,
      "y": 13,
      "z": 1,
      "name": "Furniture_Human_Ruins_Lantern"
    },
    {
      "x": -1,
      "y": 0,
      "z": 2,
      "name": "Rock_Aqua"
    },
    {
      "x": -1,
      "y": 1,
      "z": 2,
      "name": "*Rock_Runic_Brick_Half_State_Definitions_Block",
      "rotation": 7
    },
    {
      "x": -1,
      "y": 5,
      "z": 2,
      "name": "Soil_Clay_Cyan"
    },
    {
      "x": -1,
      "y": 6,
      "z": 2,
      "name": "Rock_Aqua"
    },
    {
      "x": -1,
      "y": 7,
      "z": 2,
      "name": "Rubble_Aqua",
      "support": 15
    },
    {
      "x": -1,
      "y": 9,
      "z": 2,
      "name": "Plant_Moss_Wall_Blue",
      "support": 15
    },
    {
      "x": -1,
      "y": 0,
      "z": 3,
      "name": "Rock_Aqua"
    },
    {
      "x": -1,
      "y": 1,
      "z": 3,
      "name": "*Rock_Runic_Brick_Half_State_Definitions_Block",
      "rotation": 7
    },
    {
      "x": -1,
      "y": 5,
      "z": 3,
      "name": "Soil_Clay_Cyan"
    },
    {
      "x": -1,
      "y": 6,
      "z": 3,
      "name": "Plant_Moss_Block_Blue",
      "support": 15
    },
    {
      "x": -1,
      "y": 0,
      "z": 4,
      "name": "Rock_Aqua"
    },
    {
      "x": -1,
      "y": 1,
      "z": 4,
      "name": "Rock_Runic_Brick"
    },
    {
      "x": -1,
      "y": 2,
      "z": 4,
      "name": "Deco_Bone_Skulls"
    },
    {
      "x": -1,
      "y": 3,
      "z": 4,
      "name": "Empty"
    },
    {
      "x": -1,
      "y": 4,
      "z": 4,
      "name": "Empty"
    },
    {
      "x": -1,
      "y": 5,
      "z": 4,
      "name": "Soil_Clay_Cyan"
    },
    {
      "x": -1,
      "y": 6,
      "z": 4,
      "name": "Rock_Aqua"
    },
    {
      "x": -1,
      "y": 0,
      "z": 5,
      "name": "Rock_Aqua"
    },
    {
      "x": -1,
      "y": 1,
      "z": 5,
      "name": "Rock_Runic_Brick"
    },
    {
      "x": -1,
      "y": 2,
      "z": 5,
      "name": "Rock_Aqua_Brick_Decorative"
    },
    {
      "x": -1,
      "y": 3,
      "z": 5,
      "name": "Rock_Aqua_Brick_Smooth"
    },
    {
      "x": -1,
      "y": 4,
      "z": 5,
      "name": "Rock_Aqua_Brick_Smooth"
    },
    {
      "x": -1,
      "y": 5,
      "z": 5,
      "name": "Rock_Aqua_Brick_Smooth"
    },
    {
      "x": -1,
      "y": 6,
      "z": 5,
      "name": "Rock_Aqua"
    },
    {
      "x": -1,
      "y": 1,
      "z": 6,
      "name": "Rock_Aqua"
    },
    {
      "x": -1,
      "y": 2,
      "z": 6,
      "name": "Rock_Aqua"
    },
    {
      "x": -1,
      "y": 3,
      "z": 6,
      "name": "Rock_Aqua"
    },
    {
      "x": -1,
      "y": 4,
      "z": 6,
      "name": "Rock_Aqua"
    },
    {
      "x": -1,
      "y": 5,
      "z": 6,
      "name": "Rock_Aqua"
    },
    {
      "x": -1,
      "y": 6,
      "z": 6,
      "name": "Rock_Aqua"
    },
    {
      "x": -1,
      "y": 3,
      "z": 7,
      "name": "Rock_Aqua"
    },
    {
      "x": -1,
      "y": 4,
      "z": 7,
      "name": "Rock_Aqua"
    },
    {
      "x": 0,
      "y": 2,
      "z": -7,
      "name": "Rock_Aqua"
    },
    {
      "x": 0,
      "y": 3,
      "z": -7,
      "name": "Rock_Aqua"
    },
    {
      "x": 0,
      "y": 4,
      "z": -7,
      "name": "Rock_Aqua"
    },
    {
      "x": 0,
      "y": 1,
      "z": -6,
      "name": "Rock_Aqua"
    },
    {
      "x": 0,
      "y": 2,
      "z": -6,
      "name": "Rock_Aqua"
    },
    {
      "x": 0,
      "y": 3,
      "z": -6,
      "name": "Rock_Aqua"
    },
    {
      "x": 0,
      "y": 4,
      "z": -6,
      "name": "Rock_Aqua"
    },
    {
      "x": 0,
      "y": 0,
      "z": -5,
      "name": "Rock_Aqua"
    },
    {
      "x": 0,
      "y": 1,
      "z": -5,
      "name": "Rock_Runic_Brick"
    },
    {
      "x": 0,
      "y": 2,
      "z": -5,
      "name": "Rock_Aqua_Brick_Decorative"
    },
    {
      "x": 0,
      "y": 3,
      "z": -5,
      "name": "Rock_Aqua_Brick_Smooth"
    },
    {
      "x": 0,
      "y": 4,
      "z": -5,
      "name": "Rock_Aqua_Brick_Smooth"
    },
    {
      "x": 0,
      "y": 5,
      "z": -5,
      "name": "Rock_Aqua_Brick_Smooth"
    },
    {
      "x": 0,
      "y": 6,
      "z": -5,
      "name": "Rock_Aqua_Brick_Ornate"
    },
    {
      "x": 0,
      "y": 9,
      "z": -5,
      "name": "Rock_Aqua_Brick_Stairs",
      "rotation": 8
    },
    {
      "x": 0,
      "y": 10,
      "z": -5,
      "name": "Rock_Aqua_Brick_Smooth"
    },
    {
      "x": 0,
      "y": 11,
      "z": -5,
      "name": "Rock_Aqua_Brick_Smooth"
    },
    {
      "x": 0,
      "y": 12,
      "z": -5,
      "name": "Rock_Aqua_Brick_Wall"
    },
    {
      "x": 0,
      "y": 0,
      "z": -4,
      "name": "Rock_Aqua"
    },
    {
      "x": 0,
      "y": 1,
      "z": -4,
      "name": "Rock_Runic_Brick"
    },
    {
      "x": 0,
      "y": 3,
      "z": -4,
      "name": "Rock_Runic_Blue_Brick"
    },
    {
      "x": 0,
      "y": 4,
      "z": -4,
      "name": "Rock_Runic_Blue_Brick_Stairs",
      "rotation": 3
    },
    {
      "x": 0,
      "y": 5,
      "z": -4,
      "name": "*Furniture_Temple_Dark_Trapdoor_State_Definitions_OpenDoorOut"
    },
    {
      "x": 0,
      "y": 10,
      "z": -4,
      "name": "*Furniture_Temple_Dark_Trapdoor_State_Definitions_OpenDoorOut"
    },
    {
      "x": 0,
      "y": 11,
      "z": -4,
      "name": "Rock_Runic_Teal_Brick_Half",
      "rotation": 8
    },
    {
      "x": 0,
      "y": 12,
      "z": -4,
      "name": "Rubble_Aqua_Medium",
      "support": 15
    },
    {
      "x": 0,
      "y": 0,
      "z": -3,
      "name": "Rock_Aqua"
    },
    {
      "x": 0,
      "y": 1,
      "z": -3,
      "name": "*Rock_Runic_Brick_Half_State_Definitions_Block",
      "rotation": 5
    },
    {
      "x": 0,
      "y": 3,
      "z": -3,
      "name": "Rock_Runic_Blue_Brick"
    },
    {
      "x": 0,
      "y": 4,
      "z": -3,
      "name": "Rock_Runic_Blue_Brick_Stairs",
      "rotation": 3
    },
    {
      "x": 0,
      "y": 11,
      "z": -3,
      "name": "Rock_Runic_Teal_Brick_Half",
      "rotation": 8
    },
    {
      "x": 0,
      "y": 0,
      "z": -2,
      "name": "Rock_Aqua"
    },
    {
      "x": 0,
      "y": 1,
      "z": -2,
      "name": "*Rock_Runic_Brick_Half_State_Definitions_Block",
      "rotation": 5
    },
    {
      "x": 0,
      "y": 2,
      "z": -2,
      "name": "Rock_Runic_Teal_Brick_Pillar_Base"
    },
    {
      "x": 0,
      "y": 3,
      "z": -2,
      "name": "Rock_Runic_Teal_Brick_Pillar_Base",
      "rotation": 8
    },
    {
      "x": 0,
      "y": 4,
      "z": -2,
      "name": "Rock_Runic_Teal_Brick_Pillar_Base"
    },
    {
      "x": 0,
      "y": 5,
      "z": -2,
      "name": "Rock_Runic_Teal_Brick_Pillar_Base",
      "rotation": 8
    },
    {
      "x": 0,
      "y": 6,
      "z": -2,
      "name": "Rock_Runic_Teal_Brick_Pillar_Base"
    },
    {
      "x": 0,
      "y": 7,
      "z": -2,
      "name": "Rock_Runic_Teal_Brick_Pillar_Base",
      "rotation": 8
    },
    {
      "x": 0,
      "y": 8,
      "z": -2,
      "name": "Rock_Runic_Teal_Brick_Pillar_Base"
    },
    {
      "x": 0,
      "y": 9,
      "z": -2,
      "name": "Rock_Runic_Teal_Brick_Pillar_Base",
      "rotation": 8
    },
    {
      "x": 0,
      "y": 10,
      "z": -2,
      "name": "Rock_Runic_Teal_Brick_Pillar_Base"
    },
    {
      "x": 0,
      "y": 11,
      "z": -2,
      "name": "Rock_Runic_Teal_Brick_Pillar_Base",
      "rotation": 8
    },
    {
      "x": 0,
      "y": 0,
      "z": -1,
      "name": "Rock_Aqua"
    },
    {
      "x": 0,
      "y": 1,
      "z": -1,
      "name": "*Rock_Runic_Brick_Half_State_Definitions_Block",
      "rotation": 5
    },
    {
      "x": 0,
      "y": 2,
      "z": -1,
      "name": "Rock_Crystal_Cyan_Small"
    },
    {
      "x": 0,
      "y": 5,
      "z": -1,
      "name": "Rock_Runic_Blue_Brick_Stairs",
      "rotation": 10
    },
    {
      "x": 0,
      "y": 6,
      "z": -1,
      "name": "Rock_Runic_Blue_Brick"
    },
    {
      "x": 0,
      "y": 7,
      "z": -1,
      "name": "Cloth_Roof_Blue_Flat"
    },
    {
      "x": 0,
      "y": 11,
      "z": -1,
      "name": "Rock_Runic_Teal_Brick_Half",
      "rotation": 8
    },
    {
      "x": 0,
      "y": 12,
      "z": -1,
      "name": "Plant_Seaweed_Winter_Aurora",
      "support": 15
    },
    {
      "x": 0,
      "y": 13,
      "z": -1,
      "name": "Plant_Seaweed_Winter_Aurora",
      "filler": 1024
    },
    {
      "x": 0,
      "y": 0,
      "z": 0,
      "name": "Rock_Aqua"
    },
    {
      "x": 0,
      "y": 1,
      "z": 0,
      "name": "Rock_Runic_Brick"
    },
    {
      "x": 0,
      "y": 2,
      "z": 0,
      "name": "Plant_Coral_Model_Cyan"
    },
    {
      "x": 0,
      "y": 5,
      "z": 0,
      "name": "*Furniture_Temple_Dark_Trapdoor_State_Definitions_OpenDoorOut",
      "rotation": 2
    },
    {
      "x": 0,
      "y": 6,
      "z": 0,
      "name": "Rock_Runic_Blue_Brick"
    },
    {
      "x": 0,
      "y": 10,
      "z": 0,
      "name": "*Furniture_Temple_Dark_Trapdoor_State_Definitions_OpenDoorOut",
      "rotation": 2
    },
    {
      "x": 0,
      "y": 11,
      "z": 0,
      "name": "Rock_Runic_Teal_Brick_Half",
      "rotation": 8
    },
    {
      "x": 0,
      "y": 12,
      "z": 0,
      "name": "Plant_Coral_Bush_Poisoned"
    },
    {
      "x": 0,
      "y": 0,
      "z": 1,
      "name": "Rock_Aqua"
    },
    {
      "x": 0,
      "y": 1,
      "z": 1,
      "name": "*Rock_Runic_Brick_Half_State_Definitions_Block",
      "rotation": 7
    },
    {
      "x": 0,
      "y": 2,
      "z": 1,
      "name": "Plant_Moss_Short_Blue",
      "support": 15
    },
    {
      "x": 0,
      "y": 4,
      "z": 1,
      "name": "Furniture_Temple_Dark_Trapdoor"
    },
    {
      "x": 0,
      "y": 5,
      "z": 1,
      "name": "Rock_Aqua_Brick_Smooth"
    },
    {
      "x": 0,
      "y": 6,
      "z": 1,
      "name": "Rock_Aqua_Brick_Ornate"
    },
    {
      "x": 0,
      "y": 9,
      "z": 1,
      "name": "Rock_Aqua_Brick_Smooth"
    },
    {
      "x": 0,
      "y": 10,
      "z": 1,
      "name": "Rock_Aqua_Brick_Smooth"
    },
    {
      "x": 0,
      "y": 11,
      "z": 1,
      "name": "Rock_Aqua_Brick_Smooth"
    },
    {
      "x": 0,
      "y": 12,
      "z": 1,
      "name": "Rock_Aqua_Brick_Wall"
    },
    {
      "x": 0,
      "y": 0,
      "z": 2,
      "name": "Rock_Aqua"
    },
    {
      "x": 0,
      "y": 1,
      "z": 2,
      "name": "*Rock_Runic_Brick_Half_State_Definitions_Block",
      "rotation": 7
    },
    {
      "x": 0,
      "y": 2,
      "z": 2,
      "name": "Plant_Moss_Short_Blue",
      "support": 15
    },
    {
      "x": 0,
      "y": 5,
      "z": 2,
      "name": "Soil_Clay_Cyan"
    },
    {
      "x": 0,
      "y": 6,
      "z": 2,
      "name": "Plant_Moss_Block_Blue",
      "support": 15
    },
    {
      "x": 0,
      "y": 0,
      "z": 3,
      "name": "Rock_Aqua"
    },
    {
      "x": 0,
      "y": 1,
      "z": 3,
      "name": "*Rock_Runic_Brick_Half_State_Definitions_Block",
      "rotation": 7
    },
    {
      "x": 0,
      "y": 5,
      "z": 3,
      "name": "Soil_Clay_Cyan"
    },
    {
      "x": 0,
      "y": 6,
      "z": 3,
      "name": "Rock_Aqua"
    },
    {
      "x": 0,
      "y": 7,
      "z": 3,
      "name": "Plant_Moss_Short_Blue",
      "support": 15
    },
    {
      "x": 0,
      "y": 0,
      "z": 4,
      "name": "Rock_Aqua"
    },
    {
      "x": 0,
      "y": 1,
      "z": 4,
      "name": "Rock_Runic_Brick"
    },
    {
      "x": 0,
      "y": 2,
      "z": 4,
      "name": "Block_Spawner_Block",
      "components": {
        "Components": {
          "PlacedByInteraction": {
            "WhoPlacedUuid": {
              "$binary": "ownTYu6PR7ebL9OJmdXyVA==",
              "$type": "04"
            }
          },
          "BlockSpawner": {
            "BlockSpawnerId": "The_Aqua_Subterrain_Tier1"
          }
        }
      },
      "rotation": 2
    },
    {
      "x": 0,
      "y": 5,
      "z": 4,
      "name": "Soil_Clay_Cyan"
    },
    {
      "x": 0,
      "y": 6,
      "z": 4,
      "name": "Rock_Aqua"
    },
    {
      "x": 0,
      "y": 7,
      "z": 4,
      "name": "Rock_Aqua_Brick_Decorative"
    },
    {
      "x": 0,
      "y": 0,
      "z": 5,
      "name": "Rock_Aqua"
    },
    {
      "x": 0,
      "y": 1,
      "z": 5,
      "name": "Rock_Runic_Brick"
    },
    {
      "x": 0,
      "y": 2,
      "z": 5,
      "name": "Rock_Aqua_Brick_Decorative"
    },
    {
      "x": 0,
      "y": 3,
      "z": 5,
      "name": "Rock_Aqua_Brick_Stairs",
      "rotation": 2
    },
    {
      "x": 0,
      "y": 4,
      "z": 5,
      "name": "Rock_Aqua_Brick_Smooth"
    },
    {
      "x": 0,
      "y": 5,
      "z": 5,
      "name": "Rock_Aqua_Brick_Smooth"
    },
    {
      "x": 0,
      "y": 6,
      "z": 5,
      "name": "Rock_Aqua"
    },
    {
      "x": 0,
      "y": 7,
      "z": 5,
      "name": "Plant_Moss_Rug_Blue",
      "support": 15
    },
    {
      "x": 0,
      "y": 0,
      "z": 6,
      "name": "Rock_Aqua"
    },
    {
      "x": 0,
      "y": 1,
      "z": 6,
      "name": "Rock_Aqua"
    },
    {
      "x": 0,
      "y": 2,
      "z": 6,
      "name": "Rock_Aqua"
    },
    {
      "x": 0,
      "y": 3,
      "z": 6,
      "name": "Rock_Aqua"
    },
    {
      "x": 0,
      "y": 4,
      "z": 6,
      "name": "Rock_Aqua"
    },
    {
      "x": 0,
      "y": 5,
      "z": 6,
      "name": "Rock_Aqua"
    },
    {
      "x": 0,
      "y": 6,
      "z": 6,
      "name": "Rock_Aqua"
    },
    {
      "x": 0,
      "y": 2,
      "z": 7,
      "name": "Rock_Aqua"
    },
    {
      "x": 0,
      "y": 3,
      "z": 7,
      "name": "Rock_Aqua"
    },
    {
      "x": 0,
      "y": 4,
      "z": 7,
      "name": "Rock_Aqua"
    },
    {
      "x": 0,
      "y": 5,
      "z": 7,
      "name": "Rock_Aqua"
    },
    {
      "x": 0,
      "y": 6,
      "z": 7,
      "name": "Rock_Aqua"
    },
    {
      "x": 1,
      "y": 2,
      "z": -7,
      "name": "Rock_Aqua"
    },
    {
      "x": 1,
      "y": 3,
      "z": -7,
      "name": "Rock_Aqua"
    },
    {
      "x": 1,
      "y": 4,
      "z": -7,
      "name": "Rock_Aqua"
    },
    {
      "x": 1,
      "y": 5,
      "z": -7,
      "name": "Rock_Aqua"
    },
    {
      "x": 1,
      "y": 1,
      "z": -6,
      "name": "Rock_Aqua"
    },
    {
      "x": 1,
      "y": 2,
      "z": -6,
      "name": "Rock_Aqua"
    },
    {
      "x": 1,
      "y": 3,
      "z": -6,
      "name": "Rock_Aqua"
    },
    {
      "x": 1,
      "y": 4,
      "z": -6,
      "name": "Rock_Aqua"
    },
    {
      "x": 1,
      "y": 5,
      "z": -6,
      "name": "Rock_Aqua"
    },
    {
      "x": 1,
      "y": 6,
      "z": -6,
      "name": "Rock_Aqua"
    },
    {
      "x": 1,
      "y": 0,
      "z": -5,
      "name": "Rock_Aqua"
    },
    {
      "x": 1,
      "y": 1,
      "z": -5,
      "name": "Rock_Runic_Brick"
    },
    {
      "x": 1,
      "y": 2,
      "z": -5,
      "name": "Rock_Aqua_Brick_Decorative"
    },
    {
      "x": 1,
      "y": 3,
      "z": -5,
      "name": "Rock_Aqua_Brick_Smooth"
    },
    {
      "x": 1,
      "y": 4,
      "z": -5,
      "name": "Rock_Aqua_Brick_Smooth"
    },
    {
      "x": 1,
      "y": 5,
      "z": -5,
      "name": "Rock_Aqua_Brick_Smooth"
    },
    {
      "x": 1,
      "y": 6,
      "z": -5,
      "name": "Rock_Aqua_Brick_Ornate"
    },
    {
      "x": 1,
      "y": 7,
      "z": -5,
      "name": "Rock_Aqua_Brick_Decorative"
    },
    {
      "x": 1,
      "y": 8,
      "z": -5,
      "name": "Rock_Aqua_Brick_Stairs",
      "rotation": 2
    },
    {
      "x": 1,
      "y": 9,
      "z": -5,
      "name": "Rock_Aqua_Brick_Smooth"
    },
    {
      "x": 1,
      "y": 10,
      "z": -5,
      "name": "Rock_Aqua_Brick_Smooth"
    },
    {
      "x": 1,
      "y": 11,
      "z": -5,
      "name": "Rock_Aqua_Brick_Stairs",
      "rotation": 2
    },
    {
      "x": 1,
      "y": 12,
      "z": -5,
      "name": "*Rock_Aqua_Brick_Wall_State_Definitions_Corner"
    },
    {
      "x": 1,
      "y": 0,
      "z": -4,
      "name": "Rock_Aqua"
    },
    {
      "x": 1,
      "y": 1,
      "z": -4,
      "name": "Rock_Runic_Brick"
    },
    {
      "x": 1,
      "y": 2,
      "z": -4,
      "name": "Plant_Leaves_Camphor",
      "support": 15
    },
    {
      "x": 1,
      "y": 3,
      "z": -4,
      "name": "Rock_Runic_Blue_Brick_Stairs",
      "rotation": 11
    },
    {
      "x": 1,
      "y": 4,
      "z": -4,
      "name": "Rock_Runic_Blue_Brick"
    },
    {
      "x": 1,
      "y": 11,
      "z": -4,
      "name": "Rock_Runic_Teal_Brick_Stairs",
      "rotation": 10
    },
    {
      "x": 1,
      "y": 12,
      "z": -4,
      "name": "*Rock_Aqua_Brick_Wall_State_Definitions_Corner",
      "rotation": 2
    },
    {
      "x": 1,
      "y": 0,
      "z": -3,
      "name": "Rock_Aqua"
    },
    {
      "x": 1,
      "y": 1,
      "z": -3,
      "name": "*Rock_Runic_Brick_Half_State_Definitions_Block",
      "rotation": 5
    },
    {
      "x": 1,
      "y": 3,
      "z": -3,
      "name": "Rock_Runic_Blue_Brick_Stairs",
      "rotation": 11
    },
    {
      "x": 1,
      "y": 4,
      "z": -3,
      "name": "Rock_Runic_Blue_Brick"
    },
    {
      "x": 1,
      "y": 11,
      "z": -3,
      "name": "Rock_Runic_Teal_Brick_Half",
      "rotation": 8
    },
    {
      "x": 1,
      "y": 0,
      "z": -2,
      "name": "Rock_Aqua"
    },
    {
      "x": 1,
      "y": 1,
      "z": -2,
      "name": "*Rock_Runic_Brick_Half_State_Definitions_Block",
      "rotation": 5
    },
    {
      "x": 1,
      "y": 2,
      "z": -2,
      "name": "Plant_Coral_Bush_Cyan"
    },
    {
      "x": 1,
      "y": 4,
      "z": -2,
      "name": "Rock_Runic_Blue_Brick"
    },
    {
      "x": 1,
      "y": 5,
      "z": -2,
      "name": "Rock_Runic_Blue_Brick_Stairs",
      "rotation": 2
    },
    {
      "x": 1,
      "y": 11,
      "z": -2,
      "name": "Rock_Runic_Teal_Brick_Half",
      "rotation": 8
    },
    {
      "x": 1,
      "y": 0,
      "z": -1,
      "name": "Rock_Aqua"
    },
    {
      "x": 1,
      "y": 1,
      "z": -1,
      "name": "*Rock_Runic_Brick_Half_State_Definitions_Block",
      "rotation": 5
    },
    {
      "x": 1,
      "y": 4,
      "z": -1,
      "name": "Rock_Runic_Blue_Brick_Stairs",
      "rotation": 10
    },
    {
      "x": 1,
      "y": 5,
      "z": -1,
      "name": "Rock_Runic_Blue_Brick"
    },
    {
      "x": 1,
      "y": 6,
      "z": -1,
      "name": "Rock_Runic_Blue_Brick_Stairs",
      "rotation": 2
    },
    {
      "x": 1,
      "y": 11,
      "z": -1,
      "name": "Rock_Runic_Teal_Brick_Half",
      "rotation": 8
    },
    {
      "x": 1,
      "y": 0,
      "z": 0,
      "name": "Rock_Aqua"
    },
    {
      "x": 1,
      "y": 1,
      "z": 0,
      "name": "Rock_Runic_Brick"
    },
    {
      "x": 1,
      "y": 2,
      "z": 0,
      "name": "Plant_Moss_Rug_Blue",
      "support": 15
    },
    {
      "x": 1,
      "y": 5,
      "z": 0,
      "name": "Rock_Runic_Blue_Brick_Stairs",
      "rotation": 10
    },
    {
      "x": 1,
      "y": 6,
      "z": 0,
      "name": "Rock_Runic_Blue_Brick"
    },
    {
      "x": 1,
      "y": 7,
      "z": 0,
      "name": "Cloth_Roof_Blue_Flat"
    },
    {
      "x": 1,
      "y": 9,
      "z": 0,
      "name": "Plant_Moss_Wall_Blue",
      "support": 15,
      "rotation": 2
    },
    {
      "x": 1,
      "y": 11,
      "z": 0,
      "name": "Rock_Runic_Teal_Brick_Stairs",
      "rotation": 8
    },
    {
      "x": 1,
      "y": 12,
      "z": 0,
      "name": "Plant_Crop_Mushroom_Glowing_Purple"
    },
    {
      "x": 1,
      "y": 0,
      "z": 1,
      "name": "Rock_Aqua"
    },
    {
      "x": 1,
      "y": 1,
      "z": 1,
      "name": "*Rock_Runic_Brick_Half_State_Definitions_Block",
      "rotation": 7
    },
    {
      "x": 1,
      "y": 2,
      "z": 1,
      "name": "Rubble_Chalk",
      "support": 15
    },
    {
      "x": 1,
      "y": 5,
      "z": 1,
      "name": "Rock_Aqua_Brick_Smooth"
    },
    {
      "x": 1,
      "y": 6,
      "z": 1,
      "name": "Rock_Aqua_Brick_Ornate"
    },
    {
      "x": 1,
      "y": 7,
      "z": 1,
      "name": "Rock_Aqua_Brick_Decorative"
    },
    {
      "x": 1,
      "y": 8,
      "z": 1,
      "name": "Rock_Aqua_Brick_Smooth"
    },
    {
      "x": 1,
      "y": 9,
      "z": 1,
      "name": "Rock_Aqua_Brick_Smooth"
    },
    {
      "x": 1,
      "y": 10,
      "z": 1,
      "name": "Rock_Aqua_Brick_Stairs"
    },
    {
      "x": 1,
      "y": 11,
      "z": 1,
      "name": "Rock_Aqua_Brick_Smooth"
    },
    {
      "x": 1,
      "y": 12,
      "z": 1,
      "name": "Rock_Aqua_Brick_Smooth"
    },
    {
      "x": 1,
      "y": 13,
      "z": 1,
      "name": "Rubble_Aqua",
      "support": 15
    },
    {
      "x": 1,
      "y": 0,
      "z": 2,
      "name": "Rock_Aqua"
    },
    {
      "x": 1,
      "y": 1,
      "z": 2,
      "name": "*Rock_Runic_Brick_Half_State_Definitions_Block",
      "rotation": 7
    },
    {
      "x": 1,
      "y": 5,
      "z": 2,
      "name": "Soil_Clay_Cyan"
    },
    {
      "x": 1,
      "y": 6,
      "z": 2,
      "name": "Rock_Aqua"
    },
    {
      "x": 1,
      "y": 7,
      "z": 2,
      "name": "Plant_Moss_Rug_Blue",
      "support": 15
    },
    {
      "x": 1,
      "y": 8,
      "z": 2,
      "name": "Plant_Moss_Wall_Blue",
      "support": 15
    },
    {
      "x": 1,
      "y": 0,
      "z": 3,
      "name": "Rock_Aqua"
    },
    {
      "x": 1,
      "y": 1,
      "z": 3,
      "name": "*Rock_Runic_Brick_Half_State_Definitions_Block",
      "rotation": 7
    },
    {
      "x": 1,
      "y": 5,
      "z": 3,
      "name": "Soil_Clay_Cyan"
    },
    {
      "x": 1,
      "y": 6,
      "z": 3,
      "name": "Rock_Aqua"
    },
    {
      "x": 1,
      "y": 0,
      "z": 4,
      "name": "Rock_Aqua"
    },
    {
      "x": 1,
      "y": 1,
      "z": 4,
      "name": "Rock_Runic_Brick"
    },
    {
      "x": 1,
      "y": 2,
      "z": 4,
      "name": "Rock_Crystal_Cyan_Small",
      "rotation": 6
    },
    {
      "x": 1,
      "y": 4,
      "z": 4,
      "name": "Plant_Leaves_Camphor",
      "support": 15
    },
    {
      "x": 1,
      "y": 5,
      "z": 4,
      "name": "Soil_Clay_Cyan"
    },
    {
      "x": 1,
      "y": 6,
      "z": 4,
      "name": "Rock_Aqua"
    },
    {
      "x": 1,
      "y": 7,
      "z": 4,
      "name": "Rock_Aqua_Brick_Decorative"
    },
    {
      "x": 1,
      "y": 8,
      "z": 4,
      "name": "Rock_Aqua_Brick_Smooth"
    },
    {
      "x": 1,
      "y": 0,
      "z": 5,
      "name": "Rock_Aqua"
    },
    {
      "x": 1,
      "y": 1,
      "z": 5,
      "name": "Rock_Runic_Brick"
    },
    {
      "x": 1,
      "y": 2,
      "z": 5,
      "name": "Rock_Aqua_Brick_Decorative"
    },
    {
      "x": 1,
      "y": 3,
      "z": 5,
      "name": "Rock_Aqua_Brick_Smooth"
    },
    {
      "x": 1,
      "y": 4,
      "z": 5,
      "name": "Rock_Aqua_Brick_Smooth"
    },
    {
      "x": 1,
      "y": 5,
      "z": 5,
      "name": "Rock_Aqua_Brick_Smooth"
    },
    {
      "x": 1,
      "y": 6,
      "z": 5,
      "name": "Rock_Aqua"
    },
    {
      "x": 1,
      "y": 7,
      "z": 5,
      "name": "Rock_Aqua_Brick_Stairs"
    },
    {
      "x": 1,
      "y": 0,
      "z": 6,
      "name": "Rock_Aqua"
    },
    {
      "x": 1,
      "y": 1,
      "z": 6,
      "name": "Rock_Aqua"
    },
    {
      "x": 1,
      "y": 2,
      "z": 6,
      "name": "Rock_Aqua"
    },
    {
      "x": 1,
      "y": 3,
      "z": 6,
      "name": "Rock_Aqua"
    },
    {
      "x": 1,
      "y": 4,
      "z": 6,
      "name": "Rock_Aqua"
    },
    {
      "x": 1,
      "y": 5,
      "z": 6,
      "name": "Rock_Aqua"
    },
    {
      "x": 1,
      "y": 6,
      "z": 6,
      "name": "Rock_Aqua"
    },
    {
      "x": 1,
      "y": 7,
      "z": 6,
      "name": "Rubble_Aqua_Medium",
      "support": 15
    },
    {
      "x": 1,
      "y": 2,
      "z": 7,
      "name": "Rock_Aqua"
    },
    {
      "x": 1,
      "y": 3,
      "z": 7,
      "name": "Rock_Aqua"
    },
    {
      "x": 1,
      "y": 4,
      "z": 7,
      "name": "Rock_Aqua"
    },
    {
      "x": 1,
      "y": 5,
      "z": 7,
      "name": "Rock_Aqua"
    },
    {
      "x": 1,
      "y": 6,
      "z": 7,
      "name": "Rock_Aqua"
    },
    {
      "x": 2,
      "y": 3,
      "z": -7,
      "name": "Rock_Aqua"
    },
    {
      "x": 2,
      "y": 4,
      "z": -7,
      "name": "Rock_Aqua"
    },
    {
      "x": 2,
      "y": 5,
      "z": -7,
      "name": "Rock_Aqua"
    },
    {
      "x": 2,
      "y": 1,
      "z": -6,
      "name": "Rock_Aqua"
    },
    {
      "x": 2,
      "y": 2,
      "z": -6,
      "name": "Rock_Aqua"
    },
    {
      "x": 2,
      "y": 3,
      "z": -6,
      "name": "Rock_Aqua"
    },
    {
      "x": 2,
      "y": 4,
      "z": -6,
      "name": "Rock_Aqua"
    },
    {
      "x": 2,
      "y": 5,
      "z": -6,
      "name": "Rock_Aqua"
    },
    {
      "x": 2,
      "y": 6,
      "z": -6,
      "name": "Rock_Aqua"
    },
    {
      "x": 2,
      "y": 7,
      "z": -6,
      "name": "Rubble_Aqua_Medium",
      "support": 15
    },
    {
      "x": 2,
      "y": 1,
      "z": -5,
      "name": "Rock_Aqua"
    },
    {
      "x": 2,
      "y": 2,
      "z": -5,
      "name": "Rock_Aqua"
    },
    {
      "x": 2,
      "y": 3,
      "z": -5,
      "name": "Rock_Aqua"
    },
    {
      "x": 2,
      "y": 4,
      "z": -5,
      "name": "Rock_Aqua"
    },
    {
      "x": 2,
      "y": 5,
      "z": -5,
      "name": "Rock_Aqua"
    },
    {
      "x": 2,
      "y": 6,
      "z": -5,
      "name": "Rock_Aqua"
    },
    {
      "x": 2,
      "y": 7,
      "z": -5,
      "name": "Rock_Aqua_Brick_Wall"
    },
    {
      "x": 2,
      "y": 9,
      "z": -5,
      "name": "Rock_Aqua_Brick_Smooth_Half",
      "rotation": 6
    },
    {
      "x": 2,
      "y": 0,
      "z": -4,
      "name": "Rock_Aqua"
    },
    {
      "x": 2,
      "y": 1,
      "z": -4,
      "name": "Rock_Runic_Brick"
    },
    {
      "x": 2,
      "y": 2,
      "z": -4,
      "name": "Rock_Aqua_Brick_Decorative"
    },
    {
      "x": 2,
      "y": 3,
      "z": -4,
      "name": "Rock_Aqua_Brick_Smooth"
    },
    {
      "x": 2,
      "y": 4,
      "z": -4,
      "name": "Rock_Aqua_Brick_Smooth"
    },
    {
      "x": 2,
      "y": 5,
      "z": -4,
      "name": "Rock_Aqua_Brick_Stairs",
      "rotation": 3
    },
    {
      "x": 2,
      "y": 6,
      "z": -4,
      "name": "Rock_Aqua_Brick_Ornate"
    },
    {
      "x": 2,
      "y": 7,
      "z": -4,
      "name": "Rock_Aqua_Brick_Decorative"
    },
    {
      "x": 2,
      "y": 8,
      "z": -4,
      "name": "Rock_Aqua_Brick_Smooth"
    },
    {
      "x": 2,
      "y": 9,
      "z": -4,
      "name": "Rock_Aqua_Brick_Smooth"
    },
    {
      "x": 2,
      "y": 10,
      "z": -4,
      "name": "Rock_Aqua_Brick_Smooth"
    },
    {
      "x": 2,
      "y": 11,
      "z": -4,
      "name": "Rock_Aqua_Brick_Smooth"
    },
    {
      "x": 2,
      "y": 12,
      "z": -4,
      "name": "Rock_Aqua_Brick_Wall"
    },
    {
      "x": 2,
      "y": 0,
      "z": -3,
      "name": "Rock_Aqua"
    },
    {
      "x": 2,
      "y": 1,
      "z": -3,
      "name": "Rock_Runic_Brick"
    },
    {
      "x": 2,
      "y": 4,
      "z": -3,
      "name": "Rock_Runic_Blue_Brick"
    },
    {
      "x": 2,
      "y": 5,
      "z": -3,
      "name": "Cloth_Roof_Blue_Flat"
    },
    {
      "x": 2,
      "y": 10,
      "z": -3,
      "name": "Plant_Leaves_Camphor",
      "support": 15
    },
    {
      "x": 2,
      "y": 11,
      "z": -3,
      "name": "Rock_Runic_Teal_Brick_Stairs",
      "rotation": 9
    },
    {
      "x": 2,
      "y": 12,
      "z": -3,
      "name": "Plant_Seaweed_Winter_Aurora",
      "support": 15
    },
    {
      "x": 2,
      "y": 13,
      "z": -3,
      "name": "Plant_Seaweed_Winter_Aurora",
      "filler": 1024
    },
    {
      "x": 2,
      "y": 0,
      "z": -2,
      "name": "Rock_Aqua"
    },
    {
      "x": 2,
      "y": 1,
      "z": -2,
      "name": "Rock_Runic_Brick"
    },
    {
      "x": 2,
      "y": 2,
      "z": -2,
      "name": "Plant_Crop_Mushroom_Flatcap_Green",
      "components": {
        "Components": {
          "FarmingBlock": {
            "LastTickGameTime": "0001-01-01T12:00:00Z"
          }
        }
      }
    },
    {
      "x": 2,
      "y": 4,
      "z": -2,
      "name": "Rock_Runic_Blue_Brick"
    },
    {
      "x": 2,
      "y": 5,
      "z": -2,
      "name": "Rock_Runic_Blue_Brick_Stairs",
      "rotation": 2
    },
    {
      "x": 2,
      "y": 10,
      "z": -2,
      "name": "*Furniture_Temple_Dark_Trapdoor_State_Definitions_OpenDoorOut",
      "rotation": 3
    },
    {
      "x": 2,
      "y": 11,
      "z": -2,
      "name": "Rock_Runic_Teal_Brick_Half",
      "rotation": 8
    },
    {
      "x": 2,
      "y": 0,
      "z": -1,
      "name": "Rock_Aqua"
    },
    {
      "x": 2,
      "y": 1,
      "z": -1,
      "name": "Rock_Runic_Brick"
    },
    {
      "x": 2,
      "y": 2,
      "z": -1,
      "name": "Plant_Moss_Rug_Blue",
      "support": 15
    },
    {
      "x": 2,
      "y": 3,
      "z": -1,
      "name": "Plant_Vine_Wall_Dead",
      "support": 15,
      "rotation": 3
    },
    {
      "x": 2,
      "y": 4,
      "z": -1,
      "name": "Rock_Runic_Blue_Brick_Stairs",
      "rotation": 10
    },
    {
      "x": 2,
      "y": 5,
      "z": -1,
      "name": "Rock_Runic_Blue_Brick"
    },
    {
      "x": 2,
      "y": 6,
      "z": -1,
      "name": "Rock_Runic_Blue_Brick_Stairs",
      "rotation": 2
    },
    {
      "x": 2,
      "y": 8,
      "z": -1,
      "name": "Plant_Moss_Wall_Blue",
      "support": 15,
      "rotation": 3
    },
    {
      "x": 2,
      "y": 11,
      "z": -1,
      "name": "Rock_Runic_Teal_Brick_Stairs",
      "rotation": 9
    },
    {
      "x": 2,
      "y": 12,
      "z": -1,
      "name": "Plant_Coral_Bush_Poisoned"
    },
    {
      "x": 2,
      "y": 0,
      "z": 0,
      "name": "Rock_Aqua"
    },
    {
      "x": 2,
      "y": 1,
      "z": 0,
      "name": "Rock_Runic_Brick"
    },
    {
      "x": 2,
      "y": 2,
      "z": 0,
      "name": "Rock_Runic_Dark_Brick_Pillar_Base"
    },
    {
      "x": 2,
      "y": 3,
      "z": 0,
      "name": "Rock_Calcite_Brick_Pillar_Middle"
    },
    {
      "x": 2,
      "y": 4,
      "z": 0,
      "name": "Rock_Runic_Dark_Brick_Pillar_Base",
      "rotation": 8
    },
    {
      "x": 2,
      "y": 5,
      "z": 0,
      "name": "Rock_Runic_Blue_Brick"
    },
    {
      "x": 2,
      "y": 6,
      "z": 0,
      "name": "Rock_Aqua_Brick_Ornate"
    },
    {
      "x": 2,
      "y": 7,
      "z": 0,
      "name": "Rock_Aqua_Brick_Decorative"
    },
    {
      "x": 2,
      "y": 8,
      "z": 0,
      "name": "Rock_Aqua_Brick_Smooth"
    },
    {
      "x": 2,
      "y": 9,
      "z": 0,
      "name": "Rock_Aqua_Brick_Smooth"
    },
    {
      "x": 2,
      "y": 10,
      "z": 0,
      "name": "Rock_Aqua_Brick_Smooth"
    },
    {
      "x": 2,
      "y": 11,
      "z": 0,
      "name": "Rock_Aqua_Brick_Smooth"
    },
    {
      "x": 2,
      "y": 0,
      "z": 1,
      "name": "Rock_Aqua"
    },
    {
      "x": 2,
      "y": 1,
      "z": 1,
      "name": "Rock_Runic_Brick"
    },
    {
      "x": 2,
      "y": 2,
      "z": 1,
      "name": "Plant_Moss_Short_Blue",
      "support": 15
    },
    {
      "x": 2,
      "y": 5,
      "z": 1,
      "name": "Rock_Aqua_Brick_Smooth"
    },
    {
      "x": 2,
      "y": 6,
      "z": 1,
      "name": "Rock_Aqua"
    },
    {
      "x": 2,
      "y": 7,
      "z": 1,
      "name": "Rubble_Aqua",
      "support": 15
    },
    {
      "x": 2,
      "y": 9,
      "z": 1,
      "name": "Rock_Aqua_Brick_Smooth_Half",
      "rotation": 4
    },
    {
      "x": 2,
      "y": 12,
      "z": 1,
      "name": "Rock_Aqua_Brick_Smooth_Half",
      "rotation": 5
    },
    {
      "x": 2,
      "y": 0,
      "z": 2,
      "name": "Rock_Aqua"
    },
    {
      "x": 2,
      "y": 1,
      "z": 2,
      "name": "Rock_Runic_Brick"
    },
    {
      "x": 2,
      "y": 2,
      "z": 2,
      "name": "Plant_Moss_Rug_Blue",
      "support": 15
    },
    {
      "x": 2,
      "y": 5,
      "z": 2,
      "name": "Soil_Clay_Cyan"
    },
    {
      "x": 2,
      "y": 6,
      "z": 2,
      "name": "Rock_Aqua"
    },
    {
      "x": 2,
      "y": 0,
      "z": 3,
      "name": "Rock_Aqua"
    },
    {
      "x": 2,
      "y": 1,
      "z": 3,
      "name": "Rock_Runic_Brick"
    },
    {
      "x": 2,
      "y": 2,
      "z": 3,
      "name": "Deco_Bone_Skulls"
    },
    {
      "x": 2,
      "y": 5,
      "z": 3,
      "name": "Soil_Clay_Cyan"
    },
    {
      "x": 2,
      "y": 6,
      "z": 3,
      "name": "Rock_Aqua"
    },
    {
      "x": 2,
      "y": 0,
      "z": 4,
      "name": "Rock_Aqua"
    },
    {
      "x": 2,
      "y": 1,
      "z": 4,
      "name": "Rock_Runic_Brick"
    },
    {
      "x": 2,
      "y": 2,
      "z": 4,
      "name": "Rock_Runic_Dark_Brick_Pillar_Base"
    },
    {
      "x": 2,
      "y": 3,
      "z": 4,
      "name": "Rock_Calcite_Brick_Pillar_Middle"
    },
    {
      "x": 2,
      "y": 4,
      "z": 4,
      "name": "Rock_Runic_Dark_Brick_Pillar_Base",
      "rotation": 8
    },
    {
      "x": 2,
      "y": 5,
      "z": 4,
      "name": "Soil_Clay_Cyan"
    },
    {
      "x": 2,
      "y": 6,
      "z": 4,
      "name": "Rock_Aqua"
    },
    {
      "x": 2,
      "y": 7,
      "z": 4,
      "name": "Rock_Aqua_Brick_Decorative"
    },
    {
      "x": 2,
      "y": 8,
      "z": 4,
      "name": "Rock_Aqua_Brick_Pillar_Base"
    },
    {
      "x": 2,
      "y": 9,
      "z": 4,
      "name": "Rock_Aqua_Stalactite_Small"
    },
    {
      "x": 2,
      "y": 0,
      "z": 5,
      "name": "Rock_Aqua"
    },
    {
      "x": 2,
      "y": 1,
      "z": 5,
      "name": "Rock_Runic_Brick"
    },
    {
      "x": 2,
      "y": 2,
      "z": 5,
      "name": "Rock_Aqua_Brick_Decorative"
    },
    {
      "x": 2,
      "y": 3,
      "z": 5,
      "name": "Rock_Aqua_Brick_Smooth"
    },
    {
      "x": 2,
      "y": 4,
      "z": 5,
      "name": "Rock_Aqua_Brick_Smooth"
    },
    {
      "x": 2,
      "y": 5,
      "z": 5,
      "name": "Rock_Aqua"
    },
    {
      "x": 2,
      "y": 6,
      "z": 5,
      "name": "Rock_Aqua"
    },
    {
      "x": 2,
      "y": 1,
      "z": 6,
      "name": "Rock_Aqua"
    },
    {
      "x": 2,
      "y": 2,
      "z": 6,
      "name": "Rock_Aqua"
    },
    {
      "x": 2,
      "y": 3,
      "z": 6,
      "name": "Rock_Aqua"
    },
    {
      "x": 2,
      "y": 4,
      "z": 6,
      "name": "Rock_Aqua"
    },
    {
      "x": 2,
      "y": 5,
      "z": 6,
      "name": "Rock_Aqua"
    },
    {
      "x": 2,
      "y": 6,
      "z": 6,
      "name": "Rock_Aqua"
    },
    {
      "x": 2,
      "y": 3,
      "z": 7,
      "name": "Rock_Aqua"
    },
    {
      "x": 2,
      "y": 4,
      "z": 7,
      "name": "Rock_Aqua"
    },
    {
      "x": 3,
      "y": 3,
      "z": -7,
      "name": "Rock_Aqua"
    },
    {
      "x": 3,
      "y": 4,
      "z": -7,
      "name": "Rock_Aqua"
    },
    {
      "x": 3,
      "y": 2,
      "z": -6,
      "name": "Rock_Aqua"
    },
    {
      "x": 3,
      "y": 3,
      "z": -6,
      "name": "Rock_Aqua"
    },
    {
      "x": 3,
      "y": 4,
      "z": -6,
      "name": "Rock_Aqua"
    },
    {
      "x": 3,
      "y": 5,
      "z": -6,
      "name": "Rock_Aqua"
    },
    {
      "x": 3,
      "y": 6,
      "z": -6,
      "name": "Rock_Aqua"
    },
    {
      "x": 3,
      "y": 1,
      "z": -5,
      "name": "Rock_Aqua"
    },
    {
      "x": 3,
      "y": 2,
      "z": -5,
      "name": "Rock_Aqua"
    },
    {
      "x": 3,
      "y": 3,
      "z": -5,
      "name": "Rock_Aqua"
    },
    {
      "x": 3,
      "y": 4,
      "z": -5,
      "name": "Rock_Aqua"
    },
    {
      "x": 3,
      "y": 5,
      "z": -5,
      "name": "Rock_Aqua"
    },
    {
      "x": 3,
      "y": 6,
      "z": -5,
      "name": "Rock_Aqua"
    },
    {
      "x": 3,
      "y": 7,
      "z": -5,
      "name": "*Rock_Aqua_Brick_Wall_State_Definitions_Corner"
    },
    {
      "x": 3,
      "y": 1,
      "z": -4,
      "name": "Rock_Aqua"
    },
    {
      "x": 3,
      "y": 2,
      "z": -4,
      "name": "Rock_Aqua"
    },
    {
      "x": 3,
      "y": 3,
      "z": -4,
      "name": "Rock_Aqua"
    },
    {
      "x": 3,
      "y": 4,
      "z": -4,
      "name": "Rock_Aqua"
    },
    {
      "x": 3,
      "y": 5,
      "z": -4,
      "name": "Rock_Aqua"
    },
    {
      "x": 3,
      "y": 6,
      "z": -4,
      "name": "Rock_Aqua"
    },
    {
      "x": 3,
      "y": 7,
      "z": -4,
      "name": "Rock_Aqua_Brick_Wall",
      "rotation": 1
    },
    {
      "x": 3,
      "y": 9,
      "z": -4,
      "name": "Rock_Aqua_Brick_Smooth_Half",
      "rotation": 5
    },
    {
      "x": 3,
      "y": 12,
      "z": -4,
      "name": "Rock_Aqua_Brick_Smooth_Half",
      "rotation": 6
    },
    {
      "x": 3,
      "y": 0,
      "z": -3,
      "name": "Rock_Aqua"
    },
    {
      "x": 3,
      "y": 1,
      "z": -3,
      "name": "Rock_Runic_Brick"
    },
    {
      "x": 3,
      "y": 2,
      "z": -3,
      "name": "Rock_Aqua_Brick_Decorative"
    },
    {
      "x": 3,
      "y": 3,
      "z": -3,
      "name": "Rock_Aqua_Brick_Smooth"
    },
    {
      "x": 3,
      "y": 4,
      "z": -3,
      "name": "Rock_Aqua_Brick_Smooth"
    },
    {
      "x": 3,
      "y": 5,
      "z": -3,
      "name": "Rock_Aqua_Brick_Smooth"
    },
    {
      "x": 3,
      "y": 6,
      "z": -3,
      "name": "Rock_Aqua_Brick_Ornate"
    },
    {
      "x": 3,
      "y": 7,
      "z": -3,
      "name": "Rock_Aqua_Brick_Decorative"
    },
    {
      "x": 3,
      "y": 8,
      "z": -3,
      "name": "Rock_Aqua_Brick_Smooth"
    },
    {
      "x": 3,
      "y": 9,
      "z": -3,
      "name": "Rock_Aqua_Brick_Smooth"
    },
    {
      "x": 3,
      "y": 10,
      "z": -3,
      "name": "Rock_Aqua_Brick_Stairs",
      "rotation": 1
    },
    {
      "x": 3,
      "y": 11,
      "z": -3,
      "name": "Rock_Aqua_Brick_Smooth"
    },
    {
      "x": 3,
      "y": 12,
      "z": -3,
      "name": "Rock_Aqua_Brick_Smooth"
    },
    {
      "x": 3,
      "y": 13,
      "z": -3,
      "name": "Furniture_Human_Ruins_Lantern"
    },
    {
      "x": 3,
      "y": 0,
      "z": -2,
      "name": "Rock_Aqua"
    },
    {
      "x": 3,
      "y": 1,
      "z": -2,
      "name": "Rock_Runic_Brick"
    },
    {
      "x": 3,
      "y": 2,
      "z": -2,
      "name": "Rock_Aqua_Brick_Decorative"
    },
    {
      "x": 3,
      "y": 3,
      "z": -2,
      "name": "Rock_Aqua_Brick_Smooth"
    },
    {
      "x": 3,
      "y": 4,
      "z": -2,
      "name": "Rock_Aqua_Brick_Smooth"
    },
    {
      "x": 3,
      "y": 5,
      "z": -2,
      "name": "Rock_Aqua_Brick_Smooth"
    },
    {
      "x": 3,
      "y": 6,
      "z": -2,
      "name": "Rock_Aqua_Brick_Ornate"
    },
    {
      "x": 3,
      "y": 7,
      "z": -2,
      "name": "Rock_Aqua_Brick_Decorative"
    },
    {
      "x": 3,
      "y": 8,
      "z": -2,
      "name": "Furniture_Temple_Dark_Window",
      "rotation": 1
    },
    {
      "x": 3,
      "y": 9,
      "z": -2,
      "name": "Rock_Aqua_Brick_Smooth_Half",
      "rotation": 7
    },
    {
      "x": 3,
      "y": 10,
      "z": -2,
      "name": "Rock_Aqua_Brick_Smooth"
    },
    {
      "x": 3,
      "y": 11,
      "z": -2,
      "name": "Rock_Aqua_Brick_Smooth"
    },
    {
      "x": 3,
      "y": 12,
      "z": -2,
      "name": "Rock_Aqua_Brick_Wall",
      "rotation": 1
    },
    {
      "x": 3,
      "y": 0,
      "z": -1,
      "name": "Rock_Aqua"
    },
    {
      "x": 3,
      "y": 1,
      "z": -1,
      "name": "Rock_Runic_Brick"
    },
    {
      "x": 3,
      "y": 2,
      "z": -1,
      "name": "Rock_Aqua_Brick_Decorative"
    },
    {
      "x": 3,
      "y": 3,
      "z": -1,
      "name": "Rock_Aqua_Brick_Smooth"
    },
    {
      "x": 3,
      "y": 4,
      "z": -1,
      "name": "Rock_Aqua_Brick_Smooth"
    },
    {
      "x": 3,
      "y": 5,
      "z": -1,
      "name": "Rock_Aqua_Brick_Smooth"
    },
    {
      "x": 3,
      "y": 6,
      "z": -1,
      "name": "Rock_Aqua_Brick_Ornate"
    },
    {
      "x": 3,
      "y": 7,
      "z": -1,
      "name": "Rock_Aqua_Brick_Decorative"
    },
    {
      "x": 3,
      "y": 8,
      "z": -1,
      "name": "Rock_Aqua_Brick_Smooth"
    },
    {
      "x": 3,
      "y": 9,
      "z": -1,
      "name": "Rock_Aqua_Brick_Stairs",
      "rotation": 1
    },
    {
      "x": 3,
      "y": 10,
      "z": -1,
      "name": "Rock_Aqua_Brick_Smooth"
    },
    {
      "x": 3,
      "y": 11,
      "z": -1,
      "name": "Rock_Aqua_Brick_Smooth"
    },
    {
      "x": 3,
      "y": 12,
      "z": -1,
      "name": "Rock_Aqua_Brick_Smooth"
    },
    {
      "x": 3,
      "y": 0,
      "z": 0,
      "name": "Rock_Aqua"
    },
    {
      "x": 3,
      "y": 1,
      "z": 0,
      "name": "Rock_Runic_Brick"
    },
    {
      "x": 3,
      "y": 2,
      "z": 0,
      "name": "Rock_Aqua_Brick_Decorative"
    },
    {
      "x": 3,
      "y": 3,
      "z": 0,
      "name": "Rock_Aqua_Brick_Smooth"
    },
    {
      "x": 3,
      "y": 4,
      "z": 0,
      "name": "Rock_Aqua_Brick_Smooth"
    },
    {
      "x": 3,
      "y": 5,
      "z": 0,
      "name": "Rock_Aqua_Brick_Smooth"
    },
    {
      "x": 3,
      "y": 6,
      "z": 0,
      "name": "Rock_Aqua"
    },
    {
      "x": 3,
      "y": 7,
      "z": 0,
      "name": "Plant_Moss_Wall_Blue",
      "support": 15,
      "rotation": 1
    },
    {
      "x": 3,
      "y": 9,
      "z": 0,
      "name": "Rock_Aqua_Brick_Smooth_Half",
      "rotation": 5
    },
    {
      "x": 3,
      "y": 12,
      "z": 0,
      "name": "Rock_Aqua_Brick_Smooth_Half",
      "rotation": 4
    },
    {
      "x": 3,
      "y": 0,
      "z": 1,
      "name": "Rock_Aqua"
    },
    {
      "x": 3,
      "y": 1,
      "z": 1,
      "name": "Rock_Runic_Brick"
    },
    {
      "x": 3,
      "y": 2,
      "z": 1,
      "name": "Rock_Aqua_Brick_Decorative"
    },
    {
      "x": 3,
      "y": 3,
      "z": 1,
      "name": "Rock_Aqua_Brick_Smooth"
    },
    {
      "x": 3,
      "y": 4,
      "z": 1,
      "name": "Rock_Aqua_Brick_Smooth"
    },
    {
      "x": 3,
      "y": 5,
      "z": 1,
      "name": "Rock_Aqua_Brick_Smooth"
    },
    {
      "x": 3,
      "y": 6,
      "z": 1,
      "name": "Rock_Aqua"
    },
    {
      "x": 3,
      "y": 0,
      "z": 2,
      "name": "Rock_Aqua"
    },
    {
      "x": 3,
      "y": 1,
      "z": 2,
      "name": "Rock_Runic_Brick"
    },
    {
      "x": 3,
      "y": 2,
      "z": 2,
      "name": "Rock_Aqua_Brick_Decorative"
    },
    {
      "x": 3,
      "y": 3,
      "z": 2,
      "name": "Rock_Aqua_Brick_Stairs",
      "rotation": 3
    },
    {
      "x": 3,
      "y": 4,
      "z": 2,
      "name": "Rock_Aqua_Brick_Smooth"
    },
    {
      "x": 3,
      "y": 5,
      "z": 2,
      "name": "Rock_Aqua_Brick_Smooth"
    },
    {
      "x": 3,
      "y": 6,
      "z": 2,
      "name": "Rock_Aqua"
    },
    {
      "x": 3,
      "y": 7,
      "z": 2,
      "name": "Rock_Aqua_Brick_Wall",
      "rotation": 1
    },
    {
      "x": 3,
      "y": 0,
      "z": 3,
      "name": "Rock_Aqua"
    },
    {
      "x": 3,
      "y": 1,
      "z": 3,
      "name": "Rock_Runic_Brick"
    },
    {
      "x": 3,
      "y": 2,
      "z": 3,
      "name": "Rock_Aqua_Brick_Decorative"
    },
    {
      "x": 3,
      "y": 3,
      "z": 3,
      "name": "Rock_Aqua_Brick_Smooth"
    },
    {
      "x": 3,
      "y": 4,
      "z": 3,
      "name": "Rock_Aqua_Brick_Stairs",
      "rotation": 9
    },
    {
      "x": 3,
      "y": 5,
      "z": 3,
      "name": "Rock_Aqua_Brick_Smooth"
    },
    {
      "x": 3,
      "y": 6,
      "z": 3,
      "name": "Rock_Aqua"
    },
    {
      "x": 3,
      "y": 7,
      "z": 3,
      "name": "Rock_Aqua_Brick_Wall",
      "rotation": 1
    },
    {
      "x": 3,
      "y": 0,
      "z": 4,
      "name": "Rock_Aqua"
    },
    {
      "x": 3,
      "y": 1,
      "z": 4,
      "name": "Rock_Runic_Brick"
    },
    {
      "x": 3,
      "y": 2,
      "z": 4,
      "name": "Rock_Aqua_Brick_Decorative"
    },
    {
      "x": 3,
      "y": 3,
      "z": 4,
      "name": "Rock_Aqua_Brick_Smooth"
    },
    {
      "x": 3,
      "y": 4,
      "z": 4,
      "name": "Rock_Aqua_Brick_Smooth"
    },
    {
      "x": 3,
      "y": 5,
      "z": 4,
      "name": "Rock_Aqua"
    },
    {
      "x": 3,
      "y": 6,
      "z": 4,
      "name": "Rock_Aqua"
    },
    {
      "x": 3,
      "y": 7,
      "z": 4,
      "name": "Rubble_Aqua",
      "support": 15
    },
    {
      "x": 3,
      "y": 0,
      "z": 5,
      "name": "Rock_Aqua"
    },
    {
      "x": 3,
      "y": 1,
      "z": 5,
      "name": "Rock_Runic_Brick"
    },
    {
      "x": 3,
      "y": 2,
      "z": 5,
      "name": "Rock_Aqua_Brick_Decorative"
    },
    {
      "x": 3,
      "y": 3,
      "z": 5,
      "name": "Rock_Aqua"
    },
    {
      "x": 3,
      "y": 4,
      "z": 5,
      "name": "Rock_Aqua"
    },
    {
      "x": 3,
      "y": 5,
      "z": 5,
      "name": "Rock_Aqua"
    },
    {
      "x": 3,
      "y": 6,
      "z": 5,
      "name": "Rock_Aqua"
    },
    {
      "x": 3,
      "y": 1,
      "z": 6,
      "name": "Rock_Aqua"
    },
    {
      "x": 3,
      "y": 2,
      "z": 6,
      "name": "Rock_Aqua"
    },
    {
      "x": 3,
      "y": 3,
      "z": 6,
      "name": "Rock_Aqua"
    },
    {
      "x": 3,
      "y": 4,
      "z": 6,
      "name": "Rock_Aqua"
    },
    {
      "x": 4,
      "y": 3,
      "z": -7,
      "name": "Rock_Aqua"
    },
    {
      "x": 4,
      "y": 4,
      "z": -7,
      "name": "Rock_Aqua"
    },
    {
      "x": 4,
      "y": 2,
      "z": -6,
      "name": "Rock_Aqua"
    },
    {
      "x": 4,
      "y": 3,
      "z": -6,
      "name": "Rock_Aqua"
    },
    {
      "x": 4,
      "y": 4,
      "z": -6,
      "name": "Rock_Aqua"
    },
    {
      "x": 4,
      "y": 2,
      "z": -5,
      "name": "Rock_Aqua"
    },
    {
      "x": 4,
      "y": 3,
      "z": -5,
      "name": "Rock_Aqua"
    },
    {
      "x": 4,
      "y": 4,
      "z": -5,
      "name": "Rock_Aqua"
    },
    {
      "x": 4,
      "y": 5,
      "z": -5,
      "name": "Rock_Aqua"
    },
    {
      "x": 4,
      "y": 6,
      "z": -5,
      "name": "Rock_Aqua"
    },
    {
      "x": 4,
      "y": 2,
      "z": -4,
      "name": "Rock_Aqua"
    },
    {
      "x": 4,
      "y": 3,
      "z": -4,
      "name": "Rock_Aqua"
    },
    {
      "x": 4,
      "y": 4,
      "z": -4,
      "name": "Rock_Aqua"
    },
    {
      "x": 4,
      "y": 5,
      "z": -4,
      "name": "Rock_Aqua"
    },
    {
      "x": 4,
      "y": 6,
      "z": -4,
      "name": "Rock_Aqua"
    },
    {
      "x": 4,
      "y": 1,
      "z": -3,
      "name": "Rock_Aqua"
    },
    {
      "x": 4,
      "y": 2,
      "z": -3,
      "name": "Rock_Aqua"
    },
    {
      "x": 4,
      "y": 3,
      "z": -3,
      "name": "Rock_Aqua"
    },
    {
      "x": 4,
      "y": 4,
      "z": -3,
      "name": "Rock_Aqua"
    },
    {
      "x": 4,
      "y": 1,
      "z": -2,
      "name": "Rock_Aqua"
    },
    {
      "x": 4,
      "y": 2,
      "z": -2,
      "name": "Rock_Aqua"
    },
    {
      "x": 4,
      "y": 3,
      "z": -2,
      "name": "Rock_Aqua"
    },
    {
      "x": 4,
      "y": 4,
      "z": -2,
      "name": "Rock_Aqua"
    },
    {
      "x": 4,
      "y": 5,
      "z": -2,
      "name": "Rock_Aqua"
    },
    {
      "x": 4,
      "y": 1,
      "z": -1,
      "name": "Rock_Aqua"
    },
    {
      "x": 4,
      "y": 2,
      "z": -1,
      "name": "Rock_Aqua"
    },
    {
      "x": 4,
      "y": 3,
      "z": -1,
      "name": "Rock_Aqua"
    },
    {
      "x": 4,
      "y": 4,
      "z": -1,
      "name": "Rock_Aqua"
    },
    {
      "x": 4,
      "y": 5,
      "z": -1,
      "name": "Rock_Aqua"
    },
    {
      "x": 4,
      "y": 6,
      "z": -1,
      "name": "Rock_Aqua"
    },
    {
      "x": 4,
      "y": 1,
      "z": 0,
      "name": "Rock_Aqua"
    },
    {
      "x": 4,
      "y": 2,
      "z": 0,
      "name": "Rock_Aqua"
    },
    {
      "x": 4,
      "y": 3,
      "z": 0,
      "name": "Rock_Aqua"
    },
    {
      "x": 4,
      "y": 4,
      "z": 0,
      "name": "Rock_Aqua"
    },
    {
      "x": 4,
      "y": 5,
      "z": 0,
      "name": "Rock_Aqua"
    },
    {
      "x": 4,
      "y": 6,
      "z": 0,
      "name": "Rock_Aqua"
    },
    {
      "x": 4,
      "y": 1,
      "z": 1,
      "name": "Rock_Aqua"
    },
    {
      "x": 4,
      "y": 2,
      "z": 1,
      "name": "Rock_Aqua"
    },
    {
      "x": 4,
      "y": 3,
      "z": 1,
      "name": "Rock_Aqua"
    },
    {
      "x": 4,
      "y": 4,
      "z": 1,
      "name": "Rock_Aqua"
    },
    {
      "x": 4,
      "y": 5,
      "z": 1,
      "name": "Rock_Aqua"
    },
    {
      "x": 4,
      "y": 6,
      "z": 1,
      "name": "Rock_Aqua"
    },
    {
      "x": 4,
      "y": 7,
      "z": 1,
      "name": "Rubble_Aqua_Medium",
      "support": 15
    },
    {
      "x": 4,
      "y": 1,
      "z": 2,
      "name": "Rock_Aqua"
    },
    {
      "x": 4,
      "y": 2,
      "z": 2,
      "name": "Rock_Aqua"
    },
    {
      "x": 4,
      "y": 3,
      "z": 2,
      "name": "Rock_Aqua"
    },
    {
      "x": 4,
      "y": 4,
      "z": 2,
      "name": "Rock_Aqua"
    },
    {
      "x": 4,
      "y": 5,
      "z": 2,
      "name": "Rock_Aqua"
    },
    {
      "x": 4,
      "y": 6,
      "z": 2,
      "name": "Rock_Aqua"
    },
    {
      "x": 4,
      "y": 1,
      "z": 3,
      "name": "Rock_Aqua"
    },
    {
      "x": 4,
      "y": 2,
      "z": 3,
      "name": "Rock_Aqua"
    },
    {
      "x": 4,
      "y": 3,
      "z": 3,
      "name": "Rock_Aqua"
    },
    {
      "x": 4,
      "y": 4,
      "z": 3,
      "name": "Rock_Aqua"
    },
    {
      "x": 4,
      "y": 5,
      "z": 3,
      "name": "Rock_Aqua"
    },
    {
      "x": 4,
      "y": 6,
      "z": 3,
      "name": "Rock_Aqua"
    },
    {
      "x": 4,
      "y": 1,
      "z": 4,
      "name": "Rock_Aqua"
    },
    {
      "x": 4,
      "y": 2,
      "z": 4,
      "name": "Rock_Aqua"
    },
    {
      "x": 4,
      "y": 3,
      "z": 4,
      "name": "Rock_Aqua"
    },
    {
      "x": 4,
      "y": 4,
      "z": 4,
      "name": "Rock_Aqua"
    },
    {
      "x": 4,
      "y": 5,
      "z": 4,
      "name": "Rock_Aqua"
    },
    {
      "x": 4,
      "y": 1,
      "z": 5,
      "name": "Rock_Aqua"
    },
    {
      "x": 4,
      "y": 2,
      "z": 5,
      "name": "Rock_Aqua"
    },
    {
      "x": 4,
      "y": 3,
      "z": 5,
      "name": "Rock_Aqua"
    },
    {
      "x": 4,
      "y": 4,
      "z": 5,
      "name": "Rock_Aqua"
    },
    {
      "x": 4,
      "y": 3,
      "z": 6,
      "name": "Rock_Aqua"
    },
    {
      "x": 4,
      "y": 4,
      "z": 6,
      "name": "Rock_Aqua"
    },
    {
      "x": 5,
      "y": 3,
      "z": -6,
      "name": "Rock_Aqua"
    },
    {
      "x": 5,
      "y": 4,
      "z": -6,
      "name": "Rock_Aqua"
    },
    {
      "x": 5,
      "y": 3,
      "z": -5,
      "name": "Rock_Aqua"
    },
    {
      "x": 5,
      "y": 4,
      "z": -5,
      "name": "Rock_Aqua"
    },
    {
      "x": 5,
      "y": 3,
      "z": -4,
      "name": "Rock_Aqua"
    },
    {
      "x": 5,
      "y": 4,
      "z": -4,
      "name": "Rock_Aqua"
    },
    {
      "x": 5,
      "y": 2,
      "z": -3,
      "name": "Rock_Aqua"
    },
    {
      "x": 5,
      "y": 3,
      "z": -3,
      "name": "Rock_Aqua"
    },
    {
      "x": 5,
      "y": 4,
      "z": -3,
      "name": "Rock_Aqua"
    },
    {
      "x": 5,
      "y": 2,
      "z": -2,
      "name": "Rock_Aqua"
    },
    {
      "x": 5,
      "y": 3,
      "z": -2,
      "name": "Rock_Aqua"
    },
    {
      "x": 5,
      "y": 4,
      "z": -2,
      "name": "Rock_Aqua"
    },
    {
      "x": 5,
      "y": 2,
      "z": -1,
      "name": "Rock_Aqua"
    },
    {
      "x": 5,
      "y": 3,
      "z": -1,
      "name": "Rock_Aqua"
    },
    {
      "x": 5,
      "y": 4,
      "z": -1,
      "name": "Rock_Aqua"
    },
    {
      "x": 5,
      "y": 1,
      "z": 0,
      "name": "Rock_Aqua"
    },
    {
      "x": 5,
      "y": 2,
      "z": 0,
      "name": "Rock_Aqua"
    },
    {
      "x": 5,
      "y": 3,
      "z": 0,
      "name": "Rock_Aqua"
    },
    {
      "x": 5,
      "y": 4,
      "z": 0,
      "name": "Rock_Aqua"
    },
    {
      "x": 5,
      "y": 1,
      "z": 1,
      "name": "Rock_Aqua"
    },
    {
      "x": 5,
      "y": 2,
      "z": 1,
      "name": "Rock_Aqua"
    },
    {
      "x": 5,
      "y": 3,
      "z": 1,
      "name": "Rock_Aqua"
    },
    {
      "x": 5,
      "y": 4,
      "z": 1,
      "name": "Rock_Aqua"
    },
    {
      "x": 5,
      "y": 5,
      "z": 1,
      "name": "Rock_Aqua"
    },
    {
      "x": 5,
      "y": 6,
      "z": 1,
      "name": "Rock_Aqua"
    },
    {
      "x": 5,
      "y": 1,
      "z": 2,
      "name": "Rock_Aqua"
    },
    {
      "x": 5,
      "y": 2,
      "z": 2,
      "name": "Rock_Aqua"
    },
    {
      "x": 5,
      "y": 3,
      "z": 2,
      "name": "Rock_Aqua"
    },
    {
      "x": 5,
      "y": 4,
      "z": 2,
      "name": "Rock_Aqua"
    },
    {
      "x": 5,
      "y": 5,
      "z": 2,
      "name": "Rock_Aqua"
    },
    {
      "x": 5,
      "y": 6,
      "z": 2,
      "name": "Rock_Aqua"
    },
    {
      "x": 5,
      "y": 2,
      "z": 3,
      "name": "Rock_Aqua"
    },
    {
      "x": 5,
      "y": 3,
      "z": 3,
      "name": "Rock_Aqua"
    },
    {
      "x": 5,
      "y": 4,
      "z": 3,
      "name": "Rock_Aqua"
    },
    {
      "x": 5,
      "y": 5,
      "z": 3,
      "name": "Rock_Aqua"
    },
    {
      "x": 5,
      "y": 3,
      "z": 4,
      "name": "Rock_Aqua"
    },
    {
      "x": 5,
      "y": 4,
      "z": 4,
      "name": "Rock_Aqua"
    },
    {
      "x": 5,
      "y": 3,
      "z": 5,
      "name": "Rock_Aqua"
    },
    {
      "x": 5,
      "y": 4,
      "z": 5,
      "name": "Rock_Aqua"
    },
    {
      "x": 6,
      "y": 3,
      "z": 0,
      "name": "Rock_Aqua"
    },
    {
      "x": 6,
      "y": 2,
      "z": 1,
      "name": "Rock_Aqua"
    },
    {
      "x": 6,
      "y": 3,
      "z": 1,
      "name": "Rock_Aqua"
    },
    {
      "x": 6,
      "y": 4,
      "z": 1,
      "name": "Rock_Aqua"
    },
    {
      "x": 6,
      "y": 3,
      "z": 2,
      "name": "Rock_Aqua"
    },
    {
      "x": 6,
      "y": 4,
      "z": 2,
      "name": "Rock_Aqua"
    },
    {
      "x": 6,
      "y": 5,
      "z": 2,
      "name": "Rock_Aqua"
    },
    {
      "x": 6,
      "y": 4,
      "z": 3,
      "name": "Rock_Aqua"
    }
  ],
  "fluids": [
    {
      "x": -6,
      "y": 7,
      "z": -6,
      "name": "Water_Source",
      "level": 1
    },
    {
      "x": -6,
      "y": 8,
      "z": -6,
      "name": "Water_Source",
      "level": 1
    },
    {
      "x": -6,
      "y": 9,
      "z": -6,
      "name": "Water_Source",
      "level": 1
    },
    {
      "x": -6,
      "y": 7,
      "z": 0,
      "name": "Water_Source",
      "level": 1
    },
    {
      "x": -5,
      "y": 12,
      "z": -6,
      "name": "Water_Source",
      "level": 1
    },
    {
      "x": -5,
      "y": 7,
      "z": -5,
      "name": "Water_Source",
      "level": 1
    },
    {
