{
  "version": 8,
  "blockIdVersion": 11,
  "anchorX": 0,
  "anchorY": 4,
  "anchorZ": 0,
  "blocks": [
    {
      "x": -4,
      "y": 0,
      "z": -4,
      "name": "*Rock_Aqua_Stairs_State_Definitions_Corner_Left",
      "rotation": 9
    },
    {
      "x": -4,
      "y": 1,
      "z": -4,
      "name": "Rock_Aqua"
    },
    {
      "x": -4,
      "y": 0,
      "z": -3,
      "name": "Rock_Aqua_Stairs",
      "rotation": 9
    },
    {
      "x": -4,
      "y": 1,
      "z": -3,
      "name": "Rock_Aqua"
    },
    {
      "x": -4,
      "y": 0,
      "z": -2,
      "name": "Rock_Aqua_Stairs",
      "rotation": 9
    },
    {
      "x": -4,
      "y": 1,
      "z": -2,
      "name": "Rock_Aqua"
    },
    {
      "x": -4,
      "y": 0,
      "z": -1,
      "name": "Rock_Aqua_Stairs",
      "rotation": 9
    },
    {
      "x": -4,
      "y": 1,
      "z": -1,
      "name": "Rock_Aqua"
    },
    {
      "x": -4,
      "y": 2,
      "z": -1,
      "name": "Rock_Aqua"
    },
    {
      "x": -4,
      "y": 3,
      "z": -1,
      "name": "Rock_Aqua"
    },
    {
      "x": -4,
      "y": 4,
      "z": -1,
      "name": "Rock_Aqua_Brick_Decorative"
    },
    {
      "x": -4,
      "y": 5,
      "z": -1,
      "name": "Rock_Aqua_Brick_Smooth_Half"
    },
    {
      "x": -4,
      "y": 0,
      "z": 0,
      "name": "Rock_Aqua_Stairs",
      "rotation": 9
    },
    {
      "x": -4,
      "y": 1,
      "z": 0,
      "name": "Rock_Aqua"
    },
    {
      "x": -4,
      "y": 2,
      "z": 0,
      "name": "Rock_Aqua"
    },
    {
      "x": -4,
      "y": 3,
      "z": 0,
      "name": "Rock_Aqua"
    },
    {
      "x": -4,
      "y": 4,
      "z": 0,
      "name": "Rock_Aqua_Brick_Decorative"
    },
    {
      "x": -4,
      "y": 5,
      "z": 0,
      "name": "Rock_Aqua_Brick_Decorative"
    },
    {
      "x": -4,
      "y": 0,
      "z": 1,
      "name": "Rock_Aqua_Stairs",
      "rotation": 9
    },
    {
      "x": -4,
      "y": 1,
      "z": 1,
      "name": "Rock_Aqua"
    },
    {
      "x": -4,
      "y": 2,
      "z": 1,
      "name": "Rock_Aqua"
    },
    {
      "x": -4,
      "y": 3,
      "z": 1,
      "name": "Rock_Aqua"
    },
    {
      "x": -4,
      "y": 4,
      "z": 1,
      "name": "Rock_Aqua_Brick_Wall",
      "rotation": 1
    },
    {
      "x": -4,
      "y": 0,
      "z": 2,
      "name": "Rock_Aqua_Stairs",
      "rotation": 9
    },
    {
      "x": -4,
      "y": 1,
      "z": 2,
      "name": "Rock_Aqua"
    },
    {
      "x": -4,
      "y": 2,
      "z": 2,
      "name": "Rock_Aqua"
    },
    {
      "x": -4,
      "y": 3,
      "z": 2,
      "name": "Rock_Aqua"
    },
    {
      "x": -4,
      "y": 0,
      "z": 3,
      "name": "Rock_Aqua_Stairs",
      "rotation": 9
    },
    {
      "x": -4,
      "y": 1,
      "z": 3,
      "name": "Rock_Aqua"
    },
    {
      "x": -4,
      "y": 0,
      "z": 4,
      "name": "*Rock_Aqua_Stairs_State_Definitions_Corner_Left",
      "rotation": 10
    },
    {
      "x": -4,
      "y": 1,
      "z": 4,
      "name": "Rock_Aqua"
    },
    {
      "x": -3,
      "y": 0,
      "z": -4,
      "name": "Rock_Aqua_Stairs",
      "rotation": 8
    },
    {
      "x": -3,
      "y": 1,
      "z": -4,
      "name": "Rock_Aqua"
    },
    {
      "x": -3,
      "y": 2,
      "z": -4,
      "name": "Rock_Aqua"
    },
    {
      "x": -3,
      "y": 3,
      "z": -4,
      "name": "Rock_Aqua"
    },
    {
      "x": -3,
      "y": 4,
      "z": -4,
      "name": "Rock_Aqua_Brick_Decorative"
    },
    {
      "x": -3,
      "y": 5,
      "z": -4,
      "name": "Rock_Aqua_Brick_Pillar_Base"
    },
    {
      "x": -3,
      "y": 0,
      "z": -3,
      "name": "Rock_Aqua"
    },
    {
      "x": -3,
      "y": 1,
      "z": -3,
      "name": "Rock_Aqua"
    },
    {
      "x": -3,
      "y": 0,
      "z": -2,
      "name": "Rock_Aqua"
    },
    {
      "x": -3,
      "y": 1,
      "z": -2,
      "name": "Rock_Aqua"
    },
    {
      "x": -3,
      "y": 0,
      "z": -1,
      "name": "Rock_Aqua"
    },
    {
      "x": -3,
      "y": 1,
      "z": -1,
      "name": "Rock_Aqua"
    },
    {
      "x": -3,
      "y": 2,
      "z": -1,
      "name": "Rock_Aqua"
    },
    {
      "x": -3,
      "y": 3,
      "z": -1,
      "name": "Rock_Aqua"
    },
    {
      "x": -3,
      "y": 4,
      "z": -1,
      "name": "Furniture_Temple_Dark_Stool"
    },
    {
      "x": -3,
      "y": 0,
      "z": 0,
      "name": "Rock_Aqua"
    },
    {
      "x": -3,
      "y": 1,
      "z": 0,
      "name": "Rock_Aqua"
    },
    {
      "x": -3,
      "y": 2,
      "z": 0,
      "name": "Rock_Aqua"
    },
    {
      "x": -3,
      "y": 3,
      "z": 0,
      "name": "Rock_Aqua"
    },
    {
      "x": -3,
      "y": 0,
      "z": 1,
      "name": "Rock_Aqua"
    },
    {
      "x": -3,
      "y": 1,
      "z": 1,
      "name": "Rock_Aqua"
    },
    {
      "x": -3,
      "y": 2,
      "z": 1,
      "name": "Rock_Aqua"
    },
    {
      "x": -3,
      "y": 3,
      "z": 1,
      "name": "Rock_Aqua",
      "support": 15
    },
    {
      "x": -3,
      "y": 4,
      "z": 1,
      "name": "Rubble_Aqua_Medium"
    },
    {
      "x": -3,
      "y": 0,
      "z": 2,
      "name": "Rock_Aqua"
    },
    {
      "x": -3,
      "y": 1,
      "z": 2,
      "name": "Rock_Aqua"
    },
    {
      "x": -3,
      "y": 2,
      "z": 2,
      "name": "Rock_Aqua"
    },
    {
      "x": -3,
      "y": 3,
      "z": 2,
      "name": "Rock_Aqua"
    },
    {
      "x": -3,
      "y": 0,
      "z": 3,
      "name": "Rock_Aqua"
    },
    {
      "x": -3,
      "y": 1,
      "z": 3,
      "name": "Rock_Aqua"
    },
    {
      "x": -3,
      "y": 2,
      "z": 3,
      "name": "Rock_Aqua"
    },
    {
      "x": -3,
      "y": 3,
      "z": 3,
      "name": "Rock_Aqua_Stairs",
      "rotation": 2
    },
    {
      "x": -3,
      "y": 0,
      "z": 4,
      "name": "Rock_Aqua_Stairs",
      "rotation": 10
    },
    {
      "x": -3,
      "y": 1,
      "z": 4,
      "name": "Rock_Aqua"
    },
    {
      "x": -2,
      "y": 0,
      "z": -4,
      "name": "Rock_Aqua_Stairs",
      "rotation": 8
    },
    {
      "x": -2,
      "y": 1,
      "z": -4,
      "name": "Rock_Aqua"
    },
    {
      "x": -2,
      "y": 2,
      "z": -4,
      "name": "Rock_Aqua"
    },
    {
      "x": -2,
      "y": 3,
      "z": -4,
      "name": "Rock_Aqua"
    },
    {
      "x": -2,
      "y": 4,
      "z": -4,
      "name": "Rock_Aqua_Brick_Decorative"
    },
    {
      "x": -2,
      "y": 0,
      "z": -3,
      "name": "Rock_Aqua"
    },
    {
      "x": -2,
      "y": 1,
      "z": -3,
      "name": "Rock_Aqua"
    },
    {
      "x": -2,
      "y": 2,
      "z": -3,
      "name": "Rock_Aqua"
    },
    {
      "x": -2,
      "y": 3,
      "z": -3,
      "name": "Rock_Aqua"
    },
    {
      "x": -2,
      "y": 0,
      "z": -2,
      "name": "Rock_Aqua"
    },
    {
      "x": -2,
      "y": 1,
      "z": -2,
      "name": "Rock_Aqua"
    },
    {
      "x": -2,
      "y": 0,
      "z": -1,
      "name": "Rock_Aqua"
    },
    {
      "x": -2,
      "y": 1,
      "z": -1,
      "name": "Rock_Aqua"
    },
    {
      "x": -2,
      "y": 2,
      "z": -1,
      "name": "Rock_Aqua"
    },
    {
      "x": -2,
      "y": 3,
      "z": -1,
      "name": "Rock_Aqua",
      "support": 15
    },
    {
      "x": -2,
      "y": 4,
      "z": -1,
      "name": "Rubble_Aqua"
    },
    {
      "x": -2,
      "y": 0,
      "z": 0,
      "name": "Rock_Aqua"
    },
    {
      "x": -2,
      "y": 1,
      "z": 0,
      "name": "Rock_Aqua"
    },
    {
      "x": -2,
      "y": 2,
      "z": 0,
      "name": "Rock_Aqua"
    },
    {
      "x": -2,
      "y": 3,
      "z": 0,
      "name": "Rock_Aqua"
    },
    {
      "x": -2,
      "y": 0,
      "z": 1,
      "name": "Rock_Aqua"
    },
    {
      "x": -2,
      "y": 1,
      "z": 1,
      "name": "Rock_Aqua"
    },
    {
      "x": -2,
      "y": 2,
      "z": 1,
      "name": "Rock_Aqua"
    },
    {
      "x": -2,
      "y": 3,
      "z": 1,
      "name": "Rock_Aqua_Stairs",
      "rotation": 3
    },
    {
      "x": -2,
      "y": 0,
      "z": 2,
      "name": "Rock_Aqua"
    },
    {
      "x": -2,
      "y": 1,
      "z": 2,
      "name": "Rock_Aqua"
    },
    {
      "x": -2,
      "y": 2,
      "z": 2,
      "name": "Rock_Aqua"
    },
    {
      "x": -2,
      "y": 3,
      "z": 2,
      "name": "Rock_Aqua_Stairs",
      "rotation": 3
    },
    {
      "x": -2,
      "y": 0,
      "z": 3,
      "name": "Rock_Aqua"
    },
    {
      "x": -2,
      "y": 1,
      "z": 3,
      "name": "Rock_Aqua"
    },
    {
      "x": -2,
      "y": 2,
      "z": 3,
      "name": "Rock_Aqua"
    },
    {
      "x": -2,
      "y": 3,
      "z": 3,
      "name": "Rock_Aqua"
    },
    {
      "x": -2,
      "y": 0,
      "z": 4,
      "name": "Rock_Aqua_Stairs",
      "rotation": 10
    },
    {
      "x": -2,
      "y": 1,
      "z": 4,
      "name": "Rock_Aqua"
    },
    {
      "x": -2,
      "y": 2,
      "z": 4,
      "name": "Rock_Aqua"
    },
    {
      "x": -2,
      "y": 3,
      "z": 4,
      "name": "Rock_Aqua",
      "support": 15
    },
    {
      "x": -2,
      "y": 4,
      "z": 4,
      "name": "Rubble_Aqua"
    },
    {
      "x": -1,
      "y": 0,
      "z": -4,
      "name": "Rock_Aqua_Stairs",
      "rotation": 8
    },
    {
      "x": -1,
      "y": 1,
      "z": -4,
      "name": "Rock_Aqua"
    },
    {
      "x": -1,
      "y": 2,
      "z": -4,
      "name": "Rock_Aqua"
    },
    {
      "x": -1,
      "y": 3,
      "z": -4,
      "name": "Rock_Aqua"
    },
    {
      "x": -1,
      "y": 4,
      "z": -4,
      "name": "Rock_Aqua_Brick_Wall"
    },
    {
      "x": -1,
      "y": 0,
      "z": -3,
      "name": "Rock_Aqua"
    },
    {
      "x": -1,
      "y": 1,
      "z": -3,
      "name": "Rock_Aqua"
    },
    {
      "x": -1,
      "y": 2,
      "z": -3,
      "name": "Rock_Aqua"
    },
    {
      "x": -1,
      "y": 3,
      "z": -3,
      "name": "Rock_Aqua"
    },
    {
      "x": -1,
      "y": 0,
      "z": -2,
      "name": "Rock_Aqua"
    },
    {
      "x": -1,
      "y": 1,
      "z": -2,
      "name": "Rock_Aqua"
    },
    {
      "x": -1,
      "y": 2,
      "z": -2,
      "name": "Rock_Aqua"
    },
    {
      "x": -1,
      "y": 3,
      "z": -2,
      "name": "Rock_Aqua"
    },
    {
      "x": -1,
      "y": 0,
      "z": -1,
      "name": "Rock_Aqua"
    },
    {
      "x": -1,
      "y": 1,
      "z": -1,
      "name": "Rock_Aqua"
    },
    {
      "x": -1,
      "y": 2,
      "z": -1,
      "name": "Rock_Aqua"
    },
    {
      "x": -1,
      "y": 3,
      "z": -1,
      "name": "Rock_Aqua_Stairs"
    },
    {
      "x": -1,
      "y": 0,
      "z": 0,
      "name": "Rock_Aqua"
    },
    {
      "x": -1,
      "y": 1,
      "z": 0,
      "name": "Rock_Aqua"
    },
    {
      "x": -1,
      "y": 2,
      "z": 0,
      "name": "Rock_Aqua"
    },
    {
      "x": -1,
      "y": 3,
      "z": 0,
      "name": "Rock_Aqua"
    },
    {
      "x": -1,
      "y": 0,
      "z": 1,
      "name": "Rock_Aqua"
    },
    {
      "x": -1,
      "y": 1,
      "z": 1,
      "name": "Rock_Aqua"
    },
    {
      "x": -1,
      "y": 2,
      "z": 1,
      "name": "Rock_Aqua"
    },
    {
      "x": -1,
      "y": 3,
      "z": 1,
      "name": "Rock_Aqua"
    },
    {
      "x": -1,
      "y": 4,
      "z": 1,
      "name": "Rock_Aqua_Brick_Decorative"
    },
    {
      "x": -1,
      "y": 5,
      "z": 1,
      "name": "Rock_Aqua_Brick_Smooth_Half"
    },
    {
      "x": -1,
      "y": 0,
      "z": 2,
      "name": "Rock_Aqua"
    },
    {
      "x": -1,
      "y": 1,
      "z": 2,
      "name": "Rock_Aqua"
    },
    {
      "x": -1,
      "y": 2,
      "z": 2,
      "name": "Rock_Aqua"
    },
    {
      "x": -1,
      "y": 3,
      "z": 2,
      "name": "Rock_Aqua"
    },
    {
      "x": -1,
      "y": 4,
      "z": 2,
      "name": "Rock_Aqua_Brick_Decorative"
    },
    {
      "x": -1,
      "y": 5,
      "z": 2,
      "name": "Furniture_Temple_Dark_Window",
      "rotation": 1
    },
    {
      "x": -1,
      "y": 0,
      "z": 3,
      "name": "Rock_Aqua"
    },
    {
      "x": -1,
      "y": 1,
      "z": 3,
      "name": "Rock_Aqua"
    },
    {
      "x": -1,
      "y": 2,
      "z": 3,
      "name": "Rock_Aqua"
    },
    {
      "x": -1,
      "y": 3,
      "z": 3,
      "name": "Rock_Aqua"
    },
    {
      "x": -1,
      "y": 4,
      "z": 3,
      "name": "Rock_Aqua_Brick_Decorative"
    },
    {
      "x": -1,
      "y": 5,
      "z": 3,
      "name": "Furniture_Temple_Dark_Window",
      "rotation": 1
    },
    {
      "x": -1,
      "y": 0,
      "z": 4,
      "name": "Rock_Aqua_Stairs",
      "rotation": 10
    },
    {
      "x": -1,
      "y": 1,
      "z": 4,
      "name": "Rock_Aqua"
    },
    {
      "x": -1,
      "y": 2,
      "z": 4,
      "name": "Rock_Aqua"
    },
    {
      "x": -1,
      "y": 3,
      "z": 4,
      "name": "Rock_Aqua"
    },
    {
      "x": -1,
      "y": 4,
      "z": 4,
      "name": "Rock_Aqua_Brick_Wall"
    },
    {
      "x": 0,
      "y": 0,
      "z": -4,
      "name": "Rock_Aqua_Stairs",
      "rotation": 8
    },
    {
      "x": 0,
      "y": 1,
      "z": -4,
      "name": "Rock_Aqua"
    },
    {
      "x": 0,
      "y": 0,
      "z": -3,
      "name": "Rock_Aqua"
    },
    {
      "x": 0,
      "y": 1,
      "z": -3,
      "name": "Rock_Aqua"
    },
    {
      "x": 0,
      "y": 2,
      "z": -3,
      "name": "Rock_Aqua"
    },
    {
      "x": 0,
      "y": 3,
      "z": -3,
      "name": "Rock_Aqua",
      "support": 15
    },
    {
      "x": 0,
      "y": 4,
      "z": -3,
      "name": "Rubble_Aqua_Medium"
    },
    {
      "x": 0,
      "y": 0,
      "z": -2,
      "name": "Rock_Aqua"
    },
    {
      "x": 0,
      "y": 1,
      "z": -2,
      "name": "Rock_Aqua"
    },
    {
      "x": 0,
      "y": 2,
      "z": -2,
      "name": "Rock_Aqua"
    },
    {
      "x": 0,
      "y": 3,
      "z": -2,
      "name": "Rock_Aqua_Brick_Ornate"
    },
    {
      "x": 0,
      "y": 6,
      "z": -2,
      "name": "Rock_Aqua_Brick_Smooth"
    },
    {
      "x": 0,
      "y": 7,
      "z": -2,
      "name": "Rock_Aqua_Brick_Smooth"
    },
    {
      "x": 0,
      "y": 8,
      "z": -2,
      "name": "Rock_Aqua_Cobble_Roof_Flat",
      "rotation": 1
    },
    {
      "x": 0,
      "y": 0,
      "z": -1,
      "name": "Rock_Aqua"
    },
    {
      "x": 0,
      "y": 1,
      "z": -1,
      "name": "Rock_Aqua"
    },
    {
      "x": 0,
      "y": 2,
      "z": -1,
      "name": "Rock_Aqua"
    },
    {
      "x": 0,
      "y": 3,
      "z": -1,
      "name": "Rock_Aqua"
    },
    {
      "x": 0,
      "y": 4,
      "z": -1,
      "name": "Rock_Aqua_Brick_Decorative"
    },
    {
      "x": 0,
      "y": 5,
      "z": -1,
      "name": "Rock_Aqua_Brick_Smooth"
    },
    {
      "x": 0,
      "y": 6,
      "z": -1,
      "name": "Rock_Aqua_Brick_Smooth"
    },
    {
      "x": 0,
      "y": 7,
      "z": -1,
      "name": "Rock_Aqua_Brick_Smooth"
    },
    {
      "x": 0,
      "y": 8,
      "z": -1,
      "name": "Rock_Aqua_Brick_Smooth_Half"
    },
    {
      "x": 0,
      "y": 0,
      "z": 0,
      "name": "Rock_Aqua"
    },
    {
      "x": 0,
      "y": 1,
      "z": 0,
      "name": "Rock_Aqua"
    },
    {
      "x": 0,
      "y": 2,
      "z": 0,
      "name": "Rock_Aqua"
    },
    {
      "x": 0,
      "y": 3,
      "z": 0,
      "name": "Rock_Aqua"
    },
    {
      "x": 0,
      "y": 4,
      "z": 0,
      "name": "Plant_Moss_Wall_Blue",
      "support": 15
    },
    {
      "x": 0,
      "y": 0,
      "z": 1,
      "name": "Rock_Aqua"
    },
    {
      "x": 0,
      "y": 1,
      "z": 1,
      "name": "Rock_Aqua"
    },
    {
      "x": 0,
      "y": 2,
      "z": 1,
      "name": "Rock_Aqua"
    },
    {
      "x": 0,
      "y": 3,
      "z": 1,
      "name": "Rock_Aqua",
      "support": 15
    },
    {
      "x": 0,
      "y": 4,
      "z": 1,
      "name": "Rubble_Aqua_Medium"
    },
    {
      "x": 0,
      "y": 0,
      "z": 2,
      "name": "Rock_Aqua"
    },
    {
      "x": 0,
      "y": 1,
      "z": 2,
      "name": "Rock_Aqua"
    },
    {
      "x": 0,
      "y": 2,
      "z": 2,
      "name": "Rock_Aqua",
      "support": 15
    },
    {
      "x": 0,
      "y": 3,
      "z": 2,
      "name": "Plant_Moss_Block_Blue",
      "support": 15
    },
    {
      "x": 0,
      "y": 4,
      "z": 2,
      "name": "Plant_Moss_Rug_Blue"
    },
    {
      "x": 0,
      "y": 0,
      "z": 3,
      "name": "Rock_Aqua"
    },
    {
      "x": 0,
      "y": 1,
      "z": 3,
      "name": "Rock_Aqua"
    },
    {
      "x": 0,
      "y": 2,
      "z": 3,
      "name": "Rock_Aqua",
      "support": 15
    },
    {
      "x": 0,
      "y": 3,
      "z": 3,
      "name": "Plant_Moss_Block_Blue"
    },
    {
      "x": 0,
      "y": 0,
      "z": 4,
      "name": "Rock_Aqua_Stairs",
      "rotation": 10
    },
    {
      "x": 0,
      "y": 1,
      "z": 4,
      "name": "Rock_Aqua"
    },
    {
      "x": 0,
      "y": 2,
      "z": 4,
      "name": "Rock_Aqua"
    },
    {
      "x": 0,
      "y": 3,
      "z": 4,
      "name": "Rock_Aqua"
    },
    {
      "x": 0,
      "y": 4,
      "z": 4,
      "name": "Rock_Aqua_Brick_Wall"
    },
    {
      "x": 1,
      "y": 0,
      "z": -4,
      "name": "Rock_Aqua_Stairs",
      "rotation": 8
    },
    {
      "x": 1,
      "y": 1,
      "z": -4,
      "name": "Rock_Aqua"
    },
    {
      "x": 1,
      "y": 2,
      "z": -4,
      "name": "Rock_Aqua"
    },
    {
      "x": 1,
      "y": 3,
      "z": -4,
      "name": "Rock_Aqua"
    },
    {
      "x": 1,
      "y": 4,
      "z": -4,
      "name": "Rock_Aqua_Stalactite_Small"
    },
    {
      "x": 1,
      "y": 6,
      "z": -4,
      "name": "Rock_Aqua_Brick_Smooth"
    },
    {
      "x": 1,
      "y": 7,
      "z": -4,
      "name": "Rock_Aqua_Brick_Smooth"
    },
    {
      "x": 1,
      "y": 8,
      "z": -4,
      "name": "Rock_Aqua_Brick_Smooth_Half"
    },
    {
      "x": 1,
      "y": 0,
      "z": -3,
      "name": "Rock_Aqua"
    },
    {
      "x": 1,
      "y": 1,
      "z": -3,
      "name": "Rock_Aqua"
    },
    {
      "x": 1,
      "y": 2,
      "z": -3,
      "name": "Rock_Aqua"
    },
    {
      "x": 1,
      "y": 3,
      "z": -3,
      "name": "Rock_Runic_Blue_Brick"
    },
    {
      "x": 1,
      "y": 4,
      "z": -3,
      "name": "Cloth_Roof_Blue_Flat"
    },
    {
      "x": 1,
      "y": 0,
      "z": -2,
      "name": "Rock_Aqua"
    },
    {
      "x": 1,
      "y": 1,
      "z": -2,
      "name": "Rock_Aqua"
    },
    {
      "x": 1,
      "y": 2,
      "z": -2,
      "name": "Rock_Aqua"
    },
    {
      "x": 1,
      "y": 3,
      "z": -2,
      "name": "Rock_Runic_Blue_Brick"
    },
    {
      "x": 1,
      "y": 0,
      "z": -1,
      "name": "Rock_Aqua"
    },
    {
      "x": 1,
      "y": 1,
      "z": -1,
      "name": "Rock_Aqua"
    },
    {
      "x": 1,
      "y": 2,
      "z": -1,
      "name": "Rock_Aqua"
    },
    {
      "x": 1,
      "y": 3,
      "z": -1,
      "name": "Rock_Runic_Blue_Brick"
    },
    {
      "x": 1,
      "y": 4,
      "z": -1,
      "name": "Cloth_Roof_Blue_Flat"
    },
    {
      "x": 1,
      "y": 6,
      "z": -1,
      "name": "Plant_Leaves_Camphor",
      "support": 15
    },
    {
      "x": 1,
      "y": 0,
      "z": 0,
      "name": "Rock_Aqua"
    },
    {
      "x": 1,
      "y": 1,
      "z": 0,
      "name": "Rock_Aqua"
    },
    {
      "x": 1,
      "y": 2,
      "z": 0,
      "name": "Rock_Aqua"
    },
    {
      "x": 1,
      "y": 3,
      "z": 0,
      "name": "Rock_Aqua"
    },
    {
      "x": 1,
      "y": 4,
      "z": 0,
      "name": "Plant_Moss_Wall_Blue",
      "support": 15,
      "rotation": 3
    },
    {
      "x": 1,
      "y": 5,
      "z": 0,
      "name": "Rock_Aqua_Brick_Smooth"
    },
    {
      "x": 1,
      "y": 6,
      "z": 0,
      "name": "Rock_Aqua_Brick_Smooth"
    },
    {
      "x": 1,
      "y": 7,
      "z": 0,
      "name": "Rock_Aqua_Brick_Smooth"
    },
    {
      "x": 1,
      "y": 8,
      "z": 0,
      "name": "Rock_Aqua_Cobble_Roof_Flat",
      "rotation": 1
    },
    {
      "x": 1,
      "y": 0,
      "z": 1,
      "name": "Rock_Aqua"
    },
    {
      "x": 1,
      "y": 1,
      "z": 1,
      "name": "Rock_Aqua"
    },
    {
      "x": 1,
      "y": 2,
      "z": 1,
      "name": "Rock_Aqua",
      "support": 15
    },
    {
      "x": 1,
      "y": 3,
      "z": 1,
      "name": "Plant_Moss_Block_Blue"
    },
    {
      "x": 1,
      "y": 4,
      "z": 1,
      "name": "Plant_Crop_Mushroom_Flatcap_Green",
      "components": {
        "Components": {
          "FarmingBlock": {
            "LastTickGameTime": "0001-01-01T12:00:00Z"
          }
        }
      }
    },
    {
      "x": 1,
      "y": 0,
      "z": 2,
      "name": "Rock_Aqua"
    },
    {
      "x": 1,
      "y": 1,
      "z": 2,
      "name": "Rock_Aqua"
    },
    {
      "x": 1,
      "y": 2,
      "z": 2,
      "name": "Rock_Aqua"
    },
    {
      "x": 1,
      "y": 3,
      "z": 2,
      "name": "Rock_Aqua",
      "support": 15
    },
    {
      "x": 1,
      "y": 4,
      "z": 2,
      "name": "Plant_Moss_Short_Blue"
    },
    {
      "x": 1,
      "y": 0,
      "z": 3,
      "name": "Rock_Aqua"
    },
    {
      "x": 1,
      "y": 1,
      "z": 3,
      "name": "Rock_Aqua"
    },
    {
      "x": 1,
      "y": 2,
      "z": 3,
      "name": "Rock_Aqua"
    },
    {
      "x": 1,
      "y": 3,
      "z": 3,
      "name": "Rock_Aqua"
    },
    {
      "x": 1,
      "y": 0,
      "z": 4,
      "name": "Rock_Aqua_Stairs",
      "rotation": 10
    },
    {
      "x": 1,
      "y": 1,
      "z": 4,
      "name": "Rock_Aqua"
    },
    {
      "x": 2,
      "y": 0,
      "z": -4,
      "name": "Rock_Aqua_Stairs",
      "rotation": 8
    },
    {
      "x": 2,
      "y": 1,
      "z": -4,
      "name": "Rock_Aqua"
    },
    {
      "x": 2,
      "y": 2,
      "z": -4,
      "name": "Rock_Aqua"
    },
    {
      "x": 2,
      "y": 3,
      "z": -4,
      "name": "Rock_Aqua"
    },
    {
      "x": 2,
      "y": 4,
      "z": -4,
      "name": "Rock_Aqua_Brick_Decorative"
    },
    {
      "x": 2,
      "y": 5,
      "z": -4,
      "name": "Rock_Aqua_Brick_Smooth"
    },
    {
      "x": 2,
      "y": 6,
      "z": -4,
      "name": "Rock_Aqua_Brick_Smooth"
    },
    {
      "x": 2,
      "y": 7,
      "z": -4,
      "name": "Rock_Aqua_Brick_Smooth"
    },
    {
      "x": 2,
      "y": 8,
      "z": -4,
      "name": "Rock_Aqua_Brick_Smooth",
      "support": 15
    },
    {
      "x": 2,
      "y": 9,
      "z": -4,
      "name": "Rubble_Aqua"
    },
    {
      "x": 2,
      "y": 0,
      "z": -3,
      "name": "Rock_Aqua"
    },
    {
      "x": 2,
      "y": 1,
      "z": -3,
      "name": "Rock_Aqua"
    },
    {
      "x": 2,
      "y": 2,
      "z": -3,
      "name": "Rock_Aqua"
    },
    {
      "x": 2,
      "y": 3,
      "z": -3,
      "name": "*Rock_Runic_Blue_Brick_Stairs_State_Definitions_Inverted_Corner_Left"
    },
    {
      "x": 2,
      "y": 0,
      "z": -2,
      "name": "Rock_Aqua"
    },
    {
      "x": 2,
      "y": 1,
      "z": -2,
      "name": "Rock_Aqua"
    },
    {
      "x": 2,
      "y": 2,
      "z": -2,
      "name": "Rock_Aqua"
    },
    {
      "x": 2,
      "y": 3,
      "z": -2,
      "name": "Rock_Runic_Blue_Brick_Stairs",
      "rotation": 1
    },
    {
      "x": 2,
      "y": 0,
      "z": -1,
      "name": "Rock_Aqua"
    },
    {
      "x": 2,
      "y": 1,
      "z": -1,
      "name": "Rock_Aqua"
    },
    {
      "x": 2,
      "y": 2,
      "z": -1,
      "name": "Rock_Aqua"
    },
    {
      "x": 2,
      "y": 3,
      "z": -1,
      "name": "Rock_Runic_Blue_Brick"
    },
    {
      "x": 2,
      "y": 0,
      "z": 0,
      "name": "Rock_Aqua"
    },
    {
      "x": 2,
      "y": 1,
      "z": 0,
      "name": "Rock_Aqua"
    },
    {
      "x": 2,
      "y": 2,
      "z": 0,
      "name": "Rock_Aqua"
    },
    {
      "x": 2,
      "y": 3,
      "z": 0,
      "name": "Rock_Aqua"
    },
    {
      "x": 2,
      "y": 4,
      "z": 0,
      "name": "Rock_Aqua_Brick_Decorative"
    },
    {
      "x": 2,
      "y": 5,
      "z": 0,
      "name": "Rock_Aqua_Brick_Smooth"
    },
    {
      "x": 2,
      "y": 6,
      "z": 0,
      "name": "Rock_Aqua_Brick_Smooth"
    },
    {
      "x": 2,
      "y": 0,
      "z": 1,
      "name": "Rock_Aqua"
    },
    {
      "x": 2,
      "y": 1,
      "z": 1,
      "name": "Rock_Aqua"
    },
    {
      "x": 2,
      "y": 2,
      "z": 1,
      "name": "Rock_Aqua",
      "support": 15
    },
    {
      "x": 2,
      "y": 3,
      "z": 1,
      "name": "Plant_Moss_Block_Blue",
      "support": 15
    },
    {
      "x": 2,
      "y": 4,
      "z": 1,
      "name": "Plant_Moss_Rug_Blue"
    },
    {
      "x": 2,
      "y": 6,
      "z": 1,
      "name": "Rock_Aqua_Brick_Smooth_Half",
      "rotation": 4
    },
    {
      "x": 2,
      "y": 0,
      "z": 2,
      "name": "Rock_Aqua"
    },
    {
      "x": 2,
      "y": 1,
      "z": 2,
      "name": "Rock_Aqua"
    },
    {
      "x": 2,
      "y": 2,
      "z": 2,
      "name": "Rock_Aqua",
      "support": 15
    },
    {
      "x": 2,
      "y": 3,
      "z": 2,
      "name": "Plant_Moss_Block_Blue"
    },
    {
      "x": 2,
      "y": 0,
      "z": 3,
      "name": "Rock_Aqua"
    },
    {
      "x": 2,
      "y": 1,
      "z": 3,
      "name": "Rock_Aqua"
    },
    {
      "x": 2,
      "y": 0,
      "z": 4,
      "name": "Rock_Aqua_Stairs",
      "rotation": 10
    },
    {
      "x": 2,
      "y": 1,
      "z": 4,
      "name": "Rock_Aqua"
    },
    {
      "x": 3,
      "y": 0,
      "z": -4,
      "name": "Rock_Aqua_Stairs",
      "rotation": 8
    },
    {
      "x": 3,
      "y": 1,
      "z": -4,
      "name": "Rock_Aqua"
    },
    {
      "x": 3,
      "y": 2,
      "z": -4,
      "name": "Rock_Aqua"
    },
    {
      "x": 3,
      "y": 3,
      "z": -4,
      "name": "Rock_Aqua"
    },
    {
      "x": 3,
      "y": 4,
      "z": -4,
      "name": "Rock_Aqua_Brick_Decorative"
    },
    {
      "x": 3,
      "y": 5,
      "z": -4,
      "name": "Rock_Aqua_Brick_Smooth"
    },
    {
      "x": 3,
      "y": 6,
      "z": -4,
      "name": "Rock_Aqua_Brick_Smooth"
    },
    {
      "x": 3,
      "y": 7,
      "z": -4,
      "name": "Rock_Aqua_Brick_Smooth"
    },
    {
      "x": 3,
      "y": 8,
      "z": -4,
      "name": "Rock_Aqua_Brick_Smooth"
    },
    {
      "x": 3,
      "y": 9,
      "z": -4,
      "name": "Rock_Aqua_Brick_Smooth_Half"
    },
    {
      "x": 3,
      "y": 0,
      "z": -3,
      "name": "Rock_Aqua"
    },
    {
      "x": 3,
      "y": 1,
      "z": -3,
      "name": "Rock_Aqua"
    },
    {
      "x": 3,
      "y": 2,
      "z": -3,
      "name": "Rock_Aqua"
    },
    {
      "x": 3,
      "y": 3,
      "z": -3,
      "name": "Rock_Runic_Blue_Brick"
    },
    {
      "x": 3,
      "y": 4,
      "z": -3,
      "name": "Rock_Aqua_Brick_Beam"
    },
    {
      "x": 3,
      "y": 5,
      "z": -3,
      "name": "Furniture_Human_Ruins_Lantern"
    },
    {
      "x": 3,
      "y": 7,
      "z": -3,
      "name": "Plant_Leaves_Camphor"
    },
    {
      "x": 3,
      "y": 0,
      "z": -2,
      "name": "Rock_Aqua"
    },
    {
      "x": 3,
      "y": 1,
      "z": -2,
      "name": "Rock_Aqua"
    },
    {
      "x": 3,
      "y": 2,
      "z": -2,
      "name": "Rock_Aqua"
    },
    {
      "x": 3,
      "y": 3,
      "z": -2,
      "name": "Rock_Runic_Blue_Brick"
    },
    {
      "x": 3,
      "y": 4,
      "z": -2,
      "name": "Cloth_Roof_Blue_Flat"
    },
    {
      "x": 3,
      "y": 0,
      "z": -1,
      "name": "Rock_Aqua"
    },
    {
      "x": 3,
      "y": 1,
      "z": -1,
      "name": "Rock_Aqua"
    },
    {
      "x": 3,
      "y": 2,
      "z": -1,
      "name": "Rock_Aqua"
    },
    {
      "x": 3,
      "y": 3,
      "z": -1,
      "name": "Rock_Runic_Blue_Brick_Stairs",
      "support": 15
    },
    {
      "x": 3,
      "y": 4,
      "z": -1,
      "name": "Plant_Leaves_Camphor",
      "support": 15
    },
    {
      "x": 3,
      "y": 0,
      "z": 0,
      "name": "Rock_Aqua"
    },
    {
      "x": 3,
      "y": 1,
      "z": 0,
      "name": "Rock_Aqua"
    },
    {
      "x": 3,
      "y": 2,
      "z": 0,
      "name": "Rock_Aqua"
    },
    {
      "x": 3,
      "y": 3,
      "z": 0,
      "name": "Rock_Aqua"
    },
    {
      "x": 3,
      "y": 4,
      "z": 0,
      "name": "Rock_Aqua_Brick_Decorative"
    },
    {
      "x": 3,
      "y": 5,
      "z": 0,
      "name": "Rock_Aqua_Brick_Smooth"
    },
    {
      "x": 3,
      "y": 6,
      "z": 0,
      "name": "Rock_Aqua_Brick_Smooth_Half"
    },
    {
      "x": 3,
      "y": 0,
      "z": 1,
      "name": "Rock_Aqua"
    },
    {
      "x": 3,
      "y": 1,
      "z": 1,
      "name": "Rock_Aqua"
    },
    {
      "x": 3,
      "y": 2,
      "z": 1,
      "name": "Rock_Aqua",
      "support": 15
    },
    {
      "x": 3,
      "y": 3,
      "z": 1,
      "name": "Plant_Moss_Block_Blue",
      "support": 15
    },
    {
      "x": 3,
      "y": 4,
      "z": 1,
      "name": "Plant_Moss_Short_Blue"
    },
    {
      "x": 3,
      "y": 5,
      "z": 1,
      "name": "Plant_Moss_Wall_Blue",
      "support": 15
    },
    {
      "x": 3,
      "y": 0,
      "z": 2,
      "name": "Rock_Aqua"
    },
    {
      "x": 3,
      "y": 1,
      "z": 2,
      "name": "Rock_Aqua"
    },
    {
      "x": 3,
      "y": 2,
      "z": 2,
      "name": "Rock_Aqua"
    },
    {
      "x": 3,
      "y": 3,
      "z": 2,
      "name": "Rock_Aqua",
      "support": 15
    },
    {
      "x": 3,
      "y": 4,
      "z": 2,
      "name": "Rubble_Aqua"
    },
    {
      "x": 3,
      "y": 0,
      "z": 3,
      "name": "Rock_Aqua"
    },
    {
      "x": 3,
      "y": 1,
      "z": 3,
      "name": "Rock_Aqua"
    },
    {
      "x": 3,
      "y": 2,
      "z": 3,
      "name": "Rock_Aqua"
    },
    {
      "x": 3,
      "y": 3,
      "z": 3,
      "name": "Rock_Aqua",
      "support": 15
    },
    {
      "x": 3,
      "y": 4,
      "z": 3,
      "name": "Plant_Moss_Rug_Blue"
    },
    {
      "x": 3,
      "y": 0,
      "z": 4,
      "name": "Rock_Aqua_Stairs",
      "rotation": 10
    },
    {
      "x": 3,
      "y": 1,
      "z": 4,
      "name": "Rock_Aqua"
    },
    {
      "x": 3,
      "y": 2,
      "z": 4,
      "name": "Rock_Aqua"
    },
    {
      "x": 3,
      "y": 3,
      "z": 4,
      "name": "Rock_Aqua"
    },
    {
      "x": 3,
      "y": 4,
      "z": 4,
      "name": "Rock_Aqua_Brick_Wall"
    },
    {
      "x": 4,
      "y": 0,
      "z": -4,
      "name": "*Rock_Aqua_Stairs_State_Definitions_Corner_Left",
      "rotation": 8
    },
    {
      "x": 4,
      "y": 1,
      "z": -4,
      "name": "Rock_Aqua"
    },
    {
      "x": 4,
      "y": 0,
      "z": -3,
      "name": "Rock_Aqua_Stairs",
      "rotation": 11
    },
    {
      "x": 4,
      "y": 1,
      "z": -3,
      "name": "Rock_Aqua"
    },
    {
      "x": 4,
      "y": 2,
      "z": -3,
      "name": "Rock_Aqua"
    },
    {
      "x": 4,
      "y": 3,
      "z": -3,
      "name": "Rock_Aqua",
      "support": 15
    },
    {
      "x": 4,
      "y": 4,
      "z": -3,
      "name": "Rubble_Aqua_Medium"
    },
    {
      "x": 4,
      "y": 7,
      "z": -3,
      "name": "Rock_Aqua_Brick_Smooth"
    },
    {
      "x": 4,
      "y": 8,
      "z": -3,
      "name": "Rock_Aqua_Brick_Smooth"
    },
    {
      "x": 4,
      "y": 9,
      "z": -3,
      "name": "Rock_Aqua_Cobble_Roof_Flat",
      "rotation": 1
    },
    {
      "x": 4,
      "y": 0,
      "z": -2,
      "name": "Rock_Aqua_Stairs",
      "rotation": 11
    },
    {
      "x": 4,
      "y": 1,
      "z": -2,
      "name": "Rock_Aqua"
    },
    {
      "x": 4,
      "y": 2,
      "z": -2,
      "name": "Rock_Aqua"
    },
    {
      "x": 4,
      "y": 3,
      "z": -2,
      "name": "Rock_Aqua"
    },
    {
      "x": 4,
      "y": 4,
      "z": -2,
      "name": "Rock_Aqua_Brick_Decorative"
    },
    {
      "x": 4,
      "y": 5,
      "z": -2,
      "name": "Furniture_Temple_Dark_Window",
      "rotation": 1
    },
    {
      "x": 4,
      "y": 0,
      "z": -1,
      "name": "Rock_Aqua_Stairs",
      "rotation": 11
    },
    {
      "x": 4,
      "y": 1,
      "z": -1,
      "name": "Rock_Aqua"
    },
    {
      "x": 4,
      "y": 2,
      "z": -1,
      "name": "Rock_Aqua"
    },
    {
      "x": 4,
      "y": 3,
      "z": -1,
      "name": "Rock_Aqua"
    },
    {
      "x": 4,
      "y": 4,
      "z": -1,
      "name": "Rock_Aqua_Brick_Decorative"
    },
    {
      "x": 4,
      "y": 5,
      "z": -1,
      "name": "Rock_Aqua_Brick_Smooth"
    },
    {
      "x": 4,
      "y": 6,
      "z": -1,
      "name": "Rock_Aqua_Brick_Smooth",
      "support": 15
    },
    {
      "x": 4,
      "y": 7,
      "z": -1,
      "name": "Rubble_Aqua_Medium"
    },
    {
      "x": 4,
      "y": 0,
      "z": 0,
      "name": "Rock_Aqua_Stairs",
      "rotation": 11
    },
    {
      "x": 4,
      "y": 1,
      "z": 0,
      "name": "Rock_Aqua"
    },
    {
      "x": 4,
      "y": 2,
      "z": 0,
      "name": "Rock_Aqua"
    },
    {
      "x": 4,
      "y": 3,
      "z": 0,
      "name": "Rock_Aqua"
    },
    {
      "x": 4,
      "y": 4,
      "z": 0,
      "name": "Rock_Aqua_Brick_Wall",
      "rotation": 1
    },
    {
      "x": 4,
      "y": 0,
      "z": 1,
      "name": "Rock_Aqua_Stairs",
      "rotation": 11
    },
    {
      "x": 4,
      "y": 1,
      "z": 1,
      "name": "Rock_Aqua"
    },
    {
      "x": 4,
      "y": 2,
      "z": 1,
      "name": "Rock_Aqua"
    },
    {
      "x": 4,
      "y": 3,
      "z": 1,
      "name": "Rock_Aqua"
    },
    {
      "x": 4,
      "y": 4,
      "z": 1,
      "name": "Rock_Aqua_Brick_Wall",
      "rotation": 1
    },
    {
      "x": 4,
      "y": 0,
      "z": 2,
      "name": "Rock_Aqua_Stairs",
      "rotation": 11
    },
    {
      "x": 4,
      "y": 1,
      "z": 2,
      "name": "Rock_Aqua"
    },
    {
      "x": 4,
      "y": 2,
      "z": 2,
      "name": "Rock_Aqua"
    },
    {
      "x": 4,
      "y": 3,
      "z": 2,
      "name": "Rock_Aqua"
    },
    {
      "x": 4,
      "y": 0,
      "z": 3,
      "name": "Rock_Aqua_Stairs",
      "rotation": 11
    },
    {
      "x": 4,
      "y": 1,
      "z": 3,
      "name": "Rock_Aqua"
    },
    {
      "x": 4,
      "y": 2,
      "z": 3,
      "name": "Rock_Aqua"
    },
    {
      "x": 4,
      "y": 3,
      "z": 3,
      "name": "Rock_Aqua"
    },
    {
      "x": 4,
      "y": 4,
      "z": 3,
      "name": "Rock_Aqua_Brick_Wall",
      "rotation": 1
    },
    {
      "x": 4,
      "y": 0,
      "z": 4,
      "name": "*Rock_Aqua_Stairs_State_Definitions_Corner_Left",
      "rotation": 11
    },
    {
      "x": 4,
      "y": 1,
      "z": 4,
      "name": "Rock_Aqua"
    },
    {
      "x": 4,
      "y": 2,
      "z": 4,
      "name": "Rock_Aqua"
    },
    {
      "x": 4,
      "y": 3,
      "z": 4,
      "name": "Rock_Aqua"
    },
    {
      "x": 4,
      "y": 4,
      "z": 4,
      "name": "*Rock_Aqua_Brick_Wall_State_Definitions_Corner",
      "rotation": 3
    }
  ],
  "fluids": [
    {
      "x": -4,
      "y": 5,
      "z": -1,
      "name": "Water_Source",
      "level": 1
    },
    {
      "x": -4,
      "y": 4,
      "z": 1,
      "name": "Water_Source",
      "level": 1
    },
    {
      "x": -4,
      "y": 4,
      "z": 2,
      "name": "Water_Source",
      "level": 1
    },
    {
      "x": -3,
      "y": 5,
      "z": -4,
      "name": "Water_Source",
      "level": 1
    },
    {
      "x": -3,
      "y": 4,
      "z": -1,
      "name": "Water_Source",
      "level": 1
    },
    {
      "x": -3,
      "y": 4,
      "z": 0,
      "name": "Water_Source",
      "level": 1
    },
    {
      "x": -3,
      "y": 4,
      "z": 1,
      "name": "Water_Source",
      "level": 1
    },
    {
      "x": -3,
      "y": 4,
      "z": 2,
      "name": "Water_Source",
      "level": 1
    },
    {
      "x": -3,
      "y": 3,
      "z": 3,
      "name": "Water_Source",
      "level": 1
    },
    {
      "x": -3,
      "y": 4,
      "z": 3,
      "name": "Water_Source",
      "level": 1
    },
    {
      "x": -2,
      "y": 4,
      "z": -3,
      "name": "Water_Source",
      "level": 1
    },
    {
      "x": -2,
      "y": 4,
      "z": -1,
      "name": "Water_Source",
      "level": 1
    },
    {
      "x": -2,
      "y": 4,
      "z": 0,
      "name": "Water_Source",
      "level": 1
    },
    {
      "x": -2,
      "y": 3,
      "z": 1,
      "name": "Water_Source",
      "level": 1
    },
    {
      "x": -2,
      "y": 4,
      "z": 1,
      "name": "Water_Source",
      "level": 1
    },
    {
      "x": -2,
      "y": 3,
      "z": 2,
      "name": "Water_Source",
      "level": 1
    },
    {
      "x": -2,
      "y": 4,
      "z": 2,
      "name": "Water_Source",
      "level": 1
    },
    {
      "x": -2,
      "y": 4,
      "z": 3,
      "name": "Water_Source",
      "level": 1
    },
    {
      "x": -2,
      "y": 4,
      "z": 4,
      "name": "Water_Source",
      "level": 1
    },
    {
      "x": -1,
      "y": 4,
      "z": -4,
      "name": "Water_Source",
      "level": 1
    },
    {
      "x": -1,
      "y": 4,
      "z": -3,
      "name": "Water_Source",
      "level": 1
    },
    {
      "x": -1,
      "y": 4,
      "z": -2,
      "name": "Water_Source",
      "level": 1
    },
    {
      "x": -1,
      "y": 3,
      "z": -1,
      "name": "Water_Source",
      "level": 1
    },
    {
      "x": -1,
      "y": 4,
      "z": -1,
      "name": "Water_Source",
      "level": 1
    },
    {
      "x": -1,
      "y": 4,
      "z": 0,
      "name": "Water_Source",
      "level": 1
    },
    {
      "x": -1,
      "y": 5,
      "z": 1,
      "name": "Water_Source",
      "level": 1
    },
    {
      "x": -1,
      "y": 5,
      "z": 2,
      "name": "Water_Source",
      "level": 1
    },
    {
      "x": -1,
      "y": 5,
      "z": 3,
      "name": "Water_Source",
      "level": 1
    },
    {
      "x": -1,
      "y": 4,
      "z": 4,
      "name": "Water_Source",
      "level": 1
    },
    {
      "x": 0,
      "y": 4,
      "z": -3,
      "name": "Water_Source",
      "level": 1
    },
    {
      "x": 0,
      "y": 4,
      "z": -2,
      "name": "Water_Source",
      "level": 1
    },
    {
      "x": 0,
      "y": 8,
      "z": -2,
      "name": "Water_Source",
      "level": 1
    },
    {
      "x": 0,
      "y": 8,
      "z": -1,
      "name": "Water_Source",
      "level": 1
    },
    {
      "x": 0,
      "y": 4,
      "z": 0,
      "name": "Water_Source",
      "level": 1
    },
    {
      "x": 0,
      "y": 4,
      "z": 1,
      "name": "Water_Source",
      "level": 1
    },
    {
      "x": 0,
      "y": 4,
      "z": 2,
      "name": "Water_Source",
      "level": 1
    },
    {
      "x": 0,
      "y": 4,
      "z": 3,
      "name": "Water_Source",
      "level": 1
    },
    {
      "x": 0,
      "y": 4,
      "z": 4,
      "name": "Water_Source",
      "level": 1
    },
    {
      "x": 1,
      "y": 4,
      "z": -4,
      "name": "Water_Source",
      "level": 1
    },
    {
      "x": 1,
      "y": 8,
      "z": -4,
      "name": "Water_Source",
      "level": 1
    },
    {
      "x": 1,
      "y": 4,
      "z": -3,
      "name": "Water_Source",
      "level": 1
    },
    {
      "x": 1,
      "y": 4,
      "z": -2,
      "name": "Water_Source",
      "level": 1
    },
    {
      "x": 1,
      "y": 4,
      "z": -1,
      "name": "Water_Source",
      "level": 1
    },
    {
      "x": 1,
      "y": 6,
      "z": -1,
      "name": "Water_Source",
      "level": 1
    },
    {
      "x": 1,
      "y": 4,
      "z": 0,
      "name": "Water_Source",
      "level": 1
    },
    {
      "x": 1,
      "y": 8,
      "z": 0,
      "name": "Water_Source",
      "level": 1
    },
    {
      "x": 1,
      "y": 4,
      "z": 1,
      "name": "Water_Source",
      "level": 1
    },
    {
      "x": 1,
      "y": 4,
      "z": 2,
      "name": "Water_Source",
      "level": 1
    },
    {
      "x": 1,
      "y": 4,
      "z": 3,
      "name": "Water_Source",
      "level": 1
    },
    {
      "x": 2,
      "y": 9,
      "z": -4,
      "name": "Water_Source",
      "level": 1
    },
    {
      "x": 2,
      "y": 3,
      "z": -3,
      "name": "Water_Source",
      "level": 1
    },
    {
      "x": 2,
      "y": 4,
      "z": -3,
      "name": "Water_Source",
      "level": 1
    },
    {
      "x": 2,
      "y": 3,
      "z": -2,
      "name": "Water_Source",
      "level": 1
    },
    {
      "x": 2,
      "y": 4,
      "z": -2,
      "name": "Water_Source",
      "level": 1
    },
    {
      "x": 2,
      "y": 4,
      "z": -1,
      "name": "Water_Source",
      "level": 1
    },
    {
      "x": 2,
      "y": 4,
      "z": 1,
      "name": "Water_Source",
      "level": 1
    },
    {
      "x": 2,
      "y": 6,
      "z": 1,
      "name": "Water_Source",
      "level": 1
    },
    {
      "x": 2,
      "y": 4,
      "z": 2,
      "name": "Water_Source",
      "level": 1
    },
    {
      "x": 3,
      "y": 9,
      "z": -4,
      "name": "Water_Source",
      "level": 1
    },
    {
      "x": 3,
      "y": 4,
      "z": -3,
      "name": "Water_Source",
      "level": 1
    },
    {
      "x": 3,
      "y": 5,
      "z": -3,
      "name": "Water_Source",
      "level": 1
    },
    {
      "x": 3,
      "y": 7,
      "z": -3,
      "name": "Water_Source",
      "level": 1
    },
    {
      "x": 3,
      "y": 4,
      "z": -2,
      "name": "Water_Source",
      "level": 1
    },
    {
      "x": 3,
      "y": 4,
      "z": -1,
      "name": "Water_Source",
      "level": 1
    },
    {
      "x": 3,
      "y": 6,
      "z": 0,
      "name": "Water_Source",
      "level": 1
    },
    {
      "x": 3,
      "y": 4,
      "z": 1,
      "name": "Water_Source",
      "level": 1
    },
    {
      "x": 3,
      "y": 5,
      "z": 1,
      "name": "Water_Source",
      "level": 1
    },
    {
      "x": 3,
      "y": 4,
      "z": 2,
      "name": "Water_Source",
      "level": 1
    },
    {
      "x": 3,
      "y": 4,
      "z": 3,
      "name": "Water_Source",
      "level": 1
    },
    {
      "x": 3,
      "y": 4,
      "z": 4,
      "name": "Water_Source",
      "level": 1
    },
    {
      "x": 4,
      "y": 4,
      "z": -3,
      "name": "Water_Source",
      "level": 1
    },
    {
      "x": 4,
      "y": 9,
      "z": -3,
      "name": "Water_Source",
      "level": 1
    },
    {
      "x": 4,
      "y": 5,
      "z": -2,
      "name": "Water_Source",
      "level": 1
    },
    {
      "x": 4,
      "y": 7,
      "z": -1,
      "name": "Water_Source",
      "level": 1
    },
    {
      "x": 4,
      "y": 4,
      "z": 0,
      "name": "Water_Source",
      "level": 1
    },
    {
      "x": 4,
      "y": 4,
      "z": 1,
      "name": "Water_Source",
      "level": 1
    },
    {
      "x": 4,
      "y": 4,
      "z": 2,
      "name": "Water_Source",
      "level": 1
    },
    {
      "x": 4,
      "y": 4,
      "z": 3,
      "name": "Water_Source",
      "level": 1
    },
    {
      "x": 4,
      "y": 4,
      "z": 4,
      "name": "Water_Source",
      "level": 1
    }
  ]
}