{
  "version": 8,
  "blockIdVersion": 11,
  "anchorX": 0,
  "anchorY": 2,
  "anchorZ": 0,
  "blocks": [
    {
      "x": -8,
      "y": 19,
      "z": 0,
      "name": "Plant_Coral_Block_Orange"
    },
    {
      "x": -8,
      "y": 19,
      "z": 1,
      "name": "Plant_Coral_Block_Orange"
    },
    {
      "x": -8,
      "y": 19,
      "z": 2,
      "name": "Plant_Coral_Block_Orange"
    },
    {
      "x": -8,
      "y": 19,
      "z": 4,
      "name": "Plant_Coral_Block_Orange"
    },
    {
      "x": -8,
      "y": 19,
      "z": 5,
      "name": "Plant_Coral_Block_Orange"
    },
    {
      "x": -7,
      "y": 9,
      "z": -6,
      "name": "Plant_Coral_Block_Orange"
    },
    {
      "x": -7,
      "y": 9,
      "z": -5,
      "name": "Plant_Coral_Block_Orange"
    },
    {
      "x": -7,
      "y": 9,
      "z": -4,
      "name": "Plant_Coral_Block_Orange"
    },
    {
      "x": -7,
      "y": 9,
      "z": -2,
      "name": "Plant_Coral_Block_Orange"
    },
    {
      "x": -7,
      "y": 9,
      "z": -1,
      "name": "Plant_Coral_Block_Orange"
    },
    {
      "x": -7,
      "y": 19,
      "z": 0,
      "name": "Plant_Coral_Block_Orange"
    },
    {
      "x": -7,
      "y": 19,
      "z": 1,
      "name": "Plant_Coral_Block_Blue"
    },
    {
      "x": -7,
      "y": 19,
      "z": 2,
      "name": "Plant_Coral_Block_Blue"
    },
    {
      "x": -7,
      "y": 19,
      "z": 3,
      "name": "Plant_Coral_Block_Blue"
    },
    {
      "x": -7,
      "y": 19,
      "z": 4,
      "name": "Plant_Coral_Block_Blue"
    },
    {
      "x": -7,
      "y": 19,
      "z": 5,
      "name": "Plant_Coral_Block_Blue"
    },
    {
      "x": -7,
      "y": 19,
      "z": 6,
      "name": "Plant_Coral_Block_Orange"
    },
    {
      "x": -6,
      "y": 8,
      "z": -5,
      "name": "Plant_Crop_Mushroom_Block_Blue_Mycelium"
    },
    {
      "x": -6,
      "y": 9,
      "z": -5,
      "name": "Plant_Coral_Block_Blue"
    },
    {
      "x": -6,
      "y": 9,
      "z": -4,
      "name": "Plant_Coral_Block_Blue"
    },
    {
      "x": -6,
      "y": 9,
      "z": -3,
      "name": "Plant_Coral_Block_Blue"
    },
    {
      "x": -6,
      "y": 9,
      "z": -2,
      "name": "Plant_Coral_Block_Blue"
    },
    {
      "x": -6,
      "y": 9,
      "z": -1,
      "name": "Plant_Coral_Block_Blue"
    },
    {
      "x": -6,
      "y": 19,
      "z": -1,
      "name": "Plant_Coral_Block_Orange"
    },
    {
      "x": -6,
      "y": 19,
      "z": 0,
      "name": "Plant_Coral_Block_Blue"
    },
    {
      "x": -6,
      "y": 9,
      "z": 1,
      "name": "Plant_Coral_Block_Orange"
    },
    {
      "x": -6,
      "y": 18,
      "z": 1,
      "name": "Plant_Crop_Mushroom_Block_Blue_Mycelium"
    },
    {
      "x": -6,
      "y": 19,
      "z": 1,
      "name": "Plant_Coral_Block_Blue"
    },
    {
      "x": -6,
      "y": 18,
      "z": 2,
      "name": "Plant_Crop_Mushroom_Block_Blue_Mycelium"
    },
    {
      "x": -6,
      "y": 19,
      "z": 2,
      "name": "Plant_Coral_Block_Blue"
    },
    {
      "x": -6,
      "y": 20,
      "z": 2,
      "name": "Plant_Coral_Model_Blue"
    },
    {
      "x": -6,
      "y": 19,
      "z": 3,
      "name": "Plant_Coral_Block_Blue"
    },
    {
      "x": -6,
      "y": 18,
      "z": 4,
      "name": "Plant_Crop_Mushroom_Block_Blue_Mycelium"
    },
    {
      "x": -6,
      "y": 19,
      "z": 4,
      "name": "Plant_Coral_Block_Blue"
    },
    {
      "x": -6,
      "y": 20,
      "z": 4,
      "name": "Plant_Coral_Bush_Blue"
    },
    {
      "x": -6,
      "y": 19,
      "z": 5,
      "name": "Plant_Coral_Block_Blue"
    },
    {
      "x": -6,
      "y": 19,
      "z": 6,
      "name": "Plant_Coral_Block_Blue"
    },
    {
      "x": -6,
      "y": 19,
      "z": 8,
      "name": "Plant_Coral_Block_Orange"
    },
    {
      "x": -5,
      "y": 9,
      "z": -8,
      "name": "Plant_Coral_Block_Orange"
    },
    {
      "x": -5,
      "y": 9,
      "z": -7,
      "name": "Plant_Coral_Block_Orange"
    },
    {
      "x": -5,
      "y": 9,
      "z": -6,
      "name": "Plant_Coral_Block_Blue"
    },
    {
      "x": -5,
      "y": 9,
      "z": -5,
      "name": "Plant_Coral_Block_Blue"
    },
    {
      "x": -5,
      "y": 9,
      "z": -4,
      "name": "Plant_Coral_Block_Blue"
    },
    {
      "x": -5,
      "y": 10,
      "z": -4,
      "name": "Plant_Coral_Bush_Blue"
    },
    {
      "x": -5,
      "y": 9,
      "z": -3,
      "name": "Plant_Coral_Block_Blue"
    },
    {
      "x": -5,
      "y": 10,
      "z": -3,
      "name": "Plant_Coral_Model_Blue"
    },
    {
      "x": -5,
      "y": 8,
      "z": -2,
      "name": "Plant_Crop_Mushroom_Block_Blue_Mycelium"
    },
    {
      "x": -5,
      "y": 9,
      "z": -2,
      "name": "Plant_Coral_Block_Blue"
    },
    {
      "x": -5,
      "y": 10,
      "z": -2,
      "name": "Plant_Coral_Bush_Blue"
    },
    {
      "x": -5,
      "y": 9,
      "z": -1,
      "name": "Plant_Coral_Block_Blue"
    },
    {
      "x": -5,
      "y": 10,
      "z": -1,
      "name": "Rock_Crystal_Cyan_Small"
    },
    {
      "x": -5,
      "y": 19,
      "z": -1,
      "name": "Plant_Coral_Block_Blue"
    },
    {
      "x": -5,
      "y": 8,
      "z": 0,
      "name": "Plant_Crop_Mushroom_Block_Blue_Mycelium"
    },
    {
      "x": -5,
      "y": 9,
      "z": 0,
      "name": "Plant_Coral_Block_Blue"
    },
    {
      "x": -5,
      "y": 19,
      "z": 0,
      "name": "Plant_Coral_Block_Blue"
    },
    {
      "x": -5,
      "y": 9,
      "z": 1,
      "name": "Plant_Coral_Block_Orange"
    },
    {
      "x": -5,
      "y": 19,
      "z": 1,
      "name": "Plant_Coral_Block_Blue"
    },
    {
      "x": -5,
      "y": 20,
      "z": 1,
      "name": "Plant_Coral_Bush_Blue"
    },
    {
      "x": -5,
      "y": 9,
      "z": 2,
      "name": "Plant_Coral_Block_Orange"
    },
    {
      "x": -5,
      "y": 18,
      "z": 2,
      "name": "Rock_Crystal_Cyan_Small",
      "rotation": 8
    },
    {
      "x": -5,
      "y": 19,
      "z": 2,
      "name": "Plant_Coral_Block_Blue"
    },
    {
      "x": -5,
      "y": 20,
      "z": 2,
      "name": "Rock_Crystal_Cyan_Medium"
    },
    {
      "x": -5,
      "y": 19,
      "z": 3,
      "name": "Plant_Coral_Block_Blue"
    },
    {
      "x": -5,
      "y": 20,
      "z": 3,
      "name": "Plant_Coral_Model_Blue"
    },
    {
      "x": -5,
      "y": 19,
      "z": 4,
      "name": "Plant_Coral_Block_Blue"
    },
    {
      "x": -5,
      "y": 19,
      "z": 5,
      "name": "Plant_Coral_Block_Blue"
    },
    {
      "x": -5,
      "y": 20,
      "z": 5,
      "name": "Plant_Coral_Bush_Blue"
    },
    {
      "x": -5,
      "y": 19,
      "z": 6,
      "name": "Plant_Coral_Block_Blue"
    },
    {
      "x": -5,
      "y": 19,
      "z": 7,
      "name": "Plant_Coral_Block_Blue"
    },
    {
      "x": -5,
      "y": 19,
      "z": 8,
      "name": "Plant_Coral_Block_Orange"
    },
    {
      "x": -4,
      "y": 9,
      "z": -8,
      "name": "Plant_Coral_Block_Orange"
    },
    {
      "x": -4,
      "y": 9,
      "z": -7,
      "name": "Plant_Coral_Block_Blue"
    },
    {
      "x": -4,
      "y": 8,
      "z": -6,
      "name": "Plant_Crop_Mushroom_Block_Blue_Mycelium"
    },
    {
      "x": -4,
      "y": 9,
      "z": -6,
      "name": "Plant_Coral_Block_Blue"
    },
    {
      "x": -4,
      "y": 9,
      "z": -5,
      "name": "Plant_Coral_Block_Blue"
    },
    {
      "x": -4,
      "y": 10,
      "z": -5,
      "name": "Plant_Coral_Model_Blue"
    },
    {
      "x": -4,
      "y": 9,
      "z": -4,
      "name": "Plant_Coral_Block_Blue"
    },
    {
      "x": -4,
      "y": 9,
      "z": -3,
      "name": "Plant_Coral_Block_Blue"
    },
    {
      "x": -4,
      "y": 10,
      "z": -3,
      "name": "Plant_Coral_Bush_Blue"
    },
    {
      "x": -4,
      "y": 8,
      "z": -2,
      "name": "Rock_Crystal_Cyan_Small",
      "rotation": 8
    },
    {
      "x": -4,
      "y": 9,
      "z": -2,
      "name": "Plant_Coral_Block_Blue"
    },
    {
      "x": -4,
      "y": 10,
      "z": -2,
      "name": "Plant_Coral_Model_Blue"
    },
    {
      "x": -4,
      "y": 19,
      "z": -2,
      "name": "Plant_Coral_Block_Orange"
    },
    {
      "x": -4,
      "y": 8,
      "z": -1,
      "name": "Plant_Coral_Block_Orange"
    },
    {
      "x": -4,
      "y": 9,
      "z": -1,
      "name": "Plant_Coral_Block_Orange"
    },
    {
      "x": -4,
      "y": 10,
      "z": -1,
      "name": "Plant_Coral_Block_Orange"
    },
    {
      "x": -4,
      "y": 11,
      "z": -1,
      "name": "Plant_Coral_Block_Orange"
    },
    {
      "x": -4,
      "y": 18,
      "z": -1,
      "name": "Plant_Crop_Mushroom_Block_Blue_Mycelium"
    },
    {
      "x": -4,
      "y": 19,
      "z": -1,
      "name": "Plant_Coral_Block_Blue"
    },
    {
      "x": -4,
      "y": 20,
      "z": -1,
      "name": "Plant_Coral_Model_Blue"
    },
    {
      "x": -4,
      "y": 0,
      "z": 0,
      "name": "Plant_Coral_Block_Orange"
    },
    {
      "x": -4,
      "y": 1,
      "z": 0,
      "name": "Plant_Coral_Block_Orange"
    },
    {
      "x": -4,
      "y": 2,
      "z": 0,
      "name": "Plant_Coral_Block_Orange"
    },
    {
      "x": -4,
      "y": 3,
      "z": 0,
      "name": "Plant_Coral_Block_Orange"
    },
    {
      "x": -4,
      "y": 4,
      "z": 0,
      "name": "Plant_Coral_Block_Orange"
    },
    {
      "x": -4,
      "y": 5,
      "z": 0,
      "name": "Plant_Coral_Block_Orange"
    },
    {
      "x": -4,
      "y": 6,
      "z": 0,
      "name": "Plant_Coral_Block_Orange"
    },
    {
      "x": -4,
      "y": 7,
      "z": 0,
      "name": "Plant_Coral_Block_Orange"
    },
    {
      "x": -4,
      "y": 8,
      "z": 0,
      "name": "Plant_Coral_Block_Orange"
    },
    {
      "x": -4,
      "y": 9,
      "z": 0,
      "name": "Plant_Coral_Block_Orange"
    },
    {
      "x": -4,
      "y": 10,
      "z": 0,
      "name": "Plant_Coral_Block_Orange"
    },
    {
      "x": -4,
      "y": 11,
      "z": 0,
      "name": "Plant_Coral_Block_Orange"
    },
    {
      "x": -4,
      "y": 17,
      "z": 0,
      "name": "Plant_Coral_Block_Orange"
    },
    {
      "x": -4,
      "y": 18,
      "z": 0,
      "name": "Plant_Coral_Block_Orange"
    },
    {
      "x": -4,
      "y": 19,
      "z": 0,
      "name": "Plant_Coral_Block_Orange"
    },
    {
      "x": -4,
      "y": 20,
      "z": 0,
      "name": "Plant_Coral_Block_Orange"
    },
    {
      "x": -4,
      "y": 21,
      "z": 0,
      "name": "Plant_Coral_Block_Orange"
    },
    {
      "x": -4,
      "y": 22,
      "z": 0,
      "name": "Plant_Coral_Block_Orange"
    },
    {
      "x": -4,
      "y": 0,
      "z": 1,
      "name": "Plant_Coral_Block_Orange"
    },
    {
      "x": -4,
      "y": 1,
      "z": 1,
      "name": "Plant_Coral_Block_Orange"
    },
    {
      "x": -4,
      "y": 2,
      "z": 1,
      "name": "Plant_Coral_Block_Orange"
    },
    {
      "x": -4,
      "y": 3,
      "z": 1,
      "name": "Plant_Coral_Block_Orange"
    },
    {
      "x": -4,
      "y": 4,
      "z": 1,
      "name": "Plant_Coral_Block_Orange"
    },
    {
      "x": -4,
      "y": 5,
      "z": 1,
      "name": "Plant_Coral_Block_Orange"
    },
    {
      "x": -4,
      "y": 6,
      "z": 1,
      "name": "Plant_Coral_Block_Orange"
    },
    {
      "x": -4,
      "y": 7,
      "z": 1,
      "name": "Plant_Coral_Block_Orange"
    },
    {
      "x": -4,
      "y": 8,
      "z": 1,
      "name": "Plant_Coral_Block_Orange"
    },
    {
      "x": -4,
      "y": 9,
      "z": 1,
      "name": "Plant_Coral_Block_Orange"
    },
    {
      "x": -4,
      "y": 10,
      "z": 1,
      "name": "Plant_Coral_Block_Orange"
    },
    {
      "x": -4,
      "y": 11,
      "z": 1,
      "name": "Plant_Coral_Block_Orange"
    },
    {
      "x": -4,
      "y": 17,
      "z": 1,
      "name": "Plant_Coral_Block_Orange"
    },
    {
      "x": -4,
      "y": 18,
      "z": 1,
      "name": "Plant_Coral_Block_Orange"
    },
    {
      "x": -4,
      "y": 19,
      "z": 1,
      "name": "Plant_Coral_Block_Orange"
    },
    {
      "x": -4,
      "y": 20,
      "z": 1,
      "name": "Plant_Coral_Block_Orange"
    },
    {
      "x": -4,
      "y": 21,
      "z": 1,
      "name": "Plant_Coral_Block_Orange"
    },
    {
      "x": -4,
      "y": 22,
      "z": 1,
      "name": "Plant_Coral_Block_Orange"
    },
    {
      "x": -4,
      "y": 0,
      "z": 2,
      "name": "Plant_Coral_Block_Orange"
    },
    {
      "x": -4,
      "y": 1,
      "z": 2,
      "name": "Plant_Coral_Block_Orange"
    },
    {
      "x": -4,
      "y": 2,
      "z": 2,
      "name": "Plant_Coral_Block_Orange"
    },
    {
      "x": -4,
      "y": 3,
      "z": 2,
      "name": "Plant_Coral_Block_Orange"
    },
    {
      "x": -4,
      "y": 4,
      "z": 2,
      "name": "Plant_Coral_Block_Orange"
    },
    {
      "x": -4,
      "y": 5,
      "z": 2,
      "name": "Plant_Coral_Block_Orange"
    },
    {
      "x": -4,
      "y": 6,
      "z": 2,
      "name": "Plant_Coral_Block_Orange"
    },
    {
      "x": -4,
      "y": 7,
      "z": 2,
      "name": "Plant_Coral_Block_Orange"
    },
    {
      "x": -4,
      "y": 8,
      "z": 2,
      "name": "Plant_Coral_Model_Orange"
    },
    {
      "x": -4,
      "y": 17,
      "z": 2,
      "name": "Plant_Coral_Block_Orange"
    },
    {
      "x": -4,
      "y": 18,
      "z": 2,
      "name": "Plant_Coral_Block_Orange"
    },
    {
      "x": -4,
      "y": 19,
      "z": 2,
      "name": "Plant_Coral_Block_Orange"
    },
    {
      "x": -4,
      "y": 20,
      "z": 2,
      "name": "Plant_Coral_Block_Orange"
    },
    {
      "x": -4,
      "y": 21,
      "z": 2,
      "name": "Plant_Coral_Block_Orange"
    },
    {
      "x": -4,
      "y": 22,
      "z": 2,
      "name": "Plant_Coral_Block_Orange"
    },
    {
      "x": -4,
      "y": 19,
      "z": 3,
      "name": "Plant_Coral_Block_Blue"
    },
    {
      "x": -4,
      "y": 19,
      "z": 4,
      "name": "Plant_Coral_Block_Blue"
    },
    {
      "x": -4,
      "y": 20,
      "z": 4,
      "name": "Rock_Crystal_Cyan_Small"
    },
    {
      "x": -4,
      "y": 19,
      "z": 5,
      "name": "Plant_Coral_Block_Blue"
    },
    {
      "x": -4,
      "y": 19,
      "z": 6,
      "name": "Plant_Coral_Block_Blue"
    },
    {
      "x": -4,
      "y": 19,
      "z": 7,
      "name": "Plant_Coral_Block_Blue"
    },
    {
      "x": -4,
      "y": 19,
      "z": 8,
      "name": "Plant_Coral_Block_Orange"
    },
    {
      "x": -3,
      "y": 9,
      "z": -8,
      "name": "Plant_Coral_Block_Orange"
    },
    {
      "x": -3,
      "y": 9,
      "z": -7,
      "name": "Plant_Coral_Block_Blue"
    },
    {
      "x": -3,
      "y": 9,
      "z": -6,
      "name": "Plant_Coral_Block_Blue"
    },
    {
      "x": -3,
      "y": 9,
      "z": -5,
      "name": "Plant_Coral_Block_Blue"
    },
    {
      "x": -3,
      "y": 9,
      "z": -4,
      "name": "Plant_Coral_Block_Blue"
    },
    {
      "x": -3,
      "y": 9,
      "z": -3,
      "name": "Plant_Coral_Block_Blue"
    },
    {
      "x": -3,
      "y": 10,
      "z": -3,
      "name": "Plant_Coral_Bush_Blue"
    },
    {
      "x": -3,
      "y": 8,
      "z": -2,
      "name": "Plant_Coral_Block_Orange"
    },
    {
      "x": -3,
      "y": 9,
      "z": -2,
      "name": "Plant_Coral_Block_Orange"
    },
    {
      "x": -3,
      "y": 10,
      "z": -2,
      "name": "Plant_Coral_Block_Orange"
    },
    {
      "x": -3,
      "y": 11,
      "z": -2,
      "name": "Plant_Coral_Block_Orange"
    },
    {
      "x": -3,
      "y": 19,
      "z": -2,
      "name": "Plant_Coral_Block_Orange"
    },
    {
      "x": -3,
      "y": 20,
      "z": -2,
      "name": "Plant_Coral_Model_Orange"
    },
    {
      "x": -3,
      "y": 0,
      "z": -1,
      "name": "Plant_Coral_Block_Orange"
    },
    {
      "x": -3,
      "y": 1,
      "z": -1,
      "name": "Plant_Coral_Block_Orange"
    },
    {
      "x": -3,
      "y": 2,
      "z": -1,
      "name": "Plant_Coral_Block_Orange"
    },
    {
      "x": -3,
      "y": 3,
      "z": -1,
      "name": "Plant_Coral_Block_Orange"
    },
    {
      "x": -3,
      "y": 4,
      "z": -1,
      "name": "Plant_Coral_Block_Orange"
    },
    {
      "x": -3,
      "y": 5,
      "z": -1,
      "name": "Plant_Coral_Block_Orange"
    },
    {
      "x": -3,
      "y": 6,
      "z": -1,
      "name": "Plant_Coral_Block_Orange"
    },
    {
      "x": -3,
      "y": 7,
      "z": -1,
      "name": "Plant_Coral_Block_Orange"
    },
    {
      "x": -3,
      "y": 8,
      "z": -1,
      "name": "Rock_Crystal_Orange_Medium"
    },
    {
      "x": -3,
      "y": 10,
      "z": -1,
      "name": "Plant_Coral_Bush_Orange"
    },
    {
      "x": -3,
      "y": 11,
      "z": -1,
      "name": "Plant_Coral_Block_Orange"
    },
    {
      "x": -3,
      "y": 12,
      "z": -1,
      "name": "Plant_Coral_Block_Orange"
    },
    {
      "x": -3,
      "y": 13,
      "z": -1,
      "name": "Plant_Coral_Block_Orange"
    },
    {
      "x": -3,
      "y": 14,
      "z": -1,
      "name": "Plant_Coral_Model_Orange"
    },
    {
      "x": -3,
      "y": 17,
      "z": -1,
      "name": "Plant_Coral_Block_Orange"
    },
    {
      "x": -3,
      "y": 18,
      "z": -1,
      "name": "Plant_Coral_Block_Orange"
    },
    {
      "x": -3,
      "y": 19,
      "z": -1,
      "name": "Plant_Coral_Block_Orange"
    },
    {
      "x": -3,
      "y": 20,
      "z": -1,
      "name": "Plant_Coral_Block_Orange"
    },
    {
      "x": -3,
      "y": 21,
      "z": -1,
      "name": "Plant_Coral_Block_Orange"
    },
    {
      "x": -3,
      "y": 22,
      "z": -1,
      "name": "Plant_Coral_Block_Orange"
    },
    {
      "x": -3,
      "y": 0,
      "z": 0,
      "name": "Plant_Coral_Block_Orange"
    },
    {
      "x": -3,
      "y": 1,
      "z": 0,
      "name": "Plant_Coral_Block_Orange"
    },
    {
      "x": -3,
      "y": 4,
      "z": 0,
      "name": "Plant_Coral_Bush_Orange"
    },
    {
      "x": -3,
      "y": 5,
      "z": 0,
      "name": "Plant_Coral_Bush_Orange"
    },
    {
      "x": -3,
      "y": 6,
      "z": 0,
      "name": "Plant_Coral_Bush_Orange"
    },
    {
      "x": -3,
      "y": 7,
      "z": 0,
      "name": "Empty"
    },
    {
      "x": -3,
      "y": 9,
      "z": 0,
      "name": "Plant_Coral_Bush_Orange"
    },
    {
      "x": -3,
      "y": 11,
      "z": 0,
      "name": "Plant_Coral_Block_Orange"
    },
    {
      "x": -3,
      "y": 12,
      "z": 0,
      "name": "Plant_Coral_Block_Orange"
    },
    {
      "x": -3,
      "y": 13,
      "z": 0,
      "name": "Plant_Coral_Block_Orange"
    },
    {
      "x": -3,
      "y": 14,
      "z": 0,
      "name": "Plant_Coral_Block_Orange"
    },
    {
      "x": -3,
      "y": 15,
      "z": 0,
      "name": "Plant_Coral_Block_Orange"
    },
    {
      "x": -3,
      "y": 16,
      "z": 0,
      "name": "Plant_Coral_Block_Orange"
    },
    {
      "x": -3,
      "y": 17,
      "z": 0,
      "name": "Plant_Coral_Block_Orange"
    },
    {
      "x": -3,
      "y": 18,
      "z": 0,
      "name": "Empty"
    },
    {
      "x": -3,
      "y": 19,
      "z": 0,
      "name": "Plant_Coral_Bush_Orange"
    },
    {
      "x": -3,
      "y": 20,
      "z": 0,
      "name": "Plant_Coral_Bush_Orange"
    },
    {
      "x": -3,
      "y": 21,
      "z": 0,
      "name": "Plant_Coral_Bush_Orange"
    },
    {
      "x": -3,
      "y": 0,
      "z": 1,
      "name": "Plant_Coral_Block_Orange"
    },
    {
      "x": -3,
      "y": 1,
      "z": 1,
      "name": "Plant_Coral_Block_Orange"
    },
    {
      "x": -3,
      "y": 4,
      "z": 1,
      "name": "Plant_Coral_Bush_Orange"
    },
    {
      "x": -3,
      "y": 5,
      "z": 1,
      "name": "Plant_Coral_Bush_Orange"
    },
    {
      "x": -3,
      "y": 8,
      "z": 1,
      "name": "Plant_Coral_Bush_Orange"
    },
    {
      "x": -3,
      "y": 10,
      "z": 1,
      "name": "Plant_Coral_Bush_Orange"
    },
    {
      "x": -3,
      "y": 11,
      "z": 1,
      "name": "Plant_Coral_Block_Orange"
    },
    {
      "x": -3,
      "y": 12,
      "z": 1,
      "name": "Plant_Coral_Block_Orange"
    },
    {
      "x": -3,
      "y": 13,
      "z": 1,
      "name": "Plant_Coral_Block_Orange"
    },
    {
      "x": -3,
      "y": 14,
      "z": 1,
      "name": "Plant_Coral_Block_Orange"
    },
    {
      "x": -3,
      "y": 15,
      "z": 1,
      "name": "Plant_Coral_Block_Orange"
    },
    {
      "x": -3,
      "y": 16,
      "z": 1,
      "name": "Plant_Coral_Block_Orange"
    },
    {
      "x": -3,
      "y": 17,
      "z": 1,
      "name": "Plant_Coral_Block_Orange"
    },
    {
      "x": -3,
      "y": 19,
      "z": 1,
      "name": "Plant_Coral_Bush_Orange"
    },
    {
      "x": -3,
      "y": 0,
      "z": 2,
      "name": "Plant_Coral_Block_Orange"
    },
    {
      "x": -3,
      "y": 1,
      "z": 2,
      "name": "Plant_Coral_Block_Orange"
    },
    {
      "x": -3,
      "y": 2,
      "z": 2,
      "name": "Rock_Crystal_Orange_Large",
      "rotation": 5
    },
    {
      "x": -3,
      "y": 4,
      "z": 2,
      "name": "Plant_Coral_Bush_Orange"
    },
    {
      "x": -3,
      "y": 8,
      "z": 2,
      "name": "Plant_Coral_Block_Orange"
    },
    {
      "x": -3,
      "y": 9,
      "z": 2,
      "name": "Plant_Coral_Block_Orange"
    },
    {
      "x": -3,
      "y": 10,
      "z": 2,
      "name": "Plant_Coral_Block_Orange"
    },
    {
      "x": -3,
      "y": 11,
      "z": 2,
      "name": "Plant_Coral_Block_Orange"
    },
    {
      "x": -3,
      "y": 12,
      "z": 2,
      "name": "Plant_Coral_Model_Orange"
    },
    {
      "x": -3,
      "y": 14,
      "z": 2,
      "name": "Plant_Coral_Block_Orange"
    },
    {
      "x": -3,
      "y": 15,
      "z": 2,
      "name": "Plant_Coral_Block_Orange"
    },
    {
      "x": -3,
      "y": 16,
      "z": 2,
      "name": "Plant_Coral_Block_Orange"
    },
    {
      "x": -3,
      "y": 17,
      "z": 2,
      "name": "Plant_Coral_Block_Orange"
    },
    {
      "x": -3,
      "y": 18,
      "z": 2,
      "name": "Plant_Coral_Bush_Orange"
    },
    {
      "x": -3,
      "y": 19,
      "z": 2,
      "name": "Plant_Coral_Bush_Orange"
    },
    {
      "x": -3,
      "y": 20,
      "z": 2,
      "name": "Plant_Coral_Bush_Orange"
    },
    {
      "x": -3,
      "y": 0,
      "z": 3,
      "name": "Plant_Coral_Block_Orange"
    },
    {
      "x": -3,
      "y": 1,
      "z": 3,
      "name": "Plant_Coral_Block_Orange"
    },
    {
      "x": -3,
      "y": 2,
      "z": 3,
      "name": "Plant_Coral_Block_Orange"
    },
    {
      "x": -3,
      "y": 3,
      "z": 3,
      "name": "Plant_Coral_Block_Orange"
    },
    {
      "x": -3,
      "y": 4,
      "z": 3,
      "name": "Plant_Coral_Block_Orange"
    },
    {
      "x": -3,
      "y": 5,
      "z": 3,
      "name": "Plant_Coral_Block_Orange"
    },
    {
      "x": -3,
      "y": 6,
      "z": 3,
      "name": "Plant_Coral_Block_Orange"
    },
    {
      "x": -3,
      "y": 7,
      "z": 3,
      "name": "Plant_Coral_Block_Orange"
    },
    {
      "x": -3,
      "y": 8,
      "z": 3,
      "name": "Plant_Coral_Block_Orange"
    },
    {
      "x": -3,
      "y": 15,
      "z": 3,
      "name": "Rock_Crystal_Orange_Small",
      "rotation": 4
    },
    {
      "x": -3,
      "y": 17,
      "z": 3,
      "name": "Plant_Coral_Block_Orange"
    },
    {
      "x": -3,
      "y": 18,
      "z": 3,
      "name": "Plant_Coral_Block_Orange"
    },
    {
      "x": -3,
      "y": 19,
      "z": 3,
      "name": "Plant_Coral_Block_Orange"
    },
    {
      "x": -3,
      "y": 20,
      "z": 3,
      "name": "Plant_Coral_Block_Orange"
    },
    {
      "x": -3,
      "y": 21,
      "z": 3,
      "name": "Plant_Coral_Block_Orange"
    },
    {
      "x": -3,
      "y": 22,
      "z": 3,
      "name": "Plant_Coral_Block_Orange"
    },
    {
      "x": -3,
      "y": 19,
      "z": 4,
      "name": "Plant_Coral_Block_Blue"
    },
    {
      "x": -3,
      "y": 20,
      "z": 4,
      "name": "Plant_Coral_Model_Blue"
    },
    {
      "x": -3,
      "y": 19,
      "z": 5,
      "name": "Plant_Coral_Block_Blue"
    },
    {
      "x": -3,
      "y": 20,
      "z": 5,
      "name": "Plant_Coral_Model_Blue"
    },
    {
      "x": -3,
      "y": 18,
      "z": 6,
      "name": "Plant_Crop_Mushroom_Block_Blue_Mycelium"
    },
    {
      "x": -3,
      "y": 19,
      "z": 6,
      "name": "Plant_Coral_Block_Blue"
    },
    {
      "x": -3,
      "y": 19,
      "z": 7,
      "name": "Plant_Coral_Block_Blue"
    },
    {
      "x": -2,
      "y": 8,
      "z": -7,
      "name": "Plant_Crop_Mushroom_Block_Blue_Mycelium"
    },
    {
      "x": -2,
      "y": 9,
      "z": -7,
      "name": "Plant_Coral_Block_Blue"
    },
    {
      "x": -2,
      "y": 9,
      "z": -6,
      "name": "Plant_Coral_Block_Blue"
    },
    {
      "x": -2,
      "y": 10,
      "z": -6,
      "name": "Plant_Coral_Bush_Blue"
    },
    {
      "x": -2,
      "y": 9,
      "z": -5,
      "name": "Plant_Coral_Block_Blue"
    },
    {
      "x": -2,
      "y": 9,
      "z": -4,
      "name": "Plant_Coral_Block_Blue"
    },
    {
      "x": -2,
      "y": 10,
      "z": -4,
      "name": "Rock_Crystal_Cyan_Medium"
    },
    {
      "x": -2,
      "y": 8,
      "z": -3,
      "name": "Plant_Coral_Block_Orange"
    },
    {
      "x": -2,
      "y": 9,
      "z": -3,
      "name": "Plant_Coral_Block_Orange"
    },
    {
      "x": -2,
      "y": 10,
      "z": -3,
      "name": "Plant_Coral_Block_Orange"
    },
    {
      "x": -2,
      "y": 0,
      "z": -2,
      "name": "Plant_Coral_Block_Orange"
    },
    {
      "x": -2,
      "y": 1,
      "z": -2,
      "name": "Plant_Coral_Block_Orange"
    },
    {
      "x": -2,
      "y": 2,
      "z": -2,
      "name": "Plant_Coral_Block_Orange"
    },
    {
      "x": -2,
      "y": 3,
      "z": -2,
      "name": "Plant_Coral_Block_Orange"
    },
    {
      "x": -2,
      "y": 4,
      "z": -2,
      "name": "Plant_Coral_Block_Orange"
    },
    {
      "x": -2,
      "y": 5,
      "z": -2,
      "name": "Plant_Coral_Block_Orange"
    },
    {
      "x": -2,
      "y": 6,
      "z": -2,
      "name": "Plant_Coral_Block_Orange"
    },
    {
      "x": -2,
      "y": 7,
      "z": -2,
      "name": "Plant_Coral_Block_Orange"
    },
    {
      "x": -2,
      "y": 8,
      "z": -2,
      "name": "Plant_Coral_Model_Orange"
    },
    {
      "x": -2,
      "y": 10,
      "z": -2,
      "name": "Plant_Coral_Bush_Orange"
    },
    {
      "x": -2,
      "y": 11,
      "z": -2,
      "name": "Plant_Coral_Block_Orange"
    },
    {
      "x": -2,
      "y": 12,
      "z": -2,
      "name": "Plant_Coral_Block_Orange"
    },
    {
      "x": -2,
      "y": 13,
      "z": -2,
      "name": "Plant_Coral_Block_Orange"
    },
    {
      "x": -2,
      "y": 14,
      "z": -2,
      "name": "Plant_Coral_Block_Orange"
    },
    {
      "x": -2,
      "y": 15,
      "z": -2,
      "name": "Rock_Crystal_Orange_Medium"
    },
    {
      "x": -2,
      "y": 16,
      "z": -2,
      "name": "Plant_Coral_Block_Orange"
    },
    {
      "x": -2,
      "y": 17,
      "z": -2,
      "name": "Plant_Coral_Model_Orange"
    },
    {
      "x": -2,
      "y": 18,
      "z": -2,
      "name": "Plant_Coral_Block_Orange"
    },
    {
      "x": -2,
      "y": 19,
      "z": -2,
      "name": "Plant_Coral_Block_Orange"
    },
    {
      "x": -2,
      "y": 20,
      "z": -2,
      "name": "Plant_Coral_Block_Orange"
    },
    {
      "x": -2,
      "y": 21,
      "z": -2,
      "name": "Plant_Coral_Block_Orange"
    },
    {
      "x": -2,
      "y": 22,
      "z": -2,
      "name": "Plant_Coral_Model_Orange"
    },
    {
      "x": -2,
      "y": 0,
      "z": -1,
      "name": "Plant_Coral_Block_Orange"
    },
    {
      "x": -2,
      "y": 1,
      "z": -1,
      "name": "Plant_Coral_Bush_Orange"
    },
    {
      "x": -2,
      "y": 7,
      "z": -1,
      "name": "Empty"
    },
    {
      "x": -2,
      "y": 8,
      "z": -1,
      "name": "Empty"
    },
    {
      "x": -2,
      "y": 9,
      "z": -1,
      "name": "Empty"
    },
    {
      "x": -2,
      "y": 11,
      "z": -1,
      "name": "Plant_Coral_Bush_Orange"
    },
    {
      "x": -2,
      "y": 14,
      "z": -1,
      "name": "Plant_Coral_Block_Orange"
    },
    {
      "x": -2,
      "y": 15,
      "z": -1,
      "name": "Plant_Coral_Block_Orange"
    },
    {
      "x": -2,
      "y": 16,
      "z": -1,
      "name": "Plant_Coral_Block_Orange"
    },
    {
      "x": -2,
      "y": 17,
      "z": -1,
      "name": "Plant_Coral_Block_Orange"
    },
    {
      "x": -2,
      "y": 18,
      "z": -1,
      "name": "Rock_Crystal_Orange_Medium"
    },
    {
      "x": -2,
      "y": 19,
      "z": -1,
      "name": "Plant_Coral_Bush_Orange"
    },
    {
      "x": -2,
      "y": 20,
      "z": -1,
      "name": "Plant_Coral_Bush_Orange"
    },
    {
      "x": -2,
      "y": 0,
      "z": 0,
      "name": "Plant_Coral_Block_Orange"
    },
    {
      "x": -2,
      "y": 5,
      "z": 0,
      "name": "Empty"
    },
    {
      "x": -2,
      "y": 6,
      "z": 0,
      "name": "Empty"
    },
    {
      "x": -2,
      "y": 7,
      "z": 0,
      "name": "Empty"
    },
    {
      "x": -2,
      "y": 8,
      "z": 0,
      "name": "Empty"
    },
    {
      "x": -2,
      "y": 9,
      "z": 0,
      "name": "Empty"
    },
    {
      "x": -2,
      "y": 13,
      "z": 0,
      "name": "Plant_Coral_Bush_Orange"
    },
    {
      "x": -2,
      "y": 17,
      "z": 0,
      "name": "Plant_Coral_Bush_Orange"
    },
    {
      "x": -2,
      "y": 18,
      "z": 0,
      "name": "Empty"
    },
    {
      "x": -2,
      "y": 19,
      "z": 0,
      "name": "Empty"
    },
    {
      "x": -2,
      "y": 20,
      "z": 0,
      "name": "Empty"
    },
    {
      "x": -2,
      "y": 0,
      "z": 1,
      "name": "Plant_Coral_Block_Orange"
    },
    {
      "x": -2,
      "y": 1,
      "z": 1,
      "name": "Plant_Coral_Bush_Orange"
    },
    {
      "x": -2,
      "y": 7,
      "z": 1,
      "name": "Empty"
    },
    {
      "x": -2,
      "y": 8,
      "z": 1,
      "name": "Empty"
    },
    {
      "x": -2,
      "y": 9,
      "z": 1,
      "name": "Empty"
    },
    {
      "x": -2,
      "y": 12,
      "z": 1,
      "name": "Plant_Coral_Bush_Orange"
    },
    {
      "x": -2,
      "y": 17,
      "z": 1,
      "name": "Plant_Coral_Bush_Orange"
    },
    {
      "x": -2,
      "y": 18,
      "z": 1,
      "name": "Empty"
    },
    {
      "x": -2,
      "y": 19,
      "z": 1,
      "name": "Empty"
    },
    {
      "x": -2,
      "y": 20,
      "z": 1,
      "name": "Empty"
    },
    {
      "x": -2,
      "y": 0,
      "z": 2,
      "name": "Plant_Coral_Block_Orange"
    },
    {
      "x": -2,
      "y": 1,
      "z": 2,
      "name": "Plant_Coral_Block_Orange"
    },
    {
      "x": -2,
      "y": 10,
      "z": 2,
      "name": "Plant_Coral_Bush_Orange"
    },
    {
      "x": -2,
      "y": 11,
      "z": 2,
      "name": "Plant_Coral_Block_Orange"
    },
    {
      "x": -2,
      "y": 12,
      "z": 2,
      "name": "Plant_Coral_Block_Orange"
    },
    {
      "x": -2,
      "y": 13,
      "z": 2,
      "name": "Plant_Coral_Block_Orange"
    },
    {
      "x": -2,
      "y": 14,
      "z": 2,
      "name": "Plant_Coral_Model_Orange"
    },
    {
      "x": -2,
      "y": 15,
      "z": 2,
      "name": "Plant_Coral_Bush_Orange"
    },
    {
      "x": -2,
      "y": 16,
      "z": 2,
      "name": "Empty"
    },
    {
      "x": -2,
      "y": 17,
      "z": 2,
      "name": "Empty"
    },
    {
      "x": -2,
      "y": 18,
      "z": 2,
      "name": "Empty"
    },
    {
      "x": -2,
      "y": 19,
      "z": 2,
      "name": "Empty"
    },
    {
      "x": -2,
      "y": 20,
      "z": 2,
      "name": "Empty"
    },
    {
      "x": -2,
      "y": 0,
      "z": 3,
      "name": "Plant_Coral_Block_Orange"
    },
    {
      "x": -2,
      "y": 1,
      "z": 3,
      "name": "Plant_Coral_Block_Orange"
    },
    {
      "x": -2,
      "y": 2,
      "z": 3,
      "name": "Plant_Coral_Model_Orange"
    },
    {
      "x": -2,
      "y": 3,
      "z": 3,
      "name": "Plant_Coral_Bush_Orange"
    },
    {
      "x": -2,
      "y": 7,
      "z": 3,
      "name": "Empty"
    },
    {
      "x": -2,
      "y": 8,
      "z": 3,
      "name": "Plant_Coral_Block_Orange"
    },
    {
      "x": -2,
      "y": 9,
      "z": 3,
      "name": "Plant_Coral_Block_Orange"
    },
    {
      "x": -2,
      "y": 10,
      "z": 3,
      "name": "Plant_Coral_Block_Orange"
    },
    {
      "x": -2,
      "y": 13,
      "z": 3,
      "name": "Plant_Coral_Block_Orange"
    },
    {
      "x": -2,
      "y": 14,
      "z": 3,
      "name": "Plant_Coral_Block_Orange"
    },
    {
      "x": -2,
      "y": 15,
      "z": 3,
      "name": "Plant_Coral_Block_Orange"
    },
    {
      "x": -2,
      "y": 16,
      "z": 3,
      "name": "Plant_Coral_Block_Orange"
    },
    {
      "x": -2,
      "y": 17,
      "z": 3,
      "name": "Plant_Coral_Block_Orange"
    },
    {
      "x": -2,
      "y": 18,
      "z": 3,
      "name": "Plant_Coral_Model_Orange"
    },
    {
      "x": -2,
      "y": 20,
      "z": 3,
      "name": "Plant_Coral_Bush_Orange"
    },
    {
      "x": -2,
      "y": 0,
      "z": 4,
      "name": "Plant_Coral_Block_Orange"
    },
    {
      "x": -2,
      "y": 1,
      "z": 4,
      "name": "Plant_Coral_Block_Orange"
    },
    {
      "x": -2,
      "y": 2,
      "z": 4,
      "name": "Plant_Coral_Block_Orange"
    },
    {
      "x": -2,
      "y": 3,
      "z": 4,
      "name": "Plant_Coral_Block_Orange"
    },
    {
      "x": -2,
      "y": 4,
      "z": 4,
      "name": "Plant_Coral_Block_Orange"
    },
    {
      "x": -2,
      "y": 5,
      "z": 4,
      "name": "Plant_Coral_Block_Orange"
    },
    {
      "x": -2,
      "y": 6,
      "z": 4,
      "name": "Plant_Coral_Block_Orange"
    },
    {
      "x": -2,
      "y": 7,
      "z": 4,
      "name": "Plant_Coral_Block_Orange"
    },
    {
      "x": -2,
      "y": 8,
      "z": 4,
      "name": "Plant_Coral_Block_Orange"
    },
    {
      "x": -2,
      "y": 18,
      "z": 4,
      "name": "Plant_Coral_Block_Orange"
    },
    {
      "x": -2,
      "y": 19,
      "z": 4,
      "name": "Plant_Coral_Block_Orange"
    },
    {
      "x": -2,
      "y": 20,
      "z": 4,
      "name": "Plant_Coral_Block_Orange"
    },
    {
      "x": -2,
      "y": 21,
      "z": 4,
      "name": "Plant_Coral_Block_Orange"
    },
    {
      "x": -2,
      "y": 22,
      "z": 4,
      "name": "Plant_Coral_Block_Orange"
    },
    {
      "x": -2,
      "y": 19,
      "z": 5,
      "name": "Plant_Coral_Block_Blue"
    },
    {
      "x": -2,
      "y": 19,
      "z": 6,
      "name": "Plant_Coral_Block_Blue"
    },
    {
      "x": -2,
      "y": 19,
      "z": 7,
      "name": "Plant_Coral_Block_Blue"
    },
    {
      "x": -2,
      "y": 19,
      "z": 8,
      "name": "Plant_Coral_Block_Orange"
    },
    {
      "x": -1,
      "y": 9,
      "z": -8,
      "name": "Plant_Coral_Block_Orange"
    },
    {
      "x": -1,
      "y": 9,
      "z": -7,
      "name": "Plant_Coral_Block_Blue"
    },
    {
      "x": -1,
      "y": 9,
      "z": -6,
      "name": "Plant_Coral_Block_Blue"
    },
    {
      "x": -1,
      "y": 9,
      "z": -5,
      "name": "Plant_Coral_Block_Blue"
    },
    {
      "x": -1,
      "y": 10,
      "z": -5,
      "name": "Plant_Coral_Bush_Blue"
    },
    {
      "x": -1,
      "y": 8,
      "z": -4,
      "name": "Rock_Crystal_Cyan_Small",
      "rotation": 8
    },
    {
      "x": -1,
      "y": 9,
      "z": -4,
      "name": "Plant_Coral_Block_Blue"
    },
    {
      "x": -1,
      "y": 10,
      "z": -4,
      "name": "Plant_Coral_Model_Blue"
    },
    {
      "x": -1,
      "y": 8,
      "z": -3,
      "name": "Plant_Coral_Block_Orange"
    },
    {
      "x": -1,
      "y": 9,
      "z": -3,
      "name": "Plant_Coral_Block_Orange"
    },
    {
      "x": -1,
      "y": 10,
      "z": -3,
      "name": "Plant_Coral_Block_Orange"
    },
    {
      "x": -1,
      "y": 11,
      "z": -3,
      "name": "Plant_Coral_Block_Orange"
    },
    {
      "x": -1,
      "y": 12,
      "z": -3,
      "name": "Plant_Coral_Block_Orange"
    },
    {
      "x": -1,
      "y": 13,
      "z": -3,
      "name": "Plant_Coral_Block_Orange"
    },
    {
      "x": -1,
      "y": 14,
      "z": -3,
      "name": "Plant_Coral_Block_Orange"
    },
    {
      "x": -1,
      "y": 15,
      "z": -3,
      "name": "Plant_Coral_Model_Orange"
    },
    {
      "x": -1,
      "y": 16,
      "z": -3,
      "name": "Plant_Coral_Block_Orange"
    },
    {
      "x": -1,
      "y": 0,
      "z": -2,
      "name": "Plant_Coral_Block_Orange"
    },
    {
      "x": -1,
      "y": 1,
      "z": -2,
      "name": "Plant_Coral_Block_Orange"
    },
    {
      "x": -1,
      "y": 2,
      "z": -2,
      "name": "Plant_Coral_Block_Orange"
    },
    {
      "x": -1,
      "y": 3,
      "z": -2,
      "name": "Plant_Coral_Block_Orange"
    },
    {
      "x": -1,
      "y": 4,
      "z": -2,
      "name": "Plant_Coral_Block_Orange"
    },
    {
      "x": -1,
      "y": 5,
      "z": -2,
      "name": "Plant_Coral_Block_Orange"
    },
    {
      "x": -1,
      "y": 6,
      "z": -2,
      "name": "Plant_Coral_Block_Orange"
    },
    {
      "x": -1,
      "y": 7,
      "z": -2,
      "name": "Plant_Coral_Block_Orange"
    },
    {
      "x": -1,
      "y": 8,
      "z": -2,
      "name": "Empty"
    },
    {
      "x": -1,
      "y": 13,
      "z": -2,
      "name": "Plant_Coral_Bush_Orange"
    },
    {
      "x": -1,
      "y": 14,
      "z": -2,
      "name": "Plant_Coral_Block_Orange"
    },
    {
      "x": -1,
      "y": 15,
      "z": -2,
      "name": "Plant_Coral_Block_Orange"
    },
    {
      "x": -1,
      "y": 16,
      "z": -2,
      "name": "Plant_Coral_Block_Orange"
    },
    {
      "x": -1,
      "y": 17,
      "z": -2,
      "name": "Plant_Coral_Block_Orange"
    },
    {
      "x": -1,
      "y": 18,
      "z": -2,
      "name": "Plant_Coral_Block_Orange"
    },
    {
      "x": -1,
      "y": 19,
      "z": -2,
      "name": "Plant_Coral_Block_Orange"
    },
    {
      "x": -1,
      "y": 20,
      "z": -2,
      "name": "Plant_Coral_Block_Orange"
    },
    {
      "x": -1,
      "y": 21,
      "z": -2,
      "name": "Plant_Coral_Block_Orange"
    },
    {
      "x": -1,
      "y": 0,
      "z": -1,
      "name": "Plant_Coral_Block_Orange"
    },
    {
      "x": -1,
      "y": 1,
      "z": -1,
      "name": "Plant_Coral_Model_Orange"
    },
    {
      "x": -1,
      "y": 3,
      "z": -1,
      "name": "Plant_Coral_Bush_Orange"
    },
    {
      "x": -1,
      "y": 4,
      "z": -1,
      "name": "Plant_Coral_Bush_Orange"
    },
    {
      "x": -1,
      "y": 7,
      "z": -1,
      "name": "Empty"
    },
    {
      "x": -1,
      "y": 8,
      "z": -1,
      "name": "Empty"
    },
    {
      "x": -1,
      "y": 9,
      "z": -1,
      "name": "Empty"
    },
    {
      "x": -1,
      "y": 10,
      "z": -1,
      "name": "Empty"
    },
    {
      "x": -1,
      "y": 11,
      "z": -1,
      "name": "Empty"
    },
    {
      "x": -1,
      "y": 12,
      "z": -1,
      "name": "Empty"
    },
    {
      "x": -1,
      "y": 14,
      "z": -1,
      "name": "Plant_Coral_Bush_Orange"
    },
    {
      "x": -1,
      "y": 16,
      "z": -1,
      "name": "Plant_Coral_Bush_Orange"
    },
    {
      "x": -1,
      "y": 0,
      "z": 0,
      "name": "Plant_Coral_Block_Orange"
    },
    {
      "x": -1,
      "y": 7,
      "z": 0,
      "name": "Empty"
    },
    {
      "x": -1,
      "y": 8,
      "z": 0,
      "name": "Empty"
    },
    {
      "x": -1,
      "y": 9,
      "z": 0,
      "name": "Empty"
    },
    {
      "x": -1,
      "y": 10,
      "z": 0,
      "name": "Empty"
    },
    {
      "x": -1,
      "y": 11,
      "z": 0,
      "name": "Empty"
    },
    {
      "x": -1,
      "y": 12,
      "z": 0,
      "name": "Empty"
    },
    {
      "x": -1,
      "y": 13,
      "z": 0,
      "name": "Empty"
    },
    {
      "x": -1,
      "y": 14,
      "z": 0,
      "name": "Empty"
    },
    {
      "x": -1,
      "y": 15,
      "z": 0,
      "name": "Empty"
    },
    {
      "x": -1,
      "y": 16,
      "z": 0,
      "name": "Empty"
    },
    {
      "x": -1,
      "y": 17,
      "z": 0,
      "name": "Empty"
    },
    {
      "x": -1,
      "y": 18,
      "z": 0,
      "name": "Empty"
    },
    {
      "x": -1,
      "y": 19,
      "z": 0,
      "name": "Empty"
    },
    {
      "x": -1,
      "y": 20,
      "z": 0,
      "name": "Empty"
    },
    {
      "x": -1,
      "y": 0,
      "z": 1,
      "name": "Plant_Coral_Block_Orange"
    },
    {
      "x": -1,
      "y": 7,
      "z": 1,
      "name": "Empty"
    },
    {
      "x": -1,
      "y": 8,
      "z": 1,
      "name": "Empty"
    },
    {
      "x": -1,
      "y": 9,
      "z": 1,
      "name": "Empty"
    },
    {
      "x": -1,
      "y": 10,
      "z": 1,
      "name": "Empty"
    },
    {
      "x": -1,
      "y": 11,
      "z": 1,
      "name": "Empty"
    },
    {
      "x": -1,
      "y": 12,
      "z": 1,
      "name": "Empty"
    },
    {
      "x": -1,
      "y": 13,
      "z": 1,
      "name": "Empty"
    },
    {
      "x": -1,
      "y": 14,
      "z": 1,
      "name": "Empty"
    },
    {
      "x": -1,
      "y": 15,
      "z": 1,
      "name": "Empty"
    },
    {
      "x": -1,
      "y": 16,
      "z": 1,
      "name": "Empty"
    },
    {
      "x": -1,
      "y": 17,
      "z": 1,
      "name": "Empty"
    },
    {
      "x": -1,
      "y": 18,
      "z": 1,
      "name": "Empty"
    },
    {
      "x": -1,
      "y": 19,
      "z": 1,
      "name": "Empty"
    },
    {
      "x": -1,
      "y": 20,
      "z": 1,
      "name": "Empty"
    },
    {
      "x": -1,
      "y": 0,
      "z": 2,
      "name": "Plant_Coral_Block_Orange"
    },
    {
      "x": -1,
      "y": 1,
      "z": 2,
      "name": "Plant_Coral_Block_Orange"
    },
    {
      "x": -1,
      "y": 7,
      "z": 2,
      "name": "Empty"
    },
    {
      "x": -1,
      "y": 13,
      "z": 2,
      "name": "Empty"
    },
    {
      "x": -1,
      "y": 14,
      "z": 2,
      "name": "Empty"
    },
    {
      "x": -1,
      "y": 15,
      "z": 2,
      "name": "Empty"
    },
    {
      "x": -1,
      "y": 16,
      "z": 2,
      "name": "Empty"
    },
    {
      "x": -1,
      "y": 17,
      "z": 2,
      "name": "Empty"
    },
    {
      "x": -1,
      "y": 18,
      "z": 2,
      "name": "Empty"
    },
    {
      "x": -1,
      "y": 19,
      "z": 2,
      "name": "Empty"
    },
    {
      "x": -1,
      "y": 20,
      "z": 2,
      "name": "Empty"
    },
    {
      "x": -1,
      "y": 0,
      "z": 3,
      "name": "Plant_Coral_Block_Orange"
    },
    {
      "x": -1,
      "y": 1,
      "z": 3,
      "name": "Plant_Coral_Block_Orange"
    },
    {
      "x": -1,
      "y": 5,
      "z": 3,
      "name": "Plant_Coral_Bush_Orange"
    },
    {
      "x": -1,
      "y": 7,
      "z": 3,
      "name": "Empty"
    },
    {
      "x": -1,
      "y": 8,
      "z": 3,
      "name": "Plant_Coral_Block_Orange"
    },
    {
      "x": -1,
      "y": 9,
      "z": 3,
      "name": "Plant_Coral_Block_Orange"
    },
    {
      "x": -1,
      "y": 10,
      "z": 3,
      "name": "Plant_Coral_Block_Orange"
    },
    {
      "x": -1,
      "y": 11,
      "z": 3,
      "name": "Plant_Coral_Block_Orange"
    },
    {
      "x": -1,
      "y": 12,
      "z": 3,
      "name": "Plant_Coral_Block_Orange"
    },
    {
      "x": -1,
      "y": 13,
      "z": 3,
      "name": "Plant_Coral_Block_Orange"
    },
    {
      "x": -1,
      "y": 16,
      "z": 3,
      "name": "Plant_Coral_Bush_Orange"
    },
    {
      "x": -1,
      "y": 18,
      "z": 3,
      "name": "Plant_Coral_Bush_Orange"
    },
    {
      "x": -1,
      "y": 19,
      "z": 3,
      "name": "Plant_Coral_Bush_Orange"
    },
    {
      "x": -1,
      "y": 0,
      "z": 4,
      "name": "Plant_Coral_Block_Orange"
    },
    {
      "x": -1,
      "y": 1,
      "z": 4,
      "name": "Plant_Coral_Block_Orange"
    },
    {
      "x": -1,
      "y": 2,
      "z": 4,
      "name": "Plant_Coral_Block_Orange"
    },
    {
      "x": -1,
      "y": 3,
      "z": 4,
      "name": "Plant_Coral_Block_Orange"
    },
    {
      "x": -1,
      "y": 4,
      "z": 4,
      "name": "Plant_Coral_Block_Orange"
    },
    {
      "x": -1,
      "y": 5,
      "z": 4,
      "name": "Plant_Coral_Block_Orange"
    },
    {
      "x": -1,
      "y": 6,
      "z": 4,
      "name": "Plant_Coral_Block_Orange"
    },
    {
      "x": -1,
      "y": 7,
      "z": 4,
      "name": "Plant_Coral_Block_Orange"
    },
    {
      "x": -1,
      "y": 8,
      "z": 4,
      "name": "Plant_Coral_Block_Orange"
    },
    {
      "x": -1,
      "y": 13,
      "z": 4,
      "name": "Plant_Coral_Block_Orange"
    },
    {
      "x": -1,
      "y": 14,
      "z": 4,
      "name": "Plant_Coral_Block_Orange"
    },
    {
      "x": -1,
      "y": 15,
      "z": 4,
      "name": "Plant_Coral_Block_Orange"
    },
    {
      "x": -1,
      "y": 16,
      "z": 4,
      "name": "Plant_Coral_Block_Orange"
    },
    {
      "x": -1,
      "y": 17,
      "z": 4,
      "name": "Plant_Coral_Block_Orange"
    },
    {
      "x": -1,
      "y": 18,
      "z": 4,
      "name": "Plant_Coral_Block_Orange"
    },
    {
      "x": -1,
      "y": 19,
      "z": 4,
      "name": "Plant_Coral_Block_Orange"
    },
    {
      "x": -1,
      "y": 20,
      "z": 4,
      "name": "Plant_Coral_Block_Orange"
    },
    {
      "x": -1,
      "y": 21,
      "z": 4,
      "name": "Plant_Coral_Block_Orange"
    },
    {
      "x": -1,
      "y": 22,
      "z": 4,
      "name": "Plant_Coral_Block_Orange"
    },
    {
      "x": -1,
      "y": 18,
      "z": 5,
      "name": "Rock_Crystal_Cyan_Small",
      "rotation": 8
    },
    {
      "x": -1,
      "y": 19,
      "z": 5,
      "name": "Plant_Coral_Block_Blue"
    },
    {
      "x": -1,
      "y": 20,
      "z": 5,
      "name": "Plant_Coral_Bush_Blue"
    },
    {
      "x": -1,
      "y": 18,
      "z": 6,
      "name": "Plant_Crop_Mushroom_Block_Blue_Mycelium"
    },
    {
      "x": -1,
      "y": 19,
      "z": 6,
      "name": "Plant_Coral_Block_Blue"
    },
    {
      "x": -1,
      "y": 19,
      "z": 7,
      "name": "Plant_Coral_Block_Blue"
    },
    {
      "x": -1,
      "y": 19,
      "z": 8,
      "name": "Plant_Coral_Block_Orange"
    },
    {
      "x": 0,
      "y": 9,
      "z": -8,
      "name": "Plant_Coral_Block_Orange"
    },
    {
      "x": 0,
      "y": 9,
      "z": -7,
      "name": "Plant_Coral_Block_Blue"
    },
    {
      "x": 0,
      "y": 8,
      "z": -6,
      "name": "Plant_Crop_Mushroom_Block_Blue_Mycelium"
    },
    {
      "x": 0,
      "y": 9,
      "z": -6,
      "name": "Plant_Coral_Block_Blue"
    },
    {
      "x": 0,
      "y": 9,
      "z": -5,
      "name": "Plant_Coral_Block_Blue"
    },
    {
      "x": 0,
      "y": 9,
      "z": -4,
      "name": "Plant_Coral_Block_Blue"
    },
    {
      "x": 0,
      "y": 10,
      "z": -4,
      "name": "Plant_Coral_Bush_Blue"
    },
    {
      "x": 0,
      "y": 11,
      "z": -4,
      "name": "Rock_Crystal_Cyan_Small",
      "rotation": 6
    },
    {
      "x": 0,
      "y": 8,
      "z": -3,
      "name": "Plant_Coral_Block_Orange"
    },
    {
      "x": 0,
      "y": 9,
      "z": -3,
      "name": "Plant_Coral_Block_Orange"
    },
    {
      "x": 0,
      "y": 10,
      "z": -3,
      "name": "Plant_Coral_Block_Orange"
    },
    {
      "x": 0,
      "y": 11,
      "z": -3,
      "name": "Plant_Coral_Block_Orange"
    },
    {
      "x": 0,
      "y": 12,
      "z": -3,
      "name": "Plant_Coral_Block_Orange"
    },
    {
      "x": 0,
      "y": 13,
      "z": -3,
      "name": "Plant_Coral_Block_Orange"
    },
    {
      "x": 0,
      "y": 14,
      "z": -3,
      "name": "Plant_Coral_Block_Orange"
    },
    {
      "x": 0,
      "y": 0,
      "z": -2,
      "name": "Plant_Coral_Block_Orange"
    },
    {
      "x": 0,
      "y": 1,
      "z": -2,
      "name": "Plant_Coral_Block_Orange"
    },
    {
      "x": 0,
      "y": 2,
      "z": -2,
      "name": "Plant_Coral_Block_Orange"
    },
    {
      "x": 0,
      "y": 3,
      "z": -2,
      "name": "Plant_Coral_Block_Orange"
    },
    {
      "x": 0,
      "y": 4,
      "z": -2,
      "name": "Plant_Coral_Block_Orange"
    },
    {
      "x": 0,
      "y": 5,
      "z": -2,
      "name": "Plant_Coral_Block_Orange"
    },
    {
      "x": 0,
      "y": 6,
      "z": -2,
      "name": "Plant_Coral_Block_Orange"
    },
    {
      "x": 0,
      "y": 7,
      "z": -2,
      "name": "Plant_Coral_Block_Orange"
    },
    {
      "x": 0,
      "y": 10,
      "z": -2,
      "name": "Plant_Coral_Bush_Orange"
    },
    {
      "x": 0,
      "y": 14,
      "z": -2,
      "name": "Plant_Coral_Block_Orange"
    },
    {
      "x": 0,
      "y": 15,
      "z": -2,
      "name": "Plant_Coral_Block_Orange"
    },
    {
      "x": 0,
      "y": 16,
      "z": -2,
      "name": "Plant_Coral_Block_Orange"
    },
    {
      "x": 0,
      "y": 17,
      "z": -2,
      "name": "Plant_Coral_Block_Orange"
    },
    {
      "x": 0,
      "y": 18,
      "z": -2,
      "name": "Plant_Coral_Block_Orange"
    },
    {
      "x": 0,
      "y": 19,
      "z": -2,
      "name": "Plant_Coral_Block_Orange"
    },
    {
      "x": 0,
      "y": 20,
      "z": -2,
      "name": "Plant_Coral_Block_Orange"
    },
    {
      "x": 0,
      "y": 21,
      "z": -2,
      "name": "Plant_Coral_Block_Orange"
    },
    {
      "x": 0,
      "y": 0,
      "z": -1,
      "name": "Plant_Coral_Block_Orange"
    },
    {
      "x": 0,
      "y": 1,
      "z": -1,
      "name": "Plant_Coral_Block_Orange"
    },
    {
      "x": 0,
      "y": 2,
      "z": -1,
      "name": "Plant_Coral_Bush_Orange"
    },
    {
      "x": 0,
      "y": 4,
      "z": -1,
      "name": "Plant_Coral_Bush_Orange"
    },
    {
      "x": 0,
      "y": 6,
      "z": -1,
      "name": "Plant_Coral_Bush_Orange"
    },
    {
      "x": 0,
      "y": 7,
      "z": -1,
      "name": "Empty"
    },
    {
      "x": 0,
      "y": 8,
      "z": -1,
      "name": "Empty"
    },
    {
      "x": 0,
      "y": 9,
      "z": -1,
      "name": "Empty"
    },
    {
      "x": 0,
      "y": 10,
      "z": -1,
      "name": "Empty"
    },
    {
      "x": 0,
      "y": 11,
      "z": -1,
      "name": "Empty"
    },
    {
      "x": 0,
      "y": 12,
      "z": -1,
      "name": "Empty"
    },
    {
      "x": 0,
      "y": 14,
      "z": -1,
      "name": "Plant_Coral_Bush_Orange"
    },
    {
      "x": 0,
      "y": 17,
      "z": -1,
      "name": "Plant_Coral_Bush_Orange"
    },
    {
      "x": 0,
      "y": 18,
      "z": -1,
      "name": "Plant_Coral_Bush_Orange"
    },
    {
      "x": 0,
      "y": 19,
      "z": -1,
      "name": "Plant_Coral_Bush_Orange"
    },
    {
      "x": 0,
      "y": 20,
      "z": -1,
      "name": "Plant_Coral_Bush_Orange"
    },
    {
      "x": 0,
      "y": 0,
      "z": 0,
      "name": "Plant_Coral_Block_Orange"
    },
    {
      "x": 0,
      "y": 7,
      "z": 0,
      "name": "Empty"
    },
    {
      "x": 0,
      "y": 8,
      "z": 0,
      "name": "Empty"
    },
    {
      "x": 0,
      "y": 9,
      "z": 0,
      "name": "Empty"
    },
    {
      "x": 0,
      "y": 10,
      "z": 0,
      "name": "Empty"
    },
    {
      "x": 0,
      "y": 11,
      "z": 0,
      "name": "Empty"
    },
    {
      "x": 0,
      "y": 12,
      "z": 0,
      "name": "Empty"
    },
    {
      "x": 0,
      "y": 13,
      "z": 0,
      "name": "Empty"
    },
    {
      "x": 0,
      "y": 14,
      "z": 0,
      "name": "Empty"
    },
    {
      "x": 0,
      "y": 15,
      "z": 0,
      "name": "Empty"
    },
    {
      "x": 0,
      "y": 16,
      "z": 0,
      "name": "Empty"
    },
    {
      "x": 0,
      "y": 17,
      "z": 0,
      "name": "Empty"
    },
    {
      "x": 0,
      "y": 18,
      "z": 0,
      "name": "Empty"
    },
    {
      "x": 0,
      "y": 19,
      "z": 0,
      "name": "Empty"
    },
    {
      "x": 0,
      "y": 20,
      "z": 0,
      "name": "Empty"
    },
    {
      "x": 0,
      "y": 0,
      "z": 1,
      "name": "Plant_Coral_Block_Orange"
    },
    {
      "x": 0,
      "y": 7,
      "z": 1,
      "name": "Empty"
    },
    {
      "x": 0,
      "y": 8,
      "z": 1,
      "name": "Empty"
    },
    {
      "x": 0,
      "y": 9,
      "z": 1,
      "name": "Empty"
    },
    {
      "x": 0,
      "y": 10,
      "z": 1,
      "name": "Empty"
    },
    {
      "x": 0,
      "y": 11,
      "z": 1,
      "name": "Empty"
    },
    {
      "x": 0,
      "y": 12,
      "z": 1,
      "name": "Empty"
    },
    {
      "x": 0,
      "y": 13,
      "z": 1,
      "name": "Empty"
    },
    {
      "x": 0,
      "y": 14,
      "z": 1,
      "name": "Empty"
    },
    {
      "x": 0,
      "y": 15,
      "z": 1,
      "name": "Empty"
    },
    {
      "x": 0,
      "y": 16,
      "z": 1,
      "name": "Empty"
    },
    {
      "x": 0,
      "y": 17,
      "z": 1,
      "name": "Empty"
    },
    {
      "x": 0,
      "y": 18,
      "z": 1,
      "name": "Empty"
    },
    {
      "x": 0,
      "y": 19,
      "z": 1,
      "name": "Empty"
    },
    {
      "x": 0,
      "y": 20,
      "z": 1,
      "name": "Empty"
    },
    {
      "x": 0,
      "y": 0,
      "z": 2,
      "name": "Plant_Coral_Block_Orange"
    },
    {
      "x": 0,
      "y": 1,
      "z": 2,
      "name": "Plant_Coral_Bush_Orange"
    },
    {
      "x": 0,
      "y": 2,
      "z": 2,
      "name": "Empty"
    },
    {
      "x": 0,
      "y": 10,
      "z": 2,
      "name": "Plant_Coral_Bush_Orange"
    },
    {
      "x": 0,
      "y": 12,
      "z": 2,
      "name": "Empty"
    },
    {
      "x": 0,
      "y": 13,
      "z": 2,
      "name": "Empty"
    },
    {
      "x": 0,
      "y": 14,
      "z": 2,
      "name": "Empty"
    },
    {
      "x": 0,
      "y": 15,
      "z": 2,
      "name": "Empty"
    },
    {
      "x": 0,
      "y": 16,
      "z": 2,
      "name": "Empty"
    },
    {
      "x": 0,
      "y": 17,
      "z": 2,
      "name": "Empty"
    },
    {
      "x": 0,
      "y": 18,
      "z": 2,
      "name": "Empty"
    },
    {
      "x": 0,
      "y": 19,
      "z": 2,
      "name": "Empty"
    },
    {
      "x": 0,
      "y": 20,
      "z": 2,
      "name": "Empty"
    },
    {
      "x": 0,
      "y": 0,
      "z": 3,
      "name": "Plant_Coral_Block_Orange"
    },
    {
      "x": 0,
      "y": 1,
      "z": 3,
      "name": "Plant_Coral_Block_Orange"
    },
    {
      "x": 0,
      "y": 2,
      "z": 3,
      "name": "Empty"
    },
    {
      "x": 0,
      "y": 3,
      "z": 3,
      "name": "Plant_Coral_Bush_Orange"
    },
    {
      "x": 0,
      "y": 4,
      "z": 3,
      "name": "Plant_Coral_Bush_Orange"
    },
    {
      "x": 0,
      "y": 6,
      "z": 3,
      "name": "Plant_Coral_Bush_Orange"
    },
    {
      "x": 0,
      "y": 8,
      "z": 3,
      "name": "Plant_Coral_Block_Orange"
    },
    {
      "x": 0,
      "y": 9,
      "z": 3,
      "name": "Plant_Coral_Block_Orange"
    },
    {
      "x": 0,
      "y": 10,
      "z": 3,
      "name": "Plant_Coral_Block_Orange"
    },
    {
      "x": 0,
      "y": 11,
      "z": 3,
      "name": "Plant_Coral_Block_Orange"
    },
    {
      "x": 0,
      "y": 12,
      "z": 3,
      "name": "Plant_Coral_Block_Orange"
    },
    {
      "x": 0,
      "y": 13,
      "z": 3,
      "name": "Plant_Coral_Block_Orange"
    },
    {
      "x": 0,
      "y": 14,
      "z": 3,
      "name": "Plant_Coral_Bush_Orange"
    },
    {
      "x": 0,
      "y": 18,
      "z": 3,
      "name": "Plant_Coral_Bush_Orange"
    },
    {
      "x": 0,
      "y": 19,
      "z": 3,
      "name": "Rock_Crystal_Orange_Small",
      "rotation": 6
    },
    {
      "x": 0,
      "y": 0,
      "z": 4,
      "name": "Plant_Coral_Block_Orange"
    },
    {
      "x": 0,
      "y": 1,
      "z": 4,
      "name": "Plant_Coral_Block_Orange"
    },
    {
      "x": 0,
      "y": 2,
      "z": 4,
      "name": "Plant_Coral_Block_Orange"
    },
    {
      "x": 0,
      "y": 3,
      "z": 4,
      "name": "Plant_Coral_Block_Orange"
    },
    {
      "x": 0,
      "y": 4,
      "z": 4,
      "name": "Plant_Coral_Block_Orange"
    },
    {
      "x": 0,
      "y": 5,
      "z": 4,
      "name": "Plant_Coral_Block_Orange"
    },
    {
      "x": 0,
      "y": 6,
      "z": 4,
      "name": "Plant_Coral_Block_Orange"
    },
    {
      "x": 0,
      "y": 7,
      "z": 4,
      "name": "Plant_Coral_Block_Orange"
    },
    {
      "x": 0,
      "y": 8,
      "z": 4,
      "name": "Plant_Coral_Block_Orange"
    },
    {
      "x": 0,
      "y": 9,
      "z": 4,
      "name": "Plant_Coral_Model_Orange"
    },
    {
      "x": 0,
      "y": 13,
      "z": 4,
      "name": "Plant_Coral_Block_Orange"
    },
    {
      "x": 0,
      "y": 14,
      "z": 4,
      "name": "Plant_Coral_Block_Orange"
    },
    {
      "x": 0,
      "y": 15,
      "z": 4,
      "name": "Plant_Coral_Block_Orange"
    },
    {
      "x": 0,
      "y": 16,
      "z": 4,
      "name": "Plant_Coral_Block_Orange"
    },
    {
      "x": 0,
      "y": 17,
      "z": 4,
      "name": "Plant_Coral_Block_Orange"
    },
    {
      "x": 0,
      "y": 18,
      "z": 4,
      "name": "Plant_Coral_Block_Orange"
    },
    {
      "x": 0,
      "y": 19,
      "z": 4,
      "name": "Plant_Coral_Block_Orange"
    },
    {
      "x": 0,
      "y": 20,
      "z": 4,
      "name": "Plant_Coral_Block_Orange"
    },
    {
      "x": 0,
      "y": 21,
      "z": 4,
      "name": "Plant_Coral_Block_Orange"
    },
    {
      "x": 0,
      "y": 22,
      "z": 4,
      "name": "Plant_Coral_Block_Orange"
    },
    {
      "x": 0,
      "y": 16,
      "z": 5,
      "name": "Plant_Coral_Block_Orange"
    },
    {
      "x": 0,
      "y": 19,
      "z": 5,
      "name": "Plant_Coral_Block_Blue"
    },
    {
      "x": 0,
      "y": 16,
      "z": 6,
      "name": "Plant_Coral_Block_Orange"
    },
    {
      "x": 0,
      "y": 19,
      "z": 6,
      "name": "Plant_Coral_Block_Blue"
    },
    {
      "x": 0,
      "y": 19,
      "z": 7,
      "name": "Plant_Coral_Block_Orange"
    },
    {
      "x": 0,
      "y": 19,
      "z": 8,
      "name": "Plant_Coral_Block_Orange"
    },
    {
      "x": 1,
      "y": 9,
      "z": -8,
      "name": "Plant_Coral_Block_Orange"
    },
    {
      "x": 1,
      "y": 9,
      "z": -6,
      "name": "Plant_Coral_Block_Blue"
    },
    {
      "x": 1,
      "y": 9,
      "z": -5,
      "name": "Plant_Coral_Block_Blue"
    },
    {
      "x": 1,
      "y": 8,
      "z": -4,
      "name": "Plant_Crop_Mushroom_Block_Blue_Mycelium"
    },
    {
      "x": 1,
      "y": 9,
      "z": -4,
      "name": "Plant_Coral_Block_Blue"
    },
    {
      "x": 1,
      "y": 16,
      "z": -4,
      "name": "Plant_Coral_Block_Orange"
    },
    {
      "x": 1,
      "y": 9,
      "z": -3,
      "name": "Plant_Coral_Block_Blue"
    },
    {
      "x": 1,
      "y": 10,
      "z": -3,
      "name": "Plant_Coral_Bush_Blue"
    },
    {
      "x": 1,
      "y": 11,
      "z": -3,
      "name": "Plant_Coral_Block_Orange"
    },
    {
      "x": 1,
      "y": 12,
      "z": -3,
      "name": "Plant_Coral_Block_Orange"
    },
    {
      "x": 1,
      "y": 13,
      "z": -3,
      "name": "Plant_Coral_Block_Orange"
    },
    {
      "x": 1,
      "y": 14,
      "z": -3,
      "name": "Plant_Coral_Block_Orange"
    },
    {
      "x": 1,
      "y": 16,
      "z": -3,
      "name": "Plant_Coral_Block_Blue"
    },
    {
      "x": 1,
      "y": 8,
      "z": -2,
      "name": "Plant_Coral_Block_Orange"
    },
    {
      "x": 1,
      "y": 9,
      "z": -2,
      "name": "Plant_Coral_Block_Orange"
    },
    {
      "x": 1,
      "y": 10,
      "z": -2,
      "name": "Plant_Coral_Block_Orange"
    },
    {
      "x": 1,
      "y": 11,
      "z": -2,
      "name": "Rock_Crystal_Orange_Small"
    },
    {
      "x": 1,
      "y": 14,
      "z": -2,
      "name": "Plant_Coral_Block_Orange"
    },
    {
      "x": 1,
      "y": 15,
      "z": -2,
      "name": "Plant_Coral_Block_Orange"
    },
    {
      "x": 1,
      "y": 16,
      "z": -2,
      "name": "Plant_Coral_Block_Orange"
    },
    {
      "x": 1,
      "y": 17,
      "z": -2,
      "name": "Plant_Coral_Block_Orange"
    },
    {
      "x": 1,
      "y": 18,
      "z": -2,
      "name": "Plant_Coral_Model_Orange"
    },
    {
      "x": 1,
      "y": 0,
      "z": -1,
      "name": "Plant_Coral_Block_Orange"
    },
    {
      "x": 1,
      "y": 1,
      "z": -1,
      "name": "Plant_Coral_Block_Orange"
    },
    {
      "x": 1,
      "y": 2,
      "z": -1,
      "name": "Plant_Coral_Block_Orange"
    },
    {
      "x": 1,
      "y": 3,
      "z": -1,
      "name": "Plant_Coral_Block_Orange"
    },
    {
      "x": 1,
      "y": 4,
      "z": -1,
      "name": "Plant_Coral_Block_Orange"
    },
    {
      "x": 1,
      "y": 5,
      "z": -1,
      "name": "Plant_Coral_Block_Orange"
    },
    {
      "x": 1,
      "y": 6,
      "z": -1,
      "name": "Plant_Coral_Block_Orange"
    },
    {
      "x": 1,
      "y": 7,
      "z": -1,
      "name": "Plant_Coral_Block_Orange"
    },
    {
      "x": 1,
      "y": 10,
      "z": -1,
      "name": "Plant_Coral_Bush_Orange"
    },
    {
      "x": 1,
      "y": 11,
      "z": -1,
      "name": "Empty"
    },
    {
      "x": 1,
      "y": 12,
      "z": -1,
      "name": "Empty"
    },
    {
      "x": 1,
      "y": 16,
      "z": -1,
      "name": "Empty"
    },
    {
      "x": 1,
      "y": 17,
      "z": -1,
      "name": "Empty"
    },
    {
      "x": 1,
      "y": 18,
      "z": -1,
      "name": "Plant_Coral_Block_Orange"
    },
    {
      "x": 1,
      "y": 19,
      "z": -1,
      "name": "Plant_Coral_Block_Orange"
    },
    {
      "x": 1,
      "y": 20,
      "z": -1,
      "name": "Plant_Coral_Block_Orange"
    },
    {
      "x": 1,
      "y": 21,
      "z": -1,
      "name": "Plant_Coral_Block_Orange"
    },
    {
      "x": 1,
      "y": 0,
      "z": 0,
      "name": "Plant_Coral_Block_Orange"
    },
    {
      "x": 1,
      "y": 1,
      "z": 0,
      "name": "Plant_Coral_Block_Orange"
    },
    {
      "x": 1,
      "y": 2,
      "z": 0,
      "name": "Rock_Crystal_Orange_Medium"
    },
    {
      "x": 1,
      "y": 4,
      "z": 0,
      "name": "Plant_Coral_Bush_Orange"
    },
    {
      "x": 1,
      "y": 5,
      "z": 0,
      "name": "Plant_Coral_Bush_Orange"
    },
    {
      "x": 1,
      "y": 9,
      "z": 0,
      "name": "Plant_Coral_Bush_Orange"
    },
    {
      "x": 1,
      "y": 11,
      "z": 0,
      "name": "Empty"
    },
    {
      "x": 1,
      "y": 12,
      "z": 0,
      "name": "Empty"
    },
    {
      "x": 1,
      "y": 13,
      "z": 0,
      "name": "Empty"
    },
    {
      "x": 1,
      "y": 14,
      "z": 0,
      "name": "Empty"
    },
    {
      "x": 1,
      "y": 15,
      "z": 0,
      "name": "Empty"
    },
    {
      "x": 1,
      "y": 16,
      "z": 0,
      "name": "Empty"
    },
    {
      "x": 1,
      "y": 17,
      "z": 0,
      "name": "Empty"
    },
    {
      "x": 1,
      "y": 20,
      "z": 0,
      "name": "Plant_Coral_Bush_Orange"
    },
    {
      "x": 1,
      "y": 0,
      "z": 1,
      "name": "Plant_Coral_Block_Orange"
    },
    {
      "x": 1,
      "y": 1,
      "z": 1,
      "name": "Plant_Coral_Bush_Orange"
    },
    {
      "x": 1,
      "y": 10,
      "z": 1,
      "name": "Plant_Coral_Bush_Orange"
    },
    {
      "x": 1,
      "y": 11,
      "z": 1,
      "name": "Empty"
    },
    {
      "x": 1,
      "y": 12,
      "z": 1,
      "name": "Empty"
    },
    {
      "x": 1,
      "y": 13,
      "z": 1,
      "name": "Empty"
    },
    {
      "x": 1,
      "y": 14,
      "z": 1,
      "name": "Empty"
    },
    {
      "x": 1,
      "y": 15,
      "z": 1,
      "name": "Empty"
    },
    {
      "x": 1,
      "y": 16,
      "z": 1,
      "name": "Empty"
    },
    {
      "x": 1,
      "y": 18,
      "z": 1,
      "name": "Plant_Coral_Bush_Orange"
    },
    {
      "x": 1,
      "y": 20,
      "z": 1,
      "name": "Plant_Coral_Bush_Orange"
    },
    {
      "x": 1,
      "y": 0,
      "z": 2,
      "name": "Plant_Coral_Block_Orange"
    },
    {
      "x": 1,
      "y": 3,
      "z": 2,
      "name": "Plant_Coral_Bush_Orange"
    },
    {
      "x": 1,
      "y": 4,
      "z": 2,
      "name": "Plant_Coral_Bush_Orange"
    },
    {
      "x": 1,
      "y": 5,
      "z": 2,
      "name": "Plant_Coral_Bush_Orange"
    },
    {
      "x": 1,
      "y": 8,
      "z": 2,
      "name": "Plant_Coral_Block_Orange"
    },
    {
      "x": 1,
      "y": 9,
      "z": 2,
      "name": "Plant_Coral_Block_Orange"
    },
    {
      "x": 1,
      "y": 10,
      "z": 2,
      "name": "Plant_Coral_Block_Orange"
    },
    {
      "x": 1,
      "y": 11,
      "z": 2,
      "name": "Empty"
    },
    {
      "x": 1,
      "y": 12,
      "z": 2,
      "name": "Plant_Coral_Bush_Orange"
    },
    {
      "x": 1,
      "y": 13,
      "z": 2,
      "name": "Empty"
    },
    {
      "x": 1,
      "y": 14,
      "z": 2,
      "name": "Empty"
    },
    {
      "x": 1,
      "y": 15,
      "z": 2,
      "name": "Empty"
    },
    {
      "x": 1,
      "y": 16,
      "z": 2,
      "name": "Empty"
    },
    {
      "x": 1,
      "y": 18,
      "z": 2,
      "name": "Plant_Coral_Bush_Orange"
    },
    {
      "x": 1,
      "y": 0,
      "z": 3,
      "name": "Plant_Coral_Block_Orange"
    },
    {
      "x": 1,
      "y": 1,
      "z": 3,
      "name": "Plant_Coral_Block_Orange"
    },
    {
      "x": 1,
      "y": 2,
      "z": 3,
      "name": "Plant_Coral_Block_Orange"
    },
    {
      "x": 1,
      "y": 3,
      "z": 3,
      "name": "Plant_Coral_Block_Orange"
    },
    {
      "x": 1,
      "y": 4,
      "z": 3,
      "name": "Plant_Coral_Block_Orange"
    },
    {
      "x": 1,
      "y": 5,
      "z": 3,
      "name": "Plant_Coral_Block_Orange"
    },
    {
      "x": 1,
      "y": 6,
      "z": 3,
      "name": "Plant_Coral_Block_Orange"
    },
    {
      "x": 1,
      "y": 7,
      "z": 3,
      "name": "Plant_Coral_Block_Orange"
    },
    {
      "x": 1,
      "y": 8,
      "z": 3,
      "name": "Plant_Coral_Block_Orange"
    },
    {
      "x": 1,
      "y": 9,
      "z": 3,
      "name": "Rock_Crystal_Orange_Small"
    },
    {
      "x": 1,
      "y": 11,
      "z": 3,
      "name": "Plant_Coral_Block_Orange"
    },
    {
      "x": 1,
      "y": 12,
      "z": 3,
      "name": "Plant_Coral_Block_Orange"
    },
    {
      "x": 1,
      "y": 13,
      "z": 3,
      "name": "Plant_Coral_Block_Orange"
    },
    {
      "x": 1,
      "y": 14,
      "z": 3,
      "name": "Rock_Crystal_Orange_Large"
    },
    {
      "x": 1,
      "y": 15,
      "z": 3,
      "name": "Plant_Coral_Bush_Orange"
    },
    {
      "x": 1,
      "y": 18,
      "z": 3,
      "name": "Plant_Coral_Block_Orange"
    },
    {
      "x": 1,
      "y": 19,
      "z": 3,
      "name": "Plant_Coral_Block_Orange"
    },
    {
      "x": 1,
      "y": 20,
      "z": 3,
      "name": "Plant_Coral_Block_Orange"
    },
    {
      "x": 1,
      "y": 21,
      "z": 3,
      "name": "Plant_Coral_Block_Orange"
    },
    {
      "x": 1,
      "y": 22,
      "z": 3,
      "name": "Plant_Coral_Model_Orange"
    },
    {
      "x": 1,
      "y": 13,
      "z": 4,
      "name": "Plant_Coral_Block_Orange"
    },
    {
      "x": 1,
      "y": 14,
      "z": 4,
      "name": "Plant_Coral_Block_Orange"
    },
    {
      "x": 1,
      "y": 15,
      "z": 4,
      "name": "Plant_Coral_Block_Orange"
    },
    {
      "x": 1,
      "y": 16,
      "z": 4,
      "name": "Plant_Coral_Block_Orange"
    },
    {
      "x": 1,
      "y": 17,
      "z": 4,
      "name": "Plant_Coral_Block_Orange"
    },
    {
      "x": 1,
      "y": 19,
      "z": 4,
      "name": "Plant_Coral_Block_Blue"
    },
    {
      "x": 1,
      "y": 16,
      "z": 5,
      "name": "Plant_Coral_Block_Blue"
    },
    {
      "x": 1,
      "y": 18,
      "z": 5,
      "name": "Plant_Crop_Mushroom_Block_Blue_Mycelium"
    },
    {
      "x": 1,
      "y": 19,
      "z": 5,
      "name": "Plant_Coral_Block_Blue"
    },
    {
      "x": 1,
      "y": 16,
      "z": 6,
      "name": "Plant_Coral_Block_Orange"
    },
    {
      "x": 2,
      "y": 9,
      "z": -6,
      "name": "Plant_Coral_Block_Orange"
    },
    {
      "x": 2,
      "y": 9,
      "z": -5,
      "name": "Plant_Coral_Block_Blue"
    },
    {
      "x": 2,
      "y": 9,
      "z": -4,
      "name": "Plant_Coral_Block_Blue"
    },
    {
      "x": 2,
      "y": 16,
      "z": -4,
      "name": "Plant_Coral_Block_Orange"
    },
    {
      "x": 2,
      "y": 9,
      "z": -3,
      "name": "Plant_Coral_Block_Blue"
    },
    {
      "x": 2,
      "y": 15,
      "z": -3,
      "name": "Plant_Crop_Mushroom_Block_Blue_Mycelium"
    },
    {
      "x": 2,
      "y": 16,
      "z": -3,
      "name": "Plant_Coral_Block_Blue"
    },
    {
      "x": 2,
      "y": 9,
      "z": -2,
      "name": "Plant_Coral_Block_Blue"
    },
    {
      "x": 2,
      "y": 10,
      "z": -2,
      "name": "Plant_Coral_Block_Orange"
    },
    {
      "x": 2,
      "y": 11,
      "z": -2,
      "name": "Plant_Coral_Block_Orange"
    },
    {
      "x": 2,
      "y": 12,
      "z": -2,
      "name": "Plant_Coral_Block_Orange"
    },
    {
      "x": 2,
      "y": 13,
      "z": -2,
      "name": "Plant_Coral_Block_Orange"
    },
    {
      "x": 2,
      "y": 14,
      "z": -2,
      "name": "Plant_Coral_Block_Orange"
    },
    {
      "x": 2,
      "y": 16,
      "z": -2,
      "name": "Plant_Coral_Block_Blue"
    },
    {
      "x": 2,
      "y": 8,
      "z": -1,
      "name": "Plant_Coral_Block_Orange"
    },
    {
      "x": 2,
      "y": 9,
      "z": -1,
      "name": "Plant_Coral_Block_Orange"
    },
    {
      "x": 2,
      "y": 10,
      "z": -1,
      "name": "Plant_Coral_Block_Orange"
    },
    {
      "x": 2,
      "y": 11,
      "z": -1,
      "name": "Plant_Coral_Bush_Orange"
    },
    {
      "x": 2,
      "y": 12,
      "z": -1,
      "name": "Plant_Coral_Bush_Orange"
    },
    {
      "x": 2,
      "y": 14,
      "z": -1,
      "name": "Plant_Coral_Block_Orange"
    },
    {
      "x": 2,
      "y": 15,
      "z": -1,
      "name": "Plant_Coral_Block_Orange"
    },
    {
      "x": 2,
      "y": 16,
      "z": -1,
      "name": "Plant_Coral_Block_Orange"
    },
    {
      "x": 2,
      "y": 17,
      "z": -1,
      "name": "Plant_Coral_Block_Orange"
    },
    {
      "x": 2,
      "y": 18,
      "z": -1,
      "name": "Plant_Coral_Block_Orange"
    },
    {
      "x": 2,
      "y": 0,
      "z": 0,
      "name": "Plant_Coral_Block_Orange"
    },
    {
      "x": 2,
      "y": 1,
      "z": 0,
      "name": "Plant_Coral_Block_Orange"
    },
    {
      "x": 2,
      "y": 2,
      "z": 0,
      "name": "Plant_Coral_Block_Orange"
    },
    {
      "x": 2,
      "y": 3,
      "z": 0,
      "name": "Plant_Coral_Block_Orange"
    },
    {
      "x": 2,
      "y": 4,
      "z": 0,
      "name": "Plant_Coral_Block_Orange"
    },
    {
      "x": 2,
      "y": 5,
      "z": 0,
      "name": "Plant_Coral_Block_Orange"
    },
    {
      "x": 2,
      "y": 6,
      "z": 0,
      "name": "Plant_Coral_Block_Orange"
    },
    {
      "x": 2,
      "y": 7,
      "z": 0,
      "name": "Plant_Coral_Block_Orange"
    },
    {
      "x": 2,
      "y": 8,
      "z": 0,
      "name": "Plant_Coral_Block_Orange"
    },
    {
      "x": 2,
      "y": 9,
      "z": 0,
      "name": "Plant_Coral_Block_Orange"
    },
    {
      "x": 2,
      "y": 10,
      "z": 0,
      "name": "Plant_Coral_Block_Orange"
    },
    {
      "x": 2,
      "y": 13,
      "z": 0,
      "name": "Plant_Coral_Bush_Orange"
    },
    {
      "x": 2,
      "y": 15,
      "z": 0,
      "name": "Plant_Coral_Bush_Orange"
    },
    {
      "x": 2,
      "y": 17,
      "z": 0,
      "name": "Plant_Coral_Bush_Orange"
    },
    {
      "x": 2,
      "y": 18,
      "z": 0,
      "name": "Plant_Coral_Block_Orange"
    },
    {
      "x": 2,
      "y": 19,
      "z": 0,
      "name": "Plant_Coral_Block_Orange"
    },
    {
      "x": 2,
      "y": 20,
      "z": 0,
      "name": "Plant_Coral_Block_Orange"
    },
    {
      "x": 2,
      "y": 21,
      "z": 0,
      "name": "Plant_Coral_Block_Orange"
    },
    {
      "x": 2,
      "y": 0,
      "z": 1,
      "name": "Plant_Coral_Block_Orange"
    },
    {
      "x": 2,
      "y": 1,
      "z": 1,
      "name": "Plant_Coral_Block_Orange"
    },
    {
      "x": 2,
      "y": 2,
      "z": 1,
      "name": "Plant_Coral_Block_Orange"
    },
    {
      "x": 2,
      "y": 3,
      "z": 1,
      "name": "Plant_Coral_Block_Orange"
    },
    {
      "x": 2,
      "y": 4,
      "z": 1,
      "name": "Plant_Coral_Block_Orange"
    },
    {
      "x": 2,
      "y": 5,
      "z": 1,
      "name": "Plant_Coral_Block_Orange"
    },
    {
      "x": 2,
      "y": 6,
      "z": 1,
      "name": "Plant_Coral_Block_Orange"
    },
    {
      "x": 2,
      "y": 7,
      "z": 1,
      "name": "Plant_Coral_Block_Orange"
    },
    {
      "x": 2,
      "y": 8,
      "z": 1,
      "name": "Plant_Coral_Block_Orange"
    },
    {
      "x": 2,
      "y": 9,
      "z": 1,
      "name": "Plant_Coral_Block_Orange"
    },
    {
      "x": 2,
      "y": 10,
      "z": 1,
      "name": "Plant_Coral_Block_Orange"
    },
    {
      "x": 2,
      "y": 11,
      "z": 1,
      "name": "Plant_Coral_Model_Orange"
    },
    {
      "x": 2,
      "y": 14,
      "z": 1,
      "name": "Plant_Coral_Bush_Orange"
    },
    {
      "x": 2,
      "y": 17,
      "z": 1,
      "name": "Plant_Coral_Bush_Orange"
    },
    {
      "x": 2,
      "y": 18,
      "z": 1,
      "name": "Plant_Coral_Block_Orange"
    },
    {
      "x": 2,
      "y": 19,
      "z": 1,
      "name": "Plant_Coral_Block_Orange"
    },
    {
      "x": 2,
      "y": 20,
      "z": 1,
      "name": "Plant_Coral_Block_Orange"
    },
    {
      "x": 2,
      "y": 21,
      "z": 1,
      "name": "Plant_Coral_Block_Orange"
    },
    {
      "x": 2,
      "y": 0,
      "z": 2,
      "name": "Plant_Coral_Block_Orange"
    },
    {
      "x": 2,
      "y": 1,
      "z": 2,
      "name": "Plant_Coral_Block_Orange"
    },
    {
      "x": 2,
      "y": 2,
      "z": 2,
      "name": "Plant_Coral_Block_Orange"
    },
    {
      "x": 2,
      "y": 3,
      "z": 2,
      "name": "Plant_Coral_Block_Orange"
    },
    {
      "x": 2,
      "y": 4,
      "z": 2,
      "name": "Plant_Coral_Block_Orange"
    },
    {
      "x": 2,
      "y": 5,
      "z": 2,
      "name": "Plant_Coral_Block_Orange"
    },
    {
      "x": 2,
      "y": 6,
      "z": 2,
      "name": "Plant_Coral_Block_Orange"
    },
    {
      "x": 2,
      "y": 7,
      "z": 2,
      "name": "Plant_Coral_Block_Orange"
    },
    {
      "x": 2,
      "y": 8,
      "z": 2,
      "name": "Plant_Coral_Model_Orange"
    },
    {
      "x": 2,
      "y": 10,
      "z": 2,
      "name": "Plant_Coral_Block_Orange"
    },
    {
      "x": 2,
      "y": 11,
      "z": 2,
      "name": "Plant_Coral_Block_Orange"
    },
    {
      "x": 2,
      "y": 12,
      "z": 2,
      "name": "Plant_Coral_Block_Orange"
    },
    {
      "x": 2,
      "y": 13,
      "z": 2,
      "name": "Plant_Coral_Block_Orange"
    },
    {
      "x": 2,
      "y": 17,
      "z": 2,
      "name": "Plant_Coral_Bush_Orange"
    },
    {
      "x": 2,
      "y": 18,
      "z": 2,
      "name": "Plant_Coral_Block_Orange"
    },
    {
      "x": 2,
      "y": 19,
      "z": 2,
      "name": "Plant_Coral_Block_Orange"
    },
    {
      "x": 2,
      "y": 20,
      "z": 2,
      "name": "Plant_Coral_Block_Orange"
    },
    {
      "x": 2,
      "y": 21,
      "z": 2,
      "name": "Plant_Coral_Block_Orange"
    },
    {
      "x": 2,
      "y": 13,
      "z": 3,
      "name": "Plant_Coral_Block_Orange"
    },
    {
      "x": 2,
      "y": 14,
      "z": 3,
      "name": "Plant_Coral_Block_Orange"
    },
    {
      "x": 2,
      "y": 15,
      "z": 3,
      "name": "Plant_Coral_Block_Orange"
    },
    {
      "x": 2,
      "y": 16,
      "z": 3,
      "name": "Plant_Coral_Block_Orange"
    },
    {
      "x": 2,
      "y": 17,
      "z": 3,
      "name": "Plant_Coral_Block_Orange"
    },
    {
      "x": 2,
      "y": 18,
      "z": 3,
      "name": "Plant_Coral_Block_Orange"
    },
    {
      "x": 2,
      "y": 16,
      "z": 4,
      "name": "Plant_Coral_Block_Blue"
    },
    {
      "x": 2,
      "y": 19,
      "z": 4,
      "name": "Plant_Coral_Block_Orange"
    },
    {
      "x": 2,
      "y": 16,
      "z": 5,
      "name": "Plant_Coral_Block_Blue"
    },
    {
      "x": 2,
      "y": 19,
      "z": 5,
      "name": "Plant_Coral_Block_Orange"
    },
    {
      "x": 2,
      "y": 16,
      "z": 6,
      "name": "Plant_Coral_Block_Orange"
    },
    {
      "x": 2,
      "y": 19,
      "z": 6,
      "name": "Plant_Coral_Block_Orange"
    },
    {
      "x": 3,
      "y": 9,
      "z": -5,
      "name": "Plant_Coral_Block_Orange"
    },
    {
      "x": 3,
      "y": 9,
      "z": -4,
      "name": "Plant_Coral_Block_Orange"
    },
    {
      "x": 3,
      "y": 16,
      "z": -3,
      "name": "Plant_Coral_Block_Blue"
    },
    {
      "x": 3,
      "y": 9,
      "z": -2,
      "name": "Plant_Coral_Block_Orange"
    },
    {
      "x": 3,
      "y": 16,
      "z": -2,
      "name": "Plant_Coral_Block_Blue"
    },
    {
      "x": 3,
      "y": 17,
      "z": -2,
      "name": "Plant_Coral_Bush_Blue"
    },
    {
      "x": 3,
      "y": 9,
      "z": -1,
      "name": "Plant_Coral_Block_Orange"
    },
    {
      "x": 3,
      "y": 10,
      "z": -1,
      "name": "Plant_Coral_Block_Orange"
    },
    {
      "x": 3,
      "y": 11,
      "z": -1,
      "name": "Plant_Coral_Block_Orange"
    },
    {
      "x": 3,
      "y": 12,
      "z": -1,
      "name": "Plant_Coral_Block_Orange"
    },
    {
      "x": 3,
      "y": 13,
      "z": -1,
      "name": "Plant_Coral_Block_Orange"
    },
    {
      "x": 3,
      "y": 16,
      "z": -1,
      "name": "Plant_Coral_Block_Blue"
    },
    {
      "x": 3,
      "y": 17,
      "z": -1,
      "name": "Rock_Crystal_Cyan_Small"
    },
    {
      "x": 3,
      "y": 9,
      "z": 0,
      "name": "Plant_Coral_Block_Orange"
    },
    {
      "x": 3,
      "y": 10,
      "z": 0,
      "name": "Plant_Coral_Block_Orange"
    },
    {
      "x": 3,
      "y": 11,
      "z": 0,
      "name": "Plant_Coral_Block_Orange"
    },
    {
      "x": 3,
      "y": 12,
      "z": 0,
      "name": "Plant_Coral_Block_Orange"
    },
    {
      "x": 3,
      "y": 13,
      "z": 0,
      "name": "Plant_Coral_Block_Orange"
    },
    {
      "x": 3,
      "y": 14,
      "z": 0,
      "name": "Plant_Coral_Block_Orange"
    },
    {
      "x": 3,
      "y": 15,
      "z": 0,
      "name": "Plant_Coral_Block_Orange"
    },
    {
      "x": 3,
      "y": 16,
      "z": 0,
      "name": "Plant_Coral_Block_Orange"
    },
    {
      "x": 3,
      "y": 17,
      "z": 0,
      "name": "Plant_Coral_Block_Orange"
    },
    {
      "x": 3,
      "y": 18,
      "z": 0,
      "name": "Plant_Coral_Block_Orange"
    },
    {
      "x": 3,
      "y": 10,
      "z": 1,
      "name": "Plant_Coral_Block_Orange"
    },
    {
      "x": 3,
      "y": 11,
      "z": 1,
      "name": "Plant_Coral_Block_Orange"
    },
    {
      "x": 3,
      "y": 12,
      "z": 1,
      "name": "Plant_Coral_Block_Orange"
    },
    {
      "x": 3,
      "y": 13,
      "z": 1,
      "name": "Plant_Coral_Block_Orange"
    },
    {
      "x": 3,
      "y": 14,
      "z": 1,
      "name": "Plant_Coral_Block_Orange"
    },
    {
      "x": 3,
      "y": 15,
      "z": 1,
      "name": "Plant_Coral_Block_Orange"
    },
    {
      "x": 3,
      "y": 16,
      "z": 1,
      "name": "Plant_Coral_Block_Orange"
    },
    {
      "x": 3,
      "y": 17,
      "z": 1,
      "name": "Plant_Coral_Block_Orange"
    },
    {
      "x": 3,
      "y": 18,
      "z": 1,
      "name": "Plant_Coral_Block_Orange"
    },
    {
      "x": 3,
      "y": 14,
      "z": 2,
      "name": "Plant_Coral_Block_Orange"
    },
    {
      "x": 3,
      "y": 15,
      "z": 2,
      "name": "Plant_Coral_Block_Orange"
    },
    {
      "x": 3,
      "y": 16,
      "z": 2,
      "name": "Plant_Coral_Block_Orange"
    },
    {
      "x": 3,
      "y": 17,
      "z": 2,
      "name": "Plant_Coral_Block_Orange"
    },
    {
      "x": 3,
      "y": 18,
      "z": 2,
      "name": "Plant_Coral_Block_Orange"
    },
    {
      "x": 3,
      "y": 16,
      "z": 3,
      "name": "Plant_Coral_Block_Blue"
    },
    {
      "x": 3,
      "y": 17,
      "z": 3,
      "name": "Plant_Coral_Model_Blue"
    },
    {
      "x": 3,
      "y": 16,
      "z": 4,
      "name": "Plant_Coral_Block_Blue"
    },
    {
      "x": 3,
      "y": 16,
      "z": 5,
      "name": "Plant_Coral_Block_Blue"
    },
    {
      "x": 4,
      "y": 16,
      "z": -4,
      "name": "Plant_Coral_Block_Orange"
    },
    {
      "x": 4,
      "y": 16,
      "z": -3,
      "name": "Plant_Coral_Block_Blue"
    },
    {
      "x": 4,
      "y": 16,
      "z": -2,
      "name": "Plant_Coral_Block_Blue"
    },
    {
      "x": 4,
      "y": 15,
      "z": -1,
      "name": "Rock_Crystal_Cyan_Small",
      "rotation": 8
    },
    {
      "x": 4,
      "y": 16,
      "z": -1,
      "name": "Plant_Coral_Block_Blue"
    },
    {
      "x": 4,
      "y": 17,
      "z": -1,
      "name": "Plant_Coral_Model_Blue"
    },
    {
      "x": 4,
      "y": 16,
      "z": 0,
      "name": "Plant_Coral_Block_Blue"
    },
    {
      "x": 4,
      "y": 17,
      "z": 0,
      "name": "Plant_Coral_Bush_Blue"
    },
    {
      "x": 4,
      "y": 16,
      "z": 1,
      "name": "Plant_Coral_Block_Blue"
    },
    {
      "x": 4,
      "y": 17,
      "z": 1,
      "name": "Rock_Crystal_Cyan_Small"
    },
    {
      "x": 4,
      "y": 15,
      "z": 2,
      "name": "Rock_Crystal_Cyan_Small",
      "rotation": 8
    },
    {
      "x": 4,
      "y": 16,
      "z": 2,
      "name": "Plant_Coral_Block_Blue"
    },
    {
      "x": 4,
      "y": 17,
      "z": 2,
      "name": "Plant_Coral_Bush_Blue"
    },
    {
      "x": 4,
      "y": 16,
      "z": 3,
      "name": "Plant_Coral_Block_Blue"
    },
    {
      "x": 4,
      "y": 17,
      "z": 3,
      "name": "Plant_Coral_Bush_Blue"
    },
    {
      "x": 4,
      "y": 15,
      "z": 4,
      "name": "Plant_Crop_Mushroom_Block_Blue_Mycelium"
    },
    {
      "x": 4,
      "y": 16,
      "z": 4,
      "name": "Plant_Coral_Block_Blue"
    },
    {
      "x": 4,
      "y": 16,
      "z": 5,
      "name": "Plant_Coral_Block_Blue"
    },
    {
      "x": 4,
      "y": 16,
      "z": 6,
      "name": "Plant_Coral_Block_Orange"
    },
    {
      "x": 5,
      "y": 16,
      "z": -4,
      "name": "Plant_Coral_Block_Orange"
    },
    {
      "x": 5,
      "y": 16,
      "z": -3,
      "name": "Plant_Coral_Block_Blue"
    },
    {
      "x": 5,
      "y": 15,
      "z": -2,
      "name": "Plant_Crop_Mushroom_Block_Blue_Mycelium"
    },
    {
      "x": 5,
      "y": 16,
      "z": -2,
      "name": "Plant_Coral_Block_Blue"
    },
    {
      "x": 5,
      "y": 16,
      "z": -1,
      "name": "Plant_Coral_Block_Blue"
    },
    {
      "x": 5,
      "y": 16,
      "z": 0,
      "name": "Plant_Coral_Block_Blue"
    },
    {
      "x": 5,
      "y": 16,
      "z": 1,
      "name": "Plant_Coral_Block_Blue"
    },
    {
      "x": 5,
      "y": 17,
      "z": 1,
      "name": "Plant_Coral_Model_Blue"
    },
    {
      "x": 5,
      "y": 16,
      "z": 2,
      "name": "Plant_Coral_Block_Blue"
    },
    {
      "x": 5,
      "y": 16,
      "z": 3,
      "name": "Plant_Coral_Block_Blue"
    },
    {
      "x": 5,
      "y": 16,
      "z": 4,
      "name": "Plant_Coral_Block_Blue"
    },
    {
      "x": 5,
      "y": 16,
      "z": 5,
      "name": "Plant_Coral_Block_Blue"
    },
    {
      "x": 5,
      "y": 16,
      "z": 6,
      "name": "Plant_Coral_Block_Orange"
    },
    {
      "x": 6,
      "y": 16,
      "z": -4,
      "name": "Plant_Coral_Block_Orange"
    },
    {
      "x": 6,
      "y": 16,
      "z": -2,
      "name": "Plant_Coral_Block_Blue"
    },
    {
      "x": 6,
      "y": 16,
      "z": -1,
      "name": "Plant_Coral_Block_Blue"
    },
    {
      "x": 6,
      "y": 16,
      "z": 0,
      "name": "Plant_Coral_Block_Blue"
    },
    {
      "x": 6,
      "y": 17,
      "z": 0,
      "name": "Plant_Coral_Bush_Blue"
    },
    {
      "x": 6,
      "y": 15,
      "z": 1,
      "name": "Plant_Crop_Mushroom_Block_Blue_Mycelium"
    },
    {
      "x": 6,
      "y": 16,
      "z": 1,
      "name": "Plant_Coral_Block_Blue"
    },
    {
      "x": 6,
      "y": 16,
      "z": 2,
      "name": "Plant_Coral_Block_Blue"
    },
    {
      "x": 6,
      "y": 16,
      "z": 3,
      "name": "Plant_Coral_Block_Blue"
    },
    {
      "x": 6,
      "y": 15,
      "z": 4,
      "name": "Plant_Crop_Mushroom_Block_Blue_Mycelium"
    },
    {
      "x": 6,
      "y": 16,
      "z": 4,
      "name": "Plant_Coral_Block_Blue"
    },
    {
      "x": 6,
      "y": 16,
      "z": 5,
      "name": "Plant_Coral_Block_Orange"
    },
    {
      "x": 7,
      "y": 16,
      "z": -2,
      "name": "Plant_Coral_Block_Orange"
    },
    {
      "x": 7,
      "y": 16,
      "z": -1,
      "name": "Plant_Coral_Block_Blue"
    },
    {
      "x": 7,
      "y": 16,
      "z": 0,
      "name": "Plant_Coral_Block_Blue"
    },
    {
      "x": 7,
      "y": 16,
      "z": 1,
      "name": "Plant_Coral_Block_Blue"
    },
    {
      "x": 7,
      "y": 16,
      "z": 2,
      "name": "Plant_Coral_Block_Blue"
    },
    {
      "x": 7,
      "y": 16,
      "z": 3,
      "name": "Plant_Coral_Block_Blue"
    },
    {
      "x": 8,
      "y": 16,
      "z": -2,
      "name": "Plant_Coral_Block_Orange"
    },
    {
      "x": 8,
      "y": 16,
      "z": -1,
      "name": "Plant_Coral_Block_Orange"
    },
    {
      "x": 8,
      "y": 16,
      "z": 0,
      "name": "Plant_Coral_Block_Orange"
    },
    {
      "x": 8,
      "y": 16,
      "z": 2,
      "name": "Plant_Coral_Block_Orange"
    },
    {
      "x": 8,
      "y": 16,
      "z": 3,
      "name": "Plant_Coral_Block_Orange"
    },
    {
      "x": 8,
      "y": 16,
      "z": 4,
      "name": "Plant_Coral_Block_Orange"
    }
  ],
  "fluids": [
    {
      "x": -6,
      "y": 8,
      "z": -5,
      "name": "Water_Source",
      "level": 1
    },
    {
      "x": -6,
      "y": 18,
      "z": 1,
      "name": "Water_Source",
      "level": 1
    },
    {
      "x": -6,
      "y": 18,
      "z": 2,
      "name": "Water_Source",
      "level": 1
    },
    {
      "x": -6,
      "y": 20,
      "z": 2,
      "name": "Water_Source",
      "level": 1
    },
    {
      "x": -6,
      "y": 18,
      "z": 4,
      "name": "Water_Source",
      "level": 1
    },
    {
      "x": -6,
      "y": 20,
      "z": 4,
      "name": "Water_Source",
      "level": 1
    },
    {
      "x": -5,
      "y": 10,
      "z": -4,
      "name": "Water_Source",
      "level": 1
    },
    {
      "x": -5,
      "y": 10,
      "z": -3,
      "name": "Water_Source",
      "level": 1
    },
    {
      "x": -5,
      "y": 8,
      "z": -2,
      "name": "Water_Source",
      "level": 1
    },
    {
      "x": -5,
      "y": 10,
      "z": -2,
      "name": "Water_Source",
      "level": 1
    },
    {
      "x": -5,
      "y": 10,
      "z": -1,
      "name": "Water_Source",
      "level": 1
    },
    {
      "x": -5,
      "y": 8,
      "z": 0,
      "name": "Water_Source",
      "level": 1
    },
    {
      "x": -5,
      "y": 20,
      "z": 1,
      "name": "Water_Source",
      "level": 1
    },
    {
      "x": -5,
      "y": 18,
      "z": 2,
      "name": "Water_Source",
      "level": 1
    },
    {
      "x": -5,
      "y": 20,
      "z": 2,
      "name": "Water_Source",
      "level": 1
    },
    {
      "x": -5,
      "y": 20,
      "z": 3,
      "name": "Water_Source",
      "level": 1
    },
    {
      "x": -5,
      "y": 20,
      "z": 5,
      "name": "Water_Source",
      "level": 1
    },
    {
      "x": -4,
      "y": 8,
      "z": -6,
      "name": "Water_Source",
      "level": 1
    },
    {
      "x": -4,
      "y": 10,
      "z": -5,
      "name": "Water_Source",
      "level": 1
    },
    {
      "x": -4,
      "y": 10,
      "z": -3,
      "name": "Water_Source",
      "level": 1
    },
    {
      "x": -4,
      "y": 8,
      "z": -2,
      "name": "Water_Source",
      "level": 1
    },
    {
      "x": -4,
      "y": 10,
      "z": -2,
      "name": "Water_Source",
      "level": 1
    },
    {
      "x": -4,
      "y": 18,
      "z": -1,
      "name": "Water_Source",
      "level": 1
    },
    {
      "x": -4,
      "y": 20,
      "z": -1,
      "name": "Water_Source",
      "level": 1
    },
    {
      "x": -4,
      "y": 8,
      "z": 2,
      "name": "Water_Source",
      "level": 1
    },
    {
      "x": -4,
      "y": 20,
      "z": 4,
      "name": "Water_Source",
      "level": 1
    },
    {
      "x": -3,
      "y": 10,
      "z": -3,
      "name": "Water_Source",
      "level": 1
    },
    {
      "x": -3,
      "y": 20,
      "z": -2,
      "name": "Water_Source",
      "level": 1
    },
    {
      "x": -3,
      "y": 8,
      "z": -1,
      "name": "Water_Source",
      "level": 1
    },
    {
      "x": -3,
      "y": 9,
      "z": -1,
      "name": "Water_Source",
      "level": 1
    },
    {
      "x": -3,
      "y": 10,
      "z": -1,
      "name": "Water_Source",
      "level": 1
    },
    {
      "x": -3,
      "y": 14,
      "z": -1,
      "name": "Water_Source",
      "level": 1
    },
    {
      "x": -3,
      "y": 2,
      "z": 0,
      "name": "Water_Source",
      "level": 1
    },
    {
      "x": -3,
      "y": 3,
      "z": 0,
      "name": "Water_Source",
      "level": 1
    },
    {
      "x": -3,
      "y": 4,
      "z": 0,
      "name": "Water_Source",
      "level": 1
    },
    {
      "x": -3,
      "y": 5,
      "z": 0,
      "name": "Water_Source",
      "level": 1
    },
    {
      "x": -3,
      "y": 6,
      "z": 0,
      "name": "Water_Source",
      "level": 1
    },
    {
      "x": -3,
      "y": 7,
      "z": 0,
      "name": "Water_Source",
      "level": 1
    },
    {
      "x": -3,
      "y": 8,
      "z": 0,
      "name": "Water_Source",
      "level": 1
    },
    {
      "x": -3,
      "y": 9,
      "z": 0,
      "name": "Water_Source",
      "level": 1
    },
    {
      "x": -3,
      "y": 10,
      "z": 0,
      "name": "Water_Source",
      "level": 1
    },
    {
      "x": -3,
      "y": 18,
      "z": 0,
      "name": "Water_Source",
      "level": 1
    },
    {
      "x": -3,
      "y": 19,
      "z": 0,
      "name": "Water_Source",
      "level": 1
    },
    {
      "x": -3,
      "y": 20,
      "z": 0,
      "name": "Water_Source",
      "level": 1
    },
    {
      "x": -3,
      "y": 21,
      "z": 0,
      "name": "Water_Source",
      "level": 1
    },
    {
      "x": -3,
      "y": 2,
      "z": 1,
      "name": "Water_Source",
      "level": 1
    },
    {
      "x": -3,
      "y": 3,
      "z": 1,
      "name": "Water_Source",
      "level": 1
    },
    {
      "x": -3,
      "y": 4,
      "z": 1,
      "name": "Water_Source",
      "level": 1
    },
    {
      "x": -3,
      "y": 5,
      "z": 1,
      "name": "Water_Source",
      "level": 1
    },
    {
      "x": -3,
      "y": 6,
      "z": 1,
      "name": "Water_Source",
      "level": 1
    },
    {
      "x": -3,
      "y": 7,
      "z": 1,
      "name": "Water_Source",
      "level": 1
    },
    {
      "x": -3,
      "y": 8,
      "z": 1,
      "name": "Water_Source",
      "level": 1
    },
    {
      "x": -3,
      "y": 9,
      "z": 1,
      "name": "Water_Source",
      "level": 1
    },
    {
      "x": -3,
      "y": 10,
      "z": 1,
      "name": "Water_Source",
      "level": 1
    },
    {
      "x": -3,
      "y": 18,
      "z": 1,
      "name": "Water_Source",
      "level": 1
    },
    {
      "x": -3,
      "y": 19,
      "z": 1,
      "name": "Water_Source",
      "level": 1
    },
    {
      "x": -3,
      "y": 20,
      "z": 1,
      "name": "Water_Source",
      "level": 1
    },
    {
      "x": -3,
      "y": 21,
      "z": 1,
      "name": "Water_Source",
      "level": 1
    },
    {
      "x": -3,
      "y": 2,
      "z": 2,
      "name": "Water_Source",
      "level": 1
    },
    {
      "x": -3,
      "y": 3,
      "z": 2,
      "name": "Water_Source",
      "level": 1
    },
    {
      "x": -3,
      "y": 4,
      "z": 2,
      "name": "Water_Source",
      "level": 1
    },
    {
      "x": -3,
      "y": 5,
      "z": 2,
      "name": "Water_Source",
      "level": 1
    },
    {
      "x": -3,
      "y": 6,
      "z": 2,
      "name": "Water_Source",
      "level": 1
    },
    {
      "x": -3,
      "y": 7,
      "z": 2,
      "name": "Water_Source",
      "level": 1
    },
    {
      "x": -3,
      "y": 12,
      "z": 2,
      "name": "Water_Source",
      "level": 1
    },
    {
      "x": -3,
      "y": 18,
      "z": 2,
      "name": "Water_Source",
      "level": 1
    },
    {
      "x": -3,
      "y": 19,
      "z": 2,
      "name": "Water_Source",
      "level": 1
    },
    {
      "x": -3,
      "y": 20,
      "z": 2,
      "name": "Water_Source",
      "level": 1
    },
    {
      "x": -3,
      "y": 21,
      "z": 2,
      "name": "Water_Source",
      "level": 1
    },
    {
      "x": -3,
      "y": 15,
      "z": 3,
      "name": "Water_Source",
      "level": 1
    },
    {
      "x": -3,
      "y": 20,
      "z": 4,
      "name": "Water_Source",
      "level": 1
    },
    {
      "x": -3,
      "y": 20,
      "z": 5,
      "name": "Water_Source",
      "level": 1
    },
    {
      "x": -3,
      "y": 18,
      "z": 6,
      "name": "Water_Source",
      "level": 1
    },
    {
      "x": -2,
      "y": 8,
      "z": -7,
      "name": "Water_Source",
      "level": 1
    },
    {
      "x": -2,
      "y": 10,
      "z": -6,
      "name": "Water_Source",
      "level": 1
    },
    {
      "x": -2,
      "y": 10,
      "z": -4,
      "name": "Water_Source",
      "level": 1
    },
    {
      "x": -2,
      "y": 8,
      "z": -2,
      "name": "Water_Source",
      "level": 1
    },
    {
      "x": -2,
      "y": 9,
      "z": -2,
      "name": "Water_Source",
      "level": 1
    },
    {
      "x": -2,
      "y": 10,
      "z": -2,
      "name": "Water_Source",
      "level": 1
    },
    {
      "x": -2,
      "y": 15,
      "z": -2,
      "name": "Water_Source",
      "level": 1
    },
    {
      "x": -2,
      "y": 17,
      "z": -2,
      "name": "Water_Source",
      "level": 1
    },
    {
      "x": -2,
      "y": 22,
      "z": -2,
      "name": "Water_Source",
      "level": 1
    },
    {
      "x": -2,
      "y": 1,
      "z": -1,
      "name": "Water_Source",
      "level": 1
    },
    {
      "x": -2,
      "y": 2,
      "z": -1,
      "name": "Water_Source",
      "level": 1
    },
    {
      "x": -2,
      "y": 3,
      "z": -1,
      "name": "Water_Source",
      "level": 1
    },
    {
      "x": -2,
      "y": 4,
      "z": -1,
      "name": "Water_Source",
      "level": 1
    },
    {
      "x": -2,
      "y": 5,
      "z": -1,
      "name": "Water_Source",
      "level": 1
    },
    {
      "x": -2,
      "y": 6,
      "z": -1,
      "name": "Water_Source",
      "level": 1
    },
    {
      "x": -2,
      "y": 7,
      "z": -1,
      "name": "Water_Source",
      "level": 1
    },
    {
      "x": -2,
      "y": 8,
      "z": -1,
      "name": "Water_Source",
      "level": 1
    },
    {
      "x": -2,
      "y": 9,
      "z": -1,
      "name": "Water_Source",
      "level": 1
    },
    {
      "x": -2,
      "y": 10,
      "z": -1,
      "name": "Water_Source",
      "level": 1
    },
    {
      "x": -2,
      "y": 11,
      "z": -1,
      "name": "Water_Source",
      "level": 1
    },
    {
      "x": -2,
      "y": 12,
      "z": -1,
      "name": "Water_Source",
      "level": 1
    },
    {
      "x": -2,
      "y": 13,
      "z": -1,
      "name": "Water_Source",
      "level": 1
    },
    {
      "x": -2,
      "y": 18,
      "z": -1,
      "name": "Water_Source",
      "level": 1
    },
    {
      "x": -2,
      "y": 19,
      "z": -1,
      "name": "Water_Source",
      "level": 1
    },
    {
      "x": -2,
      "y": 20,
      "z": -1,
      "name": "Water_Source",
      "level": 1
    },
    {
      "x": -2,
      "y": 21,
      "z": -1,
      "name": "Water_Source",
      "level": 1
    },
    {
      "x": -2,
      "y": 1,
      "z": 0,
      "name": "Water_Source",
      "level": 1
    },
    {
      "x": -2,
      "y": 2,
      "z": 0,
      "name": "Water_Source",
      "level": 1
    },
    {
      "x": -2,
      "y": 3,
      "z": 0,
      "name": "Water_Source",
      "level": 1
    },
    {
      "x": -2,
      "y": 4,
      "z": 0,
      "name": "Water_Source",
      "level": 1
    },
    {
      "x": -2,
      "y": 5,
      "z": 0,
      "name": "Water_Source",
      "level": 1
    },
    {
      "x": -2,
      "y": 6,
      "z": 0,
      "name": "Water_Source",
      "level": 1
    },
    {
      "x": -2,
      "y": 7,
      "z": 0,
      "name": "Water_Source",
      "level": 1
    },
    {
      "x": -2,
      "y": 8,
      "z": 0,
      "name": "Water_Source",
      "level": 1
    },
    {
      "x": -2,
      "y": 9,
      "z": 0,
      "name": "Water_Source",
      "level": 1
    },
    {
      "x": -2,
      "y": 10,
      "z": 0,
      "name": "Water_Source",
      "level": 1
    },
    {
      "x": -2,
      "y": 11,
      "z": 0,
      "name": "Water_Source",
      "level": 1
    },
    {
      "x": -2,
      "y": 12,
      "z": 0,
      "name": "Water_Source",
      "level": 1
    },
    {
      "x": -2,
      "y": 13,
      "z": 0,
      "name": "Water_Source",
      "level": 1
    },
    {
      "x": -2,
      "y": 14,
      "z": 0,
      "name": "Water_Source",
      "level": 1
    },
    {
      "x": -2,
      "y": 15,
      "z": 0,
      "name": "Water_Source",
      "level": 1
    },
    {
      "x": -2,
      "y": 16,
      "z": 0,
      "name": "Water_Source",
      "level": 1
    },
    {
      "x": -2,
      "y": 17,
      "z": 0,
      "name": "Water_Source",
      "level": 1
    },
    {
      "x": -2,
      "y": 18,
      "z": 0,
      "name": "Water_Source",
      "level": 1
    },
    {
      "x": -2,
      "y": 19,
      "z": 0,
      "name": "Water_Source",
      "level": 1
    },
    {
      "x": -2,
      "y": 20,
      "z": 0,
      "name": "Water_Source",
      "level": 1
    },
    {
      "x": -2,
      "y": 21,
      "z": 0,
      "name": "Water_Source",
      "level": 1
    },
    {
      "x": -2,
      "y": 1,
      "z": 1,
      "name": "Water_Source",
      "level": 1
    },
    {
      "x": -2,
      "y": 2,
      "z": 1,
      "name": "Water_Source",
      "level": 1
    },
    {
      "x": -2,
      "y": 3,
      "z": 1,
      "name": "Water_Source",
      "level": 1
    },
    {
      "x": -2,
      "y": 4,
      "z": 1,
      "name": "Water_Source",
      "level": 1
