{
  "version": 8,
  "blockIdVersion": 11,
  "anchorX": 0,
  "anchorY": 0,
  "anchorZ": 0,
  "blocks": [
    {
      "x": -7,
      "y": 9,
      "z": -1,
      "name": "Plant_Coral_Block_Orange"
    },
    {
      "x": -7,
      "y": 8,
      "z": 0,
      "name": "Plant_Coral_Block_Orange"
    },
    {
      "x": -7,
      "y": 9,
      "z": 0,
      "name": "Plant_Coral_Block_Orange"
    },
    {
      "x": -7,
      "y": 9,
      "z": 1,
      "name": "Plant_Coral_Block_Orange"
    },
    {
      "x": -6,
      "y": 9,
      "z": -3,
      "name": "Plant_Coral_Block_Orange"
    },
    {
      "x": -6,
      "y": 0,
      "z": -2,
      "name": "Plant_Coral_Block_Orange"
    },
    {
      "x": -6,
      "y": 1,
      "z": -2,
      "name": "Plant_Coral_Block_Orange"
    },
    {
      "x": -6,
      "y": 2,
      "z": -2,
      "name": "Plant_Coral_Bush_Orange"
    },
    {
      "x": -6,
      "y": 8,
      "z": -2,
      "name": "Plant_Coral_Block_Orange"
    },
    {
      "x": -6,
      "y": 9,
      "z": -2,
      "name": "Plant_Coral_Block_Orange"
    },
    {
      "x": -6,
      "y": 0,
      "z": -1,
      "name": "Plant_Coral_Block_Orange"
    },
    {
      "x": -6,
      "y": 1,
      "z": -1,
      "name": "Plant_Coral_Block_Orange"
    },
    {
      "x": -6,
      "y": 2,
      "z": -1,
      "name": "Plant_Coral_Block_Orange"
    },
    {
      "x": -6,
      "y": 7,
      "z": -1,
      "name": "Plant_Coral_Block_Orange"
    },
    {
      "x": -6,
      "y": 8,
      "z": -1,
      "name": "Plant_Coral_Block_Orange"
    },
    {
      "x": -6,
      "y": 9,
      "z": -1,
      "name": "Plant_Coral_Block_Orange"
    },
    {
      "x": -6,
      "y": 0,
      "z": 0,
      "name": "Plant_Coral_Block_Orange"
    },
    {
      "x": -6,
      "y": 1,
      "z": 0,
      "name": "Plant_Coral_Block_Orange"
    },
    {
      "x": -6,
      "y": 2,
      "z": 0,
      "name": "Plant_Coral_Block_Orange"
    },
    {
      "x": -6,
      "y": 3,
      "z": 0,
      "name": "Plant_Coral_Block_Orange"
    },
    {
      "x": -6,
      "y": 4,
      "z": 0,
      "name": "Plant_Coral_Block_Orange"
    },
    {
      "x": -6,
      "y": 5,
      "z": 0,
      "name": "Plant_Coral_Block_Orange"
    },
    {
      "x": -6,
      "y": 6,
      "z": 0,
      "name": "Plant_Coral_Block_Orange"
    },
    {
      "x": -6,
      "y": 7,
      "z": 0,
      "name": "Plant_Coral_Block_Orange"
    },
    {
      "x": -6,
      "y": 8,
      "z": 0,
      "name": "Plant_Coral_Block_Orange"
    },
    {
      "x": -6,
      "y": 9,
      "z": 0,
      "name": "Plant_Coral_Block_Orange"
    },
    {
      "x": -6,
      "y": 0,
      "z": 1,
      "name": "Plant_Coral_Block_Orange"
    },
    {
      "x": -6,
      "y": 1,
      "z": 1,
      "name": "Plant_Coral_Block_Orange"
    },
    {
      "x": -6,
      "y": 4,
      "z": 1,
      "name": "Plant_Coral_Block_Orange"
    },
    {
      "x": -6,
      "y": 5,
      "z": 1,
      "name": "Plant_Coral_Block_Orange"
    },
    {
      "x": -6,
      "y": 7,
      "z": 1,
      "name": "Plant_Coral_Bush_Orange"
    },
    {
      "x": -6,
      "y": 8,
      "z": 1,
      "name": "Plant_Coral_Block_Orange"
    },
    {
      "x": -6,
      "y": 9,
      "z": 1,
      "name": "Plant_Coral_Block_Orange"
    },
    {
      "x": -6,
      "y": 0,
      "z": 2,
      "name": "Plant_Coral_Block_Orange"
    },
    {
      "x": -6,
      "y": 9,
      "z": 2,
      "name": "Plant_Coral_Block_Orange"
    },
    {
      "x": -6,
      "y": 9,
      "z": 3,
      "name": "Plant_Coral_Block_Orange"
    },
    {
      "x": -5,
      "y": 0,
      "z": -4,
      "name": "Plant_Coral_Block_Orange"
    },
    {
      "x": -5,
      "y": 9,
      "z": -4,
      "name": "Plant_Coral_Block_Orange"
    },
    {
      "x": -5,
      "y": 0,
      "z": -3,
      "name": "Plant_Coral_Block_Orange"
    },
    {
      "x": -5,
      "y": 1,
      "z": -3,
      "name": "Plant_Coral_Block_Orange"
    },
    {
      "x": -5,
      "y": 2,
      "z": -3,
      "name": "Plant_Coral_Block_Orange"
    },
    {
      "x": -5,
      "y": 3,
      "z": -3,
      "name": "Plant_Coral_Block_Orange"
    },
    {
      "x": -5,
      "y": 4,
      "z": -3,
      "name": "Plant_Coral_Block_Orange"
    },
    {
      "x": -5,
      "y": 7,
      "z": -3,
      "name": "Rock_Crystal_Orange_Large",
      "rotation": 8
    },
    {
      "x": -5,
      "y": 8,
      "z": -3,
      "name": "Plant_Coral_Block_Orange"
    },
    {
      "x": -5,
      "y": 9,
      "z": -3,
      "name": "Plant_Coral_Block_Orange"
    },
    {
      "x": -5,
      "y": 0,
      "z": -2,
      "name": "Plant_Coral_Block_Orange"
    },
    {
      "x": -5,
      "y": 1,
      "z": -2,
      "name": "Plant_Coral_Block_Orange"
    },
    {
      "x": -5,
      "y": 2,
      "z": -2,
      "name": "Plant_Coral_Block_Orange"
    },
    {
      "x": -5,
      "y": 3,
      "z": -2,
      "name": "Plant_Coral_Block_Orange"
    },
    {
      "x": -5,
      "y": 4,
      "z": -2,
      "name": "Plant_Coral_Block_Orange"
    },
    {
      "x": -5,
      "y": 5,
      "z": -2,
      "name": "Plant_Coral_Block_Orange"
    },
    {
      "x": -5,
      "y": 6,
      "z": -2,
      "name": "Plant_Coral_Block_Orange"
    },
    {
      "x": -5,
      "y": 7,
      "z": -2,
      "name": "Plant_Coral_Block_Orange"
    },
    {
      "x": -5,
      "y": 8,
      "z": -2,
      "name": "Plant_Coral_Block_Orange"
    },
    {
      "x": -5,
      "y": 9,
      "z": -2,
      "name": "Plant_Coral_Block_Orange"
    },
    {
      "x": -5,
      "y": 0,
      "z": -1,
      "name": "Plant_Coral_Block_Blue"
    },
    {
      "x": -5,
      "y": 1,
      "z": -1,
      "name": "Plant_Coral_Block_Blue"
    },
    {
      "x": -5,
      "y": 2,
      "z": -1,
      "name": "Plant_Coral_Block_Blue"
    },
    {
      "x": -5,
      "y": 3,
      "z": -1,
      "name": "Plant_Coral_Block_Orange"
    },
    {
      "x": -5,
      "y": 4,
      "z": -1,
      "name": "Plant_Coral_Block_Orange"
    },
    {
      "x": -5,
      "y": 5,
      "z": -1,
      "name": "Plant_Coral_Block_Orange"
    },
    {
      "x": -5,
      "y": 6,
      "z": -1,
      "name": "Plant_Coral_Block_Orange"
    },
    {
      "x": -5,
      "y": 7,
      "z": -1,
      "name": "Plant_Coral_Block_Blue"
    },
    {
      "x": -5,
      "y": 8,
      "z": -1,
      "name": "Plant_Coral_Block_Blue"
    },
    {
      "x": -5,
      "y": 9,
      "z": -1,
      "name": "Plant_Coral_Block_Blue"
    },
    {
      "x": -5,
      "y": 0,
      "z": 0,
      "name": "Plant_Coral_Block_Blue"
    },
    {
      "x": -5,
      "y": 1,
      "z": 0,
      "name": "Plant_Coral_Block_Blue"
    },
    {
      "x": -5,
      "y": 2,
      "z": 0,
      "name": "Plant_Coral_Block_Blue"
    },
    {
      "x": -5,
      "y": 3,
      "z": 0,
      "name": "Plant_Coral_Block_Blue"
    },
    {
      "x": -5,
      "y": 4,
      "z": 0,
      "name": "Plant_Coral_Block_Blue"
    },
    {
      "x": -5,
      "y": 5,
      "z": 0,
      "name": "Plant_Coral_Block_Blue"
    },
    {
      "x": -5,
      "y": 6,
      "z": 0,
      "name": "Plant_Coral_Block_Blue"
    },
    {
      "x": -5,
      "y": 7,
      "z": 0,
      "name": "Plant_Coral_Block_Blue"
    },
    {
      "x": -5,
      "y": 8,
      "z": 0,
      "name": "Plant_Coral_Block_Blue"
    },
    {
      "x": -5,
      "y": 9,
      "z": 0,
      "name": "Plant_Coral_Block_Blue"
    },
    {
      "x": -5,
      "y": 0,
      "z": 1,
      "name": "Plant_Coral_Block_Blue"
    },
    {
      "x": -5,
      "y": 1,
      "z": 1,
      "name": "Plant_Coral_Block_Blue"
    },
    {
      "x": -5,
      "y": 2,
      "z": 1,
      "name": "Plant_Coral_Block_Orange"
    },
    {
      "x": -5,
      "y": 3,
      "z": 1,
      "name": "Plant_Coral_Block_Orange"
    },
    {
      "x": -5,
      "y": 4,
      "z": 1,
      "name": "Plant_Coral_Block_Blue"
    },
    {
      "x": -5,
      "y": 5,
      "z": 1,
      "name": "Plant_Coral_Block_Orange"
    },
    {
      "x": -5,
      "y": 6,
      "z": 1,
      "name": "Plant_Coral_Block_Orange"
    },
    {
      "x": -5,
      "y": 7,
      "z": 1,
      "name": "Plant_Coral_Block_Orange"
    },
    {
      "x": -5,
      "y": 8,
      "z": 1,
      "name": "Plant_Coral_Block_Blue"
    },
    {
      "x": -5,
      "y": 9,
      "z": 1,
      "name": "Plant_Coral_Block_Blue"
    },
    {
      "x": -5,
      "y": 0,
      "z": 2,
      "name": "Plant_Coral_Block_Orange"
    },
    {
      "x": -5,
      "y": 1,
      "z": 2,
      "name": "Plant_Coral_Block_Orange"
    },
    {
      "x": -5,
      "y": 2,
      "z": 2,
      "name": "Plant_Coral_Block_Orange"
    },
    {
      "x": -5,
      "y": 3,
      "z": 2,
      "name": "Plant_Coral_Block_Orange"
    },
    {
      "x": -5,
      "y": 4,
      "z": 2,
      "name": "Plant_Coral_Block_Orange"
    },
    {
      "x": -5,
      "y": 5,
      "z": 2,
      "name": "Plant_Coral_Model_Orange"
    },
    {
      "x": -5,
      "y": 8,
      "z": 2,
      "name": "Plant_Coral_Block_Orange"
    },
    {
      "x": -5,
      "y": 9,
      "z": 2,
      "name": "Plant_Coral_Block_Orange"
    },
    {
      "x": -5,
      "y": 0,
      "z": 3,
      "name": "Plant_Coral_Block_Orange"
    },
    {
      "x": -5,
      "y": 1,
      "z": 3,
      "name": "Plant_Coral_Block_Orange"
    },
    {
      "x": -5,
      "y": 2,
      "z": 3,
      "name": "Plant_Coral_Block_Orange"
    },
    {
      "x": -5,
      "y": 3,
      "z": 3,
      "name": "Plant_Coral_Bush_Orange"
    },
    {
      "x": -5,
      "y": 6,
      "z": 3,
      "name": "Plant_Coral_Block_Orange"
    },
    {
      "x": -5,
      "y": 7,
      "z": 3,
      "name": "Plant_Coral_Block_Orange"
    },
    {
      "x": -5,
      "y": 8,
      "z": 3,
      "name": "Plant_Coral_Block_Orange"
    },
    {
      "x": -5,
      "y": 9,
      "z": 3,
      "name": "Plant_Coral_Block_Orange"
    },
    {
      "x": -5,
      "y": 0,
      "z": 4,
      "name": "Plant_Coral_Block_Orange"
    },
    {
      "x": -5,
      "y": 1,
      "z": 4,
      "name": "Plant_Coral_Block_Orange"
    },
    {
      "x": -5,
      "y": 8,
      "z": 4,
      "name": "Plant_Coral_Block_Orange"
    },
    {
      "x": -5,
      "y": 9,
      "z": 4,
      "name": "Plant_Coral_Block_Orange"
    },
    {
      "x": -5,
      "y": 9,
      "z": 5,
      "name": "Plant_Coral_Block_Orange"
    },
    {
      "x": -4,
      "y": 9,
      "z": -5,
      "name": "Plant_Coral_Block_Orange"
    },
    {
      "x": -4,
      "y": 0,
      "z": -4,
      "name": "Plant_Coral_Block_Orange"
    },
    {
      "x": -4,
      "y": 1,
      "z": -4,
      "name": "Plant_Coral_Block_Orange"
    },
    {
      "x": -4,
      "y": 2,
      "z": -4,
      "name": "Plant_Coral_Block_Orange"
    },
    {
      "x": -4,
      "y": 3,
      "z": -4,
      "name": "Plant_Coral_Model_Orange"
    },
    {
      "x": -4,
      "y": 7,
      "z": -4,
      "name": "Plant_Coral_Block_Orange"
    },
    {
      "x": -4,
      "y": 8,
      "z": -4,
      "name": "Plant_Coral_Block_Orange"
    },
    {
      "x": -4,
      "y": 9,
      "z": -4,
      "name": "Plant_Coral_Block_Orange"
    },
    {
      "x": -4,
      "y": 0,
      "z": -3,
      "name": "Plant_Coral_Block_Blue"
    },
    {
      "x": -4,
      "y": 1,
      "z": -3,
      "name": "Plant_Coral_Block_Blue"
    },
    {
      "x": -4,
      "y": 2,
      "z": -3,
      "name": "Plant_Coral_Block_Blue"
    },
    {
      "x": -4,
      "y": 3,
      "z": -3,
      "name": "Plant_Coral_Block_Orange"
    },
    {
      "x": -4,
      "y": 4,
      "z": -3,
      "name": "Plant_Coral_Block_Orange"
    },
    {
      "x": -4,
      "y": 5,
      "z": -3,
      "name": "Plant_Coral_Block_Orange"
    },
    {
      "x": -4,
      "y": 6,
      "z": -3,
      "name": "Plant_Coral_Block_Orange"
    },
    {
      "x": -4,
      "y": 7,
      "z": -3,
      "name": "Plant_Coral_Block_Orange"
    },
    {
      "x": -4,
      "y": 8,
      "z": -3,
      "name": "Plant_Coral_Block_Blue"
    },
    {
      "x": -4,
      "y": 9,
      "z": -3,
      "name": "Plant_Coral_Block_Blue"
    },
    {
      "x": -4,
      "y": 0,
      "z": -2,
      "name": "Plant_Coral_Block_Blue"
    },
    {
      "x": -4,
      "y": 1,
      "z": -2,
      "name": "Plant_Coral_Block_Blue"
    },
    {
      "x": -4,
      "y": 2,
      "z": -2,
      "name": "Plant_Coral_Block_Blue"
    },
    {
      "x": -4,
      "y": 3,
      "z": -2,
      "name": "Plant_Coral_Block_Blue"
    },
    {
      "x": -4,
      "y": 4,
      "z": -2,
      "name": "Plant_Coral_Block_Blue"
    },
    {
      "x": -4,
      "y": 5,
      "z": -2,
      "name": "Plant_Coral_Block_Blue"
    },
    {
      "x": -4,
      "y": 6,
      "z": -2,
      "name": "Plant_Coral_Block_Blue"
    },
    {
      "x": -4,
      "y": 7,
      "z": -2,
      "name": "Plant_Coral_Block_Blue"
    },
    {
      "x": -4,
      "y": 8,
      "z": -2,
      "name": "Plant_Coral_Block_Blue"
    },
    {
      "x": -4,
      "y": 9,
      "z": -2,
      "name": "Plant_Coral_Block_Blue"
    },
    {
      "x": -4,
      "y": 0,
      "z": -1,
      "name": "Plant_Coral_Block_Blue"
    },
    {
      "x": -4,
      "y": 1,
      "z": -1,
      "name": "Plant_Coral_Block_Blue"
    },
    {
      "x": -4,
      "y": 2,
      "z": -1,
      "name": "Plant_Coral_Block_Blue"
    },
    {
      "x": -4,
      "y": 3,
      "z": -1,
      "name": "Plant_Coral_Block_Blue"
    },
    {
      "x": -4,
      "y": 4,
      "z": -1,
      "name": "Plant_Coral_Block_Blue"
    },
    {
      "x": -4,
      "y": 5,
      "z": -1,
      "name": "Plant_Coral_Block_Blue"
    },
    {
      "x": -4,
      "y": 6,
      "z": -1,
      "name": "Plant_Coral_Block_Blue"
    },
    {
      "x": -4,
      "y": 7,
      "z": -1,
      "name": "Plant_Coral_Block_Blue"
    },
    {
      "x": -4,
      "y": 8,
      "z": -1,
      "name": "Plant_Coral_Block_Blue"
    },
    {
      "x": -4,
      "y": 9,
      "z": -1,
      "name": "Plant_Coral_Block_Blue"
    },
    {
      "x": -4,
      "y": 0,
      "z": 0,
      "name": "Plant_Coral_Block_Blue"
    },
    {
      "x": -4,
      "y": 1,
      "z": 0,
      "name": "Plant_Coral_Block_Blue"
    },
    {
      "x": -4,
      "y": 2,
      "z": 0,
      "name": "Plant_Coral_Block_Blue"
    },
    {
      "x": -4,
      "y": 3,
      "z": 0,
      "name": "Plant_Coral_Block_Blue"
    },
    {
      "x": -4,
      "y": 4,
      "z": 0,
      "name": "Plant_Coral_Block_Blue"
    },
    {
      "x": -4,
      "y": 5,
      "z": 0,
      "name": "Plant_Coral_Block_Blue"
    },
    {
      "x": -4,
      "y": 6,
      "z": 0,
      "name": "Plant_Coral_Block_Blue"
    },
    {
      "x": -4,
      "y": 7,
      "z": 0,
      "name": "Plant_Coral_Block_Blue"
    },
    {
      "x": -4,
      "y": 8,
      "z": 0,
      "name": "Plant_Coral_Block_Blue"
    },
    {
      "x": -4,
      "y": 9,
      "z": 0,
      "name": "Plant_Coral_Block_Blue"
    },
    {
      "x": -4,
      "y": 0,
      "z": 1,
      "name": "Plant_Coral_Block_Blue"
    },
    {
      "x": -4,
      "y": 1,
      "z": 1,
      "name": "Plant_Coral_Block_Blue"
    },
    {
      "x": -4,
      "y": 2,
      "z": 1,
      "name": "Plant_Coral_Block_Blue"
    },
    {
      "x": -4,
      "y": 3,
      "z": 1,
      "name": "Plant_Coral_Block_Blue"
    },
    {
      "x": -4,
      "y": 4,
      "z": 1,
      "name": "Plant_Coral_Block_Blue"
    },
    {
      "x": -4,
      "y": 5,
      "z": 1,
      "name": "Plant_Coral_Block_Blue"
    },
    {
      "x": -4,
      "y": 6,
      "z": 1,
      "name": "Plant_Coral_Block_Blue"
    },
    {
      "x": -4,
      "y": 7,
      "z": 1,
      "name": "Plant_Coral_Block_Blue"
    },
    {
      "x": -4,
      "y": 8,
      "z": 1,
      "name": "Plant_Coral_Block_Blue"
    },
    {
      "x": -4,
      "y": 9,
      "z": 1,
      "name": "Plant_Coral_Block_Blue"
    },
    {
      "x": -4,
      "y": 0,
      "z": 2,
      "name": "Plant_Coral_Block_Blue"
    },
    {
      "x": -4,
      "y": 1,
      "z": 2,
      "name": "Plant_Coral_Block_Blue"
    },
    {
      "x": -4,
      "y": 2,
      "z": 2,
      "name": "Plant_Coral_Block_Blue"
    },
    {
      "x": -4,
      "y": 3,
      "z": 2,
      "name": "Plant_Coral_Block_Blue"
    },
    {
      "x": -4,
      "y": 4,
      "z": 2,
      "name": "Plant_Coral_Block_Blue"
    },
    {
      "x": -4,
      "y": 5,
      "z": 2,
      "name": "Plant_Coral_Block_Orange"
    },
    {
      "x": -4,
      "y": 6,
      "z": 2,
      "name": "Plant_Coral_Block_Orange"
    },
    {
      "x": -4,
      "y": 7,
      "z": 2,
      "name": "Plant_Coral_Block_Orange"
    },
    {
      "x": -4,
      "y": 8,
      "z": 2,
      "name": "Plant_Coral_Block_Blue"
    },
    {
      "x": -4,
      "y": 9,
      "z": 2,
      "name": "Plant_Coral_Block_Blue"
    },
    {
      "x": -4,
      "y": 0,
      "z": 3,
      "name": "Plant_Coral_Block_Blue"
    },
    {
      "x": -4,
      "y": 1,
      "z": 3,
      "name": "Plant_Coral_Block_Blue"
    },
    {
      "x": -4,
      "y": 2,
      "z": 3,
      "name": "Plant_Coral_Block_Blue"
    },
    {
      "x": -4,
      "y": 3,
      "z": 3,
      "name": "Plant_Coral_Block_Orange"
    },
    {
      "x": -4,
      "y": 4,
      "z": 3,
      "name": "Plant_Coral_Block_Orange"
    },
    {
      "x": -4,
      "y": 5,
      "z": 3,
      "name": "Plant_Coral_Block_Orange"
    },
    {
      "x": -4,
      "y": 6,
      "z": 3,
      "name": "Plant_Coral_Block_Orange"
    },
    {
      "x": -4,
      "y": 7,
      "z": 3,
      "name": "Plant_Coral_Block_Blue"
    },
    {
      "x": -4,
      "y": 8,
      "z": 3,
      "name": "Plant_Coral_Block_Blue"
    },
    {
      "x": -4,
      "y": 9,
      "z": 3,
      "name": "Plant_Coral_Block_Blue"
    },
    {
      "x": -4,
      "y": 0,
      "z": 4,
      "name": "Plant_Coral_Block_Orange"
    },
    {
      "x": -4,
      "y": 1,
      "z": 4,
      "name": "Plant_Coral_Block_Orange"
    },
    {
      "x": -4,
      "y": 2,
      "z": 4,
      "name": "Plant_Coral_Block_Orange"
    },
    {
      "x": -4,
      "y": 3,
      "z": 4,
      "name": "Plant_Coral_Block_Orange"
    },
    {
      "x": -4,
      "y": 7,
      "z": 4,
      "name": "Plant_Coral_Block_Orange"
    },
    {
      "x": -4,
      "y": 8,
      "z": 4,
      "name": "Plant_Coral_Block_Orange"
    },
    {
      "x": -4,
      "y": 9,
      "z": 4,
      "name": "Plant_Coral_Block_Orange"
    },
    {
      "x": -4,
      "y": 0,
      "z": 5,
      "name": "Plant_Coral_Block_Orange"
    },
    {
      "x": -4,
      "y": 9,
      "z": 5,
      "name": "Plant_Coral_Block_Orange"
    },
    {
      "x": -3,
      "y": 0,
      "z": -6,
      "name": "Plant_Coral_Block_Orange"
    },
    {
      "x": -3,
      "y": 9,
      "z": -6,
      "name": "Plant_Coral_Block_Orange"
    },
    {
      "x": -3,
      "y": 0,
      "z": -5,
      "name": "Plant_Coral_Block_Orange"
    },
    {
      "x": -3,
      "y": 1,
      "z": -5,
      "name": "Plant_Coral_Block_Orange"
    },
    {
      "x": -3,
      "y": 2,
      "z": -5,
      "name": "Plant_Coral_Block_Orange"
    },
    {
      "x": -3,
      "y": 3,
      "z": -5,
      "name": "Plant_Coral_Block_Orange"
    },
    {
      "x": -3,
      "y": 7,
      "z": -5,
      "name": "Plant_Coral_Bush_Orange"
    },
    {
      "x": -3,
      "y": 8,
      "z": -5,
      "name": "Plant_Coral_Block_Orange"
    },
    {
      "x": -3,
      "y": 9,
      "z": -5,
      "name": "Plant_Coral_Block_Orange"
    },
    {
      "x": -3,
      "y": 0,
      "z": -4,
      "name": "Plant_Coral_Block_Blue"
    },
    {
      "x": -3,
      "y": 1,
      "z": -4,
      "name": "Plant_Coral_Block_Blue"
    },
    {
      "x": -3,
      "y": 2,
      "z": -4,
      "name": "Plant_Coral_Block_Blue"
    },
    {
      "x": -3,
      "y": 3,
      "z": -4,
      "name": "Plant_Coral_Block_Orange"
    },
    {
      "x": -3,
      "y": 4,
      "z": -4,
      "name": "Plant_Coral_Block_Orange"
    },
    {
      "x": -3,
      "y": 5,
      "z": -4,
      "name": "Plant_Coral_Block_Orange"
    },
    {
      "x": -3,
      "y": 6,
      "z": -4,
      "name": "Plant_Coral_Block_Orange"
    },
    {
      "x": -3,
      "y": 7,
      "z": -4,
      "name": "Plant_Coral_Block_Orange"
    },
    {
      "x": -3,
      "y": 8,
      "z": -4,
      "name": "Plant_Coral_Block_Blue"
    },
    {
      "x": -3,
      "y": 9,
      "z": -4,
      "name": "Plant_Coral_Block_Blue"
    },
    {
      "x": -3,
      "y": 0,
      "z": -3,
      "name": "Plant_Coral_Block_Blue"
    },
    {
      "x": -3,
      "y": 1,
      "z": -3,
      "name": "Plant_Coral_Block_Blue"
    },
    {
      "x": -3,
      "y": 2,
      "z": -3,
      "name": "Plant_Coral_Block_Blue"
    },
    {
      "x": -3,
      "y": 3,
      "z": -3,
      "name": "Plant_Coral_Block_Blue"
    },
    {
      "x": -3,
      "y": 4,
      "z": -3,
      "name": "Plant_Coral_Block_Blue"
    },
    {
      "x": -3,
      "y": 5,
      "z": -3,
      "name": "Plant_Coral_Block_Blue"
    },
    {
      "x": -3,
      "y": 6,
      "z": -3,
      "name": "Plant_Coral_Block_Blue"
    },
    {
      "x": -3,
      "y": 7,
      "z": -3,
      "name": "Plant_Coral_Block_Blue"
    },
    {
      "x": -3,
      "y": 8,
      "z": -3,
      "name": "Plant_Coral_Block_Blue"
    },
    {
      "x": -3,
      "y": 9,
      "z": -3,
      "name": "Plant_Coral_Block_Blue"
    },
    {
      "x": -3,
      "y": 0,
      "z": -2,
      "name": "Plant_Coral_Block_Blue"
    },
    {
      "x": -3,
      "y": 1,
      "z": -2,
      "name": "Plant_Coral_Block_Blue"
    },
    {
      "x": -3,
      "y": 2,
      "z": -2,
      "name": "Plant_Coral_Block_Blue"
    },
    {
      "x": -3,
      "y": 3,
      "z": -2,
      "name": "Plant_Coral_Block_Blue"
    },
    {
      "x": -3,
      "y": 4,
      "z": -2,
      "name": "Plant_Coral_Block_Blue"
    },
    {
      "x": -3,
      "y": 5,
      "z": -2,
      "name": "Plant_Coral_Block_Blue"
    },
    {
      "x": -3,
      "y": 6,
      "z": -2,
      "name": "Plant_Coral_Block_Blue"
    },
    {
      "x": -3,
      "y": 7,
      "z": -2,
      "name": "Plant_Coral_Block_Blue"
    },
    {
      "x": -3,
      "y": 8,
      "z": -2,
      "name": "Plant_Coral_Block_Blue"
    },
    {
      "x": -3,
      "y": 9,
      "z": -2,
      "name": "Plant_Coral_Block_Blue"
    },
    {
      "x": -3,
      "y": 0,
      "z": -1,
      "name": "Plant_Coral_Block_Blue"
    },
    {
      "x": -3,
      "y": 1,
      "z": -1,
      "name": "Plant_Coral_Block_Blue"
    },
    {
      "x": -3,
      "y": 2,
      "z": -1,
      "name": "Plant_Coral_Block_Blue"
    },
    {
      "x": -3,
      "y": 3,
      "z": -1,
      "name": "Plant_Coral_Block_Blue"
    },
    {
      "x": -3,
      "y": 4,
      "z": -1,
      "name": "Plant_Coral_Block_Blue"
    },
    {
      "x": -3,
      "y": 5,
      "z": -1,
      "name": "Plant_Coral_Block_Blue"
    },
    {
      "x": -3,
      "y": 6,
      "z": -1,
      "name": "Plant_Coral_Block_Blue"
    },
    {
      "x": -3,
      "y": 7,
      "z": -1,
      "name": "Plant_Coral_Block_Blue"
    },
    {
      "x": -3,
      "y": 8,
      "z": -1,
      "name": "Plant_Coral_Block_Blue"
    },
    {
      "x": -3,
      "y": 9,
      "z": -1,
      "name": "Plant_Coral_Block_Blue"
    },
    {
      "x": -3,
      "y": 0,
      "z": 0,
      "name": "Plant_Coral_Block_Blue"
    },
    {
      "x": -3,
      "y": 1,
      "z": 0,
      "name": "Plant_Coral_Block_Blue"
    },
    {
      "x": -3,
      "y": 2,
      "z": 0,
      "name": "Plant_Coral_Block_Blue"
    },
    {
      "x": -3,
      "y": 3,
      "z": 0,
      "name": "Plant_Coral_Block_Blue"
    },
    {
      "x": -3,
      "y": 4,
      "z": 0,
      "name": "Plant_Coral_Block_Blue"
    },
    {
      "x": -3,
      "y": 5,
      "z": 0,
      "name": "Plant_Coral_Block_Blue"
    },
    {
      "x": -3,
      "y": 6,
      "z": 0,
      "name": "Plant_Coral_Block_Blue"
    },
    {
      "x": -3,
      "y": 7,
      "z": 0,
      "name": "Plant_Coral_Block_Blue"
    },
    {
      "x": -3,
      "y": 8,
      "z": 0,
      "name": "Plant_Coral_Block_Blue"
    },
    {
      "x": -3,
      "y": 9,
      "z": 0,
      "name": "Plant_Coral_Block_Blue"
    },
    {
      "x": -3,
      "y": 0,
      "z": 1,
      "name": "Plant_Coral_Block_Blue"
    },
    {
      "x": -3,
      "y": 1,
      "z": 1,
      "name": "Plant_Coral_Block_Blue"
    },
    {
      "x": -3,
      "y": 2,
      "z": 1,
      "name": "Plant_Coral_Block_Blue"
    },
    {
      "x": -3,
      "y": 3,
      "z": 1,
      "name": "Plant_Coral_Block_Blue"
    },
    {
      "x": -3,
      "y": 4,
      "z": 1,
      "name": "Plant_Coral_Block_Blue"
    },
    {
      "x": -3,
      "y": 5,
      "z": 1,
      "name": "Plant_Coral_Block_Blue"
    },
    {
      "x": -3,
      "y": 6,
      "z": 1,
      "name": "Plant_Coral_Block_Blue"
    },
    {
      "x": -3,
      "y": 7,
      "z": 1,
      "name": "Plant_Coral_Block_Blue"
    },
    {
      "x": -3,
      "y": 8,
      "z": 1,
      "name": "Plant_Coral_Block_Blue"
    },
    {
      "x": -3,
      "y": 9,
      "z": 1,
      "name": "Plant_Coral_Block_Blue"
    },
    {
      "x": -3,
      "y": 0,
      "z": 2,
      "name": "Plant_Coral_Block_Blue"
    },
    {
      "x": -3,
      "y": 1,
      "z": 2,
      "name": "Plant_Coral_Block_Blue"
    },
    {
      "x": -3,
      "y": 2,
      "z": 2,
      "name": "Plant_Coral_Block_Blue"
    },
    {
      "x": -3,
      "y": 3,
      "z": 2,
      "name": "Plant_Coral_Block_Blue"
    },
    {
      "x": -3,
      "y": 4,
      "z": 2,
      "name": "Plant_Coral_Block_Blue"
    },
    {
      "x": -3,
      "y": 5,
      "z": 2,
      "name": "Plant_Coral_Block_Blue"
    },
    {
      "x": -3,
      "y": 6,
      "z": 2,
      "name": "Plant_Coral_Block_Blue"
    },
    {
      "x": -3,
      "y": 7,
      "z": 2,
      "name": "Plant_Coral_Block_Blue"
    },
    {
      "x": -3,
      "y": 8,
      "z": 2,
      "name": "Plant_Coral_Block_Blue"
    },
    {
      "x": -3,
      "y": 9,
      "z": 2,
      "name": "Plant_Coral_Block_Blue"
    },
    {
      "x": -3,
      "y": 0,
      "z": 3,
      "name": "Plant_Coral_Block_Blue"
    },
    {
      "x": -3,
      "y": 1,
      "z": 3,
      "name": "Plant_Coral_Block_Blue"
    },
    {
      "x": -3,
      "y": 2,
      "z": 3,
      "name": "Plant_Coral_Block_Blue"
    },
    {
      "x": -3,
      "y": 3,
      "z": 3,
      "name": "Plant_Coral_Block_Blue"
    },
    {
      "x": -3,
      "y": 4,
      "z": 3,
      "name": "Plant_Coral_Block_Blue"
    },
    {
      "x": -3,
      "y": 5,
      "z": 3,
      "name": "Plant_Coral_Block_Blue"
    },
    {
      "x": -3,
      "y": 6,
      "z": 3,
      "name": "Plant_Coral_Block_Blue"
    },
    {
      "x": -3,
      "y": 7,
      "z": 3,
      "name": "Plant_Coral_Block_Blue"
    },
    {
      "x": -3,
      "y": 8,
      "z": 3,
      "name": "Plant_Coral_Block_Blue"
    },
    {
      "x": -3,
      "y": 9,
      "z": 3,
      "name": "Plant_Coral_Block_Blue"
    },
    {
      "x": -3,
      "y": 0,
      "z": 4,
      "name": "Plant_Coral_Block_Blue"
    },
    {
      "x": -3,
      "y": 1,
      "z": 4,
      "name": "Plant_Coral_Block_Blue"
    },
    {
      "x": -3,
      "y": 2,
      "z": 4,
      "name": "Plant_Coral_Block_Blue"
    },
    {
      "x": -3,
      "y": 3,
      "z": 4,
      "name": "Plant_Coral_Block_Orange"
    },
    {
      "x": -3,
      "y": 4,
      "z": 4,
      "name": "Plant_Coral_Block_Orange"
    },
    {
      "x": -3,
      "y": 5,
      "z": 4,
      "name": "Plant_Coral_Block_Orange"
    },
    {
      "x": -3,
      "y": 6,
      "z": 4,
      "name": "Plant_Coral_Block_Orange"
    },
    {
      "x": -3,
      "y": 7,
      "z": 4,
      "name": "Plant_Coral_Block_Orange"
    },
    {
      "x": -3,
      "y": 8,
      "z": 4,
      "name": "Plant_Coral_Block_Blue"
    },
    {
      "x": -3,
      "y": 9,
      "z": 4,
      "name": "Plant_Coral_Block_Blue"
    },
    {
      "x": -3,
      "y": 0,
      "z": 5,
      "name": "Plant_Coral_Block_Orange"
    },
    {
      "x": -3,
      "y": 1,
      "z": 5,
      "name": "Plant_Coral_Block_Orange"
    },
    {
      "x": -3,
      "y": 2,
      "z": 5,
      "name": "Plant_Coral_Block_Orange"
    },
    {
      "x": -3,
      "y": 3,
      "z": 5,
      "name": "Rock_Crystal_Orange_Medium"
    },
    {
      "x": -3,
      "y": 8,
      "z": 5,
      "name": "Plant_Coral_Block_Orange"
    },
    {
      "x": -3,
      "y": 9,
      "z": 5,
      "name": "Plant_Coral_Block_Orange"
    },
    {
      "x": -3,
      "y": 0,
      "z": 6,
      "name": "Plant_Coral_Block_Orange"
    },
    {
      "x": -3,
      "y": 1,
      "z": 6,
      "name": "Plant_Coral_Bush_Orange"
    },
    {
      "x": -2,
      "y": 0,
      "z": -6,
      "name": "Plant_Coral_Block_Orange"
    },
    {
      "x": -2,
      "y": 1,
      "z": -6,
      "name": "Plant_Coral_Block_Orange"
    },
    {
      "x": -2,
      "y": 8,
      "z": -6,
      "name": "Plant_Coral_Block_Orange"
    },
    {
      "x": -2,
      "y": 9,
      "z": -6,
      "name": "Plant_Coral_Block_Orange"
    },
    {
      "x": -2,
      "y": 0,
      "z": -5,
      "name": "Plant_Coral_Block_Orange"
    },
    {
      "x": -2,
      "y": 1,
      "z": -5,
      "name": "Plant_Coral_Block_Orange"
    },
    {
      "x": -2,
      "y": 2,
      "z": -5,
      "name": "Plant_Coral_Block_Orange"
    },
    {
      "x": -2,
      "y": 3,
      "z": -5,
      "name": "Plant_Coral_Block_Orange"
    },
    {
      "x": -2,
      "y": 4,
      "z": -5,
      "name": "Plant_Coral_Block_Orange"
    },
    {
      "x": -2,
      "y": 5,
      "z": -5,
      "name": "Plant_Coral_Block_Orange"
    },
    {
      "x": -2,
      "y": 6,
      "z": -5,
      "name": "Plant_Coral_Block_Orange"
    },
    {
      "x": -2,
      "y": 7,
      "z": -5,
      "name": "Plant_Coral_Block_Orange"
    },
    {
      "x": -2,
      "y": 8,
      "z": -5,
      "name": "Plant_Coral_Block_Orange"
    },
    {
      "x": -2,
      "y": 9,
      "z": -5,
      "name": "Plant_Coral_Block_Orange"
    },
    {
      "x": -2,
      "y": 0,
      "z": -4,
      "name": "Plant_Coral_Block_Blue"
    },
    {
      "x": -2,
      "y": 1,
      "z": -4,
      "name": "Plant_Coral_Block_Blue"
    },
    {
      "x": -2,
      "y": 2,
      "z": -4,
      "name": "Plant_Coral_Block_Blue"
    },
    {
      "x": -2,
      "y": 3,
      "z": -4,
      "name": "Plant_Coral_Block_Blue"
    },
    {
      "x": -2,
      "y": 4,
      "z": -4,
      "name": "Plant_Coral_Block_Blue"
    },
    {
      "x": -2,
      "y": 5,
      "z": -4,
      "name": "Plant_Coral_Block_Blue"
    },
    {
      "x": -2,
      "y": 6,
      "z": -4,
      "name": "Plant_Coral_Block_Blue"
    },
    {
      "x": -2,
      "y": 7,
      "z": -4,
      "name": "Plant_Coral_Block_Blue"
    },
    {
      "x": -2,
      "y": 8,
      "z": -4,
      "name": "Plant_Coral_Block_Blue"
    },
    {
      "x": -2,
      "y": 9,
      "z": -4,
      "name": "Plant_Coral_Block_Blue"
    },
    {
      "x": -2,
      "y": 0,
      "z": -3,
      "name": "Plant_Coral_Block_Blue"
    },
    {
      "x": -2,
      "y": 1,
      "z": -3,
      "name": "Plant_Coral_Block_Blue"
    },
    {
      "x": -2,
      "y": 2,
      "z": -3,
      "name": "Plant_Coral_Block_Blue"
    },
    {
      "x": -2,
      "y": 3,
      "z": -3,
      "name": "Plant_Coral_Block_Blue"
    },
    {
      "x": -2,
      "y": 4,
      "z": -3,
      "name": "Plant_Coral_Block_Blue"
    },
    {
      "x": -2,
      "y": 5,
      "z": -3,
      "name": "Plant_Coral_Block_Blue"
    },
    {
      "x": -2,
      "y": 6,
      "z": -3,
      "name": "Plant_Coral_Block_Blue"
    },
    {
      "x": -2,
      "y": 7,
      "z": -3,
      "name": "Plant_Coral_Block_Blue"
    },
    {
      "x": -2,
      "y": 8,
      "z": -3,
      "name": "Plant_Coral_Block_Blue"
    },
    {
      "x": -2,
      "y": 9,
      "z": -3,
      "name": "Plant_Coral_Block_Blue"
    },
    {
      "x": -2,
      "y": 0,
      "z": -2,
      "name": "Plant_Coral_Block_Blue"
    },
    {
      "x": -2,
      "y": 1,
      "z": -2,
      "name": "Plant_Coral_Block_Blue"
    },
    {
      "x": -2,
      "y": 2,
      "z": -2,
      "name": "Plant_Coral_Block_Blue"
    },
    {
      "x": -2,
      "y": 3,
      "z": -2,
      "name": "Plant_Coral_Block_Blue"
    },
    {
      "x": -2,
      "y": 4,
      "z": -2,
      "name": "Plant_Coral_Block_Blue"
    },
    {
      "x": -2,
      "y": 5,
      "z": -2,
      "name": "Plant_Coral_Block_Blue"
    },
    {
      "x": -2,
      "y": 6,
      "z": -2,
      "name": "Plant_Coral_Block_Blue"
    },
    {
      "x": -2,
      "y": 7,
      "z": -2,
      "name": "Plant_Coral_Block_Blue"
    },
    {
      "x": -2,
      "y": 8,
      "z": -2,
      "name": "Plant_Coral_Block_Blue"
    },
    {
      "x": -2,
      "y": 9,
      "z": -2,
      "name": "Plant_Coral_Block_Blue"
    },
    {
      "x": -2,
      "y": 0,
      "z": -1,
      "name": "Plant_Coral_Block_Blue"
    },
    {
      "x": -2,
      "y": 1,
      "z": -1,
      "name": "Plant_Coral_Block_Blue"
    },
    {
      "x": -2,
      "y": 2,
      "z": -1,
      "name": "Plant_Coral_Block_Blue"
    },
    {
      "x": -2,
      "y": 3,
      "z": -1,
      "name": "Plant_Coral_Block_Blue"
    },
    {
      "x": -2,
      "y": 4,
      "z": -1,
      "name": "Plant_Coral_Block_Blue"
    },
    {
      "x": -2,
      "y": 5,
      "z": -1,
      "name": "Plant_Coral_Block_Blue"
    },
    {
      "x": -2,
      "y": 6,
      "z": -1,
      "name": "Plant_Coral_Block_Blue"
    },
    {
      "x": -2,
      "y": 7,
      "z": -1,
      "name": "Plant_Coral_Block_Blue"
    },
    {
      "x": -2,
      "y": 8,
      "z": -1,
      "name": "Plant_Coral_Block_Blue"
    },
    {
      "x": -2,
      "y": 9,
      "z": -1,
      "name": "Plant_Coral_Block_Blue"
    },
    {
      "x": -2,
      "y": 0,
      "z": 0,
      "name": "Plant_Coral_Block_Blue"
    },
    {
      "x": -2,
      "y": 1,
      "z": 0,
      "name": "Plant_Coral_Block_Blue"
    },
    {
      "x": -2,
      "y": 2,
      "z": 0,
      "name": "Plant_Coral_Block_Blue"
    },
    {
      "x": -2,
      "y": 3,
      "z": 0,
      "name": "Plant_Coral_Block_Blue"
    },
    {
      "x": -2,
      "y": 4,
      "z": 0,
      "name": "Plant_Coral_Block_Blue"
    },
    {
      "x": -2,
      "y": 5,
      "z": 0,
      "name": "Plant_Coral_Block_Blue"
    },
    {
      "x": -2,
      "y": 6,
      "z": 0,
      "name": "Plant_Coral_Block_Blue"
    },
    {
      "x": -2,
      "y": 7,
      "z": 0,
      "name": "Plant_Coral_Block_Blue"
    },
    {
      "x": -2,
      "y": 8,
      "z": 0,
      "name": "Plant_Coral_Block_Blue"
    },
    {
      "x": -2,
      "y": 9,
      "z": 0,
      "name": "Plant_Coral_Block_Blue"
    },
    {
      "x": -2,
      "y": 0,
      "z": 1,
      "name": "Plant_Coral_Block_Blue"
    },
    {
      "x": -2,
      "y": 1,
      "z": 1,
      "name": "Plant_Coral_Block_Blue"
    },
    {
      "x": -2,
      "y": 2,
      "z": 1,
      "name": "Plant_Coral_Block_Blue"
    },
    {
      "x": -2,
      "y": 3,
      "z": 1,
      "name": "Plant_Coral_Block_Blue"
    },
    {
      "x": -2,
      "y": 4,
      "z": 1,
      "name": "Plant_Coral_Block_Blue"
    },
    {
      "x": -2,
      "y": 5,
      "z": 1,
      "name": "Plant_Coral_Block_Blue"
    },
    {
      "x": -2,
      "y": 6,
      "z": 1,
      "name": "Plant_Coral_Block_Blue"
    },
    {
      "x": -2,
      "y": 7,
      "z": 1,
      "name": "Plant_Coral_Block_Blue"
    },
    {
      "x": -2,
      "y": 8,
      "z": 1,
      "name": "Plant_Coral_Block_Blue"
    },
    {
      "x": -2,
      "y": 9,
      "z": 1,
      "name": "Plant_Coral_Block_Blue"
    },
    {
      "x": -2,
      "y": 0,
      "z": 2,
      "name": "Plant_Coral_Block_Blue"
    },
    {
      "x": -2,
      "y": 1,
      "z": 2,
      "name": "Plant_Coral_Block_Blue"
    },
    {
      "x": -2,
      "y": 2,
      "z": 2,
      "name": "Plant_Coral_Block_Blue"
    },
    {
      "x": -2,
      "y": 3,
      "z": 2,
      "name": "Plant_Coral_Block_Blue"
    },
    {
      "x": -2,
      "y": 4,
      "z": 2,
      "name": "Plant_Coral_Block_Blue"
    },
    {
      "x": -2,
      "y": 5,
      "z": 2,
      "name": "Plant_Coral_Block_Blue"
    },
    {
      "x": -2,
      "y": 6,
      "z": 2,
      "name": "Plant_Coral_Block_Blue"
    },
    {
      "x": -2,
      "y": 7,
      "z": 2,
      "name": "Plant_Coral_Block_Blue"
    },
    {
      "x": -2,
      "y": 8,
      "z": 2,
      "name": "Plant_Coral_Block_Blue"
    },
    {
      "x": -2,
      "y": 9,
      "z": 2,
      "name": "Plant_Coral_Block_Blue"
    },
    {
      "x": -2,
      "y": 0,
      "z": 3,
      "name": "Plant_Coral_Block_Blue"
    },
    {
      "x": -2,
      "y": 1,
      "z": 3,
      "name": "Plant_Coral_Block_Blue"
    },
    {
      "x": -2,
      "y": 2,
      "z": 3,
      "name": "Plant_Coral_Block_Blue"
    },
    {
      "x": -2,
      "y": 3,
      "z": 3,
      "name": "Plant_Coral_Block_Blue"
    },
    {
      "x": -2,
      "y": 4,
      "z": 3,
      "name": "Plant_Coral_Block_Blue"
    },
    {
      "x": -2,
      "y": 5,
      "z": 3,
      "name": "Plant_Coral_Block_Blue"
    },
    {
      "x": -2,
      "y": 6,
      "z": 3,
      "name": "Plant_Coral_Block_Blue"
    },
    {
      "x": -2,
      "y": 7,
      "z": 3,
      "name": "Plant_Coral_Block_Blue"
    },
    {
      "x": -2,
      "y": 8,
      "z": 3,
      "name": "Plant_Coral_Block_Blue"
    },
    {
      "x": -2,
      "y": 9,
      "z": 3,
      "name": "Plant_Coral_Block_Blue"
    },
    {
      "x": -2,
      "y": 0,
      "z": 4,
      "name": "Plant_Coral_Block_Blue"
    },
    {
      "x": -2,
      "y": 1,
      "z": 4,
      "name": "Plant_Coral_Block_Blue"
    },
    {
      "x": -2,
      "y": 2,
      "z": 4,
      "name": "Plant_Coral_Block_Blue"
    },
    {
      "x": -2,
      "y": 3,
      "z": 4,
      "name": "Plant_Coral_Block_Blue"
    },
    {
      "x": -2,
      "y": 4,
      "z": 4,
      "name": "Plant_Coral_Block_Blue"
    },
    {
      "x": -2,
      "y": 5,
      "z": 4,
      "name": "Plant_Coral_Block_Orange"
    },
    {
      "x": -2,
      "y": 6,
      "z": 4,
      "name": "Plant_Coral_Block_Orange"
    },
    {
      "x": -2,
      "y": 7,
      "z": 4,
      "name": "Plant_Coral_Block_Blue"
    },
    {
      "x": -2,
      "y": 8,
      "z": 4,
      "name": "Plant_Coral_Block_Blue"
    },
    {
      "x": -2,
      "y": 9,
      "z": 4,
      "name": "Plant_Coral_Block_Blue"
    },
    {
      "x": -2,
      "y": 0,
      "z": 5,
      "name": "Plant_Coral_Block_Orange"
    },
    {
      "x": -2,
      "y": 1,
      "z": 5,
      "name": "Plant_Coral_Block_Orange"
    },
    {
      "x": -2,
      "y": 2,
      "z": 5,
      "name": "Plant_Coral_Block_Orange"
    },
    {
      "x": -2,
      "y": 3,
      "z": 5,
      "name": "Plant_Coral_Block_Orange"
    },
    {
      "x": -2,
      "y": 4,
      "z": 5,
      "name": "Plant_Coral_Block_Orange"
    },
    {
      "x": -2,
      "y": 5,
      "z": 5,
      "name": "Deco_Coral_Shell_Urchin"
    },
    {
      "x": -2,
      "y": 7,
      "z": 5,
      "name": "Plant_Coral_Block_Orange"
    },
    {
      "x": -2,
      "y": 8,
      "z": 5,
      "name": "Plant_Coral_Block_Orange"
    },
    {
      "x": -2,
      "y": 9,
      "z": 5,
      "name": "Plant_Coral_Block_Orange"
    },
    {
      "x": -2,
      "y": 0,
      "z": 6,
      "name": "Plant_Coral_Block_Orange"
    },
    {
      "x": -2,
      "y": 1,
      "z": 6,
      "name": "Plant_Coral_Block_Orange"
    },
    {
      "x": -2,
      "y": 2,
      "z": 6,
      "name": "Plant_Coral_Model_Orange"
    },
    {
      "x": -2,
      "y": 8,
      "z": 6,
      "name": "Plant_Coral_Bush_Orange"
    },
    {
      "x": -2,
      "y": 9,
      "z": 6,
      "name": "Plant_Coral_Block_Orange"
    },
    {
      "x": -1,
      "y": 0,
      "z": -7,
      "name": "Plant_Coral_Block_Orange"
    },
    {
      "x": -1,
      "y": 8,
      "z": -7,
      "name": "Plant_Coral_Block_Orange"
    },
    {
      "x": -1,
      "y": 9,
      "z": -7,
      "name": "Plant_Coral_Block_Orange"
    },
    {
      "x": -1,
      "y": 0,
      "z": -6,
      "name": "Plant_Coral_Block_Orange"
    },
    {
      "x": -1,
      "y": 1,
      "z": -6,
      "name": "Plant_Coral_Block_Orange"
    },
    {
      "x": -1,
      "y": 2,
      "z": -6,
      "name": "Plant_Coral_Block_Orange"
    },
    {
      "x": -1,
      "y": 3,
      "z": -6,
      "name": "Plant_Coral_Bush_Orange"
    },
    {
      "x": -1,
      "y": 7,
      "z": -6,
      "name": "Plant_Coral_Block_Orange"
    },
    {
      "x": -1,
      "y": 8,
      "z": -6,
      "name": "Plant_Coral_Block_Orange"
    },
    {
      "x": -1,
      "y": 9,
      "z": -6,
      "name": "Plant_Coral_Block_Orange"
    },
    {
      "x": -1,
      "y": 0,
      "z": -5,
      "name": "Plant_Coral_Block_Blue"
    },
    {
      "x": -1,
      "y": 1,
      "z": -5,
      "name": "Plant_Coral_Block_Blue"
    },
    {
      "x": -1,
      "y": 2,
      "z": -5,
      "name": "Plant_Coral_Block_Blue"
    },
    {
      "x": -1,
      "y": 3,
      "z": -5,
      "name": "Plant_Coral_Block_Orange"
    },
    {
      "x": -1,
      "y": 4,
      "z": -5,
      "name": "Plant_Coral_Block_Orange"
    },
    {
      "x": -1,
      "y": 5,
      "z": -5,
      "name": "Plant_Coral_Block_Orange"
    },
    {
      "x": -1,
      "y": 6,
      "z": -5,
      "name": "Plant_Coral_Block_Orange"
    },
    {
      "x": -1,
      "y": 7,
      "z": -5,
      "name": "Plant_Coral_Block_Blue"
    },
    {
      "x": -1,
      "y": 8,
      "z": -5,
      "name": "Plant_Coral_Block_Blue"
    },
    {
      "x": -1,
      "y": 9,
      "z": -5,
      "name": "Plant_Coral_Block_Blue"
    },
    {
      "x": -1,
      "y": 0,
      "z": -4,
      "name": "Plant_Coral_Block_Blue"
    },
    {
      "x": -1,
      "y": 1,
      "z": -4,
      "name": "Plant_Coral_Block_Blue"
    },
    {
      "x": -1,
      "y": 2,
      "z": -4,
      "name": "Plant_Coral_Block_Blue"
    },
    {
      "x": -1,
      "y": 3,
      "z": -4,
      "name": "Plant_Coral_Block_Blue"
    },
    {
      "x": -1,
      "y": 4,
      "z": -4,
      "name": "Plant_Coral_Block_Blue"
    },
    {
      "x": -1,
      "y": 5,
      "z": -4,
      "name": "Plant_Coral_Block_Blue"
    },
    {
      "x": -1,
      "y": 6,
      "z": -4,
      "name": "Plant_Coral_Block_Blue"
    },
    {
      "x": -1,
      "y": 7,
      "z": -4,
      "name": "Plant_Coral_Block_Blue"
    },
    {
      "x": -1,
      "y": 8,
      "z": -4,
      "name": "Plant_Coral_Block_Blue"
    },
    {
      "x": -1,
      "y": 9,
      "z": -4,
      "name": "Plant_Coral_Block_Blue"
    },
    {
      "x": -1,
      "y": 0,
      "z": -3,
      "name": "Plant_Coral_Block_Blue"
    },
    {
      "x": -1,
      "y": 1,
      "z": -3,
      "name": "Plant_Coral_Block_Blue"
    },
    {
      "x": -1,
      "y": 2,
      "z": -3,
      "name": "Plant_Coral_Block_Blue"
    },
    {
      "x": -1,
      "y": 3,
      "z": -3,
      "name": "Plant_Coral_Block_Blue"
    },
    {
      "x": -1,
      "y": 4,
      "z": -3,
      "name": "Plant_Coral_Block_Blue"
    },
    {
      "x": -1,
      "y": 5,
      "z": -3,
      "name": "Plant_Coral_Block_Blue"
    },
    {
      "x": -1,
      "y": 6,
      "z": -3,
      "name": "Plant_Coral_Block_Blue"
    },
    {
      "x": -1,
      "y": 7,
      "z": -3,
      "name": "Plant_Coral_Block_Blue"
    },
    {
      "x": -1,
      "y": 8,
      "z": -3,
      "name": "Plant_Coral_Block_Blue"
    },
    {
      "x": -1,
      "y": 9,
      "z": -3,
      "name": "Plant_Coral_Block_Blue"
    },
    {
      "x": -1,
      "y": 0,
      "z": -2,
      "name": "Plant_Coral_Block_Blue"
    },
    {
      "x": -1,
      "y": 1,
      "z": -2,
      "name": "Plant_Coral_Block_Blue"
    },
    {
      "x": -1,
      "y": 2,
      "z": -2,
      "name": "Plant_Coral_Block_Blue"
    },
    {
      "x": -1,
      "y": 3,
      "z": -2,
      "name": "Plant_Coral_Block_Blue"
    },
    {
      "x": -1,
      "y": 4,
      "z": -2,
      "name": "Plant_Coral_Block_Blue"
    },
    {
      "x": -1,
      "y": 5,
      "z": -2,
      "name": "Plant_Coral_Block_Blue"
    },
    {
      "x": -1,
      "y": 6,
      "z": -2,
      "name": "Plant_Coral_Block_Blue"
    },
    {
      "x": -1,
      "y": 7,
      "z": -2,
      "name": "Plant_Coral_Block_Blue"
    },
    {
      "x": -1,
      "y": 8,
      "z": -2,
      "name": "Plant_Coral_Block_Blue"
    },
    {
      "x": -1,
      "y": 9,
      "z": -2,
      "name": "Plant_Coral_Block_Blue"
    },
    {
      "x": -1,
      "y": 0,
      "z": -1,
      "name": "Plant_Coral_Block_Blue"
    },
    {
      "x": -1,
      "y": 1,
      "z": -1,
      "name": "Plant_Coral_Block_Blue"
    },
    {
      "x": -1,
      "y": 2,
      "z": -1,
      "name": "Plant_Coral_Block_Blue"
    },
    {
      "x": -1,
      "y": 3,
      "z": -1,
      "name": "Plant_Coral_Block_Blue"
    },
    {
      "x": -1,
      "y": 4,
      "z": -1,
      "name": "Plant_Coral_Block_Blue"
    },
    {
      "x": -1,
      "y": 5,
      "z": -1,
      "name": "Plant_Coral_Block_Blue"
    },
    {
      "x": -1,
      "y": 6,
      "z": -1,
      "name": "Plant_Coral_Block_Blue"
    },
    {
      "x": -1,
      "y": 7,
      "z": -1,
      "name": "Plant_Coral_Block_Blue"
    },
    {
      "x": -1,
      "y": 8,
      "z": -1,
      "name": "Plant_Coral_Block_Blue"
    },
    {
      "x": -1,
      "y": 9,
      "z": -1,
      "name": "Plant_Coral_Block_Blue"
    },
    {
      "x": -1,
      "y": 0,
      "z": 0,
      "name": "Plant_Coral_Block_Blue"
    },
    {
      "x": -1,
      "y": 1,
      "z": 0,
      "name": "Plant_Coral_Block_Blue"
    },
    {
      "x": -1,
      "y": 2,
      "z": 0,
      "name": "Plant_Coral_Block_Blue"
    },
    {
      "x": -1,
      "y": 3,
      "z": 0,
      "name": "Plant_Coral_Block_Blue"
    },
    {
      "x": -1,
      "y": 4,
      "z": 0,
      "name": "Plant_Coral_Block_Blue"
    },
    {
      "x": -1,
      "y": 5,
      "z": 0,
      "name": "Plant_Coral_Block_Blue"
    },
    {
      "x": -1,
      "y": 6,
      "z": 0,
      "name": "Plant_Coral_Block_Blue"
    },
    {
      "x": -1,
      "y": 7,
      "z": 0,
      "name": "Plant_Coral_Block_Blue"
    },
    {
      "x": -1,
      "y": 8,
      "z": 0,
      "name": "Plant_Coral_Block_Blue"
    },
    {
      "x": -1,
      "y": 9,
      "z": 0,
      "name": "Plant_Coral_Block_Blue"
    },
    {
      "x": -1,
      "y": 0,
      "z": 1,
      "name": "Plant_Coral_Block_Blue"
    },
    {
      "x": -1,
      "y": 1,
      "z": 1,
      "name": "Plant_Coral_Block_Blue"
    },
    {
      "x": -1,
      "y": 2,
      "z": 1,
      "name": "Plant_Coral_Block_Blue"
    },
    {
      "x": -1,
      "y": 3,
      "z": 1,
      "name": "Plant_Coral_Block_Blue"
    },
    {
      "x": -1,
      "y": 4,
      "z": 1,
      "name": "Plant_Coral_Block_Blue"
    },
    {
      "x": -1,
      "y": 5,
      "z": 1,
      "name": "Plant_Coral_Block_Blue"
    },
    {
      "x": -1,
      "y": 6,
      "z": 1,
      "name": "Plant_Coral_Block_Blue"
    },
    {
      "x": -1,
      "y": 7,
      "z": 1,
      "name": "Plant_Coral_Block_Blue"
    },
    {
      "x": -1,
      "y": 8,
      "z": 1,
      "name": "Plant_Coral_Block_Blue"
    },
    {
      "x": -1,
      "y": 9,
      "z": 1,
      "name": "Plant_Coral_Block_Blue"
    },
    {
      "x": -1,
      "y": 0,
      "z": 2,
      "name": "Plant_Coral_Block_Blue"
    },
    {
      "x": -1,
      "y": 1,
      "z": 2,
      "name": "Plant_Coral_Block_Blue"
    },
    {
      "x": -1,
      "y": 2,
      "z": 2,
      "name": "Plant_Coral_Block_Blue"
    },
    {
      "x": -1,
      "y": 3,
      "z": 2,
      "name": "Plant_Coral_Block_Blue"
    },
    {
      "x": -1,
      "y": 4,
      "z": 2,
      "name": "Plant_Coral_Block_Blue"
    },
    {
      "x": -1,
      "y": 5,
      "z": 2,
      "name": "Plant_Coral_Block_Blue"
    },
    {
      "x": -1,
      "y": 6,
      "z": 2,
      "name": "Plant_Coral_Block_Blue"
    },
    {
      "x": -1,
      "y": 7,
      "z": 2,
      "name": "Plant_Coral_Block_Blue"
    },
    {
      "x": -1,
      "y": 8,
      "z": 2,
      "name": "Plant_Coral_Block_Blue"
    },
    {
      "x": -1,
      "y": 9,
      "z": 2,
      "name": "Plant_Coral_Block_Blue"
    },
    {
      "x": -1,
      "y": 0,
      "z": 3,
      "name": "Plant_Coral_Block_Blue"
    },
    {
      "x": -1,
      "y": 1,
      "z": 3,
      "name": "Plant_Coral_Block_Blue"
    },
    {
      "x": -1,
      "y": 2,
      "z": 3,
      "name": "Plant_Coral_Block_Blue"
    },
    {
      "x": -1,
      "y": 3,
      "z": 3,
      "name": "Plant_Coral_Block_Blue"
    },
    {
      "x": -1,
      "y": 4,
      "z": 3,
      "name": "Plant_Coral_Block_Blue"
    },
    {
      "x": -1,
      "y": 5,
      "z": 3,
      "name": "Plant_Coral_Block_Blue"
    },
    {
      "x": -1,
      "y": 6,
      "z": 3,
      "name": "Plant_Coral_Block_Blue"
    },
    {
      "x": -1,
      "y": 7,
      "z": 3,
      "name": "Plant_Coral_Block_Blue"
    },
    {
      "x": -1,
      "y": 8,
      "z": 3,
      "name": "Plant_Coral_Block_Blue"
    },
    {
      "x": -1,
      "y": 9,
      "z": 3,
      "name": "Plant_Coral_Block_Blue"
    },
    {
      "x": -1,
      "y": 0,
      "z": 4,
      "name": "Plant_Coral_Block_Blue"
    },
    {
      "x": -1,
      "y": 1,
      "z": 4,
      "name": "Plant_Coral_Block_Blue"
    },
    {
      "x": -1,
      "y": 2,
      "z": 4,
      "name": "Plant_Coral_Block_Blue"
    },
    {
      "x": -1,
      "y": 3,
      "z": 4,
      "name": "Plant_Coral_Block_Blue"
    },
    {
      "x": -1,
      "y": 4,
      "z": 4,
      "name": "Plant_Coral_Block_Blue"
    },
    {
      "x": -1,
      "y": 5,
      "z": 4,
      "name": "Plant_Coral_Block_Blue"
    },
    {
      "x": -1,
      "y": 6,
      "z": 4,
      "name": "Plant_Coral_Block_Blue"
    },
    {
      "x": -1,
      "y": 7,
      "z": 4,
      "name": "Plant_Coral_Block_Blue"
    },
    {
      "x": -1,
      "y": 8,
      "z": 4,
      "name": "Plant_Coral_Block_Blue"
    },
    {
      "x": -1,
      "y": 9,
      "z": 4,
      "name": "Plant_Coral_Block_Blue"
    },
    {
      "x": -1,
      "y": 0,
      "z": 5,
      "name": "Plant_Coral_Block_Blue"
    },
    {
      "x": -1,
      "y": 1,
      "z": 5,
      "name": "Plant_Coral_Block_Blue"
    },
    {
      "x": -1,
      "y": 2,
      "z": 5,
      "name": "Plant_Coral_Block_Blue"
    },
    {
      "x": -1,
      "y": 3,
      "z": 5,
      "name": "Plant_Coral_Block_Orange"
    },
    {
      "x": -1,
      "y": 4,
      "z": 5,
      "name": "Plant_Coral_Block_Orange"
    },
    {
      "x": -1,
      "y": 5,
      "z": 5,
      "name": "Plant_Coral_Block_Orange"
    },
    {
      "x": -1,
      "y": 6,
      "z": 5,
      "name": "Plant_Coral_Block_Orange"
    },
    {
      "x": -1,
      "y": 7,
      "z": 5,
      "name": "Plant_Coral_Block_Blue"
    },
    {
      "x": -1,
      "y": 8,
      "z": 5,
      "name": "Plant_Coral_Block_Blue"
    },
    {
      "x": -1,
      "y": 9,
      "z": 5,
      "name": "Plant_Coral_Block_Blue"
    },
    {
      "x": -1,
      "y": 0,
      "z": 6,
      "name": "Plant_Coral_Block_Orange"
    },
    {
      "x": -1,
      "y": 1,
      "z": 6,
      "name": "Plant_Coral_Block_Orange"
    },
    {
      "x": -1,
      "y": 2,
      "z": 6,
      "name": "Plant_Coral_Block_Orange"
    },
    {
      "x": -1,
      "y": 3,
      "z": 6,
      "name": "Plant_Coral_Block_Orange"
    },
    {
      "x": -1,
      "y": 7,
      "z": 6,
      "name": "Plant_Coral_Block_Orange"
    },
    {
      "x": -1,
      "y": 8,
      "z": 6,
      "name": "Plant_Coral_Block_Orange"
    },
    {
      "x": -1,
      "y": 9,
      "z": 6,
      "name": "Plant_Coral_Block_Orange"
    },
    {
      "x": 0,
      "y": 0,
      "z": -7,
      "name": "Plant_Coral_Block_Orange"
    },
    {
      "x": 0,
      "y": 1,
      "z": -7,
      "name": "Plant_Coral_Block_Orange"
    },
    {
      "x": 0,
      "y": 9,
      "z": -7,
      "name": "Plant_Coral_Block_Orange"
    },
    {
      "x": 0,
      "y": 0,
      "z": -6,
      "name": "Plant_Coral_Block_Orange"
    },
    {
      "x": 0,
      "y": 1,
      "z": -6,
      "name": "Plant_Coral_Block_Orange"
    },
    {
      "x": 0,
      "y": 2,
      "z": -6,
      "name": "Plant_Coral_Block_Orange"
    },
    {
      "x": 0,
      "y": 3,
      "z": -6,
      "name": "Plant_Coral_Block_Orange"
    },
    {
      "x": 0,
      "y": 4,
      "z": -6,
      "name": "Plant_Coral_Block_Orange"
    },
    {
      "x": 0,
      "y": 5,
      "z": -6,
      "name": "Plant_Coral_Block_Orange"
    },
    {
      "x": 0,
      "y": 6,
      "z": -6,
      "name": "Plant_Coral_Block_Orange"
    },
    {
      "x": 0,
      "y": 7,
      "z": -6,
      "name": "Plant_Coral_Block_Orange"
    },
    {
      "x": 0,
      "y": 8,
      "z": -6,
      "name": "Plant_Coral_Block_Orange"
    },
    {
      "x": 0,
      "y": 9,
      "z": -6,
      "name": "Plant_Coral_Block_Orange"
    },
    {
      "x": 0,
      "y": 0,
      "z": -5,
      "name": "Plant_Coral_Block_Blue"
    },
    {
      "x": 0,
      "y": 1,
      "z": -5,
      "name": "Plant_Coral_Block_Blue"
    },
    {
      "x": 0,
      "y": 2,
      "z": -5,
      "name": "Plant_Coral_Block_Blue"
    },
    {
      "x": 0,
      "y": 3,
      "z": -5,
      "name": "Plant_Coral_Block_Blue"
    },
    {
      "x": 0,
      "y": 4,
      "z": -5,
      "name": "Plant_Coral_Block_Blue"
    },
    {
      "x": 0,
      "y": 5,
      "z": -5,
      "name": "Plant_Coral_Block_Blue"
    },
    {
      "x": 0,
      "y": 6,
      "z": -5,
      "name": "Plant_Coral_Block_Blue"
    },
    {
      "x": 0,
      "y": 7,
      "z": -5,
      "name": "Plant_Coral_Block_Blue"
    },
    {
      "x": 0,
      "y": 8,
      "z": -5,
      "name": "Plant_Coral_Block_Blue"
    },
    {
      "x": 0,
      "y": 9,
      "z": -5,
      "name": "Plant_Coral_Block_Blue"
    },
    {
      "x": 0,
      "y": 0,
      "z": -4,
      "name": "Plant_Coral_Block_Blue"
    },
    {
      "x": 0,
      "y": 1,
      "z": -4,
      "name": "Plant_Coral_Block_Blue"
    },
    {
      "x": 0,
      "y": 2,
      "z": -4,
      "name": "Plant_Coral_Block_Blue"
    },
    {
      "x": 0,
      "y": 3,
      "z": -4,
      "name": "Plant_Coral_Block_Blue"
    },
    {
      "x": 0,
      "y": 4,
      "z": -4,
      "name": "Plant_Coral_Block_Blue"
    },
    {
      "x": 0,
      "y": 5,
      "z": -4,
      "name": "Plant_Coral_Block_Blue"
    },
    {
      "x": 0,
      "y": 6,
      "z": -4,
      "name": "Plant_Coral_Block_Blue"
    },
    {
      "x": 0,
      "y": 7,
      "z": -4,
      "name": "Plant_Coral_Block_Blue"
    },
    {
      "x": 0,
      "y": 8,
      "z": -4,
      "name": "Plant_Coral_Block_Blue"
    },
    {
      "x": 0,
      "y": 9,
      "z": -4,
      "name": "Plant_Coral_Block_Blue"
    },
    {
      "x": 0,
      "y": 0,
      "z": -3,
      "name": "Plant_Coral_Block_Blue"
    },
    {
      "x": 0,
      "y": 1,
      "z": -3,
      "name": "Plant_Coral_Block_Blue"
    },
    {
      "x": 0,
      "y": 2,
      "z": -3,
      "name": "Plant_Coral_Block_Blue"
    },
    {
      "x": 0,
      "y": 3,
      "z": -3,
      "name": "Plant_Coral_Block_Blue"
    },
    {
      "x": 0,
      "y": 4,
      "z": -3,
      "name": "Plant_Coral_Block_Blue"
    },
    {
      "x": 0,
      "y": 5,
      "z": -3,
      "name": "Plant_Coral_Block_Blue"
    },
    {
      "x": 0,
      "y": 6,
      "z": -3,
      "name": "Plant_Coral_Block_Blue"
    },
    {
      "x": 0,
      "y": 7,
      "z": -3,
      "name": "Plant_Coral_Block_Blue"
    },
    {
      "x": 0,
      "y": 8,
      "z": -3,
      "name": "Plant_Coral_Block_Blue"
    },
    {
      "x": 0,
      "y": 9,
      "z": -3,
      "name": "Plant_Coral_Block_Blue"
    },
    {
      "x": 0,
      "y": 0,
      "z": -2,
      "name": "Plant_Coral_Block_Blue"
    },
    {
      "x": 0,
      "y": 1,
      "z": -2,
      "name": "Plant_Coral_Block_Blue"
    },
    {
      "x": 0,
      "y": 2,
      "z": -2,
      "name": "Plant_Coral_Block_Blue"
    },
    {
      "x": 0,
      "y": 3,
      "z": -2,
      "name": "Plant_Coral_Block_Blue"
    },
    {
      "x": 0,
      "y": 4,
      "z": -2,
      "name": "Plant_Coral_Block_Blue"
    },
    {
      "x": 0,
      "y": 5,
      "z": -2,
      "name": "Plant_Coral_Block_Blue"
    },
    {
      "x": 0,
      "y": 6,
      "z": -2,
      "name": "Plant_Coral_Block_Blue"
    },
    {
      "x": 0,
      "y": 7,
      "z": -2,
      "name": "Plant_Coral_Block_Blue"
    },
    {
      "x": 0,
      "y": 8,
      "z": -2,
      "name": "Plant_Coral_Block_Blue"
    },
    {
      "x": 0,
      "y": 9,
      "z": -2,
      "name": "Plant_Coral_Block_Blue"
    },
    {
      "x": 0,
      "y": 0,
      "z": -1,
      "name": "Plant_Coral_Block_Blue"
    },
    {
      "x": 0,
      "y": 1,
      "z": -1,
      "name": "Plant_Coral_Block_Blue"
    },
    {
      "x": 0,
      "y": 2,
      "z": -1,
      "name": "Plant_Coral_Block_Blue"
    },
    {
      "x": 0,
      "y": 3,
      "z": -1,
      "name": "Plant_Coral_Block_Blue"
    },
    {
      "x": 0,
      "y": 4,
      "z": -1,
      "name": "Plant_Coral_Block_Blue"
    },
    {
      "x": 0,
      "y": 5,
      "z": -1,
      "name": "Plant_Coral_Block_Blue"
    },
    {
      "x": 0,
      "y": 6,
      "z": -1,
      "name": "Plant_Coral_Block_Blue"
    },
    {
      "x": 0,
      "y": 7,
      "z": -1,
      "name": "Plant_Coral_Block_Blue"
    },
    {
      "x": 0,
      "y": 8,
      "z": -1,
      "name": "Plant_Coral_Block_Blue"
    },
    {
      "x": 0,
      "y": 9,
      "z": -1,
      "name": "Plant_Coral_Block_Blue"
    },
    {
      "x": 0,
      "y": 0,
      "z": 0,
      "name": "Plant_Coral_Block_Blue"
    },
    {
      "x": 0,
      "y": 1,
      "z": 0,
      "name": "Plant_Coral_Block_Blue"
    },
    {
      "x": 0,
      "y": 2,
      "z": 0,
      "name": "Plant_Coral_Block_Blue"
    },
    {
      "x": 0,
      "y": 3,
      "z": 0,
      "name": "Plant_Coral_Block_Blue"
    },
    {
      "x": 0,
      "y": 4,
      "z": 0,
      "name": "Plant_Coral_Block_Blue"
    },
    {
      "x": 0,
      "y": 5,
      "z": 0,
      "name": "Plant_Coral_Block_Blue"
    },
    {
      "x": 0,
      "y": 6,
      "z": 0,
      "name": "Plant_Coral_Block_Blue"
    },
    {
      "x": 0,
      "y": 7,
      "z": 0,
      "name": "Plant_Coral_Block_Blue"
    },
    {
      "x": 0,
      "y": 8,
      "z": 0,
      "name": "Plant_Coral_Block_Blue"
    },
    {
      "x": 0,
      "y": 9,
      "z": 0,
      "name": "Plant_Coral_Block_Blue"
    },
    {
      "x": 0,
      "y": 0,
      "z": 1,
      "name": "Plant_Coral_Block_Blue"
    },
    {
      "x": 0,
      "y": 1,
      "z": 1,
      "name": "Plant_Coral_Block_Blue"
    },
    {
      "x": 0,
      "y": 2,
      "z": 1,
      "name": "Plant_Coral_Block_Blue"
    },
    {
      "x": 0,
      "y": 3,
      "z": 1,
      "name": "Plant_Coral_Block_Blue"
    },
    {
      "x": 0,
      "y": 4,
      "z": 1,
      "name": "Plant_Coral_Block_Blue"
    },
    {
      "x": 0,
      "y": 5,
      "z": 1,
      "name": "Plant_Coral_Block_Blue"
    },
    {
      "x": 0,
      "y": 6,
      "z": 1,
      "name": "Plant_Coral_Block_Blue"
    },
    {
      "x": 0,
      "y": 7,
      "z": 1,
      "name": "Plant_Coral_Block_Blue"
    },
    {
      "x": 0,
      "y": 8,
      "z": 1,
      "name": "Plant_Coral_Block_Blue"
    },
    {
      "x": 0,
      "y": 9,
      "z": 1,
      "name": "Plant_Coral_Block_Blue"
    },
    {
      "x": 0,
      "y": 0,
      "z": 2,
      "name": "Plant_Coral_Block_Blue"
    },
    {
      "x": 0,
      "y": 1,
      "z": 2,
      "name": "Plant_Coral_Block_Blue"
    },
    {
      "x": 0,
      "y": 2,
      "z": 2,
      "name": "Plant_Coral_Block_Blue"
    },
    {
      "x": 0,
      "y": 3,
      "z": 2,
      "name": "Plant_Coral_Block_Blue"
    },
    {
      "x": 0,
      "y": 4,
      "z": 2,
      "name": "Plant_Coral_Block_Blue"
    },
    {
      "x": 0,
      "y": 5,
      "z": 2,
      "name": "Plant_Coral_Block_Blue"
    },
    {
      "x": 0,
      "y": 6,
      "z": 2,
      "name": "Plant_Coral_Block_Blue"
    },
    {
      "x": 0,
      "y": 7,
      "z": 2,
      "name": "Plant_Coral_Block_Blue"
    },
    {
      "x": 0,
      "y": 8,
      "z": 2,
      "name": "Plant_Coral_Block_Blue"
    },
    {
      "x": 0,
      "y": 9,
      "z": 2,
      "name": "Plant_Coral_Block_Blue"
    },
    {
      "x": 0,
      "y": 0,
      "z": 3,
      "name": "Plant_Coral_Block_Blue"
    },
    {
      "x": 0,
      "y": 1,
      "z": 3,
      "name": "Plant_Coral_Block_Blue"
    },
    {
      "x": 0,
      "y": 2,
      "z": 3,
      "name": "Plant_Coral_Block_Blue"
    },
    {
      "x": 0,
      "y": 3,
      "z": 3,
      "name": "Plant_Coral_Block_Blue"
    },
    {
      "x": 0,
      "y": 4,
      "z": 3,
      "name": "Plant_Coral_Block_Blue"
    },
    {
      "x": 0,
      "y": 5,
      "z": 3,
      "name": "Plant_Coral_Block_Blue"
    },
    {
      "x": 0,
      "y": 6,
      "z": 3,
      "name": "Plant_Coral_Block_Blue"
    },
    {
      "x": 0,
      "y": 7,
      "z": 3,
      "name": "Plant_Coral_Block_Blue"
    },
    {
      "x": 0,
      "y": 8,
      "z": 3,
      "name": "Plant_Coral_Block_Blue"
    },
    {
      "x": 0,
      "y": 9,
      "z": 3,
      "name": "Plant_Coral_Block_Blue"
    },
    {
      "x": 0,
      "y": 0,
      "z": 4,
      "name": "Plant_Coral_Block_Blue"
    },
    {
      "x": 0,
      "y": 1,
      "z": 4,
      "name": "Plant_Coral_Block_Blue"
    },
    {
      "x": 0,
      "y": 2,
      "z": 4,
      "name": "Plant_Coral_Block_Blue"
    },
    {
      "x": 0,
      "y": 3,
      "z": 4,
      "name": "Plant_Coral_Block_Blue"
    },
    {
      "x": 0,
      "y": 4,
      "z": 4,
      "name": "Plant_Coral_Block_Blue"
    },
    {
      "x": 0,
      "y": 5,
      "z": 4,
      "name": "Plant_Coral_Block_Blue"
    },
    {
      "x": 0,
      "y": 6,
      "z": 4,
      "name": "Plant_Coral_Block_Blue"
    },
    {
      "x": 0,
      "y": 7,
      "z": 4,
      "name": "Plant_Coral_Block_Blue"
    },
    {
      "x": 0,
      "y": 8,
      "z": 4,
      "name": "Plant_Coral_Block_Blue"
    },
    {
      "x": 0,
      "y": 9,
      "z": 4,
      "name": "Plant_Coral_Block_Blue"
    },
    {
      "x": 0,
      "y": 0,
      "z": 5,
      "name": "Plant_Coral_Block_Blue"
    },
    {
      "x": 0,
      "y": 1,
      "z": 5,
      "name": "Plant_Coral_Block_Blue"
    },
    {
      "x": 0,
      "y": 2,
      "z": 5,
      "name": "Plant_Coral_Block_Blue"
    },
    {
      "x": 0,
      "y": 3,
      "z": 5,
      "name": "Plant_Coral_Block_Blue"
    },
    {
      "x": 0,
      "y": 4,
      "z": 5,
      "name": "Plant_Coral_Block_Orange"
    },
    {
      "x": 0,
      "y": 5,
      "z": 5,
      "name": "Plant_Coral_Block_Orange"
    },
    {
      "x": 0,
      "y": 6,
      "z": 5,
      "name": "Plant_Coral_Block_Blue"
    },
    {
      "x": 0,
      "y": 7,
      "z": 5,
      "name": "Plant_Coral_Block_Blue"
    },
    {
      "x": 0,
      "y": 8,
      "z": 5,
      "name": "Plant_Coral_Block_Blue"
    },
    {
      "x": 0,
      "y": 9,
      "z": 5,
      "name": "Plant_Coral_Block_Blue"
    },
    {
      "x": 0,
      "y": 0,
      "z": 6,
      "name": "Plant_Coral_Block_Orange"
    },
    {
      "x": 0,
      "y": 1,
      "z": 6,
      "name": "Plant_Coral_Block_Orange"
    },
    {
      "x": 0,
      "y": 2,
      "z": 6,
      "name": "Plant_Coral_Block_Orange"
    },
    {
      "x": 0,
      "y": 3,
      "z": 6,
      "name": "Plant_Coral_Block_Orange"
    },
    {
      "x": 0,
      "y": 6,
      "z": 6,
      "name": "Plant_Coral_Block_Orange"
    },
    {
      "x": 0,
      "y": 7,
      "z": 6,
      "name": "Plant_Coral_Block_Orange"
    },
    {
      "x": 0,
      "y": 8,
      "z": 6,
      "name": "Plant_Coral_Block_Orange"
    },
    {
      "x": 0,
      "y": 9,
      "z": 6,
      "name": "Plant_Coral_Block_Orange"
    },
    {
      "x": 0,
      "y": 0,
      "z": 7,
      "name": "Plant_Coral_Block_Orange"
    },
    {
      "x": 0,
      "y": 1,
      "z": 7,
      "name": "Plant_Coral_Block_Orange"
    },
    {
      "x": 0,
      "y": 8,
      "z": 7,
      "name": "Plant_Coral_Block_Orange"
    },
    {
      "x": 0,
      "y": 9,
      "z": 7,
      "name": "Plant_Coral_Block_Orange"
    },
    {
      "x": 1,
      "y": 9,
      "z": -7,
      "name": "Plant_Coral_Block_Orange"
    },
    {
      "x": 1,
      "y": 0,
      "z": -6,
      "name": "Plant_Coral_Block_Orange"
    },
    {
      "x": 1,
      "y": 1,
      "z": -6,
      "name": "Plant_Coral_Block_Orange"
    },
    {
      "x": 1,
      "y": 2,
      "z": -6,
      "name": "Plant_Coral_Block_Orange"
    },
    {
      "x": 1,
      "y": 3,
      "z": -6,
      "name": "Plant_Coral_Block_Orange"
    },
    {
      "x": 1,
      "y": 4,
      "z": -6,
      "name": "Plant_Coral_Block_Orange"
    },
    {
      "x": 1,
      "y": 5,
      "z": -6,
      "name": "Plant_Coral_Bush_Orange"
    },
    {
      "x": 1,
      "y": 7,
      "z": -6,
      "name": "Plant_Coral_Block_Orange"
    },
    {
      "x": 1,
      "y": 8,
      "z": -6,
      "name": "Plant_Coral_Block_Orange"
    },
    {
      "x": 1,
      "y": 9,
      "z": -6,
      "name": "Plant_Coral_Block_Orange"
    },
    {
      "x": 1,
      "y": 0,
      "z": -5,
      "name": "Plant_Coral_Block_Blue"
    },
    {
      "x": 1,
      "y": 1,
      "z": -5,
      "name": "Plant_Coral_Block_Blue"
    },
    {
      "x": 1,
      "y": 2,
      "z": -5,
      "name": "Plant_Coral_Block_Blue"
    },
    {
      "x": 1,
      "y": 3,
      "z": -5,
      "name": "Plant_Coral_Block_Blue"
    },
    {
      "x": 1,
      "y": 4,
      "z": -5,
      "name": "Plant_Coral_Block_Blue"
    },
    {
      "x": 1,
      "y": 5,
      "z": -5,
      "name": "Plant_Coral_Block_Orange"
    },
    {
      "x": 1,
      "y": 6,
      "z": -5,
      "name": "Plant_Coral_Block_Orange"
    },
    {
      "x": 1,
      "y": 7,
      "z": -5,
      "name": "Plant_Coral_Block_Orange"
    },
    {
      "x": 1,
      "y": 8,
      "z": -5,
      "name": "Plant_Coral_Block_Blue"
    },
    {
      "x": 1,
      "y": 9,
      "z": -5,
      "name": "Plant_Coral_Block_Blue"
    },
    {
      "x": 1,
      "y": 0,
      "z": -4,
      "name": "Plant_Coral_Block_Blue"
    },
    {
      "x": 1,
      "y": 1,
      "z": -4,
      "name": "Plant_Coral_Block_Blue"
    },
    {
      "x": 1,
      "y": 2,
      "z": -4,
      "name": "Plant_Coral_Block_Blue"
    },
    {
      "x": 1,
      "y": 3,
      "z": -4,
      "name": "Plant_Coral_Block_Blue"
    },
    {
      "x": 1,
      "y": 4,
      "z": -4,
      "name": "Plant_Coral_Block_Blue"
    },
    {
      "x": 1,
      "y": 5,
      "z": -4,
      "name": "Plant_Coral_Block_Blue"
    },
    {
      "x": 1,
      "y": 6,
      "z": -4,
      "name": "Plant_Coral_Block_Blue"
    },
    {
      "x": 1,
      "y": 7,
      "z": -4,
      "name": "Plant_Coral_Block_Blue"
    },
    {
      "x": 1,
      "y": 8,
      "z": -4,
      "name": "Plant_Coral_Block_Blue"
    },
    {
      "x": 1,
      "y": 9,
      "z": -4,
      "name": "Plant_Coral_Block_Blue"
    },
    {
      "x": 1,
      "y": 0,
      "z": -3,
      "name": "Plant_Coral_Block_Blue"
    },
    {
      "x": 1,
      "y": 1,
      "z": -3,
      "name": "Plant_Coral_Block_Blue"
    },
    {
      "x": 1,
      "y": 2,
      "z": -3,
      "name": "Plant_Coral_Block_Blue"
    },
    {
      "x": 1,
      "y": 3,
      "z": -3,
      "name": "Plant_Coral_Block_Blue"
    },
    {
      "x": 1,
      "y": 4,
      "z": -3,
      "name": "Plant_Coral_Block_Blue"
    },
    {
      "x": 1,
      "y": 5,
      "z": -3,
      "name": "Plant_Coral_Block_Blue"
    },
    {
      "x": 1,
      "y": 6,
      "z": -3,
      "name": "Plant_Coral_Block_Blue"
    },
    {
      "x": 1,
      "y": 7,
      "z": -3,
      "name": "Plant_Coral_Block_Blue"
    },
    {
      "x": 1,
      "y": 8,
      "z": -3,
      "name": "Plant_Coral_Block_Blue"
    },
    {
      "x": 1,
      "y": 9,
      "z": -3,
      "name": "Plant_Coral_Block_Blue"
    },
    {
      "x": 1,
      "y": 0,
      "z": -2,
      "name": "Plant_Coral_Block_Blue"
    },
    {
      "x": 1,
      "y": 1,
      "z": -2,
      "name": "Plant_Coral_Block_Blue"
    },
    {
      "x": 1,
      "y": 2,
      "z": -2,
      "name": "Plant_Coral_Block_Blue"
    },
    {
      "x": 1,
      "y": 3,
      "z": -2,
      "name": "Plant_Coral_Block_Blue"
    },
    {
      "x": 1,
      "y": 4,
      "z": -2,
      "name": "Plant_Coral_Block_Blue"
    },
    {
      "x": 1,
      "y": 5,
      "z": -2,
      "name": "Plant_Coral_Block_Blue"
    },
    {
      "x": 1,
      "y": 6,
      "z": -2,
      "name": "Plant_Coral_Block_Blue"
    },
    {
      "x": 1,
      "y": 7,
      "z": -2,
      "name": "Plant_Coral_Block_Blue"
    },
    {
      "x": 1,
      "y": 8,
      "z": -2,
      "name": "Plant_Coral_Block_Blue"
    },
    {
      "x": 1,
      "y": 9,
      "z": -2,
      "name": "Plant_Coral_Block_Blue"
    },
    {
      "x": 1,
      "y": 0,
      "z": -1,
      "name": "Plant_Coral_Block_Blue"
    },
    {
      "x": 1,
      "y": 1,
      "z": -1,
      "name": "Plant_Coral_Block_Blue"
    },
    {
      "x": 1,
      "y": 2,
      "z": -1,
      "name": "Plant_Coral_Block_Blue"
    },
    {
      "x": 1,
      "y": 3,
      "z": -1,
      "name": "Plant_Coral_Block_Blue"
    },
    {
      "x": 1,
      "y": 4,
      "z": -1,
      "name": "Plant_Coral_Block_Blue"
    },
    {
      "x": 1,
      "y": 5,
      "z": -1,
      "name": "Plant_Coral_Block_Blue"
    },
    {
      "x": 1,
      "y": 6,
      "z": -1,
      "name": "Plant_Coral_Block_Blue"
    },
    {
      "x": 1,
      "y": 7,
      "z": -1,
      "name": "Plant_Coral_Block_Blue"
    },
    {
      "x": 1,
      "y": 8,
      "z": -1,
      "name": "Plant_Coral_Block_Blue"
    },
    {
      "x": 1,
      "y": 9,
      "z": -1,
      "name": "Plant_Coral_Block_Blue"
    },
    {
      "x": 1,
      "y": 0,
      "z": 0,
      "name": "Plant_Coral_Block_Blue"
    },
    {
      "x": 1,
      "y": 1,
      "z": 0,
      "name": "Plant_Coral_Block_Blue"
    },
    {
      "x": 1,
      "y": 2,
      "z": 0,
      "name": "Plant_Coral_Block_Blue"
    },
    {
      "x": 1,
      "y": 3,
      "z": 0,
      "name": "Plant_Coral_Block_Blue"
    },
    {
      "x": 1,
      "y": 4,
      "z": 0,
      "name": "Plant_Coral_Block_Blue"
    },
    {
      "x": 1,
      "y": 5,
      "z": 0,
      "name": "Plant_Coral_Block_Blue"
    },
    {
      "x": 1,
      "y": 6,
      "z": 0,
      "name": "Plant_Coral_Block_Blue"
    },
    {
      "x": 1,
      "y": 7,
      "z": 0,
      "name": "Plant_Coral_Block_Blue"
    },
    {
      "x": 1,
      "y": 8,
      "z": 0,
      "name": "Plant_Coral_Block_Blue"
    },
    {
      "x": 1,
      "y": 9,
      "z": 0,
      "name": "Plant_Coral_Block_Blue"
    },
    {
      "x": 1,
      "y": 0,
      "z": 1,
      "name": "Plant_Coral_Block_Blue"
    },
    {
      "x": 1,
      "y": 1,
      "z": 1,
      "name": "Plant_Coral_Block_Blue"
    },
    {
      "x": 1,
      "y": 2,
      "z": 1,
      "name": "Plant_Coral_Block_Blue"
    },
    {
      "x": 1,
      "y": 3,
      "z": 1,
      "name": "Plant_Coral_Block_Blue"
    },
    {
      "x": 1,
      "y": 4,
      "z": 1,
      "name": "Plant_Coral_Block_Blue"
    },
    {
      "x": 1,
      "y": 5,
      "z": 1,
      "name": "Plant_Coral_Block_Blue"
    },
    {
      "x": 1,
      "y": 6,
      "z": 1,
      "name": "Plant_Coral_Block_Blue"
    },
    {
      "x": 1,
      "y": 7,
      "z": 1,
      "name": "Plant_Coral_Block_Blue"
    },
    {
      "x": 1,
      "y": 8,
      "z": 1,
      "name": "Plant_Coral_Block_Blue"
    },
    {
      "x": 1,
      "y": 9,
      "z": 1,
      "name": "Plant_Coral_Block_Blue"
    },
    {
      "x": 1,
      "y": 0,
      "z": 2,
      "name": "Plant_Coral_Block_Blue"
    },
    {
      "x": 1,
      "y": 1,
      "z": 2,
      "name": "Plant_Coral_Block_Blue"
    },
    {
      "x": 1,
      "y": 2,
      "z": 2,
      "name": "Plant_Coral_Block_Blue"
    },
    {
      "x": 1,
      "y": 3,
      "z": 2,
      "name": "Plant_Coral_Block_Blue"
    },
    {
      "x": 1,
      "y": 4,
      "z": 2,
      "name": "Plant_Coral_Block_Blue"
    },
    {
      "x": 1,
      "y": 5,
      "z": 2,
      "name": "Plant_Coral_Block_Blue"
    },
    {
      "x": 1,
      "y": 6,
      "z": 2,
      "name": "Plant_Coral_Block_Blue"
    },
    {
      "x": 1,
      "y": 7,
      "z": 2,
      "name": "Plant_Coral_Block_Blue"
    },
    {
      "x": 1,
      "y": 8,
      "z": 2,
      "name": "Plant_Coral_Block_Blue"
    },
    {
      "x": 1,
      "y": 9,
      "z": 2,
      "name": "Plant_Coral_Block_Blue"
    },
    {
      "x": 1,
      "y": 0,
      "z": 3,
      "name": "Plant_Coral_Block_Blue"
    },
    {
      "x": 1,
      "y": 1,
      "z": 3,
      "name": "Plant_Coral_Block_Blue"
    },
    {
      "x": 1,
      "y": 2,
      "z": 3,
      "name": "Plant_Coral_Block_Blue"
    },
    {
      "x": 1,
      "y": 3,
      "z": 3,
      "name": "Plant_Coral_Block_Blue"
    },
    {
      "x": 1,
      "y": 4,
      "z": 3,
      "name": "Plant_Coral_Block_Blue"
    },
    {
      "x": 1,
      "y": 5,
      "z": 3,
      "name": "Plant_Coral_Block_Blue"
    },
    {
      "x": 1,
      "y": 6,
      "z": 3,
      "name": "Plant_Coral_Block_Blue"
    },
    {
      "x": 1,
      "y": 7,
      "z": 3,
      "name": "Plant_Coral_Block_Blue"
    },
    {
      "x": 1,
      "y": 8,
      "z": 3,
      "name": "Plant_Coral_Block_Blue"
    },
    {
      "x": 1,
      "y": 9,
      "z": 3,
      "name": "Plant_Coral_Block_Blue"
    },
    {
      "x": 1,
      "y": 0,
      "z": 4,
      "name": "Plant_Coral_Block_Blue"
    },
    {
      "x": 1,
      "y": 1,
      "z": 4,
      "name": "Plant_Coral_Block_Blue"
    },
    {
      "x": 1,
      "y": 2,
      "z": 4,
      "name": "Plant_Coral_Block_Blue"
    },
    {
      "x": 1,
      "y": 3,
      "z": 4,
      "name": "Plant_Coral_Block_Blue"
    },
    {
      "x": 1,
      "y": 4,
      "z": 4,
      "name": "Plant_Coral_Block_Blue"
    },
    {
      "x": 1,
      "y": 5,
      "z": 4,
      "name": "Plant_Coral_Block_Blue"
    },
    {
      "x": 1,
      "y": 6,
      "z": 4,
      "name": "Plant_Coral_Block_Blue"
    },
    {
      "x": 1,
      "y": 7,
      "z": 4,
      "name": "Plant_Coral_Block_Blue"
    },
    {
      "x": 1,
      "y": 8,
      "z": 4,
      "name": "Plant_Coral_Block_Blue"
    },
    {
      "x": 1,
      "y": 9,
      "z": 4,
      "name": "Plant_Coral_Block_Blue"
    },
    {
      "x": 1,
      "y": 0,
      "z": 5,
      "name": "Plant_Coral_Block_Blue"
    },
    {
      "x": 1,
      "y": 1,
      "z": 5,
      "name": "Plant_Coral_Block_Blue"
    },
    {
      "x": 1,
      "y": 2,
      "z": 5,
      "name": "Plant_Coral_Block_Blue"
    },
    {
      "x": 1,
      "y": 3,
      "z": 5,
      "name": "Plant_Coral_Block_Orange"
    },
    {
      "x": 1,
      "y": 4,
      "z": 5,
      "name": "Plant_Coral_Block_Orange"
    },
    {
      "x": 1,
      "y": 5,
      "z": 5,
      "name": "Plant_Coral_Block_Orange"
    },
    {
      "x": 1,
      "y": 6,
      "z": 5,
      "name": "Plant_Coral_Block_Blue"
    },
    {
      "x": 1,
      "y": 7,
      "z": 5,
      "name": "Plant_Coral_Block_Blue"
    },
    {
      "x": 1,
      "y": 8,
      "z": 5,
      "name": "Plant_Coral_Block_Blue"
    },
    {
      "x": 1,
      "y": 9,
      "z": 5,
      "name": "Plant_Coral_Block_Blue"
    },
    {
      "x": 1,
      "y": 0,
      "z": 6,
      "name": "Plant_Coral_Block_Orange"
    },
    {
      "x": 1,
      "y": 1,
      "z": 6,
      "name": "Plant_Coral_Block_Orange"
    },
    {
      "x": 1,
      "y": 2,
      "z": 6,
      "name": "Plant_Coral_Block_Orange"
    },
    {
      "x": 1,
      "y": 3,
      "z": 6,
      "name": "Plant_Coral_Model_Orange"
    },
    {
      "x": 1,
      "y": 6,
      "z": 6,
      "name": "Plant_Coral_Block_Orange"
    },
    {
      "x": 1,
      "y": 7,
      "z": 6,
      "name": "Plant_Coral_Block_Orange"
    },
    {
      "x": 1,
      "y": 8,
      "z": 6,
      "name": "Plant_Coral_Block_Orange"
    },
    {
      "x": 1,
      "y": 9,
      "z": 6,
      "name": "Plant_Coral_Block_Orange"
    },
    {
      "x": 1,
      "y": 0,
      "z": 7,
      "name": "Plant_Coral_Block_Orange"
    },
    {
      "x": 1,
      "y": 7,
      "z": 7,
      "name": "Plant_Coral_Block_Orange"
    },
    {
      "x": 1,
      "y": 8,
      "z": 7,
      "name": "Plant_Coral_Block_Orange"
    },
    {
      "x": 1,
      "y": 9,
      "z": 7,
      "name": "Plant_Coral_Block_Orange"
    },
    {
      "x": 2,
      "y": 0,
      "z": -6,
      "name": "Plant_Coral_Block_Orange"
    },
    {
      "x": 2,
      "y": 1,
      "z": -6,
      "name": "Plant_Coral_Block_Orange"
    },
    {
      "x": 2,
      "y": 2,
      "z": -6,
      "name": "Plant_Coral_Model_Orange"
    },
    {
      "x": 2,
      "y": 8,
      "z": -6,
      "name": "Plant_Coral_Block_Orange"
    },
    {
      "x": 2,
      "y": 9,
      "z": -6,
      "name": "Plant_Coral_Block_Orange"
    },
    {
      "x": 2,
      "y": 0,
      "z": -5,
      "name": "Plant_Coral_Block_Orange"
    },
    {
      "x": 2,
      "y": 1,
      "z": -5,
      "name": "Plant_Coral_Block_Orange"
    },
    {
      "x": 2,
      "y": 2,
      "z": -5,
      "name": "Plant_Coral_Block_Orange"
    },
    {
      "x": 2,
      "y": 3,
      "z": -5,
      "name": "Plant_Coral_Block_Orange"
    },
    {
      "x": 2,
      "y": 4,
      "z": -5,
      "name": "Plant_Coral_Block_Orange"
    },
    {
      "x": 2,
      "y": 5,
      "z": -5,
      "name": "Plant_Coral_Block_Orange"
    },
    {
      "x": 2,
      "y": 6,
      "z": -5,
      "name": "Plant_Coral_Block_Orange"
    },
    {
      "x": 2,
      "y": 7,
      "z": -5,
      "name": "Plant_Coral_Block_Orange"
    },
    {
      "x": 2,
      "y": 8,
      "z": -5,
      "name": "Plant_Coral_Block_Orange"
    },
    {
      "x": 2,
      "y": 9,
      "z": -5,
      "name": "Plant_Coral_Block_Orange"
    },
    {
      "x": 2,
      "y": 0,
      "z": -4,
      "name": "Plant_Coral_Block_Blue"
    },
    {
      "x": 2,
      "y": 1,
      "z": -4,
      "name": "Plant_Coral_Block_Blue"
    },
    {
      "x": 2,
      "y": 2,
      "z": -4,
      "name": "Plant_Coral_Block_Blue"
    },
    {
      "x": 2,
      "y": 3,
      "z": -4,
      "name": "Plant_Coral_Block_Blue"
    },
    {
      "x": 2,
      "y": 4,
      "z": -4,
      "name": "Plant_Coral_Block_Blue"
    },
    {
      "x": 2,
      "y": 5,
      "z": -4,
      "name": "Plant_Coral_Block_Blue"
    },
    {
      "x": 2,
      "y": 6,
      "z": -4,
      "name": "Plant_Coral_Block_Blue"
    },
    {
      "x": 2,
      "y": 7,
      "z": -4,
      "name": "Plant_Coral_Block_Blue"
    },
    {
      "x": 2,
      "y": 8,
      "z": -4,
      "name": "Plant_Coral_Block_Blue"
    },
    {
      "x": 2,
      "y": 9,
      "z": -4,
      "name": "Plant_Coral_Block_Blue"
    },
    {
      "x": 2,
      "y": 0,
      "z": -3,
      "name": "Plant_Coral_Block_Blue"
    },
    {
      "x": 2,
      "y": 1,
      "z": -3,
      "name": "Plant_Coral_Block_Blue"
    },
    {
      "x": 2,
      "y": 2,
      "z": -3,
      "name": "Plant_Coral_Block_Blue"
    },
    {
      "x": 2,
      "y": 3,
      "z": -3,
      "name": "Plant_Coral_Block_Blue"
    },
    {
      "x": 2,
      "y": 4,
      "z": -3,
      "name": "Plant_Coral_Block_Blue"
    },
    {
      "x": 2,
      "y": 5,
      "z": -3,
      "name": "Plant_Coral_Block_Blue"
    },
    {
      "x": 2,
      "y": 6,
      "z": -3,
      "name": "Plant_Coral_Block_Blue"
    },
    {
      "x": 2,
      "y": 7,
      "z": -3,
      "name": "Plant_Coral_Block_Blue"
    },
    {
      "x": 2,
      "y": 8,
      "z": -3,
      "name": "Plant_Coral_Block_Blue"
    },
    {
      "x": 2,
      "y": 9,
      "z": -3,
      "name": "Plant_Coral_Block_Blue"
    },
    {
      "x": 2,
      "y": 0,
      "z": -2,
      "name": "Plant_Coral_Block_Blue"
    },
    {
      "x": 2,
      "y": 1,
      "z": -2,
      "name": "Plant_Coral_Block_Blue"
    },
    {
      "x": 2,
      "y": 2,
      "z": -2,
      "name": "Plant_Coral_Block_Blue"
    },
    {
      "x": 2,
      "y": 3,
      "z": -2,
      "name": "Plant_Coral_Block_Blue"
    },
    {
      "x": 2,
      "y": 4,
      "z": -2,
      "name": "Plant_Coral_Block_Blue"
    },
    {
      "x": 2,
      "y": 5,
      "z": -2,
      "name": "Plant_Coral_Block_Blue"
    },
    {
      "x": 2,
      "y": 6,
      "z": -2,
      "name": "Plant_Coral_Block_Blue"
    },
    {
      "x": 2,
      "y": 7,
      "z": -2,
      "name": "Plant_Coral_Block_Blue"
    },
    {
      "x": 2,
      "y": 8,
      "z": -2,
      "name": "Plant_Coral_Block_Blue"
    },
    {
      "x": 2,
      "y": 9,
      "z": -2,
      "name": "Plant_Coral_Block_Blue"
    },
    {
      "x": 2,
      "y": 0,
      "z": -1,
      "name": "Plant_Coral_Block_Blue"
    },
    {
      "x": 2,
      "y": 1,
      "z": -1,
      "name": "Plant_Coral_Block_Blue"
    },
    {
      "x": 2,
      "y": 2,
      "z": -1,
      "name": "Plant_Coral_Block_Blue"
    },
    {
      "x": 2,
      "y": 3,
      "z": -1,
      "name": "Plant_Coral_Block_Blue"
    },
    {
      "x": 2,
      "y": 4,
      "z": -1,
      "name": "Plant_Coral_Block_Blue"
    },
    {
      "x": 2,
      "y": 5,
      "z": -1,
      "name": "Plant_Coral_Block_Blue"
    },
    {
      "x": 2,
      "y": 6,
      "z": -1,
      "name": "Plant_Coral_Block_Blue"
    },
    {
      "x": 2,
      "y": 7,
      "z": -1,
      "name": "Plant_Coral_Block_Blue"
    },
    {
      "x": 2,
      "y": 8,
      "z": -1,
      "name": "Plant_Coral_Block_Blue"
    },
    {
      "x": 2,
      "y": 9,
      "z": -1,
      "name": "Plant_Coral_Block_Blue"
    },
    {
      "x": 2,
      "y": 0,
      "z": 0,
      "name": "Plant_Coral_Block_Blue"
    },
    {
      "x": 2,
      "y": 1,
      "z": 0,
      "name": "Plant_Coral_Block_Blue"
    },
    {
      "x": 2,
      "y": 2,
      "z": 0,
      "name": "Plant_Coral_Block_Blue"
    },
    {
      "x": 2,
      "y": 3,
      "z": 0,
      "name": "Plant_Coral_Block_Blue"
    },
    {
      "x": 2,
      "y": 4,
      "z": 0,
      "name": "Plant_Coral_Block_Blue"
    },
    {
      "x": 2,
      "y": 5,
      "z": 0,
      "name": "Plant_Coral_Block_Blue"
    },
    {
      "x": 2,
      "y": 6,
      "z": 0,
      "name": "Plant_Coral_Block_Blue"
    },
    {
      "x": 2,
      "y": 7,
      "z": 0,
      "name": "Plant_Coral_Block_Blue"
    },
    {
      "x": 2,
      "y": 8,
      "z": 0,
      "name": "Plant_Coral_Block_Blue"
    },
    {
      "x": 2,
      "y": 9,
      "z": 0,
      "name": "Plant_Coral_Block_Blue"
    },
    {
      "x": 2,
      "y": 0,
      "z": 1,
      "name": "Plant_Coral_Block_Blue"
    },
    {
      "x": 2,
      "y": 1,
      "z": 1,
      "name": "Plant_Coral_Block_Blue"
    },
    {
      "x": 2,
      "y": 2,
      "z": 1,
      "name": "Plant_Coral_Block_Blue"
    },
    {
      "x": 2,
      "y": 3,
      "z": 1,
      "name": "Plant_Coral_Block_Blue"
    },
    {
      "x": 2,
      "y": 4,
      "z": 1,
      "name": "Plant_Coral_Block_Blue"
    },
    {
      "x": 2,
      "y": 5,
      "z": 1,
      "name": "Plant_Coral_Block_Blue"
    },
    {
      "x": 2,
      "y": 6,
      "z": 1,
      "name": "Plant_Coral_Block_Blue"
    },
    {
      "x": 2,
      "y": 7,
      "z": 1,
      "name": "Plant_Coral_Block_Blue"
    },
    {
      "x": 2,
      "y": 8,
      "z": 1,
      "name": "Plant_Coral_Block_Blue"
    },
    {
      "x": 2,
      "y": 9,
      "z": 1,
      "name": "Plant_Coral_Block_Blue"
    },
    {
      "x": 2,
      "y": 0,
      "z": 2,
      "name": "Plant_Coral_Block_Blue"
    },
    {
      "x": 2,
      "y": 1,
      "z": 2,
      "name": "Plant_Coral_Block_Blue"
    },
    {
      "x": 2,
      "y": 2,
      "z": 2,
      "name": "Plant_Coral_Block_Blue"
    },
    {
      "x": 2,
      "y": 3,
      "z": 2,
      "name": "Plant_Coral_Block_Blue"
    },
    {
      "x": 2,
      "y": 4,
      "z": 2,
      "name": "Plant_Coral_Block_Blue"
    },
    {
      "x": 2,
      "y": 5,
      "z": 2,
      "name": "Plant_Coral_Block_Blue"
    },
    {
      "x": 2,
      "y": 6,
      "z": 2,
      "name": "Plant_Coral_Block_Blue"
    },
    {
      "x": 2,
      "y": 7,
      "z": 2,
      "name": "Plant_Coral_Block_Blue"
    },
    {
      "x": 2,
      "y": 8,
      "z": 2,
      "name": "Plant_Coral_Block_Blue"
    },
    {
      "x": 2,
      "y": 9,
      "z": 2,
      "name": "Plant_Coral_Block_Blue"
    },
    {
      "x": 2,
      "y": 0,
      "z": 3,
      "name": "Plant_Coral_Block_Blue"
    },
    {
      "x": 2,
      "y": 1,
      "z": 3,
      "name": "Plant_Coral_Block_Blue"
    },
    {
      "x": 2,
      "y": 2,
      "z": 3,
      "name": "Plant_Coral_Block_Blue"
    },
    {
      "x": 2,
      "y": 3,
      "z": 3,
      "name": "Plant_Coral_Block_Blue"
    },
    {
      "x": 2,
      "y": 4,
      "z": 3,
      "name": "Plant_Coral_Block_Blue"
    },
    {
      "x": 2,
      "y": 5,
      "z": 3,
      "name": "Plant_Coral_Block_Blue"
    },
    {
      "x": 2,
      "y": 6,
      "z": 3,
      "name": "Plant_Coral_Block_Blue"
    },
    {
      "x": 2,
      "y": 7,
      "z": 3,
      "name": "Plant_Coral_Block_Blue"
    },
    {
      "x": 2,
      "y": 8,
      "z": 3,
      "name": "Plant_Coral_Block_Blue"
    },
    {
      "x": 2,
      "y": 9,
      "z": 3,
      "name": "Plant_Coral_Block_Blue"
    },
    {
      "x": 2,
      "y": 0,
      "z": 4,
      "name": "Plant_Coral_Block_Blue"
    },
    {
      "x": 2,
      "y": 1,
      "z": 4,
      "name": "Plant_Coral_Block_Blue"
    },
    {
      "x": 2,
      "y": 2,
      "z": 4,
      "name": "Plant_Coral_Block_Blue"
    },
    {
      "x": 2,
      "y": 3,
      "z": 4,
      "name": "Plant_Coral_Block_Blue"
    },
    {
      "x": 2,
      "y": 4,
      "z": 4,
      "name": "Plant_Coral_Block_Blue"
    },
    {
      "x": 2,
      "y": 5,
      "z": 4,
      "name": "Plant_Coral_Block_Blue"
    },
    {
      "x": 2,
      "y": 6,
      "z": 4,
      "name": "Plant_Coral_Block_Blue"
    },
    {
      "x": 2,
      "y": 7,
      "z": 4,
      "name": "Plant_Coral_Block_Blue"
    },
    {
      "x": 2,
      "y": 8,
      "z": 4,
      "name": "Plant_Coral_Block_Blue"
    },
    {
      "x": 2,
      "y": 9,
      "z": 4,
      "name": "Plant_Coral_Block_Blue"
    },
    {
      "x": 2,
      "y": 0,
      "z": 5,
      "name": "Plant_Coral_Block_Orange"
    },
    {
      "x": 2,
      "y": 1,
      "z": 5,
      "name": "Plant_Coral_Block_Orange"
    },
    {
      "x": 2,
      "y": 2,
      "z": 5,
      "name": "Plant_Coral_Block_Orange"
    },
    {
      "x": 2,
      "y": 3,
      "z": 5,
      "name": "Plant_Coral_Block_Orange"
    },
    {
      "x": 2,
      "y": 4,
      "z": 5,
      "name": "Plant_Coral_Block_Orange"
    },
    {
      "x": 2,
      "y": 5,
      "z": 5,
      "name": "Plant_Coral_Block_Orange"
    },
    {
      "x": 2,
      "y": 6,
      "z": 5,
      "name": "Plant_Coral_Block_Orange"
    },
    {
      "x": 2,
      "y": 7,
      "z": 5,
      "name": "Plant_Coral_Block_Orange"
    },
    {
      "x": 2,
      "y": 8,
      "z": 5,
      "name": "Plant_Coral_Block_Orange"
    },
    {
      "x": 2,
      "y": 9,
      "z": 5,
      "name": "Plant_Coral_Block_Orange"
    },
    {
      "x": 2,
      "y": 0,
      "z": 6,
      "name": "Plant_Coral_Block_Orange"
    },
    {
      "x": 2,
      "y": 1,
      "z": 6,
      "name": "Plant_Coral_Block_Orange"
    },
    {
      "x": 2,
      "y": 6,
      "z": 6,
      "name": "Plant_Coral_Bush_Orange"
    },
    {
      "x": 2,
      "y": 7,
      "z": 6,
      "name": "Plant_Coral_Block_Orange"
    },
    {
      "x": 2,
      "y": 8,
      "z": 6,
      "name": "Plant_Coral_Block_Orange"
    },
    {
      "x": 2,
      "y": 9,
      "z": 6,
      "name": "Plant_Coral_Block_Orange"
    },
    {
      "x": 2,
      "y": 1,
      "z": 7,
      "name": "Plant_Coral_Bush_Orange"
    },
    {
      "x": 3,
      "y": 0,
      "z": -6,
      "name": "Plant_Coral_Block_Orange"
    },
    {
      "x": 3,
      "y": 9,
      "z": -6,
      "name": "Plant_Coral_Block_Orange"
    },
    {
      "x": 3,
      "y": 0,
      "z": -5,
      "name": "Plant_Coral_Block_Orange"
    },
    {
      "x": 3,
      "y": 1,
      "z": -5,
      "name": "Plant_Coral_Block_Orange"
    },
    {
      "x": 3,
      "y": 2,
      "z": -5,
      "name": "Plant_Coral_Block_Orange"
    },
    {
      "x": 3,
      "y": 3,
      "z": -5,
      "name": "Plant_Coral_Bush_Orange"
    },
    {
      "x": 3,
      "y": 7,
      "z": -5,
      "name": "Plant_Coral_Block_Orange"
    },
    {
      "x": 3,
      "y": 8,
      "z": -5,
      "name": "Plant_Coral_Block_Orange"
    },
    {
      "x": 3,
      "y": 9,
      "z": -5,
      "name": "Plant_Coral_Block_Orange"
    },
    {
      "x": 3,
      "y": 0,
      "z": -4,
      "name": "Plant_Coral_Block_Blue"
    },
    {
      "x": 3,
      "y": 1,
      "z": -4,
      "name": "Plant_Coral_Block_Blue"
    },
    {
      "x": 3,
      "y": 2,
      "z": -4,
      "name": "Plant_Coral_Block_Blue"
    },
    {
      "x": 3,
      "y": 3,
      "z": -4,
      "name": "Plant_Coral_Block_Orange"
    },
    {
      "x": 3,
      "y": 4,
      "z": -4,
      "name": "Plant_Coral_Block_Orange"
    },
    {
      "x": 3,
      "y": 5,
      "z": -4,
      "name": "Plant_Coral_Block_Orange"
    },
    {
      "x": 3,
      "y": 6,
      "z": -4,
      "name": "Plant_Coral_Block_Orange"
    },
    {
      "x": 3,
      "y": 7,
      "z": -4,
      "name": "Plant_Coral_Block_Orange"
    },
    {
      "x": 3,
      "y": 8,
      "z": -4,
      "name": "Plant_Coral_Block_Blue"
    },
    {
      "x": 3,
      "y": 9,
      "z": -4,
      "name": "Plant_Coral_Block_Blue"
    },
    {
      "x": 3,
      "y": 0,
      "z": -3,
      "name": "Plant_Coral_Block_Blue"
    },
    {
      "x": 3,
      "y": 1,
      "z": -3,
      "name": "Plant_Coral_Block_Blue"
    },
    {
      "x": 3,
      "y": 2,
      "z": -3,
      "name": "Plant_Coral_Block_Blue"
    },
    {
      "x": 3,
      "y": 3,
      "z": -3,
      "name": "Plant_Coral_Block_Orange"
    },
    {
      "x": 3,
      "y": 4,
      "z": -3,
      "name": "Plant_Coral_Block_Blue"
    },
    {
      "x": 3,
      "y": 5,
      "z": -3,
      "name": "Plant_Coral_Block_Blue"
    },
    {
      "x": 3,
      "y": 6,
      "z": -3,
      "name": "Plant_Coral_Block_Blue"
    },
    {
      "x": 3,
      "y": 7,
      "z": -3,
      "name": "Plant_Coral_Block_Blue"
    },
    {
      "x": 3,
      "y": 8,
      "z": -3,
      "name": "Plant_Coral_Block_Blue"
    },
    {
      "x": 3,
      "y": 9,
      "z": -3,
      "name": "Plant_Coral_Block_Blue"
    },
    {
      "x": 3,
      "y": 0,
      "z": -2,
      "name": "Plant_Coral_Block_Blue"
    },
    {
      "x": 3,
      "y": 1,
      "z": -2,
      "name": "Plant_Coral_Block_Blue"
    },
    {
      "x": 3,
      "y": 2,
      "z": -2,
      "name": "Plant_Coral_Block_Blue"
    },
    {
      "x": 3,
      "y": 3,
      "z": -2,
      "name": "Plant_Coral_Block_Blue"
    },
    {
      "x": 3,
      "y": 4,
      "z": -2,
      "name": "Plant_Coral_Block_Blue"
    },
    {
      "x": 3,
      "y": 5,
      "z": -2,
      "name": "Plant_Coral_Block_Blue"
    },
    {
      "x": 3,
      "y": 6,
      "z": -2,
      "name": "Plant_Coral_Block_Blue"
    },
    {
      "x": 3,
      "y": 7,
      "z": -2,
      "name": "Plant_Coral_Block_Blue"
    },
    {
      "x": 3,
      "y": 8,
      "z": -2,
      "name": "Plant_Coral_Block_Blue"
    },
    {
      "x": 3,
      "y": 9,
      "z": -2,
      "name": "Plant_Coral_Block_Blue"
    },
    {
      "x": 3,
      "y": 0,
      "z": -1,
      "name": "Plant_Coral_Block_Blue"
    },
    {
      "x": 3,
      "y": 1,
      "z": -1,
      "name": "Plant_Coral_Block_Blue"
    },
    {
      "x": 3,
      "y": 2,
      "z": -1,
      "name": "Plant_Coral_Block_Blue"
    },
    {
      "x": 3,
      "y": 3,
      "z": -1,
      "name": "Plant_Coral_Block_Blue"
    },
    {
      "x": 3,
      "y": 4,
      "z": -1,
      "name": "Plant_Coral_Block_Blue"
    },
    {
      "x": 3,
      "y": 5,
      "z": -1,
      "name": "Plant_Coral_Block_Blue"
    },
    {
      "x": 3,
      "y": 6,
      "z": -1,
      "name": "Plant_Coral_Block_Blue"
    },
    {
      "x": 3,
      "y": 7,
      "z": -1,
      "name": "Plant_Coral_Block_Blue"
    },
    {
      "x": 3,
      "y": 8,
      "z": -1,
      "name": "Plant_Coral_Block_Blue"
    },
    {
      "x": 3,
      "y": 9,
      "z": -1,
      "name": "Plant_Coral_Block_Blue"
    },
    {
      "x": 3,
      "y": 0,
      "z": 0,
      "name": "Plant_Coral_Block_Blue"
    },
    {
      "x": 3,
      "y": 1,
      "z": 0,
      "name": "Plant_Coral_Block_Blue"
    },
    {
      "x": 3,
      "y": 2,
      "z": 0,
      "name": "Plant_Coral_Block_Blue"
    },
    {
      "x": 3,
      "y": 3,
      "z": 0,
      "name": "Plant_Coral_Block_Blue"
    },
    {
      "x": 3,
      "y": 4,
      "z": 0,
      "name": "Plant_Coral_Block_Blue"
    },
    {
      "x": 3,
      "y": 5,
      "z": 0,
      "name": "Plant_Coral_Block_Blue"
    },
    {
      "x": 3,
      "y": 6,
      "z": 0,
      "name": "Plant_Coral_Block_Blue"
    },
    {
      "x": 3,
      "y": 7,
      "z": 0,
      "name": "Plant_Coral_Block_Blue"
    },
    {
      "x": 3,
      "y": 8,
      "z": 0,
      "name": "Plant_Coral_Block_Blue"
    },
    {
      "x": 3,
      "y": 9,
      "z": 0,
      "name": "Plant_Coral_Block_Blue"
    },
    {
      "x": 3,
      "y": 0,
      "z": 1,
      "name": "Plant_Coral_Block_Blue"
    },
    {
      "x": 3,
      "y": 1,
      "z": 1,
      "name": "Plant_Coral_Block_Blue"
    },
    {
      "x": 3,
      "y": 2,
      "z": 1,
      "name": "Plant_Coral_Block_Blue"
    },
    {
      "x": 3,
      "y": 3,
      "z": 1,
      "name": "Plant_Coral_Block_Blue"
    },
    {
      "x": 3,
      "y": 4,
      "z": 1,
      "name": "Plant_Coral_Block_Blue"
    },
    {
      "x": 3,
      "y": 5,
      "z": 1,
      "name": "Plant_Coral_Block_Blue"
    },
    {
      "x": 3,
      "y": 6,
      "z": 1,
      "name": "Plant_Coral_Block_Blue"
    },
    {
      "x": 3,
      "y": 7,
      "z": 1,
      "name": "Plant_Coral_Block_Blue"
    },
    {
      "x": 3,
      "y": 8,
      "z": 1,
      "name": "Plant_Coral_Block_Blue"
    },
    {
      "x": 3,
      "y": 9,
      "z": 1,
      "name": "Plant_Coral_Block_Blue"
    },
    {
      "x": 3,
      "y": 0,
      "z": 2,
      "name": "Plant_Coral_Block_Blue"
    },
    {
      "x": 3,
      "y": 1,
      "z": 2,
      "name": "Plant_Coral_Block_Blue"
    },
    {
      "x": 3,
      "y": 2,
      "z": 2,
      "name": "Plant_Coral_Block_Blue"
    },
    {
      "x": 3,
      "y": 3,
      "z": 2,
      "name": "Plant_Coral_Block_Blue"
    },
    {
      "x": 3,
      "y": 4,
      "z": 2,
      "name": "Plant_Coral_Block_Blue"
    },
    {
      "x": 3,
      "y": 5,
      "z": 2,
      "name": "Plant_Coral_Block_Blue"
    },
    {
      "x": 3,
      "y": 6,
      "z": 2,
      "name": "Plant_Coral_Block_Blue"
    },
    {
      "x": 3,
      "y": 7,
      "z": 2,
      "name": "Plant_Coral_Block_Blue"
    },
    {
      "x": 3,
      "y": 8,
      "z": 2,
      "name": "Plant_Coral_Block_Blue"
    },
    {
      "x": 3,
      "y": 9,
      "z": 2,
      "name": "Plant_Coral_Block_Blue"
    },
    {
      "x": 3,
      "y": 0,
      "z": 3,
      "name": "Plant_Coral_Block_Blue"
    },
    {
      "x": 3,
      "y": 1,
      "z": 3,
      "name": "Plant_Coral_Block_Blue"
    },
    {
      "x": 3,
      "y": 2,
      "z": 3,
      "name": "Plant_Coral_Block_Blue"
    },
    {
      "x": 3,
      "y": 3,
      "z": 3,
      "name": "Plant_Coral_Block_Blue"
    },
    {
      "x": 3,
      "y": 4,
      "z": 3,
      "name": "Plant_Coral_Block_Blue"
    },
    {
      "x": 3,
      "y": 5,
      "z": 3,
      "name": "Plant_Coral_Block_Blue"
    },
    {
      "x": 3,
      "y": 6,
      "z": 3,
      "name": "Plant_Coral_Block_Blue"
    },
    {
      "x": 3,
      "y": 7,
      "z": 3,
      "name": "Plant_Coral_Block_Blue"
    },
    {
      "x": 3,
      "y": 8,
      "z": 3,
      "name": "Plant_Coral_Block_Blue"
    },
    {
      "x": 3,
      "y": 9,
      "z": 3,
      "name": "Plant_Coral_Block_Blue"
    },
    {
      "x": 3,
      "y": 0,
      "z": 4,
      "name": "Plant_Coral_Block_Blue"
    },
    {
      "x": 3,
      "y": 1,
      "z": 4,
      "name": "Plant_Coral_Block_Blue"
    },
    {
      "x": 3,
      "y": 2,
      "z": 4,
      "name": "Plant_Coral_Block_Blue"
    },
    {
      "x": 3,
      "y": 3,
      "z": 4,
      "name": "Plant_Coral_Block_Orange"
    },
    {
      "x": 3,
      "y": 4,
      "z": 4,
      "name": "Plant_Coral_Block_Orange"
    },
    {
      "x": 3,
      "y": 5,
      "z": 4,
      "name": "Plant_Coral_Block_Orange"
    },
    {
      "x": 3,
      "y": 6,
      "z": 4,
      "name": "Plant_Coral_Block_Orange"
    },
    {
      "x": 3,
      "y": 7,
      "z": 4,
      "name": "Plant_Coral_Block_Orange"
    },
    {
      "x": 3,
      "y": 8,
      "z": 4,
      "name": "Plant_Coral_Block_Blue"
    },
    {
      "x": 3,
      "y": 9,
      "z": 4,
      "name": "Plant_Coral_Block_Blue"
    },
    {
      "x": 3,
      "y": 0,
      "z": 5,
      "name": "Plant_Coral_Block_Orange"
    },
    {
      "x": 3,
      "y": 1,
      "z": 5,
      "name": "Plant_Coral_Block_Orange"
    },
    {
      "x": 3,
      "y": 2,
      "z": 5,
      "name": "Plant_Coral_Block_Orange"
    },
    {
      "x": 3,
      "y": 7,
      "z": 5,
      "name": "Plant_Coral_Block_Orange"
    },
    {
      "x": 3,
      "y": 8,
      "z": 5,
      "name": "Plant_Coral_Block_Orange"
    },
    {
      "x": 3,
      "y": 9,
      "z": 5,
      "name": "Plant_Coral_Block_Orange"
    },
    {
      "x": 4,
      "y": 0,
      "z": -5,
      "name": "Plant_Coral_Block_Orange"
    },
    {
      "x": 4,
      "y": 2,
      "z": -5,
      "name": "Plant_Coral_Bush_Orange"
    },
    {
      "x": 4,
      "y": 0,
      "z": -4,
      "name": "Plant_Coral_Block_Orange"
    },
    {
      "x": 4,
      "y": 1,
      "z": -4,
      "name": "Plant_Coral_Block_Orange"
    },
    {
      "x": 4,
      "y": 2,
      "z": -4,
      "name": "Plant_Coral_Block_Orange"
    },
