{
  "version": 8,
  "blockIdVersion": 11,
  "anchorX": 0,
  "anchorY": 0,
  "anchorZ": 0,
  "blocks": [
    {
      "x": -1,
      "y": -1,
      "z": -1,
      "name": "Plant_Coral_Bush_Orange"
    },
    {
      "x": -1,
      "y": 0,
      "z": -1,
      "name": "Rock_Crystal_Orange_Small"
    },
    {
      "x": -1,
      "y": -1,
      "z": 0,
      "name": "Plant_Coral_Bush_Orange"
    },
    {
      "x": -1,
      "y": 0,
      "z": 0,
      "name": "Plant_Coral_Bush_Orange"
    },
    {
      "x": -1,
      "y": -1,
      "z": 1,
      "name": "Plant_Coral_Bush_Yellow"
    },
    {
      "x": -1,
      "y": 0,
      "z": 1,
      "name": "Plant_Flower_Orchid_Orange"
    },
    {
      "x": 0,
      "y": -1,
      "z": -1,
      "name": "Plant_Coral_Bush_Orange"
    },
    {
      "x": 0,
      "y": 0,
      "z": -1,
      "name": "Plant_Flower_Flax_Orange"
    },
    {
      "x": 0,
      "y": -1,
      "z": 0,
      "name": "Plant_Coral_Bush_Yellow"
    },
    {
      "x": 0,
      "y": 0,
      "z": 0,
      "name": "Plant_Coral_Bush_Yellow"
    },
    {
      "x": 0,
      "y": 1,
      "z": 0,
      "name": "Plant_Coral_Bush_Orange"
    },
    {
      "x": 0,
      "y": -1,
      "z": 1,
      "name": "Plant_Coral_Bush_Orange"
    },
    {
      "x": 0,
      "y": 0,
      "z": 1,
      "name": "Plant_Coral_Bush_Yellow"
    },
    {
      "x": 0,
      "y": 1,
      "z": 1,
      "name": "Plant_Coral_Bush_Orange"
    },
    {
      "x": 1,
      "y": -1,
      "z": 0,
      "name": "Plant_Coral_Bush_Yellow"
    },
    {
      "x": 1,
      "y": 0,
      "z": 0,
      "name": "Plant_Flower_Common_Orange"
    },
    {
      "x": 1,
      "y": -1,
      "z": 1,
      "name": "Plant_Coral_Bush_Orange"
    },
    {
      "x": 1,
      "y": 0,
      "z": 1,
      "name": "Plant_Coral_Bush_Orange"
    }
  ],
  "fluids": [
    {
      "x": -1,
      "y": -1,
      "z": -1,
      "name": "Water_Source",
      "level": 1
    },
    {
      "x": -1,
      "y": 0,
      "z": -1,
      "name": "Water_Source",
      "level": 1
    },
    {
      "x": -1,
      "y": 1,
      "z": -1,
      "name": "Water_Source",
      "level": 1
    },
    {
      "x": -1,
      "y": -1,
      "z": 0,
      "name": "Water_Source",
      "level": 1
    },
    {
      "x": -1,
      "y": 0,
      "z": 0,
      "name": "Water_Source",
      "level": 1
    },
    {
      "x": -1,
      "y": 1,
      "z": 0,
      "name": "Water_Source",
      "level": 1
    },
    {
      "x": -1,
      "y": -1,
      "z": 1,
      "name": "Water_Source",
      "level": 1
    },
    {
      "x": -1,
      "y": 0,
      "z": 1,
      "name": "Water_Source",
      "level": 1
    },
    {
      "x": -1,
      "y": 1,
      "z": 1,
      "name": "Water_Source",
      "level": 1
    },
    {
      "x": 0,
      "y": -1,
      "z": -1,
      "name": "Water_Source",
      "level": 1
    },
    {
      "x": 0,
      "y": 0,
      "z": -1,
      "name": "Water_Source",
      "level": 1
    },
    {
      "x": 0,
      "y": 1,
      "z": -1,
      "name": "Water_Source",
      "level": 1
    },
    {
      "x": 0,
      "y": -1,
      "z": 0,
      "name": "Water_Source",
      "level": 1
    },
    {
      "x": 0,
      "y": 0,
      "z": 0,
      "name": "Water_Source",
      "level": 1
    },
    {
      "x": 0,
      "y": 1,
      "z": 0,
      "name": "Water_Source",
      "level": 1
    },
    {
      "x": 0,
      "y": -1,
      "z": 1,
      "name": "Water_Source",
      "level": 1
    },
    {
      "x": 0,
      "y": 0,
      "z": 1,
      "name": "Water_Source",
      "level": 1
    },
    {
      "x": 0,
      "y": 1,
      "z": 1,
      "name": "Water_Source",
      "level": 1
    },
    {
      "x": 1,
      "y": 0,
      "z": -1,
      "name": "Water_Source",
      "level": 1
    },
    {
      "x": 1,
      "y": 1,
      "z": -1,
      "name": "Water_Source",
      "level": 1
    },
    {
      "x": 1,
      "y": -1,
      "z": 0,
      "name": "Water_Source",
      "level": 1
    },
    {
      "x": 1,
      "y": 0,
      "z": 0,
      "name": "Water_Source",
      "level": 1
    },
    {
      "x": 1,
      "y": 1,
      "z": 0,
      "name": "Water_Source",
      "level": 1
    },
    {
      "x": 1,
      "y": -1,
      "z": 1,
      "name": "Water_Source",
      "level": 1
    },
    {
      "x": 1,
      "y": 0,
      "z": 1,
      "name": "Water_Source",
      "level": 1
    },
    {
      "x": 1,
      "y": 1,
      "z": 1,
      "name": "Water_Source",
      "level": 1
    }
  ]
}