{
  "version": 8,
  "blockIdVersion": 11,
  "anchorX": 0,
  "anchorY": 0,
  "anchorZ": 0,
  "blocks": [
    {
      "x": -2,
      "y": -1,
      "z": -1,
      "name": "Plant_Coral_Bush_Orange"
    },
    {
      "x": -2,
      "y": 0,
      "z": -1,
      "name": "Plant_Coral_Model_Yellow"
    },
    {
      "x": -1,
      "y": -1,
      "z": 0,
      "name": "Plant_Coral_Bush_Orange"
    },
    {
      "x": -1,
      "y": 0,
      "z": 0,
      "name": "Plant_Coral_Bush_Yellow"
    },
    {
      "x": 0,
      "y": -1,
      "z": -1,
      "name": "Plant_Coral_Bush_Yellow"
    },
    {
      "x": 0,
      "y": 0,
      "z": -1,
      "name": "Plant_Coral_Bush_Yellow"
    },
    {
      "x": 0,
      "y": -1,
      "z": 0,
      "name": "Plant_Coral_Bush_Yellow"
    },
    {
      "x": 0,
      "y": 0,
      "z": 0,
      "name": "Rock_Crystal_Orange_Medium"
    },
    {
      "x": 0,
      "y": -1,
      "z": 1,
      "name": "Plant_Coral_Bush_Yellow"
    },
    {
      "x": 0,
      "y": 0,
      "z": 1,
      "name": "Plant_Coral_Bush_Yellow"
    },
    {
      "x": 1,
      "y": -1,
      "z": 0,
      "name": "Plant_Coral_Bush_Orange"
    },
    {
      "x": 1,
      "y": 0,
      "z": 0,
      "name": "Plant_Coral_Bush_Orange"
    },
    {
      "x": 1,
      "y": -1,
      "z": 1,
      "name": "Plant_Coral_Bush_Orange"
    },
    {
      "x": 1,
      "y": 0,
      "z": 1,
      "name": "Plant_Coral_Bush_Orange"
    },
    {
      "x": 2,
      "y": -1,
      "z": 0,
      "name": "Plant_Coral_Bush_Yellow"
    },
    {
      "x": 2,
      "y": 0,
      "z": 0,
      "name": "Plant_Coral_Model_Yellow"
    }
  ],
  "fluids": [
    {
      "x": -2,
      "y": -1,
      "z": -1,
      "name": "Water_Source",
      "level": 1
    },
    {
      "x": -2,
      "y": 0,
      "z": -1,
      "name": "Water_Source",
      "level": 1
    },
    {
      "x": -2,
      "y": 1,
      "z": -1,
      "name": "Water_Source",
      "level": 1
    },
    {
      "x": -2,
      "y": 0,
      "z": 0,
      "name": "Water_Source",
      "level": 1
    },
    {
      "x": -2,
      "y": 1,
      "z": 0,
      "name": "Water_Source",
      "level": 1
    },
    {
      "x": -2,
      "y": 0,
      "z": 1,
      "name": "Water_Source",
      "level": 1
    },
    {
      "x": -2,
      "y": 1,
      "z": 1,
      "name": "Water_Source",
      "level": 1
    },
    {
      "x": -1,
      "y": 0,
      "z": -1,
      "name": "Water_Source",
      "level": 1
    },
    {
      "x": -1,
      "y": 1,
      "z": -1,
      "name": "Water_Source",
      "level": 1
    },
    {
      "x": -1,
      "y": -1,
      "z": 0,
      "name": "Water_Source",
      "level": 1
    },
    {
      "x": -1,
      "y": 0,
      "z": 0,
      "name": "Water_Source",
      "level": 1
    },
    {
      "x": -1,
      "y": 1,
      "z": 0,
      "name": "Water_Source",
      "level": 1
    },
    {
      "x": -1,
      "y": 0,
      "z": 1,
      "name": "Water_Source",
      "level": 1
    },
    {
      "x": -1,
      "y": 1,
      "z": 1,
      "name": "Water_Source",
      "level": 1
    },
    {
      "x": 0,
      "y": -1,
      "z": -1,
      "name": "Water_Source",
      "level": 1
    },
    {
      "x": 0,
      "y": 0,
      "z": -1,
      "name": "Water_Source",
      "level": 1
    },
    {
      "x": 0,
      "y": 1,
      "z": -1,
      "name": "Water_Source",
      "level": 1
    },
    {
      "x": 0,
      "y": -1,
      "z": 0,
      "name": "Water_Source",
      "level": 1
    },
    {
      "x": 0,
      "y": 0,
      "z": 0,
      "name": "Water_Source",
      "level": 1
    },
    {
      "x": 0,
      "y": 1,
      "z": 0,
      "name": "Water_Source",
      "level": 1
    },
    {
      "x": 0,
      "y": -1,
      "z": 1,
      "name": "Water_Source",
      "level": 1
    },
    {
      "x": 0,
      "y": 0,
      "z": 1,
      "name": "Water_Source",
      "level": 1
    },
    {
      "x": 0,
      "y": 1,
      "z": 1,
      "name": "Water_Source",
      "level": 1
    },
    {
      "x": 1,
      "y": 0,
      "z": -1,
      "name": "Water_Source",
      "level": 1
    },
    {
      "x": 1,
      "y": 1,
      "z": -1,
      "name": "Water_Source",
      "level": 1
    },
    {
      "x": 1,
      "y": -1,
      "z": 0,
      "name": "Water_Source",
      "level": 1
    },
    {
      "x": 1,
      "y": 0,
      "z": 0,
      "name": "Water_Source",
      "level": 1
    },
    {
      "x": 1,
      "y": 1,
      "z": 0,
      "name": "Water_Source",
      "level": 1
    },
    {
      "x": 1,
      "y": -1,
      "z": 1,
      "name": "Water_Source",
      "level": 1
    },
    {
      "x": 1,
      "y": 0,
      "z": 1,
      "name": "Water_Source",
      "level": 1
    },
    {
      "x": 1,
      "y": 1,
      "z": 1,
      "name": "Water_Source",
      "level": 1
    },
    {
      "x": 2,
      "y": 0,
      "z": -1,
      "name": "Water_Source",
      "level": 1
    },
    {
      "x": 2,
      "y": 1,
      "z": -1,
      "name": "Water_Source",
      "level": 1
    },
    {
      "x": 2,
      "y": -1,
      "z": 0,
      "name": "Water_Source",
      "level": 1
    },
    {
      "x": 2,
      "y": 0,
      "z": 0,
      "name": "Water_Source",
      "level": 1
    },
    {
      "x": 2,
      "y": 1,
      "z": 0,
      "name": "Water_Source",
      "level": 1
    },
    {
      "x": 2,
      "y": 0,
      "z": 1,
      "name": "Water_Source",
      "level": 1
    },
    {
      "x": 2,
      "y": 1,
      "z": 1,
      "name": "Water_Source",
      "level": 1
    }
  ]
}