{
  "version": 8,
  "blockIdVersion": 11,
  "anchorX": 0,
  "anchorY": 3,
  "anchorZ": 0,
  "blocks": [
    {
      "x": -6,
      "y": 5,
      "z": 1,
      "name": "Rock_Aqua_Cobble_Half",
      "rotation": 7
    },
    {
      "x": -6,
      "y": 5,
      "z": 2,
      "name": "Rock_Aqua_Cobble_Half",
      "rotation": 7
    },
    {
      "x": -6,
      "y": 6,
      "z": 2,
      "name": "Rock_Aqua_Cobble_Half",
      "rotation": 7
    },
    {
      "x": -6,
      "y": 7,
      "z": 2,
      "name": "Rock_Aqua_Cobble_Half",
      "rotation": 7
    },
    {
      "x": -5,
      "y": 2,
      "z": -2,
      "name": "Rock_Aqua_Cobble"
    },
    {
      "x": -5,
      "y": 3,
      "z": -2,
      "name": "Rock_Aqua_Cobble"
    },
    {
      "x": -5,
      "y": 4,
      "z": -2,
      "name": "Rock_Aqua_Cobble"
    },
    {
      "x": -5,
      "y": 5,
      "z": -2,
      "name": "Rock_Aqua"
    },
    {
      "x": -5,
      "y": 0,
      "z": -1,
      "name": "Rock_Aqua_Cobble"
    },
    {
      "x": -5,
      "y": 1,
      "z": -1,
      "name": "Rock_Aqua_Cobble"
    },
    {
      "x": -5,
      "y": 2,
      "z": -1,
      "name": "Rock_Aqua_Cobble"
    },
    {
      "x": -5,
      "y": 3,
      "z": -1,
      "name": "Rock_Aqua_Cobble"
    },
    {
      "x": -5,
      "y": 4,
      "z": -1,
      "name": "Rock_Aqua_Cobble"
    },
    {
      "x": -5,
      "y": 5,
      "z": -1,
      "name": "Rock_Aqua_Cobble"
    },
    {
      "x": -5,
      "y": 6,
      "z": -1,
      "name": "Rock_Aqua"
    },
    {
      "x": -5,
      "y": 7,
      "z": -1,
      "name": "Rock_Aqua_Cobble"
    },
    {
      "x": -5,
      "y": 0,
      "z": 0,
      "name": "Rock_Aqua_Cobble"
    },
    {
      "x": -5,
      "y": 1,
      "z": 0,
      "name": "Rock_Aqua_Cobble"
    },
    {
      "x": -5,
      "y": 2,
      "z": 0,
      "name": "Rock_Aqua_Cobble"
    },
    {
      "x": -5,
      "y": 3,
      "z": 0,
      "name": "Rock_Aqua_Cobble"
    },
    {
      "x": -5,
      "y": 4,
      "z": 0,
      "name": "Rock_Aqua_Cobble"
    },
    {
      "x": -5,
      "y": 5,
      "z": 0,
      "name": "Rock_Aqua_Cobble"
    },
    {
      "x": -5,
      "y": 6,
      "z": 0,
      "name": "Rock_Aqua_Cobble"
    },
    {
      "x": -5,
      "y": 7,
      "z": 0,
      "name": "Rock_Aqua_Cobble"
    },
    {
      "x": -5,
      "y": 8,
      "z": 0,
      "name": "Rock_Aqua_Cobble"
    },
    {
      "x": -5,
      "y": 0,
      "z": 1,
      "name": "Rock_Aqua_Cobble"
    },
    {
      "x": -5,
      "y": 1,
      "z": 1,
      "name": "Rock_Aqua_Cobble"
    },
    {
      "x": -5,
      "y": 2,
      "z": 1,
      "name": "Rock_Aqua_Cobble"
    },
    {
      "x": -5,
      "y": 3,
      "z": 1,
      "name": "Rock_Aqua_Cobble"
    },
    {
      "x": -5,
      "y": 4,
      "z": 1,
      "name": "Rock_Aqua_Cobble"
    },
    {
      "x": -5,
      "y": 5,
      "z": 1,
      "name": "Rock_Aqua_Cobble"
    },
    {
      "x": -5,
      "y": 6,
      "z": 1,
      "name": "Rock_Aqua_Cobble"
    },
    {
      "x": -5,
      "y": 7,
      "z": 1,
      "name": "Rock_Aqua_Cobble"
    },
    {
      "x": -5,
      "y": 8,
      "z": 1,
      "name": "Rock_Aqua_Cobble"
    },
    {
      "x": -5,
      "y": 9,
      "z": 1,
      "name": "Rock_Aqua_Cobble"
    },
    {
      "x": -5,
      "y": 0,
      "z": 2,
      "name": "Rock_Aqua_Cobble"
    },
    {
      "x": -5,
      "y": 1,
      "z": 2,
      "name": "Rock_Aqua_Cobble"
    },
    {
      "x": -5,
      "y": 2,
      "z": 2,
      "name": "Rock_Aqua_Cobble"
    },
    {
      "x": -5,
      "y": 3,
      "z": 2,
      "name": "Rock_Aqua_Cobble"
    },
    {
      "x": -5,
      "y": 4,
      "z": 2,
      "name": "Rock_Aqua_Cobble"
    },
    {
      "x": -5,
      "y": 5,
      "z": 2,
      "name": "Rock_Aqua_Cobble"
    },
    {
      "x": -5,
      "y": 6,
      "z": 2,
      "name": "Rock_Aqua_Cobble"
    },
    {
      "x": -5,
      "y": 7,
      "z": 2,
      "name": "Rock_Aqua_Cobble"
    },
    {
      "x": -5,
      "y": 8,
      "z": 2,
      "name": "Rock_Aqua_Cobble"
    },
    {
      "x": -5,
      "y": 9,
      "z": 2,
      "name": "Rock_Aqua_Cobble"
    },
    {
      "x": -5,
      "y": 1,
      "z": 3,
      "name": "Rock_Aqua_Cobble"
    },
    {
      "x": -5,
      "y": 2,
      "z": 3,
      "name": "Rock_Aqua_Cobble"
    },
    {
      "x": -5,
      "y": 3,
      "z": 3,
      "name": "Rock_Aqua_Cobble"
    },
    {
      "x": -5,
      "y": 4,
      "z": 3,
      "name": "Rock_Aqua_Cobble"
    },
    {
      "x": -5,
      "y": 5,
      "z": 3,
      "name": "Rock_Aqua_Cobble"
    },
    {
      "x": -5,
      "y": 6,
      "z": 3,
      "name": "Rock_Aqua_Cobble"
    },
    {
      "x": -5,
      "y": 7,
      "z": 3,
      "name": "Rock_Aqua_Cobble"
    },
    {
      "x": -5,
      "y": 8,
      "z": 3,
      "name": "Rock_Aqua_Cobble"
    },
    {
      "x": -5,
      "y": 4,
      "z": 4,
      "name": "Rock_Aqua_Cobble"
    },
    {
      "x": -5,
      "y": 5,
      "z": 4,
      "name": "Rock_Aqua_Cobble"
    },
    {
      "x": -5,
      "y": 6,
      "z": 4,
      "name": "Rock_Aqua_Cobble"
    },
    {
      "x": -5,
      "y": 7,
      "z": 4,
      "name": "Rock_Aqua_Cobble_Half"
    },
    {
      "x": -4,
      "y": 0,
      "z": -3,
      "name": "Rock_Aqua_Cobble"
    },
    {
      "x": -4,
      "y": 1,
      "z": -3,
      "name": "Rock_Aqua_Cobble"
    },
    {
      "x": -4,
      "y": 2,
      "z": -3,
      "name": "Rock_Aqua_Cobble"
    },
    {
      "x": -4,
      "y": 3,
      "z": -3,
      "name": "Rock_Aqua_Cobble"
    },
    {
      "x": -4,
      "y": 4,
      "z": -3,
      "name": "Rock_Aqua"
    },
    {
      "x": -4,
      "y": 5,
      "z": -3,
      "name": "Rock_Aqua"
    },
    {
      "x": -4,
      "y": 6,
      "z": -3,
      "name": "Rock_Aqua"
    },
    {
      "x": -4,
      "y": 7,
      "z": -3,
      "name": "Rock_Aqua"
    },
    {
      "x": -4,
      "y": 0,
      "z": -2,
      "name": "Rock_Aqua_Cobble"
    },
    {
      "x": -4,
      "y": 1,
      "z": -2,
      "name": "Rock_Aqua_Cobble"
    },
    {
      "x": -4,
      "y": 2,
      "z": -2,
      "name": "Rock_Aqua_Cobble"
    },
    {
      "x": -4,
      "y": 3,
      "z": -2,
      "name": "Rock_Aqua_Cobble"
    },
    {
      "x": -4,
      "y": 4,
      "z": -2,
      "name": "Rock_Aqua"
    },
    {
      "x": -4,
      "y": 5,
      "z": -2,
      "name": "Rock_Aqua"
    },
    {
      "x": -4,
      "y": 6,
      "z": -2,
      "name": "Rock_Aqua"
    },
    {
      "x": -4,
      "y": 7,
      "z": -2,
      "name": "Rock_Aqua"
    },
    {
      "x": -4,
      "y": 8,
      "z": -2,
      "name": "Rock_Aqua"
    },
    {
      "x": -4,
      "y": 0,
      "z": -1,
      "name": "Rock_Aqua_Cobble"
    },
    {
      "x": -4,
      "y": 1,
      "z": -1,
      "name": "Rock_Aqua_Cobble"
    },
    {
      "x": -4,
      "y": 2,
      "z": -1,
      "name": "Rock_Aqua_Cobble"
    },
    {
      "x": -4,
      "y": 3,
      "z": -1,
      "name": "Rock_Aqua_Cobble"
    },
    {
      "x": -4,
      "y": 4,
      "z": -1,
      "name": "Rock_Aqua_Cobble"
    },
    {
      "x": -4,
      "y": 5,
      "z": -1,
      "name": "Rock_Aqua"
    },
    {
      "x": -4,
      "y": 6,
      "z": -1,
      "name": "Rock_Aqua"
    },
    {
      "x": -4,
      "y": 7,
      "z": -1,
      "name": "Rock_Aqua"
    },
    {
      "x": -4,
      "y": 8,
      "z": -1,
      "name": "Rock_Aqua"
    },
    {
      "x": -4,
      "y": 0,
      "z": 0,
      "name": "Rock_Aqua_Cobble"
    },
    {
      "x": -4,
      "y": 1,
      "z": 0,
      "name": "Rock_Aqua_Cobble"
    },
    {
      "x": -4,
      "y": 2,
      "z": 0,
      "name": "Rock_Aqua_Cobble"
    },
    {
      "x": -4,
      "y": 3,
      "z": 0,
      "name": "Rock_Aqua_Cobble"
    },
    {
      "x": -4,
      "y": 4,
      "z": 0,
      "name": "Rock_Aqua_Cobble"
    },
    {
      "x": -4,
      "y": 5,
      "z": 0,
      "name": "Rock_Aqua_Cobble"
    },
    {
      "x": -4,
      "y": 6,
      "z": 0,
      "name": "Rock_Aqua_Cobble"
    },
    {
      "x": -4,
      "y": 7,
      "z": 0,
      "name": "Rock_Aqua_Cobble"
    },
    {
      "x": -4,
      "y": 8,
      "z": 0,
      "name": "Rock_Aqua_Cobble"
    },
    {
      "x": -4,
      "y": 0,
      "z": 1,
      "name": "Rock_Aqua_Cobble"
    },
    {
      "x": -4,
      "y": 1,
      "z": 1,
      "name": "Rock_Aqua_Cobble"
    },
    {
      "x": -4,
      "y": 2,
      "z": 1,
      "name": "Rock_Aqua_Cobble"
    },
    {
      "x": -4,
      "y": 3,
      "z": 1,
      "name": "Rock_Aqua_Cobble"
    },
    {
      "x": -4,
      "y": 4,
      "z": 1,
      "name": "Rock_Aqua_Cobble"
    },
    {
      "x": -4,
      "y": 5,
      "z": 1,
      "name": "Rock_Aqua_Cobble"
    },
    {
      "x": -4,
      "y": 6,
      "z": 1,
      "name": "Rock_Aqua_Cobble"
    },
    {
      "x": -4,
      "y": 7,
      "z": 1,
      "name": "Rock_Aqua_Cobble"
    },
    {
      "x": -4,
      "y": 8,
      "z": 1,
      "name": "Rock_Aqua_Cobble"
    },
    {
      "x": -4,
      "y": 9,
      "z": 1,
      "name": "Rock_Aqua_Cobble"
    },
    {
      "x": -4,
      "y": 10,
      "z": 1,
      "name": "Rock_Aqua_Cobble"
    },
    {
      "x": -4,
      "y": 0,
      "z": 2,
      "name": "Rock_Aqua_Cobble"
    },
    {
      "x": -4,
      "y": 1,
      "z": 2,
      "name": "Rock_Aqua_Cobble"
    },
    {
      "x": -4,
      "y": 2,
      "z": 2,
      "name": "Rock_Aqua_Cobble"
    },
    {
      "x": -4,
      "y": 3,
      "z": 2,
      "name": "Rock_Aqua_Cobble"
    },
    {
      "x": -4,
      "y": 4,
      "z": 2,
      "name": "Rock_Aqua_Cobble"
    },
    {
      "x": -4,
      "y": 5,
      "z": 2,
      "name": "Rock_Aqua_Cobble"
    },
    {
      "x": -4,
      "y": 6,
      "z": 2,
      "name": "Rock_Aqua_Cobble"
    },
    {
      "x": -4,
      "y": 7,
      "z": 2,
      "name": "Rock_Aqua_Cobble"
    },
    {
      "x": -4,
      "y": 8,
      "z": 2,
      "name": "Rock_Aqua_Cobble"
    },
    {
      "x": -4,
      "y": 9,
      "z": 2,
      "name": "Rock_Aqua_Cobble"
    },
    {
      "x": -4,
      "y": 10,
      "z": 2,
      "name": "Rock_Aqua_Cobble"
    },
    {
      "x": -4,
      "y": 0,
      "z": 3,
      "name": "Rock_Aqua_Cobble"
    },
    {
      "x": -4,
      "y": 1,
      "z": 3,
      "name": "Rock_Aqua_Cobble"
    },
    {
      "x": -4,
      "y": 2,
      "z": 3,
      "name": "Rock_Aqua_Cobble"
    },
    {
      "x": -4,
      "y": 3,
      "z": 3,
      "name": "Rock_Aqua_Cobble"
    },
    {
      "x": -4,
      "y": 4,
      "z": 3,
      "name": "Rock_Aqua_Cobble"
    },
    {
      "x": -4,
      "y": 5,
      "z": 3,
      "name": "Rock_Aqua_Cobble"
    },
    {
      "x": -4,
      "y": 6,
      "z": 3,
      "name": "Rock_Aqua_Cobble"
    },
    {
      "x": -4,
      "y": 7,
      "z": 3,
      "name": "Rock_Aqua_Cobble"
    },
    {
      "x": -4,
      "y": 8,
      "z": 3,
      "name": "Rock_Aqua_Cobble"
    },
    {
      "x": -4,
      "y": 9,
      "z": 3,
      "name": "Rock_Aqua_Cobble"
    },
    {
      "x": -4,
      "y": 10,
      "z": 3,
      "name": "Rock_Aqua_Cobble"
    },
    {
      "x": -4,
      "y": 0,
      "z": 4,
      "name": "Rock_Aqua_Cobble"
    },
    {
      "x": -4,
      "y": 1,
      "z": 4,
      "name": "Rock_Aqua_Cobble"
    },
    {
      "x": -4,
      "y": 2,
      "z": 4,
      "name": "Rock_Aqua_Cobble"
    },
    {
      "x": -4,
      "y": 3,
      "z": 4,
      "name": "Rock_Aqua_Cobble"
    },
    {
      "x": -4,
      "y": 4,
      "z": 4,
      "name": "Rock_Aqua_Cobble"
    },
    {
      "x": -4,
      "y": 5,
      "z": 4,
      "name": "Rock_Aqua_Cobble"
    },
    {
      "x": -4,
      "y": 6,
      "z": 4,
      "name": "Rock_Aqua_Cobble"
    },
    {
      "x": -4,
      "y": 7,
      "z": 4,
      "name": "Rock_Aqua_Cobble"
    },
    {
      "x": -4,
      "y": 8,
      "z": 4,
      "name": "Rock_Aqua"
    },
    {
      "x": -4,
      "y": 9,
      "z": 4,
      "name": "Rock_Aqua_Cobble"
    },
    {
      "x": -4,
      "y": 3,
      "z": 5,
      "name": "Rock_Aqua_Cobble"
    },
    {
      "x": -4,
      "y": 4,
      "z": 5,
      "name": "Rock_Aqua_Cobble"
    },
    {
      "x": -4,
      "y": 5,
      "z": 5,
      "name": "Rock_Aqua_Cobble"
    },
    {
      "x": -4,
      "y": 6,
      "z": 5,
      "name": "Rock_Aqua_Cobble"
    },
    {
      "x": -4,
      "y": 7,
      "z": 5,
      "name": "Rock_Aqua"
    },
    {
      "x": -4,
      "y": 8,
      "z": 5,
      "name": "Rock_Aqua"
    },
    {
      "x": -4,
      "y": 6,
      "z": 6,
      "name": "Rock_Aqua_Cobble_Half",
      "rotation": 4
    },
    {
      "x": -3,
      "y": 2,
      "z": -5,
      "name": "Rock_Aqua_Cobble"
    },
    {
      "x": -3,
      "y": 3,
      "z": -5,
      "name": "Rock_Aqua_Cobble"
    },
    {
      "x": -3,
      "y": 4,
      "z": -5,
      "name": "Rock_Aqua_Cobble"
    },
    {
      "x": -3,
      "y": 5,
      "z": -5,
      "name": "Rock_Aqua_Cobble"
    },
    {
      "x": -3,
      "y": 0,
      "z": -4,
      "name": "Rock_Aqua_Cobble"
    },
    {
      "x": -3,
      "y": 1,
      "z": -4,
      "name": "Rock_Aqua_Cobble"
    },
    {
      "x": -3,
      "y": 2,
      "z": -4,
      "name": "Rock_Aqua_Cobble"
    },
    {
      "x": -3,
      "y": 3,
      "z": -4,
      "name": "Rock_Aqua_Cobble"
    },
    {
      "x": -3,
      "y": 4,
      "z": -4,
      "name": "Rock_Aqua_Cobble"
    },
    {
      "x": -3,
      "y": 5,
      "z": -4,
      "name": "Rock_Aqua"
    },
    {
      "x": -3,
      "y": 6,
      "z": -4,
      "name": "Rock_Aqua"
    },
    {
      "x": -3,
      "y": 7,
      "z": -4,
      "name": "Rock_Aqua"
    },
    {
      "x": -3,
      "y": 0,
      "z": -3,
      "name": "Rock_Aqua_Cobble"
    },
    {
      "x": -3,
      "y": 1,
      "z": -3,
      "name": "Rock_Aqua_Cobble"
    },
    {
      "x": -3,
      "y": 2,
      "z": -3,
      "name": "Rock_Aqua_Cobble"
    },
    {
      "x": -3,
      "y": 3,
      "z": -3,
      "name": "Rock_Aqua"
    },
    {
      "x": -3,
      "y": 4,
      "z": -3,
      "name": "Rock_Aqua"
    },
    {
      "x": -3,
      "y": 5,
      "z": -3,
      "name": "Rock_Aqua"
    },
    {
      "x": -3,
      "y": 6,
      "z": -3,
      "name": "Rock_Aqua"
    },
    {
      "x": -3,
      "y": 7,
      "z": -3,
      "name": "Rock_Aqua"
    },
    {
      "x": -3,
      "y": 8,
      "z": -3,
      "name": "Rock_Aqua"
    },
    {
      "x": -3,
      "y": 0,
      "z": -2,
      "name": "Rock_Aqua_Cobble"
    },
    {
      "x": -3,
      "y": 1,
      "z": -2,
      "name": "Rock_Aqua_Cobble"
    },
    {
      "x": -3,
      "y": 2,
      "z": -2,
      "name": "Rock_Aqua_Cobble"
    },
    {
      "x": -3,
      "y": 3,
      "z": -2,
      "name": "Rock_Aqua"
    },
    {
      "x": -3,
      "y": 4,
      "z": -2,
      "name": "Rock_Aqua"
    },
    {
      "x": -3,
      "y": 5,
      "z": -2,
      "name": "Rock_Aqua"
    },
    {
      "x": -3,
      "y": 6,
      "z": -2,
      "name": "Rock_Aqua"
    },
    {
      "x": -3,
      "y": 7,
      "z": -2,
      "name": "Rock_Aqua"
    },
    {
      "x": -3,
      "y": 8,
      "z": -2,
      "name": "Rock_Aqua"
    },
    {
      "x": -3,
      "y": 0,
      "z": -1,
      "name": "Rock_Aqua_Cobble"
    },
    {
      "x": -3,
      "y": 1,
      "z": -1,
      "name": "Rock_Aqua_Cobble"
    },
    {
      "x": -3,
      "y": 2,
      "z": -1,
      "name": "Rock_Aqua_Cobble"
    },
    {
      "x": -3,
      "y": 3,
      "z": -1,
      "name": "Rock_Aqua"
    },
    {
      "x": -3,
      "y": 4,
      "z": -1,
      "name": "Rock_Aqua_Cobble"
    },
    {
      "x": -3,
      "y": 5,
      "z": -1,
      "name": "Rock_Aqua_Cobble"
    },
    {
      "x": -3,
      "y": 6,
      "z": -1,
      "name": "Rock_Aqua"
    },
    {
      "x": -3,
      "y": 7,
      "z": -1,
      "name": "Rock_Aqua"
    },
    {
      "x": -3,
      "y": 8,
      "z": -1,
      "name": "Rock_Aqua"
    },
    {
      "x": -3,
      "y": 0,
      "z": 0,
      "name": "Rock_Aqua_Cobble"
    },
    {
      "x": -3,
      "y": 1,
      "z": 0,
      "name": "Rock_Aqua_Cobble"
    },
    {
      "x": -3,
      "y": 2,
      "z": 0,
      "name": "Rock_Aqua_Cobble"
    },
    {
      "x": -3,
      "y": 3,
      "z": 0,
      "name": "Rock_Aqua_Cobble"
    },
    {
      "x": -3,
      "y": 4,
      "z": 0,
      "name": "Rock_Aqua_Cobble"
    },
    {
      "x": -3,
      "y": 5,
      "z": 0,
      "name": "Rock_Aqua_Cobble"
    },
    {
      "x": -3,
      "y": 6,
      "z": 0,
      "name": "Rock_Aqua_Cobble"
    },
    {
      "x": -3,
      "y": 7,
      "z": 0,
      "name": "Rock_Aqua_Cobble"
    },
    {
      "x": -3,
      "y": 8,
      "z": 0,
      "name": "Rock_Aqua_Cobble"
    },
    {
      "x": -3,
      "y": 9,
      "z": 0,
      "name": "Rock_Aqua_Cobble_Half"
    },
    {
      "x": -3,
      "y": 0,
      "z": 1,
      "name": "Rock_Aqua_Cobble"
    },
    {
      "x": -3,
      "y": 1,
      "z": 1,
      "name": "Rock_Aqua_Cobble"
    },
    {
      "x": -3,
      "y": 2,
      "z": 1,
      "name": "Rock_Aqua_Cobble"
    },
    {
      "x": -3,
      "y": 3,
      "z": 1,
      "name": "Rock_Aqua_Cobble"
    },
    {
      "x": -3,
      "y": 4,
      "z": 1,
      "name": "Rock_Aqua_Cobble"
    },
    {
      "x": -3,
      "y": 5,
      "z": 1,
      "name": "Rock_Aqua_Cobble"
    },
    {
      "x": -3,
      "y": 6,
      "z": 1,
      "name": "Rock_Aqua_Cobble"
    },
    {
      "x": -3,
      "y": 7,
      "z": 1,
      "name": "Rock_Aqua_Cobble"
    },
    {
      "x": -3,
      "y": 8,
      "z": 1,
      "name": "Rock_Aqua_Cobble"
    },
    {
      "x": -3,
      "y": 9,
      "z": 1,
      "name": "Rock_Aqua_Cobble"
    },
    {
      "x": -3,
      "y": 10,
      "z": 1,
      "name": "Rock_Aqua_Cobble"
    },
    {
      "x": -3,
      "y": 0,
      "z": 2,
      "name": "Rock_Aqua_Cobble"
    },
    {
      "x": -3,
      "y": 1,
      "z": 2,
      "name": "Rock_Aqua_Cobble"
    },
    {
      "x": -3,
      "y": 2,
      "z": 2,
      "name": "Rock_Aqua_Cobble"
    },
    {
      "x": -3,
      "y": 3,
      "z": 2,
      "name": "Rock_Aqua_Cobble"
    },
    {
      "x": -3,
      "y": 4,
      "z": 2,
      "name": "Rock_Aqua_Cobble"
    },
    {
      "x": -3,
      "y": 5,
      "z": 2,
      "name": "Rock_Aqua_Cobble"
    },
    {
      "x": -3,
      "y": 6,
      "z": 2,
      "name": "Rock_Aqua_Cobble"
    },
    {
      "x": -3,
      "y": 7,
      "z": 2,
      "name": "Rock_Aqua_Cobble"
    },
    {
      "x": -3,
      "y": 8,
      "z": 2,
      "name": "Rock_Aqua_Cobble"
    },
    {
      "x": -3,
      "y": 9,
      "z": 2,
      "name": "Rock_Aqua_Cobble"
    },
    {
      "x": -3,
      "y": 10,
      "z": 2,
      "name": "Rock_Aqua_Cobble"
    },
    {
      "x": -3,
      "y": 0,
      "z": 3,
      "name": "Rock_Aqua_Cobble"
    },
    {
      "x": -3,
      "y": 1,
      "z": 3,
      "name": "Rock_Aqua_Cobble"
    },
    {
      "x": -3,
      "y": 2,
      "z": 3,
      "name": "Rock_Aqua_Cobble"
    },
    {
      "x": -3,
      "y": 3,
      "z": 3,
      "name": "Rock_Aqua_Cobble"
    },
    {
      "x": -3,
      "y": 4,
      "z": 3,
      "name": "Rock_Aqua_Cobble"
    },
    {
      "x": -3,
      "y": 5,
      "z": 3,
      "name": "Rock_Aqua_Cobble"
    },
    {
      "x": -3,
      "y": 6,
      "z": 3,
      "name": "Rock_Aqua_Cobble"
    },
    {
      "x": -3,
      "y": 7,
      "z": 3,
      "name": "Rock_Aqua_Cobble"
    },
    {
      "x": -3,
      "y": 8,
      "z": 3,
      "name": "Rock_Aqua_Cobble"
    },
    {
      "x": -3,
      "y": 9,
      "z": 3,
      "name": "Rock_Aqua_Cobble"
    },
    {
      "x": -3,
      "y": 10,
      "z": 3,
      "name": "Rock_Aqua_Cobble"
    },
    {
      "x": -3,
      "y": 0,
      "z": 4,
      "name": "Rock_Aqua_Cobble"
    },
    {
      "x": -3,
      "y": 1,
      "z": 4,
      "name": "Rock_Aqua_Cobble"
    },
    {
      "x": -3,
      "y": 2,
      "z": 4,
      "name": "Rock_Aqua_Cobble"
    },
    {
      "x": -3,
      "y": 3,
      "z": 4,
      "name": "Rock_Aqua_Cobble"
    },
    {
      "x": -3,
      "y": 4,
      "z": 4,
      "name": "Rock_Aqua_Cobble"
    },
    {
      "x": -3,
      "y": 5,
      "z": 4,
      "name": "Rock_Aqua_Cobble"
    },
    {
      "x": -3,
      "y": 6,
      "z": 4,
      "name": "Rock_Aqua_Cobble"
    },
    {
      "x": -3,
      "y": 7,
      "z": 4,
      "name": "Rock_Aqua"
    },
    {
      "x": -3,
      "y": 8,
      "z": 4,
      "name": "Rock_Aqua"
    },
    {
      "x": -3,
      "y": 9,
      "z": 4,
      "name": "Rock_Aqua"
    },
    {
      "x": -3,
      "y": 10,
      "z": 4,
      "name": "Rock_Aqua_Cobble"
    },
    {
      "x": -3,
      "y": 0,
      "z": 5,
      "name": "Rock_Aqua_Cobble"
    },
    {
      "x": -3,
      "y": 1,
      "z": 5,
      "name": "Rock_Aqua_Cobble"
    },
    {
      "x": -3,
      "y": 2,
      "z": 5,
      "name": "Rock_Aqua_Cobble"
    },
    {
      "x": -3,
      "y": 3,
      "z": 5,
      "name": "Rock_Aqua_Cobble"
    },
    {
      "x": -3,
      "y": 4,
      "z": 5,
      "name": "Rock_Aqua_Cobble"
    },
    {
      "x": -3,
      "y": 5,
      "z": 5,
      "name": "Rock_Aqua_Cobble"
    },
    {
      "x": -3,
      "y": 6,
      "z": 5,
      "name": "Rock_Aqua"
    },
    {
      "x": -3,
      "y": 7,
      "z": 5,
      "name": "Rock_Aqua"
    },
    {
      "x": -3,
      "y": 8,
      "z": 5,
      "name": "Rock_Aqua"
    },
    {
      "x": -3,
      "y": 9,
      "z": 5,
      "name": "Rock_Aqua"
    },
    {
      "x": -3,
      "y": 10,
      "z": 5,
      "name": "Rock_Aqua"
    },
    {
      "x": -3,
      "y": 3,
      "z": 6,
      "name": "Rock_Aqua_Cobble"
    },
    {
      "x": -3,
      "y": 4,
      "z": 6,
      "name": "Rock_Aqua_Cobble"
    },
    {
      "x": -3,
      "y": 5,
      "z": 6,
      "name": "Rock_Aqua_Cobble"
    },
    {
      "x": -3,
      "y": 6,
      "z": 6,
      "name": "Rock_Aqua"
    },
    {
      "x": -3,
      "y": 7,
      "z": 6,
      "name": "Rock_Aqua"
    },
    {
      "x": -3,
      "y": 8,
      "z": 6,
      "name": "Rock_Aqua"
    },
    {
      "x": -3,
      "y": 9,
      "z": 6,
      "name": "Rock_Aqua"
    },
    {
      "x": -2,
      "y": 5,
      "z": -6,
      "name": "Rock_Aqua_Cobble"
    },
    {
      "x": -2,
      "y": 6,
      "z": -6,
      "name": "Rock_Aqua_Cobble"
    },
    {
      "x": -2,
      "y": 7,
      "z": -6,
      "name": "Rock_Aqua_Cobble"
    },
    {
      "x": -2,
      "y": 0,
      "z": -5,
      "name": "Rock_Aqua"
    },
    {
      "x": -2,
      "y": 1,
      "z": -5,
      "name": "Rock_Aqua"
    },
    {
      "x": -2,
      "y": 2,
      "z": -5,
      "name": "Rock_Aqua_Cobble"
    },
    {
      "x": -2,
      "y": 3,
      "z": -5,
      "name": "Rock_Aqua"
    },
    {
      "x": -2,
      "y": 4,
      "z": -5,
      "name": "Rock_Aqua"
    },
    {
      "x": -2,
      "y": 5,
      "z": -5,
      "name": "Rock_Aqua_Cobble"
    },
    {
      "x": -2,
      "y": 6,
      "z": -5,
      "name": "Rock_Aqua_Cobble"
    },
    {
      "x": -2,
      "y": 7,
      "z": -5,
      "name": "Rock_Aqua_Cobble"
    },
    {
      "x": -2,
      "y": 8,
      "z": -5,
      "name": "Rock_Aqua"
    },
    {
      "x": -2,
      "y": 0,
      "z": -4,
      "name": "Rock_Aqua"
    },
    {
      "x": -2,
      "y": 1,
      "z": -4,
      "name": "Rock_Aqua"
    },
    {
      "x": -2,
      "y": 2,
      "z": -4,
      "name": "Rock_Aqua_Cobble"
    },
    {
      "x": -2,
      "y": 3,
      "z": -4,
      "name": "Rock_Aqua"
    },
    {
      "x": -2,
      "y": 4,
      "z": -4,
      "name": "Rock_Aqua_Cobble"
    },
    {
      "x": -2,
      "y": 5,
      "z": -4,
      "name": "Rock_Aqua_Cobble"
    },
    {
      "x": -2,
      "y": 6,
      "z": -4,
      "name": "Rock_Aqua"
    },
    {
      "x": -2,
      "y": 7,
      "z": -4,
      "name": "Rock_Aqua"
    },
    {
      "x": -2,
      "y": 8,
      "z": -4,
      "name": "Rock_Aqua"
    },
    {
      "x": -2,
      "y": 0,
      "z": -3,
      "name": "Rock_Aqua"
    },
    {
      "x": -2,
      "y": 1,
      "z": -3,
      "name": "Rock_Aqua_Cobble"
    },
    {
      "x": -2,
      "y": 2,
      "z": -3,
      "name": "Rock_Aqua_Cobble"
    },
    {
      "x": -2,
      "y": 3,
      "z": -3,
      "name": "Rock_Aqua"
    },
    {
      "x": -2,
      "y": 4,
      "z": -3,
      "name": "Rock_Aqua"
    },
    {
      "x": -2,
      "y": 5,
      "z": -3,
      "name": "Rock_Aqua"
    },
    {
      "x": -2,
      "y": 6,
      "z": -3,
      "name": "Rock_Aqua"
    },
    {
      "x": -2,
      "y": 7,
      "z": -3,
      "name": "Rock_Aqua"
    },
    {
      "x": -2,
      "y": 8,
      "z": -3,
      "name": "Rock_Aqua"
    },
    {
      "x": -2,
      "y": 0,
      "z": -2,
      "name": "Rock_Aqua_Cobble"
    },
    {
      "x": -2,
      "y": 1,
      "z": -2,
      "name": "Rock_Aqua_Cobble"
    },
    {
      "x": -2,
      "y": 2,
      "z": -2,
      "name": "Rock_Aqua_Cobble"
    },
    {
      "x": -2,
      "y": 3,
      "z": -2,
      "name": "Rock_Aqua"
    },
    {
      "x": -2,
      "y": 4,
      "z": -2,
      "name": "Rock_Aqua"
    },
    {
      "x": -2,
      "y": 5,
      "z": -2,
      "name": "Rock_Aqua"
    },
    {
      "x": -2,
      "y": 6,
      "z": -2,
      "name": "Rock_Aqua"
    },
    {
      "x": -2,
      "y": 7,
      "z": -2,
      "name": "Rock_Aqua"
    },
    {
      "x": -2,
      "y": 8,
      "z": -2,
      "name": "Rock_Aqua"
    },
    {
      "x": -2,
      "y": 0,
      "z": -1,
      "name": "Rock_Aqua_Cobble"
    },
    {
      "x": -2,
      "y": 1,
      "z": -1,
      "name": "Rock_Aqua_Cobble"
    },
    {
      "x": -2,
      "y": 2,
      "z": -1,
      "name": "Rock_Aqua_Cobble"
    },
    {
      "x": -2,
      "y": 3,
      "z": -1,
      "name": "Rock_Aqua"
    },
    {
      "x": -2,
      "y": 4,
      "z": -1,
      "name": "Rock_Aqua"
    },
    {
      "x": -2,
      "y": 5,
      "z": -1,
      "name": "Rock_Aqua_Cobble"
    },
    {
      "x": -2,
      "y": 6,
      "z": -1,
      "name": "Rock_Aqua_Cobble"
    },
    {
      "x": -2,
      "y": 7,
      "z": -1,
      "name": "Rock_Aqua"
    },
    {
      "x": -2,
      "y": 8,
      "z": -1,
      "name": "Rock_Aqua"
    },
    {
      "x": -2,
      "y": 0,
      "z": 0,
      "name": "Rock_Aqua_Cobble"
    },
    {
      "x": -2,
      "y": 1,
      "z": 0,
      "name": "Rock_Aqua_Cobble"
    },
    {
      "x": -2,
      "y": 2,
      "z": 0,
      "name": "Rock_Aqua_Cobble"
    },
    {
      "x": -2,
      "y": 3,
      "z": 0,
      "name": "Rock_Aqua"
    },
    {
      "x": -2,
      "y": 4,
      "z": 0,
      "name": "Rock_Aqua_Cobble"
    },
    {
      "x": -2,
      "y": 5,
      "z": 0,
      "name": "Rock_Aqua_Cobble"
    },
    {
      "x": -2,
      "y": 6,
      "z": 0,
      "name": "Rock_Aqua_Cobble"
    },
    {
      "x": -2,
      "y": 7,
      "z": 0,
      "name": "Rock_Aqua_Cobble"
    },
    {
      "x": -2,
      "y": 8,
      "z": 0,
      "name": "Rock_Aqua"
    },
    {
      "x": -2,
      "y": 9,
      "z": 0,
      "name": "Rock_Aqua_Cobble"
    },
    {
      "x": -2,
      "y": 0,
      "z": 1,
      "name": "Rock_Aqua_Cobble"
    },
    {
      "x": -2,
      "y": 1,
      "z": 1,
      "name": "Rock_Aqua_Cobble"
    },
    {
      "x": -2,
      "y": 2,
      "z": 1,
      "name": "Rock_Aqua"
    },
    {
      "x": -2,
      "y": 3,
      "z": 1,
      "name": "Rock_Aqua_Cobble"
    },
    {
      "x": -2,
      "y": 4,
      "z": 1,
      "name": "Rock_Aqua_Cobble"
    },
    {
      "x": -2,
      "y": 5,
      "z": 1,
      "name": "Rock_Aqua_Cobble"
    },
    {
      "x": -2,
      "y": 6,
      "z": 1,
      "name": "Rock_Aqua_Cobble"
    },
    {
      "x": -2,
      "y": 7,
      "z": 1,
      "name": "Rock_Aqua_Cobble"
    },
    {
      "x": -2,
      "y": 8,
      "z": 1,
      "name": "Rock_Aqua_Cobble"
    },
    {
      "x": -2,
      "y": 9,
      "z": 1,
      "name": "Rock_Aqua_Cobble"
    },
    {
      "x": -2,
      "y": 10,
      "z": 1,
      "name": "Rock_Aqua_Cobble"
    },
    {
      "x": -2,
      "y": 0,
      "z": 2,
      "name": "Rock_Aqua_Cobble"
    },
    {
      "x": -2,
      "y": 1,
      "z": 2,
      "name": "Rock_Aqua_Cobble"
    },
    {
      "x": -2,
      "y": 2,
      "z": 2,
      "name": "Rock_Aqua"
    },
    {
      "x": -2,
      "y": 3,
      "z": 2,
      "name": "Rock_Aqua"
    },
    {
      "x": -2,
      "y": 4,
      "z": 2,
      "name": "Rock_Aqua_Cobble"
    },
    {
      "x": -2,
      "y": 5,
      "z": 2,
      "name": "Rock_Aqua_Cobble"
    },
    {
      "x": -2,
      "y": 6,
      "z": 2,
      "name": "Rock_Aqua_Cobble"
    },
    {
      "x": -2,
      "y": 7,
      "z": 2,
      "name": "Rock_Aqua_Cobble"
    },
    {
      "x": -2,
      "y": 8,
      "z": 2,
      "name": "Rock_Aqua_Cobble"
    },
    {
      "x": -2,
      "y": 9,
      "z": 2,
      "name": "Rock_Aqua_Cobble"
    },
    {
      "x": -2,
      "y": 10,
      "z": 2,
      "name": "Rock_Aqua_Cobble"
    },
    {
      "x": -2,
      "y": 0,
      "z": 3,
      "name": "Rock_Aqua_Cobble"
    },
    {
      "x": -2,
      "y": 1,
      "z": 3,
      "name": "Rock_Aqua_Cobble"
    },
    {
      "x": -2,
      "y": 2,
      "z": 3,
      "name": "Rock_Aqua"
    },
    {
      "x": -2,
      "y": 3,
      "z": 3,
      "name": "Rock_Aqua_Cobble"
    },
    {
      "x": -2,
      "y": 4,
      "z": 3,
      "name": "Rock_Aqua_Cobble"
    },
    {
      "x": -2,
      "y": 5,
      "z": 3,
      "name": "Rock_Aqua_Cobble"
    },
    {
      "x": -2,
      "y": 6,
      "z": 3,
      "name": "Rock_Aqua_Cobble"
    },
    {
      "x": -2,
      "y": 7,
      "z": 3,
      "name": "Rock_Aqua_Cobble"
    },
    {
      "x": -2,
      "y": 8,
      "z": 3,
      "name": "Rock_Aqua_Cobble"
    },
    {
      "x": -2,
      "y": 9,
      "z": 3,
      "name": "Rock_Aqua_Cobble"
    },
    {
      "x": -2,
      "y": 10,
      "z": 3,
      "name": "Rock_Aqua_Cobble"
    },
    {
      "x": -2,
      "y": 0,
      "z": 4,
      "name": "Rock_Aqua_Cobble"
    },
    {
      "x": -2,
      "y": 1,
      "z": 4,
      "name": "Rock_Aqua_Cobble"
    },
    {
      "x": -2,
      "y": 2,
      "z": 4,
      "name": "Rock_Aqua_Cobble"
    },
    {
      "x": -2,
      "y": 3,
      "z": 4,
      "name": "Rock_Aqua_Cobble"
    },
    {
      "x": -2,
      "y": 4,
      "z": 4,
      "name": "Rock_Aqua_Cobble"
    },
    {
      "x": -2,
      "y": 5,
      "z": 4,
      "name": "Rock_Aqua_Cobble"
    },
    {
      "x": -2,
      "y": 6,
      "z": 4,
      "name": "Rock_Aqua_Cobble"
    },
    {
      "x": -2,
      "y": 7,
      "z": 4,
      "name": "Rock_Aqua_Cobble"
    },
    {
      "x": -2,
      "y": 8,
      "z": 4,
      "name": "Rock_Aqua"
    },
    {
      "x": -2,
      "y": 9,
      "z": 4,
      "name": "Rock_Aqua_Cobble"
    },
    {
      "x": -2,
      "y": 10,
      "z": 4,
      "name": "Rock_Aqua_Cobble"
    },
    {
      "x": -2,
      "y": 0,
      "z": 5,
      "name": "Rock_Aqua_Cobble"
    },
    {
      "x": -2,
      "y": 1,
      "z": 5,
      "name": "Rock_Aqua_Cobble"
    },
    {
      "x": -2,
      "y": 2,
      "z": 5,
      "name": "Rock_Aqua_Cobble"
    },
    {
      "x": -2,
      "y": 3,
      "z": 5,
      "name": "Rock_Aqua_Cobble"
    },
    {
      "x": -2,
      "y": 4,
      "z": 5,
      "name": "Rock_Aqua_Cobble"
    },
    {
      "x": -2,
      "y": 5,
      "z": 5,
      "name": "Rock_Aqua_Cobble"
    },
    {
      "x": -2,
      "y": 6,
      "z": 5,
      "name": "Rock_Aqua_Cobble"
    },
    {
      "x": -2,
      "y": 7,
      "z": 5,
      "name": "Rock_Aqua"
    },
    {
      "x": -2,
      "y": 8,
      "z": 5,
      "name": "Rock_Aqua"
    },
    {
      "x": -2,
      "y": 9,
      "z": 5,
      "name": "Rock_Aqua"
    },
    {
      "x": -2,
      "y": 10,
      "z": 5,
      "name": "Rock_Aqua_Cobble"
    },
    {
      "x": -2,
      "y": 0,
      "z": 6,
      "name": "Rock_Aqua_Cobble"
    },
    {
      "x": -2,
      "y": 1,
      "z": 6,
      "name": "Rock_Aqua_Cobble"
    },
    {
      "x": -2,
      "y": 2,
      "z": 6,
      "name": "Rock_Aqua_Cobble"
    },
    {
      "x": -2,
      "y": 3,
      "z": 6,
      "name": "Rock_Aqua_Cobble"
    },
    {
      "x": -2,
      "y": 4,
      "z": 6,
      "name": "Rock_Aqua_Cobble"
    },
    {
      "x": -2,
      "y": 5,
      "z": 6,
      "name": "Rock_Aqua_Cobble"
    },
    {
      "x": -2,
      "y": 6,
      "z": 6,
      "name": "Rock_Aqua"
    },
    {
      "x": -2,
      "y": 7,
      "z": 6,
      "name": "Rock_Aqua"
    },
    {
      "x": -2,
      "y": 8,
      "z": 6,
      "name": "Rock_Aqua"
    },
    {
      "x": -2,
      "y": 9,
      "z": 6,
      "name": "Rock_Aqua"
    },
    {
      "x": -2,
      "y": 10,
      "z": 6,
      "name": "Rock_Aqua"
    },
    {
      "x": -2,
      "y": 4,
      "z": 7,
      "name": "Rock_Aqua_Cobble"
    },
    {
      "x": -2,
      "y": 5,
      "z": 7,
      "name": "Rock_Aqua_Cobble"
    },
    {
      "x": -2,
      "y": 6,
      "z": 7,
      "name": "Rock_Aqua_Cobble"
    },
    {
      "x": -2,
      "y": 7,
      "z": 7,
      "name": "Rock_Aqua"
    },
    {
      "x": -2,
      "y": 8,
      "z": 7,
      "name": "Rock_Aqua"
    },
    {
      "x": -1,
      "y": 0,
      "z": -6,
      "name": "Rock_Aqua"
    },
    {
      "x": -1,
      "y": 1,
      "z": -6,
      "name": "Rock_Aqua"
    },
    {
      "x": -1,
      "y": 2,
      "z": -6,
      "name": "Rock_Aqua"
    },
    {
      "x": -1,
      "y": 3,
      "z": -6,
      "name": "Rock_Aqua"
    },
    {
      "x": -1,
      "y": 4,
      "z": -6,
      "name": "Rock_Aqua"
    },
    {
      "x": -1,
      "y": 5,
      "z": -6,
      "name": "Rock_Aqua_Cobble"
    },
    {
      "x": -1,
      "y": 6,
      "z": -6,
      "name": "Rock_Aqua_Cobble"
    },
    {
      "x": -1,
      "y": 7,
      "z": -6,
      "name": "Rock_Aqua_Cobble"
    },
    {
      "x": -1,
      "y": 8,
      "z": -6,
      "name": "Rock_Aqua_Cobble_Half"
    },
    {
      "x": -1,
      "y": 0,
      "z": -5,
      "name": "Rock_Aqua"
    },
    {
      "x": -1,
      "y": 1,
      "z": -5,
      "name": "Rock_Aqua"
    },
    {
      "x": -1,
      "y": 2,
      "z": -5,
      "name": "Rock_Aqua"
    },
    {
      "x": -1,
      "y": 3,
      "z": -5,
      "name": "Rock_Aqua"
    },
    {
      "x": -1,
      "y": 4,
      "z": -5,
      "name": "Rock_Aqua"
    },
    {
      "x": -1,
      "y": 5,
      "z": -5,
      "name": "Rock_Aqua"
    },
    {
      "x": -1,
      "y": 6,
      "z": -5,
      "name": "Rock_Aqua_Cobble"
    },
    {
      "x": -1,
      "y": 7,
      "z": -5,
      "name": "Rock_Aqua_Cobble"
    },
    {
      "x": -1,
      "y": 8,
      "z": -5,
      "name": "Rock_Aqua_Cobble"
    },
    {
      "x": -1,
      "y": 0,
      "z": -4,
      "name": "Rock_Aqua"
    },
    {
      "x": -1,
      "y": 1,
      "z": -4,
      "name": "Rock_Aqua"
    },
    {
      "x": -1,
      "y": 2,
      "z": -4,
      "name": "Rock_Aqua"
    },
    {
      "x": -1,
      "y": 3,
      "z": -4,
      "name": "Rock_Aqua"
    },
    {
      "x": -1,
      "y": 4,
      "z": -4,
      "name": "Rock_Aqua"
    },
    {
      "x": -1,
      "y": 5,
      "z": -4,
      "name": "Rock_Aqua_Cobble"
    },
    {
      "x": -1,
      "y": 6,
      "z": -4,
      "name": "Rock_Aqua_Cobble"
    },
    {
      "x": -1,
      "y": 7,
      "z": -4,
      "name": "Rock_Aqua"
    },
    {
      "x": -1,
      "y": 8,
      "z": -4,
      "name": "Rock_Aqua"
    },
    {
      "x": -1,
      "y": 0,
      "z": -3,
      "name": "Rock_Aqua"
    },
    {
      "x": -1,
      "y": 1,
      "z": -3,
      "name": "Rock_Aqua"
    },
    {
      "x": -1,
      "y": 2,
      "z": -3,
      "name": "Rock_Aqua_Cobble"
    },
    {
      "x": -1,
      "y": 3,
      "z": -3,
      "name": "Rock_Aqua"
    },
    {
      "x": -1,
      "y": 4,
      "z": -3,
      "name": "Rock_Aqua"
    },
    {
      "x": -1,
      "y": 5,
      "z": -3,
      "name": "Rock_Aqua"
    },
    {
      "x": -1,
      "y": 6,
      "z": -3,
      "name": "Rock_Aqua"
    },
    {
      "x": -1,
      "y": 7,
      "z": -3,
      "name": "Rock_Aqua"
    },
    {
      "x": -1,
      "y": 8,
      "z": -3,
      "name": "Rock_Aqua"
    },
    {
      "x": -1,
      "y": 0,
      "z": -2,
      "name": "Rock_Aqua"
    },
    {
      "x": -1,
      "y": 1,
      "z": -2,
      "name": "Rock_Aqua_Cobble"
    },
    {
      "x": -1,
      "y": 2,
      "z": -2,
      "name": "Rock_Aqua_Cobble"
    },
    {
      "x": -1,
      "y": 3,
      "z": -2,
      "name": "Rock_Aqua"
    },
    {
      "x": -1,
      "y": 4,
      "z": -2,
      "name": "Rock_Aqua"
    },
    {
      "x": -1,
      "y": 5,
      "z": -2,
      "name": "Rock_Aqua"
    },
    {
      "x": -1,
      "y": 6,
      "z": -2,
      "name": "Rock_Aqua"
    },
    {
      "x": -1,
      "y": 7,
      "z": -2,
      "name": "Rock_Aqua"
    },
    {
      "x": -1,
      "y": 8,
      "z": -2,
      "name": "Rock_Aqua"
    },
    {
      "x": -1,
      "y": 0,
      "z": -1,
      "name": "Rock_Aqua_Cobble"
    },
    {
      "x": -1,
      "y": 1,
      "z": -1,
      "name": "Rock_Aqua_Cobble"
    },
    {
      "x": -1,
      "y": 2,
      "z": -1,
      "name": "Rock_Aqua_Cobble"
    },
    {
      "x": -1,
      "y": 3,
      "z": -1,
      "name": "Rock_Aqua"
    },
    {
      "x": -1,
      "y": 4,
      "z": -1,
      "name": "Rock_Aqua"
    },
    {
      "x": -1,
      "y": 5,
      "z": -1,
      "name": "Rock_Aqua"
    },
    {
      "x": -1,
      "y": 6,
      "z": -1,
      "name": "Rock_Aqua"
    },
    {
      "x": -1,
      "y": 7,
      "z": -1,
      "name": "Rock_Aqua"
    },
    {
      "x": -1,
      "y": 8,
      "z": -1,
      "name": "Rock_Aqua"
    },
    {
      "x": -1,
      "y": 0,
      "z": 0,
      "name": "Rock_Aqua_Cobble"
    },
    {
      "x": -1,
      "y": 1,
      "z": 0,
      "name": "Rock_Aqua_Cobble"
    },
    {
      "x": -1,
      "y": 2,
      "z": 0,
      "name": "Rock_Aqua"
    },
    {
      "x": -1,
      "y": 3,
      "z": 0,
      "name": "Rock_Aqua"
    },
    {
      "x": -1,
      "y": 4,
      "z": 0,
      "name": "Rock_Aqua"
    },
    {
      "x": -1,
      "y": 5,
      "z": 0,
      "name": "Rock_Aqua_Cobble"
    },
    {
      "x": -1,
      "y": 6,
      "z": 0,
      "name": "Rock_Aqua_Cobble"
    },
    {
      "x": -1,
      "y": 7,
      "z": 0,
      "name": "Rock_Aqua"
    },
    {
      "x": -1,
      "y": 8,
      "z": 0,
      "name": "Rock_Aqua"
    },
    {
      "x": -1,
      "y": 9,
      "z": 0,
      "name": "Rock_Aqua"
    },
    {
      "x": -1,
      "y": 0,
      "z": 1,
      "name": "Rock_Aqua_Cobble"
    },
    {
      "x": -1,
      "y": 1,
      "z": 1,
      "name": "Rock_Aqua_Cobble"
    },
    {
      "x": -1,
      "y": 2,
      "z": 1,
      "name": "Rock_Aqua"
    },
    {
      "x": -1,
      "y": 3,
      "z": 1,
      "name": "Rock_Aqua"
    },
    {
      "x": -1,
      "y": 4,
      "z": 1,
      "name": "Rock_Aqua_Cobble"
    },
    {
      "x": -1,
      "y": 5,
      "z": 1,
      "name": "Rock_Aqua_Cobble"
    },
    {
      "x": -1,
      "y": 6,
      "z": 1,
      "name": "Rock_Aqua_Cobble"
    },
    {
      "x": -1,
      "y": 7,
      "z": 1,
      "name": "Rock_Aqua_Cobble"
    },
    {
      "x": -1,
      "y": 8,
      "z": 1,
      "name": "Rock_Aqua_Cobble"
    },
    {
      "x": -1,
      "y": 9,
      "z": 1,
      "name": "Rock_Aqua_Cobble"
    },
    {
      "x": -1,
      "y": 10,
      "z": 1,
      "name": "Rubble_Aqua_Medium",
      "support": 15
    },
    {
      "x": -1,
      "y": 0,
      "z": 2,
      "name": "Rock_Aqua_Cobble"
    },
    {
      "x": -1,
      "y": 1,
      "z": 2,
      "name": "Rock_Aqua_Cobble"
    },
    {
      "x": -1,
      "y": 2,
      "z": 2,
      "name": "Rock_Aqua"
    },
    {
      "x": -1,
      "y": 3,
      "z": 2,
      "name": "Rock_Aqua"
    },
    {
      "x": -1,
      "y": 4,
      "z": 2,
      "name": "Rock_Aqua"
    },
    {
      "x": -1,
      "y": 5,
      "z": 2,
      "name": "Rock_Aqua_Cobble"
    },
    {
      "x": -1,
      "y": 6,
      "z": 2,
      "name": "Rock_Aqua_Cobble"
    },
    {
      "x": -1,
      "y": 7,
      "z": 2,
      "name": "Rock_Aqua_Cobble"
    },
    {
      "x": -1,
      "y": 8,
      "z": 2,
      "name": "Rock_Aqua_Cobble"
    },
    {
      "x": -1,
      "y": 9,
      "z": 2,
      "name": "Rock_Aqua_Cobble"
    },
    {
      "x": -1,
      "y": 10,
      "z": 2,
      "name": "Rock_Aqua_Cobble"
    },
    {
      "x": -1,
      "y": 0,
      "z": 3,
      "name": "Rock_Aqua_Cobble"
    },
    {
      "x": -1,
      "y": 1,
      "z": 3,
      "name": "Rock_Aqua_Cobble"
    },
    {
      "x": -1,
      "y": 2,
      "z": 3,
      "name": "Rock_Aqua"
    },
    {
      "x": -1,
      "y": 3,
      "z": 3,
      "name": "Rock_Aqua"
    },
    {
      "x": -1,
      "y": 4,
      "z": 3,
      "name": "Rock_Aqua_Cobble"
    },
    {
      "x": -1,
      "y": 5,
      "z": 3,
      "name": "Rock_Aqua_Cobble"
    },
    {
      "x": -1,
      "y": 6,
      "z": 3,
      "name": "Rock_Aqua_Cobble"
    },
    {
      "x": -1,
      "y": 7,
      "z": 3,
      "name": "Rock_Aqua_Cobble"
    },
    {
      "x": -1,
      "y": 8,
      "z": 3,
      "name": "Rock_Aqua_Cobble"
    },
    {
      "x": -1,
      "y": 9,
      "z": 3,
      "name": "Rock_Aqua_Cobble"
    },
    {
      "x": -1,
      "y": 10,
      "z": 3,
      "name": "Rock_Aqua_Cobble"
    },
    {
      "x": -1,
      "y": 0,
      "z": 4,
      "name": "Rock_Aqua_Cobble"
    },
    {
      "x": -1,
      "y": 1,
      "z": 4,
      "name": "Rock_Aqua_Cobble"
    },
    {
      "x": -1,
      "y": 2,
      "z": 4,
      "name": "Rock_Aqua"
    },
    {
      "x": -1,
      "y": 3,
      "z": 4,
      "name": "Rock_Aqua_Cobble"
    },
    {
      "x": -1,
      "y": 4,
      "z": 4,
      "name": "Rock_Aqua_Cobble"
    },
    {
      "x": -1,
      "y": 5,
      "z": 4,
      "name": "Rock_Aqua_Cobble"
    },
    {
      "x": -1,
      "y": 6,
      "z": 4,
      "name": "Rock_Aqua_Cobble"
    },
    {
      "x": -1,
      "y": 7,
      "z": 4,
      "name": "Rock_Aqua_Cobble"
    },
    {
      "x": -1,
      "y": 8,
      "z": 4,
      "name": "Rock_Aqua_Cobble"
    },
    {
      "x": -1,
      "y": 9,
      "z": 4,
      "name": "Rock_Aqua_Cobble"
    },
    {
      "x": -1,
      "y": 10,
      "z": 4,
      "name": "Rock_Aqua_Cobble"
    },
    {
      "x": -1,
      "y": 0,
      "z": 5,
      "name": "Rock_Aqua"
    },
    {
      "x": -1,
      "y": 1,
      "z": 5,
      "name": "Rock_Aqua_Cobble"
    },
    {
      "x": -1,
      "y": 2,
      "z": 5,
      "name": "Rock_Aqua_Cobble"
    },
    {
      "x": -1,
      "y": 3,
      "z": 5,
      "name": "Rock_Aqua_Cobble"
    },
    {
      "x": -1,
      "y": 4,
      "z": 5,
      "name": "Rock_Aqua_Cobble"
    },
    {
      "x": -1,
      "y": 5,
      "z": 5,
      "name": "Rock_Aqua_Cobble"
    },
    {
      "x": -1,
      "y": 6,
      "z": 5,
      "name": "Rock_Aqua_Cobble"
    },
    {
      "x": -1,
      "y": 7,
      "z": 5,
      "name": "Rock_Aqua_Cobble"
    },
    {
      "x": -1,
      "y": 8,
      "z": 5,
      "name": "Rock_Aqua"
    },
    {
      "x": -1,
      "y": 9,
      "z": 5,
      "name": "Rock_Aqua_Cobble"
    },
    {
      "x": -1,
      "y": 10,
      "z": 5,
      "name": "Rock_Aqua_Cobble"
    },
    {
      "x": -1,
      "y": 0,
      "z": 6,
      "name": "Rock_Aqua"
    },
    {
      "x": -1,
      "y": 1,
      "z": 6,
      "name": "Rock_Aqua"
    },
    {
      "x": -1,
      "y": 2,
      "z": 6,
      "name": "Rock_Aqua_Cobble"
    },
    {
      "x": -1,
      "y": 3,
      "z": 6,
      "name": "Rock_Aqua_Cobble"
    },
    {
      "x": -1,
      "y": 4,
      "z": 6,
      "name": "Rock_Aqua_Cobble"
    },
    {
      "x": -1,
      "y": 5,
      "z": 6,
      "name": "Rock_Aqua_Cobble"
    },
    {
      "x": -1,
      "y": 6,
      "z": 6,
      "name": "Rock_Aqua_Cobble"
    },
    {
      "x": -1,
      "y": 7,
      "z": 6,
      "name": "Rock_Aqua"
    },
    {
      "x": -1,
      "y": 8,
      "z": 6,
      "name": "Rock_Aqua"
    },
    {
      "x": -1,
      "y": 9,
      "z": 6,
      "name": "Rock_Aqua"
    },
    {
      "x": -1,
      "y": 10,
      "z": 6,
      "name": "Rock_Aqua_Cobble"
    },
    {
      "x": -1,
      "y": 2,
      "z": 7,
      "name": "Rock_Aqua_Cobble"
    },
    {
      "x": -1,
      "y": 3,
      "z": 7,
      "name": "Rock_Aqua_Cobble"
    },
    {
      "x": -1,
      "y": 4,
      "z": 7,
      "name": "Rock_Aqua_Cobble"
    },
    {
      "x": -1,
      "y": 5,
      "z": 7,
      "name": "Rock_Aqua_Cobble"
    },
    {
      "x": -1,
      "y": 6,
      "z": 7,
      "name": "Rock_Aqua_Cobble"
    },
    {
      "x": -1,
      "y": 7,
      "z": 7,
      "name": "Rock_Aqua_Cobble"
    },
    {
      "x": -1,
      "y": 8,
      "z": 7,
      "name": "Rock_Aqua"
    },
    {
      "x": -1,
      "y": 9,
      "z": 7,
      "name": "Rock_Aqua_Cobble"
    },
    {
      "x": 0,
      "y": 2,
      "z": -7,
      "name": "Rock_Aqua"
    },
    {
      "x": 0,
      "y": 3,
      "z": -7,
      "name": "Rock_Aqua"
    },
    {
      "x": 0,
      "y": 4,
      "z": -7,
      "name": "Rock_Aqua"
    },
    {
      "x": 0,
      "y": 5,
      "z": -7,
      "name": "Rock_Aqua_Cobble"
    },
    {
      "x": 0,
      "y": 6,
      "z": -7,
      "name": "Rock_Aqua_Cobble"
    },
    {
      "x": 0,
      "y": 0,
      "z": -6,
      "name": "Rock_Aqua"
    },
    {
      "x": 0,
      "y": 1,
      "z": -6,
      "name": "Rock_Aqua"
    },
    {
      "x": 0,
      "y": 2,
      "z": -6,
      "name": "Rock_Aqua"
    },
    {
      "x": 0,
      "y": 3,
      "z": -6,
      "name": "Rock_Aqua"
    },
    {
      "x": 0,
      "y": 4,
      "z": -6,
      "name": "Rock_Aqua"
    },
    {
      "x": 0,
      "y": 5,
      "z": -6,
      "name": "Rock_Aqua"
    },
    {
      "x": 0,
      "y": 6,
      "z": -6,
      "name": "Rock_Aqua_Cobble"
    },
    {
      "x": 0,
      "y": 7,
      "z": -6,
      "name": "Rock_Aqua_Cobble"
    },
    {
      "x": 0,
      "y": 8,
      "z": -6,
      "name": "Rock_Aqua_Cobble"
    },
    {
      "x": 0,
      "y": 0,
      "z": -5,
      "name": "Rock_Aqua"
    },
    {
      "x": 0,
      "y": 1,
      "z": -5,
      "name": "Rock_Aqua"
    },
    {
      "x": 0,
      "y": 2,
      "z": -5,
      "name": "Rock_Aqua"
    },
    {
      "x": 0,
      "y": 3,
      "z": -5,
      "name": "Rock_Aqua"
    },
    {
      "x": 0,
      "y": 4,
      "z": -5,
      "name": "Rock_Aqua"
    },
    {
      "x": 0,
      "y": 5,
      "z": -5,
      "name": "Rock_Aqua"
    },
    {
      "x": 0,
      "y": 6,
      "z": -5,
      "name": "Rock_Aqua_Cobble"
    },
    {
      "x": 0,
      "y": 7,
      "z": -5,
      "name": "Rock_Aqua_Cobble"
    },
    {
      "x": 0,
      "y": 8,
      "z": -5,
      "name": "Rock_Aqua_Cobble"
    },
    {
      "x": 0,
      "y": 0,
      "z": -4,
      "name": "Rock_Aqua"
    },
    {
      "x": 0,
      "y": 1,
      "z": -4,
      "name": "Rock_Aqua"
    },
    {
      "x": 0,
      "y": 2,
      "z": -4,
      "name": "Rock_Aqua"
    },
    {
      "x": 0,
      "y": 3,
      "z": -4,
      "name": "Rock_Aqua"
    },
    {
      "x": 0,
      "y": 4,
      "z": -4,
      "name": "Rock_Aqua"
    },
    {
      "x": 0,
      "y": 5,
      "z": -4,
      "name": "Rock_Aqua"
    },
    {
      "x": 0,
      "y": 6,
      "z": -4,
      "name": "Rock_Aqua_Cobble"
    },
    {
      "x": 0,
      "y": 7,
      "z": -4,
      "name": "Rock_Aqua_Cobble"
    },
    {
      "x": 0,
      "y": 8,
      "z": -4,
      "name": "Rock_Aqua"
    },
    {
      "x": 0,
      "y": 0,
      "z": -3,
      "name": "Rock_Aqua"
    },
    {
      "x": 0,
      "y": 1,
      "z": -3,
      "name": "Rock_Aqua"
    },
    {
      "x": 0,
      "y": 2,
      "z": -3,
      "name": "Rock_Aqua"
    },
    {
      "x": 0,
      "y": 3,
      "z": -3,
      "name": "Rock_Aqua"
    },
    {
      "x": 0,
      "y": 4,
      "z": -3,
      "name": "Rock_Aqua"
    },
    {
      "x": 0,
      "y": 5,
      "z": -3,
      "name": "Rock_Aqua_Cobble"
    },
    {
      "x": 0,
      "y": 6,
      "z": -3,
      "name": "Rock_Aqua_Cobble"
    },
    {
      "x": 0,
      "y": 7,
      "z": -3,
      "name": "Rock_Aqua"
    },
    {
      "x": 0,
      "y": 8,
      "z": -3,
      "name": "Rock_Aqua"
    },
    {
      "x": 0,
      "y": 0,
      "z": -2,
      "name": "Rock_Aqua"
    },
    {
      "x": 0,
      "y": 1,
      "z": -2,
      "name": "Rock_Aqua"
    },
    {
      "x": 0,
      "y": 2,
      "z": -2,
      "name": "Rock_Aqua"
    },
    {
      "x": 0,
      "y": 3,
      "z": -2,
      "name": "Rock_Aqua"
    },
    {
      "x": 0,
      "y": 4,
      "z": -2,
      "name": "Rock_Aqua"
    },
    {
      "x": 0,
      "y": 5,
      "z": -2,
      "name": "Rock_Aqua"
    },
    {
      "x": 0,
      "y": 6,
      "z": -2,
      "name": "Rock_Aqua"
    },
    {
      "x": 0,
      "y": 7,
      "z": -2,
      "name": "Rock_Aqua"
    },
    {
      "x": 0,
      "y": 8,
      "z": -2,
      "name": "Rock_Aqua"
    },
    {
      "x": 0,
      "y": 0,
      "z": -1,
      "name": "Rock_Aqua"
    },
    {
      "x": 0,
      "y": 1,
      "z": -1,
      "name": "Rock_Aqua_Cobble"
    },
    {
      "x": 0,
      "y": 2,
      "z": -1,
      "name": "Rock_Aqua"
    },
    {
      "x": 0,
      "y": 3,
      "z": -1,
      "name": "Rock_Aqua"
    },
    {
      "x": 0,
      "y": 4,
      "z": -1,
      "name": "Rock_Aqua"
    },
    {
      "x": 0,
      "y": 5,
      "z": -1,
      "name": "Rock_Aqua_Cobble"
    },
    {
      "x": 0,
      "y": 6,
      "z": -1,
      "name": "Rock_Aqua_Cobble"
    },
    {
      "x": 0,
      "y": 7,
      "z": -1,
      "name": "Rock_Aqua"
    },
    {
      "x": 0,
      "y": 8,
      "z": -1,
      "name": "Rock_Aqua"
    },
    {
      "x": 0,
      "y": 0,
      "z": 0,
      "name": "Rock_Aqua_Cobble"
    },
    {
      "x": 0,
      "y": 1,
      "z": 0,
      "name": "Rock_Aqua_Cobble"
    },
    {
      "x": 0,
      "y": 2,
      "z": 0,
      "name": "Rock_Aqua"
    },
    {
      "x": 0,
      "y": 3,
      "z": 0,
      "name": "Rock_Aqua"
    },
    {
      "x": 0,
      "y": 4,
      "z": 0,
      "name": "Rock_Aqua_Cobble"
    },
    {
      "x": 0,
      "y": 5,
      "z": 0,
      "name": "Rock_Aqua_Cobble"
    },
    {
      "x": 0,
      "y": 6,
      "z": 0,
      "name": "Rock_Aqua_Cobble"
    },
    {
      "x": 0,
      "y": 7,
      "z": 0,
      "name": "Rock_Aqua_Cobble"
    },
    {
      "x": 0,
      "y": 8,
      "z": 0,
      "name": "Rock_Aqua"
    },
    {
      "x": 0,
      "y": 9,
      "z": 0,
      "name": "Rock_Aqua_Cobble"
    },
    {
      "x": 0,
      "y": 0,
      "z": 1,
      "name": "Rock_Aqua_Cobble"
    },
    {
      "x": 0,
      "y": 1,
      "z": 1,
      "name": "Rock_Aqua_Cobble"
    },
    {
      "x": 0,
      "y": 2,
      "z": 1,
      "name": "Rock_Aqua"
    },
    {
      "x": 0,
      "y": 3,
      "z": 1,
      "name": "Rock_Aqua"
    },
    {
      "x": 0,
      "y": 4,
      "z": 1,
      "name": "Rock_Aqua"
    },
    {
      "x": 0,
      "y": 5,
      "z": 1,
      "name": "Rock_Aqua_Cobble"
    },
    {
      "x": 0,
      "y": 6,
      "z": 1,
      "name": "Rock_Aqua_Cobble"
    },
    {
      "x": 0,
      "y": 7,
      "z": 1,
      "name": "Rock_Aqua_Cobble"
    },
    {
      "x": 0,
      "y": 8,
      "z": 1,
      "name": "Rock_Aqua_Cobble"
    },
    {
      "x": 0,
      "y": 9,
      "z": 1,
      "name": "Rock_Aqua_Cobble"
    },
    {
      "x": 0,
      "y": 0,
      "z": 2,
      "name": "Rock_Aqua_Cobble"
    },
    {
      "x": 0,
      "y": 1,
      "z": 2,
      "name": "Rock_Aqua_Cobble"
    },
    {
      "x": 0,
      "y": 2,
      "z": 2,
      "name": "Rock_Aqua"
    },
    {
      "x": 0,
      "y": 3,
      "z": 2,
      "name": "Rock_Aqua"
    },
    {
      "x": 0,
      "y": 4,
      "z": 2,
      "name": "Rock_Aqua"
    },
    {
      "x": 0,
      "y": 5,
      "z": 2,
      "name": "Rock_Aqua_Cobble"
    },
    {
      "x": 0,
      "y": 6,
      "z": 2,
      "name": "Rock_Aqua_Cobble"
    },
    {
      "x": 0,
      "y": 7,
      "z": 2,
      "name": "Rock_Aqua_Cobble"
    },
    {
      "x": 0,
      "y": 8,
      "z": 2,
      "name": "Rock_Aqua_Cobble"
    },
    {
      "x": 0,
      "y": 9,
      "z": 2,
      "name": "Rock_Aqua_Cobble"
    },
    {
      "x": 0,
      "y": 10,
      "z": 2,
      "name": "Rock_Aqua_Cobble"
    },
    {
      "x": 0,
      "y": 0,
      "z": 3,
      "name": "Rock_Aqua_Cobble"
    },
    {
      "x": 0,
      "y": 1,
      "z": 3,
      "name": "Rock_Aqua_Cobble"
    },
    {
      "x": 0,
      "y": 2,
      "z": 3,
      "name": "Rock_Aqua"
    },
    {
      "x": 0,
      "y": 3,
      "z": 3,
      "name": "Rock_Aqua"
    },
    {
      "x": 0,
      "y": 4,
      "z": 3,
      "name": "Rock_Aqua"
    },
    {
      "x": 0,
      "y": 5,
      "z": 3,
      "name": "Rock_Aqua_Cobble"
    },
    {
      "x": 0,
      "y": 6,
      "z": 3,
      "name": "Rock_Aqua_Cobble"
    },
    {
      "x": 0,
      "y": 7,
      "z": 3,
      "name": "Rock_Aqua_Cobble"
    },
    {
      "x": 0,
      "y": 8,
      "z": 3,
      "name": "Rock_Aqua_Cobble"
    },
    {
      "x": 0,
      "y": 9,
      "z": 3,
      "name": "Rock_Aqua_Cobble"
    },
    {
      "x": 0,
      "y": 10,
      "z": 3,
      "name": "Rock_Aqua_Cobble"
    },
    {
      "x": 0,
      "y": 0,
      "z": 4,
      "name": "Rock_Aqua"
    },
    {
      "x": 0,
      "y": 1,
      "z": 4,
      "name": "Rock_Aqua_Cobble"
    },
    {
      "x": 0,
      "y": 2,
      "z": 4,
      "name": "Rock_Aqua"
    },
    {
      "x": 0,
      "y": 3,
      "z": 4,
      "name": "Rock_Aqua"
    },
    {
      "x": 0,
      "y": 4,
      "z": 4,
      "name": "Rock_Aqua_Cobble"
    },
    {
      "x": 0,
      "y": 5,
      "z": 4,
      "name": "Rock_Aqua_Cobble"
    },
    {
      "x": 0,
      "y": 6,
      "z": 4,
      "name": "Rock_Aqua_Cobble"
    },
    {
      "x": 0,
      "y": 7,
      "z": 4,
      "name": "Rock_Aqua_Cobble"
    },
    {
      "x": 0,
      "y": 8,
      "z": 4,
      "name": "Rock_Aqua_Cobble"
    },
    {
      "x": 0,
      "y": 9,
      "z": 4,
      "name": "Rock_Aqua_Cobble"
    },
    {
      "x": 0,
      "y": 10,
      "z": 4,
      "name": "Rock_Aqua_Cobble"
    },
    {
      "x": 0,
      "y": 0,
      "z": 5,
      "name": "Rock_Aqua"
    },
    {
      "x": 0,
      "y": 1,
      "z": 5,
      "name": "Rock_Aqua"
    },
    {
      "x": 0,
      "y": 2,
      "z": 5,
      "name": "Rock_Aqua_Cobble"
    },
    {
      "x": 0,
      "y": 3,
      "z": 5,
      "name": "Rock_Aqua_Cobble"
    },
    {
      "x": 0,
      "y": 4,
      "z": 5,
      "name": "Rock_Aqua_Cobble"
    },
    {
      "x": 0,
      "y": 5,
      "z": 5,
      "name": "Rock_Aqua_Cobble"
    },
    {
      "x": 0,
      "y": 6,
      "z": 5,
      "name": "Rock_Aqua_Cobble"
    },
    {
      "x": 0,
      "y": 7,
      "z": 5,
      "name": "Rock_Aqua_Cobble"
    },
    {
      "x": 0,
      "y": 8,
      "z": 5,
      "name": "Rock_Aqua_Cobble"
    },
    {
      "x": 0,
      "y": 9,
      "z": 5,
      "name": "Rock_Aqua_Cobble"
    },
    {
      "x": 0,
      "y": 10,
      "z": 5,
      "name": "Rock_Aqua_Cobble"
    },
    {
      "x": 0,
      "y": 0,
      "z": 6,
      "name": "Rock_Aqua"
    },
    {
      "x": 0,
      "y": 1,
      "z": 6,
      "name": "Rock_Aqua"
    },
    {
      "x": 0,
      "y": 2,
      "z": 6,
      "name": "Rock_Aqua"
    },
    {
      "x": 0,
      "y": 3,
      "z": 6,
      "name": "Rock_Aqua_Cobble"
    },
    {
      "x": 0,
      "y": 4,
      "z": 6,
      "name": "Rock_Aqua_Cobble"
    },
    {
      "x": 0,
      "y": 5,
      "z": 6,
      "name": "Rock_Aqua_Cobble"
    },
    {
      "x": 0,
      "y": 6,
      "z": 6,
      "name": "Rock_Aqua_Cobble"
    },
    {
      "x": 0,
      "y": 7,
      "z": 6,
      "name": "Rock_Aqua_Cobble"
    },
    {
      "x": 0,
      "y": 8,
      "z": 6,
      "name": "Rock_Aqua_Cobble"
    },
    {
      "x": 0,
      "y": 9,
      "z": 6,
      "name": "Rock_Aqua_Cobble"
    },
    {
      "x": 0,
      "y": 10,
      "z": 6,
      "name": "Rock_Aqua_Cobble"
    },
    {
      "x": 0,
      "y": 2,
      "z": 7,
      "name": "Rock_Aqua_Cobble"
    },
    {
      "x": 0,
      "y": 3,
      "z": 7,
      "name": "Rock_Aqua_Cobble"
    },
    {
      "x": 0,
      "y": 4,
      "z": 7,
      "name": "Rock_Aqua_Cobble"
    },
    {
      "x": 0,
      "y": 5,
      "z": 7,
      "name": "Rock_Aqua_Cobble"
    },
    {
      "x": 0,
      "y": 6,
      "z": 7,
      "name": "Rock_Aqua_Cobble"
    },
    {
      "x": 0,
      "y": 7,
      "z": 7,
      "name": "Rock_Aqua_Cobble"
    },
    {
      "x": 0,
      "y": 8,
      "z": 7,
      "name": "Rock_Aqua_Cobble"
    },
    {
      "x": 0,
      "y": 9,
      "z": 7,
      "name": "Rock_Aqua_Cobble"
    },
    {
      "x": 1,
      "y": 2,
      "z": -7,
      "name": "Rock_Aqua"
    },
    {
      "x": 1,
      "y": 3,
      "z": -7,
      "name": "Rock_Aqua"
    },
    {
      "x": 1,
      "y": 4,
      "z": -7,
      "name": "Rock_Aqua"
    },
    {
      "x": 1,
      "y": 5,
      "z": -7,
      "name": "Rock_Aqua_Cobble"
    },
    {
      "x": 1,
      "y": 6,
      "z": -7,
      "name": "Rock_Aqua_Cobble"
    },
    {
      "x": 1,
      "y": 7,
      "z": -7,
      "name": "Rock_Aqua_Cobble"
    },
    {
      "x": 1,
      "y": 0,
      "z": -6,
      "name": "Rock_Aqua"
    },
    {
      "x": 1,
      "y": 1,
      "z": -6,
      "name": "Rock_Aqua"
    },
    {
      "x": 1,
      "y": 2,
      "z": -6,
      "name": "Rock_Aqua"
    },
    {
      "x": 1,
      "y": 3,
      "z": -6,
      "name": "Rock_Aqua"
    },
    {
      "x": 1,
      "y": 4,
      "z": -6,
      "name": "Rock_Aqua"
    },
    {
      "x": 1,
      "y": 5,
      "z": -6,
      "name": "Rock_Aqua_Cobble"
    },
    {
      "x": 1,
      "y": 6,
      "z": -6,
      "name": "Rock_Aqua_Cobble"
    },
    {
      "x": 1,
      "y": 7,
      "z": -6,
      "name": "Rock_Aqua_Cobble"
    },
    {
      "x": 1,
      "y": 8,
      "z": -6,
      "name": "Rock_Aqua_Cobble"
    },
    {
      "x": 1,
      "y": 0,
      "z": -5,
      "name": "Rock_Aqua"
    },
    {
      "x": 1,
      "y": 1,
      "z": -5,
      "name": "Rock_Aqua"
    },
    {
      "x": 1,
      "y": 2,
      "z": -5,
      "name": "Rock_Aqua"
    },
    {
      "x": 1,
      "y": 3,
      "z": -5,
      "name": "Rock_Aqua"
    },
    {
      "x": 1,
      "y": 4,
      "z": -5,
      "name": "Rock_Aqua"
    },
    {
      "x": 1,
      "y": 5,
      "z": -5,
      "name": "Rock_Aqua"
    },
    {
      "x": 1,
      "y": 6,
      "z": -5,
      "name": "Rock_Aqua_Cobble"
    },
    {
      "x": 1,
      "y": 7,
      "z": -5,
      "name": "Rock_Aqua_Cobble"
    },
    {
      "x": 1,
      "y": 8,
      "z": -5,
      "name": "Rock_Aqua_Cobble"
    },
    {
      "x": 1,
      "y": 0,
      "z": -4,
      "name": "Rock_Aqua"
    },
    {
      "x": 1,
      "y": 1,
      "z": -4,
      "name": "Rock_Aqua"
    },
    {
      "x": 1,
      "y": 2,
      "z": -4,
      "name": "Rock_Aqua"
    },
    {
      "x": 1,
      "y": 3,
      "z": -4,
      "name": "Rock_Aqua"
    },
    {
      "x": 1,
      "y": 4,
      "z": -4,
      "name": "Rock_Aqua"
    },
    {
      "x": 1,
      "y": 5,
      "z": -4,
      "name": "Rock_Aqua_Cobble"
    },
    {
      "x": 1,
      "y": 6,
      "z": -4,
      "name": "Rock_Aqua_Cobble"
    },
    {
      "x": 1,
      "y": 7,
      "z": -4,
      "name": "Rock_Aqua_Cobble"
    },
    {
      "x": 1,
      "y": 8,
      "z": -4,
      "name": "Rock_Aqua_Cobble"
    },
    {
      "x": 1,
      "y": 0,
      "z": -3,
      "name": "Rock_Aqua"
    },
    {
      "x": 1,
      "y": 1,
      "z": -3,
      "name": "Rock_Aqua"
    },
    {
      "x": 1,
      "y": 2,
      "z": -3,
      "name": "Rock_Aqua"
    },
    {
      "x": 1,
      "y": 3,
      "z": -3,
      "name": "Rock_Aqua"
    },
    {
      "x": 1,
      "y": 4,
      "z": -3,
      "name": "Rock_Aqua"
    },
    {
      "x": 1,
      "y": 5,
      "z": -3,
      "name": "Rock_Aqua_Cobble"
    },
    {
      "x": 1,
      "y": 6,
      "z": -3,
      "name": "Rock_Aqua_Cobble"
    },
    {
      "x": 1,
      "y": 7,
      "z": -3,
      "name": "Rock_Aqua_Cobble"
    },
    {
      "x": 1,
      "y": 8,
      "z": -3,
      "name": "Rock_Aqua"
    },
    {
      "x": 1,
      "y": 0,
      "z": -2,
      "name": "Rock_Aqua"
    },
    {
      "x": 1,
      "y": 1,
      "z": -2,
      "name": "Rock_Aqua"
    },
    {
      "x": 1,
      "y": 2,
      "z": -2,
      "name": "Rock_Aqua"
    },
    {
      "x": 1,
      "y": 3,
      "z": -2,
      "name": "Rock_Aqua"
    },
    {
      "x": 1,
      "y": 4,
      "z": -2,
      "name": "Rock_Aqua"
    },
    {
      "x": 1,
      "y": 5,
      "z": -2,
      "name": "Rock_Aqua_Cobble"
    },
    {
      "x": 1,
      "y": 6,
      "z": -2,
      "name": "Rock_Aqua_Cobble"
    },
    {
      "x": 1,
      "y": 7,
      "z": -2,
      "name": "Rock_Aqua"
    },
    {
      "x": 1,
      "y": 8,
      "z": -2,
      "name": "Rock_Aqua"
    },
    {
      "x": 1,
      "y": 0,
      "z": -1,
      "name": "Rock_Aqua"
    },
    {
      "x": 1,
      "y": 1,
      "z": -1,
      "name": "Rock_Aqua"
    },
    {
      "x": 1,
      "y": 2,
      "z": -1,
      "name": "Rock_Aqua"
    },
    {
      "x": 1,
      "y": 3,
      "z": -1,
      "name": "Rock_Aqua"
    },
    {
      "x": 1,
      "y": 4,
      "z": -1,
      "name": "Rock_Aqua"
    },
    {
      "x": 1,
      "y": 5,
      "z": -1,
      "name": "Rock_Aqua_Cobble"
    },
    {
      "x": 1,
      "y": 6,
      "z": -1,
      "name": "Rock_Aqua_Cobble"
    },
    {
      "x": 1,
      "y": 7,
      "z": -1,
      "name": "Rock_Aqua_Cobble"
    },
    {
      "x": 1,
      "y": 8,
      "z": -1,
      "name": "Rock_Aqua"
    },
    {
      "x": 1,
      "y": 0,
      "z": 0,
      "name": "Rock_Aqua"
    },
    {
      "x": 1,
      "y": 1,
      "z": 0,
      "name": "Rock_Aqua_Cobble"
    },
    {
      "x": 1,
      "y": 2,
      "z": 0,
      "name": "Rock_Aqua"
    },
    {
      "x": 1,
      "y": 3,
      "z": 0,
      "name": "Rock_Aqua"
    },
    {
      "x": 1,
      "y": 4,
      "z": 0,
      "name": "Rock_Aqua"
    },
    {
      "x": 1,
      "y": 5,
      "z": 0,
      "name": "Rock_Aqua_Cobble"
    },
    {
      "x": 1,
      "y": 6,
      "z": 0,
      "name": "Rock_Aqua_Cobble"
    },
    {
      "x": 1,
      "y": 7,
      "z": 0,
      "name": "Rock_Aqua_Cobble"
    },
    {
      "x": 1,
      "y": 8,
      "z": 0,
      "name": "Rock_Aqua_Cobble"
    },
    {
      "x": 1,
      "y": 9,
      "z": 0,
      "name": "Rock_Aqua_Cobble"
    },
    {
      "x": 1,
      "y": 0,
      "z": 1,
      "name": "Rock_Aqua_Cobble"
    },
    {
      "x": 1,
      "y": 1,
      "z": 1,
      "name": "Rock_Aqua_Cobble"
    },
    {
      "x": 1,
      "y": 2,
      "z": 1,
      "name": "Rock_Aqua"
    },
    {
      "x": 1,
      "y": 3,
      "z": 1,
      "name": "Rock_Aqua"
    },
    {
      "x": 1,
      "y": 4,
      "z": 1,
      "name": "Rock_Aqua"
    },
    {
      "x": 1,
      "y": 5,
      "z": 1,
      "name": "Rock_Aqua_Cobble"
    },
    {
      "x": 1,
      "y": 6,
      "z": 1,
      "name": "Rock_Aqua_Cobble"
    },
    {
      "x": 1,
      "y": 7,
      "z": 1,
      "name": "Rock_Aqua_Cobble"
    },
    {
      "x": 1,
      "y": 8,
      "z": 1,
      "name": "Rock_Aqua_Cobble"
    },
    {
      "x": 1,
      "y": 9,
      "z": 1,
      "name": "Rock_Aqua_Cobble"
    },
    {
      "x": 1,
      "y": 0,
      "z": 2,
      "name": "Rock_Aqua_Cobble"
    },
    {
      "x": 1,
      "y": 1,
      "z": 2,
      "name": "Rock_Aqua_Cobble"
    },
    {
      "x": 1,
      "y": 2,
      "z": 2,
      "name": "Rock_Aqua"
    },
    {
      "x": 1,
      "y": 3,
      "z": 2,
      "name": "Rock_Aqua"
    },
    {
      "x": 1,
      "y": 4,
      "z": 2,
      "name": "Rock_Aqua"
    },
    {
      "x": 1,
      "y": 5,
      "z": 2,
      "name": "Rock_Aqua_Cobble"
    },
    {
      "x": 1,
      "y": 6,
      "z": 2,
      "name": "Rock_Aqua_Cobble"
    },
    {
      "x": 1,
      "y": 7,
      "z": 2,
      "name": "Rock_Aqua_Cobble"
    },
    {
      "x": 1,
      "y": 8,
      "z": 2,
      "name": "Rock_Aqua_Cobble"
    },
    {
      "x": 1,
      "y": 9,
      "z": 2,
      "name": "Rock_Aqua_Cobble"
    },
    {
      "x": 1,
      "y": 10,
      "z": 2,
      "name": "Rock_Aqua_Cobble"
    },
    {
      "x": 1,
      "y": 0,
      "z": 3,
      "name": "Rock_Aqua_Cobble"
    },
    {
      "x": 1,
      "y": 1,
      "z": 3,
      "name": "Rock_Aqua_Cobble"
    },
    {
      "x": 1,
      "y": 2,
      "z": 3,
      "name": "Rock_Aqua"
    },
    {
      "x": 1,
      "y": 3,
      "z": 3,
      "name": "Rock_Aqua"
    },
    {
      "x": 1,
      "y": 4,
      "z": 3,
      "name": "Rock_Aqua_Cobble"
    },
    {
      "x": 1,
      "y": 5,
      "z": 3,
      "name": "Rock_Aqua_Cobble"
    },
    {
      "x": 1,
      "y": 6,
      "z": 3,
      "name": "Rock_Aqua_Cobble"
    },
    {
      "x": 1,
      "y": 7,
      "z": 3,
      "name": "Rock_Aqua_Cobble"
    },
    {
      "x": 1,
      "y": 8,
      "z": 3,
      "name": "Rock_Aqua_Cobble"
    },
    {
      "x": 1,
      "y": 9,
      "z": 3,
      "name": "Rock_Aqua_Cobble"
    },
    {
      "x": 1,
      "y": 10,
      "z": 3,
      "name": "Rock_Aqua_Cobble"
    },
    {
      "x": 1,
      "y": 0,
      "z": 4,
      "name": "Rock_Aqua"
    },
    {
      "x": 1,
      "y": 1,
      "z": 4,
      "name": "Rock_Aqua"
    },
    {
      "x": 1,
      "y": 2,
      "z": 4,
      "name": "Rock_Aqua"
    },
    {
      "x": 1,
      "y": 3,
      "z": 4,
      "name": "Rock_Aqua_Cobble"
    },
    {
      "x": 1,
      "y": 4,
      "z": 4,
      "name": "Rock_Aqua_Cobble"
    },
    {
      "x": 1,
      "y": 5,
      "z": 4,
      "name": "Rock_Aqua_Cobble"
    },
    {
      "x": 1,
      "y": 6,
      "z": 4,
      "name": "Rock_Aqua_Cobble"
    },
    {
      "x": 1,
      "y": 7,
      "z": 4,
      "name": "Rock_Aqua_Cobble"
    },
    {
      "x": 1,
      "y": 8,
      "z": 4,
      "name": "Rock_Aqua_Cobble"
    },
    {
      "x": 1,
      "y": 9,
      "z": 4,
      "name": "Rock_Aqua_Cobble"
    },
    {
      "x": 1,
      "y": 10,
      "z": 4,
      "name": "Rock_Aqua_Cobble"
    },
    {
      "x": 1,
      "y": 0,
      "z": 5,
      "name": "Rock_Aqua"
    },
    {
      "x": 1,
      "y": 1,
      "z": 5,
      "name": "Rock_Aqua"
    },
    {
      "x": 1,
      "y": 2,
      "z": 5,
      "name": "Rock_Aqua"
    },
    {
      "x": 1,
      "y": 3,
      "z": 5,
      "name": "Rock_Aqua_Cobble"
    },
    {
      "x": 1,
      "y": 4,
      "z": 5,
      "name": "Rock_Aqua_Cobble"
    },
    {
      "x": 1,
      "y": 5,
      "z": 5,
      "name": "Rock_Aqua_Cobble"
    },
    {
      "x": 1,
      "y": 6,
      "z": 5,
      "name": "Rock_Aqua_Cobble"
    },
    {
      "x": 1,
      "y": 7,
      "z": 5,
      "name": "Rock_Aqua_Cobble"
    },
    {
      "x": 1,
      "y": 8,
      "z": 5,
      "name": "Rock_Aqua_Cobble"
    },
    {
      "x": 1,
      "y": 9,
      "z": 5,
      "name": "Rock_Aqua_Cobble"
    },
    {
      "x": 1,
      "y": 10,
      "z": 5,
      "name": "Rock_Aqua_Cobble"
    },
    {
      "x": 1,
      "y": 0,
      "z": 6,
      "name": "Rock_Aqua"
    },
    {
      "x": 1,
      "y": 1,
      "z": 6,
      "name": "Rock_Aqua"
    },
    {
      "x": 1,
      "y": 2,
      "z": 6,
      "name": "Rock_Aqua"
    },
    {
      "x": 1,
      "y": 3,
      "z": 6,
      "name": "Rock_Aqua_Cobble"
    },
    {
      "x": 1,
      "y": 4,
      "z": 6,
      "name": "Rock_Aqua_Cobble"
    },
    {
      "x": 1,
      "y": 5,
      "z": 6,
      "name": "Rock_Aqua_Cobble"
    },
    {
      "x": 1,
      "y": 6,
      "z": 6,
      "name": "Rock_Aqua_Cobble"
    },
    {
      "x": 1,
      "y": 7,
      "z": 6,
      "name": "Rock_Aqua_Cobble"
    },
    {
      "x": 1,
      "y": 8,
      "z": 6,
      "name": "Rock_Aqua_Cobble"
    },
    {
      "x": 1,
      "y": 9,
      "z": 6,
      "name": "Rock_Aqua_Cobble"
    },
    {
      "x": 1,
      "y": 10,
      "z": 6,
      "name": "Rock_Aqua_Cobble"
    },
    {
      "x": 1,
      "y": 3,
      "z": 7,
      "name": "Rock_Aqua_Cobble"
    },
    {
      "x": 1,
      "y": 4,
      "z": 7,
      "name": "Rock_Aqua_Cobble"
    },
    {
      "x": 1,
      "y": 5,
      "z": 7,
      "name": "Rock_Aqua_Cobble"
    },
    {
      "x": 1,
      "y": 6,
      "z": 7,
      "name": "Rock_Aqua_Cobble"
    },
    {
      "x": 1,
      "y": 7,
      "z": 7,
      "name": "Rock_Aqua_Cobble"
    },
    {
      "x": 2,
      "y": 4,
      "z": -7,
      "name": "Rock_Aqua_Cobble"
    },
    {
      "x": 2,
      "y": 5,
      "z": -7,
      "name": "Rock_Aqua_Cobble"
    },
    {
      "x": 2,
      "y": 6,
      "z": -7,
      "name": "Rock_Aqua_Cobble"
    },
    {
      "x": 2,
      "y": 7,
      "z": -7,
      "name": "Rock_Aqua_Cobble"
    },
    {
      "x": 2,
      "y": 0,
      "z": -6,
      "name": "Rock_Aqua"
    },
    {
      "x": 2,
      "y": 1,
      "z": -6,
      "name": "Rock_Aqua"
    },
    {
      "x": 2,
      "y": 2,
      "z": -6,
      "name": "Rock_Aqua"
    },
    {
      "x": 2,
      "y": 3,
      "z": -6,
      "name": "Rock_Aqua"
    },
    {
      "x": 2,
      "y": 4,
      "z": -6,
      "name": "Rock_Aqua"
    },
    {
      "x": 2,
      "y": 5,
      "z": -6,
      "name": "Rock_Aqua_Cobble"
    },
    {
      "x": 2,
      "y": 6,
      "z": -6,
      "name": "Rock_Aqua_Cobble"
    },
    {
      "x": 2,
      "y": 7,
      "z": -6,
      "name": "Rock_Aqua_Cobble"
    },
    {
      "x": 2,
      "y": 8,
      "z": -6,
      "name": "Rock_Aqua_Cobble"
    },
    {
      "x": 2,
      "y": 0,
      "z": -5,
      "name": "Rock_Aqua"
    },
    {
      "x": 2,
      "y": 1,
      "z": -5,
      "name": "Rock_Aqua"
    },
    {
      "x": 2,
      "y": 2,
      "z": -5,
      "name": "Rock_Aqua"
    },
    {
      "x": 2,
      "y": 3,
      "z": -5,
      "name": "Rock_Aqua"
    },
    {
      "x": 2,
      "y": 4,
      "z": -5,
      "name": "Rock_Aqua"
    },
    {
      "x": 2,
      "y": 5,
      "z": -5,
      "name": "Rock_Aqua_Cobble"
    },
    {
      "x": 2,
      "y": 6,
      "z": -5,
      "name": "Rock_Aqua_Cobble"
    },
    {
      "x": 2,
      "y": 7,
      "z": -5,
      "name": "Rock_Aqua_Cobble"
    },
    {
      "x": 2,
      "y": 8,
      "z": -5,
      "name": "Rock_Aqua_Cobble"
    },
    {
      "x": 2,
      "y": 0,
      "z": -4,
      "name": "Rock_Aqua"
    },
    {
      "x": 2,
      "y": 1,
      "z": -4,
      "name": "Rock_Aqua"
    },
    {
      "x": 2,
      "y": 2,
      "z": -4,
      "name": "Rock_Aqua"
    },
    {
      "x": 2,
      "y": 3,
      "z": -4,
      "name": "Rock_Aqua"
    },
    {
      "x": 2,
      "y": 4,
      "z": -4,
      "name": "Rock_Aqua"
    },
    {
      "x": 2,
      "y": 5,
      "z": -4,
      "name": "Rock_Aqua_Cobble"
    },
    {
      "x": 2,
      "y": 6,
      "z": -4,
      "name": "Rock_Aqua_Cobble"
    },
    {
      "x": 2,
      "y": 7,
      "z": -4,
      "name": "Rock_Aqua_Cobble"
    },
    {
      "x": 2,
      "y": 8,
      "z": -4,
      "name": "Rock_Aqua_Cobble"
    },
    {
      "x": 2,
      "y": 0,
      "z": -3,
      "name": "Rock_Aqua"
    },
    {
      "x": 2,
      "y": 1,
      "z": -3,
      "name": "Rock_Aqua"
    },
    {
      "x": 2,
      "y": 2,
      "z": -3,
      "name": "Rock_Aqua"
    },
    {
      "x": 2,
      "y": 3,
      "z": -3,
      "name": "Rock_Aqua"
    },
    {
      "x": 2,
      "y": 4,
      "z": -3,
      "name": "Rock_Aqua"
    },
    {
      "x": 2,
      "y": 5,
      "z": -3,
      "name": "Rock_Aqua_Cobble"
    },
    {
      "x": 2,
      "y": 6,
      "z": -3,
      "name": "Rock_Aqua_Cobble"
    },
    {
      "x": 2,
      "y": 7,
      "z": -3,
      "name": "Rock_Aqua_Cobble"
    },
    {
      "x": 2,
      "y": 8,
      "z": -3,
      "name": "Rock_Aqua_Cobble"
    },
    {
      "x": 2,
      "y": 0,
      "z": -2,
      "name": "Rock_Aqua"
    },
    {
      "x": 2,
      "y": 1,
      "z": -2,
      "name": "Rock_Aqua"
    },
    {
      "x": 2,
      "y": 2,
      "z": -2,
      "name": "Rock_Aqua"
    },
    {
      "x": 2,
      "y": 3,
      "z": -2,
      "name": "Rock_Aqua"
    },
    {
      "x": 2,
      "y": 4,
      "z": -2,
      "name": "Rock_Aqua"
    },
    {
      "x": 2,
      "y": 5,
      "z": -2,
      "name": "Rock_Aqua_Cobble"
    },
    {
      "x": 2,
      "y": 6,
      "z": -2,
      "name": "Rock_Aqua_Cobble"
    },
    {
      "x": 2,
      "y": 7,
      "z": -2,
      "name": "Rock_Aqua_Cobble"
    },
    {
      "x": 2,
      "y": 8,
      "z": -2,
      "name": "Rock_Aqua_Cobble"
    },
    {
      "x": 2,
      "y": 0,
      "z": -1,
      "name": "Rock_Aqua"
    },
    {
      "x": 2,
      "y": 1,
      "z": -1,
      "name": "Rock_Aqua"
    },
    {
      "x": 2,
      "y": 2,
      "z": -1,
      "name": "Rock_Aqua"
    },
    {
      "x": 2,
      "y": 3,
      "z": -1,
      "name": "Rock_Aqua"
    },
    {
      "x": 2,
      "y": 4,
      "z": -1,
      "name": "Rock_Aqua"
    },
    {
      "x": 2,
      "y": 5,
      "z": -1,
      "name": "Rock_Aqua_Cobble"
    },
    {
      "x": 2,
      "y": 6,
      "z": -1,
      "name": "Rock_Aqua_Cobble"
    },
    {
      "x": 2,
      "y": 7,
      "z": -1,
      "name": "Rock_Aqua_Cobble"
    },
    {
      "x": 2,
      "y": 8,
      "z": -1,
      "name": "Rock_Aqua_Cobble"
    },
    {
      "x": 2,
      "y": 0,
      "z": 0,
      "name": "Rock_Aqua"
    },
    {
      "x": 2,
      "y": 1,
      "z": 0,
      "name": "Rock_Aqua"
    },
    {
      "x": 2,
      "y": 2,
      "z": 0,
      "name": "Rock_Aqua"
    },
    {
      "x": 2,
      "y": 3,
      "z": 0,
      "name": "Rock_Aqua"
    },
    {
      "x": 2,
      "y": 4,
      "z": 0,
      "name": "Rock_Aqua"
    },
    {
      "x": 2,
      "y": 5,
      "z": 0,
      "name": "Rock_Aqua_Cobble"
    },
    {
      "x": 2,
      "y": 6,
      "z": 0,
      "name": "Rock_Aqua_Cobble"
    },
    {
      "x": 2,
      "y": 7,
      "z": 0,
      "name": "Rock_Aqua_Cobble"
    },
    {
      "x": 2,
      "y": 8,
      "z": 0,
      "name": "Rock_Aqua_Cobble"
    },
    {
      "x": 2,
      "y": 9,
      "z": 0,
      "name": "Rock_Aqua_Cobble"
    },
    {
      "x": 2,
      "y": 0,
      "z": 1,
      "name": "Rock_Aqua"
    },
    {
      "x": 2,
      "y": 1,
      "z": 1,
      "name": "Rock_Aqua_Cobble"
    },
    {
      "x": 2,
      "y": 2,
      "z": 1,
      "name": "Rock_Aqua"
    },
    {
      "x": 2,
      "y": 3,
      "z": 1,
      "name": "Rock_Aqua"
    },
    {
      "x": 2,
      "y": 4,
      "z": 1,
      "name": "Rock_Aqua"
    },
    {
      "x": 2,
      "y": 5,
      "z": 1,
      "name": "Rock_Aqua_Cobble"
    },
    {
      "x": 2,
      "y": 6,
      "z": 1,
      "name": "Rock_Aqua_Cobble"
    },
    {
      "x": 2,
      "y": 7,
      "z": 1,
      "name": "Rock_Aqua_Cobble"
    },
    {
      "x": 2,
      "y": 8,
      "z": 1,
      "name": "Rock_Aqua_Cobble"
    },
    {
      "x": 2,
      "y": 9,
      "z": 1,
      "name": "Rock_Aqua_Cobble"
    },
    {
      "x": 2,
      "y": 0,
      "z": 2,
      "name": "Rock_Aqua_Cobble"
    },
    {
      "x": 2,
      "y": 1,
      "z": 2,
      "name": "Rock_Aqua_Cobble"
    },
    {
      "x": 2,
      "y": 2,
      "z": 2,
      "name": "Rock_Aqua"
    },
    {
      "x": 2,
      "y": 3,
      "z": 2,
      "name": "Rock_Aqua"
    },
    {
      "x": 2,
      "y": 4,
      "z": 2,
      "name": "Rock_Aqua_Cobble"
    },
    {
      "x": 2,
      "y": 5,
      "z": 2,
      "name": "Rock_Aqua_Cobble"
    },
    {
      "x": 2,
      "y": 6,
      "z": 2,
      "name": "Rock_Aqua_Cobble"
    },
    {
      "x": 2,
      "y": 7,
      "z": 2,
      "name": "Rock_Aqua_Cobble"
    },
    {
      "x": 2,
      "y": 8,
      "z": 2,
      "name": "Rock_Aqua_Cobble"
    },
    {
      "x": 2,
      "y": 9,
      "z": 2,
      "name": "Rock_Aqua_Cobble"
    },
    {
      "x": 2,
      "y": 10,
      "z": 2,
      "name": "Rock_Aqua_Cobble_Half"
    },
    {
      "x": 2,
      "y": 0,
      "z": 3,
      "name": "Rock_Aqua_Cobble"
    },
    {
      "x": 2,
      "y": 1,
      "z": 3,
      "name": "Rock_Aqua_Cobble"
    },
    {
      "x": 2,
      "y": 2,
      "z": 3,
      "name": "Rock_Aqua"
    },
    {
      "x": 2,
      "y": 3,
      "z": 3,
      "name": "Rock_Aqua_Cobble"
    },
    {
      "x": 2,
      "y": 4,
      "z": 3,
      "name": "Rock_Aqua_Cobble"
    },
    {
      "x": 2,
      "y": 5,
      "z": 3,
      "name": "Rock_Aqua_Cobble"
    },
    {
      "x": 2,
      "y": 6,
      "z": 3,
      "name": "Rock_Aqua_Cobble"
    },
    {
      "x": 2,
      "y": 7,
      "z": 3,
      "name": "Rock_Aqua_Cobble"
    },
    {
      "x": 2,
      "y": 8,
      "z": 3,
      "name": "Rock_Aqua_Cobble"
    },
    {
      "x": 2,
      "y": 9,
      "z": 3,
      "name": "Rock_Aqua_Cobble"
    },
    {
      "x": 2,
      "y": 10,
      "z": 3,
      "name": "Rock_Aqua_Cobble"
    },
    {
      "x": 2,
      "y": 0,
      "z": 4,
      "name": "Rock_Aqua"
    },
    {
      "x": 2,
      "y": 1,
      "z": 4,
      "name": "Rock_Aqua_Cobble"
    },
    {
      "x": 2,
      "y": 2,
      "z": 4,
      "name": "Rock_Aqua_Cobble"
    },
    {
      "x": 2,
      "y": 3,
      "z": 4,
      "name": "Rock_Aqua_Cobble"
    },
    {
      "x": 2,
      "y": 4,
      "z": 4,
      "name": "Rock_Aqua_Cobble"
    },
    {
      "x": 2,
      "y": 5,
      "z": 4,
      "name": "Rock_Aqua_Cobble"
    },
    {
      "x": 2,
      "y": 6,
      "z": 4,
      "name": "Rock_Aqua_Cobble"
    },
    {
      "x": 2,
      "y": 7,
      "z": 4,
      "name": "Rock_Aqua_Cobble"
    },
    {
      "x": 2,
      "y": 8,
      "z": 4,
      "name": "Rock_Aqua_Cobble"
    },
    {
      "x": 2,
      "y": 9,
      "z": 4,
      "name": "Rock_Aqua_Cobble"
    },
    {
      "x": 2,
      "y": 10,
      "z": 4,
      "name": "Rock_Aqua_Cobble"
    },
    {
      "x": 2,
      "y": 0,
      "z": 5,
      "name": "Rock_Aqua"
    },
    {
      "x": 2,
      "y": 1,
      "z": 5,
      "name": "Rock_Aqua"
    },
    {
      "x": 2,
      "y": 2,
      "z": 5,
      "name": "Rock_Aqua_Cobble"
    },
    {
      "x": 2,
      "y": 3,
      "z": 5,
      "name": "Rock_Aqua_Cobble"
    },
    {
      "x": 2,
      "y": 4,
      "z": 5,
      "name": "Rock_Aqua_Cobble"
    },
    {
      "x": 2,
      "y": 5,
      "z": 5,
      "name": "Rock_Aqua_Cobble"
    },
    {
      "x": 2,
      "y": 6,
      "z": 5,
      "name": "Rock_Aqua_Cobble"
    },
    {
      "x": 2,
      "y": 7,
      "z": 5,
      "name": "Rock_Aqua_Cobble"
    },
    {
      "x": 2,
      "y": 8,
      "z": 5,
      "name": "Rock_Aqua_Cobble"
    },
    {
      "x": 2,
      "y": 9,
      "z": 5,
      "name": "Rock_Aqua_Cobble"
    },
    {
      "x": 2,
      "y": 10,
      "z": 5,
      "name": "Rock_Aqua_Cobble"
    },
    {
      "x": 2,
      "y": 0,
      "z": 6,
      "name": "Rock_Aqua"
    },
    {
      "x": 2,
      "y": 1,
      "z": 6,
      "name": "Rock_Aqua"
    },
    {
      "x": 2,
      "y": 2,
      "z": 6,
      "name": "Rock_Aqua"
    },
    {
      "x": 2,
      "y": 3,
      "z": 6,
      "name": "Rock_Aqua_Cobble"
    },
    {
      "x": 2,
      "y": 4,
      "z": 6,
      "name": "Rock_Aqua_Cobble"
    },
    {
      "x": 2,
      "y": 5,
      "z": 6,
      "name": "Rock_Aqua_Cobble"
    },
    {
      "x": 2,
      "y": 6,
      "z": 6,
      "name": "Rock_Aqua_Cobble"
    },
    {
      "x": 2,
      "y": 7,
      "z": 6,
      "name": "Rock_Aqua_Cobble"
    },
    {
      "x": 2,
      "y": 8,
      "z": 6,
      "name": "Rock_Aqua_Cobble"
    },
    {
      "x": 2,
      "y": 9,
      "z": 6,
      "name": "Rock_Aqua_Cobble"
    },
    {
      "x": 2,
      "y": 5,
      "z": 7,
      "name": "Rock_Aqua_Cobble_Half",
      "rotation": 4
    },
    {
      "x": 2,
      "y": 6,
      "z": 7,
      "name": "Rock_Aqua_Cobble_Half",
      "rotation": 4
    },
    {
      "x": 3,
      "y": 0,
      "z": -6,
      "name": "Rock_Aqua"
    },
    {
      "x": 3,
      "y": 1,
      "z": -6,
      "name": "Rock_Aqua"
    },
    {
      "x": 3,
      "y": 2,
      "z": -6,
      "name": "Rock_Aqua"
    },
    {
      "x": 3,
      "y": 3,
      "z": -6,
      "name": "Rock_Aqua"
    },
    {
      "x": 3,
      "y": 4,
      "z": -6,
      "name": "Rock_Aqua_Cobble"
    },
    {
      "x": 3,
      "y": 5,
      "z": -6,
      "name": "Rock_Aqua_Cobble"
    },
    {
      "x": 3,
      "y": 6,
      "z": -6,
      "name": "Rock_Aqua_Cobble"
    },
    {
      "x": 3,
      "y": 7,
      "z": -6,
      "name": "Rock_Aqua_Cobble"
    },
    {
      "x": 3,
      "y": 0,
      "z": -5,
      "name": "Rock_Aqua"
    },
    {
      "x": 3,
      "y": 1,
      "z": -5,
      "name": "Rock_Aqua"
    },
    {
      "x": 3,
      "y": 2,
      "z": -5,
      "name": "Rock_Aqua"
    },
    {
      "x": 3,
      "y": 3,
      "z": -5,
      "name": "Rock_Aqua_Cobble"
    },
    {
      "x": 3,
      "y": 4,
      "z": -5,
      "name": "Rock_Aqua_Cobble"
    },
    {
      "x": 3,
      "y": 5,
      "z": -5,
      "name": "Rock_Aqua_Cobble"
    },
    {
      "x": 3,
      "y": 6,
      "z": -5,
      "name": "Rock_Aqua_Cobble"
    },
    {
      "x": 3,
      "y": 7,
      "z": -5,
      "name": "Rock_Aqua_Cobble"
    },
    {
      "x": 3,
      "y": 8,
      "z": -5,
      "name": "Rock_Aqua_Cobble"
    },
    {
      "x": 3,
      "y": 0,
      "z": -4,
      "name": "Rock_Aqua"
    },
    {
      "x": 3,
      "y": 1,
      "z": -4,
      "name": "Rock_Aqua"
    },
    {
      "x": 3,
      "y": 2,
      "z": -4,
      "name": "Rock_Aqua"
    },
    {
      "x": 3,
      "y": 3,
      "z": -4,
      "name": "Rock_Aqua"
    },
    {
      "x": 3,
      "y": 4,
      "z": -4,
      "name": "Rock_Aqua_Cobble"
    },
    {
      "x": 3,
      "y": 5,
      "z": -4,
      "name": "Rock_Aqua_Cobble"
    },
    {
      "x": 3,
      "y": 6,
      "z": -4,
      "name": "Rock_Aqua_Cobble"
    },
    {
      "x": 3,
      "y": 7,
      "z": -4,
      "name": "Rock_Aqua_Cobble"
    },
    {
      "x": 3,
      "y": 8,
      "z": -4,
      "name": "Rock_Aqua_Cobble"
    },
    {
      "x": 3,
      "y": 0,
      "z": -3,
      "name": "Rock_Aqua"
    },
    {
      "x": 3,
      "y": 1,
      "z": -3,
      "name": "Rock_Aqua"
    },
    {
      "x": 3,
      "y": 2,
      "z": -3,
      "name": "Rock_Aqua"
    },
    {
      "x": 3,
      "y": 3,
      "z": -3,
      "name": "Rock_Aqua"
    },
    {
      "x": 3,
      "y": 4,
      "z": -3,
      "name": "Rock_Aqua"
    },
    {
      "x": 3,
      "y": 5,
      "z": -3,
      "name": "Rock_Aqua_Cobble"
    },
    {
      "x": 3,
      "y": 6,
      "z": -3,
      "name": "Rock_Aqua_Cobble"
    },
    {
      "x": 3,
      "y": 7,
      "z": -3,
      "name": "Rock_Aqua_Cobble"
    },
    {
      "x": 3,
      "y": 8,
      "z": -3,
      "name": "Rock_Aqua_Cobble"
    },
    {
      "x": 3,
      "y": 0,
      "z": -2,
      "name": "Rock_Aqua"
    },
    {
      "x": 3,
      "y": 1,
      "z": -2,
      "name": "Rock_Aqua"
    },
    {
      "x": 3,
      "y": 2,
      "z": -2,
      "name": "Rock_Aqua"
    },
    {
      "x": 3,
      "y": 3,
      "z": -2,
      "name": "Rock_Aqua"
    },
    {
      "x": 3,
      "y": 4,
      "z": -2,
      "name": "Rock_Aqua"
    },
    {
      "x": 3,
      "y": 5,
      "z": -2,
      "name": "Rock_Aqua_Cobble"
    },
    {
      "x": 3,
      "y": 6,
      "z": -2,
      "name": "Rock_Aqua_Cobble"
    },
    {
      "x": 3,
      "y": 7,
      "z": -2,
      "name": "Rock_Aqua_Cobble"
    },
    {
      "x": 3,
      "y": 8,
      "z": -2,
      "name": "Rock_Aqua_Cobble"
    },
    {
      "x": 3,
      "y": 0,
      "z": -1,
      "name": "Rock_Aqua"
    },
    {
      "x": 3,
      "y": 1,
      "z": -1,
      "name": "Rock_Aqua"
    },
    {
      "x": 3,
      "y": 2,
      "z": -1,
      "name": "Rock_Aqua"
    },
    {
      "x": 3,
      "y": 3,
      "z": -1,
      "name": "Rock_Aqua"
    },
    {
      "x": 3,
      "y": 4,
      "z": -1,
      "name": "Rock_Aqua"
    },
    {
      "x": 3,
      "y": 5,
      "z": -1,
      "name": "Rock_Aqua_Cobble"
    },
    {
      "x": 3,
      "y": 6,
      "z": -1,
      "name": "Rock_Aqua_Cobble"
    },
    {
      "x": 3,
      "y": 7,
      "z": -1,
      "name": "Rock_Aqua_Cobble"
    },
    {
      "x": 3,
      "y": 8,
      "z": -1,
      "name": "Rock_Aqua_Cobble"
    },
    {
      "x": 3,
      "y": 9,
      "z": -1,
      "name": "Rock_Aqua_Cobble_Half"
    },
    {
      "x": 3,
      "y": 0,
      "z": 0,
      "name": "Rock_Aqua"
    },
    {
      "x": 3,
      "y": 1,
      "z": 0,
      "name": "Rock_Aqua"
    },
    {
      "x": 3,
      "y": 2,
      "z": 0,
      "name": "Rock_Aqua"
    },
    {
      "x": 3,
      "y": 3,
      "z": 0,
      "name": "Rock_Aqua"
    },
    {
      "x": 3,
      "y": 4,
      "z": 0,
      "name": "Rock_Aqua"
    },
    {
      "x": 3,
      "y": 5,
      "z": 0,
      "name": "Rock_Aqua_Cobble"
    },
    {
      "x": 3,
      "y": 6,
      "z": 0,
      "name": "Rock_Aqua_Cobble"
    },
    {
      "x": 3,
      "y": 7,
      "z": 0,
      "name": "Rock_Aqua_Cobble"
    },
    {
      "x": 3,
      "y": 8,
      "z": 0,
      "name": "Rock_Aqua_Cobble"
    },
    {
      "x": 3,
      "y": 9,
      "z": 0,
      "name": "Rock_Aqua_Cobble"
    },
    {
      "x": 3,
      "y": 0,
      "z": 1,
      "name": "Rock_Aqua"
    },
    {
      "x": 3,
      "y": 1,
      "z": 1,
      "name": "Rock_Aqua"
    },
    {
      "x": 3,
      "y": 2,
      "z": 1,
      "name": "Rock_Aqua"
    },
    {
      "x": 3,
      "y": 3,
      "z": 1,
      "name": "Rock_Aqua"
    },
    {
      "x": 3,
      "y": 4,
      "z": 1,
      "name": "Rock_Aqua_Cobble"
    },
    {
      "x": 3,
      "y": 5,
      "z": 1,
      "name": "Rock_Aqua_Cobble"
    },
    {
      "x": 3,
      "y": 6,
      "z": 1,
      "name": "Rock_Aqua_Cobble"
    },
    {
      "x": 3,
      "y": 7,
      "z": 1,
      "name": "Rock_Aqua_Cobble"
    },
    {
      "x": 3,
      "y": 8,
      "z": 1,
      "name": "Rock_Aqua_Cobble"
    },
    {
      "x": 3,
      "y": 9,
      "z": 1,
      "name": "Rock_Aqua_Cobble"
    },
    {
      "x": 3,
      "y": 0,
      "z": 2,
      "name": "Rock_Aqua_Cobble"
    },
    {
      "x": 3,
      "y": 1,
      "z": 2,
      "name": "Rock_Aqua_Cobble"
    },
    {
      "x": 3,
      "y": 2,
      "z": 2,
      "name": "Rock_Aqua"
    },
    {
      "x": 3,
      "y": 3,
      "z": 2,
      "name": "Rock_Aqua_Cobble"
    },
    {
      "x": 3,
      "y": 4,
      "z": 2,
      "name": "Rock_Aqua_Cobble"
    },
    {
      "x": 3,
      "y": 5,
      "z": 2,
      "name": "Rock_Aqua_Cobble"
    },
    {
      "x": 3,
      "y": 6,
      "z": 2,
      "name": "Rock_Aqua_Cobble"
    },
    {
      "x": 3,
      "y": 7,
      "z": 2,
      "name": "Rock_Aqua_Cobble"
    },
    {
      "x": 3,
      "y": 8,
      "z": 2,
      "name": "Rock_Aqua_Cobble"
    },
    {
      "x": 3,
      "y": 9,
      "z": 2,
      "name": "Rock_Aqua_Cobble"
    },
    {
      "x": 3,
      "y": 0,
      "z": 3,
      "name": "Rock_Aqua_Cobble"
    },
    {
      "x": 3,
      "y": 1,
      "z": 3,
      "name": "Rock_Aqua_Cobble"
    },
    {
      "x": 3,
      "y": 2,
      "z": 3,
      "name": "Rock_Aqua_Cobble"
    },
    {
      "x": 3,
      "y": 3,
      "z": 3,
      "name": "Rock_Aqua_Cobble"
    },
    {
      "x": 3,
      "y": 4,
      "z": 3,
      "name": "Rock_Aqua_Cobble"
    },
    {
      "x": 3,
      "y": 5,
      "z": 3,
      "name": "Rock_Aqua_Cobble"
    },
    {
      "x": 3,
      "y": 6,
      "z": 3,
      "name": "Rock_Aqua_Cobble"
    },
    {
      "x": 3,
      "y": 7,
      "z": 3,
      "name": "Rock_Aqua_Cobble"
    },
    {
      "x": 3,
      "y": 8,
      "z": 3,
      "name": "Rock_Aqua_Cobble"
    },
    {
      "x": 3,
      "y": 9,
      "z": 3,
      "name": "Rock_Aqua_Cobble"
    },
    {
      "x": 3,
      "y": 0,
      "z": 4,
      "name": "Rock_Aqua_Cobble"
    },
    {
      "x": 3,
      "y": 1,
      "z": 4,
      "name": "Rock_Aqua_Cobble"
    },
    {
      "x": 3,
      "y": 2,
      "z": 4,
      "name": "Rock_Aqua_Cobble"
    },
    {
      "x": 3,
      "y": 3,
      "z": 4,
      "name": "Rock_Aqua_Cobble"
    },
    {
      "x": 3,
      "y": 4,
      "z": 4,
      "name": "Rock_Aqua_Cobble"
    },
    {
      "x": 3,
      "y": 5,
      "z": 4,
      "name": "Rock_Aqua_Cobble"
    },
    {
      "x": 3,
      "y": 6,
      "z": 4,
      "name": "Rock_Aqua_Cobble"
    },
    {
      "x": 3,
      "y": 7,
      "z": 4,
      "name": "Rock_Aqua_Cobble"
    },
    {
      "x": 3,
      "y": 8,
      "z": 4,
      "name": "Rock_Aqua_Cobble"
    },
    {
      "x": 3,
      "y": 9,
      "z": 4,
      "name": "Rock_Aqua_Cobble"
    },
    {
      "x": 3,
      "y": 10,
      "z": 4,
      "name": "Rubble_Aqua"
    },
    {
      "x": 3,
      "y": 0,
      "z": 5,
      "name": "Rock_Aqua"
    },
    {
      "x": 3,
      "y": 1,
      "z": 5,
      "name": "Rock_Aqua_Cobble"
    },
    {
      "x": 3,
      "y": 2,
      "z": 5,
      "name": "Rock_Aqua_Cobble"
    },
    {
      "x": 3,
      "y": 3,
      "z": 5,
      "name": "Rock_Aqua_Cobble"
    },
    {
      "x": 3,
      "y": 4,
      "z": 5,
      "name": "Rock_Aqua_Cobble"
    },
    {
      "x": 3,
      "y": 5,
      "z": 5,
      "name": "Rock_Aqua_Cobble"
    },
    {
      "x": 3,
      "y": 6,
      "z": 5,
      "name": "Rock_Aqua_Cobble"
    },
    {
      "x": 3,
      "y": 7,
      "z": 5,
      "name": "Rock_Aqua_Cobble"
    },
    {
      "x": 3,
      "y": 8,
      "z": 5,
      "name": "Rock_Aqua_Cobble"
    },
    {
      "x": 3,
      "y": 9,
      "z": 5,
      "name": "Rock_Aqua_Cobble"
    },
    {
      "x": 3,
      "y": 1,
      "z": 6,
      "name": "Rock_Aqua"
    },
    {
      "x": 3,
      "y": 2,
      "z": 6,
      "name": "Rock_Aqua_Cobble"
    },
    {
      "x": 3,
      "y": 3,
      "z": 6,
      "name": "Rock_Aqua_Cobble"
    },
    {
      "x": 3,
      "y": 4,
      "z": 6,
      "name": "Rock_Aqua_Cobble"
    },
    {
      "x": 3,
      "y": 5,
      "z": 6,
      "name": "Rock_Aqua_Cobble"
    },
    {
      "x": 3,
      "y": 6,
      "z": 6,
      "name": "Rock_Aqua_Cobble"
    },
    {
      "x": 3,
      "y": 7,
      "z": 6,
      "name": "Rock_Aqua_Cobble"
    },
    {
      "x": 3,
      "y": 8,
      "z": 6,
      "name": "Rock_Aqua_Cobble"
    },
    {
      "x": 3,
      "y": 9,
      "z": 6,
      "name": "Rock_Aqua_Cobble"
    },
    {
      "x": 4,
      "y": 1,
      "z": -5,
      "name": "Rock_Aqua_Cobble"
    },
    {
      "x": 4,
      "y": 2,
      "z": -5,
      "name": "Rock_Aqua_Cobble"
    },
    {
      "x": 4,
      "y": 3,
      "z": -5,
      "name": "Rock_Aqua_Cobble"
    },
    {
      "x": 4,
      "y": 4,
      "z": -5,
      "name": "Rock_Aqua_Cobble"
    },
    {
      "x": 4,
      "y": 5,
      "z": -5,
      "name": "Rock_Aqua_Cobble"
    },
    {
      "x": 4,
      "y": 6,
      "z": -5,
      "name": "Rock_Aqua_Cobble"
    },
    {
      "x": 4,
      "y": 7,
      "z": -5,
      "name": "Rock_Aqua_Cobble"
    },
    {
      "x": 4,
      "y": 8,
      "z": -5,
      "name": "Rock_Aqua_Cobble_Half"
    },
    {
      "x": 4,
      "y": 0,
      "z": -4,
      "name": "Rock_Aqua"
    },
    {
      "x": 4,
      "y": 1,
      "z": -4,
      "name": "Rock_Aqua_Cobble"
    },
    {
      "x": 4,
      "y": 2,
      "z": -4,
      "name": "Rock_Aqua"
    },
    {
      "x": 4,
      "y": 3,
      "z": -4,
      "name": "Rock_Aqua_Cobble"
    },
    {
      "x": 4,
      "y": 4,
      "z": -4,
      "name": "Rock_Aqua_Cobble"
    },
    {
      "x": 4,
      "y": 5,
      "z": -4,
      "name": "Rock_Aqua_Cobble"
    },
    {
      "x": 4,
      "y": 6,
      "z": -4,
      "name": "Rock_Aqua_Cobble"
    },
    {
      "x": 4,
      "y": 7,
      "z": -4,
      "name": "Rock_Aqua_Cobble"
    },
    {
      "x": 4,
      "y": 8,
      "z": -4,
      "name": "Rock_Aqua_Cobble"
    },
    {
      "x": 4,
      "y": 0,
      "z": -3,
      "name": "Rock_Aqua"
    },
    {
      "x": 4,
      "y": 1,
      "z": -3,
      "name": "Rock_Aqua"
    },
    {
      "x": 4,
      "y": 2,
      "z": -3,
      "name": "Rock_Aqua"
    },
    {
      "x": 4,
      "y": 3,
      "z": -3,
      "name": "Rock_Aqua"
    },
    {
      "x": 4,
      "y": 4,
      "z": -3,
      "name": "Rock_Aqua_Cobble"
    },
    {
      "x": 4,
      "y": 5,
      "z": -3,
      "name": "Rock_Aqua_Cobble"
    },
    {
      "x": 4,
      "y": 6,
      "z": -3,
      "name": "Rock_Aqua_Cobble"
    },
    {
      "x": 4,
      "y": 7,
      "z": -3,
      "name": "Rock_Aqua_Cobble"
    },
    {
      "x": 4,
      "y": 8,
      "z": -3,
      "name": "Rock_Aqua_Cobble"
    },
    {
      "x": 4,
      "y": 0,
      "z": -2,
      "name": "Rock_Aqua"
    },
    {
      "x": 4,
      "y": 1,
      "z": -2,
      "name": "Rock_Aqua"
    },
    {
      "x": 4,
      "y": 2,
      "z": -2,
      "name": "Rock_Aqua"
    },
    {
      "x": 4,
      "y": 3,
      "z": -2,
      "name": "Rock_Aqua"
    },
    {
      "x": 4,
      "y": 4,
      "z": -2,
      "name": "Rock_Aqua"
    },
    {
      "x": 4,
      "y": 5,
      "z": -2,
      "name": "Rock_Aqua_Cobble"
    },
    {
      "x": 4,
      "y": 6,
      "z": -2,
      "name": "Rock_Aqua_Cobble"
    },
    {
      "x": 4,
      "y": 7,
      "z": -2,
      "name": "Rock_Aqua_Cobble"
    },
    {
      "x": 4,
      "y": 8,
      "z": -2,
      "name": "Rock_Aqua_Cobble"
    },
    {
      "x": 4,
      "y": 0,
      "z": -1,
      "name": "Rock_Aqua"
    },
    {
      "x": 4,
      "y": 1,
      "z": -1,
      "name": "Rock_Aqua"
    },
    {
      "x": 4,
      "y": 2,
      "z": -1,
      "name": "Rock_Aqua"
    },
    {
      "x": 4,
      "y": 3,
      "z": -1,
      "name": "Rock_Aqua"
    },
    {
      "x": 4,
      "y": 4,
      "z": -1,
      "name": "Rock_Aqua"
    },
    {
      "x": 4,
      "y": 5,
      "z": -1,
      "name": "Rock_Aqua_Cobble"
    },
    {
      "x": 4,
      "y": 6,
      "z": -1,
      "name": "Rock_Aqua_Cobble"
    },
    {
      "x": 4,
      "y": 7,
      "z": -1,
      "name": "Rock_Aqua_Cobble"
    },
    {
      "x": 4,
      "y": 8,
      "z": -1,
      "name": "Rock_Aqua_Cobble"
    },
    {
      "x": 4,
      "y": 9,
      "z": -1,
      "name": "Rock_Aqua_Cobble_Half"
    },
    {
      "x": 4,
      "y": 0,
      "z": 0,
      "name": "Rock_Aqua"
    },
    {
      "x": 4,
      "y": 1,
      "z": 0,
      "name": "Rock_Aqua"
    },
    {
      "x": 4,
      "y": 2,
      "z": 0,
      "name": "Rock_Aqua"
    },
    {
      "x": 4,
      "y": 3,
      "z": 0,
      "name": "Rock_Aqua"
    },
    {
      "x": 4,
      "y": 4,
      "z": 0,
      "name": "Rock_Aqua"
    },
    {
      "x": 4,
      "y": 5,
      "z": 0,
      "name": "Rock_Aqua_Cobble"
    },
    {
      "x": 4,
      "y": 6,
      "z": 0,
      "name": "Rock_Aqua_Cobble"
    },
    {
      "x": 4,
      "y": 7,
      "z": 0,
      "name": "Rock_Aqua_Cobble"
    },
    {
      "x": 4,
      "y": 8,
      "z": 0,
      "name": "Rock_Aqua_Cobble"
    },
    {
      "x": 4,
      "y": 9,
      "z": 0,
      "name": "Rock_Aqua_Cobble"
    },
    {
      "x": 4,
      "y": 10,
      "z": 0,
      "name": "Rubble_Aqua"
    },
    {
      "x": 4,
      "y": 0,
      "z": 1,
      "name": "Rock_Aqua"
    },
    {
      "x": 4,
      "y": 1,
      "z": 1,
      "name": "Rock_Aqua"
    },
    {
      "x": 4,
      "y": 2,
      "z": 1,
      "name": "Rock_Aqua"
    },
    {
      "x": 4,
      "y": 3,
      "z": 1,
      "name": "Rock_Aqua"
    },
    {
      "x": 4,
      "y": 4,
      "z": 1,
      "name": "Rock_Aqua"
    },
    {
      "x": 4,
      "y": 5,
      "z": 1,
      "name": "Rock_Aqua_Cobble"
    },
    {
      "x": 4,
      "y": 6,
      "z": 1,
      "name": "Rock_Aqua_Cobble"
    },
    {
      "x": 4,
      "y": 7,
      "z": 1,
      "name": "Rock_Aqua_Cobble"
    },
    {
      "x": 4,
      "y": 8,
      "z": 1,
      "name": "Rock_Aqua_Cobble"
    },
    {
      "x": 4,
      "y": 9,
      "z": 1,
      "name": "Rock_Aqua_Cobble"
    },
    {
      "x": 4,
      "y": 0,
      "z": 2,
      "name": "Rock_Aqua"
    },
    {
      "x": 4,
      "y": 1,
      "z": 2,
      "name": "Rock_Aqua_Cobble"
    },
    {
      "x": 4,
      "y": 2,
      "z": 2,
      "name": "Rock_Aqua"
    },
    {
      "x": 4,
      "y": 3,
      "z": 2,
      "name": "Rock_Aqua"
    },
    {
      "x": 4,
      "y": 4,
      "z": 2,
      "name": "Rock_Aqua"
    },
    {
      "x": 4,
      "y": 5,
      "z": 2,
      "name": "Rock_Aqua_Cobble"
    },
    {
      "x": 4,
      "y": 6,
      "z": 2,
      "name": "Rock_Aqua_Cobble"
    },
    {
      "x": 4,
      "y": 7,
      "z": 2,
      "name": "Rock_Aqua_Cobble"
    },
    {
      "x": 4,
      "y": 8,
      "z": 2,
      "name": "Rock_Aqua_Cobble"
    },
    {
      "x": 4,
      "y": 9,
      "z": 2,
      "name": "Rock_Aqua_Cobble"
    },
    {
      "x": 4,
      "y": 0,
      "z": 3,
      "name": "Rock_Aqua_Cobble"
    },
    {
      "x": 4,
      "y": 1,
      "z": 3,
      "name": "Rock_Aqua_Cobble"
    },
    {
      "x": 4,
      "y": 2,
      "z": 3,
      "name": "Rock_Aqua"
    },
    {
      "x": 4,
      "y": 3,
      "z": 3,
      "name": "Rock_Aqua"
    },
    {
      "x": 4,
      "y": 4,
      "z": 3,
      "name": "Rock_Aqua"
    },
    {
      "x": 4,
      "y": 5,
      "z": 3,
      "name": "Rock_Aqua_Cobble"
    },
    {
      "x": 4,
      "y": 6,
      "z": 3,
      "name": "Rock_Aqua_Cobble"
    },
    {
      "x": 4,
      "y": 7,
      "z": 3,
      "name": "Rock_Aqua_Cobble"
    },
    {
      "x": 4,
      "y": 8,
      "z": 3,
      "name": "Rock_Aqua_Cobble"
    },
    {
      "x": 4,
      "y": 9,
      "z": 3,
      "name": "Rock_Aqua_Cobble"
    },
    {
      "x": 4,
      "y": 0,
      "z": 4,
      "name": "Rock_Aqua_Cobble"
    },
    {
      "x": 4,
      "y": 1,
      "z": 4,
      "name": "Rock_Aqua_Cobble"
    },
    {
      "x": 4,
      "y": 2,
      "z": 4,
      "name": "Rock_Aqua_Cobble"
    },
    {
      "x": 4,
      "y": 3,
      "z": 4,
      "name": "Rock_Aqua"
    },
    {
      "x": 4,
      "y": 4,
      "z": 4,
      "name": "Rock_Aqua_Cobble"
    },
    {
      "x": 4,
      "y": 5,
      "z": 4,
      "name": "Rock_Aqua_Cobble"
    },
    {
      "x": 4,
      "y": 6,
      "z": 4,
