{
  "version": 8,
  "blockIdVersion": 11,
  "anchorX": 0,
  "anchorY": 16,
  "anchorZ": 0,
  "blocks": [
    {
      "x": -14,
      "y": 0,
      "z": -6,
      "name": "Rock_Aqua_Brick_Decorative"
    },
    {
      "x": -14,
      "y": 1,
      "z": -6,
      "name": "Rock_Aqua_Brick_Ornate"
    },
    {
      "x": -14,
      "y": 2,
      "z": -6,
      "name": "Rock_Aqua_Brick_Ornate"
    },
    {
      "x": -14,
      "y": 3,
      "z": -6,
      "name": "Rock_Aqua_Brick_Decorative"
    },
    {
      "x": -14,
      "y": 4,
      "z": -6,
      "name": "Rock_Aqua_Brick_Ornate"
    },
    {
      "x": -14,
      "y": 5,
      "z": -6,
      "name": "Rock_Aqua_Brick_Ornate"
    },
    {
      "x": -14,
      "y": 6,
      "z": -6,
      "name": "Rock_Aqua_Brick_Decorative"
    },
    {
      "x": -14,
      "y": 7,
      "z": -6,
      "name": "Rock_Aqua_Brick_Ornate"
    },
    {
      "x": -14,
      "y": 8,
      "z": -6,
      "name": "Rock_Aqua_Brick_Ornate"
    },
    {
      "x": -14,
      "y": 0,
      "z": -5,
      "name": "Rock_Aqua_Brick_Decorative"
    },
    {
      "x": -14,
      "y": 1,
      "z": -5,
      "name": "Rock_Aqua_Brick_Smooth"
    },
    {
      "x": -14,
      "y": 2,
      "z": -5,
      "name": "Rock_Aqua_Brick_Smooth"
    },
    {
      "x": -14,
      "y": 3,
      "z": -5,
      "name": "Rock_Aqua_Brick_Decorative"
    },
    {
      "x": -14,
      "y": 4,
      "z": -5,
      "name": "Rock_Aqua_Brick_Smooth"
    },
    {
      "x": -14,
      "y": 5,
      "z": -5,
      "name": "Rock_Aqua_Brick_Smooth"
    },
    {
      "x": -14,
      "y": 6,
      "z": -5,
      "name": "Rock_Aqua_Brick_Decorative"
    },
    {
      "x": -14,
      "y": 7,
      "z": -5,
      "name": "Rock_Aqua_Brick_Smooth"
    },
    {
      "x": -14,
      "y": 8,
      "z": -5,
      "name": "Rock_Aqua_Brick_Smooth"
    },
    {
      "x": -14,
      "y": 0,
      "z": -4,
      "name": "Rock_Aqua_Brick_Decorative"
    },
    {
      "x": -14,
      "y": 1,
      "z": -4,
      "name": "Rock_Aqua_Brick_Ornate"
    },
    {
      "x": -14,
      "y": 2,
      "z": -4,
      "name": "Rock_Aqua_Brick_Ornate"
    },
    {
      "x": -14,
      "y": 3,
      "z": -4,
      "name": "Rock_Aqua_Brick_Decorative"
    },
    {
      "x": -14,
      "y": 4,
      "z": -4,
      "name": "Rock_Aqua_Brick_Ornate"
    },
    {
      "x": -14,
      "y": 5,
      "z": -4,
      "name": "Rock_Aqua_Brick_Ornate"
    },
    {
      "x": -14,
      "y": 6,
      "z": -4,
      "name": "Rock_Aqua_Brick_Decorative"
    },
    {
      "x": -14,
      "y": 7,
      "z": -4,
      "name": "Rock_Aqua_Brick_Ornate"
    },
    {
      "x": -14,
      "y": 8,
      "z": -4,
      "name": "Rock_Aqua_Brick_Ornate"
    },
    {
      "x": -14,
      "y": 0,
      "z": -3,
      "name": "Rock_Aqua_Brick_Decorative"
    },
    {
      "x": -14,
      "y": 1,
      "z": -3,
      "name": "Rock_Aqua_Brick_Smooth"
    },
    {
      "x": -14,
      "y": 2,
      "z": -3,
      "name": "Rock_Aqua_Brick_Smooth"
    },
    {
      "x": -14,
      "y": 3,
      "z": -3,
      "name": "Rock_Aqua_Brick_Decorative"
    },
    {
      "x": -14,
      "y": 4,
      "z": -3,
      "name": "Rock_Aqua_Brick_Smooth"
    },
    {
      "x": -14,
      "y": 5,
      "z": -3,
      "name": "Rock_Aqua_Brick_Smooth"
    },
    {
      "x": -14,
      "y": 6,
      "z": -3,
      "name": "Rock_Aqua_Brick_Decorative"
    },
    {
      "x": -14,
      "y": 7,
      "z": -3,
      "name": "Rock_Aqua_Brick_Smooth"
    },
    {
      "x": -14,
      "y": 8,
      "z": -3,
      "name": "Rock_Aqua_Brick_Smooth"
    },
    {
      "x": -14,
      "y": 0,
      "z": -2,
      "name": "Rock_Aqua_Brick_Decorative"
    },
    {
      "x": -14,
      "y": 1,
      "z": -2,
      "name": "Rock_Aqua_Brick_Ornate"
    },
    {
      "x": -14,
      "y": 2,
      "z": -2,
      "name": "Rock_Aqua_Brick_Ornate"
    },
    {
      "x": -14,
      "y": 3,
      "z": -2,
      "name": "Rock_Aqua_Brick_Decorative"
    },
    {
      "x": -14,
      "y": 4,
      "z": -2,
      "name": "Rock_Aqua_Brick_Ornate"
    },
    {
      "x": -14,
      "y": 5,
      "z": -2,
      "name": "Rock_Aqua_Brick_Ornate"
    },
    {
      "x": -14,
      "y": 6,
      "z": -2,
      "name": "Rock_Aqua_Brick_Decorative"
    },
    {
      "x": -14,
      "y": 7,
      "z": -2,
      "name": "Rock_Aqua_Brick_Ornate"
    },
    {
      "x": -14,
      "y": 8,
      "z": -2,
      "name": "Rock_Aqua_Brick_Ornate"
    },
    {
      "x": -14,
      "y": 0,
      "z": -1,
      "name": "Rock_Aqua_Brick_Decorative"
    },
    {
      "x": -14,
      "y": 1,
      "z": -1,
      "name": "Rock_Aqua_Brick_Smooth"
    },
    {
      "x": -14,
      "y": 2,
      "z": -1,
      "name": "Rock_Aqua_Brick_Smooth"
    },
    {
      "x": -14,
      "y": 3,
      "z": -1,
      "name": "Rock_Aqua_Brick_Decorative"
    },
    {
      "x": -14,
      "y": 4,
      "z": -1,
      "name": "Rock_Aqua_Brick_Smooth"
    },
    {
      "x": -14,
      "y": 5,
      "z": -1,
      "name": "Rock_Aqua_Brick_Smooth"
    },
    {
      "x": -14,
      "y": 6,
      "z": -1,
      "name": "Rock_Aqua_Brick_Decorative"
    },
    {
      "x": -14,
      "y": 7,
      "z": -1,
      "name": "Rock_Aqua_Brick_Smooth"
    },
    {
      "x": -14,
      "y": 8,
      "z": -1,
      "name": "Rock_Aqua_Brick_Smooth"
    },
    {
      "x": -14,
      "y": 0,
      "z": 0,
      "name": "Rock_Aqua_Brick_Decorative"
    },
    {
      "x": -14,
      "y": 1,
      "z": 0,
      "name": "Rock_Aqua_Brick_Ornate"
    },
    {
      "x": -14,
      "y": 2,
      "z": 0,
      "name": "Rock_Aqua_Brick_Ornate"
    },
    {
      "x": -14,
      "y": 3,
      "z": 0,
      "name": "Rock_Aqua_Brick_Decorative"
    },
    {
      "x": -14,
      "y": 4,
      "z": 0,
      "name": "Rock_Aqua_Brick_Ornate"
    },
    {
      "x": -14,
      "y": 5,
      "z": 0,
      "name": "Rock_Aqua_Brick_Ornate"
    },
    {
      "x": -14,
      "y": 6,
      "z": 0,
      "name": "Rock_Aqua_Brick_Decorative"
    },
    {
      "x": -14,
      "y": 7,
      "z": 0,
      "name": "Rock_Aqua_Brick_Ornate"
    },
    {
      "x": -14,
      "y": 8,
      "z": 0,
      "name": "Rock_Aqua_Brick_Ornate"
    },
    {
      "x": -14,
      "y": 0,
      "z": 1,
      "name": "Rock_Aqua_Brick_Decorative"
    },
    {
      "x": -14,
      "y": 1,
      "z": 1,
      "name": "Rock_Aqua_Brick_Smooth"
    },
    {
      "x": -14,
      "y": 2,
      "z": 1,
      "name": "Rock_Aqua_Brick_Smooth"
    },
    {
      "x": -14,
      "y": 3,
      "z": 1,
      "name": "Rock_Aqua_Brick_Decorative"
    },
    {
      "x": -14,
      "y": 4,
      "z": 1,
      "name": "Rock_Aqua_Brick_Smooth"
    },
    {
      "x": -14,
      "y": 5,
      "z": 1,
      "name": "Rock_Aqua_Brick_Smooth"
    },
    {
      "x": -14,
      "y": 6,
      "z": 1,
      "name": "Rock_Aqua_Brick_Decorative"
    },
    {
      "x": -14,
      "y": 7,
      "z": 1,
      "name": "Rock_Aqua_Brick_Smooth"
    },
    {
      "x": -14,
      "y": 8,
      "z": 1,
      "name": "Rock_Aqua_Brick_Smooth"
    },
    {
      "x": -14,
      "y": 0,
      "z": 2,
      "name": "Rock_Aqua_Brick_Decorative"
    },
    {
      "x": -14,
      "y": 1,
      "z": 2,
      "name": "Rock_Aqua_Brick_Ornate"
    },
    {
      "x": -14,
      "y": 2,
      "z": 2,
      "name": "Rock_Aqua_Brick_Ornate"
    },
    {
      "x": -14,
      "y": 3,
      "z": 2,
      "name": "Rock_Aqua_Brick_Decorative"
    },
    {
      "x": -14,
      "y": 4,
      "z": 2,
      "name": "Rock_Aqua_Brick_Ornate"
    },
    {
      "x": -14,
      "y": 5,
      "z": 2,
      "name": "Rock_Aqua_Brick_Ornate"
    },
    {
      "x": -14,
      "y": 6,
      "z": 2,
      "name": "Rock_Aqua_Brick_Decorative"
    },
    {
      "x": -14,
      "y": 7,
      "z": 2,
      "name": "Rock_Aqua_Brick_Ornate"
    },
    {
      "x": -14,
      "y": 8,
      "z": 2,
      "name": "Rock_Aqua_Brick_Ornate"
    },
    {
      "x": -14,
      "y": 0,
      "z": 3,
      "name": "Rock_Aqua_Brick_Decorative"
    },
    {
      "x": -14,
      "y": 1,
      "z": 3,
      "name": "Rock_Aqua_Brick_Smooth"
    },
    {
      "x": -14,
      "y": 2,
      "z": 3,
      "name": "Rock_Aqua_Brick_Smooth"
    },
    {
      "x": -14,
      "y": 3,
      "z": 3,
      "name": "Rock_Aqua_Brick_Decorative"
    },
    {
      "x": -14,
      "y": 4,
      "z": 3,
      "name": "Rock_Aqua_Brick_Smooth"
    },
    {
      "x": -14,
      "y": 5,
      "z": 3,
      "name": "Rock_Aqua_Brick_Smooth"
    },
    {
      "x": -14,
      "y": 6,
      "z": 3,
      "name": "Rock_Aqua_Brick_Decorative"
    },
    {
      "x": -14,
      "y": 7,
      "z": 3,
      "name": "Rock_Aqua_Brick_Smooth"
    },
    {
      "x": -14,
      "y": 8,
      "z": 3,
      "name": "Rock_Aqua_Brick_Smooth"
    },
    {
      "x": -14,
      "y": 0,
      "z": 4,
      "name": "Rock_Aqua_Brick_Decorative"
    },
    {
      "x": -14,
      "y": 1,
      "z": 4,
      "name": "Rock_Aqua_Brick_Ornate"
    },
    {
      "x": -14,
      "y": 2,
      "z": 4,
      "name": "Rock_Aqua_Brick_Ornate"
    },
    {
      "x": -14,
      "y": 3,
      "z": 4,
      "name": "Rock_Aqua_Brick_Decorative"
    },
    {
      "x": -14,
      "y": 4,
      "z": 4,
      "name": "Rock_Aqua_Brick_Ornate"
    },
    {
      "x": -14,
      "y": 5,
      "z": 4,
      "name": "Rock_Aqua_Brick_Ornate"
    },
    {
      "x": -14,
      "y": 6,
      "z": 4,
      "name": "Rock_Aqua_Brick_Decorative"
    },
    {
      "x": -14,
      "y": 7,
      "z": 4,
      "name": "Rock_Aqua_Brick_Ornate"
    },
    {
      "x": -14,
      "y": 8,
      "z": 4,
      "name": "Rock_Aqua_Brick_Ornate"
    },
    {
      "x": -14,
      "y": 0,
      "z": 5,
      "name": "Rock_Aqua_Brick_Decorative"
    },
    {
      "x": -14,
      "y": 1,
      "z": 5,
      "name": "Rock_Aqua_Brick_Smooth"
    },
    {
      "x": -14,
      "y": 2,
      "z": 5,
      "name": "Rock_Aqua_Brick_Smooth"
    },
    {
      "x": -14,
      "y": 3,
      "z": 5,
      "name": "Rock_Aqua_Brick_Decorative"
    },
    {
      "x": -14,
      "y": 4,
      "z": 5,
      "name": "Rock_Aqua_Brick_Smooth"
    },
    {
      "x": -14,
      "y": 5,
      "z": 5,
      "name": "Rock_Aqua_Brick_Smooth"
    },
    {
      "x": -14,
      "y": 6,
      "z": 5,
      "name": "Rock_Aqua_Brick_Decorative"
    },
    {
      "x": -14,
      "y": 7,
      "z": 5,
      "name": "Rock_Aqua_Brick_Smooth"
    },
    {
      "x": -14,
      "y": 8,
      "z": 5,
      "name": "Rock_Aqua_Brick_Smooth"
    },
    {
      "x": -14,
      "y": 0,
      "z": 6,
      "name": "Rock_Aqua_Brick_Decorative"
    },
    {
      "x": -14,
      "y": 1,
      "z": 6,
      "name": "Rock_Aqua_Brick_Ornate"
    },
    {
      "x": -14,
      "y": 2,
      "z": 6,
      "name": "Rock_Aqua_Brick_Ornate"
    },
    {
      "x": -14,
      "y": 3,
      "z": 6,
      "name": "Rock_Aqua_Brick_Decorative"
    },
    {
      "x": -14,
      "y": 4,
      "z": 6,
      "name": "Rock_Aqua_Brick_Ornate"
    },
    {
      "x": -14,
      "y": 5,
      "z": 6,
      "name": "Rock_Aqua_Brick_Ornate"
    },
    {
      "x": -14,
      "y": 6,
      "z": 6,
      "name": "Rock_Aqua_Brick_Decorative"
    },
    {
      "x": -14,
      "y": 7,
      "z": 6,
      "name": "Rock_Aqua_Brick_Ornate"
    },
    {
      "x": -14,
      "y": 8,
      "z": 6,
      "name": "Rock_Aqua_Brick_Ornate"
    },
    {
      "x": -13,
      "y": 0,
      "z": -8,
      "name": "Rock_Aqua_Brick_Decorative",
      "rotation": 3
    },
    {
      "x": -13,
      "y": 1,
      "z": -8,
      "name": "Rock_Aqua_Brick_Smooth",
      "rotation": 3
    },
    {
      "x": -13,
      "y": 2,
      "z": -8,
      "name": "Rock_Aqua_Brick_Smooth",
      "rotation": 3
    },
    {
      "x": -13,
      "y": 3,
      "z": -8,
      "name": "Rock_Aqua_Brick_Decorative",
      "rotation": 3
    },
    {
      "x": -13,
      "y": 4,
      "z": -8,
      "name": "Rock_Aqua_Brick_Smooth",
      "rotation": 3
    },
    {
      "x": -13,
      "y": 5,
      "z": -8,
      "name": "Rock_Aqua_Brick_Smooth",
      "rotation": 3
    },
    {
      "x": -13,
      "y": 6,
      "z": -8,
      "name": "Rock_Aqua_Brick_Decorative",
      "rotation": 3
    },
    {
      "x": -13,
      "y": 7,
      "z": -8,
      "name": "Rock_Aqua_Brick_Smooth",
      "rotation": 3
    },
    {
      "x": -13,
      "y": 8,
      "z": -8,
      "name": "Rock_Aqua_Brick_Smooth",
      "rotation": 3
    },
    {
      "x": -13,
      "y": 0,
      "z": -7,
      "name": "Rock_Aqua_Brick_Decorative",
      "rotation": 3
    },
    {
      "x": -13,
      "y": 1,
      "z": -7,
      "name": "Rock_Aqua_Brick_Ornate",
      "rotation": 3
    },
    {
      "x": -13,
      "y": 2,
      "z": -7,
      "name": "Rock_Aqua_Brick_Ornate",
      "rotation": 3
    },
    {
      "x": -13,
      "y": 3,
      "z": -7,
      "name": "Rock_Aqua_Brick_Decorative",
      "rotation": 3
    },
    {
      "x": -13,
      "y": 4,
      "z": -7,
      "name": "Rock_Aqua_Brick_Ornate",
      "rotation": 3
    },
    {
      "x": -13,
      "y": 5,
      "z": -7,
      "name": "Rock_Aqua_Brick_Ornate",
      "rotation": 3
    },
    {
      "x": -13,
      "y": 6,
      "z": -7,
      "name": "Rock_Aqua_Brick_Decorative",
      "rotation": 3
    },
    {
      "x": -13,
      "y": 7,
      "z": -7,
      "name": "Rock_Aqua_Brick_Ornate",
      "rotation": 3
    },
    {
      "x": -13,
      "y": 8,
      "z": -7,
      "name": "Rock_Aqua_Brick_Ornate",
      "rotation": 3
    },
    {
      "x": -13,
      "y": 0,
      "z": -6,
      "name": "Rock_Aqua_Brick_Decorative"
    },
    {
      "x": -13,
      "y": 1,
      "z": -6,
      "name": "Rock_Aqua_Brick_Ornate"
    },
    {
      "x": -13,
      "y": 2,
      "z": -6,
      "name": "Rock_Aqua_Brick_Ornate"
    },
    {
      "x": -13,
      "y": 3,
      "z": -6,
      "name": "Rock_Aqua_Brick_Decorative"
    },
    {
      "x": -13,
      "y": 4,
      "z": -6,
      "name": "Rock_Aqua_Brick_Ornate"
    },
    {
      "x": -13,
      "y": 5,
      "z": -6,
      "name": "Rock_Aqua_Brick_Ornate"
    },
    {
      "x": -13,
      "y": 6,
      "z": -6,
      "name": "Rock_Aqua_Brick_Decorative"
    },
    {
      "x": -13,
      "y": 7,
      "z": -6,
      "name": "Rock_Aqua_Brick_Ornate"
    },
    {
      "x": -13,
      "y": 8,
      "z": -6,
      "name": "Rock_Aqua_Brick_Ornate"
    },
    {
      "x": -13,
      "y": 9,
      "z": -6,
      "name": "Rock_Aqua_Brick_Decorative"
    },
    {
      "x": -13,
      "y": 10,
      "z": -6,
      "name": "Rock_Aqua_Brick_Ornate"
    },
    {
      "x": -13,
      "y": 0,
      "z": -5,
      "name": "Rock_Aqua_Brick_Decorative"
    },
    {
      "x": -13,
      "y": 1,
      "z": -5,
      "name": "Rock_Aqua_Brick_Smooth"
    },
    {
      "x": -13,
      "y": 2,
      "z": -5,
      "name": "Rock_Aqua_Brick_Smooth"
    },
    {
      "x": -13,
      "y": 3,
      "z": -5,
      "name": "Rock_Aqua_Brick_Decorative"
    },
    {
      "x": -13,
      "y": 4,
      "z": -5,
      "name": "Rock_Aqua_Brick_Smooth"
    },
    {
      "x": -13,
      "y": 5,
      "z": -5,
      "name": "Rock_Aqua_Brick_Smooth"
    },
    {
      "x": -13,
      "y": 6,
      "z": -5,
      "name": "Rock_Aqua_Brick_Decorative"
    },
    {
      "x": -13,
      "y": 7,
      "z": -5,
      "name": "Rock_Aqua_Brick_Smooth"
    },
    {
      "x": -13,
      "y": 8,
      "z": -5,
      "name": "Rock_Aqua_Brick_Smooth"
    },
    {
      "x": -13,
      "y": 9,
      "z": -5,
      "name": "Rock_Aqua_Brick_Decorative"
    },
    {
      "x": -13,
      "y": 10,
      "z": -5,
      "name": "Rock_Aqua_Brick_Smooth"
    },
    {
      "x": -13,
      "y": 0,
      "z": -4,
      "name": "Rock_Aqua_Brick_Decorative"
    },
    {
      "x": -13,
      "y": 1,
      "z": -4,
      "name": "Rock_Aqua_Brick_Ornate"
    },
    {
      "x": -13,
      "y": 2,
      "z": -4,
      "name": "Rock_Aqua_Brick_Ornate"
    },
    {
      "x": -13,
      "y": 3,
      "z": -4,
      "name": "Rock_Aqua_Brick_Decorative"
    },
    {
      "x": -13,
      "y": 4,
      "z": -4,
      "name": "Rock_Aqua_Brick_Ornate"
    },
    {
      "x": -13,
      "y": 5,
      "z": -4,
      "name": "Rock_Aqua_Brick_Ornate"
    },
    {
      "x": -13,
      "y": 6,
      "z": -4,
      "name": "Rock_Aqua_Brick_Decorative"
    },
    {
      "x": -13,
      "y": 7,
      "z": -4,
      "name": "Rock_Aqua_Brick_Ornate"
    },
    {
      "x": -13,
      "y": 8,
      "z": -4,
      "name": "Rock_Aqua_Brick_Ornate"
    },
    {
      "x": -13,
      "y": 9,
      "z": -4,
      "name": "Rock_Aqua_Brick_Decorative"
    },
    {
      "x": -13,
      "y": 10,
      "z": -4,
      "name": "Rock_Aqua_Brick_Ornate"
    },
    {
      "x": -13,
      "y": 0,
      "z": -3,
      "name": "Rock_Aqua_Brick_Decorative"
    },
    {
      "x": -13,
      "y": 1,
      "z": -3,
      "name": "Rock_Aqua_Brick_Smooth"
    },
    {
      "x": -13,
      "y": 2,
      "z": -3,
      "name": "Rock_Aqua_Brick_Smooth"
    },
    {
      "x": -13,
      "y": 3,
      "z": -3,
      "name": "Rock_Aqua_Brick_Decorative"
    },
    {
      "x": -13,
      "y": 4,
      "z": -3,
      "name": "Rock_Aqua_Brick_Smooth"
    },
    {
      "x": -13,
      "y": 5,
      "z": -3,
      "name": "Rock_Aqua_Brick_Smooth"
    },
    {
      "x": -13,
      "y": 6,
      "z": -3,
      "name": "Rock_Aqua_Brick_Decorative"
    },
    {
      "x": -13,
      "y": 7,
      "z": -3,
      "name": "Rock_Aqua_Brick_Smooth"
    },
    {
      "x": -13,
      "y": 8,
      "z": -3,
      "name": "Rock_Aqua_Brick_Smooth"
    },
    {
      "x": -13,
      "y": 9,
      "z": -3,
      "name": "Rock_Aqua_Brick_Decorative"
    },
    {
      "x": -13,
      "y": 10,
      "z": -3,
      "name": "Rock_Aqua_Brick_Smooth"
    },
    {
      "x": -13,
      "y": 0,
      "z": -2,
      "name": "Rock_Aqua_Brick_Decorative"
    },
    {
      "x": -13,
      "y": 1,
      "z": -2,
      "name": "Rock_Aqua_Brick_Ornate"
    },
    {
      "x": -13,
      "y": 2,
      "z": -2,
      "name": "Rock_Aqua_Brick_Ornate"
    },
    {
      "x": -13,
      "y": 3,
      "z": -2,
      "name": "Rock_Aqua_Brick_Decorative"
    },
    {
      "x": -13,
      "y": 4,
      "z": -2,
      "name": "Rock_Aqua_Brick_Ornate"
    },
    {
      "x": -13,
      "y": 5,
      "z": -2,
      "name": "Rock_Aqua_Brick_Ornate"
    },
    {
      "x": -13,
      "y": 6,
      "z": -2,
      "name": "Rock_Aqua_Brick_Decorative"
    },
    {
      "x": -13,
      "y": 7,
      "z": -2,
      "name": "Rock_Aqua_Brick_Ornate"
    },
    {
      "x": -13,
      "y": 8,
      "z": -2,
      "name": "Rock_Aqua_Brick_Ornate"
    },
    {
      "x": -13,
      "y": 9,
      "z": -2,
      "name": "Rock_Aqua_Brick_Decorative"
    },
    {
      "x": -13,
      "y": 10,
      "z": -2,
      "name": "Rock_Aqua_Brick_Ornate"
    },
    {
      "x": -13,
      "y": 0,
      "z": -1,
      "name": "Rock_Aqua_Brick_Decorative"
    },
    {
      "x": -13,
      "y": 1,
      "z": -1,
      "name": "Rock_Aqua_Brick_Smooth"
    },
    {
      "x": -13,
      "y": 2,
      "z": -1,
      "name": "Rock_Aqua_Brick_Smooth"
    },
    {
      "x": -13,
      "y": 3,
      "z": -1,
      "name": "Rock_Aqua_Brick_Decorative"
    },
    {
      "x": -13,
      "y": 4,
      "z": -1,
      "name": "Rock_Aqua_Brick_Smooth"
    },
    {
      "x": -13,
      "y": 5,
      "z": -1,
      "name": "Rock_Aqua_Brick_Smooth"
    },
    {
      "x": -13,
      "y": 6,
      "z": -1,
      "name": "Rock_Aqua_Brick_Decorative"
    },
    {
      "x": -13,
      "y": 7,
      "z": -1,
      "name": "Rock_Aqua_Brick_Smooth"
    },
    {
      "x": -13,
      "y": 8,
      "z": -1,
      "name": "Rock_Aqua_Brick_Smooth"
    },
    {
      "x": -13,
      "y": 9,
      "z": -1,
      "name": "Rock_Aqua_Brick_Decorative"
    },
    {
      "x": -13,
      "y": 10,
      "z": -1,
      "name": "Rock_Aqua_Brick_Smooth"
    },
    {
      "x": -13,
      "y": 0,
      "z": 0,
      "name": "Rock_Aqua_Brick_Decorative"
    },
    {
      "x": -13,
      "y": 1,
      "z": 0,
      "name": "Rock_Aqua_Brick_Ornate"
    },
    {
      "x": -13,
      "y": 2,
      "z": 0,
      "name": "Rock_Aqua_Brick_Ornate"
    },
    {
      "x": -13,
      "y": 3,
      "z": 0,
      "name": "Rock_Aqua_Brick_Decorative"
    },
    {
      "x": -13,
      "y": 4,
      "z": 0,
      "name": "Rock_Aqua_Brick_Ornate"
    },
    {
      "x": -13,
      "y": 5,
      "z": 0,
      "name": "Rock_Aqua_Brick_Ornate"
    },
    {
      "x": -13,
      "y": 6,
      "z": 0,
      "name": "Rock_Aqua_Brick_Decorative"
    },
    {
      "x": -13,
      "y": 7,
      "z": 0,
      "name": "Rock_Aqua_Brick_Ornate"
    },
    {
      "x": -13,
      "y": 8,
      "z": 0,
      "name": "Rock_Aqua_Brick_Ornate"
    },
    {
      "x": -13,
      "y": 9,
      "z": 0,
      "name": "Rock_Aqua_Brick_Decorative"
    },
    {
      "x": -13,
      "y": 10,
      "z": 0,
      "name": "Rock_Aqua_Brick_Ornate"
    },
    {
      "x": -13,
      "y": 0,
      "z": 1,
      "name": "Rock_Aqua_Brick_Decorative"
    },
    {
      "x": -13,
      "y": 1,
      "z": 1,
      "name": "Rock_Aqua_Brick_Smooth"
    },
    {
      "x": -13,
      "y": 2,
      "z": 1,
      "name": "Rock_Aqua_Brick_Smooth"
    },
    {
      "x": -13,
      "y": 3,
      "z": 1,
      "name": "Rock_Aqua_Brick_Decorative"
    },
    {
      "x": -13,
      "y": 4,
      "z": 1,
      "name": "Rock_Aqua_Brick_Smooth"
    },
    {
      "x": -13,
      "y": 5,
      "z": 1,
      "name": "Rock_Aqua_Brick_Smooth"
    },
    {
      "x": -13,
      "y": 6,
      "z": 1,
      "name": "Rock_Aqua_Brick_Decorative"
    },
    {
      "x": -13,
      "y": 7,
      "z": 1,
      "name": "Rock_Aqua_Brick_Smooth"
    },
    {
      "x": -13,
      "y": 8,
      "z": 1,
      "name": "Rock_Aqua_Brick_Smooth"
    },
    {
      "x": -13,
      "y": 9,
      "z": 1,
      "name": "Rock_Aqua_Brick_Decorative"
    },
    {
      "x": -13,
      "y": 10,
      "z": 1,
      "name": "Rock_Aqua_Brick_Smooth"
    },
    {
      "x": -13,
      "y": 0,
      "z": 2,
      "name": "Rock_Aqua_Brick_Decorative"
    },
    {
      "x": -13,
      "y": 1,
      "z": 2,
      "name": "Rock_Aqua_Brick_Ornate"
    },
    {
      "x": -13,
      "y": 2,
      "z": 2,
      "name": "Rock_Aqua_Brick_Ornate"
    },
    {
      "x": -13,
      "y": 3,
      "z": 2,
      "name": "Rock_Aqua_Brick_Decorative"
    },
    {
      "x": -13,
      "y": 4,
      "z": 2,
      "name": "Rock_Aqua_Brick_Ornate"
    },
    {
      "x": -13,
      "y": 5,
      "z": 2,
      "name": "Rock_Aqua_Brick_Ornate"
    },
    {
      "x": -13,
      "y": 6,
      "z": 2,
      "name": "Rock_Aqua_Brick_Decorative"
    },
    {
      "x": -13,
      "y": 7,
      "z": 2,
      "name": "Rock_Aqua_Brick_Ornate"
    },
    {
      "x": -13,
      "y": 8,
      "z": 2,
      "name": "Rock_Aqua_Brick_Ornate"
    },
    {
      "x": -13,
      "y": 9,
      "z": 2,
      "name": "Rock_Aqua_Brick_Decorative"
    },
    {
      "x": -13,
      "y": 10,
      "z": 2,
      "name": "Rock_Aqua_Brick_Ornate"
    },
    {
      "x": -13,
      "y": 0,
      "z": 3,
      "name": "Rock_Aqua_Brick_Decorative"
    },
    {
      "x": -13,
      "y": 1,
      "z": 3,
      "name": "Rock_Aqua_Brick_Smooth"
    },
    {
      "x": -13,
      "y": 2,
      "z": 3,
      "name": "Rock_Aqua_Brick_Smooth"
    },
    {
      "x": -13,
      "y": 3,
      "z": 3,
      "name": "Rock_Aqua_Brick_Decorative"
    },
    {
      "x": -13,
      "y": 4,
      "z": 3,
      "name": "Rock_Aqua_Brick_Smooth"
    },
    {
      "x": -13,
      "y": 5,
      "z": 3,
      "name": "Rock_Aqua_Brick_Smooth"
    },
    {
      "x": -13,
      "y": 6,
      "z": 3,
      "name": "Rock_Aqua_Brick_Decorative"
    },
    {
      "x": -13,
      "y": 7,
      "z": 3,
      "name": "Rock_Aqua_Brick_Smooth"
    },
    {
      "x": -13,
      "y": 8,
      "z": 3,
      "name": "Rock_Aqua_Brick_Smooth"
    },
    {
      "x": -13,
      "y": 9,
      "z": 3,
      "name": "Rock_Aqua_Brick_Decorative"
    },
    {
      "x": -13,
      "y": 10,
      "z": 3,
      "name": "Rock_Aqua_Brick_Smooth"
    },
    {
      "x": -13,
      "y": 0,
      "z": 4,
      "name": "Rock_Aqua_Brick_Decorative"
    },
    {
      "x": -13,
      "y": 1,
      "z": 4,
      "name": "Rock_Aqua_Brick_Ornate"
    },
    {
      "x": -13,
      "y": 2,
      "z": 4,
      "name": "Rock_Aqua_Brick_Ornate"
    },
    {
      "x": -13,
      "y": 3,
      "z": 4,
      "name": "Rock_Aqua_Brick_Decorative"
    },
    {
      "x": -13,
      "y": 4,
      "z": 4,
      "name": "Rock_Aqua_Brick_Ornate"
    },
    {
      "x": -13,
      "y": 5,
      "z": 4,
      "name": "Rock_Aqua_Brick_Ornate"
    },
    {
      "x": -13,
      "y": 6,
      "z": 4,
      "name": "Rock_Aqua_Brick_Decorative"
    },
    {
      "x": -13,
      "y": 7,
      "z": 4,
      "name": "Rock_Aqua_Brick_Ornate"
    },
    {
      "x": -13,
      "y": 8,
      "z": 4,
      "name": "Rock_Aqua_Brick_Ornate"
    },
    {
      "x": -13,
      "y": 9,
      "z": 4,
      "name": "Rock_Aqua_Brick_Decorative"
    },
    {
      "x": -13,
      "y": 10,
      "z": 4,
      "name": "Rock_Aqua_Brick_Ornate"
    },
    {
      "x": -13,
      "y": 0,
      "z": 5,
      "name": "Rock_Aqua_Brick_Decorative"
    },
    {
      "x": -13,
      "y": 1,
      "z": 5,
      "name": "Rock_Aqua_Brick_Smooth"
    },
    {
      "x": -13,
      "y": 2,
      "z": 5,
      "name": "Rock_Aqua_Brick_Smooth"
    },
    {
      "x": -13,
      "y": 3,
      "z": 5,
      "name": "Rock_Aqua_Brick_Decorative"
    },
    {
      "x": -13,
      "y": 4,
      "z": 5,
      "name": "Rock_Aqua_Brick_Smooth"
    },
    {
      "x": -13,
      "y": 5,
      "z": 5,
      "name": "Rock_Aqua_Brick_Smooth"
    },
    {
      "x": -13,
      "y": 6,
      "z": 5,
      "name": "Rock_Aqua_Brick_Decorative"
    },
    {
      "x": -13,
      "y": 7,
      "z": 5,
      "name": "Rock_Aqua_Brick_Smooth"
    },
    {
      "x": -13,
      "y": 8,
      "z": 5,
      "name": "Rock_Aqua_Brick_Smooth"
    },
    {
      "x": -13,
      "y": 9,
      "z": 5,
      "name": "Rock_Aqua_Brick_Decorative"
    },
    {
      "x": -13,
      "y": 10,
      "z": 5,
      "name": "Rock_Aqua_Brick_Smooth"
    },
    {
      "x": -13,
      "y": 0,
      "z": 6,
      "name": "Rock_Aqua_Brick_Decorative"
    },
    {
      "x": -13,
      "y": 1,
      "z": 6,
      "name": "Rock_Aqua_Brick_Ornate"
    },
    {
      "x": -13,
      "y": 2,
      "z": 6,
      "name": "Rock_Aqua_Brick_Ornate"
    },
    {
      "x": -13,
      "y": 3,
      "z": 6,
      "name": "Rock_Aqua_Brick_Decorative"
    },
    {
      "x": -13,
      "y": 4,
      "z": 6,
      "name": "Rock_Aqua_Brick_Ornate"
    },
    {
      "x": -13,
      "y": 5,
      "z": 6,
      "name": "Rock_Aqua_Brick_Ornate"
    },
    {
      "x": -13,
      "y": 6,
      "z": 6,
      "name": "Rock_Aqua_Brick_Decorative"
    },
    {
      "x": -13,
      "y": 7,
      "z": 6,
      "name": "Rock_Aqua_Brick_Ornate"
    },
    {
      "x": -13,
      "y": 8,
      "z": 6,
      "name": "Rock_Aqua_Brick_Ornate"
    },
    {
      "x": -13,
      "y": 9,
      "z": 6,
      "name": "Rock_Aqua_Brick_Decorative"
    },
    {
      "x": -13,
      "y": 10,
      "z": 6,
      "name": "Rock_Aqua_Brick_Ornate"
    },
    {
      "x": -13,
      "y": 0,
      "z": 7,
      "name": "Rock_Aqua_Brick_Decorative"
    },
    {
      "x": -13,
      "y": 1,
      "z": 7,
      "name": "Rock_Aqua_Brick_Ornate"
    },
    {
      "x": -13,
      "y": 2,
      "z": 7,
      "name": "Rock_Aqua_Brick_Ornate"
    },
    {
      "x": -13,
      "y": 3,
      "z": 7,
      "name": "Rock_Aqua_Brick_Decorative"
    },
    {
      "x": -13,
      "y": 4,
      "z": 7,
      "name": "Rock_Aqua_Brick_Ornate"
    },
    {
      "x": -13,
      "y": 5,
      "z": 7,
      "name": "Rock_Aqua_Brick_Ornate"
    },
    {
      "x": -13,
      "y": 6,
      "z": 7,
      "name": "Rock_Aqua_Brick_Decorative"
    },
    {
      "x": -13,
      "y": 7,
      "z": 7,
      "name": "Rock_Aqua_Brick_Ornate"
    },
    {
      "x": -13,
      "y": 8,
      "z": 7,
      "name": "Rock_Aqua_Brick_Ornate"
    },
    {
      "x": -13,
      "y": 0,
      "z": 8,
      "name": "Rock_Aqua_Brick_Decorative"
    },
    {
      "x": -13,
      "y": 1,
      "z": 8,
      "name": "Rock_Aqua_Brick_Smooth"
    },
    {
      "x": -13,
      "y": 2,
      "z": 8,
      "name": "Rock_Aqua_Brick_Smooth"
    },
    {
      "x": -13,
      "y": 3,
      "z": 8,
      "name": "Rock_Aqua_Brick_Decorative"
    },
    {
      "x": -13,
      "y": 4,
      "z": 8,
      "name": "Rock_Aqua_Brick_Smooth"
    },
    {
      "x": -13,
      "y": 5,
      "z": 8,
      "name": "Rock_Aqua_Brick_Smooth"
    },
    {
      "x": -13,
      "y": 6,
      "z": 8,
      "name": "Rock_Aqua_Brick_Decorative"
    },
    {
      "x": -13,
      "y": 7,
      "z": 8,
      "name": "Rock_Aqua_Brick_Smooth"
    },
    {
      "x": -13,
      "y": 8,
      "z": 8,
      "name": "Rock_Aqua_Brick_Smooth"
    },
    {
      "x": -12,
      "y": 0,
      "z": -9,
      "name": "Rock_Aqua_Brick_Decorative",
      "rotation": 3
    },
    {
      "x": -12,
      "y": 1,
      "z": -9,
      "name": "Rock_Aqua_Brick_Smooth",
      "rotation": 3
    },
    {
      "x": -12,
      "y": 2,
      "z": -9,
      "name": "Rock_Aqua_Brick_Smooth",
      "rotation": 3
    },
    {
      "x": -12,
      "y": 3,
      "z": -9,
      "name": "Rock_Aqua_Brick_Decorative",
      "rotation": 3
    },
    {
      "x": -12,
      "y": 4,
      "z": -9,
      "name": "Rock_Aqua_Brick_Smooth",
      "rotation": 3
    },
    {
      "x": -12,
      "y": 5,
      "z": -9,
      "name": "Rock_Aqua_Brick_Smooth",
      "rotation": 3
    },
    {
      "x": -12,
      "y": 6,
      "z": -9,
      "name": "Rock_Aqua_Brick_Decorative",
      "rotation": 3
    },
    {
      "x": -12,
      "y": 7,
      "z": -9,
      "name": "Rock_Aqua_Brick_Smooth",
      "rotation": 3
    },
    {
      "x": -12,
      "y": 8,
      "z": -9,
      "name": "Rock_Aqua_Brick_Smooth",
      "rotation": 3
    },
    {
      "x": -12,
      "y": 0,
      "z": -8,
      "name": "Rock_Aqua_Brick_Decorative",
      "rotation": 3
    },
    {
      "x": -12,
      "y": 1,
      "z": -8,
      "name": "Rock_Aqua_Brick_Smooth",
      "rotation": 3
    },
    {
      "x": -12,
      "y": 2,
      "z": -8,
      "name": "Rock_Aqua_Brick_Smooth",
      "rotation": 3
    },
    {
      "x": -12,
      "y": 3,
      "z": -8,
      "name": "Rock_Aqua_Brick_Decorative",
      "rotation": 3
    },
    {
      "x": -12,
      "y": 4,
      "z": -8,
      "name": "Rock_Aqua_Brick_Smooth",
      "rotation": 3
    },
    {
      "x": -12,
      "y": 5,
      "z": -8,
      "name": "Rock_Aqua_Brick_Smooth",
      "rotation": 3
    },
    {
      "x": -12,
      "y": 6,
      "z": -8,
      "name": "Rock_Aqua_Brick_Decorative",
      "rotation": 3
    },
    {
      "x": -12,
      "y": 7,
      "z": -8,
      "name": "Rock_Aqua_Brick_Smooth",
      "rotation": 3
    },
    {
      "x": -12,
      "y": 8,
      "z": -8,
      "name": "Rock_Aqua_Brick_Smooth",
      "rotation": 3
    },
    {
      "x": -12,
      "y": 9,
      "z": -8,
      "name": "Rock_Aqua_Brick_Decorative"
    },
    {
      "x": -12,
      "y": 10,
      "z": -8,
      "name": "Rock_Aqua_Brick_Smooth"
    },
    {
      "x": -12,
      "y": 0,
      "z": -7,
      "name": "Rock_Aqua_Brick_Decorative",
      "rotation": 3
    },
    {
      "x": -12,
      "y": 1,
      "z": -7,
      "name": "Rock_Aqua_Brick_Ornate",
      "rotation": 3
    },
    {
      "x": -12,
      "y": 2,
      "z": -7,
      "name": "Rock_Aqua_Brick_Ornate",
      "rotation": 3
    },
    {
      "x": -12,
      "y": 3,
      "z": -7,
      "name": "Rock_Aqua_Brick_Decorative",
      "rotation": 3
    },
    {
      "x": -12,
      "y": 4,
      "z": -7,
      "name": "Rock_Aqua_Brick_Ornate",
      "rotation": 3
    },
    {
      "x": -12,
      "y": 5,
      "z": -7,
      "name": "Rock_Aqua_Brick_Ornate",
      "rotation": 3
    },
    {
      "x": -12,
      "y": 6,
      "z": -7,
      "name": "Rock_Aqua_Brick_Decorative",
      "rotation": 3
    },
    {
      "x": -12,
      "y": 7,
      "z": -7,
      "name": "Rock_Aqua_Brick_Ornate",
      "rotation": 3
    },
    {
      "x": -12,
      "y": 8,
      "z": -7,
      "name": "Rock_Aqua_Brick_Ornate",
      "rotation": 3
    },
    {
      "x": -12,
      "y": 9,
      "z": -7,
      "name": "Rock_Aqua_Brick_Decorative"
    },
    {
      "x": -12,
      "y": 10,
      "z": -7,
      "name": "Rock_Aqua_Brick_Ornate"
    },
    {
      "x": -12,
      "y": 0,
      "z": -6,
      "name": "Rock_Aqua_Brick_Decorative"
    },
    {
      "x": -12,
      "y": 1,
      "z": -6,
      "name": "Rock_Aqua_Brick_Ornate"
    },
    {
      "x": -12,
      "y": 2,
      "z": -6,
      "name": "Rock_Aqua_Brick_Ornate"
    },
    {
      "x": -12,
      "y": 3,
      "z": -6,
      "name": "Rock_Aqua_Brick_Decorative"
    },
    {
      "x": -12,
      "y": 4,
      "z": -6,
      "name": "Rock_Aqua_Brick_Ornate"
    },
    {
      "x": -12,
      "y": 5,
      "z": -6,
      "name": "Rock_Aqua_Brick_Ornate"
    },
    {
      "x": -12,
      "y": 6,
      "z": -6,
      "name": "Rock_Aqua_Brick_Decorative"
    },
    {
      "x": -12,
      "y": 7,
      "z": -6,
      "name": "Rock_Aqua_Brick_Ornate"
    },
    {
      "x": -12,
      "y": 8,
      "z": -6,
      "name": "Rock_Aqua_Brick_Ornate"
    },
    {
      "x": -12,
      "y": 9,
      "z": -6,
      "name": "Rock_Aqua_Brick_Decorative"
    },
    {
      "x": -12,
      "y": 10,
      "z": -6,
      "name": "Rock_Aqua_Brick_Ornate"
    },
    {
      "x": -12,
      "y": 11,
      "z": -6,
      "name": "Rock_Aqua_Brick_Ornate"
    },
    {
      "x": -12,
      "y": 12,
      "z": -6,
      "name": "Rock_Aqua_Brick_Decorative"
    },
    {
      "x": -12,
      "y": 0,
      "z": -5,
      "name": "Rock_Aqua_Brick_Decorative"
    },
    {
      "x": -12,
      "y": 1,
      "z": -5,
      "name": "Rock_Aqua_Brick_Smooth"
    },
    {
      "x": -12,
      "y": 2,
      "z": -5,
      "name": "Rock_Aqua_Brick_Smooth"
    },
    {
      "x": -12,
      "y": 3,
      "z": -5,
      "name": "Rock_Aqua_Brick_Decorative"
    },
    {
      "x": -12,
      "y": 4,
      "z": -5,
      "name": "Rock_Aqua_Brick_Smooth"
    },
    {
      "x": -12,
      "y": 5,
      "z": -5,
      "name": "Rock_Aqua_Brick_Smooth"
    },
    {
      "x": -12,
      "y": 6,
      "z": -5,
      "name": "Rock_Aqua_Brick_Decorative"
    },
    {
      "x": -12,
      "y": 7,
      "z": -5,
      "name": "Rock_Aqua_Brick_Smooth"
    },
    {
      "x": -12,
      "y": 8,
      "z": -5,
      "name": "Rock_Aqua_Brick_Smooth"
    },
    {
      "x": -12,
      "y": 9,
      "z": -5,
      "name": "Rock_Aqua_Brick_Decorative"
    },
    {
      "x": -12,
      "y": 10,
      "z": -5,
      "name": "Rock_Aqua_Brick_Smooth"
    },
    {
      "x": -12,
      "y": 11,
      "z": -5,
      "name": "Rock_Aqua_Brick_Smooth"
    },
    {
      "x": -12,
      "y": 12,
      "z": -5,
      "name": "Rock_Aqua_Brick_Decorative"
    },
    {
      "x": -12,
      "y": 0,
      "z": -4,
      "name": "Rock_Aqua_Brick_Decorative"
    },
    {
      "x": -12,
      "y": 1,
      "z": -4,
      "name": "Rock_Aqua_Brick_Ornate"
    },
    {
      "x": -12,
      "y": 2,
      "z": -4,
      "name": "Rock_Aqua_Brick_Ornate"
    },
    {
      "x": -12,
      "y": 3,
      "z": -4,
      "name": "Rock_Aqua_Brick_Decorative"
    },
    {
      "x": -12,
      "y": 4,
      "z": -4,
      "name": "Rock_Aqua_Brick_Ornate"
    },
    {
      "x": -12,
      "y": 5,
      "z": -4,
      "name": "Rock_Aqua_Brick_Ornate"
    },
    {
      "x": -12,
      "y": 6,
      "z": -4,
      "name": "Rock_Aqua_Brick_Decorative"
    },
    {
      "x": -12,
      "y": 7,
      "z": -4,
      "name": "Rock_Aqua_Brick_Ornate"
    },
    {
      "x": -12,
      "y": 8,
      "z": -4,
      "name": "Rock_Aqua_Brick_Ornate"
    },
    {
      "x": -12,
      "y": 9,
      "z": -4,
      "name": "Rock_Aqua_Brick_Decorative"
    },
    {
      "x": -12,
      "y": 10,
      "z": -4,
      "name": "Rock_Aqua_Brick_Ornate"
    },
    {
      "x": -12,
      "y": 11,
      "z": -4,
      "name": "Rock_Aqua_Brick_Ornate"
    },
    {
      "x": -12,
      "y": 12,
      "z": -4,
      "name": "Rock_Aqua_Brick_Decorative"
    },
    {
      "x": -12,
      "y": 0,
      "z": -3,
      "name": "Rock_Aqua_Brick_Decorative"
    },
    {
      "x": -12,
      "y": 1,
      "z": -3,
      "name": "Rock_Aqua_Brick_Smooth"
    },
    {
      "x": -12,
      "y": 2,
      "z": -3,
      "name": "Rock_Aqua_Brick_Smooth"
    },
    {
      "x": -12,
      "y": 3,
      "z": -3,
      "name": "Rock_Aqua_Brick_Decorative"
    },
    {
      "x": -12,
      "y": 4,
      "z": -3,
      "name": "Rock_Aqua_Brick_Smooth"
    },
    {
      "x": -12,
      "y": 5,
      "z": -3,
      "name": "Rock_Aqua_Brick_Smooth"
    },
    {
      "x": -12,
      "y": 6,
      "z": -3,
      "name": "Rock_Aqua_Brick_Decorative"
    },
    {
      "x": -12,
      "y": 7,
      "z": -3,
      "name": "Rock_Aqua_Brick_Smooth"
    },
    {
      "x": -12,
      "y": 8,
      "z": -3,
      "name": "Rock_Aqua_Brick_Smooth"
    },
    {
      "x": -12,
      "y": 9,
      "z": -3,
      "name": "Rock_Aqua_Brick_Decorative"
    },
    {
      "x": -12,
      "y": 10,
      "z": -3,
      "name": "Rock_Aqua_Brick_Smooth"
    },
    {
      "x": -12,
      "y": 11,
      "z": -3,
      "name": "Rock_Aqua_Brick_Smooth"
    },
    {
      "x": -12,
      "y": 12,
      "z": -3,
      "name": "Rock_Aqua_Brick_Decorative"
    },
    {
      "x": -12,
      "y": 0,
      "z": -2,
      "name": "Rock_Aqua_Brick_Decorative"
    },
    {
      "x": -12,
      "y": 1,
      "z": -2,
      "name": "Rock_Aqua_Brick_Ornate"
    },
    {
      "x": -12,
      "y": 2,
      "z": -2,
      "name": "Rock_Aqua_Brick_Ornate"
    },
    {
      "x": -12,
      "y": 3,
      "z": -2,
      "name": "Rock_Aqua_Brick_Decorative"
    },
    {
      "x": -12,
      "y": 4,
      "z": -2,
      "name": "Rock_Aqua_Brick_Ornate"
    },
    {
      "x": -12,
      "y": 5,
      "z": -2,
      "name": "Rock_Aqua_Brick_Ornate"
    },
    {
      "x": -12,
      "y": 6,
      "z": -2,
      "name": "Rock_Aqua_Brick_Decorative"
    },
    {
      "x": -12,
      "y": 7,
      "z": -2,
      "name": "Rock_Aqua_Brick_Ornate"
    },
    {
      "x": -12,
      "y": 8,
      "z": -2,
      "name": "Rock_Aqua_Brick_Ornate"
    },
    {
      "x": -12,
      "y": 9,
      "z": -2,
      "name": "Rock_Aqua_Brick_Decorative"
    },
    {
      "x": -12,
      "y": 10,
      "z": -2,
      "name": "Rock_Aqua_Brick_Ornate"
    },
    {
      "x": -12,
      "y": 11,
      "z": -2,
      "name": "Rock_Aqua_Brick_Ornate"
    },
    {
      "x": -12,
      "y": 12,
      "z": -2,
      "name": "Rock_Aqua_Brick_Decorative"
    },
    {
      "x": -12,
      "y": 0,
      "z": -1,
      "name": "Rock_Aqua_Brick_Decorative"
    },
    {
      "x": -12,
      "y": 1,
      "z": -1,
      "name": "Rock_Aqua_Brick_Smooth"
    },
    {
      "x": -12,
      "y": 2,
      "z": -1,
      "name": "Rock_Aqua_Brick_Smooth"
    },
    {
      "x": -12,
      "y": 3,
      "z": -1,
      "name": "Rock_Aqua_Brick_Decorative"
    },
    {
      "x": -12,
      "y": 4,
      "z": -1,
      "name": "Rock_Aqua_Brick_Smooth"
    },
    {
      "x": -12,
      "y": 5,
      "z": -1,
      "name": "Rock_Aqua_Brick_Smooth"
    },
    {
      "x": -12,
      "y": 6,
      "z": -1,
      "name": "Rock_Aqua_Brick_Decorative"
    },
    {
      "x": -12,
      "y": 7,
      "z": -1,
      "name": "Rock_Aqua_Brick_Smooth"
    },
    {
      "x": -12,
      "y": 8,
      "z": -1,
      "name": "Rock_Aqua_Brick_Smooth"
    },
    {
      "x": -12,
      "y": 9,
      "z": -1,
      "name": "Rock_Aqua_Brick_Decorative"
    },
    {
      "x": -12,
      "y": 10,
      "z": -1,
      "name": "Rock_Aqua_Brick_Smooth"
    },
    {
      "x": -12,
      "y": 11,
      "z": -1,
      "name": "Rock_Aqua_Brick_Smooth"
    },
    {
      "x": -12,
      "y": 12,
      "z": -1,
      "name": "Rock_Aqua_Brick_Decorative"
    },
    {
      "x": -12,
      "y": 0,
      "z": 0,
      "name": "Rock_Aqua_Brick_Decorative"
    },
    {
      "x": -12,
      "y": 1,
      "z": 0,
      "name": "Rock_Aqua_Brick_Ornate"
    },
    {
      "x": -12,
      "y": 2,
      "z": 0,
      "name": "Rock_Aqua_Brick_Ornate"
    },
    {
      "x": -12,
      "y": 3,
      "z": 0,
      "name": "Rock_Aqua_Brick_Decorative"
    },
    {
      "x": -12,
      "y": 4,
      "z": 0,
      "name": "Rock_Aqua_Brick_Ornate"
    },
    {
      "x": -12,
      "y": 5,
      "z": 0,
      "name": "Rock_Aqua_Brick_Ornate"
    },
    {
      "x": -12,
      "y": 6,
      "z": 0,
      "name": "Rock_Aqua_Brick_Decorative"
    },
    {
      "x": -12,
      "y": 7,
      "z": 0,
      "name": "Rock_Aqua_Brick_Ornate"
    },
    {
      "x": -12,
      "y": 8,
      "z": 0,
      "name": "Rock_Aqua_Brick_Ornate"
    },
    {
      "x": -12,
      "y": 9,
      "z": 0,
      "name": "Rock_Aqua_Brick_Decorative"
    },
    {
      "x": -12,
      "y": 10,
      "z": 0,
      "name": "Rock_Aqua_Brick_Ornate"
    },
    {
      "x": -12,
      "y": 11,
      "z": 0,
      "name": "Rock_Aqua_Brick_Ornate"
    },
    {
      "x": -12,
      "y": 12,
      "z": 0,
      "name": "Rock_Aqua_Brick_Decorative"
    },
    {
      "x": -12,
      "y": 0,
      "z": 1,
      "name": "Rock_Aqua_Brick_Decorative"
    },
    {
      "x": -12,
      "y": 1,
      "z": 1,
      "name": "Rock_Aqua_Brick_Smooth"
    },
    {
      "x": -12,
      "y": 2,
      "z": 1,
      "name": "Rock_Aqua_Brick_Smooth"
    },
    {
      "x": -12,
      "y": 3,
      "z": 1,
      "name": "Rock_Aqua_Brick_Decorative"
    },
    {
      "x": -12,
      "y": 4,
      "z": 1,
      "name": "Rock_Aqua_Brick_Smooth"
    },
    {
      "x": -12,
      "y": 5,
      "z": 1,
      "name": "Rock_Aqua_Brick_Smooth"
    },
    {
      "x": -12,
      "y": 6,
      "z": 1,
      "name": "Rock_Aqua_Brick_Decorative"
    },
    {
      "x": -12,
      "y": 7,
      "z": 1,
      "name": "Rock_Aqua_Brick_Smooth"
    },
    {
      "x": -12,
      "y": 8,
      "z": 1,
      "name": "Rock_Aqua_Brick_Smooth"
    },
    {
      "x": -12,
      "y": 9,
      "z": 1,
      "name": "Rock_Aqua_Brick_Decorative"
    },
    {
      "x": -12,
      "y": 10,
      "z": 1,
      "name": "Rock_Aqua_Brick_Smooth"
    },
    {
      "x": -12,
      "y": 11,
      "z": 1,
      "name": "Rock_Aqua_Brick_Smooth"
    },
    {
      "x": -12,
      "y": 12,
      "z": 1,
      "name": "Rock_Aqua_Brick_Decorative"
    },
    {
      "x": -12,
      "y": 0,
      "z": 2,
      "name": "Rock_Aqua_Brick_Decorative"
    },
    {
      "x": -12,
      "y": 1,
      "z": 2,
      "name": "Rock_Aqua_Brick_Ornate"
    },
    {
      "x": -12,
      "y": 2,
      "z": 2,
      "name": "Rock_Aqua_Brick_Ornate"
    },
    {
      "x": -12,
      "y": 3,
      "z": 2,
      "name": "Rock_Aqua_Brick_Decorative"
    },
    {
      "x": -12,
      "y": 4,
      "z": 2,
      "name": "Rock_Aqua_Brick_Ornate"
    },
    {
      "x": -12,
      "y": 5,
      "z": 2,
      "name": "Rock_Aqua_Brick_Ornate"
    },
    {
      "x": -12,
      "y": 6,
      "z": 2,
      "name": "Rock_Aqua_Brick_Decorative"
    },
    {
      "x": -12,
      "y": 7,
      "z": 2,
      "name": "Rock_Aqua_Brick_Ornate"
    },
    {
      "x": -12,
      "y": 8,
      "z": 2,
      "name": "Rock_Aqua_Brick_Ornate"
    },
    {
      "x": -12,
      "y": 9,
      "z": 2,
      "name": "Rock_Aqua_Brick_Decorative"
    },
    {
      "x": -12,
      "y": 10,
      "z": 2,
      "name": "Rock_Aqua_Brick_Ornate"
    },
    {
      "x": -12,
      "y": 11,
      "z": 2,
      "name": "Rock_Aqua_Brick_Ornate"
    },
    {
      "x": -12,
      "y": 12,
      "z": 2,
      "name": "Rock_Aqua_Brick_Decorative"
    },
    {
      "x": -12,
      "y": 0,
      "z": 3,
      "name": "Rock_Aqua_Brick_Decorative"
    },
    {
      "x": -12,
      "y": 1,
      "z": 3,
      "name": "Rock_Aqua_Brick_Smooth"
    },
    {
      "x": -12,
      "y": 2,
      "z": 3,
      "name": "Rock_Aqua_Brick_Smooth"
    },
    {
      "x": -12,
      "y": 3,
      "z": 3,
      "name": "Rock_Aqua_Brick_Decorative"
    },
    {
      "x": -12,
      "y": 4,
      "z": 3,
      "name": "Rock_Aqua_Brick_Smooth"
    },
    {
      "x": -12,
      "y": 5,
      "z": 3,
      "name": "Rock_Aqua_Brick_Smooth"
    },
    {
      "x": -12,
      "y": 6,
      "z": 3,
      "name": "Rock_Aqua_Brick_Decorative"
    },
    {
      "x": -12,
      "y": 7,
      "z": 3,
      "name": "Rock_Aqua_Brick_Smooth"
    },
    {
      "x": -12,
      "y": 8,
      "z": 3,
      "name": "Rock_Aqua_Brick_Smooth"
    },
    {
      "x": -12,
      "y": 9,
      "z": 3,
      "name": "Rock_Aqua_Brick_Decorative"
    },
    {
      "x": -12,
      "y": 10,
      "z": 3,
      "name": "Rock_Aqua_Brick_Smooth"
    },
    {
      "x": -12,
      "y": 11,
      "z": 3,
      "name": "Rock_Aqua_Brick_Smooth"
    },
    {
      "x": -12,
      "y": 12,
      "z": 3,
      "name": "Rock_Aqua_Brick_Decorative"
    },
    {
      "x": -12,
      "y": 0,
      "z": 4,
      "name": "Rock_Aqua_Brick_Decorative"
    },
    {
      "x": -12,
      "y": 1,
      "z": 4,
      "name": "Rock_Aqua_Brick_Ornate"
    },
    {
      "x": -12,
      "y": 2,
      "z": 4,
      "name": "Rock_Aqua_Brick_Ornate"
    },
    {
      "x": -12,
      "y": 3,
      "z": 4,
      "name": "Rock_Aqua_Brick_Decorative"
    },
    {
      "x": -12,
      "y": 4,
      "z": 4,
      "name": "Rock_Aqua_Brick_Ornate"
    },
    {
      "x": -12,
      "y": 5,
      "z": 4,
      "name": "Rock_Aqua_Brick_Ornate"
    },
    {
      "x": -12,
      "y": 6,
      "z": 4,
      "name": "Rock_Aqua_Brick_Decorative"
    },
    {
      "x": -12,
      "y": 7,
      "z": 4,
      "name": "Rock_Aqua_Brick_Ornate"
    },
    {
      "x": -12,
      "y": 8,
      "z": 4,
      "name": "Rock_Aqua_Brick_Ornate"
    },
    {
      "x": -12,
      "y": 9,
      "z": 4,
      "name": "Rock_Aqua_Brick_Decorative"
    },
    {
      "x": -12,
      "y": 10,
      "z": 4,
      "name": "Rock_Aqua_Brick_Ornate"
    },
    {
      "x": -12,
      "y": 11,
      "z": 4,
      "name": "Rock_Aqua_Brick_Ornate"
    },
    {
      "x": -12,
      "y": 12,
      "z": 4,
      "name": "Rock_Aqua_Brick_Decorative"
    },
    {
      "x": -12,
      "y": 0,
      "z": 5,
      "name": "Rock_Aqua_Brick_Decorative"
    },
    {
      "x": -12,
      "y": 1,
      "z": 5,
      "name": "Rock_Aqua_Brick_Smooth"
    },
    {
      "x": -12,
      "y": 2,
      "z": 5,
      "name": "Rock_Aqua_Brick_Smooth"
    },
    {
      "x": -12,
      "y": 3,
      "z": 5,
      "name": "Rock_Aqua_Brick_Decorative"
    },
    {
      "x": -12,
      "y": 4,
      "z": 5,
      "name": "Rock_Aqua_Brick_Smooth"
    },
    {
      "x": -12,
      "y": 5,
      "z": 5,
      "name": "Rock_Aqua_Brick_Smooth"
    },
    {
      "x": -12,
      "y": 6,
      "z": 5,
      "name": "Rock_Aqua_Brick_Decorative"
    },
    {
      "x": -12,
      "y": 7,
      "z": 5,
      "name": "Rock_Aqua_Brick_Smooth"
    },
    {
      "x": -12,
      "y": 8,
      "z": 5,
      "name": "Rock_Aqua_Brick_Smooth"
    },
    {
      "x": -12,
      "y": 9,
      "z": 5,
      "name": "Rock_Aqua_Brick_Decorative"
    },
    {
      "x": -12,
      "y": 10,
      "z": 5,
      "name": "Rock_Aqua_Brick_Smooth"
    },
    {
      "x": -12,
      "y": 11,
      "z": 5,
      "name": "Rock_Aqua_Brick_Smooth"
    },
    {
      "x": -12,
      "y": 12,
      "z": 5,
      "name": "Rock_Aqua_Brick_Decorative"
    },
    {
      "x": -12,
      "y": 0,
      "z": 6,
      "name": "Rock_Aqua_Brick_Decorative"
    },
    {
      "x": -12,
      "y": 1,
      "z": 6,
      "name": "Rock_Aqua_Brick_Ornate"
    },
    {
      "x": -12,
      "y": 2,
      "z": 6,
      "name": "Rock_Aqua_Brick_Ornate"
    },
    {
      "x": -12,
      "y": 3,
      "z": 6,
      "name": "Rock_Aqua_Brick_Decorative"
    },
    {
      "x": -12,
      "y": 4,
      "z": 6,
      "name": "Rock_Aqua_Brick_Ornate"
    },
    {
      "x": -12,
      "y": 5,
      "z": 6,
      "name": "Rock_Aqua_Brick_Ornate"
    },
    {
      "x": -12,
      "y": 6,
      "z": 6,
      "name": "Rock_Aqua_Brick_Decorative"
    },
    {
      "x": -12,
      "y": 7,
      "z": 6,
      "name": "Rock_Aqua_Brick_Ornate"
    },
    {
      "x": -12,
      "y": 8,
      "z": 6,
      "name": "Rock_Aqua_Brick_Ornate"
    },
    {
      "x": -12,
      "y": 9,
      "z": 6,
      "name": "Rock_Aqua_Brick_Decorative"
    },
    {
      "x": -12,
      "y": 10,
      "z": 6,
      "name": "Rock_Aqua_Brick_Ornate"
    },
    {
      "x": -12,
      "y": 11,
      "z": 6,
      "name": "Rock_Aqua_Brick_Ornate"
    },
    {
      "x": -12,
      "y": 12,
      "z": 6,
      "name": "Rock_Aqua_Brick_Decorative"
    },
    {
      "x": -12,
      "y": 0,
      "z": 7,
      "name": "Rock_Aqua_Brick_Decorative"
    },
    {
      "x": -12,
      "y": 1,
      "z": 7,
      "name": "Rock_Aqua_Brick_Ornate"
    },
    {
      "x": -12,
      "y": 2,
      "z": 7,
      "name": "Rock_Aqua_Brick_Ornate"
    },
    {
      "x": -12,
      "y": 3,
      "z": 7,
      "name": "Rock_Aqua_Brick_Decorative"
    },
    {
      "x": -12,
      "y": 4,
      "z": 7,
      "name": "Rock_Aqua_Brick_Ornate"
    },
    {
      "x": -12,
      "y": 5,
      "z": 7,
      "name": "Rock_Aqua_Brick_Ornate"
    },
    {
      "x": -12,
      "y": 6,
      "z": 7,
      "name": "Rock_Aqua_Brick_Decorative"
    },
    {
      "x": -12,
      "y": 7,
      "z": 7,
      "name": "Rock_Aqua_Brick_Ornate"
    },
    {
      "x": -12,
      "y": 8,
      "z": 7,
      "name": "Rock_Aqua_Brick_Ornate"
    },
    {
      "x": -12,
      "y": 9,
      "z": 7,
      "name": "Rock_Aqua_Brick_Decorative"
    },
    {
      "x": -12,
      "y": 10,
      "z": 7,
      "name": "Rock_Aqua_Brick_Ornate"
    },
    {
      "x": -12,
      "y": 0,
      "z": 8,
      "name": "Rock_Aqua_Brick_Decorative"
    },
    {
      "x": -12,
      "y": 1,
      "z": 8,
      "name": "Rock_Aqua_Brick_Smooth"
    },
    {
      "x": -12,
      "y": 2,
      "z": 8,
      "name": "Rock_Aqua_Brick_Smooth"
    },
    {
      "x": -12,
      "y": 3,
      "z": 8,
      "name": "Rock_Aqua_Brick_Decorative"
    },
    {
      "x": -12,
      "y": 4,
      "z": 8,
      "name": "Rock_Aqua_Brick_Smooth"
    },
    {
      "x": -12,
      "y": 5,
      "z": 8,
      "name": "Rock_Aqua_Brick_Smooth"
    },
    {
      "x": -12,
      "y": 6,
      "z": 8,
      "name": "Rock_Aqua_Brick_Decorative"
    },
    {
      "x": -12,
      "y": 7,
      "z": 8,
      "name": "Rock_Aqua_Brick_Smooth"
    },
    {
      "x": -12,
      "y": 8,
      "z": 8,
      "name": "Rock_Aqua_Brick_Smooth"
    },
    {
      "x": -12,
      "y": 9,
      "z": 8,
      "name": "Rock_Aqua_Brick_Decorative"
    },
    {
      "x": -12,
      "y": 10,
      "z": 8,
      "name": "Rock_Aqua_Brick_Smooth"
    },
    {
      "x": -12,
      "y": 0,
      "z": 9,
      "name": "Rock_Aqua_Brick_Decorative"
    },
    {
      "x": -12,
      "y": 1,
      "z": 9,
      "name": "Rock_Aqua_Brick_Smooth"
    },
    {
      "x": -12,
      "y": 2,
      "z": 9,
      "name": "Rock_Aqua_Brick_Smooth"
    },
    {
      "x": -12,
      "y": 3,
      "z": 9,
      "name": "Rock_Aqua_Brick_Decorative"
    },
    {
      "x": -12,
      "y": 4,
      "z": 9,
      "name": "Rock_Aqua_Brick_Smooth"
    },
    {
      "x": -12,
      "y": 5,
      "z": 9,
      "name": "Rock_Aqua_Brick_Smooth"
    },
    {
      "x": -12,
      "y": 6,
      "z": 9,
      "name": "Rock_Aqua_Brick_Decorative"
    },
    {
      "x": -12,
      "y": 7,
      "z": 9,
      "name": "Rock_Aqua_Brick_Smooth"
    },
    {
      "x": -12,
      "y": 8,
      "z": 9,
      "name": "Rock_Aqua_Brick_Smooth"
    },
    {
      "x": -11,
      "y": 0,
      "z": -10,
      "name": "Rock_Aqua_Brick_Decorative",
      "rotation": 3
    },
    {
      "x": -11,
      "y": 1,
      "z": -10,
      "name": "Rock_Aqua_Brick_Smooth",
      "rotation": 3
    },
    {
      "x": -11,
      "y": 2,
      "z": -10,
      "name": "Rock_Aqua_Brick_Smooth",
      "rotation": 3
    },
    {
      "x": -11,
      "y": 3,
      "z": -10,
      "name": "Rock_Aqua_Brick_Decorative",
      "rotation": 3
    },
    {
      "x": -11,
      "y": 4,
      "z": -10,
      "name": "Rock_Aqua_Brick_Smooth",
      "rotation": 3
    },
    {
      "x": -11,
      "y": 5,
      "z": -10,
      "name": "Rock_Aqua_Brick_Smooth",
      "rotation": 3
    },
    {
      "x": -11,
      "y": 6,
      "z": -10,
      "name": "Rock_Aqua_Brick_Decorative",
      "rotation": 3
    },
    {
      "x": -11,
      "y": 7,
      "z": -10,
      "name": "Rock_Aqua_Brick_Smooth",
      "rotation": 3
    },
    {
      "x": -11,
      "y": 8,
      "z": -10,
      "name": "Rock_Aqua_Brick_Smooth",
      "rotation": 3
    },
    {
      "x": -11,
      "y": 0,
      "z": -9,
      "name": "Rock_Aqua_Brick_Decorative",
      "rotation": 3
    },
    {
      "x": -11,
      "y": 1,
      "z": -9,
      "name": "Rock_Aqua_Brick_Smooth",
      "rotation": 3
    },
    {
      "x": -11,
      "y": 2,
      "z": -9,
      "name": "Rock_Aqua_Brick_Smooth",
      "rotation": 3
    },
    {
      "x": -11,
      "y": 3,
      "z": -9,
      "name": "Rock_Aqua_Brick_Decorative",
      "rotation": 3
    },
    {
      "x": -11,
      "y": 4,
      "z": -9,
      "name": "Rock_Aqua_Brick_Smooth",
      "rotation": 3
    },
    {
      "x": -11,
      "y": 5,
      "z": -9,
      "name": "Rock_Aqua_Brick_Smooth",
      "rotation": 3
    },
    {
      "x": -11,
      "y": 6,
      "z": -9,
      "name": "Rock_Aqua_Brick_Decorative",
      "rotation": 3
    },
    {
      "x": -11,
      "y": 7,
      "z": -9,
      "name": "Rock_Aqua_Brick_Smooth",
      "rotation": 3
    },
    {
      "x": -11,
      "y": 8,
      "z": -9,
      "name": "Rock_Aqua_Brick_Smooth",
      "rotation": 3
    },
    {
      "x": -11,
      "y": 9,
      "z": -9,
      "name": "Rock_Aqua_Brick_Decorative"
    },
    {
      "x": -11,
      "y": 10,
      "z": -9,
      "name": "Rock_Aqua_Brick_Smooth"
    },
    {
      "x": -11,
      "y": 0,
      "z": -8,
      "name": "Rock_Aqua_Brick_Decorative",
      "rotation": 3
    },
    {
      "x": -11,
      "y": 1,
      "z": -8,
      "name": "Rock_Aqua_Brick_Smooth",
      "rotation": 3
    },
    {
      "x": -11,
      "y": 2,
      "z": -8,
      "name": "Rock_Aqua_Brick_Smooth",
      "rotation": 3
    },
    {
      "x": -11,
      "y": 3,
      "z": -8,
      "name": "Rock_Aqua_Brick_Decorative",
      "rotation": 3
    },
    {
      "x": -11,
      "y": 4,
      "z": -8,
      "name": "Rock_Aqua_Brick_Smooth",
      "rotation": 3
    },
    {
      "x": -11,
      "y": 5,
      "z": -8,
      "name": "Rock_Aqua_Brick_Smooth",
      "rotation": 3
    },
    {
      "x": -11,
      "y": 6,
      "z": -8,
      "name": "Rock_Aqua_Brick_Decorative",
      "rotation": 3
    },
    {
      "x": -11,
      "y": 7,
      "z": -8,
      "name": "Rock_Aqua_Brick_Smooth",
      "rotation": 3
    },
    {
      "x": -11,
      "y": 8,
      "z": -8,
      "name": "Rock_Aqua_Brick_Smooth",
      "rotation": 3
    },
    {
      "x": -11,
      "y": 9,
      "z": -8,
      "name": "Rock_Aqua_Brick_Decorative"
    },
    {
      "x": -11,
      "y": 10,
      "z": -8,
      "name": "Rock_Aqua_Brick_Smooth"
    },
    {
      "x": -11,
      "y": 11,
      "z": -8,
      "name": "Rock_Aqua_Brick_Smooth"
    },
    {
      "x": -11,
      "y": 12,
      "z": -8,
      "name": "Rock_Aqua_Brick_Decorative"
    },
    {
      "x": -11,
      "y": 0,
      "z": -7,
      "name": "Rock_Aqua_Brick_Decorative",
      "rotation": 3
    },
    {
      "x": -11,
      "y": 1,
      "z": -7,
      "name": "Rock_Aqua_Brick_Ornate",
      "rotation": 3
    },
    {
      "x": -11,
      "y": 2,
      "z": -7,
      "name": "Rock_Aqua_Brick_Ornate",
      "rotation": 3
    },
    {
      "x": -11,
      "y": 3,
      "z": -7,
      "name": "Rock_Aqua_Brick_Decorative",
      "rotation": 3
    },
    {
      "x": -11,
      "y": 4,
      "z": -7,
      "name": "Rock_Aqua_Brick_Ornate",
      "rotation": 3
    },
    {
      "x": -11,
      "y": 5,
      "z": -7,
      "name": "Rock_Aqua_Brick_Ornate",
      "rotation": 3
    },
    {
      "x": -11,
      "y": 6,
      "z": -7,
      "name": "Rock_Aqua_Brick_Decorative",
      "rotation": 3
    },
    {
      "x": -11,
      "y": 7,
      "z": -7,
      "name": "Rock_Aqua_Brick_Ornate",
      "rotation": 3
    },
    {
      "x": -11,
      "y": 8,
      "z": -7,
      "name": "Rock_Aqua_Brick_Ornate",
      "rotation": 3
    },
    {
      "x": -11,
      "y": 9,
      "z": -7,
      "name": "Rock_Aqua_Brick_Decorative"
    },
    {
      "x": -11,
      "y": 10,
      "z": -7,
      "name": "Rock_Aqua_Brick_Ornate"
    },
    {
      "x": -11,
      "y": 11,
      "z": -7,
      "name": "Rock_Aqua_Brick_Ornate"
    },
    {
      "x": -11,
      "y": 12,
      "z": -7,
      "name": "Rock_Aqua_Brick_Decorative"
    },
    {
      "x": -11,
      "y": 0,
      "z": -6,
      "name": "Rock_Aqua_Brick_Decorative"
    },
    {
      "x": -11,
      "y": 1,
      "z": -6,
      "name": "Rock_Aqua_Brick_Ornate"
    },
    {
      "x": -11,
      "y": 2,
      "z": -6,
      "name": "Rock_Aqua_Brick_Ornate"
    },
    {
      "x": -11,
      "y": 3,
      "z": -6,
      "name": "Rock_Aqua_Brick_Decorative"
    },
    {
      "x": -11,
      "y": 4,
      "z": -6,
      "name": "Rock_Aqua_Brick_Ornate"
    },
    {
      "x": -11,
      "y": 5,
      "z": -6,
      "name": "Rock_Aqua_Brick_Ornate"
    },
    {
      "x": -11,
      "y": 6,
      "z": -6,
      "name": "Rock_Aqua_Brick_Decorative"
    },
    {
      "x": -11,
      "y": 7,
      "z": -6,
      "name": "Rock_Aqua_Brick_Ornate"
    },
    {
      "x": -11,
      "y": 8,
      "z": -6,
      "name": "Rock_Aqua_Brick_Ornate"
    },
    {
      "x": -11,
      "y": 9,
      "z": -6,
      "name": "Rock_Aqua_Brick_Decorative"
    },
    {
      "x": -11,
      "y": 10,
      "z": -6,
      "name": "Rock_Aqua_Brick_Ornate"
    },
    {
      "x": -11,
      "y": 11,
      "z": -6,
      "name": "Rock_Aqua_Brick_Ornate"
    },
    {
      "x": -11,
      "y": 12,
      "z": -6,
      "name": "Rock_Aqua_Brick_Decorative"
    },
    {
      "x": -11,
      "y": 13,
      "z": -6,
      "name": "Rock_Aqua_Brick_Ornate"
    },
    {
      "x": -11,
      "y": 14,
      "z": -6,
      "name": "Rock_Aqua_Brick_Ornate"
    },
    {
      "x": -11,
      "y": 0,
      "z": -5,
      "name": "Rock_Aqua_Brick_Decorative"
    },
    {
      "x": -11,
      "y": 1,
      "z": -5,
      "name": "Rock_Aqua_Brick_Smooth"
    },
    {
      "x": -11,
      "y": 2,
      "z": -5,
      "name": "Rock_Aqua_Brick_Smooth"
    },
    {
      "x": -11,
      "y": 3,
      "z": -5,
      "name": "Rock_Aqua_Brick_Decorative"
    },
    {
      "x": -11,
      "y": 4,
      "z": -5,
      "name": "Rock_Aqua_Brick_Smooth"
    },
    {
      "x": -11,
      "y": 5,
      "z": -5,
      "name": "Rock_Aqua_Brick_Smooth"
    },
    {
      "x": -11,
      "y": 6,
      "z": -5,
      "name": "Rock_Aqua_Brick_Decorative"
    },
    {
      "x": -11,
      "y": 7,
      "z": -5,
      "name": "Rock_Aqua_Brick_Smooth"
    },
    {
      "x": -11,
      "y": 8,
      "z": -5,
      "name": "Rock_Aqua_Brick_Smooth"
    },
    {
      "x": -11,
      "y": 9,
      "z": -5,
      "name": "Rock_Aqua_Brick_Decorative"
    },
    {
      "x": -11,
      "y": 10,
      "z": -5,
      "name": "Rock_Aqua_Brick_Smooth"
    },
    {
      "x": -11,
      "y": 11,
      "z": -5,
      "name": "Rock_Aqua_Brick_Smooth"
    },
    {
      "x": -11,
      "y": 12,
      "z": -5,
      "name": "Rock_Aqua_Brick_Decorative"
    },
    {
      "x": -11,
      "y": 13,
      "z": -5,
      "name": "Rock_Aqua_Brick_Smooth"
    },
    {
      "x": -11,
      "y": 14,
      "z": -5,
      "name": "Rock_Aqua_Brick_Smooth"
    },
    {
      "x": -11,
      "y": 0,
      "z": -4,
      "name": "Rock_Aqua_Brick_Decorative"
    },
    {
      "x": -11,
      "y": 1,
      "z": -4,
      "name": "Rock_Aqua_Brick_Ornate"
    },
    {
      "x": -11,
      "y": 2,
      "z": -4,
      "name": "Rock_Aqua_Brick_Ornate"
    },
    {
      "x": -11,
      "y": 3,
      "z": -4,
      "name": "Rock_Aqua_Brick_Decorative"
    },
    {
      "x": -11,
      "y": 4,
      "z": -4,
      "name": "Rock_Aqua_Brick_Ornate"
    },
    {
      "x": -11,
      "y": 5,
      "z": -4,
      "name": "Rock_Aqua_Brick_Ornate"
    },
    {
      "x": -11,
      "y": 6,
      "z": -4,
      "name": "Rock_Aqua_Brick_Decorative"
    },
    {
      "x": -11,
      "y": 7,
      "z": -4,
      "name": "Rock_Aqua_Brick_Ornate"
    },
    {
      "x": -11,
      "y": 8,
      "z": -4,
      "name": "Rock_Aqua_Brick_Ornate"
    },
    {
      "x": -11,
      "y": 9,
      "z": -4,
      "name": "Rock_Aqua_Brick_Decorative"
    },
    {
      "x": -11,
      "y": 10,
      "z": -4,
      "name": "Rock_Aqua_Brick_Ornate"
    },
    {
      "x": -11,
      "y": 11,
      "z": -4,
      "name": "Rock_Aqua_Brick_Ornate"
    },
    {
      "x": -11,
      "y": 12,
      "z": -4,
      "name": "Rock_Aqua_Brick_Decorative"
    },
    {
      "x": -11,
      "y": 13,
      "z": -4,
      "name": "Rock_Aqua_Brick_Ornate"
    },
    {
      "x": -11,
      "y": 14,
      "z": -4,
      "name": "Rock_Aqua_Brick_Ornate"
    },
    {
      "x": -11,
      "y": 0,
      "z": -3,
      "name": "Rock_Aqua_Brick_Decorative"
    },
    {
      "x": -11,
      "y": 1,
      "z": -3,
      "name": "Rock_Aqua_Brick_Smooth"
    },
    {
      "x": -11,
      "y": 2,
      "z": -3,
      "name": "Rock_Aqua_Brick_Smooth"
    },
    {
      "x": -11,
      "y": 3,
      "z": -3,
      "name": "Rock_Aqua_Brick_Decorative"
    },
    {
      "x": -11,
      "y": 4,
      "z": -3,
      "name": "Rock_Aqua_Brick_Smooth"
    },
    {
      "x": -11,
      "y": 5,
      "z": -3,
      "name": "Rock_Aqua_Brick_Smooth"
    },
    {
      "x": -11,
      "y": 6,
      "z": -3,
      "name": "Rock_Aqua_Brick_Decorative"
    },
    {
      "x": -11,
      "y": 7,
      "z": -3,
      "name": "Rock_Aqua_Brick_Smooth"
    },
    {
      "x": -11,
      "y": 8,
      "z": -3,
      "name": "Rock_Aqua_Brick_Smooth"
    },
    {
      "x": -11,
      "y": 9,
      "z": -3,
      "name": "Rock_Aqua_Brick_Decorative"
    },
    {
      "x": -11,
      "y": 10,
      "z": -3,
      "name": "Rock_Aqua_Brick_Smooth"
    },
    {
      "x": -11,
      "y": 11,
      "z": -3,
      "name": "Rock_Aqua_Brick_Smooth"
    },
    {
      "x": -11,
      "y": 12,
      "z": -3,
      "name": "Rock_Aqua_Brick_Decorative"
    },
    {
      "x": -11,
      "y": 13,
      "z": -3,
      "name": "Rock_Aqua_Brick_Smooth"
    },
    {
      "x": -11,
      "y": 14,
      "z": -3,
      "name": "Rock_Aqua_Brick_Smooth"
    },
    {
      "x": -11,
      "y": 0,
      "z": -2,
      "name": "Rock_Aqua_Brick_Decorative"
    },
    {
      "x": -11,
      "y": 1,
      "z": -2,
      "name": "Rock_Aqua_Brick_Ornate"
    },
    {
      "x": -11,
      "y": 2,
      "z": -2,
      "name": "Rock_Aqua_Brick_Ornate"
    },
    {
      "x": -11,
      "y": 3,
      "z": -2,
      "name": "Rock_Aqua_Brick_Decorative"
    },
    {
      "x": -11,
      "y": 4,
      "z": -2,
      "name": "Rock_Aqua_Brick_Ornate"
    },
    {
      "x": -11,
      "y": 5,
      "z": -2,
      "name": "Rock_Aqua_Brick_Ornate"
    },
    {
      "x": -11,
      "y": 6,
      "z": -2,
      "name": "Rock_Aqua_Brick_Decorative"
    },
    {
      "x": -11,
      "y": 7,
      "z": -2,
      "name": "Rock_Aqua_Brick_Ornate"
    },
    {
      "x": -11,
      "y": 8,
      "z": -2,
      "name": "Rock_Aqua_Brick_Ornate"
    },
    {
      "x": -11,
      "y": 9,
      "z": -2,
      "name": "Rock_Aqua_Brick_Decorative"
    },
    {
      "x": -11,
      "y": 10,
      "z": -2,
      "name": "Rock_Aqua_Brick_Ornate"
    },
    {
      "x": -11,
      "y": 11,
      "z": -2,
      "name": "Rock_Aqua_Brick_Ornate"
    },
    {
      "x": -11,
      "y": 12,
      "z": -2,
      "name": "Rock_Aqua_Brick_Decorative"
    },
    {
      "x": -11,
      "y": 13,
      "z": -2,
      "name": "Rock_Aqua_Brick_Ornate"
    },
    {
      "x": -11,
      "y": 14,
      "z": -2,
      "name": "Rock_Aqua_Brick_Ornate"
    },
    {
      "x": -11,
      "y": 0,
      "z": -1,
      "name": "Rock_Aqua_Brick_Decorative"
    },
    {
      "x": -11,
      "y": 1,
      "z": -1,
      "name": "Rock_Aqua_Brick_Smooth"
    },
    {
      "x": -11,
      "y": 2,
      "z": -1,
      "name": "Rock_Aqua_Brick_Smooth"
    },
    {
      "x": -11,
      "y": 3,
      "z": -1,
      "name": "Rock_Aqua_Brick_Decorative"
    },
    {
      "x": -11,
      "y": 4,
      "z": -1,
      "name": "Rock_Aqua_Brick_Smooth"
    },
    {
      "x": -11,
      "y": 5,
      "z": -1,
      "name": "Rock_Aqua_Brick_Smooth"
    },
    {
      "x": -11,
      "y": 6,
      "z": -1,
      "name": "Rock_Aqua_Brick_Decorative"
    },
    {
      "x": -11,
      "y": 7,
      "z": -1,
      "name": "Rock_Aqua_Brick_Smooth"
    },
    {
      "x": -11,
      "y": 8,
      "z": -1,
      "name": "Rock_Aqua_Brick_Smooth"
    },
    {
      "x": -11,
      "y": 9,
      "z": -1,
      "name": "Rock_Aqua_Brick_Decorative"
    },
    {
      "x": -11,
      "y": 10,
      "z": -1,
      "name": "Rock_Aqua_Brick_Smooth"
    },
    {
      "x": -11,
      "y": 11,
      "z": -1,
      "name": "Rock_Aqua_Brick_Smooth"
    },
    {
      "x": -11,
      "y": 12,
      "z": -1,
      "name": "Rock_Aqua_Brick_Decorative"
    },
    {
      "x": -11,
      "y": 13,
      "z": -1,
      "name": "Rock_Aqua_Brick_Smooth"
    },
    {
      "x": -11,
      "y": 14,
      "z": -1,
      "name": "Rock_Aqua_Brick_Smooth"
    },
    {
      "x": -11,
      "y": 0,
      "z": 0,
      "name": "Rock_Aqua_Brick_Decorative"
    },
    {
      "x": -11,
      "y": 1,
      "z": 0,
      "name": "Rock_Aqua_Brick_Ornate"
    },
    {
      "x": -11,
      "y": 2,
      "z": 0,
      "name": "Rock_Aqua_Brick_Ornate"
    },
    {
      "x": -11,
      "y": 3,
      "z": 0,
      "name": "Rock_Aqua_Brick_Decorative"
    },
    {
      "x": -11,
      "y": 4,
      "z": 0,
      "name": "Rock_Aqua_Brick_Ornate"
    },
    {
      "x": -11,
      "y": 5,
      "z": 0,
      "name": "Rock_Aqua_Brick_Ornate"
    },
    {
      "x": -11,
      "y": 6,
      "z": 0,
      "name": "Rock_Aqua_Brick_Decorative"
    },
    {
      "x": -11,
      "y": 7,
      "z": 0,
      "name": "Rock_Aqua_Brick_Ornate"
    },
    {
      "x": -11,
      "y": 8,
      "z": 0,
      "name": "Rock_Aqua_Brick_Ornate"
    },
    {
      "x": -11,
      "y": 9,
      "z": 0,
      "name": "Rock_Aqua_Brick_Decorative"
    },
    {
      "x": -11,
      "y": 10,
      "z": 0,
      "name": "Rock_Aqua_Brick_Ornate"
    },
    {
      "x": -11,
      "y": 11,
      "z": 0,
      "name": "Rock_Aqua_Brick_Ornate"
    },
    {
      "x": -11,
      "y": 12,
      "z": 0,
      "name": "Rock_Aqua_Brick_Decorative"
    },
    {
      "x": -11,
      "y": 13,
      "z": 0,
      "name": "Rock_Aqua_Brick_Ornate"
    },
    {
      "x": -11,
      "y": 14,
      "z": 0,
      "name": "Rock_Aqua_Brick_Ornate"
    },
    {
      "x": -11,
      "y": 0,
      "z": 1,
      "name": "Rock_Aqua_Brick_Decorative"
    },
    {
      "x": -11,
      "y": 1,
      "z": 1,
      "name": "Rock_Aqua_Brick_Smooth"
    },
    {
      "x": -11,
      "y": 2,
      "z": 1,
      "name": "Rock_Aqua_Brick_Smooth"
    },
    {
      "x": -11,
      "y": 3,
      "z": 1,
      "name": "Rock_Aqua_Brick_Decorative"
    },
    {
      "x": -11,
      "y": 4,
      "z": 1,
      "name": "Rock_Aqua_Brick_Smooth"
    },
    {
      "x": -11,
      "y": 5,
      "z": 1,
      "name": "Rock_Aqua_Brick_Smooth"
    },
    {
      "x": -11,
      "y": 6,
      "z": 1,
      "name": "Rock_Aqua_Brick_Decorative"
    },
    {
      "x": -11,
      "y": 7,
      "z": 1,
      "name": "Rock_Aqua_Brick_Smooth"
    },
    {
      "x": -11,
      "y": 8,
      "z": 1,
      "name": "Rock_Aqua_Brick_Smooth"
    },
    {
      "x": -11,
      "y": 9,
      "z": 1,
      "name": "Rock_Aqua_Brick_Decorative"
    },
    {
      "x": -11,
      "y": 10,
      "z": 1,
      "name": "Rock_Aqua_Brick_Smooth"
    },
    {
      "x": -11,
      "y": 11,
      "z": 1,
      "name": "Rock_Aqua_Brick_Smooth"
    },
    {
      "x": -11,
      "y": 12,
      "z": 1,
      "name": "Rock_Aqua_Brick_Decorative"
    },
    {
      "x": -11,
      "y": 13,
      "z": 1,
      "name": "Rock_Aqua_Brick_Smooth"
    },
    {
      "x": -11,
      "y": 14,
      "z": 1,
      "name": "Rock_Aqua_Brick_Smooth"
    },
    {
      "x": -11,
      "y": 0,
      "z": 2,
      "name": "Rock_Aqua_Brick_Decorative"
    },
    {
      "x": -11,
      "y": 1,
      "z": 2,
      "name": "Rock_Aqua_Brick_Ornate"
    },
    {
      "x": -11,
      "y": 2,
      "z": 2,
      "name": "Rock_Aqua_Brick_Ornate"
    },
    {
      "x": -11,
      "y": 3,
      "z": 2,
      "name": "Rock_Aqua_Brick_Decorative"
    },
    {
      "x": -11,
      "y": 4,
      "z": 2,
      "name": "Rock_Aqua_Brick_Ornate"
    },
    {
      "x": -11,
      "y": 5,
      "z": 2,
      "name": "Rock_Aqua_Brick_Ornate"
    },
    {
      "x": -11,
      "y": 6,
      "z": 2,
      "name": "Rock_Aqua_Brick_Decorative"
    },
    {
      "x": -11,
      "y": 7,
      "z": 2,
      "name": "Rock_Aqua_Brick_Ornate"
    },
    {
      "x": -11,
      "y": 8,
      "z": 2,
      "name": "Rock_Aqua_Brick_Ornate"
    },
    {
      "x": -11,
      "y": 9,
      "z": 2,
      "name": "Rock_Aqua_Brick_Decorative"
    },
    {
      "x": -11,
      "y": 10,
      "z": 2,
      "name": "Rock_Aqua_Brick_Ornate"
    },
    {
      "x": -11,
      "y": 11,
      "z": 2,
      "name": "Rock_Aqua_Brick_Ornate"
    },
    {
      "x": -11,
      "y": 12,
      "z": 2,
      "name": "Rock_Aqua_Brick_Decorative"
    },
    {
      "x": -11,
      "y": 13,
      "z": 2,
      "name": "Rock_Aqua_Brick_Ornate"
    },
    {
      "x": -11,
      "y": 14,
      "z": 2,
      "name": "Rock_Aqua_Brick_Ornate"
    },
    {
      "x": -11,
      "y": 0,
      "z": 3,
      "name": "Rock_Aqua_Brick_Decorative"
    },
    {
      "x": -11,
      "y": 1,
      "z": 3,
      "name": "Rock_Aqua_Brick_Smooth"
    },
    {
      "x": -11,
      "y": 2,
      "z": 3,
      "name": "Rock_Aqua_Brick_Smooth"
    },
    {
      "x": -11,
      "y": 3,
      "z": 3,
      "name": "Rock_Aqua_Brick_Decorative"
    },
    {
      "x": -11,
      "y": 4,
      "z": 3,
      "name": "Rock_Aqua_Brick_Smooth"
    },
    {
      "x": -11,
      "y": 5,
      "z": 3,
      "name": "Rock_Aqua_Brick_Smooth"
    },
    {
      "x": -11,
      "y": 6,
      "z": 3,
      "name": "Rock_Aqua_Brick_Decorative"
    },
    {
      "x": -11,
      "y": 7,
      "z": 3,
      "name": "Rock_Aqua_Brick_Smooth"
    },
    {
      "x": -11,
      "y": 8,
      "z": 3,
      "name": "Rock_Aqua_Brick_Smooth"
    },
    {
      "x": -11,
      "y": 9,
      "z": 3,
      "name": "Rock_Aqua_Brick_Decorative"
    },
    {
      "x": -11,
      "y": 10,
      "z": 3,
      "name": "Rock_Aqua_Brick_Smooth"
    },
    {
      "x": -11,
      "y": 11,
      "z": 3,
      "name": "Rock_Aqua_Brick_Smooth"
    },
    {
      "x": -11,
      "y": 12,
      "z": 3,
      "name": "Rock_Aqua_Brick_Decorative"
    },
    {
      "x": -11,
      "y": 13,
      "z": 3,
      "name": "Rock_Aqua_Brick_Smooth"
    },
    {
      "x": -11,
      "y": 14,
      "z": 3,
      "name": "Rock_Aqua_Brick_Smooth"
    },
    {
      "x": -11,
      "y": 0,
      "z": 4,
      "name": "Rock_Aqua_Brick_Decorative"
    },
    {
      "x": -11,
      "y": 1,
      "z": 4,
      "name": "Rock_Aqua_Brick_Ornate"
    },
    {
      "x": -11,
      "y": 2,
      "z": 4,
      "name": "Rock_Aqua_Brick_Ornate"
    },
    {
      "x": -11,
      "y": 3,
      "z": 4,
      "name": "Rock_Aqua_Brick_Decorative"
    },
    {
      "x": -11,
      "y": 4,
      "z": 4,
      "name": "Rock_Aqua_Brick_Ornate"
    },
    {
      "x": -11,
      "y": 5,
      "z": 4,
      "name": "Rock_Aqua_Brick_Ornate"
    },
    {
      "x": -11,
      "y": 6,
      "z": 4,
      "name": "Rock_Aqua_Brick_Decorative"
    },
    {
      "x": -11,
      "y": 7,
      "z": 4,
      "name": "Rock_Aqua_Brick_Ornate"
    },
    {
      "x": -11,
      "y": 8,
      "z": 4,
      "name": "Rock_Aqua_Brick_Ornate"
    },
    {
      "x": -11,
      "y": 9,
      "z": 4,
      "name": "Rock_Aqua_Brick_Decorative"
    },
    {
      "x": -11,
      "y": 10,
      "z": 4,
      "name": "Rock_Aqua_Brick_Ornate"
    },
    {
      "x": -11,
      "y": 11,
      "z": 4,
      "name": "Rock_Aqua_Brick_Ornate"
    },
    {
      "x": -11,
      "y": 12,
      "z": 4,
      "name": "Rock_Aqua_Brick_Decorative"
    },
    {
      "x": -11,
      "y": 13,
      "z": 4,
      "name": "Rock_Aqua_Brick_Ornate"
    },
    {
      "x": -11,
      "y": 14,
      "z": 4,
      "name": "Rock_Aqua_Brick_Ornate"
    },
    {
      "x": -11,
      "y": 0,
      "z": 5,
      "name": "Rock_Aqua_Brick_Decorative"
    },
    {
      "x": -11,
      "y": 1,
      "z": 5,
      "name": "Rock_Aqua_Brick_Smooth"
    },
    {
      "x": -11,
      "y": 2,
      "z": 5,
      "name": "Rock_Aqua_Brick_Smooth"
    },
    {
      "x": -11,
      "y": 3,
      "z": 5,
      "name": "Rock_Aqua_Brick_Decorative"
    },
    {
      "x": -11,
      "y": 4,
      "z": 5,
      "name": "Rock_Aqua_Brick_Smooth"
    },
    {
      "x": -11,
      "y": 5,
      "z": 5,
      "name": "Rock_Aqua_Brick_Smooth"
    },
    {
      "x": -11,
      "y": 6,
      "z": 5,
      "name": "Rock_Aqua_Brick_Decorative"
    },
    {
      "x": -11,
      "y": 7,
      "z": 5,
      "name": "Rock_Aqua_Brick_Smooth"
    },
    {
      "x": -11,
      "y": 8,
      "z": 5,
      "name": "Rock_Aqua_Brick_Smooth"
    },
    {
      "x": -11,
      "y": 9,
      "z": 5,
      "name": "Rock_Aqua_Brick_Decorative"
    },
    {
      "x": -11,
      "y": 10,
      "z": 5,
      "name": "Rock_Aqua_Brick_Smooth"
    },
    {
      "x": -11,
      "y": 11,
      "z": 5,
      "name": "Rock_Aqua_Brick_Smooth"
    },
    {
      "x": -11,
      "y": 12,
      "z": 5,
      "name": "Rock_Aqua_Brick_Decorative"
    },
    {
      "x": -11,
      "y": 13,
      "z": 5,
      "name": "Rock_Aqua_Brick_Smooth"
    },
    {
      "x": -11,
      "y": 14,
      "z": 5,
      "name": "Rock_Aqua_Brick_Smooth"
    },
    {
      "x": -11,
      "y": 0,
      "z": 6,
      "name": "Rock_Aqua_Brick_Decorative"
    },
    {
      "x": -11,
      "y": 1,
      "z": 6,
      "name": "Rock_Aqua_Brick_Ornate"
    },
    {
      "x": -11,
      "y": 2,
      "z": 6,
      "name": "Rock_Aqua_Brick_Ornate"
    },
    {
      "x": -11,
      "y": 3,
      "z": 6,
      "name": "Rock_Aqua_Brick_Decorative"
    },
    {
      "x": -11,
      "y": 4,
      "z": 6,
      "name": "Rock_Aqua_Brick_Ornate"
    },
    {
      "x": -11,
      "y": 5,
      "z": 6,
      "name": "Rock_Aqua_Brick_Ornate"
    },
    {
      "x": -11,
      "y": 6,
      "z": 6,
      "name": "Rock_Aqua_Brick_Decorative"
    },
    {
      "x": -11,
      "y": 7,
      "z": 6,
      "name": "Rock_Aqua_Brick_Ornate"
    },
    {
      "x": -11,
      "y": 8,
      "z": 6,
      "name": "Rock_Aqua_Brick_Ornate"
    },
    {
      "x": -11,
      "y": 9,
      "z": 6,
      "name": "Rock_Aqua_Brick_Decorative"
    },
    {
      "x": -11,
      "y": 10,
      "z": 6,
      "name": "Rock_Aqua_Brick_Ornate"
    },
    {
      "x": -11,
      "y": 11,
      "z": 6,
      "name": "Rock_Aqua_Brick_Ornate"
    },
    {
      "x": -11,
      "y": 12,
      "z": 6,
      "name": "Rock_Aqua_Brick_Decorative"
    },
    {
      "x": -11,
      "y": 13,
      "z": 6,
      "name": "Rock_Aqua_Brick_Ornate"
    },
    {
      "x": -11,
      "y": 14,
      "z": 6,
      "name": "Rock_Aqua_Brick_Ornate"
    },
    {
      "x": -11,
      "y": 0,
      "z": 7,
      "name": "Rock_Aqua_Brick_Decorative"
    },
    {
      "x": -11,
      "y": 1,
      "z": 7,
      "name": "Rock_Aqua_Brick_Ornate"
    },
    {
      "x": -11,
      "y": 2,
      "z": 7,
      "name": "Rock_Aqua_Brick_Ornate"
    },
    {
      "x": -11,
      "y": 3,
      "z": 7,
      "name": "Rock_Aqua_Brick_Decorative"
    },
    {
      "x": -11,
      "y": 4,
      "z": 7,
      "name": "Rock_Aqua_Brick_Ornate"
    },
    {
      "x": -11,
      "y": 5,
      "z": 7,
      "name": "Rock_Aqua_Brick_Ornate"
    },
    {
      "x": -11,
      "y": 6,
      "z": 7,
      "name": "Rock_Aqua_Brick_Decorative"
    },
    {
      "x": -11,
      "y": 7,
      "z": 7,
      "name": "Rock_Aqua_Brick_Ornate"
    },
    {
      "x": -11,
      "y": 8,
      "z": 7,
      "name": "Rock_Aqua_Brick_Ornate"
    },
    {
      "x": -11,
      "y": 9,
      "z": 7,
      "name": "Rock_Aqua_Brick_Decorative"
    },
    {
      "x": -11,
      "y": 10,
      "z": 7,
      "name": "Rock_Aqua_Brick_Ornate"
    },
    {
      "x": -11,
      "y": 11,
      "z": 7,
      "name": "Rock_Aqua_Brick_Ornate"
    },
    {
      "x": -11,
      "y": 12,
      "z": 7,
      "name": "Rock_Aqua_Brick_Decorative"
    },
    {
      "x": -11,
      "y": 0,
      "z": 8,
      "name": "Rock_Aqua_Brick_Decorative"
    },
    {
      "x": -11,
      "y": 1,
      "z": 8,
      "name": "Rock_Aqua_Brick_Smooth"
    },
    {
      "x": -11,
      "y": 2,
      "z": 8,
      "name": "Rock_Aqua_Brick_Smooth"
    },
    {
      "x": -11,
      "y": 3,
      "z": 8,
      "name": "Rock_Aqua_Brick_Decorative"
    },
    {
      "x": -11,
      "y": 4,
      "z": 8,
      "name": "Rock_Aqua_Brick_Smooth"
    },
    {
      "x": -11,
      "y": 5,
      "z": 8,
      "name": "Rock_Aqua_Brick_Smooth"
    },
    {
      "x": -11,
      "y": 6,
      "z": 8,
      "name": "Rock_Aqua_Brick_Decorative"
    },
    {
      "x": -11,
      "y": 7,
      "z": 8,
      "name": "Rock_Aqua_Brick_Smooth"
    },
    {
      "x": -11,
      "y": 8,
      "z": 8,
      "name": "Rock_Aqua_Brick_Smooth"
    },
    {
      "x": -11,
      "y": 9,
      "z": 8,
      "name": "Rock_Aqua_Brick_Decorative"
    },
    {
      "x": -11,
      "y": 10,
      "z": 8,
      "name": "Rock_Aqua_Brick_Smooth"
    },
    {
      "x": -11,
      "y": 11,
      "z": 8,
      "name": "Rock_Aqua_Brick_Smooth"
    },
    {
      "x": -11,
      "y": 12,
      "z": 8,
      "name": "Rock_Aqua_Brick_Decorative"
    },
    {
      "x": -11,
      "y": 0,
      "z": 9,
      "name": "Rock_Aqua_Brick_Decorative"
    },
    {
      "x": -11,
      "y": 1,
      "z": 9,
      "name": "Rock_Aqua_Brick_Smooth"
    },
    {
      "x": -11,
      "y": 2,
      "z": 9,
      "name": "Rock_Aqua_Brick_Smooth"
    },
    {
      "x": -11,
      "y": 3,
      "z": 9,
      "name": "Rock_Aqua_Brick_Decorative"
    },
    {
      "x": -11,
      "y": 4,
      "z": 9,
      "name": "Rock_Aqua_Brick_Smooth"
    },
    {
      "x": -11,
      "y": 5,
      "z": 9,
      "name": "Rock_Aqua_Brick_Smooth"
    },
    {
      "x": -11,
      "y": 6,
      "z": 9,
      "name": "Rock_Aqua_Brick_Decorative"
    },
    {
      "x": -11,
      "y": 7,
      "z": 9,
      "name": "Rock_Aqua_Brick_Smooth"
    },
    {
      "x": -11,
      "y": 8,
      "z": 9,
      "name": "Rock_Aqua_Brick_Smooth"
    },
    {
      "x": -11,
      "y": 9,
      "z": 9,
      "name": "Rock_Aqua_Brick_Decorative"
    },
    {
      "x": -11,
      "y": 10,
      "z": 9,
      "name": "Rock_Aqua_Brick_Smooth"
    },
    {
      "x": -11,
      "y": 0,
      "z": 10,
      "name": "Rock_Aqua_Brick_Decorative"
    },
    {
      "x": -11,
      "y": 1,
      "z": 10,
      "name": "Rock_Aqua_Brick_Smooth"
    },
    {
      "x": -11,
      "y": 2,
      "z": 10,
      "name": "Rock_Aqua_Brick_Smooth"
    },
    {
      "x": -11,
      "y": 3,
      "z": 10,
      "name": "Rock_Aqua_Brick_Decorative"
    },
    {
      "x": -11,
      "y": 4,
      "z": 10,
      "name": "Rock_Aqua_Brick_Smooth"
    },
    {
      "x": -11,
      "y": 5,
      "z": 10,
      "name": "Rock_Aqua_Brick_Smooth"
    },
    {
      "x": -11,
      "y": 6,
      "z": 10,
      "name": "Rock_Aqua_Brick_Decorative"
    },
    {
      "x": -11,
      "y": 7,
      "z": 10,
      "name": "Rock_Aqua_Brick_Smooth"
    },
    {
      "x": -11,
      "y": 8,
      "z": 10,
      "name": "Rock_Aqua_Brick_Smooth"
    },
    {
      "x": -10,
      "y": 0,
      "z": -11,
      "name": "Rock_Aqua_Brick_Decorative",
      "rotation": 3
    },
    {
      "x": -10,
      "y": 1,
      "z": -11,
      "name": "Rock_Aqua_Brick_Smooth",
      "rotation": 3
    },
    {
      "x": -10,
      "y": 2,
      "z": -11,
      "name": "Rock_Aqua_Brick_Smooth",
      "rotation": 3
    },
    {
      "x": -10,
      "y": 3,
      "z": -11,
      "name": "Rock_Aqua_Brick_Decorative",
      "rotation": 3
    },
    {
      "x": -10,
      "y": 4,
      "z": -11,
      "name": "Rock_Aqua_Brick_Smooth",
      "rotation": 3
    },
    {
      "x": -10,
      "y": 5,
      "z": -11,
      "name": "Rock_Aqua_Brick_Smooth",
      "rotation": 3
    },
    {
      "x": -10,
      "y": 6,
      "z": -11,
      "name": "Rock_Aqua_Brick_Decorative",
      "rotation": 3
    },
    {
      "x": -10,
      "y": 7,
      "z": -11,
      "name": "Rock_Aqua_Brick_Smooth",
      "rotation": 3
    },
    {
      "x": -10,
      "y": 8,
      "z": -11,
      "name": "Rock_Aqua_Brick_Smooth",
      "rotation": 3
    },
    {
      "x": -10,
      "y": 0,
      "z": -10,
      "name": "Rock_Aqua_Brick_Decorative",
      "rotation": 3
    },
    {
      "x": -10,
      "y": 1,
      "z": -10,
      "name": "Rock_Aqua_Brick_Smooth",
      "rotation": 3
    },
    {
      "x": -10,
      "y": 2,
      "z": -10,
      "name": "Rock_Aqua_Brick_Smooth",
      "rotation": 3
    },
    {
      "x": -10,
      "y": 3,
      "z": -10,
      "name": "Rock_Aqua_Brick_Decorative",
      "rotation": 3
    },
    {
      "x": -10,
      "y": 4,
      "z": -10,
      "name": "Rock_Aqua_Brick_Smooth",
      "rotation": 3
    },
    {
      "x": -10,
      "y": 5,
      "z": -10,
      "name": "Rock_Aqua_Brick_Smooth",
      "rotation": 3
    },
    {
      "x": -10,
      "y": 6,
      "z": -10,
      "name": "Rock_Aqua_Brick_Decorative",
      "rotation": 3
    },
    {
      "x": -10,
      "y": 7,
      "z": -10,
      "name": "Rock_Aqua_Brick_Smooth",
      "rotation": 3
    },
    {
      "x": -10,
      "y": 8,
      "z": -10,
      "name": "Rock_Aqua_Brick_Smooth",
      "rotation": 3
    },
    {
      "x": -10,
      "y": 9,
      "z": -10,
      "name": "Rock_Aqua_Brick_Decorative"
    },
    {
      "x": -10,
      "y": 10,
      "z": -10,
      "name": "Rock_Aqua_Brick_Smooth"
    },
    {
      "x": -10,
      "y": 0,
      "z": -9,
      "name": "Rock_Aqua_Brick_Decorative",
      "rotation": 3
    },
    {
      "x": -10,
      "y": 1,
      "z": -9,
      "name": "Rock_Aqua_Brick_Smooth",
      "rotation": 3
    },
    {
      "x": -10,
      "y": 2,
      "z": -9,
      "name": "Rock_Aqua_Brick_Smooth",
      "rotation": 3
    },
    {
      "x": -10,
      "y": 3,
      "z": -9,
      "name": "Rock_Aqua_Brick_Decorative",
      "rotation": 3
    },
    {
      "x": -10,
      "y": 4,
      "z": -9,
      "name": "Rock_Aqua_Brick_Smooth",
      "rotation": 3
    },
    {
      "x": -10,
      "y": 5,
      "z": -9,
      "name": "Rock_Aqua_Brick_Smooth",
      "rotation": 3
    },
    {
      "x": -10,
      "y": 6,
      "z": -9,
      "name": "Rock_Aqua_Brick_Decorative",
      "rotation": 3
    },
    {
      "x": -10,
      "y": 7,
      "z": -9,
      "name": "Rock_Aqua_Brick_Smooth",
      "rotation": 3
    },
    {
      "x": -10,
      "y": 8,
      "z": -9,
      "name": "Rock_Aqua_Brick_Smooth",
      "rotation": 3
    },
    {
      "x": -10,
      "y": 9,
      "z": -9,
      "name": "Rock_Aqua_Brick_Decorative"
    },
    {
      "x": -10,
      "y": 10,
      "z": -9,
      "name": "Rock_Aqua_Brick_Smooth"
    },
    {
      "x": -10,
      "y": 11,
      "z": -9,
      "name": "Rock_Aqua_Brick_Smooth"
    },
    {
      "x": -10,
      "y": 12,
      "z": -9,
      "name": "Rock_Aqua_Brick_Decorative"
    },
    {
      "x": -10,
      "y": 0,
      "z": -8,
      "name": "Rock_Aqua_Brick_Decorative",
      "rotation": 3
    },
    {
      "x": -10,
      "y": 1,
      "z": -8,
      "name": "Rock_Aqua_Brick_Smooth",
      "rotation": 3
    },
    {
      "x": -10,
      "y": 2,
      "z": -8,
      "name": "Rock_Aqua_Brick_Smooth",
      "rotation": 3
    },
    {
      "x": -10,
      "y": 3,
      "z": -8,
      "name": "Rock_Aqua_Brick_Decorative",
      "rotation": 3
    },
    {
      "x": -10,
      "y": 4,
      "z": -8,
      "name": "Rock_Aqua_Brick_Smooth",
      "rotation": 3
    },
    {
      "x": -10,
      "y": 5,
      "z": -8,
      "name": "Rock_Aqua_Brick_Smooth",
      "rotation": 3
    },
    {
      "x": -10,
      "y": 6,
      "z": -8,
      "name": "Rock_Aqua_Brick_Decorative",
      "rotation": 3
    },
    {
      "x": -10,
      "y": 7,
      "z": -8,
      "name": "Rock_Aqua_Brick_Smooth",
      "rotation": 3
    },
    {
      "x": -10,
      "y": 8,
      "z": -8,
      "name": "Rock_Aqua_Brick_Smooth",
      "rotation": 3
    },
    {
      "x": -10,
      "y": 9,
      "z": -8,
      "name": "Rock_Aqua_Brick_Decorative"
    },
    {
      "x": -10,
      "y": 10,
      "z": -8,
      "name": "Rock_Aqua_Brick_Smooth"
    },
    {
      "x": -10,
      "y": 11,
      "z": -8,
      "name": "Rock_Aqua_Brick_Smooth"
    },
    {
      "x": -10,
      "y": 12,
      "z": -8,
      "name": "Rock_Aqua_Brick_Decorative"
    },
    {
      "x": -10,
      "y": 13,
      "z": -8,
      "name": "Rock_Aqua_Brick_Smooth"
    },
    {
      "x": -10,
      "y": 14,
      "z": -8,
      "name": "Rock_Aqua_Brick_Smooth"
    },
    {
      "x": -10,
      "y": 0,
      "z": -7,
      "name": "Rock_Aqua_Brick_Decorative",
      "rotation": 3
    },
    {
      "x": -10,
      "y": 1,
      "z": -7,
      "name": "Rock_Aqua_Brick_Ornate",
      "rotation": 3
    },
    {
      "x": -10,
      "y": 2,
      "z": -7,
      "name": "Rock_Aqua_Brick_Ornate",
      "rotation": 3
    },
    {
      "x": -10,
      "y": 3,
      "z": -7,
      "name": "Rock_Aqua_Brick_Decorative",
      "rotation": 3
    },
    {
      "x": -10,
      "y": 4,
      "z": -7,
      "name": "Rock_Aqua_Brick_Ornate",
      "rotation": 3
    },
    {
      "x": -10,
      "y": 5,
      "z": -7,
      "name": "Rock_Aqua_Brick_Ornate",
      "rotation": 3
    },
    {
      "x": -10,
      "y": 6,
      "z": -7,
      "name": "Rock_Aqua_Brick_Decorative",
      "rotation": 3
    },
    {
      "x": -10,
      "y": 7,
      "z": -7,
      "name": "Rock_Aqua_Brick_Ornate",
      "rotation": 3
    },
    {
      "x": -10,
      "y": 8,
      "z": -7,
      "name": "Rock_Aqua_Brick_Ornate",
      "rotation": 3
    },
    {
      "x": -10,
      "y": 9,
      "z": -7,
      "name": "Rock_Aqua_Brick_Decorative"
    },
    {
      "x": -10,
      "y": 10,
      "z": -7,
      "name": "Rock_Aqua_Brick_Ornate"
    },
    {
      "x": -10,
      "y": 11,
      "z": -7,
      "name": "Rock_Aqua_Brick_Ornate"
    },
    {
      "x": -10,
      "y": 12,
      "z": -7,
      "name": "Rock_Aqua_Brick_Decorative"
    },
    {
      "x": -10,
      "y": 13,
      "z": -7,
      "name": "Rock_Aqua_Brick_Ornate"
    },
    {
      "x": -10,
      "y": 14,
      "z": -7,
      "name": "Rock_Aqua_Brick_Ornate"
    },
    {
      "x": -10,
      "y": 0,
      "z": -6,
      "name": "Rock_Aqua_Brick_Decorative"
    },
    {
      "x": -10,
      "y": 1,
      "z": -6,
      "name": "Rock_Aqua_Brick_Ornate",
      "rotation": 1
    },
    {
      "x": -10,
      "y": 2,
      "z": -6,
      "name": "Rock_Aqua_Brick_Ornate",
      "rotation": 1
    },
    {
      "x": -10,
      "y": 3,
      "z": -6,
      "name": "Rock_Aqua_Brick_Decorative"
    },
    {
      "x": -10,
      "y": 4,
      "z": -6,
      "name": "Rock_Aqua_Brick_Ornate",
      "rotation": 1
    },
    {
      "x": -10,
      "y": 5,
      "z": -6,
      "name": "Rock_Aqua_Brick_Ornate",
      "rotation": 1
    },
    {
      "x": -10,
      "y": 6,
      "z": -6,
      "name": "Rock_Aqua_Brick_Decorative"
    },
    {
      "x": -10,
      "y": 7,
      "z": -6,
      "name": "Rock_Aqua_Brick_Ornate",
      "rotation": 1
    },
    {
      "x": -10,
      "y": 8,
      "z": -6,
      "name": "Rock_Aqua_Brick_Ornate",
      "rotation": 1
    },
    {
      "x": -10,
      "y": 9,
      "z": -6,
      "name": "Rock_Aqua_Brick_Decorative"
    },
    {
      "x": -10,
      "y": 10,
      "z": -6,
      "name": "Rock_Aqua_Brick_Ornate",
      "rotation": 1
    },
    {
      "x": -10,
      "y": 11,
      "z": -6,
      "name": "Rock_Aqua_Brick_Ornate",
      "rotation": 1
    },
    {
      "x": -10,
      "y": 12,
      "z": -6,
      "name": "Rock_Aqua_Brick_Decorative"
    },
    {
      "x": -10,
      "y": 13,
      "z": -6,
      "name": "Rock_Aqua_Brick_Ornate",
      "rotation": 1
    },
    {
      "x": -10,
      "y": 14,
      "z": -6,
      "name": "Rock_Aqua_Brick_Ornate",
      "rotation": 1
    },
    {
      "x": -10,
      "y": 15,
      "z": -6,
      "name": "Rock_Aqua_Brick_Decorative"
    },
    {
      "x": -10,
      "y": 16,
      "z": -6,
      "name": "Rock_Aqua_Brick_Ornate",
      "rotation": 1
    },
    {
      "x": -10,
      "y": 0,
      "z": -5,
      "name": "Rock_Aqua_Brick_Decorative"
    },
    {
      "x": -10,
      "y": 1,
      "z": -5,
      "name": "Rock_Aqua_Brick_Smooth",
      "rotation": 1
    },
    {
      "x": -10,
      "y": 2,
      "z": -5,
      "name": "Rock_Aqua_Brick_Smooth",
      "rotation": 1
    },
    {
      "x": -10,
      "y": 3,
      "z": -5,
      "name": "Rock_Aqua_Brick_Decorative"
    },
    {
      "x": -10,
      "y": 4,
      "z": -5,
      "name": "Rock_Aqua_Brick_Smooth",
      "rotation": 1
    },
    {
      "x": -10,
      "y": 5,
      "z": -5,
      "name": "Rock_Aqua_Brick_Smooth",
      "rotation": 1
    },
    {
      "x": -10,
      "y": 6,
      "z": -5,
      "name": "Rock_Aqua_Brick_Decorative"
    },
    {
      "x": -10,
      "y": 7,
      "z": -5,
      "name": "Rock_Aqua_Brick_Smooth",
      "rotation": 1
    },
    {
      "x": -10,
      "y": 8,
      "z": -5,
      "name": "Rock_Aqua_Brick_Smooth",
      "rotation": 1
    },
    {
      "x": -10,
      "y": 9,
      "z": -5,
      "name": "Rock_Aqua_Brick_Decorative"
    },
    {
      "x": -10,
      "y": 10,
      "z": -5,
      "name": "Rock_Aqua_Brick_Smooth",
      "rotation": 1
    },
    {
      "x": -10,
      "y": 11,
      "z": -5,
      "name": "Rock_Aqua_Brick_Smooth",
      "rotation": 1
    },
    {
      "x": -10,
      "y": 12,
      "z": -5,
      "name": "Rock_Aqua_Brick_Decorative"
    },
    {
      "x": -10,
      "y": 13,
      "z": -5,
      "name": "Rock_Aqua_Brick_Smooth",
      "rotation": 1
    },
    {
      "x": -10,
      "y": 14,
      "z": -5,
      "name": "Rock_Aqua_Brick_Smooth",
      "rotation": 1
    },
    {
      "x": -10,
      "y": 15,
      "z": -5,
      "name": "Rock_Aqua_Brick_Decorative"
    },
    {
      "x": -10,
      "y": 16,
      "z": -5,
      "name": "Rock_Aqua_Brick_Smooth",
      "rotation": 1
    },
    {
      "x": -10,
      "y": 0,
      "z": -4,
      "name": "Rock_Aqua_Brick_Decorative"
    },
    {
      "x": -10,
      "y": 1,
      "z": -4,
      "name": "Rock_Aqua_Brick_Ornate",
      "rotation": 1
    },
    {
      "x": -10,
      "y": 2,
      "z": -4,
      "name": "Rock_Aqua_Brick_Ornate",
      "rotation": 1
    },
    {
      "x": -10,
      "y": 3,
      "z": -4,
      "name": "Rock_Aqua_Brick_Decorative"
    },
    {
      "x": -10,
      "y": 4,
      "z": -4,
      "name": "Rock_Aqua_Brick_Ornate",
      "rotation": 1
    },
    {
      "x": -10,
      "y": 5,
      "z": -4,
      "name": "Rock_Aqua_Brick_Ornate",
      "rotation": 1
    },
    {
      "x": -10,
      "y": 6,
      "z": -4,
      "name": "Rock_Aqua_Brick_Decorative"
    },
    {
      "x": -10,
      "y": 7,
      "z": -4,
      "name": "Rock_Aqua_Brick_Ornate",
      "rotation": 1
    },
    {
      "x": -10,
      "y": 8,
      "z": -4,
      "name": "Rock_Aqua_Brick_Ornate",
      "rotation": 1
    },
    {
      "x": -10,
      "y": 9,
      "z": -4,
      "name": "Rock_Aqua_Brick_Decorative"
    },
    {
      "x": -10,
      "y": 10,
      "z": -4,
      "name": "Rock_Aqua_Brick_Ornate",
      "rotation": 1
    },
    {
      "x": -10,
      "y": 11,
      "z": -4,
      "name": "Rock_Aqua_Brick_Ornate",
      "rotation": 1
    },
    {
      "x": -10,
      "y": 12,
      "z": -4,
      "name": "Rock_Aqua_Brick_Decorative"
    },
    {
      "x": -10,
      "y": 13,
      "z": -4,
      "name": "Rock_Aqua_Brick_Ornate",
      "rotation": 1
    },
    {
      "x": -10,
      "y": 14,
      "z": -4,
      "name": "Rock_Aqua_Brick_Ornate",
      "rotation": 1
    },
    {
      "x": -10,
      "y": 15,
      "z": -4,
      "name": "Rock_Aqua_Brick_Decorative"
    },
    {
      "x": -10,
      "y": 16,
      "z": -4,
      "name": "Rock_Aqua_Brick_Ornate",
      "rotation": 1
    },
    {
      "x": -10,
      "y": 0,
      "z": -3,
      "name": "Rock_Aqua_Brick_Decorative"
    },
    {
      "x": -10,
      "y": 1,
      "z": -3,
      "name": "Rock_Aqua_Brick_Smooth",
      "rotation": 1
    },
    {
      "x": -10,
      "y": 2,
      "z": -3,
      "name": "Rock_Aqua_Brick_Smooth",
      "rotation": 1
    },
    {
      "x": -10,
      "y": 3,
      "z": -3,
      "name": "Rock_Aqua_Brick_Decorative"
    },
    {
      "x": -10,
      "y": 4,
      "z": -3,
      "name": "Rock_Aqua_Brick_Smooth",
      "rotation": 1
    },
    {
      "x": -10,
      "y": 5,
      "z": -3,
      "name": "Rock_Aqua_Brick_Smooth",
      "rotation": 1
    },
    {
      "x": -10,
      "y": 6,
      "z": -3,
      "name": "Rock_Aqua_Brick_Decorative"
    },
    {
      "x": -10,
      "y": 7,
      "z": -3,
      "name": "Rock_Aqua_Brick_Smooth",
      "rotation": 1
    },
    {
      "x": -10,
      "y": 8,
      "z": -3,
      "name": "Rock_Aqua_Brick_Smooth",
      "rotation": 1
    },
    {
      "x": -10,
      "y": 9,
      "z": -3,
      "name": "Rock_Aqua_Brick_Decorative"
    },
    {
      "x": -10,
      "y": 10,
      "z": -3,
      "name": "Rock_Aqua_Brick_Smooth",
      "rotation": 1
    },
    {
      "x": -10,
      "y": 11,
      "z": -3,
      "name": "Rock_Aqua_Brick_Smooth",
      "rotation": 1
    },
    {
      "x": -10,
      "y": 12,
      "z": -3,
      "name": "Rock_Aqua_Brick_Decorative"
    },
    {
      "x": -10,
      "y": 13,
      "z": -3,
      "name": "Rock_Aqua_Brick_Smooth",
      "rotation": 1
    },
    {
      "x": -10,
      "y": 14,
      "z": -3,
      "name": "Rock_Aqua_Brick_Smooth",
      "rotation": 1
    },
    {
      "x": -10,
      "y": 15,
      "z": -3,
      "name": "Rock_Aqua_Brick_Decorative"
    },
    {
      "x": -10,
      "y": 16,
      "z": -3,
      "name": "Rock_Aqua_Brick_Smooth",
      "rotation": 1
    },
    {
      "x": -10,
      "y": 0,
      "z": -2,
      "name": "Rock_Aqua_Brick_Decorative"
    },
    {
      "x": -10,
      "y": 1,
      "z": -2,
      "name": "Rock_Aqua_Brick_Ornate",
      "rotation": 1
    },
    {
      "x": -10,
      "y": 2,
      "z": -2,
      "name": "Rock_Aqua_Brick_Ornate",
      "rotation": 1
    },
    {
      "x": -10,
      "y": 3,
      "z": -2,
      "name": "Rock_Aqua_Brick_Decorative"
    },
    {
      "x": -10,
      "y": 4,
      "z": -2,
      "name": "Rock_Aqua_Brick_Ornate",
      "rotation": 1
    },
    {
      "x": -10,
      "y": 5,
      "z": -2,
      "name": "Rock_Aqua_Brick_Ornate",
      "rotation": 1
    },
    {
      "x": -10,
      "y": 6,
      "z": -2,
      "name": "Rock_Aqua_Brick_Decorative"
    },
    {
      "x": -10,
      "y": 7,
      "z": -2,
      "name": "Rock_Aqua_Brick_Ornate",
      "rotation": 1
    },
    {
      "x": -10,
      "y": 8,
      "z": -2,
      "name": "Rock_Aqua_Brick_Ornate",
      "rotation": 1
    },
    {
      "x": -10,
      "y": 9,
      "z": -2,
      "name": "Rock_Aqua_Brick_Decorative"
    },
    {
      "x": -10,
      "y": 10,
      "z": -2,
      "name": "Rock_Aqua_Brick_Ornate",
      "rotation": 1
    },
    {
      "x": -10,
      "y": 11,
      "z": -2,
      "name": "Rock_Aqua_Brick_Ornate",
      "rotation": 1
    },
    {
      "x": -10,
      "y": 12,
      "z": -2,
      "name": "Rock_Aqua_Brick_Decorative"
    },
    {
      "x": -10,
      "y": 13,
      "z": -2,
      "name": "Rock_Aqua_Brick_Ornate",
      "rotation": 1
    },
    {
      "x": -10,
      "y": 14,
      "z": -2,
      "name": "Rock_Aqua_Brick_Ornate",
      "rotation": 1
    },
    {
      "x": -10,
      "y": 15,
      "z": -2,
      "name": "Rock_Aqua_Brick_Decorative"
    },
    {
      "x": -10,
      "y": 16,
      "z": -2,
      "name": "Rock_Aqua_Brick_Ornate",
      "rotation": 1
    },
    {
      "x": -10,
      "y": 0,
      "z": -1,
      "name": "Rock_Aqua_Brick_Decorative"
    },
    {
      "x": -10,
      "y": 1,
      "z": -1,
      "name": "Rock_Aqua_Brick_Smooth"
    },
    {
      "x": -10,
      "y": 2,
      "z": -1,
      "name": "Rock_Aqua_Brick_Smooth"
    },
    {
      "x": -10,
      "y": 3,
      "z": -1,
      "name": "Rock_Aqua_Brick_Decorative"
    },
    {
      "x": -10,
      "y": 4,
      "z": -1,
      "name": "Rock_Aqua_Brick_Smooth"
    },
    {
      "x": -10,
      "y": 5,
      "z": -1,
      "name": "Rock_Aqua_Brick_Smooth"
    },
    {
      "x": -10,
      "y": 6,
      "z": -1,
      "name": "Rock_Aqua_Brick_Decorative"
    },
    {
      "x": -10,
      "y": 7,
      "z": -1,
      "name": "Rock_Aqua_Brick_Smooth"
    },
    {
      "x": -10,
      "y": 8,
      "z": -1,
      "name": "Rock_Aqua_Brick_Smooth"
    },
    {
      "x": -10,
      "y": 9,
      "z": -1,
      "name": "Rock_Aqua_Brick_Decorative"
    },
    {
      "x": -10,
      "y": 10,
      "z": -1,
      "name": "Rock_Aqua_Brick_Smooth"
    },
    {
      "x": -10,
      "y": 11,
      "z": -1,
      "name": "Rock_Aqua_Brick_Smooth"
    },
    {
      "x": -10,
      "y": 12,
      "z": -1,
      "name": "Rock_Aqua_Brick_Decorative"
    },
    {
      "x": -10,
      "y": 13,
      "z": -1,
      "name": "Rock_Aqua_Brick_Smooth"
    },
    {
      "x": -10,
      "y": 14,
      "z": -1,
      "name": "Rock_Aqua_Brick_Smooth"
    },
    {
      "x": -10,
      "y": 15,
      "z": -1,
      "name": "Rock_Aqua_Brick_Decorative"
    },
    {
      "x": -10,
      "y": 16,
