{
  "version": 8,
  "blockIdVersion": 11,
  "anchorX": 2,
  "anchorY": 1,
  "anchorZ": 2,
  "blocks": [
    {
      "x": -2,
      "y": 4,
      "z": -2,
      "name": "Rock_Crystal_Orange_Block"
    },
    {
      "x": -2,
      "y": 5,
      "z": -2,
      "name": "Rock_Crystal_Orange_Block"
    },
    {
      "x": -2,
      "y": 6,
      "z": -2,
      "name": "Rock_Crystal_Orange_Small"
    },
    {
      "x": -1,
      "y": 3,
      "z": -2,
      "name": "Rock_Crystal_Orange_Block"
    },
    {
      "x": -1,
      "y": 4,
      "z": -2,
      "name": "Rock_Crystal_Orange_Small",
      "rotation": 5
    },
    {
      "x": -1,
      "y": 3,
      "z": -1,
      "name": "Rock_Crystal_Orange_Block"
    },
    {
      "x": -1,
      "y": 4,
      "z": -1,
      "name": "Rock_Crystal_Orange_Block"
    },
    {
      "x": -1,
      "y": 3,
      "z": 0,
      "name": "Rock_Crystal_Orange_Block"
    },
    {
      "x": -1,
      "y": 4,
      "z": 0,
      "name": "Rock_Crystal_Orange_Small"
    },
    {
      "x": 0,
      "y": 2,
      "z": -1,
      "name": "Rock_Crystal_Orange_Block"
    },
    {
      "x": 0,
      "y": 3,
      "z": -1,
      "name": "Rock_Crystal_Orange_Block"
    },
    {
      "x": 0,
      "y": 2,
      "z": 0,
      "name": "Rock_Crystal_Orange_Block"
    },
    {
      "x": 0,
      "y": 3,
      "z": 0,
      "name": "Rock_Crystal_Orange_Block"
    },
    {
      "x": 0,
      "y": 1,
      "z": 1,
      "name": "Rock_Crystal_Orange_Small",
      "rotation": 8
    },
    {
      "x": 0,
      "y": 2,
      "z": 1,
      "name": "Rock_Crystal_Orange_Block"
    },
    {
      "x": 0,
      "y": 1,
      "z": 2,
      "name": "Rock_Crystal_Orange_Block"
    },
    {
      "x": 0,
      "y": 2,
      "z": 2,
      "name": "Rock_Crystal_Orange_Block"
    },
    {
      "x": 1,
      "y": 2,
      "z": -1,
      "name": "Rock_Crystal_Orange_Block"
    },
    {
      "x": 1,
      "y": 1,
      "z": 0,
      "name": "Rock_Crystal_Orange_Block"
    },
    {
      "x": 1,
      "y": 2,
      "z": 0,
      "name": "Rock_Crystal_Orange_Block"
    },
    {
      "x": 1,
      "y": 3,
      "z": 0,
      "name": "Rock_Crystal_Orange_Medium"
    },
    {
      "x": 1,
      "y": 1,
      "z": 1,
      "name": "Rock_Crystal_Orange_Block"
    },
    {
      "x": 1,
      "y": 2,
      "z": 1,
      "name": "Rock_Crystal_Orange_Block"
    },
    {
      "x": 1,
      "y": 1,
      "z": 2,
      "name": "Rock_Crystal_Orange_Block"
    },
    {
      "x": 1,
      "y": 2,
      "z": 2,
      "name": "Rock_Crystal_Orange_Block"
    },
    {
      "x": 1,
      "y": 0,
      "z": 3,
      "name": "Rock_Crystal_Orange_Block"
    },
    {
      "x": 1,
      "y": 1,
      "z": 3,
      "name": "Rock_Crystal_Orange_Block"
    },
    {
      "x": 2,
      "y": 1,
      "z": 0,
      "name": "Rock_Crystal_Orange_Block"
    },
    {
      "x": 2,
      "y": 2,
      "z": 0,
      "name": "Rock_Crystal_Orange_Block"
    },
    {
      "x": 2,
      "y": 0,
      "z": 1,
      "name": "Rock_Crystal_Orange_Block"
    },
    {
      "x": 2,
      "y": 1,
      "z": 1,
      "name": "Rock_Crystal_Orange_Block"
    },
    {
      "x": 2,
      "y": 2,
      "z": 1,
      "name": "Rock_Crystal_Orange_Block"
    },
    {
      "x": 2,
      "y": 0,
      "z": 2,
      "name": "Rock_Crystal_Orange_Block"
    },
    {
      "x": 2,
      "y": 1,
      "z": 2,
      "name": "Rock_Crystal_Orange_Block"
    },
    {
      "x": 2,
      "y": 2,
      "z": 2,
      "name": "Rock_Crystal_Orange_Medium"
    },
    {
      "x": 2,
      "y": 0,
      "z": 3,
      "name": "Rock_Crystal_Orange_Block"
    },
    {
      "x": 2,
      "y": 1,
      "z": 3,
      "name": "Rock_Crystal_Orange_Block"
    },
    {
      "x": 3,
      "y": 0,
      "z": 1,
      "name": "Rock_Crystal_Orange_Block"
    },
    {
      "x": 3,
      "y": 1,
      "z": 1,
      "name": "Rock_Crystal_Orange_Block"
    },
    {
      "x": 3,
      "y": 0,
      "z": 2,
      "name": "Rock_Crystal_Orange_Block"
    },
    {
      "x": 3,
      "y": 1,
      "z": 2,
      "name": "Rock_Crystal_Orange_Block"
    },
    {
      "x": 3,
      "y": 0,
      "z": 3,
      "name": "Rock_Crystal_Orange_Block"
    }
  ],
  "fluids": [
    {
      "x": -2,
      "y": 6,
      "z": -2,
      "name": "Water_Source",
      "level": 1
    },
    {
      "x": -1,
      "y": 4,
      "z": -2,
      "name": "Water_Source",
      "level": 1
    },
    {
      "x": -1,
      "y": 4,
      "z": 0,
      "name": "Water_Source",
      "level": 1
    },
    {
      "x": 0,
      "y": 1,
      "z": 1,
      "name": "Water_Source",
      "level": 1
    },
    {
      "x": 1,
      "y": 3,
      "z": 0,
      "name": "Water_Source",
      "level": 1
    },
    {
      "x": 2,
      "y": 2,
      "z": 2,
      "name": "Water_Source",
      "level": 1
    }
  ]
}