{
  "version": 8,
  "blockIdVersion": 11,
  "anchorX": 0,
  "anchorY": 0,
  "anchorZ": 0,
  "blocks": [
    {
      "x": -3,
      "y": 0,
      "z": 0,
      "name": "Plant_Coral_Bush_Blue"
    },
    {
      "x": -2,
      "y": 0,
      "z": -2,
      "name": "Plant_Coral_Bush_Blue"
    },
    {
      "x": -2,
      "y": -1,
      "z": -1,
      "name": "Plant_Coral_Block_Blue"
    },
    {
      "x": -2,
      "y": 0,
      "z": -1,
      "name": "Plant_Coral_Block_Blue"
    },
    {
      "x": -2,
      "y": -1,
      "z": 0,
      "name": "Plant_Coral_Block_Cyan"
    },
    {
      "x": -2,
      "y": 0,
      "z": 0,
      "name": "Plant_Coral_Block_Blue"
    },
    {
      "x": -2,
      "y": 1,
      "z": 0,
      "name": "Plant_Coral_Bush_Cyan"
    },
    {
      "x": -2,
      "y": -1,
      "z": 1,
      "name": "Plant_Coral_Block_Blue"
    },
    {
      "x": -2,
      "y": 0,
      "z": 1,
      "name": "Plant_Coral_Block_Blue"
    },
    {
      "x": -2,
      "y": 0,
      "z": 2,
      "name": "Plant_Coral_Bush_Blue"
    },
    {
      "x": -1,
      "y": -1,
      "z": -2,
      "name": "Plant_Coral_Block_Blue"
    },
    {
      "x": -1,
      "y": 0,
      "z": -2,
      "name": "Plant_Coral_Block_Blue"
    },
    {
      "x": -1,
      "y": -1,
      "z": -1,
      "name": "Plant_Coral_Block_Blue"
    },
    {
      "x": -1,
      "y": 0,
      "z": -1,
      "name": "Plant_Coral_Block_Blue"
    },
    {
      "x": -1,
      "y": 1,
      "z": -1,
      "name": "Plant_Coral_Block_Cyan"
    },
    {
      "x": -1,
      "y": 2,
      "z": -1,
      "name": "Plant_Coral_Model_Cyan"
    },
    {
      "x": -1,
      "y": -1,
      "z": 0,
      "name": "Plant_Coral_Block_Blue"
    },
    {
      "x": -1,
      "y": 0,
      "z": 0,
      "name": "Plant_Coral_Block_Blue"
    },
    {
      "x": -1,
      "y": 1,
      "z": 0,
      "name": "Plant_Coral_Block_Cyan"
    },
    {
      "x": -1,
      "y": -1,
      "z": 1,
      "name": "Plant_Coral_Block_Blue"
    },
    {
      "x": -1,
      "y": 0,
      "z": 1,
      "name": "Plant_Coral_Block_Blue"
    },
    {
      "x": -1,
      "y": 1,
      "z": 1,
      "name": "Plant_Coral_Block_Cyan"
    },
    {
      "x": -1,
      "y": -1,
      "z": 2,
      "name": "Plant_Coral_Block_Blue"
    },
    {
      "x": -1,
      "y": 0,
      "z": 2,
      "name": "Plant_Coral_Block_Blue"
    },
    {
      "x": 0,
      "y": -1,
      "z": -2,
      "name": "Plant_Coral_Block_Cyan"
    },
    {
      "x": 0,
      "y": 0,
      "z": -2,
      "name": "Plant_Coral_Block_Blue"
    },
    {
      "x": 0,
      "y": 1,
      "z": -2,
      "name": "Plant_Coral_Bush_Blue"
    },
    {
      "x": 0,
      "y": -1,
      "z": -1,
      "name": "Plant_Coral_Block_Blue"
    },
    {
      "x": 0,
      "y": 0,
      "z": -1,
      "name": "Plant_Coral_Block_Blue"
    },
    {
      "x": 0,
      "y": 1,
      "z": -1,
      "name": "Plant_Coral_Block_Cyan"
    },
    {
      "x": 0,
      "y": 2,
      "z": -1,
      "name": "Plant_Coral_Bush_Cyan"
    },
    {
      "x": 0,
      "y": -1,
      "z": 0,
      "name": "Plant_Coral_Block_Blue"
    },
    {
      "x": 0,
      "y": 0,
      "z": 0,
      "name": "Plant_Coral_Block_Blue"
    },
    {
      "x": 0,
      "y": 1,
      "z": 0,
      "name": "Plant_Coral_Block_Cyan"
    },
    {
      "x": 0,
      "y": 2,
      "z": 0,
      "name": "Plant_Flower_Orchid_Blue"
    },
    {
      "x": 0,
      "y": -1,
      "z": 1,
      "name": "Plant_Coral_Block_Blue"
    },
    {
      "x": 0,
      "y": 0,
      "z": 1,
      "name": "Plant_Coral_Block_Blue"
    },
    {
      "x": 0,
      "y": 1,
      "z": 1,
      "name": "Plant_Coral_Block_Cyan"
    },
    {
      "x": 0,
      "y": 2,
      "z": 1,
      "name": "Plant_Coral_Bush_Cyan"
    },
    {
      "x": 0,
      "y": -1,
      "z": 2,
      "name": "Plant_Coral_Block_Cyan"
    },
    {
      "x": 0,
      "y": 0,
      "z": 2,
      "name": "Plant_Coral_Block_Blue"
    },
    {
      "x": 0,
      "y": 0,
      "z": 3,
      "name": "Plant_Coral_Bush_Blue"
    },
    {
      "x": 1,
      "y": -1,
      "z": -2,
      "name": "Plant_Coral_Block_Blue"
    },
    {
      "x": 1,
      "y": 0,
      "z": -2,
      "name": "Plant_Coral_Block_Blue"
    },
    {
      "x": 1,
      "y": -1,
      "z": -1,
      "name": "Plant_Coral_Block_Blue"
    },
    {
      "x": 1,
      "y": 0,
      "z": -1,
      "name": "Plant_Coral_Block_Blue"
    },
    {
      "x": 1,
      "y": 1,
      "z": -1,
      "name": "Plant_Coral_Block_Cyan"
    },
    {
      "x": 1,
      "y": -1,
      "z": 0,
      "name": "Plant_Coral_Block_Blue"
    },
    {
      "x": 1,
      "y": 0,
      "z": 0,
      "name": "Plant_Coral_Block_Blue"
    },
    {
      "x": 1,
      "y": 1,
      "z": 0,
      "name": "Plant_Coral_Block_Cyan"
    },
    {
      "x": 1,
      "y": 2,
      "z": 0,
      "name": "Plant_Coral_Model_Cyan"
    },
    {
      "x": 1,
      "y": -1,
      "z": 1,
      "name": "Plant_Coral_Block_Blue"
    },
    {
      "x": 1,
      "y": 0,
      "z": 1,
      "name": "Plant_Coral_Block_Blue"
    },
    {
      "x": 1,
      "y": 1,
      "z": 1,
      "name": "Plant_Coral_Block_Cyan"
    },
    {
      "x": 1,
      "y": -1,
      "z": 2,
      "name": "Plant_Coral_Block_Blue"
    },
    {
      "x": 1,
      "y": 0,
      "z": 2,
      "name": "Plant_Coral_Block_Blue"
    },
    {
      "x": 1,
      "y": 1,
      "z": 2,
      "name": "Plant_Coral_Bush_Blue"
    },
    {
      "x": 2,
      "y": -1,
      "z": -1,
      "name": "Plant_Coral_Block_Blue"
    },
    {
      "x": 2,
      "y": 0,
      "z": -1,
      "name": "Plant_Coral_Block_Blue"
    },
    {
      "x": 2,
      "y": -1,
      "z": 0,
      "name": "Plant_Coral_Block_Cyan"
    },
    {
      "x": 2,
      "y": 0,
      "z": 0,
      "name": "Plant_Coral_Block_Blue"
    },
    {
      "x": 2,
      "y": 1,
      "z": 0,
      "name": "Plant_Coral_Bush_Cyan"
    },
    {
      "x": 2,
      "y": -1,
      "z": 1,
      "name": "Plant_Coral_Block_Blue"
    },
    {
      "x": 2,
      "y": 0,
      "z": 1,
      "name": "Plant_Coral_Block_Blue"
    },
    {
      "x": 3,
      "y": 0,
      "z": 0,
      "name": "Plant_Coral_Bush_Blue"
    }
  ],
  "fluids": [
    {
      "x": -3,
      "y": 0,
      "z": 0,
      "name": "Water_Source",
      "level": 1
    },
    {
      "x": -2,
      "y": 0,
      "z": -2,
      "name": "Water_Source",
      "level": 1
    },
    {
      "x": -2,
      "y": 1,
      "z": 0,
      "name": "Water_Source",
      "level": 1
    },
    {
      "x": -2,
      "y": 0,
      "z": 2,
      "name": "Water_Source",
      "level": 1
    },
    {
      "x": -1,
      "y": 2,
      "z": -1,
      "name": "Water_Source",
      "level": 1
    },
    {
      "x": 0,
      "y": 1,
      "z": -2,
      "name": "Water_Source",
      "level": 1
    },
    {
      "x": 0,
      "y": 2,
      "z": -1,
      "name": "Water_Source",
      "level": 1
    },
    {
      "x": 0,
      "y": 2,
      "z": 0,
      "name": "Water_Source",
      "level": 1
    },
    {
      "x": 0,
      "y": 2,
      "z": 1,
      "name": "Water_Source",
      "level": 1
    },
    {
      "x": 0,
      "y": 0,
      "z": 3,
      "name": "Water_Source",
      "level": 1
    },
    {
      "x": 1,
      "y": 2,
      "z": 0,
      "name": "Water_Source",
      "level": 1
    },
    {
      "x": 1,
      "y": 1,
      "z": 2,
      "name": "Water_Source",
      "level": 1
    },
    {
      "x": 2,
      "y": 1,
      "z": 0,
      "name": "Water_Source",
      "level": 1
    },
    {
      "x": 3,
      "y": 0,
      "z": 0,
      "name": "Water_Source",
      "level": 1
    }
  ]
}